Workbook
Name BALANCE1_LDA01: '[1]Financial Statements'!$E$112
Name BALANCE1_LDA12: '[1]Financial Statements'!$E$123
Name BALANCE2_LDA01: '[1]Financial Statements'!$F$112
Name BALANCE2_LDA12: '[1]Financial Statements'!$F$123
Name BALANCE3_LDA01: '[1]Financial Statements'!$G$112
Name BALANCE3_LDA12: '[1]Financial Statements'!$G$123
Name BALANCE4_LDA01: '[1]Financial Statements'!$H$112
Name BALANCE4_LDA12: '[1]Financial Statements'!$H$123
Name BALANCE5_LDA01: '[1]Financial Statements'!$I$112
Name BALANCE5_LDA12: '[1]Financial Statements'!$I$123
Name BALANCE6_LDA01: '[1]Financial Statements'!$J$112
Name BALANCE6_LDA12: '[1]Financial Statements'!$J$123
Name NotApplicable: CAELS!$B$25
Name PEARLS1_LA002: '[1]Financial Statements'!$E$280
Name PEARLS1_LE008: '[1]Financial Statements'!$E$275
Name PEARLS1_LE009: '[1]Financial Statements'!$E$276
Name PEARLS1_LR001: '[1]Financial Statements'!$E$282
Name PEARLS1_LR005: '[1]Financial Statements'!$E$286
Name PEARLS1_LR006: '[1]Financial Statements'!$E$287
Name PEARLS1_LR007: '[1]Financial Statements'!$E$288
Name PEARLS1_LR009: '[1]Financial Statements'!$E$290
Name PEARLS1_LS001: '[1]Financial Statements'!$E$298
Name PEARLS1_LS005: '[1]Financial Statements'!$E$302
Name PEARLS1_LS011: '[1]Financial Statements'!$E$308
Name PEARLS2_LA002: '[1]Financial Statements'!$F$280
Name PEARLS2_LE008: '[1]Financial Statements'!$F$275
Name PEARLS2_LE009: '[1]Financial Statements'!$F$276
Name PEARLS2_LR001: '[1]Financial Statements'!$F$282
Name PEARLS2_LR005: '[1]Financial Statements'!$F$286
Name PEARLS2_LR006: '[1]Financial Statements'!$F$287
Name PEARLS2_LR007: '[1]Financial Statements'!$F$288
Name PEARLS2_LR009: '[1]Financial Statements'!$F$290
Name PEARLS2_LS001: '[1]Financial Statements'!$F$298
Name PEARLS2_LS005: '[1]Financial Statements'!$F$302
Name PEARLS2_LS010: '[1]Financial Statements'!$F$307
Name PEARLS2_LS011: '[1]Financial Statements'!$F$308
Name PEARLS3_LA002: '[1]Financial Statements'!$G$280
Name PEARLS3_LE008: '[1]Financial Statements'!$G$275
Name PEARLS3_LE009: '[1]Financial Statements'!$G$276
Name PEARLS3_LR001: '[1]Financial Statements'!$G$282
Name PEARLS3_LR005: '[1]Financial Statements'!$G$286
Name PEARLS3_LR006: '[1]Financial Statements'!$G$287
Name PEARLS3_LR007: '[1]Financial Statements'!$G$288
Name PEARLS3_LR009: '[1]Financial Statements'!$G$290
Name PEARLS3_LS001: '[1]Financial Statements'!$G$298
Name PEARLS3_LS005: '[1]Financial Statements'!$G$302
Name PEARLS3_LS010: '[1]Financial Statements'!$G$307
Name PEARLS3_LS011: '[1]Financial Statements'!$G$308
Name PEARLS4_LA002: '[1]Financial Statements'!$H$280
Name PEARLS4_LE008: '[1]Financial Statements'!$H$275
Name PEARLS4_LE009: '[1]Financial Statements'!$H$276
Name PEARLS4_LR001: '[1]Financial Statements'!$H$282
Name PEARLS4_LR005: '[1]Financial Statements'!$H$286
Name PEARLS4_LR006: '[1]Financial Statements'!$H$287
Name PEARLS4_LR007: '[1]Financial Statements'!$H$288
Name PEARLS4_LR009: '[1]Financial Statements'!$H$290
Name PEARLS4_LS001: '[1]Financial Statements'!$H$298
Name PEARLS4_LS005: '[1]Financial Statements'!$H$302
Name PEARLS4_LS010: '[1]Financial Statements'!$H$307
Name PEARLS4_LS011: '[1]Financial Statements'!$H$308

Sheet Trend
B3: DEFENCE SACCO | J3: Base Year
C4: 2013 | D4: 2014 | E4: Audit 2015 | F4: Audit 2016 | G4: Audit 2017 | H4: Audited 2018 | I4: Audited 2019 | J4: Audited 2020 | K4: Audited 2021 | L4: 44562 | M4: 44593 | N4: 44621 | O4: 44652 | P4: 44682 | Q4: 44713 | R4: 44743 | S4: 44774 | T4: 44805 | U4: 44835 | V4: 44866 | W4: 44896 | X4: Audited-2022 | Y4: 44949 | Z4: 44980 | AA4: 45008 | AB4: 45039 | AC4: 45069 | AD4: 45100
B5: Cash and Cash Equivalent | J5: =J6+J7 -> 375933615 | K5: =K6+K7 -> 583646239 | L5: =L6+L7 -> 5.3005126e+08 | M5: =M6+M7 -> 4.1482331e+08 | N5: =N6+N7 -> 6.7492501e+08 | O5: =O6+O7 -> 6.5037254e+08 | P5: =P6+P7 -> 6.8629423e+08 | Q5: =Q6+Q7 -> 7.0539082e+08 | ... AD5: =AD6+AD7 -> 8.2005767e+08
B6: Cash in Hand | J6: 0 | L6: 200100 | M6: 1199830 | N6: 4094100 | O6: 2951700 | P6: 8750 | Q6: 4948100 | R6: 5149700 | S6: 4506450 | T6: 7058650 | U6: 5160050 | V6: 5408800 | W6: 6948900 | X6: =6948900+44915433+11276757 -> 63141090 | Y6: 2665250 | Z6: 4277700 | AA6: 4143400 | AB6: 6607350 | AC6: 5756000 | AD6: 2455300
B7: Cash at Bank | J7: 375933615 | K7: 583646239 | L7: 5.2985116e+08 | M7: 4.1362348e+08 | N7: 6.7083091e+08 | O7: 6.4742084e+08 | P7: 6.8628548e+08 | Q7: 7.0044272e+08 | R7: 3.8653254e+08 | S7: 8.9762557e+08 | T7: 8.9475624e+08 | U7: 9.1670022e+08 | V7: 8.9582156e+08 | W7: 3.0547507e+08 | X7: =15309747+557326+24720482+8561345+200000000+60000000+51511250+2867694 -> 363527844 | Y7: 9.0808746e+08 | Z7: 9.2114728e+08 | AA7: 7.907949e+08 | AB7: 2.9451931e+08 | AC7: 2.5092602e+08 | AD7: 8.1760237e+08
B8: Prepayments and Sundry Receivables | J8: 5863447 | K8: 24284162 | L8: 24779370 | M8: 2.1566836e+08 | N8: 618454.57 | O8: 2094825 | P8: 3757175.1 | Q8: 1.1976176e+08 | R8: 4.9342878e+08 | S8: 6147486.8 | T8: 8381173.8 | U8: 11930338 | V8: 13610850 | W8: 6.316281e+08 | X8: =430753438+195053203+2621600+1738005+628152+500000 -> 631294398 | Y8: 6132599.2 | Z8: 7298663.1 | AA8: 6209622.8 | AB8: 5.4085677e+08 | AC8: 5.714849e+08 | AD8: 2731571.5
B9: Financial Investments | J9: =J10+J11+J12+J13 -> 10000000 | K9: =K10+K11+K12+K13 -> 10000000 | L9: =L10+L11+L12+L13 -> 1.3078489e+08 | M9: =M10+M11+M12+M13 -> 1.3243854e+08 | N9: =N10+N11+N12+N13 -> 1.3243854e+08 | O9: =O10+O11+O12+O13 -> 1.928705e+08 | P9: =P10+P11+P12+P13 -> 2.338705e+08 | Q9: =Q10+Q11+Q12+Q13 -> 2.3544865e+08 | ... AD9: =AD10+AD11+AD12+AD13 -> 1.1395298e+08
B10: Government Securities | L10: 60000000 | M10: 60000000 | N10: 60000000 | O10: 60000000 | P10: 60000000 | Q10: 60000000 | R10: 60000000 | S10: 60000000 | T10: 60000000 | U10: 60000000 | V10: 60000000 | W10: 60000000 | Y10: 60000000 | Z10: 60000000 | AA10: 60000000 | AB10: 60000000 | AC10: 60000000 | AD10: 60000000
B11: Other Securities | L11: 10784886 | M11: 10855746 | N11: 10855747 | O11: 71287705 | P11: 71287705 | Q11: 71332526 | R11: 2764793.6 | S11: 2764793.6 | T11: 2764793.6 | U11: 2764793.6 | V11: 2764793.6 | W11: 2867694.4 | Y11: 2867694.4 | Z11: 2867694.4 | AA11: 2867694.4 | AB11: 2867694.4 | AC11: 2952981.5 | AD11: 2952981.5
B12: Balances with other SACCO Societies | J12: 10000000 | K12: 10000000 | L12: 50000000 | M12: 51582795 | N12: 51582795 | O12: 51582795 | P12: 51582795 | Q12: 53116127 | R12: 0 | S12: 0 | T12: 50000000 | U12: 50000000 | V12: 60000000 | W12: 50000000 | X12: 51000000 | Y12: 51511250 | Z12: 51511250 | AA12: 70000000 | AB12: 0 | AC12: 0 | AD12: 0
B13: Investments in companies | L13: 10000000 | M13: 10000000 | N13: 10000000 | O13: 10000000 | P13: 51000000 | Q13: 51000000 | R13: 51000000 | S13: 51000000 | T13: 51000000 | U13: 51000000 | V13: 41000000 | W13: 51000000 | Y13: 51000000 | Z13: 51000000 | AA13: 51000000 | AB13: 51000000 | AC13: 51000000 | AD13: 51000000
B14: Net Loan Portfolio | J14: =J15-J16 -> 67566895 | K14: =K15-K16 -> 5.5293772e+08 | L14: =L15-L16 -> 5.9571784e+08 | M14: =M15-M16 -> 6.3966133e+08 | N14: =N15-N16 -> 7.068788e+08 | O14: =O15-O16 -> 8.0472316e+08 | P14: =P15-P16 -> 9.1367836e+08 | Q14: =Q15-Q16 -> 1.0367631e+09 | ... AD14: =AD15-AD16 -> 3.2002342e+09
B15: Gross Loan Portfolio | J15: 67566895 | K15: 5.5293772e+08 | L15: 6.0713821e+08 | M15: 654081705 | N15: 7.2585877e+08 | O15: 8.2786399e+08 | P15: 9.4205761e+08 | Q15: 1.0602147e+09 | R15: 1.1788905e+09 | S15: 1.31237e+09 | T15: 1.4622987e+09 | U15: 1.6238722e+09 | V15: 1.795915e+09 | W15: 1.9658763e+09 | X15: 1965911975 | Y15: 2156775721 | Z15: 2.3521872e+09 | AA15: 2.5945021e+09 | AB15: 2.8057196e+09 | AC15: 3.031349e+09 | AD15: 3.2831912e+09
B16: Allowance for Loan Loss | J16: 0 | L16: 11420371 | M16: 14420371 | N16: 18979978 | O16: 23140824 | P16: 28379254 | Q16: 23451622 | R16: 26672724 | S16: 32820242 | T16: 36575624 | U16: 40075391 | V16: 43791359 | W16: 46239386 | X16: 46239386 | Y16: 54050756 | Z16: 58714104 | AA16: 61762371 | AB16: 69572162 | AC16: 76315224 | AD16: 82956980
B17: Account Receivables | J17: =J18+J19+J20 -> 0 | K17: =K18+K19+K20 -> 0 | L17: =L18+L19+L20 -> 628152.18 | M17: =M18+M19+M20 -> 628152.18 | N17: =N18+N19+N20 -> 628152.18 | O17: =O18+O19+O20 -> 628152.18 | P17: =P18+P19+P20 -> 628152.18 | Q17: =Q18+Q19+Q20 -> 628152.18 | ... AD17: =AD18+AD19+AD20 -> 628152.18
B18: Tax Recoverable | J18: 0 | L18: 628152.18 | M18: 628152.18 | N18: 628152.18 | O18: 628152.18 | P18: 628152.18 | Q18: 628152.18 | R18: 628152.18 | S18: 628152.18 | T18: 628152.18 | U18: 628152.18 | V18: 628152.18 | W18: 628152.18 | X18: 0 | Y18: 628152.18 | Z18: 628152.18 | AA18: 628152.18 | AB18: 628152.18 | AC18: 628152.18 | AD18: 628152.18
B19: Deferred Tax Assets | J19: 0 | L19: 0 | M19: 0 | N19: 0 | O19: 0 | P19: 0 | Q19: 0 | R19: 0 | S19: 0 | T19: 0 | U19: 0 | V19: 0 | W19: 0 | X19: 0 | Y19: 0 | Z19: 0 | AA19: 0 | AB19: 0 | AC19: 0 | AD19: 0
B20: Retirement Benefit Assets | J20: 0 | L20: 0 | M20: 0 | N20: 0 | O20: 0 | P20: 0 | Q20: 0 | R20: 0 | S20: 0 | T20: 0 | U20: 0 | V20: 0 | W20: 0 | X20: 0 | Y20: 0 | Z20: 0 | AA20: 0 | AB20: 0 | AC20: 0 | AD20: 0
B21: Property and Equipment and Other Assets | J21: =J22+J23+J24+J25+J26 -> 0 | W21: =W22+W23+W24+W25+W26 -> 0 | X21: =X22+X23+X24+X25+X26 -> 0 | Y21: =Y22+Y23+Y24+Y25+Y26 -> 0 | Z21: =Z22+Z23+Z24+Z25+Z26 -> 0 | AA21: =AA22+AA23+AA24+AA25+AA26 -> 2552000 | AB21: =AB22+AB23+AB24+AB25+AB26 -> 6902000 | AC21: =AC22+AC23+AC24+AC25+AC26 -> 7027000 | AD21: =AD22+AD23+AD24+AD25+AD26 -> 7027000
B22: Investment Properties | J22: 0 | L22: 0 | M22: 0 | N22: 0 | O22: 0 | P22: 0 | Q22: 0 | R22: 0 | S22: 0 | T22: 0 | U22: 0 | V22: 0 | W22: 0 | Y22: 0 | Z22: 0 | AA22: 0 | AB22: 0 | AC22: 0 | AD22: 4475000
B23: Property and Equipment | J23: 0 | L23: 0 | M23: 0 | N23: 0 | O23: 0 | P23: 0 | Q23: 0 | R23: 0 | S23: 0 | T23: 0 | U23: 0 | V23: 0 | W23: 0 | Y23: 0 | Z23: 0 | AA23: 0 | AB23: 4350000 | AC23: 4475000 | AD23: 0
B24: Prepaid lease rentals | J24: 0 | L24: 0 | M24: 0 | N24: 0 | O24: 0 | P24: 0 | Q24: 0 | R24: 0 | S24: 0 | T24: 0 | U24: 0 | V24: 0 | W24: 0 | Y24: 0 | Z24: 0 | AA24: 0 | AB24: 0 | AC24: 0 | AD24: 0
B25: Intangible Assets | J25: 0 | L25: 0 | M25: 0 | N25: 0 | O25: 0 | P25: 0 | Q25: 0 | R25: 0 | S25: 0 | T25: 0 | U25: 0 | V25: 0 | W25: 0 | Y25: 0 | Z25: 0 | AA25: 2552000 | AB25: 2552000 | AC25: 2552000 | AD25: 2552000
B26: Other Assets | J26: 0 | L26: 0 | M26: 0 | N26: 0 | O26: 0 | P26: 0 | Q26: 0 | R26: 0 | S26: 0 | T26: 0 | U26: 0 | V26: 0 | W26: 0 | Y26: 0 | Z26: 0 | AA26: 0 | AB26: 0 | AC26: 0 | AD26: 0
B27: Total Assets | J27: =J5+J8+J9+J14+J17+J21 -> 459363957 | K27: =K5+K8+K9+K14+K17+K21 -> 1.1708681e+09 | L27: =L5+L8+L9+L14+L17+L21 -> 1.2819615e+09 | M27: =M5+M8+M9+M14+M17+M21 -> 1.4032197e+09 | N27: =N5+N8+N9+N14+N17+N21 -> 1.515489e+09 | O27: =O5+O8+O9+O14+O17+O21 -> 1.6506892e+09 | P27: =P5+P8+P9+P14+P17+P21 -> 1.8382284e+09 | Q27: =Q5+Q8+Q9+Q14+Q17+Q21 -> 2.0979925e+09 | ... AD27: =AD5+AD8+AD9+AD14+AD17+AD21 -> 4.1446316e+09
B28: Savings Deposits | K28: 319521.55 | L28: 13983820 | M28: 49599559 | N28: 54281773 | O28: 75270723 | P28: 1.4092141e+08 | Q28: 2.573535e+08 | R28: 1.5415079e+08 | S28: 1.4814507e+08 | T28: 1.7932285e+08 | U28: 1.9141829e+08 | V28: 1.8570586e+08 | W28: 1.9540497e+08 | X28: 195438509 | Y28: 1.8637761e+08 | Z28: 2.1125221e+08 | AA28: 2.4384265e+08 | AB28: 2.3917689e+08 | AC28: 2.3691099e+08 | AD28: 2.6955472e+08
B29: Short Term Deposits | L29: 10205 | M29: 12955 | N29: 19136 | O29: 20236 | P29: 49312 | Q29: 119512 | R29: 19512 | S29: 19512 | T29: 19512 | U29: 19512 | V29: 9512 | W29: 9512 | Y29: 9512 | Z29: 9512 | AA29: 9512 | AB29: 9512 | AC29: 9512 | AD29: 9512
B30: Non withdrawable Deposits | J30: 291131418 | K30: 926612134 | L30: 1.0137507e+09 | M30: 1.103747e+09 | N30: 1.050628e+09 | O30: 1.1557788e+09 | P30: 1.2593688e+09 | Q30: 1.3679773e+09 | R30: 1.4954133e+09 | S30: 1.6289172e+09 | T30: 1.7111129e+09 | U30: 1.8455846e+09 | V30: 1.9464446e+09 | W30: 2.0914307e+09 | X30: 2091506898 | Y30: 2.2312789e+09 | Z30: 2.3698231e+09 | AA30: 2.3117227e+09 | AB30: 2.4667379e+09 | AC30: 2.6122539e+09 | AD30: 2.7663758e+09
B31: Total Deposit Liabilities | J31: =J28+J29+J30 -> 291131418 | K31: =K28+K29+K30 -> 9.2693166e+08 | L31: =L28+L29+L30 -> 1.0277447e+09 | M31: =M28+M29+M30 -> 1.1533595e+09 | N31: =N28+N29+N30 -> 1.1049289e+09 | O31: =O28+O29+O30 -> 1.2310698e+09 | P31: =P28+P29+P30 -> 1.4003395e+09 | Q31: =Q28+Q29+Q30 -> 1.6254503e+09 | ... AD31: =AD28+AD29+AD30 -> 3.03594e+09
B32: Accounts Payable Other Liabilities | J32: =J33+J34+J35+J36+J37+J38 -> 117409937 | K32: =K33+K34+K35+K36+K37+K38 -> 95695469 | L32: =L33+L34+L35+L36+L37+L38 -> 99271776 | M32: =M33+M34+M35+M36+M37+M38 -> 85051193 | N32: =N33+N34+N35+N36+N37+N38 -> 83997975 | O32: =O33+O34+O35+O36+O37+O38 -> 88767715 | P32: =P33+P34+P35+P36+P37+P38 -> 93678348 | Q32: =Q33+Q34+Q35+Q36+Q37+Q38 -> 99278714 | ... AD32: =AD33+AD34+AD35+AD36+AD37+AD38 -> 1.7135978e+08
B33: Tax Payable | L33: 5893585.2 | M33: 5981502.2 | N33: 388478.63 | O33: 438731.05 | P33: 429410.19 | Q33: 667283.09 | R33: 795224.09 | S33: 810965.19 | T33: 885780.39 | U33: 860287.79 | V33: 879071.59 | W33: 916346.79 | Y33: 12378272 | Z33: 16133050 | AA33: 1312211 | AB33: 1096107.9 | AC33: 1171225.8 | AD33: 1425818
B34: Dividends Payable | J34: 2463184 | K34: =16452616+3074654 -> 19527270 | L34: 18769641 | M34: 57 | N34: 57 | O34: 57 | P34: 57 | Q34: 57 | R34: 57 | S34: 57 | T34: 57 | U34: 57 | V34: 57 | W34: 57 | X34: =19514754+52611583 -> 72126337 | Y34: 72126394 | Z34: 68520074 | AA34: 57 | AB34: 8390.35 | AC34: 57 | AD34: 57
B35: Deferred Tax Liability | L35: 0 | M35: 0 | N35: 0 | O35: 0 | P35: 0 | Q35: 0 | R35: 0 | S35: 0 | T35: 0 | U35: 0 | V35: 0 | W35: 0 | Y35: 0 | Z35: 0 | AA35: 0 | AB35: 0 | AC35: 0 | AD35: 0
B36: Retirement Benefits Liability | J36: 8735358 | L36: 0 | M36: 0 | N36: 0 | O36: 0 | P36: 0 | Q36: 0 | R36: 0 | S36: 0 | T36: 0 | U36: 0 | V36: 0 | W36: 0 | Y36: 0 | Z36: 0 | AA36: 0 | AB36: 0 | AC36: 0 | AD36: 0
B37: Other Liabilities | J37: =10378923+5832472 -> 16211395 | K37: =35636830+10531369 -> 46168199 | L37: 44608550 | M37: 49069634 | N37: 53609440 | O37: 58328927 | P37: 63248881 | Q37: 68611374 | R37: 76451239 | S37: 84690972 | T37: 92021462 | U37: 97818028 | V37: 93821000 | W37: 1.0549287e+08 | X37: =25147127+93295271 -> 118442398 | Y37: 1.1128224e+08 | Z37: 1.1695203e+08 | AA37: 1.2140631e+08 | AB37: 1.2341994e+08 | AC37: 1.2984475e+08 | AD37: 1.399339e+08
B38: External Borrowings | J38: 90000000 | K38: 30000000 | L38: 30000000 | M38: 30000000 | N38: 30000000 | O38: 30000000 | P38: 30000000 | Q38: 30000000 | R38: 30000000 | S38: 30000000 | T38: 30000000 | U38: 30000000 | V38: 30000000 | W38: 30000000 | X38: 30000000 | Y38: 30000000 | Z38: 30000000 | AA38: 30000000 | AB38: 30000000 | AC38: 30000000 | AD38: 30000000
B39: Total Liabilities | J39: =J31+J32 -> 408541355 | K39: =K31+K32 -> 1.0226271e+09 | L39: =L31+L32 -> 1.1270165e+09 | M39: =M31+M32 -> 1.2384107e+09 | N39: =N31+N32 -> 1.1889269e+09 | O39: =O31+O32 -> 1.3198375e+09 | P39: =P31+P32 -> 1.4940178e+09 | Q39: =Q31+Q32 -> 1.724729e+09 | ... AD39: =AD31+AD32 -> 3.2072998e+09
B40: Share Capital | J40: 43186838 | K40: 73760486 | L40: 73765486 | M40: 73796626 | N40: 225824998 | O40: 226402490 | P40: 232021774 | Q40: 2.3209907e+08 | R40: 2.3232325e+08 | S40: 2.3247503e+08 | T40: 2.8673854e+08 | U40: 2.9506328e+08 | V40: 3.3168816e+08 | W40: 3.37595e+08 | X40: 337595002 | Y40: 3.3826777e+08 | Z40: 3.3970426e+08 | AA40: 5.397673e+08 | AB40: 5.4092581e+08 | AC40: 5.5288937e+08 | AD40: 5.5391011e+08
B41: Capital Grants | L41: 31750000 | M41: 31750000 | N41: 31750000 | O41: 31750000 | P41: 31750000 | Q41: 31750000 | R41: 31750000 | S41: 31750000 | T41: 31750000 | U41: 31750000 | V41: 31750000 | W41: 31750000 | X41: 31750000 | Y41: 31750000 | Z41: 31750000 | AA41: 31750000 | AB41: 31750000 | AC41: 31750000 | AD41: 31750000
B42: Retained Earnings | J42: 5615976 | K42: =K43+K44 -> 32981843 | L42: =L43+L44 -> 39775842 | M42: =M43+M44 -> 49608677 | N42: =N43+N44 -> 59333428 | O42: =O43+O44 -> 63045553 | P42: =P43+P44 -> 70785145 | Q42: =Q43+Q44 -> 1.0076071e+08 | R42: =R43+R44 -> 1.2116468e+08 | ... AD42: =AD43+AD44 -> 3.1630583e+08
...

Sheet GDP
A1: Share of Financial Sector Total Assets to National GDP
A2: Year | B2: 2017 | D2: 2018 | F2: 2019 | H2: 2020
A3: Nominal GDP(Millions) | B3: 8144373 | D3: 8904984 | F3: 9740400 | H3: 10266381
A4: Industry/Indicator | B4: Total Assets KShs B) | C4: Share of GDP | D4: Total Assets KShs B) | E4: Share of GDP | F4: Total Assets KShs B) | G4: Share of GDP | H4: Total Assets KShs B) | I4: Share of GDP
A5: Banks excl MFB | B5: 4002.74 | C5: 49.15 | D5: 4408.59 | E5: 49.51 | F5: 4832.3 | G5: 49.61 | H5: 5420.1 | I5: 52.79
A6: Microfinance Banks | B6: 67.6 | C6: 0.83 | D6: 70.75 | E6: 0.79 | F6: 76.35 | G6: 0.78 | H6: 74.88 | I6: 0.73
A7: Insurance | B7: 590.95 | C7: 7.26 | D7: 637.41 | E7: 7.14 | F7: 705.84 | G7: 7.25 | H7: 761.34 | I7: 7.42
A8: Pension | B8: 1081.1 | C8: 13.27 | D8: 1166.34 | E8: 13.1 | F8: 1298.19 | G8: 13.33 | H8: 1398.95 | I8: 13.63
A9: SACCO's | B9: 442.9 | C9: 5.44 | D9: 493.82 | E9: 5.55 | F9: 556.71 | G9: 5.72 | H9: 627.68 | I9: 6.11

Sheet Sheet2
A1: KEY FINANCIAL SECTOR PERFORMANCE INDICATORS
B2: DT-SACCOS | E2: COMMERCIAL BANKS | H2: MICROFINANCE BANKS
A3: PARAMETER | B3: 2018 | C3: 2019 | D3: 2020 | E3: 2018 | F3: 2019 | G3: 2020 | H3: 2018 | I3: 2019 | J3: 2020
A4: No of Institutions | B4: 174 | C4: 172 | D4: 175 | E4: 40 | F4: 39 | G4: 39 | H4: 13 | I4: 14 | J4: 14
A5: No of branches | B5: 504 | C5: 526 | D5: 537 | E5: 1505 | F5: 1490 | G5: 1502 | H5: 118 | I5: 123 | J5: 120
A6: Total Asset (KShs B) | B6: 495.25 | C6: 556.71 | D6: 627.68 | E6: 4446.1 | F6: 4832.3 | G6: 5405.75 | H6: 70.75 | I6: 76.35 | J6: 74.88
A7: Gross Loans (KShs B) | B7: 374.28 | C7: 419.55 | D7: 473.74 | E7: 2567.3 | F7: 2774.6 | G7: 3006.1 | H7: 49.36 | I7: 50.45 | J7: 48.85
A8: Customer deposits | B8: 341.91 | C8: 380.44 | D8: 430.11 | E8: 3332.4 | F8: 3554.4 | G8: 4011.32 | H8: 40.96 | I8: 43.94 | J8: 49.36
A9: NPL | B9: 0.063 | C9: 0.0615 | D9: 0.0839 | E9: 0.1203 | F9: 0.1201 | G9: 0.145 | H9: 0.2004 | I9: 0.195 | J9: 0.266

Sheet Sheet4
A1: PARAMETER | B1: 2018 | C1: YtY % change | D1: 2019 | E1: YtY % change | F1: 2020
A2: No of DTS | B2: 174 | D2: 172 | F2: 175
A3: Total Assets | B3: 495.25 | C3: 0.1241 | D3: 556.71 | E3: 0.1275 | F3: 627.68
A4: Total Deposits | B4: 341.91 | C4: 0.1127 | D4: 380.44 | E4: 0.1341 | F4: 431.46
A5: Gross Loans | B5: 374.29 | C5: 0.1209 | D5: 419.55 | E5: 0.1316 | F5: 474.77
A6: Capital & Reserves | B6: 83.76 | C6: 0.1647 | D6: 97.55 | E6: 0.1818 | F6: 115.28
A7: Core Capital | B7: 74.37 | C7: 0.0649 | D7: 79.2 | E7: 0.2341 | F7: 97.74

Sheet FSI
A1: FINANCIAL SOUNDNESS INDICATORS | B1: Prescribed Minimum | C1: 2016 | D1: 2017 | E1: 2018 | F1: 2019 | G1: 2020
A2: CAPITAL ADEQUACY | B2: No of DTS | C2: 175 | D2: 174 | E2: 172 | F2: 172 | G2: 175
A3: Core Capital | B3: KShs 10 M | C3: 54.94 | D3: 64.25 | E3: 74.37 | F3: 79.2 | G3: 97.74
A4: Core Capital/Total Assets | B4: 0.1 | C4: 0.1396 | D4: 0.1453 | E4: 0.1502 | F4: 0.1423 | G4: 0.1557
A5: Core Capital/Total Deposits | B5: 0.08 | C5: 0.2016 | D5: 0.2105 | E5: 0.2175 | F5: 0.2082 | G5: 0.2265
A6: Institutional Capital/Total Assets | B6: 0.08 | C6: 0.0771 | D6: 0.0818 | E6: 0.085 | F6: 0.1063 | G6: 0.1139
A7: ASSET QUALITY
A8: Non-performing loans to Gross Loans | C8: 0.0523 | D8: 0.0614 | E8: 0.063 | F8: 0.0615 | G8: 0.0839
A9: NPL net of provisions to Core capital | C9: 0.0763 | D9: 0.099 | E9: 0.0927 | F9: 0.085 | G9: 0.1018
A10: Earning Assets to Total Assets | C10: 0.8071 | D10: 0.785 | E10: 0.7768 | F10: 0.769 | G10: 0.7962
A11: EARNING RATING
A12: Return on Assets | C12: 0.0245 | D12: 0.0269 | E12: 0.024 | F12: 0.026 | G12: 0.0265
A13: Cost Income ratio | C13: 0.628 | D13: 0.661 | E13: 0.621 | F13: 0.5767 | G13: 0.5672
A14: Operating Expense/Total Assets | C14: 0.0544 | D14: 0.0529 | E14: 0.0462 | F14: 0.0475 | G14: 0.045
A15: LIQUIDITY
A16: Liquid Assets/Short term Liabilities | C16: 0.4995 | D16: 0.541 | E16: 0.5268 | F16: 0.5092 | G16: 0.485
A17: Liquid Assets/Total Deposits | C17: 0.1805 | D17: 0.1717 | E17: 0.1705 | F17: 0.17 | G17: 0.2099
A18: Gross Loans/Total Deposits | C18: 1.0839 | D18: 0.1049 | E18: 1.0947 | F18: 1.1028 | G18: 1.1004

Sheet Financials
B2: DEFENCE SACCO FINANCIALS | I2: Base
B3: Year | C3: 2013 | D3: 2014 | E3: Audit 2015 | F3: Audit 2016 | G3: Audit 2017 | H3: Audit 2018 | I3: Audited 2020 | J3: Audited 2021 | K3: 44562 | L3: 44593 | M3: 44621 | N3: 44652 | O3: 44682 | P3: 44713 | Q3: 44743 | R3: 44774 | S3: 44805 | T3: 44835 | U3: 44866 | V3: 44896 | W3: Audited-2022 | X3: 44949 | Y3: 44980 | Z3: 45008 | AA3: 45039 | AB3: 45069 | AC3: 45100 | AD3: 45130 | AE3: 45161 | AF3: 45192
A4: 1 | B4: Membership | C4: 10344 | D4: 10824 | E4: 11521
A5: 2 | B5: Total Assets | C5: =Trend!C27 -> 0 | D5: =Trend!D27 -> 0 | E5: =Trend!E27 -> 0 | F5: =Trend!F27 -> 0 | G5: =Trend!G27 -> 0 | H5: =Trend!H27 -> 0 | I5: =Trend!J27 -> 459363957 | J5: =Trend!K27 -> 1.1708681e+09 | K5: =Trend!L27 -> 1.2819615e+09 | L5: =Trend!M27 -> 1.4032197e+09 | M5: =Trend!N27 -> 1.515489e+09 | N5: =Trend!O27 -> 1.6506892e+09 | O5: =Trend!P27 -> 1.8382284e+09 | P5: =Trend!Q27 -> 2.0979925e+09 | ... AC5: =Trend!AD27 -> 4.1446316e+09
A6: 3 | B6: Total Deposits | C6: =Trend!C31 -> 0 | D6: =Trend!D31 -> 0 | E6: =Trend!E31 -> 0 | F6: =Trend!F31 -> 0 | G6: =Trend!G31 -> 0 | H6: =Trend!H31 -> 0 | I6: =Trend!J31 -> 291131418 | J6: =Trend!K31 -> 9.2693166e+08 | K6: =Trend!L31 -> 1.0277447e+09 | L6: =Trend!M31 -> 1.1533595e+09 | M6: =Trend!N31 -> 1.1049289e+09 | N6: =Trend!O31 -> 1.2310698e+09 | O6: =Trend!P31 -> 1.4003395e+09 | P6: =Trend!Q31 -> 1.6254503e+09 | ... AC6: =Trend!AD31 -> 3.03594e+09
A7: 3.1 | B7: Deposits-Members(BOSA) | C7: =Trend!C30 -> 0 | D7: =Trend!D30 -> 0 | E7: =Trend!E30 -> 0 | F7: =Trend!F30 -> 0 | G7: =Trend!G30 -> 0 | H7: =Trend!H30 -> 0 | I7: =Trend!J30 -> 291131418 | J7: =Trend!K30 -> 926612134 | K7: =Trend!L30 -> 1.0137507e+09 | L7: =Trend!M30 -> 1.103747e+09 | M7: =Trend!N30 -> 1.050628e+09 | N7: =Trend!O30 -> 1.1557788e+09 | O7: =Trend!P30 -> 1.2593688e+09 | P7: =Trend!Q30 -> 1.3679773e+09 | ... AC7: =Trend!AD30 -> 2.7663758e+09
A8: 3.2 | B8: Deposits-Customers(FOSA) | C8: =Trend!C28 -> 0 | D8: =Trend!D28 -> 0 | E8: =Trend!E28 -> 0 | F8: =Trend!F28 -> 0 | G8: =Trend!G28 -> 0 | H8: =Trend!H28 -> 0 | I8: =Trend!J28 -> 0 | J8: =Trend!K28 -> 319521.55 | K8: =Trend!L28 -> 13983820 | L8: =Trend!M28 -> 49599559 | M8: =Trend!N28 -> 54281773 | N8: =Trend!O28 -> 75270723 | O8: =Trend!P28 -> 1.4092141e+08 | P8: =Trend!Q28 -> 2.573535e+08 | ... AC8: =Trend!AD28 -> 2.6955472e+08
A9: 4 | B9: External Borrowing | C9: =Trend!C38 -> 0 | D9: =Trend!D38 -> 0 | E9: =Trend!E38 -> 0 | F9: =Trend!F38 -> 0 | G9: =Trend!G38 -> 0 | H9: =Trend!H38 -> 0 | I9: =Trend!J38 -> 90000000 | J9: =Trend!K38 -> 30000000 | K9: =Trend!L38 -> 30000000 | L9: =Trend!M38 -> 30000000 | M9: =Trend!N38 -> 30000000 | N9: =Trend!O38 -> 30000000 | O9: =Trend!P38 -> 30000000 | P9: =Trend!Q38 -> 30000000 | ... AC9: =Trend!AD38 -> 30000000
A10: 4.1 | B10: Short term Liabilities | C10: =Trend!C33+Trend!C34+Trend!C35+Trend!C37 -> 0 | D10: =Trend!D33+Trend!D34+Trend!D35+Trend!D37 -> 0 | E10: =Trend!E33+Trend!E34+Trend!E35+Trend!E37 -> 0 | F10: =Trend!F33+Trend!F34+Trend!F35+Trend!F37 -> 0 | G10: =Trend!G33+Trend!G34+Trend!G35+Trend!G37 -> 0 | H10: =Trend!H33+Trend!H34+Trend!H35+Trend!H37 -> 0 | I10: =Trend!J33+Trend!J34+Trend!J35+Trend!J37 -> 18674579 | J10: =Trend!K33+Trend!K34+Trend!K35+Trend!K37 -> 65695469 | K10: =Trend!L33+Trend!L34+Trend!L35+Trend!L37 -> 69271776 | L10: =Trend!M33+Trend!M34+Trend!M35+Trend!M37 -> 55051193 | M10: =Trend!N33+Trend!N34+Trend!N35+Trend!N37 -> 53997975 | N10: =Trend!O33+Trend!O34+Trend!O35+Trend!O37 -> 58767715 | O10: =Trend!P33+Trend!P34+Trend!P35+Trend!P37 -> 63678348 | P10: =Trend!Q33+Trend!Q34+Trend!Q35+Trend!Q37 -> 69278714 | ... AC10: =Trend!AD33+Trend!AD34+Trend!AD35+Trend!AD37 -> 1.4135978e+08
A12: 5 | B12: Share capital and Reserves
A13: 5.1 | B13: Core Capital | C13: =C16-C28 -> 0 | D13: =D16-D28 -> 0 | E13: =E16-E28 -> 0 | F13: =F16-F28 -> 0 | G13: =G16-G28 -> 0 | H13: =H16-H28 -> 0 | I13: =I16-I28 -> 50822603 | J13: =J16-J28 -> 148240999 | ... AC13: =AC16-AC28 -> 8.5458182e+08
A14: 5.2 | B14: Institutional Capital | C14: =C13-C17 -> 0 | D14: =D13-D17 -> 0 | E14: =E13-E17 -> 0 | F14: =F13-F17 -> 0 | G14: =G13-G17 -> 0 | H14: =H13-H17 -> 0 | I14: =I13-I17 -> 7635765 | J14: =J13-J17 -> 74480513 | ... AC14: =AC13-AC17 -> 3.0067171e+08
A16: 5.3 | B16: Total Capital | C16: =SUM(C17:C20) -> 0 | D16: =SUM(D17:D20) -> 0 | E16: =SUM(E17:E20) -> 0 | F16: =SUM(F17:F20) -> 0 | G16: =SUM(G17:G20) -> 0 | H16: =SUM(H17:H20) -> 0 | I16: =SUM(I17:I20) -> 50822603 | J16: =SUM(J17:J20) -> 148240999 | ... AC16: =SUM(AC17:AC20) -> 9.0558182e+08
A17: 5.3.1 | B17: Members Share Capital | C17: =Trend!C40 -> 0 | D17: =Trend!D40 -> 0 | E17: =Trend!E40 -> 0 | F17: =Trend!F40 -> 0 | G17: =Trend!G40 -> 0 | H17: =Trend!H40 -> 0 | I17: =Trend!J40 -> 43186838 | J17: =Trend!K40 -> 73760486 | K17: =Trend!L40 -> 73765486 | L17: =Trend!M40 -> 73796626 | M17: =Trend!N40 -> 225824998 | N17: =Trend!O40 -> 226402490 | O17: =Trend!P40 -> 232021774 | P17: =Trend!Q40 -> 2.3209907e+08 | ... AC17: =Trend!AD40 -> 5.5391011e+08
A18: 5.3.3 | B18: Retained Earnings | C18: =Trend!C42 -> 0 | D18: =Trend!D42 -> 0 | E18: =Trend!E42 -> 0 | F18: =Trend!F42 -> 0 | G18: =Trend!G42 -> 0 | H18: =Trend!H42 -> 0 | I18: =Trend!J42 -> 5615976 | J18: =Trend!K42 -> 32981843 | K18: =Trend!L42 -> 39775842 | L18: =Trend!M42 -> 49608677 | M18: =Trend!N42 -> 59333428 | N18: =Trend!O42 -> 63045553 | O18: =Trend!P42 -> 70785145 | P18: =Trend!Q42 -> 1.0076071e+08 | ... AC18: =Trend!AD42 -> 3.1630583e+08
A19: 5.3.5 | B19: Statutory Reserves | C19: =Trend!C46 -> 0 | D19: =Trend!D46 -> 0 | E19: =Trend!E46 -> 0 | F19: =Trend!F46 -> 0 | G19: =Trend!G46 -> 0 | H19: =Trend!H46 -> 0 | I19: =Trend!J46 -> 2019789 | J19: =Trend!K46 -> 9748670 | K19: =Trend!L46 -> 9653670.2 | L19: =Trend!M46 -> 9653670.2 | M19: =Trend!N46 -> 9653670.2 | N19: =Trend!O46 -> 9653670.2 | O19: =Trend!P46 -> 9653670.2 | P19: =Trend!Q46 -> 9653670.2 | ... AC19: =Trend!AD46 -> 35365874
A20: 5.3.6 | B20: Capital Reserve | C20: =Trend!C47 -> 0 | D20: =Trend!D47 -> 0 | E20: =Trend!E47 -> 0 | F20: =Trend!F47 -> 0 | G20: =Trend!G47 -> 0 | H20: =Trend!H47 -> 0 | I20: =Trend!J47 -> 0 | J20: =Trend!K47 -> 31750000 | K20: =Trend!L47 -> 0 | L20: =Trend!M47 -> 0 | M20: =Trend!N47 -> 0 | N20: =Trend!O47 -> 0 | O20: =Trend!P47 -> 0 | P20: =Trend!Q47 -> 0 | ... AC20: =Trend!AD47 -> 0
A21: Capital grant | W21: 31750000
A22: 5.3.7 | B22: Supplementary Capital & reserves
A23: a | B23: Proposed Dividends | C23: =Trend!C69+Trend!C70 -> 0 | D23: =Trend!D69+Trend!D70 -> 0 | E23: =Trend!E69+Trend!E70 -> 0 | F23: =Trend!F69+Trend!F70 -> 0 | G23: =Trend!G69+Trend!G70 -> 0 | H23: =Trend!H69+Trend!H70 -> 0 | I23: =Trend!J69+Trend!J70 -> 13028923 | J23: =Trend!K69+Trend!K70 -> 17052616 | K23: =Trend!L69+Trend!L70 -> 0 | L23: =Trend!M69+Trend!M70 -> 0 | M23: =Trend!N69+Trend!N70 -> 0 | N23: =Trend!O69+Trend!O70 -> 0 | O23: =Trend!P69+Trend!P70 -> 0 | P23: =Trend!Q69+Trend!Q70 -> 0 | ... AC23: =Trend!AD69+Trend!AD70 -> 0
A24: b
A26: 6 | B26: Investments | C26: =SUM(C27:C28) -> 0 | D26: =SUM(D27:D28) -> 0 | E26: =SUM(E27:E28) -> 0 | F26: =SUM(F27:F28) -> 0 | G26: =SUM(G27:G28) -> 0 | H26: =SUM(H27:H28) -> 0 | I26: =SUM(I27:I28) -> 10000000 | J26: =SUM(J27:J28) -> 10000000 | ... AC26: =SUM(AC27:AC28) -> 51000000
A27: 6.1 | B27: Investments in Coop bank, CIC, Kuscco, Kerussu & Codic | C27: =Trend!C12 -> 0 | D27: =Trend!D12 -> 0 | E27: =Trend!E12 -> 0 | F27: =Trend!F12 -> 0 | G27: =Trend!G12 -> 0 | H27: =Trend!H12 -> 0 | I27: =Trend!J12 -> 10000000 | J27: =Trend!K12 -> 10000000 | K27: =Trend!L12 -> 50000000 | L27: =Trend!M12 -> 51582795 | M27: =Trend!N12 -> 51582795 | N27: =Trend!O12 -> 51582795 | O27: =Trend!P12 -> 51582795 | P27: =Trend!Q12 -> 53116127 | ... AC27: =Trend!AD12 -> 0
A28: 6.2 | B28: Equity Investments (at cost) | C28: =Trend!C13 -> 0 | D28: =Trend!D13 -> 0 | E28: =Trend!E13 -> 0 | F28: =Trend!F13 -> 0 | G28: =Trend!G13 -> 0 | H28: =Trend!H13 -> 0 | I28: =Trend!J13 -> 0 | J28: =Trend!K13 -> 0 | K28: =Trend!L13 -> 10000000 | L28: =Trend!M13 -> 10000000 | M28: =Trend!N13 -> 10000000 | N28: =Trend!O13 -> 10000000 | O28: =Trend!P13 -> 51000000 | P28: =Trend!Q13 -> 51000000 | ... AC28: =Trend!AD13 -> 51000000
A29: 6.3 | B29: Deposits in KUSCCO CFP
A31: 7 | B31: Net Loans & advances | C31: =C32-C33 -> 0 | D31: =D32-D33 -> 0 | E31: =E32-E33 -> 0 | F31: =F32-F33 -> 0 | G31: =G32-G33 -> 0 | H31: =H32-H33 -> 0 | I31: =I32-I33 -> 67566895 | J31: =J32-J33 -> 5.5293772e+08 | ... AC31: =AC32-AC33 -> 3.2002342e+09
A32: 7.1 | B32: Gross Loans & advances | C32: =+Trend!C15 -> 0 | D32: =+Trend!D15 -> 0 | E32: =+Trend!E15 -> 0 | F32: =+Trend!F15 -> 0 | G32: =+Trend!G15 -> 0 | H32: =+Trend!H15 -> 0 | I32: =+Trend!J15 -> 67566895 | J32: =+Trend!K15 -> 5.5293772e+08 | K32: =+Trend!L15 -> 6.0713821e+08 | L32: =+Trend!M15 -> 654081705 | M32: =+Trend!N15 -> 7.2585877e+08 | N32: =+Trend!O15 -> 8.2786399e+08 | O32: =+Trend!P15 -> 9.4205761e+08 | P32: =+Trend!Q15 -> 1.0602147e+09 | ... AC32: =+Trend!AD15 -> 3.2831912e+09
A33: 7.3 | B33: Allowance for loan losses | C33: =+Trend!C16 -> 0 | D33: =+Trend!D16 -> 0 | E33: =+Trend!E16 -> 0 | F33: =+Trend!F16 -> 0 | G33: =+Trend!G16 -> 0 | H33: =+Trend!H16 -> 0 | I33: =+Trend!J16 -> 0 | J33: =+Trend!K16 -> 0 | K33: =+Trend!L16 -> 11420371 | L33: =+Trend!M16 -> 14420371 | M33: =+Trend!N16 -> 18979978 | N33: =+Trend!O16 -> 23140824 | O33: =+Trend!P16 -> 28379254 | P33: =+Trend!Q16 -> 23451622 | ... AC33: =+Trend!AD16 -> 82956980
A34: 7.4 | B34: Non Performing Loans NPL30 | F34: 15659839 | G34: =9488181.59+650188.65+8950044.59 -> 19088415 | H34: =9488181.59+650188.65+8950044.59 -> 19088415
A35: 7.5666667 | B35: Non Performing Loans A/L NPL30
A36: 7.7166667 | B36: Required loan loss provision
A37: 7.8666667 | B37: Cash and Cash equipments | C37: =Trend!C5 -> 0 | D37: =Trend!D5 -> 0 | E37: =Trend!E5 -> 0 | F37: =Trend!F5 -> 0 | G37: =Trend!G5 -> 0 | H37: =Trend!H5 -> 0 | I37: =Trend!J5 -> 375933615 | J37: =Trend!K5 -> 583646239 | K37: =Trend!L5 -> 5.3005126e+08 | L37: =Trend!M5 -> 4.1482331e+08 | M37: =Trend!N5 -> 6.7492501e+08 | N37: =Trend!O5 -> 6.5037254e+08 | O37: =Trend!P5 -> 6.8629423e+08 | P37: =Trend!Q5 -> 7.0539082e+08 | ... AC37: =Trend!AD5 -> 8.2005767e+08
A39: 8 | B39: Non-Earning Assets | C39: =Trend!C8+Trend!C21 -> 0 | D39: =Trend!D8+Trend!D21 -> 0 | E39: =Trend!E8+Trend!E21 -> 0 | F39: =Trend!F8+Trend!F21 -> 0 | G39: =Trend!G8+Trend!G21 -> 0 | H39: =Trend!H8+Trend!H21 -> 0 | I39: =Trend!J8+Trend!J21 -> 5863447 | J39: =Trend!K8+Trend!K21 -> 24284162 | K39: =Trend!L8+Trend!L21 -> 24779370 | L39: =Trend!M8+Trend!M21 -> 2.1566836e+08 | M39: =Trend!N8+Trend!N21 -> 618454.57 | N39: =Trend!O8+Trend!O21 -> 2094825 | O39: =Trend!P8+Trend!P21 -> 3757175.1 | P39: =Trend!Q8+Trend!Q21 -> 1.1976176e+08 | ... AC39: =Trend!AD8+Trend!AD21 -> 9758571.4
A40: 8.1 | B40: Property and Equipment | C40: =Trend!C23 -> 0 | D40: =Trend!D23 -> 0 | E40: =Trend!E23 -> 0 | F40: =Trend!F23 -> 0 | G40: =Trend!G23 -> 0 | H40: =Trend!H23 -> 0 | I40: =Trend!J23 -> 0 | J40: =Trend!K23 -> 0 | K40: =Trend!L23 -> 0 | L40: =Trend!M23 -> 0 | M40: =Trend!N23 -> 0 | N40: =Trend!O23 -> 0 | O40: =Trend!P23 -> 0 | P40: =Trend!Q23 -> 0 | ... AC40: =Trend!AD23 -> 0
A41: 8.2 | B41: Land and Building
A43: 9 | B43: Turnover | C43: =C44+C45+C46 -> 0 | D43: =D44+D45+D46 -> 0 | E43: =E44+E45+E46 -> 0 | F43: =F44+F45+F46 -> 0 | G43: =G44+G45+G46 -> 0 | H43: =H44+H45+H46 -> 0 | I43: =I44+I45+I46 -> 26073627 | J43: =J44+J45+J46 -> 75147891 | ... AC43: =AC44+AC45+AC46 -> 2.5405281e+08
A44: 9.1 | B44: Loan Interest | C44: =Trend!C61 -> 0 | D44: =Trend!D61 -> 0 | E44: =Trend!E61 -> 0 | F44: =Trend!F61 -> 0 | G44: =Trend!G61 -> 0 | H44: =Trend!H61 -> 0 | I44: =Trend!J61 -> 2051377 | J44: =Trend!K61 -> 30031682 | K44: =Trend!L61 -> 5791010 | L44: =Trend!M61 -> 12004631 | M44: =Trend!N61 -> 18456061 | N44: =Trend!O61 -> 26231070 | O44: =Trend!P61 -> 34864959 | P44: =Trend!Q61 -> 44097122 | ... AC44: =Trend!AD61 -> 1.8222278e+08
B45: Income from investments | C45: =Trend!C62 -> 0 | D45: =Trend!D62 -> 0 | E45: =Trend!E62 -> 0 | F45: =Trend!F62 -> 0 | G45: =Trend!G62 -> 0 | H45: =Trend!H62 -> 0 | I45: =Trend!J62 -> 0 | J45: =Trend!K62 -> 0 | K45: =Trend!L62 -> 596470 | L45: =Trend!M62 -> 1283490 | M45: =Trend!N62 -> 2143432 | N45: =Trend!O62 -> 3243754.1 | O45: =Trend!P62 -> 4481696.4 | P45: =Trend!Q62 -> 5806191.4 | ... AC45: =Trend!AD62 -> 20129664
A46: 9.2 | B46: Fees & Commissions | C46: =Trend!C63 -> 0 | D46: =Trend!D63 -> 0 | E46: =Trend!E63 -> 0 | F46: =Trend!F63 -> 0 | G46: =Trend!G63 -> 0 | H46: =Trend!H63 -> 0 | I46: =Trend!J63 -> 24022250 | J46: =Trend!K63 -> 45116209 | K46: =Trend!L63 -> 3456641.8 | L46: =Trend!M63 -> 10019741 | M46: =Trend!N63 -> 17563406 | N46: =Trend!O63 -> 22167160 | O46: =Trend!P63 -> 28521731 | P46: =Trend!Q63 -> 44814404 | ... AC46: =Trend!AD63 -> 51700363
B47: Average yield on loans | C47: =C44/C32 -> #DIV/0! | D47: =D44/D32 -> #DIV/0! | E47: =E44/E32 -> #DIV/0! | F47: =F44/F32 -> #DIV/0! | G47: =G44/G32 -> #DIV/0! | H47: =H44/H32 -> #DIV/0! | I47: =I44/I32 -> 0.030360682 | J47: =J44/J32 -> 0.054312955 | ... AC47: =AC44/AC32 -> 0.055501726
...

Sheet Prudential Ratios
B2: DEFENCE SACCO
B3: FINANCIAL SOUNDNESS INDICATORS | C3: Prude. Std | D3: Ref. # | E3: 2013 | F3: 2014 | G3: 2015 | H3: Audit 2016 | I3: Audit 2017 | J3: AUDIT 2018 | K3: Audited 2020 | L3: Audited 2021 | M3: 44562 | N3: 44593 | O3: 44621 | P3: 44682 | Q3: 44713 | R3: 44743 | S3: 44652 | T3: 44774 | U3: 44805 | V3: 44835 | W3: 44866 | X3: 44896 | Y3: Audited-2022 | Z3: 44949 | AA3: 44980 | AB3: 45008 | AC3: 45039 | AD3: 45069 | AE3: 45100 | AF3: 45130 | AG3: 45161 | AH3: 45192 | AI3: 45222
A4: 1 | B4: CAPITAL ADEQUACY REQUIREMENTS
A5: 1.1 | B5: Core capital | C5: ≥ Ksh.10M | D5: 9.a | E5: =Financials!C13/1000000 -> 0 | F5: =Financials!D13/1000000 -> 0 | G5: =Financials!E13/1000000 -> 0 | H5: =Financials!F13/1000000 -> 0 | I5: =Financials!G13/1000000 -> 0 | J5: =Financials!H13/1000000 -> 0 | K5: =Financials!I13/1000000 -> 50.822603 | L5: =Financials!J13/1000000 -> 148.241 | ... O5: =Financials!M13/1000000 -> 284.8121 | P5: =Financials!O13/1000000 -> 261.46059 | Q5: =Financials!P13/1000000 -> 291.51345 | R5: =Financials!Q13/1000000 -> 312.1416 | S5: =Financials!N13/1000000 -> 289.10171 | T5: =Financials!R13/1000000 -> 326.88847 | U5: =Financials!S13/1000000 -> 404.19952 | V5: =Financials!T13/1000000 -> 433.52966 | W5: =Financials!U13/1000000 -> 501.7477 | X5: =Financials!V13/1000000 -> 522.18035 | Y5: =Financials!W13/1000000 -> 489.37178 | Z5: =Financials!X13/1000000 -> 459.41448 | AA5: =Financials!Y13/1000000 -> 496.76393 | ... AE5: =Financials!AC13/1000000 -> 854.58182
A6: 1.2 | B6: Core capital /Total Assets | C6: ≥ 10% | D6: 9.b | E6: =Financials!C13/Financials!C5 -> #DIV/0! | F6: =Financials!D13/Financials!D5 -> #DIV/0! | G6: =Financials!E13/Financials!E5 -> #DIV/0! | H6: =Financials!F13/Financials!F5 -> #DIV/0! | I6: =Financials!G13/Financials!G5 -> #DIV/0! | J6: =Financials!H13/Financials!H5 -> #DIV/0! | K6: =Financials!I13/Financials!I5 -> 0.1106369 | L6: =Financials!J13/Financials!J5 -> 0.12660777 | ... O6: =Financials!M13/Financials!M5 -> 0.18793413 | P6: =Financials!O13/Financials!O5 -> 0.14223509 | Q6: =Financials!P13/Financials!P5 -> 0.13894876 | R6: =Financials!Q13/Financials!Q5 -> 0.14506597 | S6: =Financials!N13/Financials!N5 -> 0.17514001 | T6: =Financials!R13/Financials!R5 -> 0.14198824 | U6: =Financials!S13/Financials!S5 -> 0.16165963 | V6: =Financials!T13/Financials!T5 -> 0.16164535 | W6: =Financials!U13/Financials!U5 -> 0.17721098 | X6: =Financials!V13/Financials!V5 -> 0.17244005 | Y6: =Financials!W13/Financials!W5 -> 0.16158158 | Z6: =Financials!X13/Financials!X5 -> 0.14421521 | AA6: =Financials!Y13/Financials!Y5 -> 0.14644283 | ... AE6: =Financials!AC13/Financials!AC5 -> 0.20619006
A7: 1.3 | B7: Core capital /Total Deposits | C7: ≥ 8% | D7: 9.d | E7: =Financials!C13/Financials!C6 -> #DIV/0! | F7: =Financials!D13/Financials!D6 -> #DIV/0! | G7: =Financials!E13/Financials!E6 -> #DIV/0! | H7: =Financials!F13/Financials!F6 -> #DIV/0! | I7: =Financials!G13/Financials!G6 -> #DIV/0! | J7: =Financials!H13/Financials!H6 -> #DIV/0! | K7: =Financials!I13/Financials!I6 -> 0.17456928 | L7: =Financials!J13/Financials!J6 -> 0.15992657 | ... O7: =Financials!M13/Financials!M6 -> 0.25776509 | P7: =Financials!O13/Financials!O6 -> 0.18671229 | Q7: =Financials!P13/Financials!P6 -> 0.1793432 | R7: =Financials!Q13/Financials!Q6 -> 0.18922448 | S7: =Financials!N13/Financials!N6 -> 0.2348378 | T7: =Financials!R13/Financials!R6 -> 0.18394678 | U7: =Financials!S13/Financials!S6 -> 0.21381068 | V7: =Financials!T13/Financials!T6 -> 0.21282519 | W7: =Financials!U13/Financials!U6 -> 0.23532367 | X7: =Financials!V13/Financials!V6 -> 0.22834093 | Y7: =Financials!W13/Financials!W6 -> 0.2139849 | Z7: =Financials!X13/Financials!X6 -> 0.19002397 | AA7: =Financials!Y13/Financials!Y6 -> 0.19246323 | ... AE7: =Financials!AC13/Financials!AC6 -> 0.28148838
A8: 1.4 | B8: Share Capital/Total Assets | C8: ≤2% | D8: 9.c | E8: =Financials!C17/Financials!C5 -> #DIV/0! | F8: =Financials!D17/Financials!D5 -> #DIV/0! | G8: =Financials!E17/Financials!E5 -> #DIV/0! | H8: =Financials!F17/Financials!F5 -> #DIV/0! | I8: =Financials!G17/Financials!G5 -> #DIV/0! | J8: =Financials!H17/Financials!H5 -> #DIV/0! | K8: =Financials!I17/Financials!I5 -> 0.094014424 | L8: =Financials!J17/Financials!J5 -> 0.062996408 | ... O8: =Financials!M17/Financials!M5 -> 0.14901131 | P8: =Financials!O17/Financials!O5 -> 0.12622032 | Q8: =Financials!P17/Financials!P5 -> 0.11062913 | R8: =Financials!Q17/Financials!Q5 -> 0.10797086 | S8: =Financials!N17/Financials!N5 -> 0.13715634 | T8: =Financials!R17/Financials!R5 -> 0.10097853 | U8: =Financials!S17/Financials!S5 -> 0.1146811 | V8: =Financials!T17/Financials!T5 -> 0.11001694 | W8: =Financials!U17/Financials!U5 -> 0.11714809 | X8: =Financials!V17/Financials!V5 -> 0.11148428 | Y8: =Financials!W17/Financials!W5 -> 0.11146767 | Z8: =Financials!X17/Financials!X5 -> 0.10618594 | AA8: =Financials!Y17/Financials!Y5 -> 0.10014264 | ... AE8: =Financials!AC17/Financials!AC5 -> 0.1336452
A9: 1.5 | B9: Institutional Capital/Total Assets | C9: ≥ 8% | D9: 9.c | E9: =Financials!C14/Financials!C5 -> #DIV/0! | F9: =Financials!D14/Financials!D5 -> #DIV/0! | G9: =Financials!E14/Financials!E5 -> #DIV/0! | H9: =Financials!F14/Financials!F5 -> #DIV/0! | I9: =Financials!G14/Financials!G5 -> #DIV/0! | J9: =Financials!H14/Financials!H5 -> #DIV/0! | K9: =Financials!I14/Financials!I5 -> 0.016622473 | L9: =Financials!J14/Financials!J5 -> 0.063611359 | ... O9: =Financials!M14/Financials!M5 -> 0.038922816 | P9: =Financials!O14/Financials!O5 -> 0.016014775 | Q9: =Financials!P14/Financials!P5 -> 0.028319635 | R9: =Financials!Q14/Financials!Q5 -> 0.037095108 | S9: =Financials!N14/Financials!N5 -> 0.037983664 | T9: =Financials!R14/Financials!R5 -> 0.041009701 | U9: =Financials!S14/Financials!S5 -> 0.046978529 | V9: =Financials!T14/Financials!T5 -> 0.051628409 | W9: =Financials!U14/Financials!U5 -> 0.060062893 | X9: =Financials!V14/Financials!V5 -> 0.060955773 | Y9: =Financials!W14/Financials!W5 -> 0.050113906 | Z9: =Financials!X14/Financials!X5 -> 0.038029274 | AA9: =Financials!Y14/Financials!Y5 -> 0.046300183 | ... AE9: =Financials!AC14/Financials!AC5 -> 0.072544857
A10: 2 | B10: ASSET MIX AND QUALITY
A11: 2.1 | B11: Non Earning Assets
A12: 2.1.1 | B12: Non earning Assets/Total assets | C12: ≤ 10% | D12: 48.1 | E12: =Financials!C39/Financials!C5 -> #DIV/0! | F12: =Financials!D39/Financials!D5 -> #DIV/0! | G12: =Financials!E39/Financials!E5 -> #DIV/0! | H12: =Financials!F39/Financials!F5 -> #DIV/0! | I12: =Financials!G39/Financials!G5 -> #DIV/0! | J12: =Financials!H39/Financials!H5 -> #DIV/0! | K12: =Financials!I39/Financials!I5 -> 0.012764273 | L12: =Financials!J39/Financials!J5 -> 0.020740305 | ... O12: =Financials!M39/Financials!M5 -> 0.00040808913 | P12: =Financials!O39/Financials!O5 -> 0.0020439109 | Q12: =Financials!P39/Financials!P5 -> 0.057083981 | R12: =Financials!Q39/Financials!Q5 -> 0.22931812 | S12: =Financials!N39/Financials!N5 -> 0.0012690609 | T12: =Financials!R39/Financials!R5 -> 0.0026702404 | U12: =Financials!S39/Financials!S5 -> 0.0033520511 | V12: =Financials!T39/Financials!T5 -> 0.0044483317 | W12: =Financials!U39/Financials!U5 -> 0.0048071812 | X12: =Financials!V39/Financials!V5 -> 0.20858308 | Y12: =Financials!W39/Financials!W5 -> 0.20844182 | Z12: =Financials!X39/Financials!X5 -> 0.0019250897 | AA12: =Financials!Y39/Financials!Y5 -> 0.0021515992 | ... AE12: =Financials!AC39/Financials!AC5 -> 0.0023545088
A13: 2.1.2 | B13: Property and Equipment/Total Assets | C13: ≤ 5% | D13: 48.1 | E13: =Financials!C40/Financials!C5 -> #DIV/0! | F13: =Financials!D40/Financials!D5 -> #DIV/0! | G13: =Financials!E40/Financials!E5 -> #DIV/0! | H13: =Financials!F40/Financials!F5 -> #DIV/0! | I13: =Financials!G40/Financials!G5 -> #DIV/0! | J13: =Financials!H40/Financials!H5 -> #DIV/0! | K13: =Financials!I40/Financials!I5 -> 0 | L13: =Financials!J40/Financials!J5 -> 0 | ... O13: =Financials!M40/Financials!M5 -> 0 | P13: =Financials!O40/Financials!O5 -> 0 | Q13: =Financials!P40/Financials!P5 -> 0 | R13: =Financials!Q40/Financials!Q5 -> 0 | S13: =Financials!N40/Financials!N5 -> 0 | T13: =Financials!R40/Financials!R5 -> 0 | U13: =Financials!S40/Financials!S5 -> 0 | V13: =Financials!T40/Financials!T5 -> 0 | W13: =Financials!U40/Financials!U5 -> 0 | X13: =Financials!V40/Financials!V5 -> 0 | Y13: =Financials!W40/Financials!W5 -> 0 | Z13: =Financials!X40/Financials!X5 -> 0 | AA13: =Financials!Y40/Financials!Y5 -> 0 | ... AE13: =Financials!AC40/Financials!AC5 -> 0
A14: 2.1.3 | B14: Non Performing loans/Gross Loans | C14: ≤ 6% | D14: 41 | E14: =Financials!C34/Financials!C32 -> #DIV/0! | F14: =Financials!D34/Financials!D32 -> #DIV/0! | G14: =Financials!E34/Financials!E32 -> #DIV/0! | H14: =Financials!F34/Financials!F32 -> #DIV/0! | I14: =Financials!G34/Financials!G32 -> #DIV/0! | J14: =Financials!H34/Financials!H32 -> #DIV/0! | K14: =Financials!I34/Financials!I32 -> 0 | L14: =Financials!J34/Financials!J32 -> 0 | ... O14: =Financials!M34/Financials!M32 -> 0 | P14: =Financials!O34/Financials!O32 -> 0 | Q14: =Financials!P34/Financials!P32 -> 0 | R14: =Financials!Q34/Financials!Q32 -> 0 | S14: =Financials!N34/Financials!N32 -> 0 | T14: =Financials!R34/Financials!R32 -> 0 | U14: =Financials!S34/Financials!S32 -> 0 | V14: =Financials!T34/Financials!T32 -> 0 | W14: =Financials!U34/Financials!U32 -> 0 | X14: =Financials!V34/Financials!V32 -> 0 | Y14: =Financials!W34/Financials!W32 -> 0 | Z14: =Financials!X34/Financials!X32 -> 0 | AA14: =Financials!Y34/Financials!Y32 -> 0 | ... AE14: =Financials!AC34/Financials!AC32 -> 0
A15: 2.2 | B15: Earning Assets
A16: 2.2.1 | B16: Equities & Investments/Deposits | C16: ≤ 5% | D16: 48.4 | E16: =Financials!C26/Financials!C6 -> #DIV/0! | F16: =Financials!D26/Financials!D6 -> #DIV/0! | G16: =Financials!E26/Financials!E6 -> #DIV/0! | H16: =Financials!F26/Financials!F6 -> #DIV/0! | I16: =Financials!G26/Financials!G6 -> #DIV/0! | J16: =Financials!H26/Financials!H6 -> #DIV/0! | K16: =Financials!I26/Financials!I6 -> 0.034348749 | L16: =Financials!J26/Financials!J6 -> 0.010788282 | ... O16: =Financials!M26/Financials!M6 -> 0.055734623 | P16: =Financials!O26/Financials!O6 -> 0.073255662 | Q16: =Financials!P26/Financials!P6 -> 0.064053713 | R16: =Financials!Q26/Financials!Q6 -> 0.030916893 | S16: =Financials!N26/Financials!N6 -> 0.050023806 | T16: =Financials!R26/Financials!R6 -> 0.028698736 | U16: =Financials!S26/Financials!S6 -> 0.053426284 | V16: =Financials!T26/Financials!T6 -> 0.049582175 | W16: =Financials!U26/Financials!U6 -> 0.047369805 | X16: =Financials!V26/Financials!V6 -> 0.044165648 | Y16: =Financials!W26/Financials!W6 -> 0.022300489 | Z16: =Financials!X26/Financials!X6 -> 0.042400915 | AA16: =Financials!Y26/Financials!Y6 -> 0.039716343 | ... AE16: =Financials!AC26/Financials!AC6 -> 0.016798751
A17: 2.2.2 | B17: Equities & Investments/Core Capital | C17: ≤ 40% | D17: 48.4 | E17: =Financials!C26/Financials!C13 -> #DIV/0! | F17: =Financials!D26/Financials!D13 -> #DIV/0! | G17: =Financials!E26/Financials!E13 -> #DIV/0! | H17: =Financials!F26/Financials!F13 -> #DIV/0! | I17: =Financials!G26/Financials!G13 -> #DIV/0! | J17: =Financials!H26/Financials!H13 -> #DIV/0! | K17: =Financials!I26/Financials!I13 -> 0.19676285 | L17: =Financials!J26/Financials!J13 -> 0.067457721 | ... O17: =Financials!M26/Financials!M13 -> 0.21622254 | P17: =Financials!O26/Financials!O13 -> 0.39234515 | Q17: =Financials!P26/Financials!P13 -> 0.35715719 | R17: =Financials!Q26/Financials!Q13 -> 0.16338738 | S17: =Financials!N26/Financials!N13 -> 0.21301429 | T17: =Financials!R26/Financials!R13 -> 0.15601652 | U17: =Financials!S26/Financials!S13 -> 0.24987659 | V17: =Financials!T26/Financials!T13 -> 0.23297137 | W17: =Financials!U26/Financials!U13 -> 0.20129639 | X17: =Financials!V26/Financials!V13 -> 0.19341976 | Y17: =Financials!W26/Financials!W13 -> 0.10421525 | Z17: =Financials!X26/Financials!X13 -> 0.22313456 | AA17: =Financials!Y26/Financials!Y13 -> 0.20635808 | ... AE17: =Financials!AC26/Financials!AC13 -> 0.059678312
A18: 2.2.3 | B18: Net Loans & advances /Total assets | C18: NPR | E18: =Financials!C31/Financials!C5 -> #DIV/0! | F18: =Financials!D31/Financials!D5 -> #DIV/0! | G18: =Financials!E31/Financials!E5 -> #DIV/0! | H18: =Financials!F31/Financials!F5 -> #DIV/0! | I18: =Financials!G31/Financials!G5 -> #DIV/0! | J18: =Financials!H31/Financials!H5 -> #DIV/0! | K18: =Financials!I31/Financials!I5 -> 0.14708793 | L18: =Financials!J31/Financials!J5 -> 0.47224595 | ... O18: =Financials!M31/Financials!M5 -> 0.46643612 | P18: =Financials!O31/Financials!O5 -> 0.49704289 | Q18: =Financials!P31/Financials!P5 -> 0.49416912 | R18: =Financials!Q31/Financials!Q5 -> 0.53548642 | S18: =Financials!N31/Financials!N5 -> 0.48750738 | T18: =Financials!R31/Financials!R5 -> 0.55578899 | U18: =Financials!S31/Financials!S5 -> 0.57021805 | V18: =Financials!T31/Financials!T5 -> 0.5905326 | W18: =Financials!U31/Financials!U5 -> 0.61882805 | X18: =Financials!V31/Financials!V5 -> 0.6339233 | Y18: =Financials!W31/Financials!W5 -> 0.63384066 | Z18: =Financials!X31/Financials!X5 -> 0.66006828 | AA18: =Financials!Y31/Financials!Y5 -> 0.67610121 | ... AE18: =Financials!AC31/Financials!AC5 -> 0.77213961
A19: 3 | B19: FUNDING MIX
A20: 3.1 | B20: Total Deposits/Total Assets | C20: NPR | E20: =Financials!C6/Financials!C5 -> #DIV/0! | F20: =Financials!D6/Financials!D5 -> #DIV/0! | G20: =Financials!E6/Financials!E5 -> #DIV/0! | H20: =Financials!F6/Financials!F5 -> #DIV/0! | I20: =Financials!G6/Financials!G5 -> #DIV/0! | J20: =Financials!H6/Financials!H5 -> #DIV/0! | K20: =Financials!I6/Financials!I5 -> 0.6337707 | L20: =Financials!J6/Financials!J5 -> 0.79166187 | ... O20: =Financials!M6/Financials!M5 -> 0.72909069 | P20: =Financials!O6/Financials!O5 -> 0.76178753 | Q20: =Financials!P6/Financials!P5 -> 0.7747646 | R20: =Financials!Q6/Financials!Q5 -> 0.76663426 | S20: =Financials!N6/Financials!N5 -> 0.74579137 | T20: =Financials!R6/Financials!R5 -> 0.77189845 | U20: =Financials!S6/Financials!S5 -> 0.75608772 | V20: =Financials!T6/Financials!T5 -> 0.75952172 | W20: =Financials!U6/Financials!U5 -> 0.75305211 | X20: =Financials!V6/Financials!V5 -> 0.7551868 | Y20: =Financials!W6/Financials!W5 -> 0.7551074 | Z20: =Financials!X6/Financials!X5 -> 0.75893169 | AA20: =Financials!Y6/Financials!Y5 -> 0.76088728 | ... AE20: =Financials!AC6/Financials!AC5 -> 0.73249936
A21: 3.1.1 | B21: BOSA Deposits/Total Assets | C21: NPR | E21: =Financials!C7/Financials!C5 -> #DIV/0! | F21: =Financials!D7/Financials!D5 -> #DIV/0! | G21: =Financials!E7/Financials!E5 -> #DIV/0! | H21: =Financials!F7/Financials!F5 -> #DIV/0! | I21: =Financials!G7/Financials!G5 -> #DIV/0! | J21: =Financials!H7/Financials!H5 -> #DIV/0! | K21: =Financials!I7/Financials!I5 -> 0.6337707 | L21: =Financials!J7/Financials!J5 -> 0.79138898 | ... O21: =Financials!M7/Financials!M5 -> 0.69326007 | P21: =Financials!O7/Financials!O5 -> 0.68509917 | Q21: =Financials!P7/Financials!P5 -> 0.65204108 | R21: =Financials!Q7/Financials!Q5 -> 0.69498452 | S21: =Financials!N7/Financials!N5 -> 0.70017954 | T21: =Financials!R7/Financials!R5 -> 0.70754124 | U21: =Financials!S7/Financials!S5 -> 0.68435973 | V21: =Financials!T7/Financials!T5 -> 0.68814245 | W21: =Financials!U7/Financials!U5 -> 0.68745978 | X21: =Financials!V7/Financials!V5 -> 0.69065491 | Y21: =Financials!W7/Financials!W5 -> 0.69057719 | Z21: =Financials!X7/Financials!X5 -> 0.70042274 | AA21: =Financials!Y7/Financials!Y5 -> 0.69860868 | ... AE21: =Financials!AC7/Financials!AC5 -> 0.66745999
A22: 3.1.2 | B22: FOSA Deposits/Total Assets | C22: NPR | E22: =Financials!C8/Financials!C5 -> #DIV/0! | F22: =Financials!D8/Financials!D5 -> #DIV/0! | G22: =Financials!E8/Financials!E5 -> #DIV/0! | H22: =Financials!F8/Financials!F5 -> #DIV/0! | I22: =Financials!G8/Financials!G5 -> #DIV/0! | J22: =Financials!H8/Financials!H5 -> #DIV/0! | K22: =Financials!I8/Financials!I5 -> 0 | L22: =Financials!J8/Financials!J5 -> 0.00027289286 | ... O22: =Financials!M8/Financials!M5 -> 0.035817993 | P22: =Financials!O8/Financials!O5 -> 0.076661535 | Q22: =Financials!P8/Financials!P5 -> 0.12266655 | R22: =Financials!Q8/Financials!Q5 -> 0.071640673 | S22: =Financials!N8/Financials!N5 -> 0.045599574 | T22: =Financials!R8/Financials!R5 -> 0.064348728 | U22: =Financials!S8/Financials!S5 -> 0.071720186 | V22: =Financials!T8/Financials!T5 -> 0.071371995 | W22: =Financials!U8/Financials!U5 -> 0.065588976 | X22: =Financials!V8/Financials!V5 -> 0.064528745 | Y22: =Financials!W8/Financials!W5 -> 0.064530209 | Z22: =Financials!X8/Financials!X5 -> 0.058505963 | AA22: =Financials!Y8/Financials!Y5 -> 0.0622758 | ... AE22: =Financials!AC8/Financials!AC5 -> 0.065037077
A23: 3.2 | B23: External Borrowing/Total assets | C23: ≤ 25% | D23: 35.1 | E23: =Financials!C9/Financials!C5 -> #DIV/0! | F23: =Financials!D9/Financials!D5 -> #DIV/0! | G23: =Financials!E9/Financials!E5 -> #DIV/0! | H23: =Financials!F9/Financials!F5 -> #DIV/0! | I23: =Financials!G9/Financials!G5 -> #DIV/0! | J23: =Financials!H9/Financials!H5 -> #DIV/0! | K23: =Financials!I9/Financials!I5 -> 0.19592308 | L23: =Financials!J9/Financials!J5 -> 0.025622014 | ... O23: =Financials!M9/Financials!M5 -> 0.019795591 | P23: =Financials!O9/Financials!O5 -> 0.016320061 | Q23: =Financials!P9/Financials!P5 -> 0.014299384 | R23: =Financials!Q9/Financials!Q5 -> 0.013942323 | S23: =Financials!N9/Financials!N5 -> 0.018174227 | T23: =Financials!R9/Financials!R5 -> 0.013030888 | U23: =Financials!S9/Financials!S5 -> 0.011998502 | V23: =Financials!T9/Financials!T5 -> 0.011185764 | W23: =Financials!U9/Financials!U5 -> 0.010595623 | X23: =Financials!V9/Financials!V5 -> 0.0099069251 | Y23: =Financials!W9/Financials!W5 -> 0.0099054494 | Z23: =Financials!X9/Financials!X5 -> 0.0094173268 | AA23: =Financials!Y9/Financials!Y5 -> 0.0088438081 | ... AE23: =Financials!AC9/Financials!AC5 -> 0.007238279
A24: 4 | B24: GROWTH RATIOS
A25: 4.1 | B25: Total Assets | C25: NPR | E25: =Financials!C5/Financials!#REF!-1 -> #REF! | F25: =Financials!D5/Financials!C5-1 -> #DIV/0! | G25: =Financials!E5/Financials!D5-1 -> #DIV/0! | H25: =Financials!F5/Financials!E5-1 -> #DIV/0! | I25: =Financials!G5/Financials!F5-1 -> #DIV/0! | J25: =Financials!H5/Financials!G5-1 -> #DIV/0! | K25: =Financials!I5/Financials!H5-1 -> #DIV/0! | L25: =Financials!J5/Financials!H5-1 -> #DIV/0! | M25: =Financials!K5/Financials!I5-1 -> 1.7907316 | N25: =Financials!L5/Financials!J5-1 -> 0.19844384 | O25: =Financials!M5/Financials!K5-1 -> 0.18216417 | P25: =Financials!O5/Financials!M5-1 -> 0.21296061 | Q25: =Financials!P5/Financials!N5-1 -> 0.27097971 | R25: =Financials!Q5/Financials!O5-1 -> 0.170541 | S25: =Financials!N5/Financials!L5-1 -> 0.17635833 | T25: =Financials!R5/Financials!P5-1 -> 0.097345327 | U25: =Financials!S5/Financials!Q5-1 -> 0.16200532 | V25: =Financials!T5/Financials!R5-1 -> 0.16495287 | W25: =Financials!U5/Financials!S5-1 -> 0.13240174 | X25: =Financials!V5/Financials!T5-1 -> 0.12908536 | Y25: =Financials!W5/Financials!U5-1 -> 0.069676166 | Z25: =Financials!X5/Financials!V5-1 -> 0.051989087 | AA25: =Financials!Y5/Financials!W5-1 -> 0.12004347 | ... AE25: =Financials!AC5/Financials!AA5-1 -> 0.12031341
A26: 4.2 | B26: Total Deposits | C26: NPR | E26: =Financials!C6/Financials!#REF!-1 -> #REF! | F26: =Financials!D6/Financials!C6-1 -> #DIV/0! | G26: =Financials!E6/Financials!D6-1 -> #DIV/0! | H26: =Financials!F6/Financials!E6-1 -> #DIV/0! | I26: =Financials!G6/Financials!F6-1 -> #DIV/0! | J26: =Financials!H6/Financials!G6-1 -> #DIV/0! | K26: =Financials!I6/Financials!H6-1 -> #DIV/0! | L26: =Financials!J6/Financials!H6-1 -> #DIV/0! | M26: =Financials!K6/Financials!I6-1 -> 2.5301746 | N26: =Financials!L6/Financials!J6-1 -> 0.24427677 | O26: =Financials!M6/Financials!K6-1 -> 0.075100511 | P26: =Financials!O6/Financials!M6-1 -> 0.2673571 | Q26: =Financials!P6/Financials!N6-1 -> 0.32035596 | R26: =Financials!Q6/Financials!O6-1 -> 0.17798835 | S26: =Financials!N6/Financials!L6-1 -> 0.067377278 | T26: =Financials!R6/Financials!P6-1 -> 0.093285822 | U26: =Financials!S6/Financials!Q6-1 -> 0.14601968 | V26: =Financials!T6/Financials!R6-1 -> 0.14627386 | W26: =Financials!U6/Financials!S6-1 -> 0.12785527 | X26: =Financials!V6/Financials!T6-1 -> 0.12264118 | Y26: =Financials!W6/Financials!U6-1 -> 0.072595616 | Z26: =Financials!X6/Financials!V6-1 -> 0.057205791 | AA26: =Financials!Y6/Financials!W6-1 -> 0.12861671 | ... AE26: =Financials!AC6/Financials!AA6-1 -> 0.12196045
A27: 4.2.1 | B27: FOSA Deposits | C27: NPR | E27: =Financials!C8/Financials!#REF!-1 -> #REF! | F27: =Financials!D8/Financials!C8-1 -> #DIV/0! | G27: =Financials!E8/Financials!D8-1 -> #DIV/0! | H27: =Financials!F8/Financials!E8-1 -> #DIV/0! | I27: =Financials!G8/Financials!F8-1 -> #DIV/0! | J27: =Financials!H8/Financials!G8-1 -> #DIV/0! | K27: =Financials!I8/Financials!H8-1 -> #DIV/0! | L27: =Financials!J8/Financials!H8-1 -> #DIV/0! | M27: =Financials!K8/Financials!I8-1 -> #DIV/0! | N27: =Financials!L8/Financials!J8-1 -> 154.23072 | O27: =Financials!M8/Financials!K8-1 -> 2.8817557 | P27: =Financials!O8/Financials!M8-1 -> 1.5961092 | Q27: =Financials!P8/Financials!N8-1 -> 2.4190385 | R27: =Financials!Q8/Financials!O8-1 -> 0.093877713 | S27: =Financials!N8/Financials!L8-1 -> 0.51756839 | T27: =Financials!R8/Financials!P8-1 -> -0.42435183 | U27: =Financials!S8/Financials!Q8-1 -> 0.16329503 | V27: =Financials!T8/Financials!R8-1 -> 0.29210029 | W27: =Financials!U8/Financials!S8-1 -> 0.035595055 | X27: =Financials!V8/Financials!T8-1 -> 0.020827023 | Y27: =Financials!W8/Financials!U8-1 -> 0.052408971 | Z27: =Financials!X8/Financials!V8-1 -> -0.046198176 | AA27: =Financials!Y8/Financials!W8-1 -> 0.080913954 | ... AE27: =Financials!AC8/Financials!AA8-1 -> 0.12700989
A28: 4.2.2 | B28: BOSA Deposits | C28: NPR | E28: =Financials!C7/Financials!#REF!-1 -> #REF! | F28: =Financials!D7/Financials!C7-1 -> #DIV/0! | G28: =Financials!E7/Financials!D7-1 -> #DIV/0! | H28: =Financials!F7/Financials!E7-1 -> #DIV/0! | I28: =Financials!G7/Financials!F7-1 -> #DIV/0! | J28: =Financials!H7/Financials!G7-1 -> #DIV/0! | K28: =Financials!I7/Financials!H7-1 -> #DIV/0! | L28: =Financials!J7/Financials!H7-1 -> #DIV/0! | M28: =Financials!K7/Financials!I7-1 -> 2.4821069 | N28: =Financials!L7/Financials!J7-1 -> 0.191164 | O28: =Financials!M7/Financials!K7-1 -> 0.03637706 | P28: =Financials!O7/Financials!M7-1 -> 0.19868191 | Q28: =Financials!P7/Financials!N7-1 -> 0.18359783 | R28: =Financials!Q7/Financials!O7-1 -> 0.18743084 | S28: =Financials!N7/Financials!L7-1 -> 0.047141039 | T28: =Financials!R7/Financials!P7-1 -> 0.19074871 | U28: =Financials!S7/Financials!Q7-1 -> 0.14424081 | V28: =Financials!T7/Financials!R7-1 -> 0.13301314 | W28: =Financials!U7/Financials!S7-1 -> 0.13753135 | X28: =Financials!V7/Financials!T7-1 -> 0.13320774 | Y28: =Financials!W7/Financials!U7-1 -> 0.07452682 | Z28: =Financials!X7/Financials!V7-1 -> 0.066867212 | AA28: =Financials!Y7/Financials!W7-1 -> 0.13306969 | ... AE28: =Financials!AC7/Financials!AA7-1 -> 0.12147132
A29: 4.3 | B29: Net Loans & advances | C29: NPR | E29: =Financials!C31/Financials!#REF!-1 -> #REF! | F29: =Financials!D31/Financials!C31-1 -> #DIV/0! | G29: =Financials!E31/Financials!D31-1 -> #DIV/0! | H29: =Financials!F31/Financials!E31-1 -> #DIV/0! | I29: =Financials!G31/Financials!F31-1 -> #DIV/0! | J29: =Financials!H31/Financials!G31-1 -> #DIV/0! | K29: =Financials!I31/Financials!H31-1 -> #DIV/0! | L29: =Financials!J31/Financials!H31-1 -> #DIV/0! | M29: =Financials!K31/Financials!I31-1 -> 7.8167117 | N29: =Financials!L31/Financials!J31-1 -> 0.15684155 | O29: =Financials!M31/Financials!K31-1 -> 0.18660002 | P29: =Financials!O31/Financials!M31-1 -> 0.29255307 | Q29: =Financials!P31/Financials!N31-1 -> 0.28834751 | R29: =Financials!Q31/Financials!O31-1 -> 0.26107589 | S29: =Financials!N31/Financials!L31-1 -> 0.25804566 | T29: =Financials!R31/Financials!P31-1 -> 0.2341776 | U29: =Financials!S31/Financials!Q31-1 -> 0.23737295 | V29: =Financials!T31/Financials!R31-1 -> 0.23777666 | W29: =Financials!U31/Financials!S31-1 -> 0.22893683 | X29: =Financials!V31/Financials!T31-1 -> 0.21204742 | Y29: =Financials!W31/Financials!U31-1 -> 0.095626232 | Z29: =Financials!X31/Financials!V31-1 -> 0.095376408 | AA29: =Financials!Y31/Financials!W31-1 -> 0.19472099 | ... AE29: =Financials!AC31/Financials!AA31-1 -> 0.16961323
A30: 4.4 | B30: Core capital | C30: NPR | E30: =Financials!C13/Financials!#REF!-1 -> #REF! | F30: =Financials!D13/Financials!C13-1 -> #DIV/0! | G30: =Financials!E13/Financials!D13-1 -> #DIV/0! | H30: =Financials!F13/Financials!E13-1 -> #DIV/0! | I30: =Financials!G13/Financials!F13-1 -> #DIV/0! | J30: =Financials!H13/Financials!G13-1 -> #DIV/0! | K30: =Financials!I13/Financials!H13-1 -> #DIV/0! | L30: =Financials!J13/Financials!H13-1 -> #DIV/0! | M30: =Financials!K13/Financials!I13-1 -> 1.227257 | N30: =Financials!L13/Financials!J13-1 -> -0.16987221 | O30: =Financials!M13/Financials!K13-1 -> 1.5161191 | P30: =Financials!O13/Financials!M13-1 -> -0.081989169 | Q30: =Financials!P13/Financials!N13-1 -> 0.0083421905 | R30: =Financials!Q13/Financials!O13-1 -> 0.19383807 | S30: =Financials!N13/Financials!L13-1 -> 1.349294 | T30: =Financials!R13/Financials!P13-1 -> 0.12134951 | U30: =Financials!S13/Financials!Q13-1 -> 0.29492358 | V30: =Financials!T13/Financials!R13-1 -> 0.32623112 | W30: =Financials!U13/Financials!S13-1 -> 0.24133668 | X30: =Financials!V13/Financials!T13-1 -> 0.20448586 | Y30: =Financials!W13/Financials!U13-1 -> -0.024665618 | Z30: =Financials!X13/Financials!V13-1 -> -0.12019959 | AA30: =Financials!Y13/Financials!W13-1 -> 0.015105379 | ... AE30: =Financials!AC13/Financials!AA13-1 -> 0.12990606
