Workbook

Sheet SFP
B1: FORM 6 SASRA2/006
B2: STATEMENT OF FINANCIAL POSITION
B3: NAME OF SACCO SOCIETY: ECO PILLAR (KAPENGURIA TEACHERS)
B4: FINANCIAL YEAR
B5: START DATE:
B6: END DATE: | C6: AUDITED 2012 | D6: AUDITED 2013 | E6: Audited 2014 | F6: 42005 | G6: 42036 | H6: 42064 | I6: 42095 | J6: 42125 | K6: 42156 | L6: 42186 | M6: 42217 | N6: 42248 | O6: 42278 | P6: 42309 | Q6: 42339 | R6: Audited 2015 | S6: 42385 | T6: 42416 | U6: 42445 | V6: 42476 | W6: 42506 | X6: 42537 | Y6: 42567 | Z6: 42598 | AA6: 42629 | AB6: 42659 | AC6: 42690 | AD6: 42720 | AE6: 42736 | AF6: 42767 | AG6: 42795 | AH6: 42826 | AI6: 42856 | AJ6: 42887 | AK6: 42917 | AL6: 42948 | AM6: 42979 | AN6: 43009 | AO6: 43040 | AP6: 43070 | AQ6: Audited 2017 | AR6: 43101 | AS6: 43132 | AT6: 43160 | AU6: 43191 | AV6: 43221 | AW6: 43252 | AX6: 43282 | AY6: 43313 | AZ6: 43344 | BA6: 43374 | BB6: 43405 | BC6: 43435 | BD6: Aud-18 | BE6: 43466 | BF6: 43497 | BG6: 43525 | BH6: 43556 | BI6: 43586 | BJ6: 43617 | BK6: 43647 | BL6: 43678 | BM6: 43709 | BN6: 43739 | BO6: 43770 | BP6: 43800 | BQ6: Audited 2019 | BR6: 43831 | BS6: 43862 | BT6: 43891 | BU6: 43922 | BV6: 43952 | BW6: 43983 | BX6: 44013 | BY6: 44044 | BZ6: 44075 | CA6: 44105 | CB6: 44136 | CC6: 44166 | CD6: Audited 2020 | CE6: Audited 2021 | CF6: 44562 | CG6: 44593 | CH6: 44621 | CI6: 44652 | CJ6: 44682 | CK6: 44713 | CL6: 44743 | CM6: 44774 | CN6: 44805 | CO6: 44835 | CP6: 44866 | CQ6: 44896 | CR6: Dec 2022 Audited
A9: Ref No | B9: ASSETS
A10: 1 | B10: Cash & Cash Equivalent | C10: 37828323 | D10: 34544013 | E10: =SUM(E11:E12) -> 50299714 | F10: =SUM(F11:F12) -> 30898512 | G10: =SUM(G11:G12) -> 22594248 | H10: =SUM(H11:H12) -> 35458880 | I10: =SUM(I11:I12) -> 20508258 | J10: =SUM(J11:J12) -> 20541709 | K10: =SUM(K11:K12) -> 43473322 | L10: =SUM(L11:L12) -> 42233129 | ... CS10: =SUM(CS11:CS12) -> 0
A11: 1.1 | B11: Cash in hand(both local and foreign notes and coins) | E11: 7625036 | F11: 3785161.8 | G11: 7230893.8 | H11: 4355078.8 | I11: 5144903.8 | J11: 5178354.8 | K11: 4160419.8 | L11: 6998399.8 | M11: 15994075 | N11: 3164275.6 | O11: 6423052.6 | P11: 3251961.6 | Q11: 4783446.6 | R11: 7608696.6 | S11: 2185543.6 | T11: 566332.6 | U11: 1001426.6 | V11: 9687698.6 | W11: 2781993.6 | X11: 1167787.6 | Y11: 2836908.1 | Z11: 4903050 | AA11: 4482292.1 | AB11: 3047252.1 | AC11: 2369022.1 | AD11: 1993390.6 | AE11: 528036.1 | AF11: 6863519 | AG11: 4677222.1 | AH11: 3964643.1 | AI11: 4512542.1 | AJ11: 4109589.1 | AK11: 584739.1 | AL11: 1698185.5 | AM11: 2070296.1 | AN11: 2504803.1 | AO11: 2799938.9 | AP11: 3402526.1 | AQ11: 4473703 | AR11: 6815420.1 | AS11: 6943416.1 | AT11: 13048606 | AU11: 7558427 | AV11: 1764446.1 | AW11: 5022559.1 | AX11: 3616157.1 | AY11: 3237226.1 | AZ11: 3494679.1 | BA11: 3494679.1 | BB11: 1532967.4 | BC11: 15339910 | BD11: 17628340 | BE11: 3274500.1 | BF11: 10562660 | BG11: 8593830.1 | BH11: 6419700.1 | BI11: 6841160.1 | BJ11: 2002753.1 | BK11: 1336383.1 | BL11: 8756273.1 | BM11: 7694259.1 | BN11: 3781798.1 | BO11: 1629208.1 | BP11: 6219857.1 | BQ11: 10763824 | BR11: 4904382.1 | BS11: 5181862.1 | BT11: 663127.1 | BU11: 12508795 | BV11: 13260191 | BW11: 4899632.1 | BY11: 2551507.1 | BZ11: 9690616.1 | CA11: 2217402.1 | CB11: 2407666.1 | CC11: 617294.1 | CD11: =236504.1+380790+121895+6691847 -> 7431036.1 | CE11: =1876540+817640+121895+6444611 -> 9260686 | CF11: 2475953.1 | CG11: 13692810 | CH11: 5126391.1 | CI11: 763491.1 | CJ11: 4489306.1 | CK11: 8469153.1 | CL11: 5375585.1 | CM11: 3250325 | CN11: 962457 | CO11: 4444441 | CP11: 9185977 | CQ11: 774907
A12: 1.2 | B12: Cash at bank:(placement with financial institutions) | E12: 42674678 | F12: 27113350 | G12: 15363354 | H12: 31103802 | I12: 15363354 | J12: 15363354 | K12: 39312902 | L12: 35234729 | M12: 18425266 | N12: 56814495 | O12: 49957979 | P12: 29855363 | Q12: 35209919 | R12: 26083051 | S12: 37215014 | T12: 66129085 | U12: 65495563 | V12: 51970884 | W12: 93212764 | X12: 1.0241091e+08 | Y12: 1.0342108e+08 | Z12: 97528841 | AA12: 93432544 | AB12: 91594018 | AC12: 87153169 | AD12: 83782379 | AE12: 72216620 | AF12: 72879899 | AG12: 58343777 | AH12: 50957558 | AI12: 49268376 | AJ12: 59285199 | AK12: 50185029 | AL12: 50611375 | AM12: 46694402 | AN12: 64859617 | AO12: 69741486 | AP12: 82226406 | AQ12: 81155229 | AR12: 76918650 | AS12: 74755893 | AT12: 68058401 | AU12: 76415145 | AV12: 77406355 | AW12: 84669941 | AX12: 95527132 | AY12: 91815429 | AZ12: 90351487 | BA12: 90351487 | BB12: 94152297 | BC12: 97747448 | BD12: =51788836.75+41890172.55+7593.95+1976172.3-203757.85 -> 95459018 | BE12: 90076615 | BF12: 98632213 | BG12: 97521622 | BH12: 88504167 | BI12: 92167657 | BJ12: 97543488 | BK12: 94960184 | BL12: 89820042 | BM12: 1.0546745e+08 | BN12: 36806920 | BO12: 47180723 | BP12: 73068801 | BQ12: =67009876.6+321520.75+53309.7+7593+1133092.1-559.3 -> 68524833 | BR12: 33918458 | BS12: 27880363 | BT12: 41649350 | BU12: 33520607 | BV12: 52101459 | BW12: 77586120 | BY12: 57351045 | BZ12: 64680985 | CA12: 67984533 | CB12: 69703285 | CC12: 1.0237802e+08 | CD12: =61392673.3+429347.45+302307.25+7593.95+2454+46517+19632.6+32748871.25+-2415.4 -> 94946981 | CE12: =145762949-9260686 -> 136502263 | CF12: 1.0391534e+08 | CG12: 1.0199325e+08 | CH12: 93482430 | CI12: 1.0116455e+08 | CJ12: 1.1228537e+08 | CK12: 94222387 | CL12: 114804223 | CM12: 1.1751479e+08 | CN12: 1.7857995e+08 | CO12: 1.8890064e+08 | CP12: 2.1890064e+08 | CQ12: 1.8423676e+08
A13: 2 | B13: Prepayments & Sundry Receivables | C13: 21679003 | D13: 10068961 | E13: =10139889+134820232+129744+113867562 -> 258957427 | F13: 13679940 | G13: 101733797 | H13: 1.0937328e+08 | I13: 2.7706016e+08 | J13: 13679940 | K13: 2.6344487e+08 | L13: 2.6319353e+08 | M13: 2.7113116e+08 | O13: 2.7060451e+08 | P13: 2.9575405e+08 | Q13: 2.8244385e+08 | R13: 1.4405243e+08 | S13: 260187916 | T13: 3.3101983e+08 | U13: 3.233589e+08 | V13: 3.248621e+08 | W13: 2.8413293e+08 | X13: 2.5327936e+08 | Y13: 2.5163007e+08 | Z13: 2.4259642e+08 | AA13: 2.427855e+08 | AB13: 2.5756745e+08 | AC13: 2.4756366e+08 | AD13: 2.655252e+08 | AE13: 2.4676051e+08 | AF13: 2.5345305e+08 | AG13: 2.5561828e+08 | AH13: 2.5075067e+08 | AI13: 2.9654479e+08 | AJ13: 2.9102322e+08 | AK13: 2.9202652e+08 | AL13: 2.7255358e+08 | AM13: 2.6949753e+08 | AN13: 2.7270549e+08 | AO13: 2.3434263e+08 | AP13: 2.537381e+08 | AQ13: 244383762 | AR13: 2.2308901e+08 | AS13: 2.3037669e+08 | AT13: 2.5084187e+08 | AU13: 2.5125782e+08 | AV13: 2.749258e+08 | AX13: 2.785692e+08 | AY13: 2.946085e+08 | AZ13: 2.9359313e+08 | BA13: 2.9359313e+08 | BB13: 2.8625008e+08 | BC13: 2.2535988e+08 | BD13: 2.4282255e+08 | BE13: 1.4289018e+08 | BF13: 1.3467452e+08 | BG13: 1.3564782e+08 | BH13: 1.4221476e+08 | BI13: 1.3897491e+08 | BJ13: 1.5653713e+08 | BK13: 1.4820193e+08 | BL13: 1.2913807e+08 | BM13: 1.4756285e+08 | BN13: 2.0706101e+08 | BO13: 1.9650484e+08 | BP13: 2.4238557e+08 | BQ13: 2.7377833e+08 | BR13: 2.3168512e+08 | BS13: 2.5182354e+08 | BT13: 2.4092401e+08 | BU13: 2.6802922e+08 | BV13: 2.8250484e+08 | BW13: 2.5862592e+08 | BY13: 2.7288854e+08 | BZ13: 2.5904977e+08 | CA13: 2.4666889e+08 | CB13: 2.4050605e+08 | CC13: 2.2402078e+08 | CD13: 2.9475628e+08 | CE13: 287019357 | CF13: 2.2027759e+08 | CG13: 2.1184673e+08 | CH13: 2.9783031e+08 | CI13: 2.9324579e+08 | CJ13: 2.6400454e+08 | CK13: 2.8027957e+08 | CL13: 2.6552673e+08 | CM13: 2.6114129e+08 | CN13: 2.0684292e+08 | CO13: 1.964148e+08 | CP13: 1.8575727e+08 | CQ13: 2.4677593e+08
A14: 3 | B14: Financial Investments | C14: =SUM(C15:C18) -> 34475098 | D14: =SUM(D15:D18) -> 40570790 | E14: =SUM(E15:E18) -> 35208138 | F14: =SUM(F15:F18) -> 0 | G14: =SUM(G15:G18) -> 0 | H14: =SUM(H15:H18) -> 0 | I14: =SUM(I15:I18) -> 28462661 | J14: =SUM(J15:J18) -> 28462661 | ... CS14: =SUM(CS15:CS18) -> 0
A15: 3.1 | B15: Government Securities - Treasury Bills/bonds, | N15: 0 | S15: 0 | T15: 0 | U15: 0 | V15: 0 | X15: 0 | Y15: 0 | Z15: 0 | AB15: 0 | AC15: 0 | AD15: 0 | AE15: 0 | AF15: 0 | AG15: 0 | AH15: 0 | AI15: 0 | AJ15: 0 | AK15: 0 | AL15: 0 | AM15: 0 | AN15: 0 | AO15: 0 | AP15: 0 | AR15: 0 | AS15: 0 | AT15: 0 | AU15: 0 | AV15: 0 | AX15: 0 | AY15: 0 | AZ15: 0 | BA15: 0 | BB15: 0 | BC15: 0 | BD15: 0 | BE15: 0 | BF15: 0 | BG15: 0 | BH15: 0 | BI15: 0 | BJ15: 0 | BK15: 0 | BL15: 0 | BM15: 0 | BN15: 0 | BO15: 0 | BP15: 0 | BR15: 0 | BS15: 0 | BT15: 0 | BU15: 0 | BV15: 0 | BW15: 0 | BY15: 0 | BZ15: 0 | CA15: 0 | CB15: 0 | CC15: 0 | CF15: 0 | CG15: 0 | CH15: 0 | CI15: 0 | CJ15: 0 | CK15: 0 | CL15: 0 | CM15: 0 | CN15: 0 | CO15: 0 | CP15: 0 | CQ15: 0
A16: 3.2 | B16: Other Securities - Commercial papers/Bonds | E16: =11000+76528 -> 87528 | N16: 0 | S16: 0 | T16: 0 | U16: 0 | V16: 0 | X16: 0 | Y16: 0 | Z16: 0 | AB16: 0 | AC16: 0 | AD16: 0 | AE16: 0 | AF16: 0 | AG16: 0 | AH16: 0 | AI16: 0 | AJ16: 0 | AK16: 0 | AL16: 0 | AM16: 0 | AN16: 0 | AO16: 0 | AP16: 0 | AR16: 0 | AS16: 0 | AT16: 0 | AU16: 0 | AV16: 0 | AX16: 0 | AY16: 0 | AZ16: 0 | BA16: 0 | BB16: 0 | BC16: 0 | BD16: 0 | BE16: 0 | BF16: 0 | BG16: 0 | BH16: 0 | BI16: 0 | BJ16: 0 | BK16: 0 | BL16: 0 | BM16: 0 | BN16: 0 | BO16: 0 | BP16: 0 | BR16: 0 | BS16: 0 | BT16: 0 | BU16: 0 | BV16: 0 | BW16: 0 | BY16: 0 | BZ16: 0 | CA16: 0 | CB16: 0 | CC16: 0 | CF16: 0 | CG16: 0 | CH16: 0 | CI16: 0 | CJ16: 0 | CK16: 0 | CL16: 0 | CM16: 0 | CN16: 0 | CO16: 0 | CP16: 0 | CQ16: 0
A17: 3.3a | B17: Balances with other SACCO Societies | C17: 30347798 | D17: 32511490 | N17: 0 | S17: 0 | T17: 0 | U17: 0 | V17: 0 | X17: 0 | Y17: 0 | Z17: 0 | AB17: 0 | AC17: 0 | AD17: 0 | AE17: 0 | AF17: 0 | AG17: 0 | AH17: 0 | AI17: 0 | AJ17: 0 | AK17: 0 | AL17: 0 | AM17: 0 | AN17: 0 | AO17: 0 | AP17: 0 | AQ17: 19297893 | AR17: 0 | AS17: 0 | AT17: 0 | AU17: 0 | AV17: 0 | AX17: 0 | AY17: 0 | AZ17: 0 | BA17: 0 | BB17: 0 | BC17: 0 | BD17: 14708554 | BE17: 0 | BF17: 0 | BG17: 0 | BH17: 0 | BI17: 0 | BJ17: 0 | BK17: 0 | BL17: 0 | BM17: 0 | BN17: 0 | BO17: 0 | BP17: 0 | BQ17: 14442915 | BR17: 0 | BS17: 0 | BT17: 0 | BU17: 0 | BV17: 0 | BW17: 0 | BY17: 0 | BZ17: 0 | CA17: 0 | CB17: 0 | CC17: 0 | CD17: 14442918 | CE17: =11000+76528 -> 87528 | CF17: 0 | CG17: 0 | CH17: 0 | CI17: 0 | CJ17: 0 | CK17: 0 | CL17: 0 | CM17: 0 | CN17: 0 | CO17: 0 | CP17: 0 | CQ17: 0
A18: 3.3b | B18: Investments in companies - shares/stocks | C18: =3994772+11000+45000+76528 -> 4127300 | D18: =3942000+3984772+11000+45000+76528 -> 8059300 | E18: =6000000+9579348+3984772+15511490+45000 -> 35120610 | I18: 28462661 | J18: 28462661 | K18: 28462661 | L18: 28462661 | M18: 28462661 | N18: 28462661 | O18: 28462661 | P18: 28462661 | Q18: 28462661 | R18: 33641898 | S18: 28462661 | T18: 28462661 | U18: 28462661 | V18: 28462661 | W18: 22273509 | X18: 22273509 | Y18: 22273509 | Z18: 22273509 | AA18: 22273509 | AB18: 22273509 | AC18: 22273509 | AD18: 22273509 | AE18: 32448819 | AF18: 32448819 | AG18: 32448819 | AH18: 32448819 | AI18: 32448819 | AJ18: 32448819 | AK18: 34881096 | AL18: 34881096 | AM18: 34881096 | AN18: 34881096 | AO18: 34093974 | AP18: 34093974 | AQ18: 87528 | AR18: 34093974 | AS18: 34093974 | AT18: 34093974 | AU18: 34093974 | AV18: 34116047 | AW18: 34116047 | AX18: 34116047 | AY18: 34116047 | AZ18: 34116047 | BA18: 34116047 | BB18: 34116047 | BC18: 34116047 | BD18: =12011625+45000+6781017.6+11000+76528+482323+113186777 -> 1.3259427e+08 | BE18: 34116047 | BF18: 34116047 | BG18: 34529146 | BH18: 35575057 | BI18: 35775057 | BJ18: 38735057 | BK18: 38763252 | BL18: 36263252 | BM18: 34863252 | BN18: 34898176 | BO18: 34898176 | BP18: 34898176 | BQ18: 1.3364357e+08 | BR18: 34899711 | BS18: 35450236 | BT18: 35450733 | BU18: 35450733 | BV18: 35450733 | BW18: 35952324 | BY18: 39469709 | BZ18: 39506671 | CA18: 39506671 | CB18: 30613452 | CC18: 36618314 | CD18: 1.3536218e+08 | CE18: =135372831+14442917-87528 -> 149728220 | CF18: 36628968 | CG18: 36628968 | CH18: 36648066 | CI18: 36648066 | CJ18: 37196808 | CK18: 36398696 | CL18: 36398696 | CM18: 36399080 | CN18: 36399269 | CO18: 36399269 | CP18: 36399659 | CQ18: 23456744
A19: 4 | B19: Net Loan Portfolio | C19: =C20-C21 -> 3.0242896e+08 | D19: =D20-D21 -> 1.9123114e+08 | E19: =E20-E21 -> 237111555 | F19: =F20-F21 -> 2.4111051e+08 | G19: =G20-G21 -> 2.4155344e+08 | H19: =H20-H21 -> 2.3122683e+08 | I19: =I20-I21 -> 2.3341683e+08 | J19: =J20-J21 -> 2.3940967e+08 | ... CS19: =CS20-CS21 -> 0
B20: Gross Loan Portfolio | C20: 305479221 | D20: 1.9513381e+08 | E20: =180386268+66741713 -> 247127981 | F20: 2.4311463e+08 | G20: 2.4387353e+08 | H20: 2.3323095e+08 | I20: 2.4141379e+08 | J20: 2.4141379e+08 | K20: 2.4185374e+08 | L20: 2.4981319e+08 | M20: 2.5086799e+08 | N20: 2.8515109e+08 | O20: 3.1510298e+08 | P20: 3.15778e+08 | Q20: 3.2968773e+08 | R20: 258801812 | S20: 3.3932498e+08 | T20: 2.5311014e+08 | U20: 261440035 | V20: 2.7277301e+08 | W20: 2.5322397e+08 | X20: 2.5263731e+08 | Y20: 251123467 | Z20: 2.6447442e+08 | AA20: 2.6481779e+08 | AB20: 2.6339101e+08 | AC20: 2.6529082e+08 | AD20: 2.706052e+08 | AE20: 2.6730061e+08 | AF20: 2.7428541e+08 | AG20: 2.9225437e+08 | AH20: 2.9922121e+08 | AI20: 2.9429869e+08 | AJ20: 2.9880763e+08 | AK20: 3.0263226e+08 | AL20: 3.2077988e+08 | AM20: 3.2372741e+08 | AN20: 3.2059876e+08 | AO20: 3.4132997e+08 | AP20: 3.3460069e+08 | AQ20: 334089794 | AR20: 3.4105815e+08 | AS20: 3.4745152e+08 | AT20: 3.3593149e+08 | AU20: 3.3880095e+08 | AV20: 3.3187692e+08 | AW20: 3.2816436e+08 | AX20: 3.3303477e+08 | AY20: 3.1455427e+08 | AZ20: 3.1148918e+08 | BA20: 3.1148918e+08 | BB20: 3.2140363e+08 | BC20: 3.1844843e+08 | BD20: 318461829 | BE20: 3.4815466e+08 | BF20: 3.5454538e+08 | BG20: 3.484768e+08 | BH20: 3.4680111e+08 | BI20: 3.5584433e+08 | BJ20: 3.4870585e+08 | BK20: 3.5215567e+08 | BL20: 3.8123742e+08 | BM20: 3.6609873e+08 | BN20: 3.8274941e+08 | BO20: 3.9274699e+08 | BP20: 4.0621646e+08 | BQ20: 4.0604441e+08 | BR20: 4.0823919e+08 | BS20: 4.0164629e+08 | BT20: 3.9711314e+08 | BU20: 3.8384055e+08 | BV20: 3.9584636e+08 | BW20: 4.0442843e+08 | BY20: 4.2910041e+08 | BZ20: 4.3984774e+08 | CA20: 4.5990353e+08 | CB20: 4.5859292e+08 | CC20: 4.7110886e+08 | CD20: 4.7111686e+08 | CE20: 529871512 | CF20: 5.2931815e+08 | CG20: 5.31518e+08 | CH20: 5.339991e+08 | CI20: 5.3776946e+08 | CJ20: 5.3503708e+08 | CK20: 5.3438795e+08 | CL20: 5.3563081e+08 | CM20: 5.3824604e+08 | CN20: 5.3955404e+08 | CO20: 5.4255458e+08 | CP20: 5.447509e+08 | CQ20: 6.1787486e+08
B21: Allowance for Loan Loss | C21: 3050258.2 | D21: 3902676.2 | E21: 10016426 | F21: 2004119.4 | G21: 2320087 | H21: 2004119.4 | I21: 7996958.1 | J21: 2004119.4 | K21: 2547249.6 | L21: 2160622.9 | M21: 2720125.4 | N21: 3892150.5 | O21: 4393500.3 | P21: 5271719.2 | Q21: 7122341.1 | R21: 7504736 | S21: 2010478.7 | T21: 1010297.2 | U21: 2065128.3 | V21: 2370230.1 | W21: 1213077.3 | X21: 996699.5 | Y21: 1099590.1 | Z21: 2054575.7 | AA21: 1356716.5 | AB21: 11922708 | AC21: 10596215 | AD21: 18317843 | AE21: 11235789 | AF21: 12369785 | AG21: 11924753 | AH21: 12394568 | AI21: 11095883 | AJ21: 13741671 | AK21: 13340487 | AL21: 10375125 | AM21: 13645903 | AN21: 14379390 | AO21: 9825396.4 | AP21: 13788864 | AQ21: 13277969 | AR21: 13245897 | AS21: 11245365 | AT21: 12757388 | AU21: 13526987 | AV21: 14369785 | AW21: 10502228 | AX21: 11868566 | AY21: 9807410.6 | AZ21: 9609968.1 | BA21: 9609968.1 | BB21: 10509439 | BC21: 12013231 | BD21: 16777969 | BE21: 9625368.9 | BF21: 10225012 | BG21: 10867106 | BH21: 10735257 | BI21: 9298227.3 | BJ21: 9879712.9 | BK21: 9507885.7 | BL21: 9703533.6 | BM21: 9824517.5 | BN21: 10001064 | BO21: 10778845 | BP21: 22777969 | BQ21: 22777969 | BR21: 10523347 | BS21: 11311511 | BT21: 10722159 | BU21: 8260963.2 | BV21: 9145689.2 | BW21: 10699318 | BY21: 10257200 | BZ21: 10239570 | CA21: 10413070 | CB21: 11552130 | CC21: 29769969 | CD21: 29777969 | CE21: 36777969 | CF21: 6915696.2 | CG21: 6959043.4 | CH21: 6655279.3 | CI21: 7103146.2 | CJ21: 7315798.8 | CK21: 7178230.4 | CL21: 7595142 | CM21: 7494352.8 | CN21: 7730461 | CO21: 7725468.1 | CP21: 7825319.1 | CQ21: 7500000
A22: 5 | B22: Accounts Receivables | C22: 0 | E22: =SUM(E23:E25) -> 0 | F22: =SUM(F23:F25) -> 0 | G22: =SUM(G23:G25) -> 0 | H22: =SUM(H23:H25) -> 0 | I22: =SUM(I23:I25) -> 0 | J22: =SUM(J23:J25) -> 0 | K22: =SUM(K23:K25) -> 0 | L22: =SUM(L23:L25) -> 0 | ... CS22: =SUM(CS23:CS25) -> 0
A23: 5.1 | B23: Tax Recoverable | S23: 0 | T23: 0 | U23: 0 | V23: 0 | W23: 0 | X23: 0 | Y23: 0 | Z23: 0 | AB23: 0 | AC23: 0 | AD23: 0 | AE23: 0 | AF23: 0 | AG23: 0 | AH23: 0 | AI23: 0 | AJ23: 0 | AK23: 0 | AL23: 0 | AM23: 0 | AN23: 0 | AO23: 0 | AP23: 0 | AR23: 0 | AS23: 0 | AT23: 0 | AU23: 0 | AV23: 0 | AW23: 0 | AX23: 0 | AY23: 0 | AZ23: 0 | BA23: 0 | BB23: 0 | BC23: 0 | BD23: 0 | BE23: 0 | BF23: 0 | BG23: 0 | BH23: 0 | BI23: 0 | BJ23: 0 | BK23: 0 | BL23: 0 | BM23: 0 | BN23: 0 | BO23: 0 | BP23: 0 | BR23: 0 | BS23: 0 | BT23: 0 | BU23: 0 | BV23: 0 | BW23: 0 | BY23: 0 | BZ23: 0 | CA23: 0 | CB23: 0 | CC23: 0 | CF23: 0 | CG23: 0 | CH23: 0 | CI23: 0 | CJ23: 0 | CK23: 0 | CL23: 0 | CM23: 0 | CN23: 0 | CO23: 0 | CP23: 0 | CQ23: 0
A24: 5.2 | B24: Deferred Tax Assets | S24: 0 | T24: 0 | U24: 0 | V24: 0 | W24: 0 | X24: 0 | Y24: 0 | Z24: 0 | AB24: 0 | AC24: 0 | AD24: 0 | AE24: 0 | AF24: 0 | AG24: 0 | AH24: 0 | AI24: 0 | AJ24: 0 | AK24: 0 | AL24: 0 | AM24: 0 | AN24: 0 | AO24: 0 | AP24: 0 | AR24: 0 | AS24: 0 | AT24: 0 | AU24: 0 | AV24: 0 | AW24: 0 | AX24: 0 | AY24: 0 | AZ24: 0 | BA24: 0 | BB24: 0 | BC24: 0 | BD24: 0 | BE24: 0 | BF24: 0 | BG24: 0 | BH24: 0 | BI24: 0 | BJ24: 0 | BK24: 0 | BL24: 0 | BM24: 0 | BN24: 0 | BO24: 0 | BP24: 0 | BR24: 0 | BS24: 0 | BT24: 0 | BU24: 0 | BV24: 0 | BW24: 0 | BY24: 0 | BZ24: 0 | CA24: 0 | CB24: 0 | CC24: 0 | CF24: 0 | CG24: 0 | CH24: 0 | CI24: 0 | CJ24: 0 | CK24: 0 | CL24: 0 | CM24: 0 | CN24: 0 | CO24: 0 | CP24: 0 | CQ24: 0
A25: 5.3 | B25: Retirement Benefit Assets | S25: 0 | T25: 0 | U25: 0 | V25: 0 | W25: 0 | X25: 0 | Y25: 0 | Z25: 0 | AB25: 0 | AC25: 0 | AD25: 0 | AE25: 0 | AF25: 0 | AG25: 0 | AH25: 0 | AI25: 0 | AJ25: 0 | AK25: 0 | AL25: 0 | AM25: 0 | AN25: 0 | AO25: 0 | AP25: 0 | AR25: 0 | AS25: 0 | AT25: 0 | AU25: 0 | AV25: 0 | AW25: 0 | AX25: 0 | AY25: 0 | AZ25: 0 | BA25: 0 | BB25: 0 | BC25: 0 | BD25: 0 | BE25: 0 | BF25: 0 | BG25: 0 | BH25: 0 | BI25: 0 | BJ25: 0 | BK25: 0 | BL25: 0 | BM25: 0 | BN25: 0 | BO25: 0 | BP25: 0 | BR25: 0 | BS25: 0 | BT25: 0 | BU25: 0 | BV25: 0 | BW25: 0 | BY25: 0 | BZ25: 0 | CA25: 0 | CB25: 0 | CC25: 0 | CF25: 0 | CG25: 0 | CH25: 0 | CI25: 0 | CJ25: 0 | CK25: 0 | CL25: 0 | CM25: 0 | CN25: 0 | CO25: 0 | CP25: 0 | CQ25: 0
A26: 6 | B26: Property & Equipment & Other assets | C26: =SUM(C27:C31) -> 1.1680019e+08 | D26: =SUM(D27:D31) -> 2.6580812e+08 | E26: =SUM(E27:E31) -> 19672436 | F26: =SUM(F27:F31) -> 1.7844756e+08 | G26: =SUM(G27:G31) -> 1.7206346e+08 | H26: =SUM(H27:H31) -> 1.6531798e+08 | I26: =SUM(I27:I31) -> 19672436 | J26: =SUM(J27:J31) -> 19672436 | ... CS26: =SUM(CS27:CS31) -> 0
A27: 6.1 | B27: Investment Properties | F27: 23570790 | G27: 23570790 | H27: 16825313 | Q27: 0 | S27: 0 | T27: 0 | U27: 0 | V27: 0 | W27: 1.0718678e+08 | X27: 1.0718678e+08 | Y27: 1.0718678e+08 | Z27: 1.0718678e+08 | AA27: 1.0718678e+08 | AB27: 1.0718678e+08 | AC27: 1.0718678e+08 | AD27: 1.0718678e+08 | AE27: 1.0718678e+08 | AF27: 1.0718678e+08 | AG27: 1.0718678e+08 | AH27: 1.0718678e+08 | AI27: 1.0718678e+08 | AJ27: 1.0718678e+08 | AK27: 1.0718678e+08 | AL27: 1.0718678e+08 | AM27: 1.0718678e+08 | AN27: 1.0718678e+08 | AO27: 1.0718678e+08 | AP27: 1.0718678e+08 | AQ27: 41547728 | AR27: 1.1318678e+08 | AS27: 1.1318678e+08 | AT27: 1.1318678e+08 | AU27: 1.1318678e+08 | AV27: 1.1318678e+08 | AW27: 1.1318678e+08 | AX27: 1.1318678e+08 | AY27: 1.1318678e+08 | AZ27: 1.1318678e+08 | BA27: 1.1318678e+08 | BB27: 1.1318678e+08 | BC27: 1.1318678e+08 | BE27: 1.1318678e+08 | BF27: 1.1318678e+08 | BG27: 1.1318678e+08 | BH27: 1.1318678e+08 | BI27: 1.1318678e+08 | BJ27: 1.1318678e+08 | BK27: 1.1318678e+08 | BL27: 1.1318678e+08 | BM27: 1.1318678e+08 | BN27: 1.1318678e+08 | BO27: 1.1318678e+08 | BP27: 1.1318678e+08 | BR27: 1.1318678e+08 | BS27: 1.1318678e+08 | BT27: 1.1318678e+08 | BU27: 1.1318678e+08 | BV27: 1.1318678e+08 | BW27: 1.1318678e+08 | BY27: 1.1318678e+08 | BZ27: 1.1318678e+08 | CA27: 1.1318678e+08 | CB27: 1.1318678e+08 | CC27: 1.1318678e+08 | CF27: 1.1318678e+08 | CG27: 1.1318678e+08 | CH27: 1.1318678e+08 | CI27: 1.1318678e+08 | CJ27: 1.1318678e+08 | CK27: 1.1318678e+08 | CL27: 1.1318678e+08 | CM27: 1.1318678e+08 | CN27: 1.1318678e+08 | CO27: 1.1318678e+08 | CP27: 1.1318678e+08 | CQ27: 1.1318678e+08
A28: 6.2 | B28: Property & Equipment | C28: 1.1586468e+08 | D28: 6580532 | E28: =7375517+1934506+752103+114750+4949165+4546395 -> 19672436 | F28: 21344950 | G28: 19672436 | H28: 19672436 | I28: 19672436 | J28: 19672436 | K28: 19672436 | L28: 19672436 | M28: 19672436 | N28: 39853019 | O28: 39853019 | P28: 39853019 | Q28: 39853019 | R28: 19460785 | S28: 39853019 | T28: 39853019 | U28: 39853019 | V28: 30053019 | W28: 56865513 | X28: 56877263 | Y28: 56877263 | Z28: 56877263 | AA28: 56877263 | AB28: 56877263 | AC28: 64241230 | AD28: 64241230 | AE28: 64306230 | AF28: 64306230 | AG28: 64306230 | AH28: 64306230 | AI28: 64306230 | AJ28: 64306230 | AK28: 64306230 | AL28: 64349730 | AM28: 64349730 | AN28: 64349730 | AO28: 64349730 | AP28: 64349730 | AQ28: 10334868 | AR28: 75440365 | AS28: 65640365 | AT28: 65640365 | AU28: 65640365 | AV28: 65640365 | AW28: 65640365 | AX28: 66473165 | AY28: 66473165 | AZ28: 66473165 | BA28: 66473165 | BB28: 66433165 | BC28: 66433165 | BD28: 50224362 | BE28: 66433165 | BF28: 66433165 | BG28: 66433165 | BH28: 66433165 | BI28: 66563665 | BJ28: 66563665 | BK28: 66563665 | BL28: 66563665 | BM28: 66747665 | BN28: 66747665 | BO28: 66747665 | BP28: 66747665 | BQ28: 48670717 | BR28: 66797865 | BS28: 66797865 | BT28: 66797865 | BU28: 66797865 | BV28: 66860865 | BW28: 66785865 | BY28: 66745865 | BZ28: 66745865 | CA28: 63005865 | CB28: 63005865 | CC28: 63005865 | CD28: 46450359 | CE28: 51204736 | CF28: 69203921 | CG28: 69203921 | CH28: 69649922 | CI28: 69649922 | CJ28: 69701426 | CK28: 70119896 | CL28: 70119896 | CM28: 70119896 | CN28: 70119896 | CO28: 70119896 | CP28: 70119896 | CQ28: 49997050
A29: 6.3 | B29: Prepaid Lease rentals | Q29: 0 | S29: 0 | T29: 0 | U29: 0 | V29: 0 | W29: 0 | X29: 0 | Y29: 0 | Z29: 0 | AA29: 0 | AB29: 0 | AC29: 0 | AD29: 0 | AE29: 0 | AF29: 0 | AG29: 0 | AH29: 0 | AI29: 0 | AJ29: 0 | AK29: 0 | AL29: 0 | AM29: 0 | AN29: 0 | AO29: 0 | AP29: 0 | AR29: 0 | AS29: 0 | AT29: 0 | AU29: 0 | AV29: 0 | AW29: 0 | AX29: 0 | AY29: 0 | AZ29: 0 | BA29: 0 | BB29: 0 | BC29: 0 | BE29: 0 | BF29: 0 | BG29: 0 | BH29: 0 | BI29: 0 | BJ29: 0 | BK29: 0 | BL29: 0 | BM29: 0 | BN29: 0 | BO29: 0 | BP29: 0 | BR29: 0 | BS29: 0 | BT29: 0 | BU29: 0 | BV29: 0 | BW29: 0 | BY29: 0 | BZ29: 0 | CA29: 0 | CB29: 0 | CC29: 0 | CD29: 0 | CF29: 0 | CG29: 0 | CH29: 0 | CI29: 0 | CJ29: 0 | CK29: 0 | CL29: 0 | CM29: 0 | CN29: 0 | CO29: 0 | CP29: 0 | CQ29: 0
A30: 6.4 | B30: Intangible Assets | Q30: 0 | R30: 6536600 | S30: 0 | T30: 0 | U30: 0 | V30: 9800000 | W30: 9800000 | X30: 9800000 | Y30: 9800000 | Z30: 9800000 | AA30: 9800000 | AB30: 9800000 | AC30: 9800000 | AD30: 9800000 | AE30: 9800000 | AF30: 9800000 | AG30: 9800000 | AH30: 9800000 | AI30: 9800000 | AJ30: 9800000 | AK30: 9800000 | AL30: 9800000 | AM30: 9800000 | AN30: 9800000 | AO30: 9800000 | AP30: 9800000 | AQ30: 2906753 | AR30: 9800000 | AS30: 9800000 | AT30: 9800000 | AU30: 9800000 | AV30: 9800000 | AW30: 9800000 | AX30: 9800000 | AY30: 9800000 | AZ30: 9800000 | BA30: 9800000 | BB30: 16300000 | BC30: 16300000 | BD30: 6271482 | BE30: 16300000 | BF30: 16300000 | BG30: 16300000 | BH30: 16300000 | BI30: 16300000 | BJ30: 16300000 | BK30: 16300000 | BL30: 16300000 | BM30: 16300000 | BN30: 16300000 | BO30: 16300000 | BP30: 16300000 | BQ30: 4181197.1 | BR30: 16300000 | BS30: 17518000 | BT30: 17518000 | BU30: 17518000 | BV30: 17518000 | BW30: 17518000 | BY30: 17518000 | BZ30: 17518000 | CA30: 17518000 | CB30: 17518000 | CC30: 17518000 | CD30: 3599645 | CE30: 2699734 | CF30: 17648000 | CG30: 17648000 | CH30: 17648000 | CI30: 25734000 | CJ30: 25734000 | CK30: 25734000 | CL30: 25734000 | CM30: 25734000 | CN30: 25734000 | CO30: 25734000 | CP30: 25734000 | CQ30: 8186800.5
A31: 6.5 | B31: Other Assets | C31: 935514 | D31: 2.5922759e+08 | F31: 1.3353182e+08 | G31: 128820232 | H31: 128820232 | Q31: 0 | R31: =-[1]tb!$AG$247 -> 2.4643446e+08 | S31: 0 | T31: 0 | U31: 0 | V31: 0 | X31: 0 | Y31: 0 | Z31: 0 | AA31: 0 | AB31: 0 | AC31: 0 | AD31: 0 | AE31: 0 | AF31: 0 | AG31: 0 | AH31: 0 | AI31: 0 | AJ31: 0 | AK31: 0 | AL31: 0 | AM31: 0 | AN31: 0 | AO31: 0 | AP31: 0 | AQ31: 181803025 | AR31: 0 | AS31: 0 | AT31: 0 | AU31: 0 | AV31: 0 | AW31: 0 | AX31: 0 | AY31: 0 | AZ31: 0 | BA31: 0 | BB31: 0 | BC31: 1.2333862e+08 | BD31: 162923025 | BE31: 179803025 | BF31: 1.7187951e+08 | BG31: 1.6193181e+08 | BH31: 1.6226426e+08 | BI31: 1.6286405e+08 | BJ31: 1.5496093e+08 | BK31: 1.6076275e+08 | BL31: 1.5582198e+08 | BM31: 1.5669856e+08 | BN31: 1.5713847e+08 | BO31: 1.5252955e+08 | BP31: 150078175 | BQ31: 147578175 | BR31: 147578175 | BS31: 1.480705e+08 | BT31: 1.4794333e+08 | BU31: 1.497057e+08 | BV31: 1.4887041e+08 | BW31: 1.4687095e+08 | BY31: 1.4131487e+08 | BZ31: 1.4150222e+08 | CA31: 1.4131487e+08 | CB31: 1.4131487e+08 | CC31: 136928175 | CD31: 136928175 | CE31: 125428175 | CF31: 125563675 | CG31: 1.2499451e+08 | CH31: 125428175 | CI31: 125428175 | CJ31: 125428175 | CK31: 125428175 | CL31: 125468165 | CM31: 125428175 | CN31: 125428175 | CO31: 125428175 | CP31: 125428175 | CQ31: 113428175
B32: Total Assets | C32: =C26+C22+C19+C14+C13+C12-C53 -> 4.7538325e+08 | D32: =D26+D22+D19+D14+D13+D12 -> 5.07679e+08 | E32: =E10+E13+E14+E19+E22+E26 -> 601249270 | F32: =F10+F13+F14+F19+F22+F26 -> 4.6413652e+08 | G32: =G10+G13+G14+G19+G22+G26 -> 5.3794494e+08 | H32: =H10+H13+H14+H19+H22+H26 -> 5.4137697e+08 | I32: =I10+I13+I14+I19+I22+I26 -> 5.7912035e+08 | J32: =J10+J13+J14+J19+J22+J26 -> 3.2176642e+08 | K32: =K10+K13+K14+K19+K22+K26 -> 5.9435978e+08 | L32: =L10+L13+L14+L19+L22+L26 -> 6.0121432e+08 | ... CS32: =CS10+CS13+CS14+CS19+CS22+CS26 -> 0
A33: 7 | B33: Savings Deposits - Withdrawable deposits - FOSA) | C33: 16847165 | D33: 15401823 | E33: 18011508 | F33: 20656216 | G33: 17777237 | H33: 19926587 | I33: 27383127 | J33: 27383127 | K33: 25101091 | L33: 28751608 | M33: 26984489 | N33: 27507276 | O33: 34473158 | P33: 31556816 | Q33: 45111728 | R33: 48905597 | S33: 36126277 | T33: 34203886 | U33: 33569332 | V33: 43819425 | W33: 35174165 | X33: 37948670 | Y33: 36342998 | Z33: 36221018 | AA33: 40466132 | AB33: 42890344 | AC33: 40596096 | AD33: 51474886 | AE33: 33977753 | AF33: 41618645 | AG33: 41520260 | AH33: 39202512 | AI33: 38912549 | AJ33: 38611538 | AK33: 37183079 | AL33: 43740054 | AM33: 37163676 | AN33: 43030844 | AO33: 43089757 | AP33: 48364100 | AQ33: 48614100 | AR33: 41484423 | AS33: 41152387 | AT33: 42420543 | AU33: 42833833 | AV33: 43567265 | AW33: 38606432 | AX33: 43364745 | AY33: 41551977 | AZ33: 46057619 | BA33: 46057619 | BB33: 49219511 | BC33: 59511516 | BD33: 59788680 | BE33: 41972123 | BF33: 38940664 | BG33: 39653550 | BH33: 35059336 | BI33: 39505387 | BJ33: 38208789 | BK33: 33842063 | BL33: 42319800 | BM33: 41359495 | BN33: 48922568 | BO33: 43202579 | BP33: 47860435 | BQ33: =47070016.5+777427.4+225612 -> 48073056 | BR33: 44748933 | BS33: 46574289 | BT33: 40815256 | BU33: 56929135 | BV33: 56499684 | BW33: 50546955 | BY33: 57786254 | BZ33: 58787360 | CA33: 60620769 | CB33: 53783141 | CC33: 59663422 | CD33: =57986049.75+1286436.15+379636.15 -> 59652122 | CE33: 61809136 | CF33: 66839945 | CG33: 68651395 | CH33: 60208655 | CI33: 69111451 | CJ33: 54546341 | CK33: 54139961 | CL33: 50894442 | CM33: 50219990 | CN33: 52158523 | CO33: 45871120 | CP33: 58609992 | CQ33: 49429332
A34: 8 | B34: Short Term Deposits (e.g Fixed deposits, special savings) | F34: 1460576.8 | G34: 1341781.2 | H34: 1362011.3 | I34: 2171729.8 | J34: 2171729.8 | K34: 2218536.9 | L34: 2289868 | M34: 2520988.1 | N34: -15000 | O34: -15000 | S34: 0 | T34: 0 | U34: 0 | V34: 0 | W34: -15000 | X34: 0 | Y34: 0 | Z34: 0 | AB34: 0 | AC34: 0 | AD34: 0 | AE34: 0 | AF34: 0 | AG34: 0 | AH34: 0 | AI34: 0 | AJ34: 0 | AK34: 0 | AL34: 0 | AM34: 0 | AN34: 0 | AO34: 250000 | AP34: 250000 | AR34: 151000 | AS34: 0 | AT34: 151000 | AU34: 151000 | AV34: 151000 | AW34: 331000 | AX34: 331000 | AY34: 181000 | AZ34: 181000 | BA34: 181000 | BB34: 181000 | BC34: 181000 | BE34: 481000 | BF34: 382000 | BG34: 542000 | BH34: 492000 | BI34: 462000 | BJ34: 456000 | BK34: 683200 | BL34: 871200 | BM34: 832200 | BN34: 1006200 | BO34: 4005678.2 | BP34: 4005678.2 | BQ34: 4035678.2 | BR34: 4005678.2 | BS34: 4005678.2 | BT34: 1201200 | BU34: 1001300 | BV34: 1001300 | BW34: 1600272 | BY34: 2880450 | BZ34: 2870450 | CA34: 2322748.2 | CB34: 2322748.2 | CC34: 2102648.2 | CD34: =2102648.15+11300 -> 2113948.1 | CE34: =1422951+11300+3185793+2141712 -> 6761756 | CF34: 1672951.4 | CG34: 2874292.9 | CH34: 3900000 | CI34: 5140200.6 | CJ34: 5170200.6 | CK34: 5976795.2 | CL34: 12498352 | CM34: 11649727 | CN34: 7931570.4 | CO34: 7973170.4 | CP34: 7764995.6 | CQ34: 7469495.6
A35: 9 | B35: Non withdrawable deposits (BOSA member deposits) | C35: 3.7322967e+08 | D35: 3.8929794e+08 | E35: 415784125 | F35: 4.2352297e+08 | G35: 4.2268456e+08 | H35: 4.2642651e+08 | I35: 4.289255e+08 | J35: 4.289255e+08 | K35: 4.3485987e+08 | L35: 4.3820851e+08 | M35: 4.4016168e+08 | N35: 4.4628222e+08 | O35: 4.4564725e+08 | P35: 4.5197172e+08 | Q35: 4.5448169e+08 | R35: 4.4464562e+08 | S35: 4.6056628e+08 | T35: 4.6735761e+08 | U35: 4.7073249e+08 | V35: 4.7586137e+08 | W35: 4.8474955e+08 | X35: 4.893117e+08 | Y35: 4.9081224e+08 | Z35: 4.9164507e+08 | AA35: 4.8718085e+08 | AB35: 4.9171624e+08 | AC35: 4.9576986e+08 | AD35: 4.9634275e+08 | AE35: 5.027937e+08 | AF35: 5.0762425e+08 | AG35: 5.1087213e+08 | AH35: 5.1590025e+08 | AI35: 5.2143816e+08 | AJ35: 5.2725932e+08 | AK35: 5.2679731e+08 | AL35: 5.2213041e+08 | AM35: 5.2565868e+08 | AN35: 5.3625553e+08 | AO35: 5.40706e+08 | AP35: 5.4880044e+08 | AQ35: 548800441 | AR35: 5.4982232e+08 | AS35: 5.5757936e+08 | AT35: 5.6292242e+08 | AU35: 5.6761539e+08 | AV35: 5.7454559e+08 | AW35: 5.8508916e+08 | AX35: 5.8644593e+08 | AY35: 5.9241989e+08 | AZ35: 5.79735e+08 | BA35: 5.79735e+08 | BB35: 5.9000451e+08 | BC35: 5.9673947e+08 | BD35: 592342053 | BE35: 5.9959149e+08 | BF35: 5.9957934e+08 | BG35: 6.0477158e+08 | BH35: 6.1072066e+08 | BI35: 6.177616e+08 | BJ35: 6.2358725e+08 | BK35: 6.2949253e+08 | BL35: 6.2899733e+08 | BM35: 6.3679566e+08 | BN35: 6.4260625e+08 | BO35: 6.4949111e+08 | BP35: 6.5656202e+08 | BQ35: 6.5656202e+08 | BR35: 6.5788018e+08 | BS35: 6.629484e+08 | BT35: 6.6947452e+08 | BU35: 6.7941792e+08 | BV35: 6.8644596e+08 | BW35: 6.9115963e+08 | BY35: 6.9469359e+08 | BZ35: 6.9706176e+08 | CA35: 6.9977605e+08 | CB35: 7.0657558e+08 | CC35: 7.1349988e+08 | CD35: 7.1349988e+08 | CE35: 756058831 | CF35: 7.6069962e+08 | CG35: 7.6037185e+08 | CH35: 7.6934195e+08 | CI35: 7.7904268e+08 | CJ35: 7.8122735e+08 | CK35: 7.8324855e+08 | CL35: 7.8430685e+08 | CM35: 7.8301662e+08 | CN35: 7.9170544e+08 | CO35: 7.9190649e+08 | CP35: 7.9573398e+08 | CQ35: 8.0202415e+08
B36: Total Deposit liabilities | C36: =SUM(C33:C35) -> 3.9007683e+08 | D36: =SUM(D33:D35) -> 4.0469976e+08 | E36: =SUM(E33:E35) -> 433795633 | F36: =SUM(F33:F35) -> 4.4563976e+08 | G36: =SUM(G33:G35) -> 4.4180358e+08 | H36: =SUM(H33:H35) -> 4.4771511e+08 | I36: =SUM(I33:I35) -> 4.5848036e+08 | J36: =SUM(J33:J35) -> 4.5848036e+08 | ... CS36: =SUM(CS33:CS35) -> 0
A37: 10 | B37: Accounts Payable & Other Liabilities | C37: =C38+C39+C40+C41+C42+C43 -> 5851152.5 | D37: =D38+D39+D40+D41+D42+D43 -> 57286691 | E37: =SUM(E38:E43) -> 82474599 | F37: =SUM(F38:F43) -> 40426054 | G37: =SUM(G38:G43) -> 40426054 | H37: =SUM(H38:H43) -> 38300198 | I37: =SUM(I38:I43) -> 38300198 | J37: =SUM(J38:J43) -> 38300198 | K37: =SUM(K38:K43) -> 38300198 | L37: =SUM(L38:L43) -> 36965198 | ... CS37: =SUM(CS38:CS43) -> 0
A38: 10.1 | B38: Tax Payable | E38: =154735+199232 -> 353967 | R38: 413375.8 | S38: 0 | T38: 0 | U38: 0 | V38: 0 | X38: 0 | Y38: 0 | Z38: 0 | AA38: 0 | AB38: 0 | AC38: 0 | AD38: 0 | AE38: 0 | AF38: 0 | AG38: 0 | AH38: 0 | AI38: 0 | AJ38: 0 | AK38: 0 | AL38: 0 | AM38: 0 | AN38: 0 | AO38: 0 | AP38: 0 | AQ38: 729864 | AR38: 0 | AS38: 0 | AT38: 0 | AU38: 0 | AV38: 0 | AW38: 0 | AX38: 0 | AY38: 0 | AZ38: 0 | BA38: 0 | BB38: 10997 | BC38: 10997 | BD38: 962618 | BE38: 0 | BF38: 0 | BG38: 0 | BH38: 0 | BI38: 0 | BJ38: 0 | BK38: 0 | BL38: 0 | BM38: 0 | BN38: 0 | BO38: 0 | BP38: 32500000 | BQ38: 1459727 | BR38: 0 | BS38: 0 | BT38: 0 | BU38: 0 | BV38: 0 | BW38: 0 | BY38: 0 | BZ38: 984632 | CA38: 0 | CB38: 0 | CC38: 0 | CD38: 1910136 | CE38: 2671948 | CF38: 2671948 | CG38: 2671948 | CH38: 2497948 | CI38: 0 | CJ38: 0 | CK38: 0 | CL38: 0 | CM38: 0 | CN38: 547392 | CO38: 0 | CP38: 0 | CQ38: 1703939.4
A39: 10.2 | B39: Dividends Payable | C39: 5851152.5 | D39: 20234988 | E39: =26342838+2078921 -> 28421759 | S39: 0 | T39: 0 | U39: 0 | V39: 0 | X39: 0 | Y39: 0 | Z39: 0 | AA39: 0 | AB39: 0 | AC39: 0 | AD39: 0 | AE39: 0 | AF39: 0 | AG39: 0 | AH39: 0 | AI39: 0 | AJ39: 0 | AK39: 0 | AL39: 0 | AM39: 0 | AN39: 0 | AO39: 0 | AP39: 0 | AQ39: 31000000 | AR39: 0 | AS39: 0 | AT39: 0 | AU39: 0 | AV39: 0 | AW39: 0 | AX39: 0 | AY39: 0 | AZ39: 0 | BA39: 0 | BB39: 0 | BC39: 0 | BD39: 20740000 | BE39: 0 | BF39: 0 | BG39: 0 | BH39: 0 | BI39: 0 | BJ39: 0 | BK39: 0 | BL39: 0 | BM39: 0 | BN39: 0 | BO39: 0 | BP39: 0 | BQ39: 32500000 | BR39: 0 | BS39: 0 | BT39: 0 | BU39: 0 | BV39: 0 | BW39: 0 | BY39: 0 | BZ39: 0 | CA39: 0 | CB39: 0 | CC39: 0 | CD39: 40000000 | CE39: 48700000 | CF39: 0 | CG39: 0 | CH39: 0 | CI39: 0 | CJ39: 0 | CK39: 0 | CL39: 0 | CM39: 0 | CN39: 0 | CO39: 0 | CP39: 0 | CQ39: 0
A40: 10.3 | B40: Deferred Tax Liability | D40: =50000+5000+106681.95 -> 161681.95 | S40: 0 | T40: 0 | U40: 0 | V40: 0 | X40: 0 | Y40: 0 | Z40: 0 | AA40: 0 | AB40: 0 | AC40: 0 | AD40: 0 | AE40: 0 | AF40: 0 | AG40: 0 | AH40: 0 | AI40: 0 | AJ40: 0 | AK40: 0 | AL40: 0 | AM40: 0 | AN40: 0 | AO40: 0 | AP40: 0 | AR40: 0 | AS40: 0 | AT40: 0 | AU40: 0 | AV40: 0 | AW40: 0 | AX40: 0 | AY40: 0 | AZ40: 0 | BA40: 0 | BB40: 0 | BC40: 0 | BE40: 0 | BF40: 0 | BG40: 0 | BH40: 0 | BI40: 0 | BJ40: 0 | BK40: 0 | BL40: 0 | BM40: 0 | BN40: 0 | BO40: 0 | BP40: 0 | BR40: 0 | BS40: 0 | BT40: 0 | BU40: 0 | BV40: 0 | BW40: 0 | BY40: 0 | BZ40: 0 | CA40: 0 | CB40: 0 | CC40: 0 | CD40: 0 | CF40: 0 | CG40: 0 | CH40: 0 | CI40: 0 | CJ40: 0 | CK40: 0 | CL40: 0 | CM40: 0 | CN40: 0 | CO40: 0 | CP40: 0 | CQ40: 0
A41: 10.4 | B41: Retirement Benefits Liability | S41: 0 | T41: 0 | U41: 0 | V41: 0 | X41: 0 | Y41: 0 | Z41: 0 | AA41: 0 | AB41: 0 | AC41: 0 | AD41: 0 | AE41: 0 | AF41: 0 | AG41: 0 | AH41: 0 | AI41: 0 | AJ41: 0 | AK41: 0 | AL41: 0 | AM41: 0 | AN41: 0 | AO41: 0 | AP41: 0 | AR41: 0 | AS41: 0 | AT41: 0 | AU41: 0 | AV41: 0 | AW41: 0 | AX41: 0 | AY41: 0 | AZ41: 0 | BA41: 0 | BB41: 0 | BC41: 0 | BE41: 0 | BF41: 0 | BG41: 0 | BH41: 0 | BI41: 0 | BJ41: 0 | BK41: 0 | BL41: 0 | BM41: 0 | BN41: 0 | BO41: 0 | BP41: 0 | BR41: 0 | BS41: 0 | BT41: 0 | BU41: 0 | BV41: 0 | BW41: 0 | BY41: 0 | BZ41: 0 | CA41: 0 | CB41: 0 | CC41: 0 | CD41: 0 | CF41: 0 | CG41: 0 | CH41: 0 | CI41: 0 | CJ41: 0 | CK41: 0 | CL41: 0 | CM41: 0 | CN41: 0 | CO41: 0 | CP41: 0 | CQ41: 0
A42: 10.5 | B42: Other Liabilities | D42: 9893489.9 | E42: =-44908+120928+17920+36519+400+190220+550017+663040+11738702 -> 13272838 | R42: 30277534 | S42: 0 | T42: 0 | U42: 0 | V42: 0 | W42: 24682064 | X42: 0 | Y42: 0 | Z42: 0 | AB42: 0 | AC42: 0 | AD42: 0 | AE42: 0 | AF42: 0 | AG42: 0 | AH42: 0 | AI42: 0 | AJ42: 0 | AK42: 0 | AL42: 0 | AM42: 0 | AN42: 0 | AO42: 0 | AP42: 0 | AQ42: 949074 | AR42: 0 | AS42: 0 | AT42: 0 | AU42: 0 | AV42: 0 | AW42: 0 | AX42: 0 | AY42: 0 | AZ42: 0 | BA42: 0 | BB42: 0 | BC42: 0 | BD42: 801000 | BE42: 0 | BF42: 0 | BG42: 0 | BH42: 0 | BI42: 0 | BJ42: 0 | BK42: 0 | BL42: 0 | BM42: 0 | BN42: 0 | BO42: 0 | BP42: 0 | BQ42: =2002520.2+1000000 -> 3002520.2 | BR42: 0 | BS42: 0 | BT42: 0 | BU42: 0 | BV42: 0 | BW42: 0 | BY42: 0 | BZ42: 0 | CB42: 0 | CC42: 4756198.7 | CD42: =3374770.05+1300000 -> 4674770 | CE42: 2862127 | CF42: 0 | CG42: 0 | CH42: 2678740 | CI42: 0 | CJ42: 0 | CK42: 0 | CL42: 0 | CM42: 0 | CN42: 752536 | CO42: 3199986 | CP42: 3950793 | CQ42: 58773709
...

Sheet SCI
A1: FORM 7 SASRA/007
A2: STATEMENT OF COMPREHENSIVE INCOME
A3: NAME OF SACCO SOCIETY: ECO-PILLAR | O3: =(R10-E10)/E10 -> 0.22539948
A4: FINANCIAL YEAR | AZ4: =31928/3 -> 10642.667
A5: START DATE:
A6: END DATE:
A8: Ref No. | C8: AUDITED 2012 | D8: AUDITED 2013 | E8: Audited 2014 | F8: 42005 | G8: 42036 | H8: 42064 | I8: 42095 | J8: 42125 | K8: 42156 | L8: 42186 | M8: 42217 | N8: 42248 | O8: 42278 | P8: 42309 | Q8: 42339 | R8: Audit 2015 | S8: 42385 | T8: 42416 | U8: 42445 | V8: 42476 | W8: 42506 | X8: 42537 | Y8: 42567 | Z8: 42598 | AA8: 42629 | AB8: 42659 | AC8: 42690 | AD8: 42720 | AE8: 42736 | AF8: 42767 | AG8: 42795 | AH8: 42826 | AI8: 42856 | AJ8: 42887 | AK8: 42917 | AL8: 42948 | AM8: 42979 | AN8: 43009 | AO8: 43040 | AP8: 43070 | AQ8: Audited 2017 | AR8: 43101 | AS8: 43132 | AT8: 43160 | AU8: 43191 | AV8: 43221 | AW8: 43252 | AX8: 43282 | AY8: 43313 | AZ8: 43344 | BA8: 43374 | BB8: 43405 | BC8: 43435 | BD8: Aud-18 | BE8: 43466 | BF8: 43497 | BG8: 43525 | BH8: 43556 | BI8: 43586 | BJ8: 43617 | BK8: 43647 | BL8: 43678 | BM8: 43709 | BN8: 43739 | BO8: 43770 | BP8: 43800 | BQ8: Audited -19 | BR8: 43831 | BS8: 43862 | BT8: 43891 | BU8: 43922 | BV8: 43952 | BW8: 43983 | BX8: 44013 | BY8: 44044 | BZ8: 44075 | CA8: 44105 | CB8: 44136 | CC8: 44166 | CD8: Audited 2020 | CE8: Audited 2021 | CF8: 44562 | CG8: 44593 | CH8: 44621 | CI8: 44652 | CJ8: 44682 | CK8: 44713 | CL8: 44743 | CM8: 44774 | CN8: 44805 | CO8: 44835 | CP8: 44866 | CQ8: 44896 | CR8: Dec 2022 Audited
A10: 1 | B10: Financial Income | C10: =C11+C14 -> 45324711 | D10: =D11+D14 -> 45274899 | E10: =E11+E14 -> 67694492 | F10: =F11+F14 -> 6107686.8 | G10: =G11+G14 -> 10515264 | H10: =H11+H14 -> 14520010 | I10: =I11+I14 -> 19445843 | J10: =J11+J14 -> 28051245 | ... CR10: =CR11+CR14 -> 0
A11: 2 | B11: Financial Income from Loans Portfolio | C11: =C12+C13 -> 44986975 | D11: =D12+D13 -> 44247378 | E11: =SUM(E12:E13) -> 66366282 | F11: =SUM(F12:F13) -> 5788629.3 | G11: =SUM(G12:G13) -> 9889522.2 | H11: =SUM(H12:H13) -> 13574744 | I11: =SUM(I12:I13) -> 18194118 | J11: =SUM(J12:J13) -> 25996301 | K11: =SUM(K12:K13) -> 31493424 | L11: =SUM(L12:L13) -> 36232691 | ... CR11: =SUM(CR12:CR13) -> 0
A12: 2.1 | B12: Interest on Loan Portfolio | C12: 44346813 | D12: 43848893 | E12: =32739537+32356032 -> 65095569 | F12: 5293412.2 | G12: 8814618.7 | H12: 11941258 | I12: 15976794 | J12: 22773179 | K12: 27786423 | L12: 31965435 | M12: 34301413 | N12: 45441103 | O12: 49657572 | P12: 58085052 | Q12: 68498850 | R12: 80105335 | S12: 6240484.5 | T12: 9191283.5 | U12: 19865408 | V12: 26331597 | W12: 32790874 | X12: 36012061 | Y12: 42911257 | Z12: 44403802 | AA12: 51348502 | AB12: 56432183 | AC12: 59911894 | AD12: 68603616 | AE12: 8340896.4 | AF12: 11346978 | AG12: 16772741 | AH12: 22533644 | AI12: 29220521 | AJ12: 39968899 | AK12: 44231306 | AL12: 50819365 | AM12: 59581625 | AN12: 69449227 | AO12: 75848224 | AP12: 82516332 | AQ12: 82516332 | AR12: 8805333.2 | AS12: 17804492 | AT12: 23367416 | AU12: 31714268 | AV12: 40040279 | AW12: 49076826 | AX12: 55700743 | AY12: 62869798 | AZ12: 69961556 | BA12: 69961556 | BB12: 87604925 | BC12: 98040908 | BD12: 98521727 | BE12: 9463908 | BF12: 20608412 | BG12: 27884516 | BH12: 34642879 | BI12: 39516341 | BJ12: 52060033 | BK12: 58249943 | BL12: 69491514 | BM12: 81181260 | BN12: 86756322 | BO12: 94053168 | BP12: 1.1263499e+08 | BQ12: 1.1263499e+08 | BR12: 14539248 | BS12: 23327466 | BT12: 33316997 | BU12: 35778819 | BV12: 45263111 | BW12: 53090883 | BY12: 71863730 | BZ12: 81505966 | CA12: 93911601 | CB12: 1.0396758e+08 | CC12: 1.157573e+08 | CD12: 1.157573e+08 | CE12: 123851259 | CF12: 15038865 | CG12: 28143854 | CH12: 33929528 | CI12: 40082943 | CJ12: 48970279 | CK12: 55839194 | CL12: 65226230 | CM12: 72870868 | CN12: 81562087 | CO12: 98526541 | CP12: 1.2773453e+08 | CQ12: 1.3642388e+08
A13: 2.2 | B13: Fees & Commission on Loan Portfolio | C13: 640162.06 | D13: 398485.5 | E13: 1270713 | F13: 495217.05 | G13: 1074903.5 | H13: 1633485.9 | I13: 2217323.9 | J13: 3223122.1 | K13: 3707001.4 | L13: 4267256.1 | M13: 5304368.1 | N13: 2868188 | O13: 3041503.6 | P13: 3332466.5 | Q13: 3926584.1 | R13: 2451398.7 | S13: 391158 | T13: 575348 | U13: 755467.9 | V13: 3980742.3 | W13: 4961777.1 | X13: 5474023.7 | Y13: 5997308.3 | Z13: 6706225.2 | AA13: 7285245.7 | AB13: 7866097.2 | AC13: 8354035.2 | AD13: 8769113.2 | AE13: 628376 | AF13: 723569.5 | AG13: 2380936.9 | AH13: 4130600.2 | AI13: 4918751.9 | AJ13: 5588518.4 | AK13: 5692394.8 | AL13: 6673249.6 | AM13: 7627231.6 | AN13: 7934004.1 | AO13: 8613850 | AP13: 11458304 | AQ13: 11517170 | AR13: 545627.5 | AS13: 1044731.3 | AT13: 2548667.5 | AU13: 3939722.2 | AV13: 4907707.4 | AW13: 5523410.8 | AX13: 6044592.2 | AY13: 6918273.8 | AZ13: 7994676.6 | BA13: 7994676.6 | BB13: 9944911.6 | BC13: 9862884.8 | BE13: 3388162.8 | BF13: 2847760.4 | BG13: 3592766.8 | BH13: 4768859.1 | BI13: 5715067.9 | BJ13: 6315782.6 | BK13: 7008611.3 | BL13: 8506045 | BM13: 9212470.3 | BN13: 10188364 | BO13: 11422172 | BP13: 12059443 | BR13: 845976.2 | BS13: 1598571.7 | BT13: 2390109.1 | BU13: 5271418.3 | BV13: 6465918.2 | BW13: 7530483.4 | BY13: 12554228 | BZ13: 14003169 | CA13: 14981978 | CB13: 15993606 | CC13: 17109702 | CF13: 2017645.9 | CG13: 3212177.5 | CH13: 5312494 | CI13: 9997249.9 | CJ13: 12509357 | CK13: 14800532 | CL13: 17174592 | CM13: 18471614 | CN13: 20884364 | CO13: 26053688 | CP13: 24491131 | CQ13: 25619577
A14: 3 | B14: Financial Income from Investments in: | C14: =SUM(C16:C18) -> 337736.05 | D14: =SUM(D16:D18) -> 1027520.1 | E14: =SUM(E15:E18) -> 1328210 | F14: =SUM(F15:F18) -> 319057.5 | G14: =SUM(G15:G18) -> 625742 | H14: =SUM(H15:H18) -> 945266 | I14: =SUM(I15:I18) -> 1251725 | J14: =SUM(J15:J18) -> 2054943.6 | K14: =SUM(K15:K18) -> 2277488.6 | L14: =SUM(L15:L18) -> 2496039.6 | ... CR14: =SUM(CR15:CR18) -> 0
A15: 3.1 | B15: Government Securities | N15: 0 | O15: 0 | P15: 0 | Q15: 0 | S15: 0 | T15: 0 | U15: 0 | W15: 0 | X15: 0 | Y15: 0 | Z15: 0 | AA15: 0 | AB15: 0 | AC15: 0 | AD15: 0 | AE15: 0 | AF15: 0 | AG15: 0 | AH15: 0 | AI15: 0 | AJ15: 0 | AK15: 0 | AL15: 0 | AM15: 0 | AN15: 0 | AO15: 0 | AP15: 0 | AR15: 0 | AS15: 0 | AT15: 0 | AU15: 0 | AV15: 0 | AW15: 0 | AX15: 0 | AY15: 0 | AZ15: 0 | BB15: 0 | BC15: 0 | BE15: 0 | BF15: 0 | BG15: 0 | BH15: 0 | BI15: 0 | BJ15: 0 | BK15: 0 | BL15: 0 | BM15: 0 | BN15: 0 | BO15: 0 | BP15: 0 | BR15: 0 | BS15: 0 | BT15: 0 | BU15: 0 | BV15: 0 | BW15: 0 | BY15: 0 | BZ15: 0 | CA15: 0 | CB15: 0 | CC15: 0 | CF15: 0 | CG15: 0 | CH15: 0 | CI15: 0 | CJ15: 0 | CK15: 0 | CL15: 0 | CM15: 0 | CN15: 0 | CO15: 0 | CP15: 0 | CQ15: 0
A16: 3.2 | B16: Deposit with Banks and Other Financial Inst. | N16: 0 | O16: 0 | P16: 0 | Q16: 0 | S16: 0 | T16: 0 | U16: 0 | W16: 0 | X16: 0 | Y16: 0 | Z16: 0 | AA16: 0 | AB16: 0 | AC16: 0 | AD16: 0 | AE16: 0 | AF16: 0 | AG16: 0 | AH16: 0 | AI16: 0 | AJ16: 0 | AK16: 0 | AL16: 0 | AM16: 0 | AN16: 0 | AO16: 0 | AP16: 0 | AQ16: 1467012 | AR16: 0 | AS16: 0 | AT16: 0 | AU16: 0 | AV16: 0 | AW16: 0 | AX16: 0 | AY16: 0 | AZ16: 0 | BB16: 0 | BC16: 0 | BE16: 0 | BF16: 0 | BG16: 0 | BH16: 0 | BI16: 0 | BJ16: 0 | BK16: 0 | BL16: 0 | BM16: 0 | BN16: 0 | BO16: 0 | BP16: 0 | BR16: 0 | BS16: 0 | BT16: 0 | BU16: 0 | BV16: 0 | BW16: 0 | BY16: 0 | BZ16: 0 | CA16: 0 | CB16: 0 | CC16: 0 | CF16: 0 | CG16: 0 | CH16: 0 | CI16: 0 | CJ16: 0 | CK16: 0 | CL16: 0 | CM16: 0 | CN16: 0 | CO16: 0 | CP16: 0 | CQ16: 0
A17: 3.3 | B17: Other Investments - dividend & Interest incomes from investments | C17: 337736.05 | D17: 1027520.1 | N17: 0 | O17: 0 | P17: 0 | Q17: 0 | S17: 0 | T17: 0 | U17: 0 | V17: 424462 | W17: 424462 | X17: 440244 | Y17: 895808.35 | Z17: 895808.35 | AA17: 895808.35 | AB17: 895808.35 | AC17: 895808.35 | AD17: 895808.35 | AE17: 0 | AF17: 0 | AG17: 0 | AH17: 0 | AI17: 0 | AJ17: 1026160 | AK17: 1467012 | AL17: 1867012 | AM17: 1467012 | AN17: 1467012 | AO17: 1467012 | AP17: 1467012 | AR17: 0 | AS17: 0 | AT17: 0 | AU17: 0 | AV17: 0 | AW17: 896 | AX17: 569886.5 | AY17: 587922.2 | AZ17: 587922.2 | BA17: 587922.2 | BB17: 587922.2 | BC17: 587922.2 | BE17: 0 | BF17: 2443.75 | BG17: 2443.75 | BH17: 0 | BI17: 0 | BJ17: 0 | BK17: 523123.2 | BL17: 523123.2 | BM17: 523123.2 | BN17: 523123.2 | BO17: 523123.2 | BP17: 523123.2 | BR17: 0 | BS17: 0 | BT17: 0 | BU17: 1080094.1 | BV17: 1080094.1 | BW17: 1584430.1 | BY17: 1584430.1 | BZ17: 1584430.1 | CA17: 1584430.1 | CB17: 1584430.1 | CC17: 1584430.1 | CF17: 680734 | CG17: 380734 | CH17: 382566.8 | CI17: 382566.8 | CJ17: 382566.8 | CK17: 1567106.4 | CL17: 1567106.4 | CM17: 1567106.4 | CN17: 1567106.4 | CO17: 3385932.2 | CP17: 3385932.2 | CQ17: 3592164.2
A18: 3.4 | B18: Other Operating Income- Salary processing fees, transaction fees, membership fees | E18: 1328210 | F18: 319057.5 | G18: 625742 | H18: 945266 | I18: 1251725 | J18: 2054943.6 | K18: 2277488.6 | L18: 2496039.6 | M18: 2873568.6 | N18: 5590391.9 | O18: 6122572.9 | P18: 6319675.9 | Q18: 7123546.9 | R18: 396062 | S18: 688684 | T18: 1175683.1 | U18: 1566079.1 | V18: 328800 | W18: 490815 | X18: 639471 | Y18: 1215751 | Z18: 1448701 | AA18: 1524851 | AB18: 1712711 | AC18: 1862561 | AD18: 2622501 | AE18: 826983.36 | AF18: 887325.45 | AG18: 812495 | AH18: 1226105.6 | AI18: 1439799.6 | AJ18: 2436674.6 | AK18: 2452674.6 | AL18: 2725284.6 | AM18: 2576934.6 | AN18: 2587334.6 | AO18: 2692971 | AP18: 3398751 | AQ18: 3398751 | AR18: 141210 | AS18: 700280 | AT18: 474544 | AU18: 651919 | AV18: 1206224 | AW18: 1724286.6 | AX18: 2084924.6 | AY18: 2453562.3 | AZ18: 2574276.3 | BA18: 2574276.3 | BB18: 3168625.9 | BC18: 3576864.9 | BD18: 18017613 | BE18: 370131 | BF18: 671035.65 | BG18: 901180.65 | BH18: 1475080.6 | BI18: 1999306.1 | BJ18: 2619777.3 | BK18: 2275420.9 | BL18: 2536508.7 | BM18: 2884154.1 | BN18: 3076695.7 | BO18: 3381902.4 | BP18: 3667631.4 | BQ18: 17783000 | BR18: 382658.77 | BS18: 663591.77 | BT18: 731881.77 | BU18: 1293236.8 | BV18: 1754791.8 | BW18: 2343091.8 | BY18: 2826595.5 | BZ18: 3873055.5 | CA18: 4381456 | CB18: 4423370.5 | CC18: 4903124.4 | CD18: 23597256 | CE18: 35619130 | CF18: 0 | CG18: 0 | CH18: 0 | CI18: 0 | CJ18: 0 | CK18: 0 | CL18: 0 | CM18: 3201170 | CN18: 3571120 | CO18: 6458005 | CP18: 2888995 | CQ18: 4163956.2
A19: 4 | B19: Financial Expense | C19: =SUM(C20:C25) -> 13012501 | D19: =SUM(D20:D25) -> 9863205.4 | E19: =E20+E21+E22+E23+E24+E25 -> 27897903 | F19: =F20+F21+F22+F23+F24+F25 -> 1335000 | G19: =G20+G21+G22+G23+G24+G25 -> 1335000 | H19: =H20+H21+H22+H23+H24+H25 -> 1335000 | I19: =I20+I21+I22+I23+I24+I25 -> 9913510.1 | J19: =J20+J21+J22+J23+J24+J25 -> 12106280 | K19: =K20+K21+K22+K23+K24+K25 -> 14380796 | L19: =L20+L21+L22+L23+L24+L25 -> 16672298 | ... CR19: =CR20+CR21+CR22+CR23+CR24+CR25 -> 0
A20: 4.2 | B20: Interest Expense on Deposits | C20: 5851152.5 | D20: 6070496.4 | E20: 24947048 | I20: 8578510.1 | J20: 10771280 | K20: 13045796 | L20: 15337298 | M20: 16606467 | N20: 20082700 | O20: 22280900 | P20: 24858444 | Q20: 27268901 | R20: 15562597 | S20: 1655641.9 | T20: 1363126 | U20: 4118909.3 | V20: 5551715.9 | W20: 7069264.2 | X20: 8562954.7 | Y20: 10020750 | Z20: 11471718 | AA20: 12788497 | AB20: 14341727 | AC20: 18178228 | AD20: 17371996 | AE20: 2780236.3 | AF20: 0 | AG20: 0 | AH20: 5394570.3 | AI20: 9342433.8 | AJ20: 11278942 | AK20: 13828429 | AL20: 14967738 | AM20: 16952493 | AN20: 21137406 | AO20: 21312828 | AP20: 23598419 | AQ20: 29700000 | AR20: 2474200.5 | AS20: 5018214.2 | AT20: 7599452.7 | AU20: 10217077 | AV20: 12687882 | AW20: 15797407 | AX20: 18473047 | AY20: 21327116 | AZ20: 23479268 | BA20: 23479268 | BB20: 29205223 | BC20: 36997847 | BD20: 20740000 | BE20: 0 | BF20: 3497546.2 | BG20: 5291751.3 | BH20: 7125074.2 | BI20: 9006856.7 | BJ20: 10912777 | BK20: 12852139 | BL20: 14676604 | BM20: 16715886 | BN20: 18742682 | BO20: 22732189 | BP20: 32500000 | BQ20: 32500000 | BR20: 2739854.4 | BS20: 5524570 | BT20: 8368431.4 | BU20: 11323632 | BV20: 14300957 | BW20: 17278991 | BY20: 23156453 | BZ20: 26139816 | CA20: 31259297 | CB20: 35623186 | CC20: 40000000 | CD20: 40000000 | CE20: 47000000 | CF20: 680734 | CG20: 380734 | CH20: 382566.8 | CI20: 382566.8 | CJ20: 382566.8 | CK20: 1567106.4 | CL20: 1567106.4 | CM20: 31500900 | CN20: 35626745 | CO20: 44495324 | CP20: 51059597 | CQ20: 50400000
A21: 4.3 | B21: Cost of External Borrowings | C21: =2187682+4876654.2 -> 7064336.2 | D21: =3371543+378751 -> 3750294 | E21: 1335000 | F21: 1335000 | G21: 1335000 | H21: 1335000 | I21: 1335000 | J21: 1335000 | K21: 1335000 | L21: 1335000 | M21: 1335000 | N21: 1335000 | O21: 1335000 | P21: 0 | Q21: 1335000 | R21: 13249143 | S21: 1335000 | T21: 0 | U21: 2726252 | V21: 4343744.9 | W21: 6456798.9 | X21: 7748158.6 | Y21: 8979578.6 | Z21: 1335000 | AA21: 1335000 | AB21: 1335000 | AC21: 1335000 | AD21: 1335000 | AE21: 1335000 | AF21: 1335000 | AG21: 2770280 | AH21: 3770280 | AI21: 4272396.4 | AJ21: 5070280 | AK21: 5896536 | AL21: 6932410.4 | AM21: 7570389.6 | AN21: 8930285.4 | AO21: 9589535.7 | AP21: 9589535.7 | AQ21: 9592536 | AR21: 0 | AS21: 1246379 | AT21: 1350000 | AU21: 1350000 | AV21: 3261479 | AW21: 4861479 | AX21: 4861479 | AY21: 5961479 | AZ21: 6451479 | BA21: 6451479 | BB21: 7508389.6 | BC21: 7508389.6 | BD21: 7512889 | BE21: 1925360.2 | BF21: 1925360.4 | BG21: 2240125.7 | BH21: 2865321.2 | BI21: 3400899.5 | BJ21: 5301799.1 | BK21: 5301799.1 | BL21: 7363625.6 | BM21: 7363625.6 | BN21: 9276280.1 | BO21: 9276280.1 | BP21: 10610116 | BQ21: 10610116 | BR21: 1570137 | BS21: 1570137 | BT21: 2201413.3 | BU21: 3201413.3 | BV21: 5664581 | BW21: 6689016.5 | BY21: 8711019.9 | BZ21: 9700575.9 | CA21: 10147494 | CB21: 10147494 | CC21: 11784115 | CD21: 11784115 | CE21: 10402628 | CF21: 1254347 | CG21: 1875459.6 | CH21: 2141451 | CI21: 3141451 | CJ21: 3846930.5 | CK21: 5298862.5 | CL21: 6529555.3 | CM21: 7329455.3 | CN21: 8539260.5 | CO21: 9739260.5 | CP21: 10846900 | CQ21: 14501682
A22: 4.4 | B22: Dividend Expenses (on member shares) | Q22: 0 | S22: 0 | T22: 0 | U22: 0 | V22: 0 | X22: 0 | Y22: 0 | Z22: 0 | AA22: 0 | AB22: 0 | AC22: 0 | AD22: 0 | AE22: 0 | AF22: 0 | AG22: 0 | AH22: 0 | AI22: 0 | AJ22: 0 | AK22: 0 | AL22: 0 | AM22: 0 | AN22: 0 | AO22: 0 | AP22: 0 | AR22: 0 | AS22: 0 | AT22: 0 | AU22: 0 | AV22: 0 | AX22: 0 | AY22: 0 | AZ22: 0 | BA22: 0 | BB22: 0 | BC22: 0 | BE22: 0 | BF22: 0 | BG22: 0 | BH22: 0 | BI22: 0 | BJ22: 0 | BK22: 0 | BL22: 0 | BM22: 0 | BN22: 0 | BO22: 0 | BP22: 0 | BR22: 0 | BS22: 0 | BT22: 0 | BU22: 0 | BV22: 0 | BW22: 0 | BY22: 0 | BZ22: 0 | CA22: 0 | CB22: 0 | CC22: 0 | CF22: 0 | CG22: 0 | CH22: 0 | CI22: 0 | CJ22: 0 | CK22: 0 | CL22: 0 | CM22: 0 | CN22: 0 | CO22: 0 | CP22: 0 | CQ22: 0
A23: 4.5 | B23: Other Financial Expense | E23: 568105 | S23: 0 | T23: 0 | U23: 0 | V23: 0 | X23: 0 | Y23: 0 | Z23: 0 | AA23: 0 | AB23: 0 | AC23: 0 | AD23: 0 | AE23: 0 | AF23: 0 | AG23: 1432000 | AH23: 1432000 | AI23: 1432000 | AJ23: 1432000 | AK23: 1432000 | AL23: 1432000 | AM23: 1432000 | AN23: 1432000 | AO23: 2369867.9 | AP23: 2369867.9 | AR23: 0 | AS23: 0 | AT23: 0 | AU23: 0 | AV23: 0 | AX23: 0 | AY23: 0 | AZ23: 379698.56 | BA23: 379698.56 | BB23: 0 | BC23: 0 | BE23: 19104 | BF23: 67606 | BG23: 83956 | BH23: 84755.45 | BI23: 0 | BJ23: 0 | BK23: 1354821.4 | BL23: 1420353.4 | BM23: 2370834.6 | BN23: 1576376.6 | BO23: 1697236.6 | BP23: 0 | BR23: 0 | BS23: 167421.59 | BT23: 534638.94 | BU23: 0 | BV23: 794589.51 | BW23: 794589.51 | BY23: 1120674.2 | BZ23: 1704092.8 | CA23: 1958147.7 | CB23: 2161992.2 | CC23: 2721608.2 | CD23: 1799552 | CF23: 0 | CG23: 0 | CH23: 0 | CI23: 628719.99 | CJ23: 859263.54 | CK23: 419823.17 | CL23: 484091.81 | CM23: 558497.6 | CN23: 562300.2 | CO23: 562300.2 | CP23: 570350.8 | CQ23: 0
A24: 4.6 | B24: Fees & Commission Expense | C24: 97012.1 | D24: 42415 | S24: 0 | T24: 0 | U24: 0 | V24: 0 | X24: 0 | Y24: 0 | Z24: 0 | AA24: 1 | AB24: 0 | AC24: 0 | AD24: 0 | AE24: 0 | AF24: 0 | AG24: 0 | AH24: 0 | AI24: 0 | AJ24: 0 | AK24: 0 | AL24: 0 | AM24: 0 | AN24: 0 | AO24: 0 | AP24: 0 | AR24: 0 | AS24: 0 | AT24: 0 | AU24: 0 | AV24: 0 | AX24: 0 | AY24: 0 | AZ24: 0 | BA24: 0 | BB24: 0 | BC24: 0 | BD24: 0 | BE24: 0 | BF24: 0 | BG24: 0 | BH24: 0 | BI24: 0 | BJ24: 0 | BK24: 0 | BL24: 0 | BM24: 0 | BN24: 0 | BO24: 0 | BP24: 0 | BR24: 0 | BS24: 0 | BT24: 0 | BU24: 0 | BV24: 0 | BW24: 0 | BY24: 0 | BZ24: 0 | CA24: 0 | CB24: 0 | CC24: 0 | CF24: 0 | CG24: 0 | CH24: 0 | CI24: 0 | CJ24: 0 | CK24: 0 | CL24: 0 | CM24: 0 | CN24: 0 | CO24: 0 | CP24: 0 | CQ24: 0
A25: 4.7 | B25: Other Expense | E25: =912500+135250 -> 1047750 | AK25: 0 | AL25: 0 | AO25: 0 | AP25: 0 | AR25: 0 | AS25: 0 | AT25: 0 | AU25: 0 | AV25: 0 | AX25: 0 | AY25: 0 | AZ25: 0 | BA25: 0 | BB25: 0 | BC25: 0 | BD25: 0 | BE25: 0 | BF25: 0 | BG25: 0 | BH25: 0 | BI25: 0 | BJ25: 0 | BK25: 0 | BL25: 0 | BM25: 0 | BN25: 0 | BO25: 0 | BP25: 0 | BR25: 0 | BS25: 0 | BT25: 0 | BU25: 0 | BV25: 0 | BW25: 0 | BY25: 0 | BZ25: 0 | CA25: 0 | CB25: 0 | CC25: 0 | CD25: 1910136 | CF25: 0 | CG25: 0 | CH25: 0 | CI25: 0 | CJ25: 0 | CK25: 0 | CL25: 0 | CM25: 0 | CN25: 0 | CO25: 0 | CP25: 0 | CQ25: 0
A26: 5 | B26: Net Financial Income/(Loss) | C26: =C10-C19 -> 32312211 | D26: =D10-D19 -> 35411693 | E26: =E10-E19 -> 39796589 | F26: =F10-F19 -> 4772686.8 | G26: =G10-G19 -> 9180264.2 | H26: =H10-H19 -> 13185010 | I26: =I10-I19 -> 9532332.7 | J26: =J10-J19 -> 15944965 | ... CR26: =CR10-CR19 -> 0
A27: 6 | B27: Allowance for Loan Loss | C27: =C28-C29 -> 0 | D27: =D28-D29 -> 852418.02 | E27: =E28-E29 -> 6113750 | F27: =F28-F29 -> 2004119.4 | G27: =G28-G29 -> 2320087 | H27: =H28-H29 -> 3800123 | I27: =I28-I29 -> 7996958.1 | J27: =J28-J29 -> 7808518.7 | ... CR27: =CR28-CR29 -> 0
A28: 6.1 | B28: Provision for Loan Losses | D28: 852418.02 | E28: 6113750 | F28: 31788444 | G28: 35574259 | H28: 37229273 | I28: 35191294 | J28: 36008201 | K28: 25650895 | L28: 25565318 | M28: 25565318 | N28: 26684223 | O28: 35042555 | P28: 35144795 | Q28: 27229957 | R28: 1690285 | S28: 31295425 | T28: 7826079.6 | U28: 6634379.5 | V28: 5990682.4 | W28: 7195090.7 | X28: 8136285.8 | Y28: 9901946.3 | Z28: 12479945 | AA28: 11512086 | AB28: 11922708 | AC28: 10596215 | AD28: 18317842 | AE28: 11236789 | AF28: 12369785 | AG28: 11924753 | AH28: 12394567 | AI28: 11095883 | AJ28: 13741671 | AK28: 13340487 | AL28: 10375126 | AM28: 13645903 | AN28: 14379390 | AO28: 9825396.4 | AP28: 13788864 | AQ28: 3973233 | AR28: 13245897 | AS28: 11245365 | AT28: 12757388 | AU28: 13526987 | AV28: 14369785 | AW28: 10502228 | AX28: 11868566 | AY28: 9807410.6 | AZ28: 9609968.1 | BA28: 9609968.1 | BB28: 10509439 | BC28: 12013231 | BD28: 3500000 | BE28: 9625368.9 | BF28: 10225012 | BG28: 10867106 | BH28: 10735257 | BI28: 9298227.3 | BJ28: 9879712.9 | BK28: 9507885.7 | BL28: 9703533.6 | BM28: 9824517.5 | BN28: 10001064 | BO28: 10778845 | BP28: 11034851 | BQ28: 6000000 | BR28: 10526347 | BS28: 11311511 | BT28: 10722159 | BU28: 8260963.2 | BV28: 10260370 | BW28: 10699318 | BY28: 10257200 | BZ28: 10146692 | CA28: 10413070 | CB28: 11552130 | CC28: 8329276.5 | CD28: 7000000 | CE28: 7000000 | CF28: 6915696.2 | CG28: 6959043.4 | CH28: 6655279.3 | CI28: 7103146.2 | CJ28: 7315798.9 | CK28: 7178230.4 | CL28: 7595142 | CM28: 7494352.8 | CN28: 7730461 | CO28: 7725468.1 | CP28: 7825319.1 | CQ28: 7500000
A29: 6.2 | B29: Value of Loans Recovered | F29: 29784325 | G29: 33254172 | H29: 33429150 | I29: 27194336 | J29: 28199682 | K29: 23103646 | L29: 23404696 | M29: 23404696 | N29: 22792072 | O29: 30649054 | P29: 29873076 | Q29: 20107616 | S29: 29284946 | T29: 6815782.4 | U29: 4569251.2 | V29: 3620452.3 | W29: 5982013.4 | X29: 7139586.3 | Y29: 8802356.2 | Z29: 10425369 | AA29: 10155370 | AB29: 6349865.2 | AC29: 6389707.6 | AD29: 12319867 | AE29: 9920369.6 | AF29: 10526379 | AG29: 9863269.4 | AH29: 11479087 | AI29: 10235987 | AJ29: 12389964 | AK29: 12325370 | AL29: 9026967.1 | AM29: 12125370 | AN29: 12550237 | AO29: 8239489.7 | AP29: 12349212 | AQ29: 0 | AR29: 12362429 | AS29: 10163279 | AT29: 11428697 | AU29: 12247893 | AV29: 13246589 | AW29: 9233125.9 | AX29: 10800269 | AY29: 8137500 | AZ29: 8246398.4 | BA29: 8246398.4 | BB29: 9352689.4 | BC29: 10152357 | BE29: 8245149.2 | BF29: 9094251.4 | BG29: 9214522.2 | BH29: 8254126.4 | BI29: 8150236.4 | BJ29: 8245362.1 | BK29: 8213456.2 | BL29: 8239569.3 | BM29: 8249165.3 | BN29: 8715345.6 | BO29: 9256135.7 | BP29: 3450000 | BR29: 8246796.3 | BS29: 10213456 | BT29: 9287360.9 | BU29: 7340694 | BV29: 9145689.2 | BW29: 9356290.2 | BY29: 7925633.1 | BZ29: 9146237 | CA29: 9134856.3 | CB29: 10135630 | CC29: 0 | CF29: 5203146.2 | CG29: 5124989.2 | CH29: 5112479.3 | CI29: 5346983.3 | CJ29: 6154237 | CK29: 5924156.4 | CL29: 6123587.3 | CM29: 6232550.2 | CN29: 6320450.2 | CO29: 6505450.2 | CP29: 6400455.2 | CQ29: 0
A30: 7 | B30: Operating Expenses | C30: =C31+C32+C33+C34+C35 -> 14729924 | D30: =D31+D32+D33+D34+D35 -> 23782929 | E30: =SUM(E31:E35) -> 28899075 | F30: =SUM(F31:F35) -> 2685293.5 | G30: =SUM(G31:G35) -> 7250951.1 | H30: =SUM(H31:H35) -> 10496937 | I30: =SUM(I31:I35) -> 16723133 | J30: =SUM(J31:J35) -> 17981726 | K30: =SUM(K31:K35) -> 22147582 | L30: =SUM(L31:L35) -> 24527976 | ... CR30: =SUM(CR31:CR35) -> 0
A31: 7.1 | B31: Personnel Expenses | C31: 5434455 | D31: 7065720.4 | E31: =3537698+1282293+960960+53200+2313830+1812660 -> 9960641 | F31: 250647.58 | G31: 1647087.7 | H31: 1920033.6 | I31: 2265954.6 | J31: 2265954.6 | K31: 4021991.5 | L31: 4609287.5 | M31: 5177287.5 | N31: 9466252.9 | O31: 10459187 | P31: 11428658 | Q31: 12759714 | R31: 18827351 | S31: 1117127 | T31: 2254970 | U31: 3376527 | V31: 4441940 | W31: 6340550 | X31: 8786218 | Y31: 10432809 | Z31: 11855632 | AA31: 13295668 | AB31: 14878301 | AC31: 16757699 | AD31: 18957066 | AE31: 1236782.1 | AF31: 2052326.6 | AG31: 4291914 | AH31: 5304952 | AI31: 6757568 | AJ31: 8946309 | AK31: 10762763 | AL31: 12119377 | AM31: 15835392 | AN31: 16329416 | AO31: 17758581 | AP31: 20196229 | AQ31: 20296229 | AR31: 2111580 | AS31: 2448580 | AT31: 5297015 | AU31: 6772103.6 | AV31: 9615117.6 | AW31: 13762690 | AX31: 15054121 | AY31: 17353694 | AZ31: 19535377 | BA31: 19535377 | BB31: 24258159 | BC31: 27489033 | BD31: 21067433 | BE31: 2668499.1 | BF31: 3892858.1 | BG31: 5672374.4 | BH31: 9213306.5 | BI31: 11196575 | BJ31: 13057625 | BK31: 14888992 | BL31: 17590287 | BM31: 19607519 | BN31: 21522692 | BO31: 23275040 | BP31: 23672845 | BQ31: 24413005 | BR31: 1967820 | BS31: 3960896.9 | BT31: 5827391.9 | BU31: 7723011.9 | BV31: 8988999.3 | BW31: 10979019 | BY31: 15878253 | BZ31: 18074347 | CA31: 20981323 | CB31: 22867705 | CC31: 26053125 | CD31: 26053125 | CE31: 27260039 | CF31: 1797524 | CG31: 3358948 | CH31: 5213208.6 | CI31: 8060223.6 | CJ31: 10319548 | CK31: 12770811 | CL31: 15133254 | CM31: 17672338 | CN31: 21740896 | CO31: 23951116 | CP31: 27272528 | CQ31: 29117254
