Workbook

Sheet Balance Sheet
B1: KIPSIGIS EDIS SACCO SOCIETY | Q1: =+V:V -> 0
B2: STATEMENT OF FINANCIAL POSITION
B3: FINANCIAL YEAR 2020 | C3: Jan | D3: Feb | E3: Mar | F3: Apr | G3: May | H3: Jun | I3: Jul | J3: Aug | K3: Sep | L3: Oct | M3: Nov | N3: Dec | O3: Aud-21 | P3: 44583 | Q3: 44614 | R3: 44642 | S3: 44673 | T3: 44703 | U3: 44734 | V3: 44764 | W3: 44795 | X3: 44826 | Y3: 44856 | Z3: 44887 | AA3: 44917 | AB3: Audited 2022
A4: 1 | B4: Cash & Cash Equivalent | C4: =C5+C6 -> 21869559 | D4: =D5+D6 -> 20393309 | E4: =E5+E6 -> 13152600 | F4: =F5+F6 -> 8085101.1 | G4: =G5+G6 -> 5660346.6 | H4: =H5+H6 -> 8033299.3 | I4: =I5+I6 -> 5971670.2 | J4: =J5+J6 -> 9141548.8 | ... AC4: =AC5+AC6 -> 0
A5: 1.1 | B5: Cash in hand(both local and foreign notes and coins) | C5: 3547039 | D5: 2873262 | E5: 3617583 | F5: 2812329 | G5: 3355911 | H5: 2941444 | I5: 2735368 | J5: 3832464 | K5: 3233753 | L5: 3479163 | M5: 2703381 | N5: 425510.05 | O5: 474905 | P5: 933625.05 | Q5: 209945.05 | R5: 811794.05 | S5: 1316251.1 | T5: 1448677.1 | U5: 1268559.1 | V5: 415967.05 | W5: 1027703.1 | X5: 1124591.1 | Y5: 1231041.1 | Z5: 1753516.1 | AA5: 342812.05 | AB5: 342812
A6: 1.2 | B6: Cash at bank:(placement with financial institutions) | C6: 18322520 | D6: 17520047 | E6: 9535017.4 | F6: 5272772.1 | G6: 2304435.5 | H6: 5091855.3 | I6: 3236302.1 | J6: 5309084.7 | K6: 1942771.7 | L6: 804848.73 | M6: 1063504.6 | N6: 3502662.1 | O6: 9253533 | P6: 8732969.2 | Q6: 8068728 | R6: 4445877.3 | S6: 555308.43 | T6: 5016583.8 | U6: 8180685.1 | V6: 12635236 | W6: 15009882 | X6: 15445546 | Y6: 7105034.8 | Z6: 8503291.3 | AA6: 6596216.7 | AB6: =9010955-342812 -> 8668143
A7: 2 | B7: Prepayments & Sundry Receivables | C7: 8228625.5 | D7: 8166766.8 | E7: 8109412.5 | F7: 9162507.2 | G7: 8765505.3 | H7: 8495541.8 | I7: 8435282.5 | J7: 7382024 | K7: 7545191.9 | L7: 7554749.5 | M7: 7870453.4 | N7: 6759764.1 | O7: 24569795 | P7: 7600054.6 | Q7: 8474968 | R7: 8475708.4 | S7: 8542990.9 | T7: 8069519 | U7: 7982954.9 | V7: 8147430.1 | W7: 10718178 | X7: 9863994.7 | Y7: 10142080 | Z7: 11632055 | AA7: 11655614 | AB7: 30879703
A8: 3 | B8: Financial Investments | C8: =SUM(C9:C12) -> 6000 | D8: =SUM(D9:D12) -> 6000 | E8: =SUM(E9:E12) -> 6000 | F8: =SUM(F9:F12) -> 6000 | G8: =SUM(G9:G12) -> 6000 | H8: =SUM(H9:H12) -> 6000 | I8: =SUM(I9:I12) -> 6000 | J8: =SUM(J9:J12) -> 6000 | ... AB8: =SUM(AB9:AB12) -> 106000
A9: 3.1 | B9: Government Securities - Treasury Bills/bonds, | C9: 0 | D9: 0 | E9: 0 | F9: 0 | G9: 0 | H9: 0 | I9: 0 | J9: 0 | K9: 0 | L9: 0 | M9: 0 | N9: 0 | P9: 0 | Q9: 0 | R9: 0 | S9: 0 | T9: 0 | U9: 0 | V9: 0 | W9: 0 | X9: 0 | Y9: 0 | Z9: 0 | AA9: 0
A10: 3.2 | B10: Other Securities - Commercial papers/Bonds | C10: 0 | D10: 0 | E10: 0 | F10: 0 | G10: 0 | H10: 0 | I10: 0 | J10: 0 | K10: 0 | L10: 0 | M10: 0 | N10: 0 | P10: 0 | Q10: 0 | R10: 0 | S10: 0 | T10: 0 | U10: 0 | V10: 0 | W10: 0 | X10: 0 | Y10: 0 | Z10: 0 | AA10: 0
A11: 3.3a | B11: Balances with other SACCO Societies | C11: 0 | D11: 0 | E11: 0 | F11: 0 | G11: 0 | H11: 0 | I11: 0 | J11: 0 | K11: 0 | L11: 0 | M11: 0 | N11: 0 | O11: 6000 | P11: 0 | Q11: 0 | R11: 0 | S11: 0 | T11: 0 | U11: 0 | V11: 0 | W11: 0 | X11: 0 | Y11: 0 | Z11: 0 | AA11: 0 | AB11: 106000
A12: 3.3b | B12: Investments in companies - shares/stocks | C12: 6000 | D12: 6000 | E12: 6000 | F12: 6000 | G12: 6000 | H12: 6000 | I12: 6000 | J12: 6000 | K12: 6000 | L12: 6000 | M12: 6000 | N12: 6000 | P12: 6000 | Q12: 6000 | R12: 6000 | S12: 6000 | T12: 6000 | U12: 56000 | V12: 56000 | W12: 106000 | X12: 106000 | Y12: 106000 | Z12: 106000 | AA12: 106000
A13: 4 | B13: Net Loan Portfolio | C13: =C14-C15 -> 1.5366134e+08 | D13: =D14-D15 -> 1.5618533e+08 | E13: =E14-E15 -> 1.6603889e+08 | F13: =F14-F15 -> 1.6866789e+08 | G13: =G14-G15 -> 1.7244486e+08 | H13: =H14-H15 -> 1.7377605e+08 | I13: =I14-I15 -> 1.798867e+08 | J13: =J14-J15 -> 1.8363099e+08 | ... AB13: =AB14-AB15 -> 214255208
A14: 4.1 | B14: Gross Loan Portfolio | C14: 1.6502172e+08 | D14: 1.675457e+08 | E14: 1.7739927e+08 | F14: 1.8002826e+08 | G14: 1.8380523e+08 | H14: 1.8513642e+08 | I14: 1.9124707e+08 | J14: 1.9499137e+08 | K14: 1.9825321e+08 | L14: 1.9975312e+08 | M14: 2.0346196e+08 | N14: 1.9619861e+08 | O14: 195282233 | P14: 2.0625708e+08 | Q14: 2.0787622e+08 | R14: 2.0565114e+08 | S14: 2.0453638e+08 | T14: 2.1349291e+08 | U14: 2.1165461e+08 | V14: 2.1588888e+08 | W14: 2.1856417e+08 | X14: 2.2381692e+08 | Y14: 2.3303019e+08 | Z14: 2.3220397e+08 | AA14: 2.3846894e+08 | AB14: 229615583
A15: 4.2 | B15: Allowance for Loan Loss | C15: 11360375 | D15: 11360375 | E15: 11360375 | F15: 11360375 | G15: 11360375 | H15: 11360375 | I15: 11360375 | J15: 11360375 | K15: 11360375 | L15: 11360375 | M15: 11360375 | N15: 12360375 | O15: 13360375 | P15: 1113365 | Q15: 2226730 | R15: 3340093.7 | S15: 4453458 | T15: 5566823 | U15: 6680190 | V15: 7793555 | W15: 8906920 | X15: 13360375 | Y15: 13360375 | Z15: 13360375 | AA15: 13360375 | AB15: 15360375
A16: 5 | B16: Accounts Receivables | C16: 0 | D16: 0 | E16: =E17+E18+E19 -> 0 | F16: =F17+F18+F19 -> 0 | G16: =G17+G18+G19 -> 0 | H16: =H17+H18+H19 -> 0 | I16: =I17+I18+I19 -> 0 | J16: =J17+J18+J19 -> 0 | K16: =K17+K18+K19 -> 0 | L16: =L17+L18+L19 -> 0 | ... W16: =W17+W18+W19 -> 0 | X16: 0 | Y16: 0 | Z16: 0 | AA16: 0 | AB16: =AB17+AB18+AB19 -> 0
A17: 5.1 | B17: Tax Recoverable | C17: 0 | D17: 0 | E17: 0 | F17: 0 | G17: 0 | H17: 0 | I17: 0 | J17: 0 | K17: 0 | L17: 0 | M17: 0 | N17: 0 | O17: 0 | P17: 0 | Q17: 0 | R17: 0 | S17: 0 | T17: 0 | U17: 0 | V17: 0 | W17: 0 | X17: 0 | Y17: 0 | Z17: 0 | AA17: 0 | AB17: 0
A18: 5.2 | B18: Deferred Tax Assets | C18: 0 | D18: 0 | E18: 0 | F18: 0 | G18: 0 | H18: 0 | I18: 0 | J18: 0 | K18: 0 | L18: 0 | M18: 0 | N18: 0 | O18: 0 | P18: 0 | Q18: 0 | R18: 0 | S18: 0 | T18: 0 | U18: 0 | V18: 0 | W18: 0 | X18: 0 | Y18: 0 | Z18: 0 | AA18: 0 | AB18: 0
A19: 5.3 | B19: Retirement Benefit Assets | C19: 0 | D19: 0 | E19: 0 | F19: 0 | G19: 0 | H19: 0 | I19: 0 | J19: 0 | K19: 0 | L19: 0 | M19: 0 | N19: 0 | O19: 0 | P19: 0 | Q19: 0 | R19: 0 | S19: 0 | T19: 0 | U19: 0 | V19: 0 | W19: 0 | X19: 0 | Y19: 0 | Z19: 0 | AA19: 0 | AB19: 0
A20: 6 | B20: Property & Equipment & Other assets | C20: =SUM(C21:C25) -> 4383284.6 | D20: =SUM(D21:D25) -> 4388784.6 | E20: =SUM(E21:E25) -> 4432424.6 | F20: =SUM(F21:F25) -> 7706340.9 | G20: =SUM(G21:G25) -> 4443024.6 | H20: =SUM(H21:H25) -> 4466264.6 | I20: =SUM(I21:I25) -> 4477609.6 | J20: =SUM(J21:J25) -> 4488609.6 | ... AB20: =SUM(AB21:AB25) -> 6571511
A21: 6.1 | B21: Investment Properties | C21: 0 | D21: 0 | E21: 0 | F21: 0 | G21: 0 | H21: 0 | I21: 0 | J21: 0 | K21: 0 | L21: 0 | M21: 0 | N21: 0 | P21: 0 | Q21: 0 | R21: 0 | S21: 0 | T21: 0 | U21: 0 | V21: 0 | W21: 0 | X21: 0 | Y21: 0 | Z21: 0 | AA21: 0
A22: 6.2 | B22: Property & Equipment | C22: 2606642 | D22: 2606642 | E22: 2637642 | F22: 2637642 | G22: 2637642 | H22: 2637642 | I22: 2637642 | J22: 2637642 | K22: 3706622 | L22: 3723122 | M22: 4538122 | N22: 5724072 | O22: 5724072 | P22: 5740072 | Q22: 5752272 | R22: 5946760 | S22: 5946760 | T22: 5946760 | U22: 5946760 | V22: 5981760 | W22: 5981760 | X22: 6004760 | Y22: 6004760 | Z22: 6004760 | AA22: 6004760 | AB22: 5915639
A23: 6.3 | B23: Prepaid Lease rentals | C23: 0 | D23: 0 | E23: 0 | F23: 0 | G23: 0 | H23: 0 | I23: 0 | J23: 0 | K23: 0 | L23: 0 | M23: 0 | N23: 0 | P23: 0 | Q23: 0 | R23: 0 | S23: 0 | T23: 0 | U23: 0 | V23: 0 | W23: 0 | X23: 0 | Y23: 0 | Z23: 0 | AA23: 0
A24: 6.4 | B24: Intangible Assets | C24: 1475565 | D24: 1475565 | E24: 1475565 | F24: 1475565 | G24: 1475565 | H24: 1475565 | I24: 1475565 | J24: 1475565 | K24: 1475565 | L24: 1475565 | M24: 1475565 | N24: 983759 | O24: 983759 | P24: 983759 | Q24: 983759 | R24: 983759 | S24: 983759 | T24: 983759 | U24: 983759 | V24: 983759 | W24: 983759 | X24: 983759 | Y24: 983759 | Z24: 983759 | AA24: 983759 | AB24: 655872
A25: 6.5 | B25: Other Assets | C25: 301077.6 | D25: 306577.6 | E25: 319217.6 | F25: 3593133.9 | G25: 329817.6 | H25: 353057.6 | I25: 364402.6 | J25: 375402.6 | K25: 381352.6 | L25: 390352.6 | M25: 395352.6 | N25: 415252.6 | P25: 415107.6 | Q25: 420607.6 | R25: 434947.6 | S25: 442387.6 | T25: 447687.6 | U25: 454957.6 | V25: 461682.6 | W25: 0 | X25: 0 | Y25: 0 | Z25: 0 | AA25: 0
B26: Total Assets | C26: =C4+C7+C8+C13+C16+C20 -> 1.8814881e+08 | D26: =D4+D7+D8+D13+D16+D20 -> 1.8914019e+08 | E26: =E4+E7+E8+E13+E16+E20 -> 1.9173933e+08 | F26: =F4+F7+F8+F13+F16+F20 -> 1.9362784e+08 | G26: =G4+G7+G8+G13+G16+G20 -> 1.9131974e+08 | H26: =H4+H7+H8+H13+H16+H20 -> 1.9477715e+08 | I26: =I4+I7+I8+I13+I16+I20 -> 1.9877726e+08 | J26: =J4+J7+J8+J13+J16+J20 -> 2.0464917e+08 | ... AB26: =AB4+AB7+AB8+AB13+AB16+AB20 -> 260823377
A27: 7 | B27: Savings Deposits - Withdrawable deposits - FOSA) | C27: 11874266 | D27: 11948734 | E27: 15024171 | F27: 11683164 | G27: 13769371 | H27: 14352218 | I27: 16708107 | J27: 15380446 | K27: 14633753 | L27: 13847085 | M27: 13516146 | N27: 19885235 | O27: =18832630+1575739 -> 20408369 | P27: 17794372 | Q27: 14324250 | R27: 14569255 | S27: 18211961 | T27: 18804672 | U27: 18642493 | V27: 17224412 | W27: 18478903 | X27: 19486732 | Y27: 18947653 | Z27: 18161734 | AA27: 18038818 | AB27: 25328764
A28: 8 | B28: Short Term Deposits (e.g Fixed deposits, special savings) | C28: 106000 | D28: 106000 | E28: 0 | F28: 0 | G28: 0 | H28: 0 | I28: 0 | J28: 0 | K28: 0 | L28: 86000 | M28: 86000 | N28: 86000 | O28: 86000 | P28: 146000 | Q28: 146000 | R28: 146000 | S28: 246000 | T28: 1046000 | U28: 1446000 | V28: 1486000 | W28: 2231000 | X28: 2145000 | Y28: 2505000 | Z28: 2505000 | AA28: 1660000 | AB28: 4108688
A29: 9 | B29: Non withdrawable deposits (BOSA member deposits) | C29: 1.1729068e+08 | D29: 1.1828458e+08 | E29: 1.193335e+08 | F29: 1.0966947e+08 | G29: 1.2123889e+08 | H29: 1.2290023e+08 | I29: 1.2463661e+08 | J29: 1.2238321e+08 | K29: 1.2376666e+08 | L29: 1.253182e+08 | M29: 1.2721559e+08 | N29: 116861714 | O29: =115552140+173043 -> 115725183 | P29: 1.281291e+08 | Q29: 1.2956583e+08 | R29: 1.2967046e+08 | S29: 1.3086141e+08 | T29: 1.32151e+08 | U29: 1.3320791e+08 | V29: 1.3416383e+08 | W29: 1.3637663e+08 | X29: 1.3854401e+08 | Y29: 1.3960013e+08 | Z29: 1.4058134e+08 | AA29: 1.4187395e+08 | AB29: 130510902
B30: Total Deposit liabilities | C30: =SUM(C27:C29) -> 1.2927094e+08 | D30: =SUM(D27:D29) -> 1.3033932e+08 | E30: =SUM(E27:E29) -> 1.3435767e+08 | F30: =SUM(F27:F29) -> 1.2135263e+08 | G30: =SUM(G27:G29) -> 1.3500826e+08 | H30: =SUM(H27:H29) -> 1.3725244e+08 | I30: =SUM(I27:I29) -> 1.4134472e+08 | J30: =SUM(J27:J29) -> 1.3776365e+08 | ... AB30: =SUM(AB27:AB29) -> 159948354
A31: 10 | B31: Accounts Payable & Other Liabilities | C31: =SUM(C32:C37) -> 4704745.4 | D31: =SUM(D32:D37) -> 12020264 | E31: =SUM(E32:E37) -> 8561775.8 | F31: =SUM(F32:F37) -> 23177479 | G31: =SUM(G32:G37) -> 3949000.1 | H31: =SUM(H32:H37) -> 2912831.7 | I31: =SUM(I32:I37) -> 204863.44 | J31: =SUM(J32:J37) -> 17425225 | ... AB31: =SUM(AB32:AB37) -> 33371025
A32: 10.1 | B32: Tax Payable | C32: 0 | D32: 515208 | E32: 649250.87 | F32: 594764.23 | G32: 781204.79 | H32: 643094.19 | I32: 0 | J32: 0 | K32: 138318.27 | L32: 141875.8 | M32: 131392.6 | N32: 177801.2 | P32: 1451335.2 | Q32: 1408708.2 | R32: 1441109.6 | S32: 938132.93 | T32: 831511.13 | U32: 140564.53 | V32: 115641.89 | W32: 154491.09 | X32: 117765.89 | Y32: 98586.29 | Z32: 148393.89 | AA32: 138761.69
A33: 10.2 | B33: Dividends Payable | C33: 0 | D33: 2497750 | E33: 2497750 | F33: 2497750 | G33: 114887.95 | H33: 114887.95 | I33: 0 | J33: 0 | K33: 0 | L33: 0 | M33: 0 | N33: 0 | P33: 3252077 | Q33: 3252077 | R33: 3252077 | S33: 1861696.7 | T33: 1715092.7 | U33: 1715092.7 | V33: 1715092.7 | W33: 0 | X33: 0 | Y33: 0 | Z33: 0 | AA33: 0
A34: 10.3 | B34: Deferred Tax Liability | C34: 0 | D34: 0 | E34: 0 | F34: 0 | G34: 0 | H34: 0 | I34: 0 | J34: 0 | K34: 0 | L34: 0 | M34: 0 | N34: 0 | P34: 0 | Q34: 0 | R34: 0 | S34: 0 | T34: 0 | U34: 0 | V34: 0 | W34: 0 | X34: 0 | Y34: 0 | Z34: 0 | AA34: 0
A35: 10.4 | B35: Retirement Benefits Liability | C35: 0 | D35: 0 | E35: 0 | F35: 0 | G35: 0 | H35: 0 | I35: 0 | J35: 0 | K35: 0 | L35: 0 | M35: 0 | N35: 0 | P35: 0 | Q35: 0 | R35: 0 | S35: 0 | T35: 0 | U35: 0 | V35: 0 | W35: 0 | X35: 0 | Y35: 0 | Z35: 0 | AA35: 0
A36: 10.5 | B36: Other Liabilities | C36: 3372373.4 | D36: 7923360.1 | E36: 4330829 | F36: 19759809 | G36: 2727752.3 | H36: 1829694.5 | I36: 204863.44 | J36: 9425224.6 | K36: 6971776.5 | L36: 5626928.1 | M36: 6702890.3 | N36: 1996243.6 | O36: 21727762 | P36: 16646041 | Q36: 19239894 | R36: 12659477 | S36: 2412304.4 | T36: 10867527 | U36: 10103176 | V36: 14231912 | W36: 19200311 | X36: 18139857 | Y36: 18004291 | Z36: 19903130 | AA36: 14689349 | AB36: 24566608
A37: 10.6 | B37: External Borrowings | C37: 1332372 | D37: 1083946 | E37: 1083946 | F37: 325155 | G37: 325155 | H37: 325155 | I37: 0 | J37: 8000000 | K37: 8000000 | L37: 7244747 | M37: 6906342 | N37: 6220650 | O37: 6220650 | P37: 6220650 | Q37: 5871930 | R37: 5520151 | S37: 5158370 | T37: 5158370 | U37: 4103346 | V37: 7230084 | W37: 5687393.3 | X37: 4520726.7 | Y37: 2588087 | Z37: 2588087 | AA37: 8804417 | AB37: 8804417
B38: Total Liabilities | C38: =C30+C31 -> 1.3397569e+08 | D38: =D30+D31 -> 1.4235958e+08 | E38: =E30+E31 -> 1.4291944e+08 | F38: =F30+F31 -> 1.4453011e+08 | G38: =G30+G31 -> 1.3895726e+08 | H38: =H30+H31 -> 1.4016528e+08 | I38: =I30+I31 -> 1.4154958e+08 | J38: =J30+J31 -> 1.5518888e+08 | ... AB38: =AB30+AB31 -> 193319379
A39: 11 | B39: Share Capital (Members share capital per Bylaws) | C39: 28889545 | D39: 29115769 | E39: 29367424 | F39: 29618334 | G39: 29862795 | H39: 30038038 | I39: 30197604 | J39: 30382178 | K39: 30507338 | L39: 30625984 | M39: 30720266 | N39: 30853772 | O39: 30863970 | P39: 30916709 | Q39: 30979717 | R39: 31092275 | S39: 31212903 | T39: 31097439 | U39: 31212941 | V39: 31240515 | W39: 31348376 | X39: 31498467 | Y39: 31550671 | Z39: 31588115 | AA39: 31661545 | AB39: 31724224
A40: 12 | B40: Capital Grants | C40: 0 | D40: 0 | E40: 0 | F40: 0 | G40: 0 | H40: 0 | I40: 0 | J40: 0 | K40: 0 | L40: 0 | M40: 0 | N40: 0 | P40: 0 | Q40: 0 | R40: 0 | S40: 0 | T40: 0 | U40: 0 | V40: 0 | W40: 0 | X40: 0 | Y40: 0 | Z40: 0 | AA40: 0
...

Sheet Income Stat.
A1: KIPSIGIS EDIS SACCO SOCIETY
A2: STATEMENT OF COMPREHENSIVE INCOME
A3: FINANCIAL YEAR 2020 | C3: Jan | D3: Feb | E3: Mar | F3: Apr | G3: May | H3: Jun | I3: Jul | J3: Aug | K3: Sep | L3: Oct | M3: Nov | N3: Dec | O3: Aud-21 | P3: 44583 | Q3: 44614 | R3: 44642 | S3: 44673 | T3: 44703 | U3: 44734 | V3: 44764 | W3: 44795 | X3: 44805 | Y3: 44835 | Z3: 44866 | AA3: 44896 | AB3: Audited 2022
A4: 1 | B4: Financial Income | C4: 26153074 | D4: 5625994.1 | E4: 8800240.3 | F4: 10359912 | G4: 14479136 | H4: 17794512 | I4: 21321916 | J4: 25725136 | K4: 28671203 | L4: 32055995 | M4: 34998235 | N4: 39607909 | O4: =O5+O8 -> 39856481 | P4: =P5+P8 -> 769720.99 | Q4: =Q5+Q8 -> 1406802.9 | R4: =R5+R8 -> 2724356.7 | S4: =S5+S8 -> 6005760.5 | T4: =T5+T8 -> 8293536.2 | U4: =U5+U8 -> 9624665.7 | V4: =V5+V8 -> 22732298 | W4: =W5+W8 -> 20780613 | X4: 32194253 | Y4: 35786689 | Z4: 37015193 | AA4: 40196197 | AB4: =AB5+AB8 -> 42267504
A5: 2 | B5: Financial Income from Loans Portfolio | C5: 21163468 | D5: 4783810.3 | E5: 7371541.8 | F5: 8633208.3 | G5: 11535163 | H5: 14226272 | I5: 16984766 | J5: 20729232 | K5: 23136893 | L5: 25748675 | M5: 28215679 | N5: 32093553 | O5: =O6+O7 -> 38680363 | P5: =P6+P7 -> 271961.89 | Q5: =Q6+Q7 -> 560586.83 | R5: =R6+R7 -> 1037674.6 | S5: =S6+S7 -> 3020931.4 | T5: =T6+T7 -> 3553976.6 | U5: =U6+U7 -> 4072571.1 | V5: 17657831 | W5: 20780613 | X5: 25549465 | Y5: 28554693 | Z5: 29581357 | AA5: 32283641 | AB5: 31904066
A6: 2.1 | B6: Interest on Loan Portfolio | C6: 18951478 | D6: 4030548.9 | E6: 6130837.7 | F6: 7210830.7 | G6: 9661087.6 | H6: 12033900 | I6: 14355932 | J6: 17611502 | K6: 19679355 | L6: 21980809 | M6: 24118146 | N6: 27728406 | O6: 30137296 | P6: 247107.89 | Q6: 496047.53 | R6: 900582.77 | S6: 2839488.4 | T6: 3097488.6 | U6: 3481563.6 | V6: 15373875 | W6: 18087767 | X6: 22203283 | Y6: 24697585 | Z6: 25627818 | AA6: 27888354
A7: 2.2 | B7: Fees & Commission on Loan Portfolio | C7: 2211989.5 | D7: 753261.4 | E7: 1240704.1 | F7: 1422377.6 | G7: 1874075.3 | H7: 2192372 | I7: 2628834.2 | J7: 3117729.5 | K7: 3457538.2 | L7: 3767865.8 | M7: 4097533.2 | N7: 4365147.3 | O7: 8543067 | P7: 24854 | Q7: 64539.3 | R7: 137091.8 | S7: 181443 | T7: 456488 | U7: 591007.5 | V7: 2283955.5 | W7: 2692846.1 | X7: 3346181.6 | Y7: 3857108.6 | Z7: 3953539.4 | AA7: 4395287.5
A8: 3 | B8: Financial Income from Investments in: | C8: 0 | D8: 0 | E8: 0 | F8: 0 | G8: 0 | H8: 0 | I8: 0 | J8: 0 | K8: 0 | L8: 0 | M8: 0 | N8: 0 | O8: =O9+O10+O11+O12 -> 1176118 | P8: =P9+P10+P11+P12 -> 497759.1 | Q8: =Q9+Q10+Q11+Q12 -> 846216.1 | R8: =R9+R10+R11+R12 -> 1686682.1 | S8: =S9+S10+S11+S12 -> 2984829.1 | T8: =T9+T10+T11+T12 -> 4739559.6 | U8: =U9+U10+U11+U12 -> 5552094.6 | V8: =V9+V10+V11+V12 -> 5074467.3 | W8: =W9+W10+W11+W12 -> 0 | X8: 0 | Y8: 0 | Z8: 0 | AA8: 0 | AB8: =AB9+AB10+AB11+AB12 -> 10363438
A9: 3.1 | B9: Government Securities | C9: 0 | D9: 0 | E9: 0 | F9: 0 | G9: 0 | H9: 0 | I9: 0 | J9: 0 | K9: 0 | L9: 0 | M9: 0 | N9: 0 | P9: 0 | Q9: 0 | R9: 0 | S9: 0 | T9: 0 | U9: 0 | V9: 0 | W9: 0 | X9: 0 | Y9: 0 | Z9: 0 | AA9: 0
A10: 3.2 | B10: Deposit with Banks and Other Financial Inst. | C10: 0 | D10: 0 | E10: 0 | F10: 0 | G10: 0 | H10: 0 | I10: 0 | J10: 0 | K10: 0 | L10: 0 | M10: 0 | N10: 0 | O10: 966917 | P10: 0 | Q10: 0 | R10: 0 | S10: 0 | T10: 0 | U10: 0 | V10: 0 | W10: 0 | X10: 0 | Y10: 0 | Z10: 0 | AA10: 0 | AB10: 1025964
A11: 3.3 | B11: Other Investments - dividend & Interest incomes from investments | C11: 0 | D11: 0 | E11: 0 | F11: 0 | G11: 0 | H11: 0 | I11: 0 | J11: 0 | K11: 0 | L11: 0 | M11: 0 | N11: 0 | O11: 209201 | P11: 0 | Q11: 0 | R11: 0 | S11: 0 | T11: 0 | U11: 0 | V11: 0 | W11: 0 | X11: 0 | Y11: 0 | Z11: 0 | AA11: 0
A12: 3.4 | B12: Other Operating Income- Salary processing fees, transaction fees, membership fees | C12: 4989606.5 | D12: 842183.79 | E12: 1428698.5 | F12: 1726704 | G12: 2943973.6 | H12: 3568240.3 | I12: 4337149.3 | J12: 4995904.3 | K12: 5534310 | L12: 6307319.5 | M12: 6782556.4 | N12: 7514355.2 | P12: 497759.1 | Q12: 846216.1 | R12: 1686682.1 | S12: 2984829.1 | T12: 4739559.6 | U12: 5552094.6 | V12: 5074467.3 | W12: 0 | X12: 6644788.3 | Y12: 7231996 | Z12: 7433836 | AA12: 7912556 | AB12: 9337474
A13: 4 | B13: Financial Expense | C13: 2374091 | D13: 43717 | E13: 52527 | F13: 87485 | G13: 92195 | H13: 326356.3 | I13: 442786.96 | J13: 454220.96 | K13: 462714.96 | L13: 567218.96 | M13: 659453.96 | N13: 1822665 | O13: =O14+O15+O16+O17+O18+O19 -> 8688629 | P13: =P14+P15+P16+P17+P18+P19 -> 0 | Q13: =Q14+Q15+Q16+Q17+Q18+Q19 -> 0 | R13: =R14+R15+R16+R17+R18+R19 -> 0 | S13: =S14+S15+S16+S17+S18+S19 -> 0 | T13: =T14+T15+T16+T17+T18+T19 -> 0 | U13: =U14+U15+U16+U17+U18+U19 -> 1178990.6 | V13: =V14+V15+V16+V17+V18+V19 -> 1009364.6 | W13: =W14+W15+W16+W17+W18+W19 -> 1123405.4 | X13: 1163602.4 | Y13: 1266597.2 | Z13: 1271451.2 | AA13: 1640003.2 | AB13: =AB14+AB15+AB16+AB17+AB18+AB19 -> 10689887
A14: 4.2 | B14: Interest Expense on Deposits | C14: 8020 | D14: 0 | E14: 3710 | F14: 3710 | G14: 3710 | H14: 3710 | I14: 3710 | J14: 3710 | K14: 3710 | L14: 8515 | M14: 8515 | N14: 8515 | O14: 7859162 | P14: 0 | Q14: 0 | R14: 0 | S14: 0 | T14: 0 | U14: 0 | V14: 6370 | W14: 26370 | X14: 35892.5 | Y14: 35892.5 | Z14: 35892.5 | AA14: 78142.5 | AB14: 9041252.1
A15: 4.3 | B15: Cost of External Borrowings | C15: 409590 | D15: 16157 | E15: 16157 | F15: 51115 | G15: 51115 | H15: 275124.3 | I15: 360288.96 | J15: 360288.96 | K15: 360288.96 | L15: 451701.96 | M15: 536629.96 | N15: 697603.96 | O15: 697604 | P15: 0 | Q15: 0 | R15: 0 | S15: 0 | T15: 0 | U15: 1178990.6 | V15: 870400.55 | W15: 956353.39 | X15: 1042716.9 | Y15: 1135875.7 | Z15: 1135875.7 | AA15: 1458371.7 | AB15: 1458372
A16: 4.4 | B16: Dividend Expenses (on member shares) | C16: 0 | D16: 0 | E16: 0 | F16: 0 | G16: 0 | H16: 0 | I16: 0 | J16: 0 | K16: 0 | L16: 0 | M16: 0 | N16: 0 | P16: 0 | Q16: 0 | R16: 0 | S16: 0 | T16: 0 | U16: 0 | V16: 0 | W16: 0 | X16: 0 | Y16: 0 | Z16: 0 | AA16: 0
A17: 4.5 | B17: Other Financial Expense | C17: 1850000 | D17: 0 | E17: 0 | F17: 0 | G17: 0 | H17: 0 | I17: 0 | J17: 0 | K17: 0 | L17: 0 | M17: 0 | N17: 1000000 | P17: 0 | Q17: 0 | R17: 0 | S17: 0 | T17: 0 | U17: 0 | V17: 0 | W17: 0 | X17: 0 | Y17: 0 | Z17: 0 | AA17: 0
A18: 4.6 | B18: Fees & Commission Expense | C18: 106481 | D18: 27560 | E18: 32660 | F18: 32660 | G18: 37370 | H18: 47522 | I18: 78788 | J18: 90222 | K18: 98716 | L18: 107002 | M18: 114309 | N18: 116546 | P18: 0 | Q18: 0 | R18: 0 | S18: 0 | T18: 0 | U18: 0 | V18: 132594 | W18: 140682 | X18: 84993 | Y18: 94829 | Z18: 99683 | AA18: 103489
A19: 4.7 | B19: Other Expense | C19: 0 | D19: 0 | E19: 0 | F19: 0 | G19: 0 | H19: 0 | I19: 0 | J19: 0 | K19: 0 | L19: 0 | M19: 0 | N19: 0 | O19: 131863 | P19: 0 | Q19: 0 | R19: 0 | S19: 0 | T19: 0 | U19: 0 | V19: 0 | W19: 0 | X19: 0 | Y19: 0 | Z19: 0 | AA19: 0 | AB19: 190263
A20: 5 | B20: Net Financial Income/(Loss) | C20: 23778983 | D20: 5582277.1 | E20: 8747713.3 | F20: 10272427 | G20: 14386942 | H20: 17468156 | I20: 20879129 | J20: 25270915 | K20: 28208488 | L20: 31488776 | M20: 34338781 | N20: 37785244 | O20: =O4-O13 -> 31167852 | P20: =P4-P13 -> 769720.99 | Q20: =Q4-Q13 -> 1406802.9 | R20: =R4-R13 -> 2724356.7 | S20: =S4-S13 -> 6005760.5 | T20: =T4-T13 -> 8293536.2 | U20: =U4-U13 -> 8445675.1 | V20: =V4-V13 -> 21722934 | W20: =W4-W13 -> 19657207 | X20: 31030651 | Y20: 34520092 | Z20: 35743742 | AA20: 38556194 | AB20: =AB4-AB13 -> 31577617
A21: 6 | B21: Allowance for Loan Loss | C21: 0 | D21: 0 | E21: 0 | F21: 0 | G21: 0 | H21: 0 | I21: 0 | J21: 11360375 | K21: 11360375 | L21: 11360375 | M21: 11360375 | N21: 12360375 | O21: =O22-O23 -> 2000000 | P21: =P22-P23 -> 0 | Q21: =Q22-Q23 -> 0 | R21: =R22-R23 -> 0 | S21: =S22-S23 -> 0 | T21: =T22-T23 -> 0 | U21: =U22-U23 -> 0 | V21: =V22-V23 -> 7793555 | W21: =W22-W23 -> 8906920 | X21: 13360375 | Y21: 13360375 | Z21: 13360375 | AA21: 13360375 | AB21: =AB22-AB23 -> 2000000
A22: 6.1 | B22: Provision for Loan Losses | C22: 0 | D22: 0 | E22: 0 | F22: 0 | G22: 0 | H22: 0 | I22: 0 | J22: 11360375 | K22: 11360375 | L22: 11360375 | M22: 11360375 | N22: 12360375 | O22: 2000000 | P22: 0 | Q22: 0 | R22: 0 | S22: 0 | T22: 0 | U22: 0 | V22: 7793555 | W22: 8906920 | X22: 13360375 | Y22: 13360375 | Z22: 13360375 | AA22: 13360375 | AB22: 2000000
A23: 6.2 | B23: Value of Loans Recovered | C23: 0 | D23: 0 | E23: 0 | F23: 0 | G23: 0 | H23: 0 | I23: 0 | J23: 0 | K23: 0 | L23: 0 | M23: 0 | N23: 0 | O23: 0 | P23: 0 | Q23: 0 | R23: 0 | S23: 0 | T23: 0 | U23: 0 | V23: 0 | W23: 0 | X23: 0 | Y23: 0 | Z23: 0 | AA23: 0
A24: 7 | B24: Operating Expenses | C24: 11734413 | D24: 1934615.3 | E24: 3312423.3 | F24: 4810208.3 | G24: 5904436.3 | H24: 6911490.3 | I24: 7866234.3 | J24: 8849597.3 | K24: 9699050.3 | L24: 11209852 | M24: 12120243 | N24: 13868206 | O24: =O25+O26+O27+O28+O29 -> 13978406 | P24: =P25+P26+P27+P28+P29 -> 733848 | Q24: =Q25+Q26+Q27+Q28+Q29 -> 1257218 | R24: =R25+R26+R27+R28+R29 -> 2457689 | S24: =S25+S26+S27+S28+S29 -> 3248054 | T24: =T25+T26+T27+T28+T29 -> 5245635.2 | U24: =U25+U26+U27+U28+U29 -> 4750821 | V24: =V25+V26+V27+V28+V29 -> 9209610.4 | W24: =W25+W26+W27+W28+W29 -> 10564673 | X24: 11863467 | Y24: 12937474 | Z24: 13758014 | AA24: 14990767 | AB24: =AB25+AB26+AB27+AB28+AB29 -> 16024855
A25: 7.1 | B25: Personnel Expenses | C25: 5610045 | D25: 803936 | E25: 1242399 | F25: 1669222 | G25: 2114381 | H25: 2565860 | I25: 3051359 | J25: 3521178 | K25: 3998196 | L25: 4559278 | M25: 5149794 | N25: 5713536 | O25: 5060751 | P25: 227526 | Q25: 497166 | R25: 965843 | S25: 1260014 | T25: 1497308 | U25: 1894769 | V25: 4155402 | W25: 4733772 | X25: 5429623 | Y25: 5931915 | Z25: 6462655 | AA25: 7139117 | AB25: 6647897
A26: 7.2 | B26: Governance Expenses | C26: 1045210 | D26: 230680 | E26: 519390 | F26: 1078645 | G26: 1269415 | H26: 1524305 | I26: 1635575 | J26: 1738245 | K26: 1770905 | L26: 2297795 | M26: 2359060 | N26: 2447420 | O26: 2447420 | P26: 240200 | Q26: 383740 | R26: 497030 | S26: 601580 | T26: 728796 | U26: 887090 | V26: 1549731 | W26: 1633671 | X26: 1773666 | Y26: 2065481 | Z26: 2089446 | AA26: 2168666 | AB26: 2168666
A27: 7.3 | B27: Marketing Expenses | C27: 193410 | D27: 40000 | E27: 50500 | F27: 58200 | G27: 78600 | H27: 201300 | I27: 249990 | J27: 278980 | K27: 292980 | L27: 297780 | M27: 307980 | N27: 315930 | O27: 315930 | P27: 24580 | Q27: 66320 | R27: 153405 | S27: 337805 | T27: 434905 | U27: 502505 | V27: 95290 | W27: 97720 | X27: 101370 | Y27: 120970 | Z27: 217970 | AA27: 346990 | AB27: 346990
A28: 7.4 | B28: Depreciation and Amortization Charges | C28: 1017647 | D28: 0 | E28: 0 | F28: 0 | G28: 0 | H28: 0 | I28: 0 | J28: 0 | K28: 0 | L28: 0 | M28: 0 | N28: 820356 | O28: 820356 | P28: 0 | Q28: 0 | R28: 0 | S28: 0 | T28: 0 | U28: 0 | V28: 0 | W28: 0 | X28: 0 | Y28: 0 | Z28: 0 | AA28: 0 | AB28: 976088
A29: 7.5 | B29: Administrative Expenses | C29: 3868101.3 | D29: 859999.27 | E29: 1500134.3 | F29: 2004141.3 | G29: 2442040.3 | H29: 2620025.3 | I29: 2929310.3 | J29: 3311194.3 | K29: 3636969.3 | L29: 4054999.3 | M29: 4303409.3 | N29: 4570964.3 | O29: 5333949 | P29: 241542 | Q29: 309992 | R29: 841411 | S29: 1048655 | T29: 2584626.2 | U29: 1466457 | V29: 3409187.5 | W29: 4099510 | X29: 4558808 | Y29: 4819108 | Z29: 4987943 | AA29: 5335994 | AB29: 5885214
A30: 8 | B30: Net Operating Income | C30: 12044570 | D30: 3647661.8 | E30: 5435290 | F30: 5462219.1 | G30: 8482505.2 | H30: 10556666 | I30: 13012894 | J30: 5060942.9 | K30: 7149062.8 | L30: 8918548.3 | M30: 10858163 | N30: 11556662 | O30: =O20-O21-O24 -> 15189446 | P30: =P20-P21-P24 -> 35872.99 | Q30: =Q20-Q21-Q24 -> 149584.93 | R30: =R20-R21-R24 -> 266667.67 | S30: =S20-S21-S24 -> 2757706.5 | T30: =T20-T21-T24 -> 3047900.9 | U30: =U20-U21-U24 -> 3694854.1 | V30: =V20-V21-V24 -> 4719768.2 | W30: =W20-W21-W24 -> 185614.22 | X30: 5806808.7 | Y30: 8222243.2 | Z30: 8625353.2 | AA30: 10205052 | AB30: =AB20-AB21-AB24 -> 13552762
A31: 9 | B31: Net Non- Operating Income/ (Expense) | C31: 0 | D31: 0 | E31: 0 | F31: 0 | G31: 0 | H31: 0 | I31: 0 | J31: 0 | K31: 0 | L31: 0 | M31: 0 | N31: 0 | P31: 0 | Q31: 0 | R31: 0 | S31: 0 | T31: 0 | U31: 0 | V31: 0 | W31: 0 | X31: 0 | Y31: 0 | Z31: 0 | AA31: 0
A32: 9.1 | B32: Non- Operating Income | C32: 0 | D32: 0 | E32: 0 | F32: 0 | G32: 0 | H32: 0 | I32: 0 | J32: 0 | K32: 0 | L32: 0 | M32: 0 | N32: 0 | P32: 0 | Q32: 0 | R32: 0 | S32: 0 | T32: 0 | U32: 0 | V32: 0 | W32: 0 | X32: 0 | Y32: 0 | Z32: 0 | AA32: 0
A33: 9.2 | B33: Non- Operating Expense | C33: 0 | D33: 0 | E33: 0 | F33: 0 | G33: 0 | H33: 0 | I33: 0 | J33: 0 | K33: 0 | L33: 0 | M33: 0 | N33: 0 | P33: 0 | Q33: 0 | R33: 0 | S33: 0 | T33: 0 | U33: 0 | V33: 0 | W33: 0 | X33: 0 | Y33: 0 | Z33: 0 | AA33: 0
A34: 10 | B34: Net Income (Before Taxes and Donations) | C34: =C30-C31 -> 12044570 | D34: =D30-D31 -> 3647661.8 | E34: =E30-E31 -> 5435290 | F34: =F30-F31 -> 5462219.1 | G34: =G30-G31 -> 8482505.2 | H34: =H30-H31 -> 10556666 | I34: =I30-I31 -> 13012894 | J34: =J30-J31 -> 5060942.9 | ... W34: =W30-W31 -> 185614.22 | X34: 5806808.7 | Y34: 8222243.2 | Z34: 8625353.2 | AA34: 10205052 | AB34: =AB30-AB31 -> 13552762
A35: 11 | B35: Taxes (Incomes taxes & Other payable to KRA) | C35: 0 | D35: 0 | E35: 0 | F35: 0 | G35: 0 | H35: 0 | I35: 0 | J35: 0 | K35: 0 | L35: 0 | M35: 0 | N35: 0 | O35: 1304633 | P35: 0 | Q35: 0 | R35: 0 | S35: 0 | T35: 0 | U35: 0 | V35: 0 | W35: 0 | X35: 0 | Y35: 0 | Z35: 0 | AA35: 0 | AB35: 1498818
A36: 12 | B36: Net Income (After Taxes before Donations) | C36: =C34-C35 -> 12044570 | D36: =D34-D35 -> 3647661.8 | E36: =E34-E35 -> 5435290 | F36: =F34-F35 -> 5462219.1 | G36: =G34-G35 -> 8482505.2 | H36: =H34-H35 -> 10556666 | I36: =I34-I35 -> 13012894 | J36: =J34-J35 -> 5060942.9 | ... W36: =W34-W35 -> 185614.22 | X36: 5806808.7 | Y36: 8222243.2 | Z36: 8625353.2 | AA36: 10205052 | AB36: =AB34-AB35 -> 12053944
A37: 13 | B37: Donations | C37: 0 | D37: 0 | E37: 0 | F37: 0 | G37: 0 | H37: 0 | I37: 0 | J37: 0 | K37: 0 | L37: 0 | M37: 0 | N37: 0 | P37: 0 | Q37: 0 | R37: 0 | S37: 0 | T37: 0 | U37: 0 | V37: 0 | W37: 0 | X37: 0 | Y37: 0 | Z37: 0 | AA37: 0
A38: 14 | B38: Net Income/(After Taxes and Donations) | C38: =C36-C37 -> 12044570 | D38: 3647661.8 | E38: 5435290 | F38: 5462219.1 | G38: 8482505.2 | H38: 10556666 | I38: 13012894 | J38: 5060942.9 | K38: 7149062.8 | L38: 8918548.3 | M38: 10858163 | N38: 11556662 | O38: =O36-O37 -> 13884813 | P38: =P36-P37 -> 35872.99 | Q38: =Q36-Q37 -> 149584.93 | R38: =R36-R37 -> 266667.67 | S38: =S36-S37 -> 2757706.5 | T38: =T36-T37 -> 3047900.9 | U38: =U36-U37 -> 3694854.1 | V38: =V36-V37 -> 4719768.2 | W38: =W36-W37 -> 185614.22 | X38: 5806808.7 | Y38: 8222243.2 | Z38: 8625353.2 | AA38: 10205052 | AB38: =AB36-AB37 -> 12053944

Sheet Form 4
C6: FORM 4
E7: 44348
C9: CLASSIFICATION | D9: NO. OF A/Cs | E9: OUTSTANDING LOAN PORTFOLIO(Kshs) | F9: REQUIRED PROVISION | G9: REQUIRED PROVISION AMOUNT(Kshs)
C10: Performing | D10: 3003 | E10: 1.6118478e+08 | F10: 0.01 | G10: =F10*E10 -> 1611847.8
C11: Watch | D11: 134 | E11: 6166641.3 | F11: 0.05 | G11: =F11*E11 -> 308332.07
C12: Substandard | D12: 54 | E12: 2153434.2 | F12: 0.25 | G12: =F12*E12 -> 538358.56
C13: Doubtful | D13: 126 | E13: 4375007.4 | F13: 0.5 | G13: =F13*E13 -> 2187503.7
C14: Loss | D14: 352 | E14: 11256561 | F14: 1 | G14: =F14*E14 -> 11256561
C15: subtotal | D15: =SUM(D10:D14) -> 3669 | E15: =SUM(E10:E14) -> 1.8513642e+08 | F15: 1.81 | G15: =SUM(G10:G14) -> 15902603
C17: Performing | F17: 0.01 | G17: -
C18: Watch | F18: 0.05 | G18: -
C19: Substandard | F19: 0.25 | G19: -
C20: Doubtful | F20: 0.5 | G20: -
C21: Loss | F21: 1 | G21: -
C22: subtotal
D26: NPL | E26: =E14+E13+E12 -> 17785002
D27: PAR | E27: =E26/E15 -> 0.096064308
E32: 44734
C33: CLASSIFICATION | D33: NO. OF A/Cs | E33: OUTSTANDING LOAN PORTFOLIO(Kshs) | F33: REQUIRED PROVISION | G33: REQUIRED PROVISION AMOUNT(Kshs)
C34: Performing | D34: 3673 | E34: 2.04276e+08 | F34: 0.01 | G34: =F34*E34 -> 2042760
C35: Watch | D35: 36 | E35: 1173234.6 | F35: 0.05 | G35: =F35*E35 -> 58661.729
C36: Substandard | D36: 56 | E36: 1480271.2 | F36: 0.25 | G36: =F36*E36 -> 370067.81
C37: Doubtful | D37: 91 | E37: 4015481.1 | F37: 0.5 | G37: =F37*E37 -> 2007740.5
C38: Loss | D38: 193 | E38: 5217836.4 | F38: 1 | G38: =F38*E38 -> 5217836.4
C39: subtotal | D39: =SUM(D34:D38) -> 4049 | E39: =SUM(E34:E38) -> 2.1616282e+08 | G39: =SUM(G34:G38) -> 9697066.5
C41: Performing | F41: 0.01 | G41: -
C42: Watch | F42: 0.05 | G42: -
C43: Substandard | F43: 0.25 | G43: -
C44: Doubtful | F44: 0.5 | G44: -
C45: Loss | F45: 1 | G45: -
C46: subtotal
D50: NPL | E50: =E38+E37+E36 -> 10713589
D51: PAR | E51: =E50/E39 -> 0.049562588
E56: Aud-2022
C57: CLASSIFICATION | D57: NO. OF A/Cs | E57: OUTSTANDING LOAN PORTFOLIO(Kshs) | F57: REQUIRED PROVISION | G57: REQUIRED PROVISION AMOUNT(Kshs)
C58: Performing | E58: 2.1603797e+08 | F58: 0.01 | G58: =F58*E58 -> 2160379.7
C59: Watch | E59: 3484233 | F59: 0.05 | G59: =F59*E59 -> 174211.65
C60: Substandard | E60: 6443360.1 | F60: 0.25 | G60: =F60*E60 -> 1610840
C61: Doubtful | E61: 4713350.2 | F61: 0.5 | G61: =F61*E61 -> 2356675.1
C62: Loss | E62: 7790023.1 | F62: 1 | G62: =F62*E62 -> 7790023.1
...

Sheet Financials
A1: KIPSIGIS EDIS SACCO FINANCIALS
A3: Year/month | B3: Jan | C3: Feb | D3: Mar | E3: Apr | F3: May | G3: Jun | H3: Jul | I3: Aug | J3: Sep | K3: Oct | L3: Nov | M3: Dec | N3: Aud-21 | O3: 44583 | P3: 44614 | Q3: 44642 | R3: 44673 | S3: 44703 | T3: 44734 | U3: 44764 | V3: 44795 | W3: 44826 | X3: 44856 | Y3: 44887 | Z3: 44917 | AA3: Aud-22
A4: Membership
A5: Total Assets | B5: ='Balance Sheet'!C26 -> 1.8814881e+08 | C5: ='Balance Sheet'!D26 -> 1.8914019e+08 | D5: ='Balance Sheet'!E26 -> 1.9173933e+08 | E5: ='Balance Sheet'!F26 -> 1.9362784e+08 | F5: ='Balance Sheet'!G26 -> 1.9131974e+08 | G5: ='Balance Sheet'!H26 -> 1.9477715e+08 | H5: ='Balance Sheet'!I26 -> 1.9877726e+08 | I5: ='Balance Sheet'!J26 -> 2.0464917e+08 | ... AF5: ='Balance Sheet'!AG26 -> 0
A6: Total Deposits | B6: =B7+B8 -> 1.2916494e+08 | C6: =C7+C8 -> 1.3023332e+08 | D6: =D7+D8 -> 1.3435767e+08 | E6: =E7+E8 -> 1.2135263e+08 | F6: =F7+F8 -> 1.3500826e+08 | G6: =G7+G8 -> 1.3725244e+08 | H6: =H7+H8 -> 1.4134472e+08 | I6: =I7+I8 -> 1.3776365e+08 | ... AF6: =AF7+AF8 -> 0
A7: Deposits-Members(BOSA) | B7: ='Balance Sheet'!C29 -> 1.1729068e+08 | C7: ='Balance Sheet'!D29 -> 1.1828458e+08 | D7: ='Balance Sheet'!E29 -> 1.193335e+08 | E7: ='Balance Sheet'!F29 -> 1.0966947e+08 | F7: ='Balance Sheet'!G29 -> 1.2123889e+08 | G7: ='Balance Sheet'!H29 -> 1.2290023e+08 | H7: ='Balance Sheet'!I29 -> 1.2463661e+08 | I7: ='Balance Sheet'!J29 -> 1.2238321e+08 | ... AF7: ='Balance Sheet'!AG29 -> 0
A8: Deposits-Customers(FOSA) | B8: ='Balance Sheet'!C27 -> 11874266 | C8: ='Balance Sheet'!D27 -> 11948734 | D8: ='Balance Sheet'!E27 -> 15024171 | E8: ='Balance Sheet'!F27 -> 11683164 | F8: ='Balance Sheet'!G27 -> 13769371 | G8: ='Balance Sheet'!H27 -> 14352218 | H8: ='Balance Sheet'!I27 -> 16708107 | I8: ='Balance Sheet'!J27 -> 15380446 | ... AF8: ='Balance Sheet'!AG27 -> 0
A9: Deposits-Term | B9: ='Balance Sheet'!C28 -> 106000 | C9: ='Balance Sheet'!D28 -> 106000 | D9: ='Balance Sheet'!E28 -> 0 | E9: ='Balance Sheet'!F28 -> 0 | F9: ='Balance Sheet'!G28 -> 0 | G9: ='Balance Sheet'!H28 -> 0 | H9: ='Balance Sheet'!I28 -> 0 | I9: ='Balance Sheet'!J28 -> 0 | ... AF9: ='Balance Sheet'!AG28 -> 0
A10: External Borrowing | B10: ='Balance Sheet'!C37 -> 1332372 | C10: ='Balance Sheet'!D37 -> 1083946 | D10: ='Balance Sheet'!E37 -> 1083946 | E10: ='Balance Sheet'!F37 -> 325155 | F10: ='Balance Sheet'!G37 -> 325155 | G10: ='Balance Sheet'!H37 -> 325155 | H10: ='Balance Sheet'!I37 -> 0 | I10: ='Balance Sheet'!J37 -> 8000000 | ... V10: ='Balance Sheet'!W37 -> 5687393.3 | W10: ='Balance Sheet'!X38 -> 1.8295409e+08 | X10: ='Balance Sheet'!Y38 -> 1.8174374e+08 | Y10: ='Balance Sheet'!Z38 -> 1.8388768e+08 | Z10: ='Balance Sheet'!AA38 -> 1.852053e+08 | AA10: ='Balance Sheet'!AB37 -> 8804417 | AB10: ='Balance Sheet'!AC37 -> 0 | AC10: ='Balance Sheet'!AD37 -> 0 | AD10: ='Balance Sheet'!AE37 -> 0 | AE10: ='Balance Sheet'!AF37 -> 0 | AF10: ='Balance Sheet'!AG37 -> 0
A12: Share capital and Reserves
A13: Core Capital | B13: =B15-B28 -> 54173123 | C13: =C15-C28 -> 46780605 | D13: =D15-D28 -> 48819889 | E13: =E15-E28 -> 49097728 | F13: =F15-F28 -> 52362476 | G13: =G15-G28 -> 54611878 | H13: =H15-H28 -> 57227673 | I13: =I15-I28 -> 49460296 | ... AF13: =AF15-AF28 -> 0
A14: Institutional Capital | B14: =B13-B16 -> 25283578 | C14: =C13-C16 -> 17664837 | D14: =D13-D16 -> 19452465 | E14: =E13-E16 -> 19479394 | F14: =F13-F16 -> 22499680 | G14: =G13-G16 -> 24573840 | H14: =H13-H16 -> 27030070 | I14: =I13-I16 -> 19078118 | ... AF14: =AF13-AF16 -> 0
A15: Total Capital | B15: =B16+B17+B18+B19+B20+B21 -> 54173123 | C15: =C16+C17+C18+C19+C20+C21 -> 46780605 | D15: =D16+D17+D18+D19+D20+D21 -> 48819889 | E15: =E16+E17+E18+E19+E20+E21 -> 49097728 | F15: =F16+F17+F18+F19+F20+F21 -> 52362476 | G15: =G16+G17+G18+G19+G20+G21 -> 54611878 | H15: =H16+H17+H18+H19+H20+H21 -> 57227673 | I15: =I16+I17+I18+I19+I20+I21 -> 49460296 | ... M15: =M16+M17+M18+M19+M20+M21 -> 56427609 | N15: =N16+N17+N18+N20+N21 -> 55513881 | O15: =O16+O17+O18+O19+O20+O21 -> 55915730 | P15: =P16+P17+P18+P19+P20+P21 -> 55757083 | Q15: =Q16+Q17+Q18+Q19+Q20+Q21 -> 56157355 | R15: =R16+R17+R18+R19+R20+R21 -> 58186508 | S15: =S16+S17+S18+S19+S20+S21 -> 59270906 | T15: =T16+T17+T18+T19+T20+T21 -> 60489517 | U15: =U16+U17+U18+U19+U20+U21 -> 60610195 | V15: =V16+V17+V18+V19+V20+V21 -> 61355804 | ... AF15: =AF16+AF17+AF18+AF19+AF20+AF21 -> 0
A16: Members Share Capital | B16: ='Balance Sheet'!C39 -> 28889545 | C16: ='Balance Sheet'!D39 -> 29115769 | D16: ='Balance Sheet'!E39 -> 29367424 | E16: ='Balance Sheet'!F39 -> 29618334 | F16: ='Balance Sheet'!G39 -> 29862795 | G16: ='Balance Sheet'!H39 -> 30038038 | H16: ='Balance Sheet'!I39 -> 30197604 | I16: ='Balance Sheet'!J39 -> 30382178 | ... AF16: ='Balance Sheet'!AG39 -> 0
A17: Entrance Fees
A18: Retained Earnings | B18: ='Balance Sheet'!C41 -> 17601338 | C18: ='Balance Sheet'!D41 -> 9327413.9 | D18: ='Balance Sheet'!E41 -> 11115042 | E18: ='Balance Sheet'!F41 -> 11141971 | F18: ='Balance Sheet'!G41 -> 14162257 | G18: ='Balance Sheet'!H41 -> 16236418 | H18: ='Balance Sheet'!I41 -> 18692647 | I18: ='Balance Sheet'!J41 -> 10740695 | ... AF18: ='Balance Sheet'!AG41 -> 0
A19: Appropriation Account | B19: ='Balance Sheet'!C48 -> 0 | C19: ='Balance Sheet'!D48 -> 0 | D19: ='Balance Sheet'!E48 -> 0 | E19: ='Balance Sheet'!F48 -> 0 | F19: ='Balance Sheet'!G48 -> 0 | G19: ='Balance Sheet'!H48 -> 0 | H19: ='Balance Sheet'!I48 -> 0 | I19: ='Balance Sheet'!J48 -> 0 | ... AF19: ='Balance Sheet'!AG48 -> 0
A20: Statutory Reserves | B20: ='Balance Sheet'!C45 -> 5685968.2 | C20: ='Balance Sheet'!D45 -> 6341151.6 | D20: ='Balance Sheet'!E45 -> 6341151.6 | E20: ='Balance Sheet'!F45 -> 6341151.6 | F20: ='Balance Sheet'!G45 -> 6341151.6 | G20: ='Balance Sheet'!H45 -> 6341151.6 | H20: ='Balance Sheet'!I45 -> 6341151.6 | I20: ='Balance Sheet'!J45 -> 6341151.6 | ... AF20: ='Balance Sheet'!AG45 -> 0
A21: Capital Reserves | B21: ='Balance Sheet'!C46 -> 1996271.3 | C21: ='Balance Sheet'!D46 -> 1996271.3 | D21: ='Balance Sheet'!E46 -> 1996271.3 | E21: ='Balance Sheet'!F46 -> 1996271.3 | F21: ='Balance Sheet'!G46 -> 1996271.3 | G21: ='Balance Sheet'!H46 -> 1996271.3 | H21: ='Balance Sheet'!I46 -> 1996271.3 | I21: ='Balance Sheet'!J46 -> 1996271.3 | ... AF21: ='Balance Sheet'!AG46 -> 0
A22: Supplementary Capital & reserves
A23: Proposed Dividends
A24: Benevolent Fund
A25: Investments | B25: =B26+B27+B29 -> 6000 | C25: =C26+C27+C29 -> 6000 | D25: =D26+D27+D29 -> 6000 | E25: =E26+E27+E29 -> 6000 | F25: =F26+F27+F29 -> 6000 | G25: =G26+G27+G29 -> 6000 | H25: =H26+H27+H29 -> 6000 | I25: =I26+I27+I29 -> 6000 | ... AF25: =AF26+AF27+AF29 -> 0
A26: Govt bills | B26: ='Balance Sheet'!C8 -> 6000 | C26: ='Balance Sheet'!D8 -> 6000 | D26: ='Balance Sheet'!E8 -> 6000 | E26: ='Balance Sheet'!F8 -> 6000 | F26: ='Balance Sheet'!G8 -> 6000 | G26: ='Balance Sheet'!H8 -> 6000 | H26: ='Balance Sheet'!I8 -> 6000 | I26: ='Balance Sheet'!J8 -> 6000 | ... AF26: ='Balance Sheet'!AG8 -> 0
A27: Investments in naccos | B27: ='Balance Sheet'!C11 -> 0 | C27: ='Balance Sheet'!D11 -> 0 | D27: ='Balance Sheet'!E11 -> 0 | E27: ='Balance Sheet'!F11 -> 0 | F27: ='Balance Sheet'!G11 -> 0 | G27: ='Balance Sheet'!H11 -> 0 | H27: ='Balance Sheet'!I11 -> 0 | I27: ='Balance Sheet'!J11 -> 0 | ... AF27: ='Balance Sheet'!AG11 -> 0
A28: Equity Investments (at cost) | B28: ='Balance Sheet'!C9 -> 0 | C28: ='Balance Sheet'!D9 -> 0 | D28: ='Balance Sheet'!E9 -> 0 | E28: ='Balance Sheet'!F9 -> 0 | F28: ='Balance Sheet'!G9 -> 0 | G28: ='Balance Sheet'!H9 -> 0 | H28: ='Balance Sheet'!I9 -> 0 | I28: ='Balance Sheet'!J9 -> 0 | ... AF28: ='Balance Sheet'!AG9 -> 0
A29: Deposits in KUSCCO CFP | B29: ='Balance Sheet'!C10 -> 0 | C29: ='Balance Sheet'!D10 -> 0 | D29: ='Balance Sheet'!E10 -> 0 | E29: ='Balance Sheet'!F10 -> 0 | F29: ='Balance Sheet'!G10 -> 0 | G29: ='Balance Sheet'!H10 -> 0 | H29: ='Balance Sheet'!I10 -> 0 | I29: ='Balance Sheet'!J10 -> 0 | ... AF29: ='Balance Sheet'!AG10 -> 0
A30: Net Loans & Advances | B30: =B31-B32 -> -11360375 | C30: =C31-C32 -> -11360375 | D30: =D31-D32 -> -11360375 | E30: =E31-E32 -> -11360375 | F30: =F31-F32 -> -11360375 | G30: =G31-G32 -> -11360375 | H30: =H31-H32 -> -11360375 | I30: =I31-I32 -> -11360375 | ... AF30: =AF31-AF32 -> 0
A31: Gross Loans & advances | B31: ='Balance Sheet'!C13 -> 1.5366134e+08 | C31: ='Balance Sheet'!D13 -> 1.5618533e+08 | D31: ='Balance Sheet'!E13 -> 1.6603889e+08 | E31: ='Balance Sheet'!F13 -> 1.6866789e+08 | F31: ='Balance Sheet'!G13 -> 1.7244486e+08 | G31: ='Balance Sheet'!H13 -> 1.7377605e+08 | H31: ='Balance Sheet'!I13 -> 1.798867e+08 | I31: ='Balance Sheet'!J13 -> 1.8363099e+08 | ... AF31: ='Balance Sheet'!AG13 -> 0
A32: Allowance for loan losses | B32: ='Balance Sheet'!C14 -> 1.6502172e+08 | C32: ='Balance Sheet'!D14 -> 1.675457e+08 | D32: ='Balance Sheet'!E14 -> 1.7739927e+08 | E32: ='Balance Sheet'!F14 -> 1.8002826e+08 | F32: ='Balance Sheet'!G14 -> 1.8380523e+08 | G32: ='Balance Sheet'!H14 -> 1.8513642e+08 | H32: ='Balance Sheet'!I14 -> 1.9124707e+08 | I32: ='Balance Sheet'!J14 -> 1.9499137e+08 | ... AF32: ='Balance Sheet'!AG14 -> 0
A34: Non-Earning Assets | B34: ='Balance Sheet'!C6+'Balance Sheet'!C15+'Balance Sheet'!C19 -> 29682895 | C34: ='Balance Sheet'!D6+'Balance Sheet'!D15+'Balance Sheet'!D19 -> 28880422 | D34: ='Balance Sheet'!E6+'Balance Sheet'!E15+'Balance Sheet'!E19 -> 20895392 | E34: ='Balance Sheet'!F6+'Balance Sheet'!F15+'Balance Sheet'!F19 -> 16633147 | F34: ='Balance Sheet'!G6+'Balance Sheet'!G15+'Balance Sheet'!G19 -> 13664811 | G34: ='Balance Sheet'!H6+'Balance Sheet'!H15+'Balance Sheet'!H19 -> 16452230 | H34: ='Balance Sheet'!I6+'Balance Sheet'!I15+'Balance Sheet'!I19 -> 14596677 | I34: ='Balance Sheet'!J6+'Balance Sheet'!J15+'Balance Sheet'!J19 -> 16669460 | ... AF34: ='Balance Sheet'!AG6+'Balance Sheet'!AG15+'Balance Sheet'!AG19 -> 0
A35: Property and Equipment | B35: ='Balance Sheet'!C19 -> 0 | C35: ='Balance Sheet'!D19 -> 0 | D35: ='Balance Sheet'!E19 -> 0 | E35: ='Balance Sheet'!F19 -> 0 | F35: ='Balance Sheet'!G19 -> 0 | G35: ='Balance Sheet'!H19 -> 0 | H35: ='Balance Sheet'!I19 -> 0 | I35: ='Balance Sheet'!J19 -> 0 | ... AF35: ='Balance Sheet'!AG19 -> 0
A38: Turnover | B38: =B39+B41+B42 -> 21163468 | C38: =C39+C41+C42 -> 4783810.3 | D38: =D39+D41+D42 -> 7371541.8 | E38: =E39+E41+E42 -> 8633208.3 | F38: =F39+F41+F42 -> 11535163 | G38: =G39+G41+G42 -> 14226272 | H38: =H39+H41+H42 -> 0 | I38: =I39+I41+I42 -> 20729232 | ... AF38: =AF39+AF41+AF42 -> 0
A39: Loan Interest | B39: ='Income Stat.'!C6 -> 18951478 | C39: ='Income Stat.'!D6 -> 4030548.9 | D39: ='Income Stat.'!E6 -> 6130837.7 | E39: ='Income Stat.'!F6 -> 7210830.7 | F39: ='Income Stat.'!G6 -> 9661087.6 | G39: ='Income Stat.'!H6 -> 12033900 | I39: ='Income Stat.'!J6 -> 17611502 | J39: ='Income Stat.'!K6 -> 19679355 | K39: ='Income Stat.'!L6 -> 21980809 | L39: ='Income Stat.'!M6 -> 24118146 | M39: ='Income Stat.'!N6 -> 27728406 | N39: ='Income Stat.'!O6 -> 30137296 | O39: ='Income Stat.'!P6 -> 247107.89 | P39: ='Income Stat.'!Q6 -> 496047.53 | ... AF39: ='Income Stat.'!AG6 -> 0
A40: Yield on loans | B40: ='Income Stat.'!C6/'Income Stat.'!C14 -> 2363.0272 | C40: ='Income Stat.'!D6/'Income Stat.'!D14 -> #DIV/0! | D40: ='Income Stat.'!E6/'Income Stat.'!E14 -> 1652.5169 | E40: ='Income Stat.'!F6/'Income Stat.'!F14 -> 1943.6201 | F40: ='Income Stat.'!G6/'Income Stat.'!G14 -> 2604.0667 | G40: ='Income Stat.'!H6/'Income Stat.'!H14 -> 3243.6388 | I40: ='Income Stat.'!J6/'Income Stat.'!J14 -> 4747.0357 | J40: ='Income Stat.'!K6/'Income Stat.'!K14 -> 5304.4083 | K40: ='Income Stat.'!L6/'Income Stat.'!L14 -> 2581.4221 | L40: ='Income Stat.'!M6/'Income Stat.'!M14 -> 2832.4305 | M40: ='Income Stat.'!N6/'Income Stat.'!N14 -> 3256.4188 | N40: ='Income Stat.'!O6/'Income Stat.'!O14 -> 3.8346704 | O40: ='Income Stat.'!P6/'Income Stat.'!P14 -> #DIV/0! | P40: ='Income Stat.'!Q6/'Income Stat.'!Q14 -> #DIV/0! | ... AF40: ='Income Stat.'!AG6/'Income Stat.'!AG14 -> #DIV/0!
A41: Income from investments | B41: ='Income Stat.'!C8 -> 0 | C41: ='Income Stat.'!D8 -> 0 | D41: ='Income Stat.'!E8 -> 0 | E41: ='Income Stat.'!F8 -> 0 | F41: ='Income Stat.'!G8 -> 0 | G41: ='Income Stat.'!H8 -> 0 | I41: ='Income Stat.'!J8 -> 0 | J41: ='Income Stat.'!K8 -> 0 | K41: ='Income Stat.'!L8 -> 0 | L41: ='Income Stat.'!M8 -> 0 | M41: ='Income Stat.'!N8 -> 0 | N41: ='Income Stat.'!O8 -> 1176118 | O41: ='Income Stat.'!P8 -> 497759.1 | P41: ='Income Stat.'!Q8 -> 846216.1 | ... AF41: ='Income Stat.'!AG8 -> 0
A42: Fees & Commissions | B42: ='Income Stat.'!C7 -> 2211989.5 | C42: ='Income Stat.'!D7 -> 753261.4 | D42: ='Income Stat.'!E7 -> 1240704.1 | E42: ='Income Stat.'!F7 -> 1422377.6 | F42: ='Income Stat.'!G7 -> 1874075.3 | G42: ='Income Stat.'!H7 -> 2192372 | I42: ='Income Stat.'!J7 -> 3117729.5 | J42: ='Income Stat.'!K7 -> 3457538.2 | K42: ='Income Stat.'!L7 -> 3767865.8 | L42: ='Income Stat.'!M7 -> 4097533.2 | M42: ='Income Stat.'!N7 -> 4365147.3 | N42: ='Income Stat.'!O7 -> 8543067 | O42: ='Income Stat.'!P7 -> 24854 | P42: ='Income Stat.'!Q7 -> 64539.3 | ... AF42: ='Income Stat.'!AG7 -> 0
A44: Finanacial and Operating costs | B44: =B45+B46+B47+B48 -> 12462180 | C44: =C45+C46+C47+C48 -> 3663818.8 | D44: =D45+D46+D47+D48 -> 5455157 | E44: =E45+E46+E47+E48 -> 5517044.1 | F44: =F45+F46+F47+F48 -> 8537330.2 | G44: =G45+G46+G47+G48 -> 10835500 | I44: =I45+I46+I47+I48 -> 5424941.9 | J44: =J45+J46+J47+J48 -> 7513061.7 | K44: =K45+K46+K47+K48 -> 9378765.3 | L44: =L45+L46+L47+L48 -> 11403308 | M44: =M45+M46+M47+M48 -> 12262781 | N44: =N45+N46+N47+N48 -> 23746212 | O44: =O45+O46+O47+O48 -> 35872.99 | P44: =P45+P46+P47+P48 -> 149584.93 | ... AF44: =AF45+AF46+AF47+AF48 -> 0
A45: Interest expense on deposits | B45: ='Income Stat.'!C14 -> 8020 | C45: ='Income Stat.'!D14 -> 0 | D45: ='Income Stat.'!E14 -> 3710 | E45: ='Income Stat.'!F14 -> 3710 | F45: ='Income Stat.'!G14 -> 3710 | G45: ='Income Stat.'!H14 -> 3710 | I45: ='Income Stat.'!J14 -> 3710 | J45: ='Income Stat.'!K14 -> 3710 | K45: ='Income Stat.'!L14 -> 8515 | L45: ='Income Stat.'!M14 -> 8515 | M45: ='Income Stat.'!N14 -> 8515 | N45: ='Income Stat.'!O14 -> 7859162 | O45: ='Income Stat.'!P14 -> 0 | P45: ='Income Stat.'!Q14 -> 0 | ... AF45: ='Income Stat.'!AG14 -> 0
A46: Dividend expense on share capital | B46: ='Income Stat.'!C16 -> 0 | C46: ='Income Stat.'!D16 -> 0 | D46: ='Income Stat.'!E16 -> 0 | E46: ='Income Stat.'!F16 -> 0 | F46: ='Income Stat.'!G16 -> 0 | G46: ='Income Stat.'!H16 -> 0 | I46: ='Income Stat.'!J16 -> 0 | J46: ='Income Stat.'!K16 -> 0 | K46: ='Income Stat.'!L16 -> 0 | L46: ='Income Stat.'!M16 -> 0 | M46: ='Income Stat.'!N16 -> 0 | N46: ='Income Stat.'!O16 -> 0 | O46: ='Income Stat.'!P16 -> 0 | P46: ='Income Stat.'!Q16 -> 0 | ... AF46: ='Income Stat.'!AG16 -> 0
...

Sheet CAEL
A1: KIPSIGIS EDIS SACCO CAELS 2020
C2: Regulatory Stds | D2: Jan | E2: Feb | F2: Mar | G2: Apr | H2: May | I2: Jun | J2: Jul | K2: Aug | L2: Sep | M2: Oct | N2: Nov | O2: Dec | P2: Aud-21 | Q2: 44583 | R2: 44614 | S2: 44642 | T2: 44673 | U2: 44703 | V2: 44734 | W2: 44764 | X2: 44795 | Y2: 44826 | Z2: 44856 | AA2: 44887 | AB2: 44917 | AC2: Aud-22
A3: CAPITAL ADEQUACY | B3: Core Capital | C3: 10 M | D3: =Financials!B13 -> 54173123 | E3: =Financials!C13 -> 46780605 | F3: =Financials!D13 -> 48819889 | G3: =Financials!E13 -> 49097728 | H3: =Financials!F13 -> 52362476 | I3: =Financials!G13 -> 54611878 | J3: =Financials!H13 -> 57227673 | K3: =Financials!I13 -> 49460296 | ... AF3: =Financials!AD13 -> 0
B4: CCA | C4: 0.1 | D4: =Financials!B13/Financials!B5 -> 0.287927 | E4: =Financials!C13/Financials!C5 -> 0.24733297 | F4: =Financials!D13/Financials!D5 -> 0.25461593 | G4: =Financials!E13/Financials!E5 -> 0.2535675 | H4: =Financials!F13/Financials!F5 -> 0.27369093 | I4: =Financials!G13/Financials!G5 -> 0.28038133 | J4: =Financials!H13/Financials!H5 -> 0.2878985 | K4: =Financials!I13/Financials!I5 -> 0.24168334 | ... AF4: =Financials!AD13/Financials!AD5 -> #DIV/0!
B5: CCD | C5: 0.08 | D5: =Financials!B13/Financials!B6 -> 0.41941042 | E5: =Financials!C13/Financials!C6 -> 0.35920612 | F5: =Financials!D13/Financials!D6 -> 0.36335767 | G5: =Financials!E13/Financials!E6 -> 0.40458725 | H5: =Financials!F13/Financials!F6 -> 0.38784646 | I5: =Financials!G13/Financials!G6 -> 0.39789366 | J5: =Financials!H13/Financials!H6 -> 0.40488016 | K5: =Financials!I13/Financials!I6 -> 0.35902282 | ... AF5: =Financials!AD13/Financials!AD6 -> #DIV/0!
B6: ICA | C6: 0.08 | D6: =(Financials!B13-Financials!B16)/Financials!B5 -> 0.13438075 | E6: =(Financials!C13-Financials!C16)/Financials!C5 -> 0.09339547 | F6: =(Financials!D13-Financials!D16)/Financials!D5 -> 0.10145266 | G6: =(Financials!E13-Financials!E16)/Financials!E5 -> 0.10060224 | H6: =(Financials!F13-Financials!F16)/Financials!F5 -> 0.11760251 | I6: =(Financials!G13-Financials!G16)/Financials!G5 -> 0.12616387 | J6: =(Financials!H13-Financials!H16)/Financials!H5 -> 0.1359817 | K6: =(Financials!I15-Financials!I16)/Financials!I5 -> 0.093223527 | L6: =(Financials!J15-Financials!J16)/Financials!J5 -> 0.10315731 | M6: =(Financials!K15-Financials!K16)/Financials!K5 -> 0.11143229 | N6: =(Financials!L15-Financials!L16)/Financials!L5 -> 0.11836721 | O6: =(Financials!M15-Financials!M16)/Financials!M5 -> 0.12681959 | P6: =(Financials!N15-Financials!N16)/Financials!N5 -> 0.11057048 | Q6: =(Financials!O15-Financials!O16)/Financials!O5 -> 0.10890195 | R6: =(Financials!P15-Financials!P16)/Financials!P5 -> 0.10793145 | ... AF6: =(Financials!AD15-Financials!AD16)/Financials!AD5 -> #DIV/0!
A7: ASSET QUALITY | B7: A/LNPL30
B8: NPL30 | I8: 0.1 | J8: 1.1 | V8: 0.08 | Y8: 0.08 | AB8: 0.08 | AC8: 0.08
B9: Non-earning Asset ratio | C9: Max 10% | D9: =('Balance Sheet'!C7+'Balance Sheet'!C20)/'Balance Sheet'!C26 -> 0.067031569 | E9: =('Balance Sheet'!D7+'Balance Sheet'!D20)/'Balance Sheet'!D26 -> 0.066382251 | F9: =('Balance Sheet'!E7+'Balance Sheet'!E20)/'Balance Sheet'!E26 -> 0.065410873 | G9: =('Balance Sheet'!F7+'Balance Sheet'!F20)/'Balance Sheet'!F26 -> 0.087119953 | H9: =('Balance Sheet'!G7+'Balance Sheet'!G20)/'Balance Sheet'!G26 -> 0.069039035 | I9: =('Balance Sheet'!H7+'Balance Sheet'!H20)/'Balance Sheet'!H26 -> 0.066546852 | J9: =('Balance Sheet'!I7+'Balance Sheet'!I20)/'Balance Sheet'!I26 -> 0.064961617 | K9: =('Balance Sheet'!J7+'Balance Sheet'!J20)/'Balance Sheet'!J26 -> 0.058004796 | ... AF9: =('Balance Sheet'!AE7+'Balance Sheet'!AE20)/'Balance Sheet'!AE26 -> #DIV/0!
B10: Land and Building ratio | C10: Max 5% | D10: =('Balance Sheet'!C21+'Balance Sheet'!C22)/'Balance Sheet'!C26 -> 0.013854151 | E10: =('Balance Sheet'!D21+'Balance Sheet'!D22)/'Balance Sheet'!D26 -> 0.013781534 | F10: =('Balance Sheet'!E21+'Balance Sheet'!E22)/'Balance Sheet'!E26 -> 0.013756395 | G10: =('Balance Sheet'!F21+'Balance Sheet'!F22)/'Balance Sheet'!F26 -> 0.013622225 | H10: =('Balance Sheet'!G21+'Balance Sheet'!G22)/'Balance Sheet'!G26 -> 0.013786565 | I10: =('Balance Sheet'!H21+'Balance Sheet'!H22)/'Balance Sheet'!H26 -> 0.013541845 | J10: =('Balance Sheet'!I21+'Balance Sheet'!I22)/'Balance Sheet'!I26 -> 0.013269335 | K10: =('Balance Sheet'!J21+'Balance Sheet'!J22)/'Balance Sheet'!J26 -> 0.012888603 | ... AF10: =('Balance Sheet'!AE21+'Balance Sheet'!AE22)/'Balance Sheet'!AE26 -> #DIV/0!
A11: EARNINGS | B11: Non-Government Investment to Deposit ratio | C11: Max 5% | D11: ='Balance Sheet'!C11/'Balance Sheet'!C29 -> 0 | E11: ='Balance Sheet'!D11/'Balance Sheet'!D29 -> 0 | F11: ='Balance Sheet'!E11/'Balance Sheet'!E29 -> 0 | G11: ='Balance Sheet'!F11/'Balance Sheet'!F29 -> 0 | H11: ='Balance Sheet'!G11/'Balance Sheet'!G29 -> 0 | I11: ='Balance Sheet'!H11/'Balance Sheet'!H29 -> 0 | J11: ='Balance Sheet'!I11/'Balance Sheet'!I29 -> 0 | K11: ='Balance Sheet'!J11/'Balance Sheet'!J29 -> 0 | ... AF11: ='Balance Sheet'!AE11/'Balance Sheet'!AE29 -> #DIV/0!
B12: Non-Government Investment to Core Capital ratio | C12: Max 40% | D12: ='Balance Sheet'!C11/Financials!B13 -> 0 | E12: ='Balance Sheet'!D11/Financials!C13 -> 0 | F12: ='Balance Sheet'!E11/Financials!D13 -> 0 | G12: ='Balance Sheet'!F11/Financials!E13 -> 0 | H12: ='Balance Sheet'!G11/Financials!F13 -> 0 | I12: ='Balance Sheet'!H11/Financials!G13 -> 0 | J12: ='Balance Sheet'!I11/Financials!H13 -> 0 | K12: ='Balance Sheet'!J11/Financials!I13 -> 0 | ... AF12: ='Balance Sheet'!AE11/Financials!AD13 -> #DIV/0!
B13: Gross loans/TA | D13: =Financials!B31/Financials!B5 -> 0.81670111 | E13: =Financials!C31/Financials!C5 -> 0.8257649 | F13: =Financials!D31/Financials!D5 -> 0.86596158 | G13: =Financials!E31/Financials!E5 -> 0.87109318 | H13: =Financials!F31/Financials!F5 -> 0.90134381 | I13: =Financials!G31/Financials!G5 -> 0.8921788 | J13: =Financials!H31/Financials!H5 -> 0.90496618 | K13: =Financials!I31/Financials!I5 -> 0.89729652 | ... AF13: =Financials!AD31/Financials!AD5 -> #DIV/0!
B14: ROA | D14: ='Income Stat.'!C38/Financials!B5 -> 0.064016188 | E14: ='Income Stat.'!D38/Financials!C5 -> 0.019285493 | F14: ='Income Stat.'!E38/Financials!D5 -> 0.028347288 | G14: ='Income Stat.'!F38/Financials!E5 -> 0.028209885 | H14: ='Income Stat.'!G38/Financials!F5 -> 0.044336802 | I14: ='Income Stat.'!H38/Financials!G5 -> 0.054198684 | J14: ='Income Stat.'!I38/Financials!H5 -> 0.065464705 | K14: ='Income Stat.'!J38/Financials!I5 -> 0.024729848 | ... AF14: ='Income Stat.'!AE38/Financials!AD5 -> #DIV/0!
B15: Cost Income ratio | D15: ='Income Stat.'!C24/('Income Stat.'!C20-'Income Stat.'!C22) -> 0.49347835 | E15: ='Income Stat.'!D24/('Income Stat.'!D20-'Income Stat.'!D22) -> 0.34656382 | F15: ='Income Stat.'!E24/('Income Stat.'!E20-'Income Stat.'!E22) -> 0.37866162 | G15: ='Income Stat.'!F24/('Income Stat.'!F20-'Income Stat.'!F22) -> 0.46826403 | H15: ='Income Stat.'!G24/('Income Stat.'!G20-'Income Stat.'!G22) -> 0.41040247 | I15: ='Income Stat.'!H24/('Income Stat.'!H20-'Income Stat.'!H22) -> 0.39566228 | J15: ='Income Stat.'!I24/('Income Stat.'!I20-'Income Stat.'!I22) -> 0.37675108 | K15: ='Income Stat.'!J24/('Income Stat.'!J20-'Income Stat.'!J22) -> 0.63617927 | ... AF15: ='Income Stat.'!AE24/('Income Stat.'!AE20-'Income Stat.'!AE22) -> #DIV/0!
B16: Operating Expense ratio | D16: ='Income Stat.'!C24/'Income Stat.'!C4 -> 0.44868199 | E16: ='Income Stat.'!D24/'Income Stat.'!D4 -> 0.34387083 | F16: ='Income Stat.'!E24/'Income Stat.'!E4 -> 0.37640146 | G16: ='Income Stat.'!F24/'Income Stat.'!F4 -> 0.46430975 | H16: ='Income Stat.'!G24/'Income Stat.'!G4 -> 0.40778925 | I16: ='Income Stat.'!H24/'Income Stat.'!H4 -> 0.38840572 | J16: ='Income Stat.'!I24/'Income Stat.'!I4 -> 0.36892718 | K16: ='Income Stat.'!J24/'Income Stat.'!J4 -> 0.34400585 | ... AF16: ='Income Stat.'!AE24/'Income Stat.'!AE4 -> #DIV/0!
A17: LIQUIDITY | B17: MIN LIQ ratio | C17: Min 15% | D17: ='Balance Sheet'!C4/'Balance Sheet'!C27 -> 1.8417609 | E17: ='Balance Sheet'!D4/'Balance Sheet'!D27 -> 1.7067339 | F17: ='Balance Sheet'!E4/'Balance Sheet'!E27 -> 0.87542938 | G17: ='Balance Sheet'!F4/'Balance Sheet'!F27 -> 0.69203013 | H17: ='Balance Sheet'!G4/'Balance Sheet'!G27 -> 0.41108245 | I17: ='Balance Sheet'!H4/'Balance Sheet'!H27 -> 0.55972529 | J17: ='Balance Sheet'!I4/'Balance Sheet'!I27 -> 0.35741154 | K17: ='Balance Sheet'!J4/'Balance Sheet'!J27 -> 0.59436174 | ... AF17: ='Balance Sheet'!AE4/'Balance Sheet'!AE27 -> #DIV/0!
B18: Technical LIQ ratio | D18: ='Balance Sheet'!C4/'Balance Sheet'!C29 -> 0.18645607 | E18: ='Balance Sheet'!D4/'Balance Sheet'!D29 -> 0.17240885 | F18: ='Balance Sheet'!E4/'Balance Sheet'!E29 -> 0.11021717 | G18: ='Balance Sheet'!F4/'Balance Sheet'!F29 -> 0.073722443 | H18: ='Balance Sheet'!G4/'Balance Sheet'!G29 -> 0.046687549 | I18: ='Balance Sheet'!H4/'Balance Sheet'!H29 -> 0.065364398 | J18: ='Balance Sheet'!I4/'Balance Sheet'!I29 -> 0.047912648 | K18: ='Balance Sheet'!J4/'Balance Sheet'!J29 -> 0.074696103 | ... AF18: ='Balance Sheet'!AE4/'Balance Sheet'!AE29 -> #DIV/0!
B19: External Borrowing ratio | C19: Max 25% | D19: ='Balance Sheet'!C37/'Balance Sheet'!C26 -> 0.0070814798 | E19: ='Balance Sheet'!D37/'Balance Sheet'!D26 -> 0.0057309132 | F19: ='Balance Sheet'!E37/'Balance Sheet'!E26 -> 0.0056532272 | G19: ='Balance Sheet'!F37/'Balance Sheet'!F26 -> 0.0016792782 | H19: ='Balance Sheet'!G37/'Balance Sheet'!G26 -> 0.0016995372 | I19: ='Balance Sheet'!H37/'Balance Sheet'!H26 -> 0.0016693693 | J19: ='Balance Sheet'!I37/'Balance Sheet'!I26 -> 0 | K19: ='Balance Sheet'!J37/'Balance Sheet'!J26 -> 0.039091289 | ... AF19: ='Balance Sheet'!AE37/'Balance Sheet'!AE26 -> #DIV/0!
