Workbook

Sheet Balance Sheet
B1: FORM 6 SASRA2/006
B2: STATEMENT OF FINANCIAL POSITION
B3: FINANCIAL YEAR 2020 | C3: Audited 2019 | D3: 44216 | E3: 44247 | F3: 44275 | G3: 44306 | H3: 44336 | I3: 44367 | J3: 44428 | K3: 44459 | L3: 44489 | M3: 44520 | N3: 44550 | O3: Aud-20 | P3: 44197 | Q3: 44229 | R3: 44258 | S3: 44290 | T3: 44321 | U3: 44353 | V3: 44384 | W3: 44416 | X3: 44448 | Y3: 44479 | Z3: 44511 | AA3: 44542 | AB3: Audited 2021 | AC3: Audited 2022 | AD3: 44927 | AE3: 44958 | AF3: 44986 | AG3: 45017 | AH3: 45047 | AI3: 45078
A4: 1 | B4: Cash & Cash Equivalent | C4: =C5+C6 -> 5913431 | D4: =D5+D6 -> 9406573.4 | E4: =E5+E6 -> 8277490.9 | F4: =F5+F6 -> 9373390.3 | G4: =G5+G6 -> 8126.11 | H4: =H5+H6 -> 7859723.3 | I4: =I5+I6 -> 9595878 | J4: =J5+J6 -> 6578642.2 | ... AI4: =AI5+AI6 -> 4254981.4
A5: 1.1 | B5: Cash in hand(both local and foreign notes and coins) | C5: 1181486 | D5: 1535873 | E5: 1627931 | F5: 1432331 | G5: 1362.78 | H5: 1020140 | I5: 1339502 | J5: 983329 | K5: 745868 | L5: 1175304 | M5: 999453 | N5: 889413 | O5: 889413 | P5: 808744 | Q5: 1463195 | R5: 996536 | S5: 995865 | T5: 1005286 | U5: 745462 | V5: 789695 | W5: 812263 | X5: 997919 | Y5: 741860 | Z5: 1131988 | AA5: 936573 | AB5: =1246202+652830+633783 -> 2532815 | AC5: 826316 | AD5: 855522 | AE5: 1037821 | AF5: 1756212 | AG5: 963293 | AH5: 1412183 | AI5: 1406003
A6: 1.2 | B6: Cash at bank:(placement with financial institutions) | C6: =3779296+730618+222031 -> 4731945 | D6: 7870700.4 | E6: 6649559.9 | F6: 7941059.3 | G6: 6763.33 | H6: 6839583.3 | I6: 8256376 | J6: 5595313.2 | K6: 6613868.1 | L6: 8141403.1 | M6: 7231173.8 | N6: 7539183.7 | O6: =7022807+407426+141154 -> 7571387 | P6: 6967820.9 | Q6: 6211026.8 | R6: 9582098.5 | S6: 8318772.3 | T6: 4120272.6 | U6: 4159200.2 | V6: 6700986.7 | W6: 7196491.5 | X6: 6368694.3 | Y6: 7993184.5 | Z6: 7065447.8 | AA6: 7018014.8 | AB6: =172243+3492748+119643+34314+9510+816860+73173+337+276687 -> 4995515 | AC6: =1965432+27660+138132+4047+29475+36380+62210+817106 -> 3080442 | AD6: 2615046.2 | AE6: 3437612.8 | AF6: 3931551.2 | AG6: 2414344.5 | AH6: 2631695.3 | AI6: 2848978.4
A7: 2 | B7: Prepayments & Sundry Receivables | C7: =50000+502558 -> 552558 | D7: 0 | E7: 0 | F7: 0 | G7: 0 | H7: 0 | I7: 0 | J7: 0 | K7: 0 | L7: 0 | M7: 0 | N7: 0 | O7: =50000+502558 -> 552558 | P7: 0 | Q7: 0 | R7: 0 | S7: 0 | T7: 0 | U7: 0 | V7: 0 | W7: 0 | X7: 0 | Y7: 0 | Z7: 0 | AA7: 0 | AB7: =50000+502558 -> 552558 | AC7: =50000+502558 -> 552558 | AD7: 0 | AE7: 0 | AF7: 0 | AG7: 0 | AH7: 0 | AI7: 0
A8: 3 | B8: Financial Investments | C8: =SUM(C9:C12) -> 914790 | D8: =SUM(D9:D12) -> 830000 | E8: =SUM(E9:E12) -> 830000 | F8: =SUM(F9:F12) -> 830000 | G8: =SUM(G9:G12) -> 830 | H8: =SUM(H9:H12) -> 830000 | I8: =SUM(I9:I12) -> 830000 | J8: =SUM(J9:J12) -> 830000 | ... AI8: =SUM(AI9:AI12) -> 0
A9: 3.1 | B9: Government Securities - Treasury Bills/bonds, | D9: 0 | E9: 0 | F9: 0 | G9: 0 | H9: 0 | I9: 0 | J9: 0 | K9: 0 | L9: 0 | M9: 0 | N9: 0 | P9: 0 | Q9: 0 | R9: 0 | S9: 0 | T9: 0 | U9: 0 | V9: 0 | W9: 0 | X9: 0 | Y9: 0 | Z9: 0 | AA9: 0 | AD9: 0 | AE9: 0 | AF9: 0 | AG9: 0 | AH9: 0 | AI9: 0
A10: 3.2 | B10: Other Securities - Commercial papers/Bonds | D10: 0 | E10: 0 | F10: 0 | G10: 0 | H10: 0 | I10: 0 | J10: 0 | K10: 0 | L10: 0 | M10: 0 | N10: 0 | P10: 0 | Q10: 0 | R10: 0 | S10: 0 | T10: 0 | U10: 0 | V10: 0 | W10: 0 | X10: 0 | Y10: 0 | Z10: 0 | AA10: 0 | AD10: 0 | AE10: 0 | AF10: 0 | AG10: 0 | AH10: 0 | AI10: 0
A11: 3.3a | B11: Balances with other SACCO Societies | C11: 914790 | D11: 0 | E11: 0 | F11: 0 | G11: 0 | H11: 0 | I11: 0 | J11: 0 | K11: 0 | L11: 0 | M11: 0 | N11: 0 | O11: 1121325 | P11: 0 | Q11: 0 | R11: 0 | S11: 0 | T11: 0 | U11: 0 | V11: 0 | W11: 0 | X11: 0 | Y11: 0 | Z11: 0 | AA11: 0 | AB11: =800000+997415 -> 1797415 | AC11: 1811583 | AD11: 0 | AE11: 0 | AF11: 0 | AG11: 0 | AH11: 0 | AI11: 0
A12: 3.3b | B12: Investments in companies - shares/stocks | D12: 830000 | E12: 830000 | F12: 830000 | G12: 830 | H12: 830000 | I12: 830000 | J12: 830000 | K12: 830000 | L12: 830000 | M12: 830000 | N12: 830000 | P12: 940000 | Q12: 940000 | R12: 0 | S12: 12790 | T12: 12790 | U12: 12790 | V12: 12790 | W12: 0 | X12: 0 | Y12: 0 | Z12: 0 | AA12: 0 | AB12: 14168 | AC12: 14168 | AD12: 0 | AE12: 0 | AF12: 0 | AG12: 0 | AH12: 0 | AI12: 0
A13: 4 | B13: Net Loan Portfolio | C13: =C14-C15 -> 34556455 | D13: =D14-D15 -> 33360262 | E13: =E14-E15 -> 31943513 | F13: =F14-F15 -> 30943015 | G13: =G14-G15 -> 30037.26 | H13: =H14-H15 -> 31338995 | I13: =I14-I15 -> 30894868 | J13: =J14-J15 -> 28324892 | ... AI13: =AI14-AI15 -> 39250917
A14: 4.1 | B14: Gross Loan Portfolio | C14: =33461992+36452329-34743360 -> 35170961 | D14: 33720055 | E14: 32289005 | F14: 31278269 | G14: 30378.5 | H14: 31678269 | I14: 31212425 | J14: 28631247 | K14: 28075287 | L14: 27920687 | M14: 28020687 | N14: 27520107 | O14: =34556455+16049999-15122495 -> 35483959 | P14: 26114120 | Q14: 26314120 | R14: 34818647 | S14: 34878059 | T14: 35988059 | U14: 35948938 | V14: 36563938 | W14: 36063938 | X14: 36063812 | Y14: 35948812 | Z14: 35848812 | AA14: 37148812 | AB14: =34818647+22108610-18838885 -> 38088372 | AC14: 44270076 | AD14: 43142023 | AE14: 43912269 | AF14: 41723017 | AG14: 40999261 | AH14: 40460610 | AI14: 39675444
A15: 4.2 | B15: Allowance for Loan Loss | C15: 614506 | D15: 359792.98 | E15: 345492 | F15: 335254 | G15: 341.24 | H15: 339274 | I15: 317557 | J15: 306354.34 | K15: 300405.56 | L15: 298751.35 | M15: 299821.34 | N15: 294465.14 | O15: 665312 | P15: 279421.08 | Q15: 281561.08 | R15: 372559.52 | S15: 373195.23 | T15: 385072.23 | U15: 384653.64 | V15: 391234.14 | W15: 385884.14 | X15: 385882.79 | Y15: 384652.29 | Z15: 383582.29 | AA15: 397492.29 | AB15: 939560 | AC15: 916390 | AD15: 461619.65 | AE15: 469861.28 | AF15: 446436.28 | AG15: 438692.09 | AH15: 432928.53 | AI15: 424527.26
A16: 5 | B16: Accounts Receivables | C16: =SUM(C17:C19) -> 0 | D16: =SUM(D17:D19) -> 0 | E16: =SUM(E17:E19) -> 0 | F16: =SUM(F17:F19) -> 0 | G16: =SUM(G17:G19) -> 0 | H16: =SUM(H17:H19) -> 0 | I16: =SUM(I17:I19) -> 0 | J16: =SUM(J17:J19) -> 0 | ... AI16: =SUM(AI17:AI19) -> 0
A17: 5.1 | B17: Tax Recoverable | D17: 0 | E17: 0 | F17: 0 | G17: 0 | H17: 0 | I17: 0 | J17: 0 | K17: 0 | L17: 0 | M17: 0 | N17: 0 | P17: 0 | Q17: 0 | R17: 0 | S17: 0 | T17: 0 | U17: 0 | V17: 0 | W17: 0 | X17: 0 | Y17: 0 | Z17: 0 | AA17: 0 | AD17: 0 | AE17: 0 | AF17: 0 | AG17: 0 | AH17: 0 | AI17: 0
A18: 5.2 | B18: Deferred Tax Assets | D18: 0 | E18: 0 | F18: 0 | G18: 0 | H18: 0 | I18: 0 | J18: 0 | K18: 0 | L18: 0 | M18: 0 | N18: 0 | P18: 0 | Q18: 0 | R18: 0 | S18: 0 | T18: 0 | U18: 0 | V18: 0 | W18: 0 | X18: 0 | Y18: 0 | Z18: 0 | AA18: 0 | AD18: 0 | AE18: 0 | AF18: 0 | AG18: 0 | AH18: 0 | AI18: 0
A19: 5.3 | B19: Retirement Benefit Assets | D19: 0 | E19: 0 | F19: 0 | G19: 0 | H19: 0 | I19: 0 | J19: 0 | K19: 0 | L19: 0 | M19: 0 | N19: 0 | P19: 0 | Q19: 0 | R19: 0 | S19: 0 | T19: 0 | U19: 0 | V19: 0 | W19: 0 | X19: 0 | Y19: 0 | Z19: 0 | AA19: 0 | AD19: 0 | AE19: 0 | AF19: 0 | AG19: 0 | AH19: 0 | AI19: 0
A20: 6 | B20: Property & Equipment & Other assets | C20: =SUM(C21:C25) -> 3684210 | D20: =SUM(D21:D25) -> 5311543 | E20: =SUM(E21:E25) -> 5311543 | F20: =SUM(F21:F25) -> 5311543 | G20: =SUM(G21:G25) -> 5311.54 | H20: =SUM(H21:H25) -> 5311543 | I20: =SUM(I21:I25) -> 5311543 | J20: =SUM(J21:J25) -> 5311543 | ... AI20: =SUM(AI21:AI25) -> 4056552
A21: 6.1 | B21: Investment Properties | D21: 12790 | E21: 12790 | F21: 12790 | G21: 12.79 | H21: 12790 | I21: 12790 | J21: 12790 | K21: 12790 | L21: 12790 | M21: 12790 | N21: 12790 | P21: 12790 | Q21: 12790 | R21: 12790 | S21: 1121325 | T21: 1121325 | U21: 1121325 | V21: 1021325 | W21: 1021325 | X21: 1021325 | Y21: 1021325 | Z21: 1021325 | AA21: 1021325 | AE21: 0 | AF21: 0 | AG21: 0 | AH21: 0 | AI21: 0
A22: 6.2 | B22: Property & Equipment | C22: 3252299 | D22: 3121603 | E22: 3121603 | F22: 3121603 | G22: 3121.6 | H22: 3121603 | I22: 3121603 | J22: 3121603 | K22: 3121603 | L22: 3121603 | M22: 3121603 | N22: 3121603 | O22: 2908487 | P22: 2497283 | Q22: 2497283 | R22: 2908487 | S22: 2908487 | T22: 2908487 | U22: 2908487 | V22: 2908487 | W22: 2908487 | X22: 2908487 | Y22: 2908487 | Z22: 2908487 | AA22: 2908487 | AB22: =5972801+362793+616097+1074326+945 -> 8026962 | AC22: =2818976+661225+1286323+1756454+709+892871 -> 7416558 | AD22: 1766522 | AE22: 1966552 | AF22: 1966552 | AG22: 1966552 | AH22: 1966552 | AI22: 1966552
A23: 6.3 | B23: Prepaid Lease rentals | D23: 0 | E23: 0 | F23: 0 | G23: 0 | H23: 0 | I23: 0 | J23: 0 | K23: 0 | L23: 0 | M23: 0 | N23: 0 | P23: 0 | Q23: 0 | R23: 0 | S23: 0 | T23: 0 | U23: 0 | V23: 0 | W23: 0 | X23: 0 | Y23: 0 | Z23: 0 | AA23: 0 | AD23: 0 | AE23: 0 | AF23: 0 | AG23: 0 | AH23: 0 | AI23: 0
A24: 6.4 | B24: Intangible Assets | C24: 431561 | D24: 399162 | E24: 399162 | F24: 399162 | G24: 399.16 | H24: 399162 | I24: 399162 | J24: 399162 | K24: 399162 | L24: 399162 | M24: 399162 | N24: 399162 | O24: 1931561 | P24: 1500000 | Q24: 1500000 | R24: 1931561 | S24: 1931561 | T24: 1931561 | U24: 1931561 | V24: 1931561 | W24: 1504343 | X24: 1504343 | Y24: 1500000 | Z24: 1500000 | AA24: 1500000 | AB24: 1563747 | AC24: 3506594 | AD24: 1500000 | AE24: 1700000 | AF24: 1700000 | AG24: 1700000 | AH24: 1700000 | AI24: 2090000
A25: 6.5 | B25: Other Assets | C25: 350 | D25: 1777988 | E25: 1777988 | F25: 1777988 | G25: 1777.99 | H25: 1777988 | I25: 1777988 | J25: 1777988 | K25: 1777988 | L25: 1777988 | M25: 1777988 | N25: 1777988 | O25: 450 | P25: 1538390 | Q25: 1538390 | R25: 0 | S25: 0 | T25: 0 | U25: 0 | V25: 0 | W25: 0 | X25: 0 | Y25: 0 | Z25: 0 | AA25: 0 | AB25: =28243 -> 28243 | AC25: 17680 | AD25: 0 | AE25: 0 | AF25: 0 | AG25: 0 | AH25: 0 | AI25: 0
B26: Total Assets | C26: =C4+C7+C8+C13+C16+C20 -> 45621444 | D26: =D4+D7+D8+D13+D16+D20 -> 48908378 | E26: =E4+E7+E8+E13+E16+E20 -> 46362547 | F26: =F4+F7+F8+F13+F16+F20 -> 46457948 | G26: =G4+G7+G8+G13+G16+G20 -> 44304.91 | H26: =H4+H7+H8+H13+H16+H20 -> 45340261 | I26: =I4+I7+I8+I13+I16+I20 -> 46632289 | J26: =J4+J7+J8+J13+J16+J20 -> 41045078 | ... AI26: =AI4+AI7+AI8+AI13+AI16+AI20 -> 47562451
A27: 7 | B27: Savings Deposits - Withdrawable deposits - FOSA) | C27: 1971265 | D27: 7372722.5 | E27: 6326562.9 | F27: 6172651 | G27: 4172.65 | H27: 3910168.4 | I27: 4070168.4 | J27: 3070168.4 | K27: 3250228.4 | L27: 3990624.4 | M27: 4118624.4 | N27: 3948625 | O27: 3948625 | P27: 4008625 | Q27: 3041804.9 | R27: 6477107.9 | S27: 6077107.9 | T27: 4977107.9 | U27: 4077107.9 | V27: 6700986.7 | W27: 5700986.7 | X27: 5607807.9 | Y27: 8207818.7 | Z27: 7307818.7 | AA27: 7807818.7 | AB27: 7807819 | AC27: 10150000 | AD27: 10810000 | AE27: 12860000 | AF27: 11975503 | AG27: 9267177.1 | AH27: 9379478.7 | AI27: 13080785
A28: 8 | B28: Short Term Deposits (e.g Fixed deposits, special savings) | C28: 462570 | D28: 1000000 | E28: 800000 | F28: 1000000 | G28: 800 | H28: 800000 | I28: 800000 | J28: 600000 | K28: 680000 | L28: 600000 | M28: 600000 | N28: 600000 | O28: 600000 | P28: 600000 | Q28: 600000 | R28: 600000 | S28: 600000 | T28: 600000 | U28: 800000 | V28: 600000 | W28: 800000 | X28: 800000 | Y28: 800000 | Z28: 800000 | AA28: 800000 | AB28: 800000 | AC28: 1270000 | AD28: 1250000 | AE28: 1330000 | AF28: 1304000 | AG28: 951188 | AH28: 966509.2 | AI28: 971466.05
A29: 9 | B29: Non withdrawable deposits (BOSA member deposits) | C29: 16751811 | D29: 17196600 | E29: 17866325 | F29: 17896600 | G29: 18041.33 | H29: 19185646 | I29: 17866325 | J29: 19040852 | K29: 19052852 | L29: 19052852 | M29: 19121352 | N29: 19121352 | O29: 19121352 | P29: 19716252 | Q29: 20116252 | R29: 23669977 | S29: 23949977 | T29: 22949977 | U29: 22949977 | V29: 23959977 | W29: 23959977 | X29: 23685977 | Y29: 21996252 | Z29: 21996252 | AA29: 21903252 | AB29: 21903252 | AC29: 17259000 | AD29: 19020000 | AE29: 19055000 | AF29: 19010000 | AG29: 19045000 | AH29: 19050730 | AI29: 19320630
B30: Total Deposit liabilities | C30: =SUM(C27:C29) -> 19185646 | D30: =SUM(D27:D29) -> 25569322 | E30: =SUM(E27:E29) -> 24992888 | F30: =SUM(F27:F29) -> 25069251 | G30: =SUM(G27:G29) -> 23013.98 | H30: =SUM(H27:H29) -> 23895814 | I30: =SUM(I27:I29) -> 22736493 | J30: =SUM(J27:J29) -> 22711020 | ... AI30: =SUM(AI27:AI29) -> 33372882
A31: 10 | B31: Accounts Payable & Other Liabilities | C31: =SUM(C32:C37) -> 4651478 | D31: =SUM(D32:D37) -> 4632781 | E31: =SUM(E32:E37) -> 2415998 | F31: =SUM(F32:F37) -> 2246430 | G31: =SUM(G32:G37) -> 2046.43 | H31: =SUM(H32:H37) -> 1899331.3 | I31: =SUM(I32:I37) -> 1799331.3 | J31: =SUM(J32:J37) -> 998032 | ... AI31: =SUM(AI32:AI37) -> 228356
A32: 10.1 | B32: Tax Payable | C32: 120447 | D32: 0 | E32: 0 | F32: 0 | G32: 0 | H32: 0 | I32: 0 | J32: 0 | K32: 0 | L32: 0 | M32: 0 | N32: 0 | O32: 120000 | P32: 0 | Q32: 0 | R32: 0 | S32: 20226 | T32: 20226 | U32: 20226 | V32: 20226 | W32: 20226 | X32: 20226 | Y32: 20226 | Z32: 0 | AA32: 0 | AB32: 244821 | AC32: 288356 | AD32: 0 | AE32: 0 | AF32: 0 | AG32: 0 | AH32: 0 | AI32: 228356
A33: 10.2 | B33: Dividends Payable | C33: =469475+80000 -> 549475 | D33: 0 | E33: 0 | F33: 0 | G33: 0 | H33: 0 | I33: 0 | J33: 0 | K33: 0 | L33: 0 | M33: 0 | N33: 0 | O33: =468758+80000 -> 548758 | P33: 0 | Q33: 0 | R33: 0 | S33: 0 | T33: 0 | U33: 0 | V33: 0 | W33: 0 | X33: 0 | Y33: 0 | Z33: 0 | AA33: 0 | AB33: =468758+80000 -> 548758 | AC33: =120400+1720740 -> 1841140 | AD33: 0 | AE33: 0 | AF33: 0 | AG33: 0 | AH33: 0 | AI33: 0
A34: 10.3 | B34: Deferred Tax Liability | D34: 0 | E34: 0 | F34: 0 | G34: 0 | H34: 0 | I34: 0 | J34: 0 | K34: 0 | L34: 0 | M34: 0 | N34: 0 | P34: 0 | Q34: 0 | R34: 0 | S34: 0 | T34: 0 | U34: 0 | V34: 0 | W34: 0 | X34: 0 | Y34: 0 | Z34: 0 | AA34: 0 | AD34: 0 | AE34: 0 | AF34: 0 | AG34: 0 | AH34: 0 | AI34: 0
A35: 10.4 | B35: Retirement Benefits Liability | D35: 0 | E35: 0 | F35: 0 | G35: 0 | H35: 0 | I35: 0 | J35: 0 | K35: 0 | L35: 0 | M35: 0 | N35: 0 | P35: 0 | Q35: 0 | R35: 0 | S35: 0 | T35: 0 | U35: 0 | V35: 0 | W35: 0 | X35: 0 | Y35: 0 | Z35: 0 | AA35: 0 | AD35: 0 | AE35: 0 | AF35: 0 | AG35: 0 | AH35: 0 | AI35: 0
A36: 10.5 | B36: Other Liabilities | C36: =210200+1854693 -> 2064893 | D36: 1986251 | E36: 0 | F36: 0 | G36: 0 | H36: 0 | I36: 0 | J36: 0 | K36: 0 | L36: 0 | M36: 0 | N36: 0 | O36: =223778+2089208 -> 2312986 | P36: 0 | Q36: 0 | R36: 352000 | S36: 276000 | T36: 276000 | U36: 276000 | V36: 0 | W36: 0 | X36: 0 | Y36: 0 | Z36: 0 | AA36: 0 | AB36: =75000+300000+2389060 -> 2764060 | AC36: =608778+108000+69000+2728339 -> 3514117 | AD36: 0 | AE36: 0 | AF36: 0 | AG36: 0 | AH36: 0 | AI36: 0
A37: 10.6 | B37: External Borrowings | C37: 1916663 | D37: 2646530 | E37: 2415998 | F37: 2246430 | G37: 2046.43 | H37: 1899331.3 | I37: 1799331.3 | J37: 998032 | K37: 918755.33 | L37: 814756.33 | M37: 0 | N37: 0 | P37: 0 | Q37: 0 | R37: 0 | S37: 0 | T37: 0 | U37: 0 | V37: 0 | W37: 0 | X37: 0 | Y37: 0 | Z37: 0 | AA37: 0 | AC37: 2550000 | AD37: 0 | AE37: 0 | AF37: 0 | AG37: 0 | AH37: 0 | AI37: 0
B38: Total Liabilities | C38: =C30+C31 -> 23837124 | D38: =D30+D31 -> 30202103 | E38: =E30+E31 -> 27408886 | F38: =F30+F31 -> 27315681 | G38: =G30+G31 -> 25060.41 | H38: =H30+H31 -> 25795146 | I38: =I30+I31 -> 24535825 | J38: =J30+J31 -> 23709052 | ... AI38: =AI30+AI31 -> 33601238
A39: 11 | B39: Share Capital (Members share capital per Bylaws) | C39: 11986229 | D39: 11903229 | E39: 11903229 | F39: 11903229 | G39: 11903.23 | H39: 11903229 | I39: 11903229 | J39: 11903229 | K39: 11903229 | L39: 11903229 | M39: 11903229 | N39: 11903229 | O39: 11986229 | P39: 11903229 | Q39: 11903229 | R39: 11986229 | S39: 11986229 | T39: 11986229 | U39: 11986229 | V39: 11986229 | W39: 12186229 | X39: 12186229 | Y39: 12236229 | Z39: 12236229 | AA39: 12236229 | AB39: 11986229 | AC39: 13324579 | AD39: 13324578 | AE39: 13326478 | AF39: 13328478 | AG39: 13328478 | AH39: 13328478 | AI39: 13328478
A40: 12 | B40: Capital Grants | D40: 0 | E40: 0 | F40: 0 | G40: 0 | H40: 0 | I40: 0 | J40: 0 | K40: 0 | L40: 0 | M40: 0 | N40: 0 | P40: 0 | Q40: 0 | R40: 353000 | S40: 353000 | T40: 353000 | U40: 353000 | V40: 353000 | W40: 353000 | X40: 353000 | Y40: 353000 | Z40: 353000 | AA40: 353000 | AC40: 353000 | AD40: 353000 | AE40: 353000 | AF40: 353000 | AG40: 353000 | AH40: 353000 | AI40: 353000
...

Sheet Income Statement
A1: FORM 7 SASRA/007
A2: STATEMENT OF COMPREHENSIVE INCOME
A3: FINANCIAL YEAR 2020 | C3: Audited 2019 | D3: 44216 | E3: 44247 | F3: 44275 | G3: 44306 | H3: 44336 | I3: 44367 | J3: 44428 | K3: 44459 | L3: 44489 | M3: 44520 | N3: 44550 | O3: Aud-20 | P3: 44197 | Q3: 44229 | R3: 44258 | S3: 44290 | T3: 44321 | U3: 44353 | V3: 44384 | W3: 44416 | X3: 44448 | Y3: 44479 | Z3: 44511 | AA3: 44542 | AB3: Audited 2021 | AC3: Audited 2022 | AD3: 44927 | AE3: 44958 | AF3: 44986 | AG3: 45017 | AH3: 45047 | AI3: 45078
A4: 1 | B4: Financial Income | C4: =C5+C8 -> 9358783 | D4: =D5+D8 -> 794544 | E4: =E5+E8 -> 1218213 | F4: =F5+F8 -> 1599578 | G4: =G5+G8 -> 1828.14 | H4: =H5+H8 -> 2095852 | I4: =I5+I8 -> 2508852 | J4: =J5+J8 -> 3060732 | ... AI4: =AI5+AI8 -> 4123779.1
A5: 2 | B5: Financial Income from Loans Portfolio | C5: =SUM(C6:C7) -> 8185722 | D5: =SUM(D6:D7) -> 523021 | E5: =SUM(E6:E7) -> 845052 | F5: =SUM(F6:F7) -> 1142961 | G5: =SUM(G6:G7) -> 1371.53 | H5: =SUM(H6:H7) -> 1469179 | I5: =SUM(I6:I7) -> 1772179 | J5: =SUM(J6:J7) -> 2284074 | ... AI5: =SUM(AI6:AI7) -> 3055241.1
A6: 2.1 | B6: Interest on Loan Portfolio | C6: 5708221 | D6: 495800 | E6: 805788 | F6: 1084733 | G6: 1294.73 | H6: 1391535 | I6: 1691535 | J6: 2171667 | K6: 2321667 | L6: 2561667 | M6: 2841667 | N6: 3081667 | O6: 4343844 | P6: 311643 | Q6: 691958 | R6: 1052954 | S6: 1373679.9 | T6: 1789343.7 | U6: 2174997.2 | V6: 2544983 | W6: 2987009.8 | X6: 2987009.8 | Y6: 3398058.1 | Z6: 3819253.8 | AA6: 4154721.8 | AB6: =1813304+4154722 -> 5968026 | AC6: =2243600+4296386 -> 6539986 | AD6: 409253.57 | AE6: 847486.69 | AF6: 1230257.2 | AG6: 1702036.4 | AH6: 1857489.1 | AI6: 2239980.8
A7: 2.2 | B7: Fees & Commission on Loan Portfolio | C7: =1778141+699360 -> 2477501 | D7: 27221 | E7: 39264 | F7: 58228 | G7: 76.8 | H7: 77644 | I7: 80644 | J7: 112407 | K7: 125107 | L7: 132007 | M7: 224796 | N7: 257776 | O7: =408484+2479484 -> 2887968 | P7: 30059 | Q7: 91999 | R7: 101920 | S7: 127810 | T7: 190778 | U7: 219272.5 | V7: 246664.5 | W7: 282668.5 | X7: 283240.3 | Y7: 316084.3 | Z7: 348401.3 | AA7: 406583.3 | AB7: =464602+1519398 -> 1984000 | AC7: 2418677 | AD7: 117905 | AE7: 237617 | AF7: 341492 | AG7: 491317 | AH7: 733962.1 | AI7: 815260.28
A8: 3 | B8: Financial Income from Investments in: | C8: =C9+C10+C11+C12 -> 1173061 | D8: =D9+D10+D11+D12 -> 271523 | E8: =E9+E10+E11+E12 -> 373161 | F8: =F9+F10+F11+F12 -> 456617 | G8: =G9+G10+G11+G12 -> 456.61 | H8: =H9+H10+H11+H12 -> 626673 | I8: =I9+I10+I11+I12 -> 736673 | J8: =J9+J10+J11+J12 -> 776658 | ... AI8: =AI9+AI10+AI11+AI12 -> 1068538
A9: 3.1 | B9: Government Securities | D9: 0 | E9: 0 | F9: 0 | G9: 0 | H9: 0 | I9: 0 | J9: 0 | K9: 0 | L9: 0 | M9: 0 | N9: 0 | P9: 0 | Q9: 0 | R9: 0 | S9: 0 | T9: 0 | U9: 0 | V9: 0 | W9: 0 | X9: 0 | AD9: 0 | AE9: 0 | AF9: 0 | AG9: 0 | AH9: 0 | AI9: 0
A10: 3.2 | B10: Deposit with Banks and Other Financial Inst. | D10: 0 | E10: 0 | F10: 0 | G10: 0 | H10: 0 | I10: 0 | J10: 0 | K10: 0 | L10: 0 | M10: 0 | N10: 0 | P10: 0 | Q10: 0 | R10: 0 | S10: 0 | T10: 0 | U10: 0 | V10: 0 | W10: 0 | X10: 0 | AB10: =5126 -> 5126 | AC10: 0 | AD10: 0 | AE10: 0 | AF10: 0 | AG10: 0 | AH10: 0 | AI10: 0
A11: 3.3 | B11: Other Investments - dividend & Interest incomes from investments | D11: 120773 | E11: 120773 | F11: 120773 | G11: 120.77 | H11: 120773 | I11: 120773 | J11: 120773 | K11: 120773 | L11: 120773 | M11: 120773 | N11: 120773 | P11: 0 | Q11: 0 | R11: 0 | S11: 0 | T11: 0 | U11: 0 | V11: 0 | W11: 0 | X11: 0 | AC11: 6630 | AD11: 0 | AE11: 0 | AF11: 0 | AG11: 0 | AH11: 0 | AI11: 0
A12: 3.4 | B12: Other Operating Income- Salary processing fees, transaction fees, membership fees | C12: 1173061 | D12: 150750 | E12: 252388 | F12: 335844 | G12: 335.84 | H12: 505900 | I12: 615900 | J12: 655885 | K12: 779980 | L12: 1121160 | M12: 1267760 | N12: 1365711 | O12: 1094511 | P12: 214890 | Q12: 216210 | R12: 309535 | S12: 498450 | T12: 586890 | U12: 672970 | V12: 826501 | W12: 920382 | X12: 920382 | Y12: 1034924.5 | Z12: 1171014.5 | AA12: 1406720.5 | AB12: =1429266 -> 1429266 | AC12: 1212145 | AD12: 138995.72 | AE12: 311673.72 | AF12: 469963.52 | AG12: 653873.28 | AH12: 832495.23 | AI12: 1068538
A13: 4 | B13: Financial Expense | C13: =C14+C15+C16+C17+C18+C19 -> 0 | D13: =D14+D15+D16+D17+D18+D19 -> 28800 | E13: =E14+E15+E16+E17+E18+E19 -> 52458 | F13: =F14+F15+F16+F17+F18+F19 -> 74791 | G13: =G14+G15+G16+G17+G18+G19 -> 93.03 | H13: =H14+H15+H16+H17+H18+H19 -> 110960 | I13: =I14+I15+I16+I17+I18+I19 -> 133152 | J13: =J14+J15+J16+J17+J18+J19 -> 161806.83 | ... AI13: =AI14+AI15+AI16+AI17+AI18+AI19 -> 1879372
A14: 4.2 | B14: Interest Expense on Deposits | D14: 0 | E14: 0 | F14: 0 | G14: 0 | H14: 0 | I14: 0 | J14: 0 | K14: 0 | L14: 0 | M14: 0 | N14: 0 | O14: 425004 | P14: 0 | Q14: 0 | R14: 6000 | S14: 6000 | T14: 6000 | U14: 6000 | V14: 6000 | W14: 6000 | X14: 6000 | Y14: 6000 | Z14: 6000 | AA14: 6000 | AB14: 468758 | AC14: 1841140 | AD14: 0 | AE14: 0 | AF14: 0 | AG14: 0 | AH14: 755364 | AI14: 755364
A15: 4.3 | B15: Cost of External Borrowings | D15: 28800 | E15: 52458 | F15: 74791 | G15: 93.03 | H15: 110960 | I15: 133152 | J15: 161806.83 | K15: 172473.83 | L15: 180711.83 | M15: 180711.83 | N15: 180711.83 | P15: 0 | Q15: 0 | R15: 0 | S15: 0 | T15: 0 | U15: 0 | V15: 0 | W15: 0 | X15: 0 | Y15: 0 | Z15: 0 | AA15: 0 | AD15: 0 | AE15: 0 | AF15: 0 | AG15: 0 | AH15: 0 | AI15: 0
A16: 4.4 | B16: Dividend Expenses (on member shares) | D16: 0 | E16: 0 | F16: 0 | G16: 0 | H16: 0 | I16: 0 | J16: 0 | K16: 0 | L16: 0 | M16: 0 | N16: 0 | P16: 0 | Q16: 0 | R16: 0 | S16: 0 | T16: 0 | U16: 0 | V16: 0 | W16: 0 | X16: 0 | Y16: 0 | Z16: 0 | AA16: 0 | AD16: 0 | AE16: 0 | AF16: 0 | AG16: 0 | AH16: 1120633 | AI16: 1120633
A17: 4.5 | B17: Other Financial Expense | D17: 0 | E17: 0 | F17: 0 | G17: 0 | H17: 0 | I17: 0 | J17: 0 | K17: 0 | L17: 0 | M17: 0 | N17: 0 | P17: 0 | Q17: 0 | R17: 0 | S17: 0 | T17: 0 | U17: 0 | V17: 0 | W17: 0 | X17: 0 | Y17: 0 | Z17: 0 | AA17: 0 | AC17: 0 | AD17: 0 | AE17: 0 | AF17: 0 | AG17: 0 | AH17: 0 | AI17: 0
A18: 4.6 | B18: Fees & Commission Expense | D18: 0 | E18: 0 | F18: 0 | G18: 0 | H18: 0 | I18: 0 | J18: 0 | K18: 0 | L18: 0 | M18: 0 | N18: 0 | P18: 0 | Q18: 0 | R18: 0 | S18: 0 | T18: 0 | U18: 0 | V18: 0 | W18: 0 | X18: 0 | Y18: 0 | Z18: 0 | AA18: 0 | AD18: 0 | AE18: 0 | AF18: 0 | AG18: 0 | AH18: 0 | AI18: 3375
A19: 4.7 | B19: Other Expense | D19: 0 | E19: 0 | F19: 0 | G19: 0 | H19: 0 | I19: 0 | J19: 0 | K19: 0 | L19: 0 | M19: 0 | N19: 0 | P19: 0 | Q19: 0 | R19: 0 | S19: 0 | T19: 0 | U19: 0 | V19: 0 | W19: 0 | X19: 0 | Y19: 0 | Z19: 0 | AA19: 0 | AC19: 559580 | AD19: 0 | AE19: 0 | AF19: 0 | AG19: 0 | AH19: 0 | AI19: 0
A20: 5 | B20: Net Financial Income/(Loss) | C20: =C4-C13 -> 9358783 | D20: =D4-D13 -> 765744 | E20: =E4-E13 -> 1165755 | F20: =F4-F13 -> 1524787 | G20: =G4-G13 -> 1735.11 | H20: =H4-H13 -> 1984892 | I20: =I4-I13 -> 2375700 | J20: =J4-J13 -> 2898925.2 | ... AI20: =AI4-AI13 -> 2244407.1
A21: 6 | B21: Allowance for Loan Loss | C21: =C22-C23 -> 15867 | D21: =D22-D23 -> 359793 | E21: =E22-E23 -> 345492 | F21: =F22-F23 -> 345492 | G21: =G22-G23 -> 341.2 | H21: =H22-H23 -> 339274 | I21: =I22-I23 -> 317557 | J21: =J22-J23 -> 306354.3 | ... AI21: =AI22-AI23 -> 424527.3
A22: 6.1 | B22: Provision for Loan Losses | C22: 15867 | D22: 359793 | E22: 345492 | F22: 345492 | G22: 341.2 | H22: 339274 | I22: 317557 | J22: 306354.3 | K22: 300405.6 | L22: 298751.4 | M22: 299821.3 | N22: 299821.3 | O22: 50806 | P22: 279421.1 | Q22: 281561.1 | R22: 281561.1 | S22: 373629.5 | T22: 385072.2 | U22: 385072.2 | V22: 385072.2 | W22: 385072.2 | X22: 385072.2 | Y22: 384652.3 | Z22: 384652.3 | AA22: 384652.3 | AB22: 274248 | AC22: 0 | AD22: 461619.6 | AE22: 469861.3 | AF22: 469861.3 | AG22: 438692.1 | AH22: 432928.5 | AI22: 424527.3
A23: 6.2 | B23: Value of Loans Recovered | D23: 0 | E23: 0 | F23: 0 | G23: 0 | H23: 0 | I23: 0 | J23: 0 | K23: 0 | L23: 0 | M23: 0 | N23: 0 | P23: 0 | Q23: 0 | R23: 0 | S23: 0 | T23: 0 | U23: 0 | V23: 0 | W23: 0 | X23: 0 | Y23: 0 | Z23: 0 | AA23: 0 | AC23: =1205099-916390 -> 288709 | AD23: 0 | AE23: 0 | AF23: 0 | AG23: 0 | AH23: 0 | AI23: 0
A24: 7 | B24: Operating Expenses | C24: =C25+C26+C27+C28+C29 -> 6458194 | D24: =D25+D26+D27+D28+D29 -> 343366 | E24: =E25+E26+E27+E28+E29 -> 510292 | F24: =F25+F26+F27+F28+F29 -> 680718 | G24: =G25+G26+G27+G28+G29 -> 788.8 | H24: =H25+H26+H27+H28+H29 -> 897312 | I24: =I25+I26+I27+I28+I29 -> 1049512 | J24: =J25+J26+J27+J28+J29 -> 1408986 | ... AI24: =AI25+AI26+AI27+AI28+AI29 -> 2990046.7
A25: 7.1 | B25: Personnel Expenses | C25: 2547911 | D25: 164926 | E25: 329852 | F25: 476778 | G25: 578.9 | H25: 674752 | I25: 775952 | J25: 1102426 | K25: 1266949 | L25: 1452460 | M25: 1637971 | N25: 1823482 | O25: 2393386 | P25: 220439 | Q25: 475439 | R25: 730439 | S25: 985439 | T25: 1240439 | U25: 1471439 | V25: 1687609.7 | W25: 1903780.3 | X25: 2122201 | Y25: 2353201 | Z25: 2600791.6 | AA25: 2852791.6 | AB25: 3178894 | AC25: =2627254+2984776 -> 5612030 | AD25: 237000 | AE25: 263211 | AF25: 239020 | AG25: 1022703 | AH25: 1435828.7 | AI25: 1679188.7
A26: 7.2 | B26: Governance Expenses | C26: 86705 | D26: 25500 | E26: 25500 | F26: 45500 | G26: 45.5 | H26: 61000 | I26: 89000 | J26: 119000 | K26: 143000 | L26: 166000 | M26: 196000 | N26: 215600 | O26: 215600 | P26: 20000 | Q26: 45000 | R26: 61000 | S26: 124000 | T26: 139000 | U26: 159000 | V26: 174000 | W26: 199250 | X26: 215750 | Y26: 249250 | Z26: 270250 | AA26: 290250 | AB26: =321270 -> 321270 | AC26: 269017 | AD26: 24750 | AE26: 0 | AF26: 0 | AG26: 0 | AH26: 263350 | AI26: 333970
A27: 7.3 | B27: Marketing Expenses | C27: 148426 | D27: 2100 | E27: 4100 | F27: 7600 | G27: 13.6 | H27: 10600 | I27: 13600 | J27: 16600 | K27: 19600 | L27: 22600 | M27: 25600 | N27: 25600 | O27: 61600 | P27: 3000 | Q27: 3000 | R27: 6000 | S27: 9000 | T27: 40600 | U27: 40600 | V27: 55600 | W27: 60600 | X27: 60600 | Y27: 60600 | Z27: 97500 | AA27: 102500 | AC27: 116000 | AD27: 4000 | AE27: 10000 | AF27: 13950 | AG27: 32500 | AH27: 50508 | AI27: 64558
A28: 7.4 | B28: Depreciation and Amortization Charges | C28: 665723 | D28: 0 | E28: 0 | F28: 0 | G28: 0 | H28: 0 | I28: 0 | J28: 0 | K28: 0 | L28: 0 | M28: 0 | N28: 0 | O28: 459812 | P28: 0 | Q28: 0 | R28: 0 | S28: 0 | T28: 0 | U28: 0 | V28: 0 | W28: 0 | X28: 0 | Y28: 0 | Z28: 0 | AA28: 0 | AB28: =1692350 -> 1692350 | AD28: 0 | AE28: 0 | AF28: 0 | AG28: 0 | AH28: 0 | AI28: 0
A29: 7.5 | B29: Administrative Expenses | C29: =563035+3112117-665723 -> 3009429 | D29: 150840 | E29: 150840 | F29: 150840 | G29: 150.8 | H29: 150960 | I29: 170960 | J29: 170960 | K29: 197460 | L29: 232460 | M29: 232460 | N29: 244460 | O29: =3196540+96772 -> 3293312 | P29: 3500 | Q29: 7000 | R29: 10500 | S29: 13500 | T29: 131894 | U29: 131894 | V29: 141894 | W29: 239261 | X29: 280001 | Y29: 291001 | Z29: 313813 | AA29: 0 | AB29: =3619000-AB28+425758 -> 2352408 | AC29: 652288 | AD29: 45593 | AE29: 22348 | AF29: 60258 | AG29: 236548 | AH29: 601496 | AI29: 912330
A30: 8 | B30: Net Operating Income | C30: =C20-C21-C24 -> 2884722 | D30: =D20-D21-D24 -> 62585 | E30: =E20-E21-E24 -> 309971 | F30: =F20-F21-F24 -> 498577 | G30: =G20-G21-G24 -> 605.11 | H30: =H20-H21-H24 -> 748306 | I30: =I20-I21-I24 -> 1008631 | J30: =J20-J21-J24 -> 1183584.9 | ... AI30: =AI20-AI21-AI24 -> -1170166.9
A31: 9 | B31: Net Non- Operating Income/ (Expense) | C31: =C32-C33 -> 0 | D31: =D32-D33 -> 0 | E31: =E32-E33 -> 0 | F31: =F32-F33 -> 0 | G31: =G32-G33 -> 0 | H31: =H32-H33 -> 0 | I31: =I32-I33 -> 0 | J31: =J32-J33 -> 0 | ... AI31: =AI32-AI33 -> 0
A32: 9.1 | B32: Non- Operating Income | D32: 0 | E32: 0 | F32: 0 | G32: 0 | H32: 0 | I32: 0 | J32: 0 | K32: 0 | L32: 0 | M32: 0 | N32: 0 | P32: 0 | Q32: 0 | R32: 0 | S32: 0 | T32: 0 | U32: 0 | V32: 0 | W32: 0 | X32: 0 | AD32: 0 | AE32: 0 | AF32: 0 | AG32: 0 | AH32: 0 | AI32: 0
A33: 9.2 | B33: Non- Operating Expense | D33: 0 | E33: 0 | F33: 0 | G33: 0 | H33: 0 | I33: 0 | J33: 0 | K33: 0 | L33: 0 | M33: 0 | N33: 0 | P33: 0 | Q33: 0 | R33: 0 | S33: 0 | T33: 0 | U33: 0 | V33: 0 | W33: 0 | X33: 0 | AD33: 0 | AE33: 0 | AF33: 0 | AG33: 0 | AH33: 0 | AI33: 0
A34: 10 | B34: Net Income (Before Taxes and Donations) | C34: =C30+C31 -> 2884722 | D34: =D30+D31 -> 62585 | E34: =E30+E31 -> 309971 | F34: =F30+F31 -> 498577 | G34: =G30+G31 -> 605.11 | H34: =H30+H31 -> 748306 | I34: =I30+I31 -> 1008631 | J34: =J30+J31 -> 1183584.9 | ... AI34: =AI30+AI31 -> -1170166.9
A35: 11 | B35: Taxes (Incomes taxes & Other payable to KRA) | C35: 120900 | D35: 0 | E35: 0 | F35: 0 | G35: 0 | H35: 0 | I35: 0 | J35: 0 | K35: 0 | L35: 0 | M35: 0 | N35: 0 | O35: 120000 | P35: 0 | Q35: 0 | R35: 0 | S35: 0 | T35: 0 | U35: 0 | V35: 0 | W35: 0 | X35: 0 | AB35: 244821 | AC35: 244821 | AD35: 0 | AE35: 0 | AF35: 0 | AG35: 0 | AH35: 0 | AI35: 0
A36: 12 | B36: Net Income (After Taxes before Donations) | C36: =C34-C35 -> 2763822 | D36: =D34-D35 -> 62585 | E36: =E34-E35 -> 309971 | F36: =F34-F35 -> 498577 | G36: =G34-G35 -> 605.11 | H36: =H34-H35 -> 748306 | I36: =I34-I35 -> 1008631 | J36: =J34-J35 -> 1183584.9 | ... AI36: =AI34-AI35 -> -1170166.9
A37: 13 | B37: Donations | D37: 0 | E37: 0 | F37: 0 | G37: 0 | H37: 0 | I37: 0 | J37: 0 | K37: 0 | L37: 0 | M37: 0 | N37: 0 | P37: 0 | Q37: 0 | R37: 0 | S37: 0 | T37: 0 | U37: 0 | V37: 0 | W37: 0 | X37: 0 | AD37: 0 | AE37: 0 | AF37: 0 | AG37: 0 | AH37: 0 | AI37: 0
A38: 14 | B38: Net Income/(After Taxes and Donations) | C38: =C36-C37 -> 2763822 | D38: =D36-D37 -> 62585 | E38: =E36-E37 -> 309971 | F38: =F36-F37 -> 498577 | G38: =G36-G37 -> 605.11 | H38: =H36-H37 -> 748306 | I38: =I36-I37 -> 1008631 | J38: =J36-J37 -> 1183584.9 | ... AI38: =AI36-AI37 -> -1170166.9

Sheet performance report
A1: KENYA ACHIEVAS SACCO SOCIETY LIMITED
A2: PERFORMANCE AND COMPLIANCE REPORT AS AT : 31st December , 2020
B3: Prudential Standard | C3: Audited | D3: Returns | F3: audited 2020
C4: 2019 | D4: 30th September , 2020 | E4: 31st December , 2020
A5: A. CAPITAL ADEQUACY
A6: Core Capital | B6: ≥10M | C6: 105761017 | D6: 1.3090778e+08 | E6: 1.3180408e+08 | F6: 151314319
A7: Core Capital/Total Assets | B7: ≥10% | C7: 0.25651421 | D7: 0.33118356 | E7: 0.33539735 | F7: 0.38281096
A8: Institutional Capital/Total Assets | B8: ≥8% | C8: 0.075663262 | D8: 0.078922816 | E8: 0.079383462 | F8: 0.082144729
A9: B. ASSET QUALITY
A10: NPL (Substandard+Doubtful+Loss) | B10: <5% | C10: 0 | D10: 0.35335718 | E10: 0.17684352 | F10: 0.17709617
A11: Non-Earning Assets | B11: <10% | C11: 0.39367662 | D11: 0.40733915 | E11: 0.384709 | F11: 0.38827796
A12: Equity investments/Deposits | B12: <5% | C12: 0.10766462 | D12: 0.11804502 | E12: 0.11696392 | F12: 0.11696392
A13: Equity investments/Core capital | B13: <40% | C13: 0.1975872 | D13: 0.15963163 | E13: 0.1585461 | F13: 0.1381034
A14: C. EARNINGS RATING
A15: Yield on Gross Loans | C15: 0.21113871 | D15: 0.095884024 | E15: 0.15807556 | F15: 0.71974145
A16: Total Expense/Total Income | C16: 0.94538921 | D16: 0.93145747 | E16: 0.91913046 | F16: 0.94963975
A17: Net Income/Average Assets (ROA) | C17: 0.0011817921 | D17: 0.011032346 | E17: 0.013320391 | F17: 0.0032121204
A18: Operating Expenses/Financial Income (OPEX) | C18: 0.76738298 | D18: 0.82018259 | E18: 0.72286404 | F18: 0.7342184
A19: D. LIQUIDITY
A20: Liquid Assets/Short-term Liabilities | B20: >15% | C20: 0.82348453 | D20: 0.99869763 | E20: 1.3905577 | F20: 1.3905578
A21: External Borrowing/Total Assets | B21: <25% | C21: 0.15037564 | D21: 0.14243551 | E21: 0.11714059 | F21: 0.11646112
A22: Liquid Assets/Total Assets | C22: 0.17216881 | D22: 0.17398863 | E22: 0.25781697 | F22: 0.25632152
A23: E. STRUCTURE/SENSITIVITY TO RISK
A24: Gross loans /Total Assets | B24: 70-80 | C24: 0.44059964 | D24: 0.42539494 | E24: 0.37304617 | F24: 0.3703532
A25: Gross loans/Deposits | B25: >100% | C25: 0.93593771 | D25: 0.94984399 | E25: 0.82053915 | F25: 0.8193685
A26: Financial Investments/Total Assets | C26: 0.10766462 | D26: 0.29809868 | E26: 0.11696392 | F26: 0.11696392
A27: Dividends+Interest on Deposits/Total Income | C27: 0.038593323 | D27: 0.016222684 | E27: 0.014425275 | F27: 0
A28: F. KEY FINANCIAL STATISTICS | C28: 2015 | D28: 2016 | E28: 2017
A29: Total Assets | C29: 4.1230082e+08 | D29: 3.9527258e+08 | E29: 3.9297889e+08 | F29: 395271644
A30: Average Assets | C30: 3.9895258e+08 | D30: 4.1287967e+08 | E30: 4.0296011e+08 | F30: 4.0378623e+08
A31: Total Deposits | C31: 194093679 | D31: 1.7702587e+08 | E31: 1.7866213e+08 | F31: 178662126
A32: Gross Loans | C32: 1.8165959e+08 | D32: 1.6814696e+08 | E32: 146599270 | F32: 146390119
A33: Core Capital | C33: 105761017 | D33: 1.3090778e+08 | E33: 1.3180408e+08 | F33: 151314319
A34: Institutional Capital | C34: 31196025 | D34: 31196025 | E34: 31196025 | F34: 32469482
A35: Non-performing Loans | C35: 0 | D35: 59415934 | E35: 25925130 | F35: 25925130
A36: Non-Earning Assets | C36: 162313194 | D36: 1.6101e+08 | E36: 1.5118252e+08 | F36: 153475268
A37: Property and Equipment | C37: 70993240 | D37: 66863240 | E37: 65630884 | F37: 65630483
A38: Equity Investments | C38: 20897023 | D38: 20897022 | E38: 20897022 | F38: 20897022
A39: Financial Investments | C39: 20897023 | D39: 52771176 | E39: 20897022 | F39: 20897022
A40: Liquid Assets | C40: 70985340 | D40: 68772935 | E40: 1.0131663e+08 | F40: 101316629
...

Sheet Financials
A1: BORESHA SACCO FINANCIALS
A3: Year/month | C3: 44216 | D3: 44247 | E3: 44275 | F3: 44306 | G3: 44336 | H3: 44397 | I3: 44428 | J3: 44459 | K3: 44489 | L3: 44520 | M3: 44550 | N3: Aud-20 | O3: 44197 | P3: 44229 | Q3: 44258 | R3: 44290 | S3: 44321 | T3: 44353 | U3: 44384 | V3: 44416 | W3: 44448 | X3: 44479 | Y3: 44511 | Z3: 44542 | AA3: Audited 2021 | AB3: Audited 2022 | AC3: 44927 | AD3: 44958 | AE3: 44986 | AF3: 45017 | AG3: 45047 | AH3: 45078 | AI3: 45109 | AJ3: 45141 | AK3: 45173 | AL3: 45204 | AM3: 45236 | AN3: 45268
A4: Membership
A5: Total Assets | B5: ='[1]Balance Sheet'!C26 -> 0 | C5: ='Balance Sheet'!D26 -> 48908378 | D5: ='Balance Sheet'!E26 -> 46362547 | E5: ='Balance Sheet'!F26 -> 46457948 | F5: ='Balance Sheet'!G26 -> 44304.91 | G5: ='Balance Sheet'!H26 -> 45340261 | H5: ='Balance Sheet'!I26 -> 46632289 | I5: ='Balance Sheet'!J26 -> 41045078 | J5: ='Balance Sheet'!K26 -> 41276160 | ... AN5: ='Balance Sheet'!AO26 -> 0
A6: Total Deposits | B6: =B7+B8 -> 0 | C6: =C7+C8 -> 24569322 | D6: =D7+D8 -> 24192888 | E6: =E7+E8 -> 24069251 | F6: =F7+F8 -> 22213.98 | G6: =G7+G8 -> 23095814 | H6: =H7+H8 -> 21936493 | I6: =I7+I8 -> 22111020 | ... AN6: =AN7+AN8 -> 0
A7: Deposits-Members(BOSA) | B7: ='[1]Balance Sheet'!C29 -> 0 | C7: ='Balance Sheet'!D29 -> 17196600 | D7: ='Balance Sheet'!E29 -> 17866325 | E7: ='Balance Sheet'!F29 -> 17896600 | F7: ='Balance Sheet'!G29 -> 18041.33 | G7: ='Balance Sheet'!H29 -> 19185646 | H7: ='Balance Sheet'!I29 -> 17866325 | I7: ='Balance Sheet'!J29 -> 19040852 | J7: ='Balance Sheet'!K29 -> 19052852 | ... AN7: ='Balance Sheet'!AO29 -> 0
A8: Deposits-Customers(FOSA) | B8: ='[1]Balance Sheet'!C27 -> 0 | C8: ='Balance Sheet'!D27 -> 7372722.5 | D8: ='Balance Sheet'!E27 -> 6326562.9 | E8: ='Balance Sheet'!F27 -> 6172651 | F8: ='Balance Sheet'!G27 -> 4172.65 | G8: ='Balance Sheet'!H27 -> 3910168.4 | H8: ='Balance Sheet'!I27 -> 4070168.4 | I8: ='Balance Sheet'!J27 -> 3070168.4 | J8: ='Balance Sheet'!K27 -> 3250228.4 | ... AN8: ='Balance Sheet'!AO27 -> 0
A9: Deposits-Term | B9: ='[1]Balance Sheet'!C28 -> 0 | C9: ='Balance Sheet'!D28 -> 1000000 | D9: ='Balance Sheet'!E28 -> 800000 | E9: ='Balance Sheet'!F28 -> 1000000 | F9: ='Balance Sheet'!G28 -> 800 | G9: ='Balance Sheet'!H28 -> 800000 | H9: ='Balance Sheet'!I28 -> 800000 | I9: ='Balance Sheet'!J28 -> 600000 | J9: ='Balance Sheet'!K28 -> 680000 | ... AN9: ='Balance Sheet'!AO28 -> 0
A10: External Borrowing | B10: ='[1]Balance Sheet'!C37 -> 0 | C10: ='Balance Sheet'!D37 -> 2646530 | D10: ='Balance Sheet'!E37 -> 2415998 | E10: ='Balance Sheet'!F37 -> 2246430 | F10: ='Balance Sheet'!G37 -> 2046.43 | G10: ='Balance Sheet'!H37 -> 1899331.3 | H10: ='Balance Sheet'!I37 -> 1799331.3 | I10: ='Balance Sheet'!J37 -> 998032 | J10: ='Balance Sheet'!K37 -> 918755.33 | ... AN10: ='Balance Sheet'!AO37 -> 0
A12: Share capital and Reserves
A13: Core Capital | B13: =B15-B28 -> 0 | C13: =C15-C28 -> 18706275 | D13: =D15-D28 -> 18953661 | E13: =E15-E28 -> 19142267 | F13: =F15-F28 -> 19244.49 | G13: =G15-G28 -> 21996464 | H13: =H15-H28 -> 22096464 | I13: =I15-I28 -> 17336025 | ... AN13: =AN15-AN28 -> 0
A14: Institutional Capital | B14: =B13-B16 -> 0 | C14: =C13-C16 -> 6803046 | D14: =D13-D16 -> 7050432 | E14: =E13-E16 -> 7239038 | F14: =F13-F16 -> 7341.26 | G14: =G13-G16 -> 10093235 | H14: =H13-H16 -> 10193235 | I14: =I13-I16 -> 5432796 | ... AN14: =AN13-AN16 -> 0
A15: Total Capital | B15: =B16+B17+B18+B19+B20+B21 -> 0 | C15: =C16+C17+C18+C19+C20+C21 -> 18706275 | D15: =D16+D17+D18+D19+D20+D21 -> 18953661 | E15: =E16+E17+E18+E19+E20+E21 -> 19142267 | F15: =F16+F17+F18+F19+F20+F21 -> 19244.49 | G15: =G16+G17+G18+G19+G20+G21 -> 21996464 | H15: =H16+H17+H18+H19+H20+H21 -> 22096464 | I15: =I16+I17+I18+I19+I20+I21 -> 17336025 | ... AN15: =AN16+AN17+AN18+AN19+AN20+AN21 -> 0
A16: Members Share Capital | B16: ='[1]Balance Sheet'!C39 -> 0 | C16: ='Balance Sheet'!D39 -> 11903229 | D16: ='Balance Sheet'!E39 -> 11903229 | E16: ='Balance Sheet'!F39 -> 11903229 | F16: ='Balance Sheet'!G39 -> 11903.23 | G16: ='Balance Sheet'!H39 -> 11903229 | H16: ='Balance Sheet'!I39 -> 11903229 | I16: ='Balance Sheet'!J39 -> 11903229 | J16: ='Balance Sheet'!K39 -> 11903229 | ... AN16: ='Balance Sheet'!AO39 -> 0
A17: Entrance Fees
A18: Retained Earnings | B18: ='[1]Balance Sheet'!C41 -> 0 | C18: ='Balance Sheet'!D41 -> 4226429 | D18: ='Balance Sheet'!E41 -> 4473815 | E18: ='Balance Sheet'!F41 -> 4662421 | F18: ='Balance Sheet'!G41 -> 4764.64 | G18: ='Balance Sheet'!H41 -> 7042856 | H18: ='Balance Sheet'!I41 -> 7142856 | I18: ='Balance Sheet'!J41 -> 2735417 | J18: ='Balance Sheet'!K41 -> 3017995.6 | ... AN18: ='Balance Sheet'!AO41 -> 0
A19: Appropriation Account | B19: ='[1]Balance Sheet'!C42 -> 0
A20: Statutory Reserves | B20: ='[1]Balance Sheet'!C45 -> 0 | C20: ='Balance Sheet'!D45 -> 2223617 | D20: ='Balance Sheet'!E45 -> 2223617 | E20: ='Balance Sheet'!F45 -> 2223617 | F20: ='Balance Sheet'!G45 -> 2223.62 | G20: ='Balance Sheet'!H45 -> 2697379 | H20: ='Balance Sheet'!I45 -> 2697379 | I20: ='Balance Sheet'!J45 -> 2697379 | J20: ='Balance Sheet'!K45 -> 2697379 | ... AN20: ='Balance Sheet'!AO45 -> 0
A21: Capital Reserves | B21: ='[1]Balance Sheet'!C46 -> 0 | C21: ='Balance Sheet'!D46 -> 353000 | D21: ='Balance Sheet'!E46 -> 353000 | E21: ='Balance Sheet'!F46 -> 353000 | F21: ='Balance Sheet'!G46 -> 353 | G21: ='Balance Sheet'!H46 -> 353000 | H21: ='Balance Sheet'!I46 -> 353000 | I21: ='Balance Sheet'!J46 -> 0 | J21: ='Balance Sheet'!K46 -> 0 | ... AN21: ='Balance Sheet'!AO46 -> 0
A22: Supplementary Capital & reserves
A23: Proposed Dividends
A24: Benevolent Fund
A25: Investments | B25: =B26+B27+B29 -> 0 | C25: =C26+C27+C29 -> 830000 | D25: =D26+D27+D29 -> 830000 | E25: =E26+E27+E29 -> 830000 | F25: =F26+F27+F29 -> 830 | G25: =G26+G27+G29 -> 830000 | H25: =H26+H27+H29 -> 830000 | I25: =I26+I27+I29 -> 830000 | ... AN25: =AN26+AN27+AN29 -> 0
A26: Govt bills | B26: ='[1]Balance Sheet'!C9 -> 0 | C26: ='Balance Sheet'!D9 -> 0 | D26: ='Balance Sheet'!E9 -> 0 | E26: ='Balance Sheet'!F9 -> 0 | F26: ='Balance Sheet'!G9 -> 0 | G26: ='Balance Sheet'!H9 -> 0 | H26: ='Balance Sheet'!I9 -> 0 | I26: ='Balance Sheet'!J9 -> 0 | J26: ='Balance Sheet'!K9 -> 0 | ... AN26: ='Balance Sheet'!AO9 -> 0
A27: Investments in naccos | B27: ='[1]Balance Sheet'!C12 -> 0 | C27: ='Balance Sheet'!D12 -> 830000 | D27: ='Balance Sheet'!E12 -> 830000 | E27: ='Balance Sheet'!F12 -> 830000 | F27: ='Balance Sheet'!G12 -> 830 | G27: ='Balance Sheet'!H12 -> 830000 | H27: ='Balance Sheet'!I12 -> 830000 | I27: ='Balance Sheet'!J12 -> 830000 | J27: ='Balance Sheet'!K12 -> 830000 | ... AN27: ='Balance Sheet'!AO12 -> 0
A28: Equity Investments (at cost) | B28: ='[1]Balance Sheet'!C10 -> 0 | C28: ='Balance Sheet'!D10 -> 0 | D28: ='Balance Sheet'!E10 -> 0 | E28: ='Balance Sheet'!F10 -> 0 | F28: ='Balance Sheet'!G10 -> 0 | G28: ='Balance Sheet'!H10 -> 0 | H28: ='Balance Sheet'!I10 -> 0 | I28: ='Balance Sheet'!J10 -> 0 | J28: ='Balance Sheet'!K10 -> 0 | ... AN28: ='Balance Sheet'!AO10 -> 0
A29: Deposits in KUSCCO CFP | B29: ='[1]Balance Sheet'!C11 -> 0 | C29: ='Balance Sheet'!D11 -> 0 | D29: ='Balance Sheet'!E11 -> 0 | E29: ='Balance Sheet'!F11 -> 0 | F29: ='Balance Sheet'!G11 -> 0 | G29: ='Balance Sheet'!H11 -> 0 | H29: ='Balance Sheet'!I11 -> 0 | I29: ='Balance Sheet'!J11 -> 0 | J29: ='Balance Sheet'!K11 -> 0 | ... AN29: ='Balance Sheet'!AO11 -> 0
A30: Net Loans & Advances | B30: =B31-B32 -> 0 | C30: =C31-C32 -> 33360262 | D30: =D31-D32 -> 31943513 | E30: =E31-E32 -> 30943015 | F30: =F31-F32 -> 30037.26 | G30: =G31-G32 -> 31338995 | H30: =H31-H32 -> 30894868
A31: Gross Loans & advances | B31: ='[1]Balance Sheet'!C14 -> 0 | C31: ='Balance Sheet'!D14 -> 33720055 | D31: ='Balance Sheet'!E14 -> 32289005 | E31: ='Balance Sheet'!F14 -> 31278269 | F31: ='Balance Sheet'!G14 -> 30378.5 | G31: ='Balance Sheet'!H14 -> 31678269 | H31: ='Balance Sheet'!I14 -> 31212425 | I31: ='Balance Sheet'!J14 -> 28631247 | J31: ='Balance Sheet'!K14 -> 28075287 | ... AN31: ='Balance Sheet'!AO14 -> 0
A32: Allowance for loan losses | B32: ='[1]Balance Sheet'!C15 -> 0 | C32: ='Balance Sheet'!D15 -> 359792.98 | D32: ='Balance Sheet'!E15 -> 345492 | E32: ='Balance Sheet'!F15 -> 335254 | F32: ='Balance Sheet'!G15 -> 341.24 | G32: ='Balance Sheet'!H15 -> 339274 | H32: ='Balance Sheet'!I15 -> 317557 | I32: ='Balance Sheet'!J15 -> 306354.34 | J32: ='Balance Sheet'!K15 -> 300405.56 | ... AN32: ='Balance Sheet'!AO15 -> 0
A34: Non-Earning Assets | B34: ='[1]Balance Sheet'!C7+'[1]Balance Sheet'!C16+'[1]Balance Sheet'!C20 -> 0 | C34: ='Balance Sheet'!D7+'Balance Sheet'!D16+'Balance Sheet'!D20 -> 5311543 | D34: ='Balance Sheet'!E7+'Balance Sheet'!E16+'Balance Sheet'!E20 -> 5311543 | E34: ='Balance Sheet'!F7+'Balance Sheet'!F16+'Balance Sheet'!F20 -> 5311543 | F34: ='Balance Sheet'!G7+'Balance Sheet'!G16+'Balance Sheet'!G20 -> 5311.54 | G34: ='Balance Sheet'!H7+'Balance Sheet'!H16+'Balance Sheet'!H20 -> 5311543 | H34: ='Balance Sheet'!I7+'Balance Sheet'!I16+'Balance Sheet'!I20 -> 5311543 | I34: ='Balance Sheet'!J7+'Balance Sheet'!J16+'Balance Sheet'!J20 -> 5311543 | J34: ='Balance Sheet'!K7+'Balance Sheet'!K16+'Balance Sheet'!K20 -> 5311543 | ... AN34: ='Balance Sheet'!AO7+'Balance Sheet'!AO16+'Balance Sheet'!AO20 -> 0
A35: Property and Equipment | B35: ='[1]Balance Sheet'!C20 -> 0 | C35: ='Balance Sheet'!D20 -> 5311543 | D35: ='Balance Sheet'!E20 -> 5311543 | E35: ='Balance Sheet'!F20 -> 5311543 | F35: ='Balance Sheet'!G20 -> 5311.54 | G35: ='Balance Sheet'!H20 -> 5311543 | H35: ='Balance Sheet'!I20 -> 5311543 | I35: ='Balance Sheet'!J20 -> 5311543 | J35: ='Balance Sheet'!K20 -> 5311543 | ... AN35: ='Balance Sheet'!AO20 -> 0
A38: Turnover | B38: =B39+B41+B42 -> 0 | C38: =C39+C41+C42 -> 794544 | D38: =D39+D41+D42 -> 1218213 | E38: =E39+E41+E42 -> 1599578 | F38: =F39+F41+F42 -> 1828.14 | G38: =G39+G41+G42 -> 2095852 | H38: =H39+H41+H42 -> 2508852
A39: Loan Interest | B39: ='[1]Income Statement'!C6 -> 0 | C39: ='Income Statement'!D6 -> 495800 | D39: ='Income Statement'!E6 -> 805788 | E39: ='Income Statement'!F6 -> 1084733 | F39: ='Income Statement'!G6 -> 1294.73 | G39: ='Income Statement'!H6 -> 1391535 | H39: ='Income Statement'!I6 -> 1691535 | I39: ='Income Statement'!J6 -> 2171667 | J39: ='Income Statement'!K6 -> 2321667 | ... AN39: ='Income Statement'!AO6 -> 0
A40: Yield on loans | B40: ='[1]Income Statement'!C6/'[1]Income Statement'!C14 -> #DIV/0! | C40: ='Income Statement'!D6/'Income Statement'!D14 -> #DIV/0! | D40: ='Income Statement'!E6/'Income Statement'!E14 -> #DIV/0! | E40: ='Income Statement'!F6/'Income Statement'!F14 -> #DIV/0! | F40: ='Income Statement'!G6/'Income Statement'!G14 -> #DIV/0! | G40: ='Income Statement'!H6/'Income Statement'!H14 -> #DIV/0! | H40: ='Income Statement'!I6/'Income Statement'!I14 -> #DIV/0! | I40: ='Income Statement'!J6/'Income Statement'!J14 -> #DIV/0! | J40: ='Income Statement'!K6/'Income Statement'!K14 -> #DIV/0! | ... AN40: ='Income Statement'!AO6/'Income Statement'!AO14 -> #DIV/0!
A41: Income from investments | B41: ='[1]Income Statement'!C8 -> 0 | C41: ='Income Statement'!D8 -> 271523 | D41: ='Income Statement'!E8 -> 373161 | E41: ='Income Statement'!F8 -> 456617 | F41: ='Income Statement'!G8 -> 456.61 | G41: ='Income Statement'!H8 -> 626673 | H41: ='Income Statement'!I8 -> 736673 | I41: ='Income Statement'!J8 -> 776658 | J41: ='Income Statement'!K8 -> 900753 | ... AN41: ='Income Statement'!AO8 -> 0
A42: Fees & Commissions | B42: ='[1]Income Statement'!C7 -> 0 | C42: ='Income Statement'!D7 -> 27221 | D42: ='Income Statement'!E7 -> 39264 | E42: ='Income Statement'!F7 -> 58228 | F42: ='Income Statement'!G7 -> 76.8 | G42: ='Income Statement'!H7 -> 77644 | H42: ='Income Statement'!I7 -> 80644 | I42: ='Income Statement'!J7 -> 112407 | J42: ='Income Statement'!K7 -> 125107 | ... AN42: ='Income Statement'!AO7 -> 0
A44: Finanacial and Operating costs | B44: =B45+B46+B47+B48 -> 0 | C44: =C45+C46+C47+C48 -> 91385 | D44: =D45+D46+D47+D48 -> 362429 | E44: =E45+E46+E47+E48 -> 573368 | F44: =F45+F46+F47+F48 -> 698.14 | G44: =G45+G46+G47+G48 -> 859266 | H44: =H45+H46+H47+H48 -> 1141783
A45: Interest expense on deposits | B45: ='[1]Income Statement'!C14 -> 0 | C45: ='Income Statement'!D14 -> 0 | D45: ='Income Statement'!E14 -> 0 | E45: ='Income Statement'!F14 -> 0 | F45: ='Income Statement'!G14 -> 0 | G45: ='Income Statement'!H14 -> 0 | H45: ='Income Statement'!I14 -> 0 | I45: ='Income Statement'!J14 -> 0 | J45: ='Income Statement'!K14 -> 0 | ... AN45: ='Income Statement'!AO14 -> 0
A46: Dividend expense on share capital | B46: ='[1]Income Statement'!C16 -> 0 | C46: ='Income Statement'!D16 -> 0 | D46: ='Income Statement'!E16 -> 0 | E46: ='Income Statement'!F16 -> 0 | F46: ='Income Statement'!G16 -> 0 | G46: ='Income Statement'!H16 -> 0 | H46: ='Income Statement'!I16 -> 0 | I46: ='Income Statement'!J16 -> 0 | J46: ='Income Statement'!K16 -> 0 | ... AN46: ='Income Statement'!AO16 -> 0
...

Sheet FORM 4

Sheet CAEL
A1: NYALA SACCO CAELS 2020
C2: Regulatory Stds | E2: 44216 | F2: 44247 | G2: 44275 | H2: 44306 | I2: 44336 | J2: 44367 | K2: 44428 | L2: 44459 | M2: 44489 | N2: 44520 | O2: 44550 | P2: Aud-20 | Q2: 44197 | R2: 44229 | S2: 44258 | T2: 44290 | U2: 44321 | V2: 44353 | W2: 44384 | X2: 44416 | Y2: 44448 | Z2: 44479 | AA2: 44511 | AB2: 44542 | AC2: Audited 2021
A3: CAPITAL ADEQUACY | B3: Core Capital | C3: 10 M | D3: =[2]Financials!B14 -> 0 | E3: =Financials!C13 -> 18706275 | F3: =Financials!D13 -> 18953661 | G3: =Financials!E13 -> 19142267 | H3: =Financials!F13 -> 19244.49 | I3: =Financials!G13 -> 21996464 | J3: =Financials!H13 -> 22096464 | K3: =Financials!I13 -> 17336025 | L3: =Financials!J13 -> 17618604 | ... AG3: =Financials!AE13 -> 17988394
B4: CCA | C4: 0.1 | D4: =[2]Financials!B13/[2]Financials!B5 -> #DIV/0! | E4: =Financials!C13/Financials!C5 -> 0.38247588 | F4: =Financials!D13/Financials!D5 -> 0.40881406 | G4: =Financials!E13/Financials!E5 -> 0.41203428 | H4: =Financials!F13/Financials!F5 -> 0.43436472 | I4: =Financials!G13/Financials!G5 -> 0.48514198 | J4: =Financials!H13/Financials!H5 -> 0.47384473 | K4: =Financials!I13/Financials!I5 -> 0.42236551 | L4: =Financials!J13/Financials!J5 -> 0.42684696 | ... AC4: =Financials!AA13/Financials!AA5 -> 0.40272704
B5: CCD | C5: 0.08 | D5: =[2]Financials!B13/[2]Financials!B6 -> #DIV/0! | E5: =Financials!C13/Financials!C6 -> 0.76136715 | F5: =Financials!D13/Financials!D6 -> 0.78343938 | G5: =Financials!E13/Financials!E6 -> 0.79529965 | H5: =Financials!F13/Financials!F6 -> 0.86632337 | I5: =Financials!G13/Financials!G6 -> 0.95240045 | J5: =Financials!H13/Financials!H6 -> 1.0072924 | K5: =Financials!I13/Financials!I6 -> 0.78404455 | L5: =Financials!J13/Financials!J6 -> 0.78996279 | ... AC5: =Financials!AA13/Financials!AA6 -> 0.76801705
B6: ICA | C6: 0.08 | D6: =([2]Financials!B15-[2]Financials!B16)/[2]Financials!B5 -> #DIV/0! | E6: =(Financials!C15-Financials!C16)/Financials!C5 -> 0.13909776 | F6: =(Financials!D15-Financials!D16)/Financials!D5 -> 0.15207171 | G6: =(Financials!E15-Financials!E16)/Financials!E5 -> 0.15581915 | H6: =(Financials!F15-Financials!F16)/Financials!F5 -> 0.16569856 | I6: =(Financials!G15-Financials!G16)/Financials!G5 -> 0.22261087 | J6: =(Financials!H15-Financials!H16)/Financials!H5 -> 0.21858749 | K6: =(Financials!I15-Financials!I16)/Financials!I5 -> 0.13236169 | L6: =(Financials!J15-Financials!J16)/Financials!J5 -> 0.13846672 | ... AC6: =(Financials!AA15-Financials!AA16)/Financials!AA5 -> 0.19118135
A7: ASSET QUALITY | B7: A/LNPL30
B8: NPL30 | D8: =6.5% -> 0.065 | E8: =6.5% -> 0.065 | F8: =6.5% -> 0.065 | G8: =6.5% -> 0.065 | H8: =6.5% -> 0.065 | I8: =6.5% -> 0.065 | J8: =6.5% -> 0.065 | K8: =6.5% -> 0.065 | ... O8: =6.5% -> 0.065 | P8: ='[1]FORM 4'!F22 -> 0 | Q8: ='[1]FORM 4'!G22 -> 0 | R8: ='[1]FORM 4'!H22 -> 0 | S8: ='[1]FORM 4'!I22 -> 0 | T8: ='[1]FORM 4'!J22 -> 0 | U8: ='[1]FORM 4'!K22 -> 0 | V8: ='[1]FORM 4'!L22 -> 0 | W8: ='[1]FORM 4'!M22 -> 0 | ... AC8: ='[1]FORM 4'!S22 -> 0
B9: Non-earning Asset ratio | C9: Max 10% | D9: =('[1]Balance Sheet'!C7+'[1]Balance Sheet'!C20)/'[1]Balance Sheet'!C26 -> #DIV/0! | E9: =('Balance Sheet'!D7+'Balance Sheet'!D20)/'Balance Sheet'!D26 -> 0.1086019 | F9: =('Balance Sheet'!E7+'Balance Sheet'!E20)/'Balance Sheet'!E26 -> 0.11456538 | G9: =('Balance Sheet'!F7+'Balance Sheet'!F20)/'Balance Sheet'!F26 -> 0.11433013 | H9: =('Balance Sheet'!G7+'Balance Sheet'!G20)/'Balance Sheet'!G26 -> 0.11988604 | I9: =('Balance Sheet'!H7+'Balance Sheet'!H20)/'Balance Sheet'!H26 -> 0.11714849 | J9: =('Balance Sheet'!I7+'Balance Sheet'!I20)/'Balance Sheet'!I26 -> 0.11390269 | K9: =('Balance Sheet'!J7+'Balance Sheet'!J20)/'Balance Sheet'!J26 -> 0.12940755 | L9: =('Balance Sheet'!K7+'Balance Sheet'!K20)/'Balance Sheet'!K26 -> 0.12868307 | ... AC9: =('Balance Sheet'!AB7+'Balance Sheet'!AB20)/'Balance Sheet'!AB26 -> 0.17951761
B10: Land and Building ratio | C10: Max 5% | D10: =('[1]Balance Sheet'!C22+'[1]Balance Sheet'!C23)/'[1]Balance Sheet'!C26 -> #DIV/0! | E10: =('Balance Sheet'!D22+'Balance Sheet'!D23)/'Balance Sheet'!D26 -> 0.063825526 | F10: =('Balance Sheet'!E22+'Balance Sheet'!E23)/'Balance Sheet'!E26 -> 0.067330274 | G10: =('Balance Sheet'!F22+'Balance Sheet'!F23)/'Balance Sheet'!F26 -> 0.067192012 | H10: =('Balance Sheet'!G22+'Balance Sheet'!G23)/'Balance Sheet'!G26 -> 0.070457202 | I10: =('Balance Sheet'!H22+'Balance Sheet'!H23)/'Balance Sheet'!H26 -> 0.068848369 | J10: =('Balance Sheet'!I22+'Balance Sheet'!I23)/'Balance Sheet'!I26 -> 0.066940806 | K10: =('Balance Sheet'!J22+'Balance Sheet'!J23)/'Balance Sheet'!J26 -> 0.076053042 | L10: =('Balance Sheet'!K22+'Balance Sheet'!K23)/'Balance Sheet'!K26 -> 0.075627262 | ... AC10: =('Balance Sheet'!AB22+'Balance Sheet'!AB23)/'Balance Sheet'!AB26 -> 0.14166835
A11: EARNINGS | B11: Non-Government Investment to Deposit ratio | C11: Max 5% | D11: ='[1]Balance Sheet'!C12/'[1]Balance Sheet'!C30 -> #DIV/0! | E11: ='Balance Sheet'!D12/'Balance Sheet'!D30 -> 0.032460774 | F11: ='Balance Sheet'!E12/'Balance Sheet'!E30 -> 0.033209448 | G11: ='Balance Sheet'!F12/'Balance Sheet'!F30 -> 0.033108289 | H11: ='Balance Sheet'!G12/'Balance Sheet'!G30 -> 0.036065035 | I11: ='Balance Sheet'!H12/'Balance Sheet'!H30 -> 0.034734117 | J11: ='Balance Sheet'!I12/'Balance Sheet'!I30 -> 0.03650519 | K11: ='Balance Sheet'!J12/'Balance Sheet'!J30 -> 0.036546134 | L11: ='Balance Sheet'!K12/'Balance Sheet'!K30 -> 0.036113523 | ... AC11: ='Balance Sheet'!AB12/'Balance Sheet'!AB30 -> 0.00046435604
B12: Non-Government Investment to Core Capital ratio | C12: Max 40% | D12: ='[1]Balance Sheet'!C12/[1]Financials!B13 -> #DIV/0! | E12: ='Balance Sheet'!D12/Financials!C13 -> 0.044370138 | F12: ='Balance Sheet'!E12/Financials!D13 -> 0.043791012 | G12: ='Balance Sheet'!F12/Financials!E13 -> 0.043359546 | H12: ='Balance Sheet'!G12/Financials!F13 -> 0.043129228 | I12: ='Balance Sheet'!H12/Financials!G13 -> 0.037733338 | J12: ='Balance Sheet'!I12/Financials!H13 -> 0.037562571 | K12: ='Balance Sheet'!J12/Financials!I13 -> 0.047877181 | L12: ='Balance Sheet'!K12/Financials!J13 -> 0.047109295 | ... AC12: ='Balance Sheet'!AB12/Financials!AA13 -> 0.00062089674
B13: Gross loans/TA | D13: =[1]Financials!B31/[1]Financials!B5 -> #DIV/0! | E13: =Financials!C31/Financials!C5 -> 0.68945355 | F13: =Financials!D31/Financials!D5 -> 0.69644589 | G13: =Financials!E31/Financials!E5 -> 0.6732598 | H13: =Financials!F31/Financials!F5 -> 0.68566892 | I13: =Financials!G31/Financials!G5 -> 0.69867857 | J13: =Financials!H31/Financials!H5 -> 0.66933075 | K13: =Financials!I31/Financials!I5 -> 0.69755616 | L13: =Financials!J31/Financials!J5 -> 0.68018165 | ... AC13: =Financials!AA31/Financials!AA5 -> 0.67222404
B14: ROA | D14: ='[1]Income Statement'!C38/[1]Financials!B5 -> #DIV/0! | E14: ='Income Statement'!D38/Financials!C5 -> 0.0012796376 | F14: ='Income Statement'!E38/Financials!D5 -> 0.0066858061 | G14: ='Income Statement'!F38/Financials!E5 -> 0.010731791 | H14: ='Income Statement'!G38/Financials!F5 -> 0.013657854 | I14: ='Income Statement'!H38/Financials!G5 -> 0.016504228 | J14: ='Income Statement'!I38/Financials!H5 -> 0.021629455 | K14: ='Income Statement'!J38/Financials!I5 -> 0.02883622 | L14: ='Income Statement'!K38/Financials!J5 -> 0.030226614 | ... AC14: ='Income Statement'!AB38/Financials!AA5 -> 0.015066457
B15: Cost Income ratio | D15: ='[1]Income Statement'!C24/('[1]Income Statement'!C20-'[1]Income Statement'!C22) -> #DIV/0! | E15: ='Income Statement'!D24/('Income Statement'!D20-'Income Statement'!D22) -> 0.84583115 | F15: ='Income Statement'!E24/('Income Statement'!E20-'Income Statement'!E22) -> 0.62210779 | G15: ='Income Statement'!F24/('Income Statement'!F20-'Income Statement'!F22) -> 0.57722453 | H15: ='Income Statement'!G24/('Income Statement'!G20-'Income Statement'!G22) -> 0.56589019 | I15: ='Income Statement'!H24/('Income Statement'!H20-'Income Statement'!H22) -> 0.54527357 | J15: ='Income Statement'!I24/('Income Statement'!I20-'Income Statement'!I22) -> 0.50993153 | K15: ='Income Statement'!J24/('Income Statement'!J20-'Income Statement'!J22) -> 0.54347058 | L15: ='Income Statement'!K24/('Income Statement'!K20-'Income Statement'!K22) -> 0.56598555 | ... AC15: ='Income Statement'!AB24/('Income Statement'!AB20-'Income Statement'!AB22) -> 0.87291014
B16: Operating Expense ratio | D16: ='[1]Income Statement'!C24/'[1]Income Statement'!C4 -> #DIV/0! | E16: ='Income Statement'!D24/'Income Statement'!D4 -> 0.4321548 | F16: ='Income Statement'!E24/'Income Statement'!E4 -> 0.4188857 | G16: ='Income Statement'!F24/'Income Statement'!F4 -> 0.42556099 | H16: ='Income Statement'!G24/'Income Statement'!G4 -> 0.4314768 | I16: ='Income Statement'!H24/'Income Statement'!H4 -> 0.4281371 | J16: ='Income Statement'!I24/'Income Statement'!I4 -> 0.4183236 | K16: ='Income Statement'!J24/'Income Statement'!J4 -> 0.46034282 | L16: ='Income Statement'!K24/'Income Statement'!K4 -> 0.48603312 | ... AC16: ='Income Statement'!AB24/'Income Statement'!AB4 -> 0.8038127
A17: LIQUIDITY | B17: MIN LIQ ratio | C17: Min 15% | D17: ='[1]Balance Sheet'!C5/'[1]Balance Sheet'!C28 -> #DIV/0! | E17: ='Balance Sheet'!D5/'Balance Sheet'!D28 -> 1.535873 | F17: ='Balance Sheet'!E5/'Balance Sheet'!E28 -> 2.0349137 | G17: ='Balance Sheet'!F5/'Balance Sheet'!F28 -> 1.432331 | H17: ='Balance Sheet'!G5/'Balance Sheet'!G28 -> 1.703475 | I17: ='Balance Sheet'!H5/'Balance Sheet'!H28 -> 1.275175 | J17: ='Balance Sheet'!I5/'Balance Sheet'!I28 -> 1.6743775 | K17: ='Balance Sheet'!J5/'Balance Sheet'!J28 -> 1.6388817 | L17: ='Balance Sheet'!K5/'Balance Sheet'!K28 -> 1.0968647 | ... AC17: ='Balance Sheet'!AB5/'Balance Sheet'!AB28 -> 3.1660188
B18: Technical LIQ ratio | D18: ='[1]Balance Sheet'!C5/'[1]Balance Sheet'!C30 -> #DIV/0! | E18: ='Balance Sheet'!D5/'Balance Sheet'!D30 -> 0.06006702 | F18: ='Balance Sheet'!E5/'Balance Sheet'!E30 -> 0.06513577 | G18: ='Balance Sheet'!F5/'Balance Sheet'!F30 -> 0.057134974 | H18: ='Balance Sheet'!G5/'Balance Sheet'!G30 -> 0.059215312 | I18: ='Balance Sheet'!H5/'Balance Sheet'!H30 -> 0.042691159 | J18: ='Balance Sheet'!I5/'Balance Sheet'!I30 -> 0.058914186 | K18: ='Balance Sheet'!J5/'Balance Sheet'!J30 -> 0.043297438 | L18: ='Balance Sheet'!K5/'Balance Sheet'!K30 -> 0.032452917 | ... AC18: ='Balance Sheet'!AB5/'Balance Sheet'!AB30 -> 0.083012982
