Workbook
Name BALANCE1_LDA01: '[1]Financial Statements'!$E$112
Name BALANCE1_LDA12: '[1]Financial Statements'!$E$123
Name BALANCE2_LDA01: '[1]Financial Statements'!$F$112
Name BALANCE2_LDA12: '[1]Financial Statements'!$F$123
Name BALANCE3_LDA01: '[1]Financial Statements'!$G$112
Name BALANCE3_LDA12: '[1]Financial Statements'!$G$123
Name BALANCE4_LDA01: '[1]Financial Statements'!$H$112
Name BALANCE4_LDA12: '[1]Financial Statements'!$H$123
Name BALANCE5_LDA01: '[1]Financial Statements'!$I$112
Name BALANCE5_LDA12: '[1]Financial Statements'!$I$123
Name BALANCE6_LDA01: '[1]Financial Statements'!$J$112
Name BALANCE6_LDA12: '[1]Financial Statements'!$J$123
Name NotApplicable: CAELS!$B$25
Name PEARLS1_LA002: '[1]Financial Statements'!$E$280
Name PEARLS1_LE008: '[1]Financial Statements'!$E$275
Name PEARLS1_LE009: '[1]Financial Statements'!$E$276
Name PEARLS1_LR001: '[1]Financial Statements'!$E$282
Name PEARLS1_LR005: '[1]Financial Statements'!$E$286
Name PEARLS1_LR006: '[1]Financial Statements'!$E$287
Name PEARLS1_LR007: '[1]Financial Statements'!$E$288
Name PEARLS1_LR009: '[1]Financial Statements'!$E$290
Name PEARLS1_LS001: '[1]Financial Statements'!$E$298
Name PEARLS1_LS005: '[1]Financial Statements'!$E$302
Name PEARLS1_LS011: '[1]Financial Statements'!$E$308
Name PEARLS2_LA002: '[1]Financial Statements'!$F$280
Name PEARLS2_LE008: '[1]Financial Statements'!$F$275
Name PEARLS2_LE009: '[1]Financial Statements'!$F$276
Name PEARLS2_LR001: '[1]Financial Statements'!$F$282
Name PEARLS2_LR005: '[1]Financial Statements'!$F$286
Name PEARLS2_LR006: '[1]Financial Statements'!$F$287
Name PEARLS2_LR007: '[1]Financial Statements'!$F$288
Name PEARLS2_LR009: '[1]Financial Statements'!$F$290
Name PEARLS2_LS001: '[1]Financial Statements'!$F$298
Name PEARLS2_LS005: '[1]Financial Statements'!$F$302
Name PEARLS2_LS010: '[1]Financial Statements'!$F$307
Name PEARLS2_LS011: '[1]Financial Statements'!$F$308
Name PEARLS3_LA002: '[1]Financial Statements'!$G$280
Name PEARLS3_LE008: '[1]Financial Statements'!$G$275
Name PEARLS3_LE009: '[1]Financial Statements'!$G$276
Name PEARLS3_LR001: '[1]Financial Statements'!$G$282
Name PEARLS3_LR005: '[1]Financial Statements'!$G$286
Name PEARLS3_LR006: '[1]Financial Statements'!$G$287
Name PEARLS3_LR007: '[1]Financial Statements'!$G$288
Name PEARLS3_LR009: '[1]Financial Statements'!$G$290
Name PEARLS3_LS001: '[1]Financial Statements'!$G$298
Name PEARLS3_LS005: '[1]Financial Statements'!$G$302
Name PEARLS3_LS010: '[1]Financial Statements'!$G$307
Name PEARLS3_LS011: '[1]Financial Statements'!$G$308
Name PEARLS4_LA002: '[1]Financial Statements'!$H$280
Name PEARLS4_LE008: '[1]Financial Statements'!$H$275
Name PEARLS4_LE009: '[1]Financial Statements'!$H$276
Name PEARLS4_LR001: '[1]Financial Statements'!$H$282
Name PEARLS4_LR005: '[1]Financial Statements'!$H$286
Name PEARLS4_LR006: '[1]Financial Statements'!$H$287
Name PEARLS4_LR007: '[1]Financial Statements'!$H$288
Name PEARLS4_LR009: '[1]Financial Statements'!$H$290
Name PEARLS4_LS001: '[1]Financial Statements'!$H$298
Name PEARLS4_LS005: '[1]Financial Statements'!$H$302
Name PEARLS4_LS010: '[1]Financial Statements'!$H$307
Name PEARLS4_LS011: '[1]Financial Statements'!$H$308

Sheet Financials
B2: INVEST AND GROW FINANCIALS
B3: Year | C3: Audited 2017 | D3: Audited 2018 | E3: 43466 | F3: 43497 | G3: 43525 | H3: 43556 | I3: 43586 | J3: 43617 | K3: 43647 | L3: 43678 | M3: 43709 | N3: 43739 | O3: 43770 | P3: 43800 | Q3: AUDITED 2019 | R3: 43831 | S3: 43862 | T3: 43891 | U3: 43922 | V3: 43952 | W3: 43983 | X3: 44013 | Y3: 44044 | Z3: 44075 | AA3: 44105 | AB3: 44136 | AC3: 44166 | AD3: AUDITED 2020 | AE3: 44197 | AF3: 44228 | AG3: 44256 | AH3: 44287 | AI3: 44317 | AJ3: 44348 | AK3: 44378 | AL3: 44409 | AM3: 44440 | AN3: 44470 | AO3: 44501 | AP3: 44531 | AQ3: Audited 2021 | AR3: 44562 | AS3: 44593 | AT3: 44621 | AU3: 44652 | AV3: 44682 | AW3: 44713 | AX3: 44743 | AY3: 44774 | AZ3: 44805 | BA3: 44835 | BB3: 44866 | BC3: 44896 | BD3: Audited 2022
A4: 1 | B4: Membership | AQ4: 32447 | BD4: 33724
A5: 2 | B5: Total Assets | C5: =SFP!U27 -> 8106353615 | D5: =SFP!V27 -> 8715310718 | E5: =SFP!W27 -> 8960270626 | F5: =SFP!X27 -> 8958482401 | G5: =SFP!Y27 -> 9048315222 | H5: =SFP!Z27 -> 8549803719 | I5: =SFP!AA27 -> 8553114064 | J5: =SFP!AB27 -> 8706983540 | ... BD5: =SFP!BV27 -> 12958024000
A6: 3 | B6: Total Deposits | C6: =SFP!U32 -> 4484295483 | D6: =SFP!V32 -> 4962987100 | E6: =SFP!W32 -> 4979841046 | F6: =SFP!X32 -> 5035187526 | G6: =SFP!Y32 -> 5144194841 | H6: =SFP!Z32 -> 5165409133 | I6: =SFP!AA32 -> 5144139209 | J6: =SFP!AB32 -> 5173463255 | ... BD6: =SFP!BV32 -> 7044649000
A7: 3.1 | B7: Deposits-Members(BOSA) | C7: =SFP!U31 -> 4085665384 | D7: =SFP!V31 -> 4454006657 | E7: =SFP!W31 -> 4412161292 | F7: =SFP!X31 -> 4456600587 | G7: =SFP!Y31 -> 4489078500 | H7: =SFP!Z31 -> 4535050198 | I7: =SFP!AA31 -> 4556535041 | J7: =SFP!AB31 -> 4602930363 | ... BD7: =SFP!BV31 -> 5967690000
A8: 3.2 | B8: Deposits-Customers(FOSA) | C8: =SFP!U29 -> 272121207 | D8: =SFP!V29 -> 358299491 | E8: =SFP!W29 -> 420539519 | F8: =SFP!X29 -> 436535669 | G8: =SFP!Y29 -> 491265589 | H8: =SFP!Z29 -> 461506696 | I8: =SFP!AA29 -> 421211633 | J8: =SFP!AB29 -> 408643393 | ... BD8: =SFP!BV29 -> 913891000
A9: 4 | B9: External Borrowing | C9: =SFP!U39 -> 375000000 | D9: =SFP!V39 -> 275000000 | E9: =SFP!W39 -> 266666667 | F9: =SFP!X39 -> 200265525 | G9: =SFP!Y39 -> 95392958 | H9: =SFP!Z39 -> 91941390 | I9: =SFP!AA39 -> 0 | J9: =SFP!AB39 -> 0 | ... BD9: =SFP!BV39 -> 0
A10: 4.1 | B10: Short term Liabilities | C10: =(SFP!U34+SFP!U35+SFP!U38) -> 554554538 | D10: =(SFP!V34+SFP!V35+SFP!V38) -> 588706903 | E10: =(SFP!W34+SFP!W35+SFP!W38) -> 7.1367817e+08 | F10: =(SFP!X34+SFP!X35+SFP!X38) -> 7.7168466e+08 | G10: =(SFP!Y34+SFP!Y35+SFP!Y38) -> 830973117 | H10: =(SFP!Z34+SFP!Z35+SFP!Z38) -> 274944616 | I10: =(SFP!AA34+SFP!AA35+SFP!AA38) -> 3.3458643e+08 | J10: =(SFP!AB34+SFP!AB35+SFP!AB38) -> 396968427 | ... BD10: =(SFP!BV34+SFP!BV35+SFP!BV38) -> 814693000
A12: 5 | B12: Share capital and Reserves | C12: =SFP!U42 -> 382449866 | D12: =SFP!V42 -> 421922225 | E12: =SFP!W42 -> 671803630 | F12: =SFP!X42 -> 675549493 | G12: =SFP!Y42 -> 682351864 | H12: =SFP!Z42 -> 694996501 | I12: =SFP!AA42 -> 699865703 | J12: =SFP!AB42 -> 704056427 | ... BD12: =SFP!BV42 -> 1305241000
A13: 5.1 | B13: Core Capital | C13: =C16-C27 -> 2354877200 | D13: =D16-D27 -> 2112253899 | E13: =E16-E27 -> 2260453672 | F13: =F16-F27 -> 2296490354 | G13: =G16-G27 -> 2316883115 | H13: =H16-H27 -> 2350463995 | I13: =I16-I27 -> 2401164231 | J13: =J16-J27 -> 2419093562 | ... BD13: =BD16-BD27 -> 4484427000
A14: 5.2 | B14: Institutional Capital | C14: =(C13-C12) -> 1972427334 | D14: =(D13-D12) -> 1690331674 | E14: =(E13-E12) -> 1588650042 | F14: =(F13-F12) -> 1620940861 | G14: =(G13-G12) -> 1634531251 | H14: =(H13-H12) -> 1655467494 | I14: =(I13-I12) -> 1701298528 | J14: =(J13-J12) -> 1715037135 | ... BD14: =(BD13-BD12) -> 3179186000
A16: 5.3 | B16: Total Capital | C16: =SUM(C17:C20) -> 2354877200 | D16: =SUM(D17:D20) -> 2593223115 | E16: =SUM(E17:E20) -> 2716051604 | F16: =SUM(F17:F20) -> 2725964420 | G16: =SUM(G17:G20) -> 2746357181 | H16: =SUM(H17:H20) -> 2779938061 | I16: =SUM(I17:I20) -> 2830638297 | J16: =SUM(J17:J20) -> 2886567629 | ... BD16: =SUM(BD17:BD20) -> 4484427000
A17: 5.3.1 | B17: Members Share Capital | C17: =SFP!U42 -> 382449866 | D17: =SFP!V42 -> 421922225 | E17: =SFP!W42 -> 671803630 | F17: =SFP!X42 -> 675549493 | G17: =SFP!Y42 -> 682351864 | H17: =SFP!Z42 -> 694996501 | I17: =SFP!AA42 -> 699865703 | J17: =SFP!AB42 -> 704056427 | ... BD17: =SFP!BV42 -> 1305241000
A18: 5.3.3 | B18: Retained Earnings | C18: =SFP!U44 -> 1244145530 | D18: =SFP!V44 -> 1354697707 | E18: =SFP!W44 -> 1433879611 | F18: =SFP!X44 -> 1407719966 | G18: =SFP!Y44 -> 1421155356 | H18: =SFP!Z44 -> 1442012599 | I18: =SFP!AA44 -> 1487770133 | J18: =SFP!AB44 -> 1539468741 | ... BD18: =SFP!BV44 -> 1974689000
A19: 5.3.5 | B19: Statutory Reserves | C19: =SFP!U48 -> 450731709 | D19: =SFP!V48 -> 0 | E19: =SFP!W48 -> 494856977 | F19: =SFP!X48 -> 528921206 | G19: =SFP!Y48 -> 528921206 | H19: =SFP!Z48 -> 528921206 | I19: =SFP!AA48 -> 528921206 | J19: =SFP!AB48 -> 528921206 | ... BD19: =SFP!BV48 -> 984947000
A20: 5.3.6 | B20: Capital Reserve | C20: =SFP!U49 -> 277550095 | D20: =SFP!V49 -> 816603183 | E20: =SFP!W49 -> 115511386 | F20: =SFP!X49 -> 113773755 | G20: =SFP!Y49 -> 113928755 | H20: =SFP!Z49 -> 114007755 | I20: =SFP!AA49 -> 114081255 | J20: =SFP!AB49 -> 114121255 | ... BD20: =SFP!BV49 -> 219550000
A21: 5.3.7 | B21: Supplementary Capital & reserves
A22: a | B22: Proposed Dividends
A23: b
A25: 6 | B25: Investments | C25: =SUM(C26:C28) -> 438411690 | D25: =SUM(D26:D28) -> 480969216 | E25: =SUM(E26:E28) -> 504037257 | F25: =SUM(F26:F28) -> 478357566 | G25: =SUM(G26:G28) -> 478801741 | H25: =SUM(H26:H28) -> 479245916 | I25: =SUM(I26:I28) -> 483490091 | J25: =SUM(J26:J28) -> 521934267 | ... BD25: =SUM(BD26:BD28) -> 1541829000
A26: 6.1 | B26: Investments in Coop bank, CIC, Kuscco, Kerussu & Codic | C26: =SFP!U12 -> 0 | D26: =SFP!V12 -> 0 | E26: =SFP!W12 -> 0 | F26: =SFP!X12 -> 0 | G26: =SFP!Y12 -> 0 | H26: =SFP!Z12 -> 0 | I26: =SFP!AA12 -> 0 | J26: =SFP!AB12 -> 0 | ... BD26: =SFP!BV12 -> 625541000
A27: 6.2 | B27: Equity Investments (at cost) | C27: =SFP!U13 -> 0 | D27: =SFP!V13 -> 480969216 | E27: =SFP!W13 -> 455597932 | F27: =SFP!X13 -> 429474066 | G27: =SFP!Y13 -> 429474066 | H27: =SFP!Z13 -> 429474066 | I27: =SFP!AA13 -> 429474066 | J27: =SFP!AB13 -> 467474067 | ... BD27: =SFP!BV13 -> 0
A28: 6.3 | B28: Deposits in KUSCCO CFP | C28: =SFP!U11 -> 438411690 | D28: =SFP!V11 -> 0 | E28: =SFP!W11 -> 48439325 | F28: =SFP!X11 -> 48883500 | G28: =SFP!Y11 -> 49327675 | H28: =SFP!Z11 -> 49771850 | I28: =SFP!AA11 -> 54016025 | J28: =SFP!AB11 -> 54460200 | ... BD28: =SFP!BV11 -> 916288000
A30: 7 | B30: Net Loans & advances | C30: =C31-C32 -> 6527159792 | D30: =D31-D32 -> 6735591075 | E30: =E31-E32 -> 6723378302 | F30: =F31-F32 -> 6701926883 | G30: =G31-G32 -> 6625163637 | H30: =H31-H32 -> 6469028018 | I30: =I31-I32 -> 6388246711 | J30: =J31-J32 -> 6355553649 | ... BD30: =BD31-BD32 -> 9122098000
A31: 7.1 | B31: Gross Loans & advances | C31: =SFP!U15 -> 6677545533 | D31: =SFP!V15 -> 7151001513 | E31: =SFP!W15 -> 7136929610 | F31: =SFP!X15 -> 7117337321 | G31: =SFP!Y15 -> 7040574075 | H31: =SFP!Z15 -> 6884438456 | I31: =SFP!AA15 -> 6803657149 | J31: =SFP!AB15 -> 6770964087 | ... BD31: =SFP!BV15 -> 9515329000
A32: 7.3 | B32: Allowance for loan losses | C32: =SFP!U16 -> 150385741 | D32: =SFP!V16 -> 415410438 | E32: =SFP!W16 -> 413551308 | F32: =SFP!X16 -> 415410438 | G32: =SFP!Y16 -> 415410438 | H32: =SFP!Z16 -> 415410438 | I32: =SFP!AA16 -> 415410438 | J32: =SFP!AB16 -> 415410438 | ... BD32: =SFP!BV16 -> 393231000
A33: 7.4 | B33: Non Performing Loans (A/L NPL30
A34: 7.5666667 | B34: Non Performing Loans NPL30
A35: 7.7166667 | B35: Required loan loss provision
A36: 7.8666667 | B36: Cash and Cash equipments | C36: =SFP!U4 -> 429143643 | D36: =SFP!V4 -> 750100001 | E36: =SFP!W4 -> 812532694 | F36: =SFP!X4 -> 938755546 | G36: =SFP!Y4 -> 1105837097 | H36: =SFP!Z4 -> 799400736 | I36: =SFP!AA4 -> 883354226 | J36: =SFP!AB4 -> 1024877296 | ... BD36: =SFP!BV4 -> 1471320000
A38: 8 | B38: Non-Earning Assets | C38: =SFP!U7+SFP!U17+SFP!U21-SFP!U22 -> 365513490 | D38: =SFP!V7+SFP!V17+SFP!V21-SFP!V22 -> 363650426 | E38: =SFP!W7+SFP!W17+SFP!W21-SFP!W22 -> 535322373 | F38: =SFP!X7+SFP!X17+SFP!X21-SFP!X22 -> 454442406 | G38: =SFP!Y7+SFP!Y17+SFP!Y21-SFP!Y22 -> 453512747 | H38: =SFP!Z7+SFP!Z17+SFP!Z21-SFP!Z22 -> 417129049 | I38: =SFP!AA7+SFP!AA17+SFP!AA21-SFP!AA22 -> 413023036 | J38: =SFP!AB7+SFP!AB17+SFP!AB21-SFP!AB22 -> 419618328 | ... W38: =SFP!AO7+SFP!AO17+SFP!AO21-SFP!AO22 -> 314284713 | X38: =SFP!AQ7+SFP!AP17+SFP!AP21-SFP!AP22 -> 444754612 | Y38: =SFP!AR7+SFP!AQ17+SFP!AQ21-SFP!AQ22 -> 500888407 | Z38: =SFP!AS7+SFP!AR17+SFP!AR21-SFP!AR22 -> 494777306 | AA38: =SFP!AT7+SFP!AS17+SFP!AS21-SFP!AS22 -> 524507513 | AB38: =SFP!AU7+SFP!AT17+SFP!AT21-SFP!AT22 -> 481977030 | AC38: =SFP!#REF!+SFP!AU17+SFP!AU21-SFP!AU22 -> #REF! | AD38: =SFP!AV7+SFP!AV17+SFP!AV21-SFP!AV22 -> 570700 | AE38: =SFP!AW7+SFP!AW17+SFP!AW21-SFP!AW22 -> 625922229 | AF38: =SFP!AX7+SFP!AX17+SFP!AX21-SFP!AX22 -> 520573369 | AG38: =SFP!AY7+SFP!AY17+SFP!AY21-SFP!AY22 -> 523234323 | AH38: =SFP!AZ7+SFP!AZ17+SFP!AZ21-SFP!AZ22 -> 479381954 | AI38: =SFP!BA7+SFP!BA17+SFP!BA21-SFP!BA22 -> 477346147 | AJ38: =SFP!BB7+SFP!BB17+SFP!BB21-SFP!BB22 -> 385026122 | AK38: =SFP!BC7+SFP!BC17+SFP!BC21-SFP!BC22 -> 335073363 | ... BD38: =SFP!BV7+SFP!BV17+SFP!BV21-SFP!BV22 -> 514977000
A39: 8.1 | B39: Property and Equipment | C39: =SFP!U23 -> 36326430 | D39: =SFP!V23 -> 32449324 | E39: =SFP!W23 -> 31896736 | F39: =SFP!X23 -> 32507453 | G39: =SFP!Y23 -> 32000246 | H39: =SFP!Z23 -> 31493038 | I39: =SFP!AA23 -> 32562424 | J39: =SFP!AB23 -> 32085699 | ... BD39: =SFP!BV23 -> 133616000
A40: 8.2 | B40: Land and Building
A42: 9 | B42: Turnover | C42: =SUM(C43:C45) -> 1341798042 | D42: =SUM(D43:D45) -> 1367622498 | E42: =SUM(E43:E45) -> 123283534 | F42: =SUM(F43:F45) -> 237196091 | G42: =SUM(G43:G45) -> 357021027 | H42: =SUM(H43:H45) -> 473117791 | I42: =SUM(I43:I45) -> 604661545 | J42: =SUM(J43:J45) -> 741828590 | ... BD42: =SUM(BD43:BD45) -> 1763187000
A43: 9.1 | B43: Loan Interest | C43: =SCI!T5 -> 1239848635 | D43: =SCI!U5 -> 1246870335 | E43: =SCI!V5 -> 116892118 | F43: =SCI!W5 -> 226319507 | G43: =SCI!X5 -> 338628579 | H43: =SCI!Y5 -> 441339573 | I43: =SCI!Z5 -> 552042078 | J43: =SCI!AA5 -> 659271924 | ... BD43: =SCI!BU5 -> 1424256000
B44: Income from investments | C44: =SCI!T7 -> 101949407 | D44: =SCI!U7 -> 120752163 | E44: =SCI!V7 -> 422941 | F44: =SCI!W7 -> 4908109 | G44: =SCI!X7 -> 16349047 | H44: =SCI!Y7 -> 29734817 | I44: =SCI!Z7 -> 50576066 | J44: =SCI!AA7 -> 79685544 | ... BD44: =SCI!BU7 -> 338931000
A45: 9.2 | B45: Fees & Commissions | C45: =SCI!T6 -> 0 | D45: =SCI!U6 -> 0 | E45: =SCI!V6 -> 5968475 | F45: =SCI!W6 -> 5968475 | G45: =SCI!X6 -> 2043401 | H45: =SCI!Y6 -> 2043401 | I45: =SCI!Z6 -> 2043401 | J45: =SCI!AA6 -> 2871122 | ... BD45: =SCI!BU6 -> 0
B46: Average yield on loans | C46: =SCI!T5/SFP!U15 -> 0.18567431 | D46: =SCI!U5/SFP!V15 -> 0.17436304 | E46: =SCI!V5/SFP!W15 -> 0.016378488 | F46: =SCI!W5/SFP!X15 -> 0.031798339 | G46: =SCI!X5/SFP!Y15 -> 0.048096728 | H46: =SCI!Y5/SFP!Z15 -> 0.064106837 | I46: =SCI!Z5/SFP!AA15 -> 0.081139021 | J46: =SCI!AA5/SFP!AB15 -> 0.097367512 | ... BD46: =SCI!BU5/SFP!BV15 -> 0.14968016
A48: 10 | B48: Total Expenses (FinCosts + OpEx) | C48: =SUM(C49:C55) -> 814507555 | D48: =SUM(D49:D55) -> 863458557 | E48: =SUM(E49:E55) -> 83314316 | F48: =SUM(F49:F55) -> 1.6574666e+08 | G48: =SUM(G49:G55) -> 261177070 | H48: =SUM(H49:H55) -> 3.5222661e+08 | I48: =SUM(I49:I55) -> 4.3357931e+08 | J48: =SUM(J49:J55) -> 5.1426315e+08 | ... BD48: =SUM(BD49:BD55) -> 1175350000
...

Sheet CAELS
B1: INVEST & GROW (IG)CAELS
E2: Audited 2017 | F2: Audited 2018 | G2: 43466 | H2: 43497 | I2: 43525 | J2: 43556 | K2: 43586 | L2: 43617 | M2: 43647 | N2: 43678 | O2: 43709 | P2: 43739 | Q2: 43770 | R2: 43800 | S2: Audited 2019 | T2: 43831 | U2: 43862 | V2: 43891 | W2: 43922 | X2: 43952 | Y2: 43983 | Z2: 44013 | AA2: 44044 | AB2: 44075 | AC2: 44105 | AD2: 44136 | AE2: 44166 | AF2: Audited 2020 | AG2: 44197 | AH2: 44228 | AI2: 44256 | AJ2: 44287 | AK2: 44317 | AL2: 44348 | AM2: 44378 | AN2: 44409 | AO2: 44440 | AP2: 44470 | AQ2: 44501 | AR2: 44531 | AS2: Audited 2021 | AT2: 44562 | AU2: 44593 | AV2: 44621 | AW2: 44652 | AX2: 44682 | AY2: 44713 | AZ2: 44743 | BA2: 44774 | BB2: 44805 | BC2: 44835 | BD2: 44866 | BE2: 44896 | BF2: Aud-22
A4: INDICATORS | B4: Capital adequacy | C4: CORE CAPITAL | D4: 10M | E4: =Financials!C13/1000000 -> 2354.8772 | F4: =Financials!D13/1000000 -> 2112.2539 | G4: =Financials!E13/1000000 -> 2260.4537 | H4: =Financials!F13/1000000 -> 2296.4904 | I4: =Financials!G13/1000000 -> 2316.8831 | J4: =Financials!H13/1000000 -> 2350.464 | K4: =Financials!I13/1000000 -> 2401.1642 | L4: =Financials!J13/1000000 -> 2419.0936 | ... BF4: =Financials!BD13/1000000 -> 4484.427
C5: CCA | D5: Min 10% | E5: =Financials!C13/Financials!C5 -> 0.29049771 | F5: =Financials!D13/Financials!D5 -> 0.24236128 | G5: =Financials!E13/Financials!E5 -> 0.25227516 | H5: =Financials!F13/Financials!F5 -> 0.25634815 | I5: =Financials!G13/Financials!G5 -> 0.25605685 | J5: =Financials!H13/Financials!H5 -> 0.27491438 | K5: =Financials!I13/Financials!I5 -> 0.28073567 | L5: =Financials!J13/Financials!J5 -> 0.27783371 | ... BF5: =Financials!BD13/Financials!BD5 -> 0.34607337
C6: ICA | D6: Min 8% | E6: =Financials!C14/Financials!C5 -> 0.24331869 | F6: =Financials!D14/Financials!D5 -> 0.19394967 | G6: =Financials!E14/Financials!E5 -> 0.17729934 | H6: =Financials!F14/Financials!F5 -> 0.18093922 | I6: =Financials!G14/Financials!G5 -> 0.18064482 | J6: =Financials!H14/Financials!H5 -> 0.19362637 | K6: =Financials!I14/Financials!I5 -> 0.19890984 | L6: =Financials!J14/Financials!J5 -> 0.19697259 | ... BF6: =Financials!BD14/Financials!BD5 -> 0.24534497
C7: CCD | D7: Min 8% | E7: =Financials!C13/Financials!C6 -> 0.52513872 | F7: =Financials!D13/Financials!D6 -> 0.42560133 | G7: =Financials!E13/Financials!E6 -> 0.45392085 | H7: =Financials!F13/Financials!F6 -> 0.45608835 | I7: =Financials!G13/Financials!G6 -> 0.4503879 | J7: =Financials!H13/Financials!H6 -> 0.45503927 | K7: =Financials!I13/Financials!I6 -> 0.46677668 | L7: =Financials!J13/Financials!J6 -> 0.46759655 | ... BF7: =Financials!BD13/Financials!BD6 -> 0.6365721
C8: Adjusted CCA | E8: =(Financials!C13-Financials!C33)/Financials!C5 -> 0.29049771 | F8: =(Financials!D13-Financials!D33)/Financials!D5 -> 0.24236128 | G8: =(Financials!E13-Financials!E33)/Financials!E5 -> 0.25227516 | H8: =(Financials!F13-Financials!F33)/Financials!F5 -> 0.25634815 | I8: =(Financials!G13-Financials!G33)/Financials!G5 -> 0.25605685 | J8: =(Financials!H13-Financials!H33)/Financials!H5 -> 0.27491438 | K8: =(Financials!I13-Financials!I33)/Financials!I5 -> 0.28073567 | L8: =(Financials!J13-Financials!J33)/Financials!J5 -> 0.27783371 | ... BF8: =(Financials!BD13-Financials!BD33)/Financials!BD5 -> 0.34607337
B10: ASSET QUALITY | C10: NPL30 | I10: ='Form 4'!D28 -> 0.06980849 | L10: ='Form 4'!M28 -> 0.065020366 | O10: ='Form 4'!D54 -> 0.076137488 | R10: ='Form 4'!M54 -> 0.072045972 | BE10: 0.05 | BF10: 0.05
C11: A/L NPL30
B13: EARNINGS | C13: ROA | E13: =SCI!T37/SFP!U27 -> 0.060280468 | F13: =SCI!U37/SFP!V27 -> 0.038168181 | G13: =SCI!V37/SFP!W27 -> 0.0029391629 | H13: =SCI!W37/SFP!X27 -> 0.0059186653 | I13: =SCI!X37/SFP!Y27 -> 0.007344754 | J13: =SCI!Y37/SFP!Z27 -> 0.010212503 | K13: =SCI!Z37/SFP!AA27 -> 0.01555836 | L13: =SCI!AA37/SFP!AB27 -> 0.021221016 | ... BF13: =SCI!BU37/SFP!BV27 -> 0.053190286
C14: C/I ratio | E14: =SCI!T23/SCI!T19 -> 0.31813166 | F14: =SCI!U29/SCI!U23 -> 1.3202692 | G14: =SCI!V29/SCI!V23 -> 1.3109569 | H14: =SCI!W29/SCI!W23 -> 1.4144466 | I14: =SCI!X29/SCI!X23 -> 0.95236554 | J14: =SCI!Y29/SCI!Y23 -> 0.89366754 | K14: =SCI!Z29/SCI!Z23 -> 1.1517 | L14: =SCI!AA29/SCI!AA23 -> 1.3999237 | M14: =SCI!AB29/SCI!AB23 -> 1.2170551 | ... BF14: =SCI!BU29/SCI!BU23 -> 1.6268845
C15: OE ratio | E15: =SCI!T23/SFP!U27 -> 0.030348048 | F15: =SCI!U23/SFP!V27 -> 0.030639167 | G15: =SCI!V23/SFP!W27 -> 0.002241998 | H15: =SCI!W23/SFP!X27 -> 0.0041844389 | I15: =SCI!X23/SFP!Y27 -> 0.0077121165 | J15: =SCI!Y23/SFP!Z27 -> 0.011427631 | K15: =SCI!Z23/SFP!AA27 -> 0.013509039 | L15: =SCI!AA23/SFP!AB27 -> 0.015158694 | ... BF15: =SCI!BU23/SFP!BV27 -> 0.032694568
B17: LIQUIDITY | C17: W NLIQ ratio | D17: Min 15% | E17: =(SFP!U4+SFP!U11)/(SFP!U29+SFP!U30+SFP!U33-SFP!U39) -> 0.88648678 | F17: =(SFP!V4+SFP!V11)/(SFP!V29+SFP!V30+SFP!V33-SFP!V39) -> 0.68307476 | G17: =(SFP!W4+SFP!W11)/(SFP!W29+SFP!W30+SFP!W33-SFP!W39) -> 0.67192156 | H17: =(SFP!X4+SFP!X11)/(SFP!X29+SFP!X30+SFP!X33-SFP!X39) -> 0.73143732 | I17: =(SFP!Y4+SFP!Y11)/(SFP!Y29+SFP!Y30+SFP!Y33-SFP!Y39) -> 0.77731846 | J17: =(SFP!Z4+SFP!Z11)/(SFP!Z29+SFP!Z30+SFP!Z33-SFP!Z39) -> 0.93799763 | K17: =(SFP!AA4+SFP!AA11)/(SFP!AA29+SFP!AA30+SFP!AA33-SFP!AA39) -> 1.0164604 | L17: =(SFP!AB4+SFP!AB11)/(SFP!AB29+SFP!AB30+SFP!AB33-SFP!AB39) -> 1.1155928 | ... BF17: =(SFP!BV4+SFP!BV11)/(SFP!BV29+SFP!BV30+SFP!BV33-SFP!BV39) -> 1.2621814
C18: T NLIQ ratio | E18: =(SFP!U4+SFP!U11)/(SFP!U32+SFP!U33-SFP!U39) -> 0.17130771 | F18: =(SFP!V4+SFP!V11)/(SFP!V32+SFP!V33-SFP!V39) -> 0.13510132 | G18: =(SFP!W4+SFP!W11)/(SFP!W32+SFP!W33-SFP!W39) -> 0.15121966 | H18: =(SFP!X4+SFP!X11)/(SFP!X32+SFP!X33-SFP!X39) -> 0.17008107 | I18: =(SFP!Y4+SFP!Y11)/(SFP!Y32+SFP!Y33-SFP!Y39) -> 0.19332758 | J18: =(SFP!Z4+SFP!Z11)/(SFP!Z32+SFP!Z33-SFP!Z39) -> 0.15608775 | K18: =(SFP!AA4+SFP!AA11)/(SFP!AA32+SFP!AA33-SFP!AA39) -> 0.17109275 | L18: =(SFP!AB4+SFP!AB11)/(SFP!AB32+SFP!AB33-SFP!AB39) -> 0.19376191 | ... BF18: =(SFP!BV4+SFP!BV11)/(SFP!BV32+SFP!BV33-SFP!BV39) -> 0.30379235
C19: EB ratio | D19: Max 25% | E19: =Financials!C9/Financials!C5 -> 0.04626001 | F19: =Financials!D9/Financials!D5 -> 0.031553666 | G19: =Financials!E9/Financials!E5 -> 0.029761006 | H19: =Financials!F9/Financials!F5 -> 0.022354849 | I19: =Financials!G9/Financials!G5 -> 0.010542621 | J19: =Financials!H9/Financials!H5 -> 0.010753626 | K19: =Financials!I9/Financials!I5 -> 0 | L19: =Financials!J9/Financials!J5 -> 0 | ... BF19: =Financials!BD9/Financials!BD5 -> 0
C20: LIQ to TA ratio | E20: =(SFP!U4+SFP!U11)/SFP!U27 -> 0.10702165 | F20: =(SFP!V4+SFP!V11)/SFP!V27 -> 0.086066926 | G20: =(SFP!W4+SFP!W11)/SFP!W27 -> 0.096087725 | H20: =(SFP!X4+SFP!X11)/SFP!X27 -> 0.11024625 | I20: =(SFP!Y4+SFP!Y11)/SFP!Y27 -> 0.12766628 | J20: =(SFP!Z4+SFP!Z11)/SFP!Z27 -> 0.099320711 | K20: =(SFP!AA4+SFP!AA11)/SFP!AA27 -> 0.10959403 | L20: =(SFP!AB4+SFP!AB11)/SFP!AB27 -> 0.12396228 | ... BF20: =(SFP!BV4+SFP!BV11)/SFP!BV27 -> 0.18425711
B22: STRUCTURE OF ASSETS | C22: LB ratio | D22: Max 5% | E22: =Financials!C40/Financials!C5 -> 0 | F22: =Financials!D40/Financials!D5 -> 0 | G22: =Financials!E40/Financials!E5 -> 0 | H22: =Financials!F40/Financials!F5 -> 0 | I22: =Financials!G40/Financials!G5 -> 0 | J22: =Financials!H40/Financials!H5 -> 0 | K22: =Financials!I40/Financials!I5 -> 0 | L22: =Financials!J40/Financials!J5 -> 0 | ... BF22: =Financials!BD40/Financials!BD5 -> 0
C23: FICC | D23: Max 40% | E23: =Financials!C25/Financials!C13 -> 0.18617178 | F23: =Financials!D25/Financials!D13 -> 0.22770426 | G23: =Financials!E25/Financials!E13 -> 0.22298057 | H23: =Financials!F25/Financials!F13 -> 0.2082994 | I23: =Financials!G25/Financials!G13 -> 0.2066577 | J23: =Financials!H25/Financials!H13 -> 0.20389417 | K23: =Financials!I25/Financials!I13 -> 0.20135653 | L23: =Financials!J25/Financials!J13 -> 0.21575613 | ... BF23: =Financials!BD25/Financials!BD13 -> 0.34381851
C24: FITD | D24: Max 5% | E24: =Financials!C25/Financials!C6 -> 0.097766013 | F24: =Financials!D25/Financials!D6 -> 0.096911236 | G24: =Financials!E25/Financials!E6 -> 0.10121553 | H24: =Financials!F25/Financials!F6 -> 0.09500293 | I24: =Financials!G25/Financials!G6 -> 0.093076129 | J24: =Financials!H25/Financials!H6 -> 0.092779856 | K24: =Financials!I25/Financials!I6 -> 0.093988532 | L24: =Financials!J25/Financials!J6 -> 0.10088682 | ... BF24: =Financials!BD25/Financials!BD6 -> 0.21886527
C25: NEA | D25: Max 10% | E25: =Financials!C38/Financials!C5 -> 0.045089754 | F25: =Financials!D38/Financials!D5 -> 0.041725469 | G25: =Financials!E38/Financials!E5 -> 0.059743996 | H25: =Financials!F38/Financials!F5 -> 0.050727611 | I25: =Financials!G38/Financials!G5 -> 0.050121236 | J25: =Financials!H38/Financials!H5 -> 0.048788143 | K25: =Financials!I38/Financials!I5 -> 0.0482892 | L25: =Financials!J38/Financials!J5 -> 0.048193307 | ... BF25: =Financials!BD38/Financials!BD5 -> 0.039741939
C26: LOANS/TA | E26: =SFP!U14/SFP!U27 -> 0.80519061 | F26: =SFP!V14/SFP!V27 -> 0.77284578 | G26: =SFP!W14/SFP!W27 -> 0.75035438 | H26: =SFP!X14/SFP!X27 -> 0.74810962 | I26: =SFP!Y14/SFP!Y27 -> 0.73219859 | J26: =SFP!Z14/SFP!Z27 -> 0.75662883 | K26: =SFP!AA14/SFP!AA27 -> 0.74689133 | L26: =SFP!AB14/SFP!AB27 -> 0.72993748 | ... BF26: =SFP!BV14/SFP!BV27 -> 0.70397292
A28: RATING PARAMETERS | B28: CAPITAL | C28: CORE CAPITAL | D28: 10M | E28: =IF(E4>10,1,5) -> 1 | F28: =IF(F4>10,1,5) -> 1 | G28: =IF(G4>10,1,5) -> 1 | H28: =IF(H4>10,1,5) -> 1 | I28: =IF(I4>10,1,5) -> 1 | J28: =IF(J4>10,1,5) -> 1 | K28: =IF(K4>10,1,5) -> 1 | L28: =IF(L4>10,1,5) -> 1 | ... BF28: =IF(BF4>10,1,5) -> 1
C29: CCA | D29: Min 10% | E29: =IF(E5>20%,1,IF(E5>15,2,IF(E5>12,3,IF(E5>10,4,5)))) -> 1 | F29: =IF(F5>20%,1,IF(F5>15,2,IF(F5>12,3,IF(F5>10,4,5)))) -> 1 | G29: =IF(G5>20%,1,IF(G5>15,2,IF(G5>12,3,IF(G5>10,4,5)))) -> 1 | H29: =IF(H5>20%,1,IF(H5>15,2,IF(H5>12,3,IF(H5>10,4,5)))) -> 1 | I29: =IF(I5>20%,1,IF(I5>15,2,IF(I5>12,3,IF(I5>10,4,5)))) -> 1 | J29: =IF(J5>20%,1,IF(J5>15,2,IF(J5>12,3,IF(J5>10,4,5)))) -> 1 | K29: =IF(K5>20%,1,IF(K5>15,2,IF(K5>12,3,IF(K5>10,4,5)))) -> 1 | L29: =IF(L5>20%,1,IF(L5>15,2,IF(L5>12,3,IF(L5>10,4,5)))) -> 1 | ... BF29: =IF(BF5>20%,1,IF(BF5>15,2,IF(BF5>12,3,IF(BF5>10,4,5)))) -> 1
C30: ICA | D30: Min 8% | E30: =IF(E6>15,1,IF(E6>12,2,IF(E6>10,3,IF(E6>8,4,5)))) -> 5 | F30: =IF(F6>15,1,IF(F6>12,2,IF(F6>10,3,IF(F6>8,4,5)))) -> 5 | G30: =IF(G6>15,1,IF(G6>12,2,IF(G6>10,3,IF(G6>8,4,5)))) -> 5 | H30: =IF(H6>15,1,IF(H6>12,2,IF(H6>10,3,IF(H6>8,4,5)))) -> 5 | I30: =IF(I6>15,1,IF(I6>12,2,IF(I6>10,3,IF(I6>8,4,5)))) -> 5 | J30: =IF(J6>15,1,IF(J6>12,2,IF(J6>10,3,IF(J6>8,4,5)))) -> 5 | K30: =IF(K6>15,1,IF(K6>12,2,IF(K6>10,3,IF(K6>8,4,5)))) -> 5 | L30: =IF(L6>15,1,IF(L6>12,2,IF(L6>10,3,IF(L6>8,4,5)))) -> 5 | ... BF30: =IF(BF6>15,1,IF(BF6>12,2,IF(BF6>10,3,IF(BF6>8,4,5)))) -> 5
C31: CCD | D31: Min 8% | E31: =IF(E7>20%,1,IF(E7>12%,2,IF(E7>10%,3,IF(E7>8%,4,5)))) -> 1 | F31: =IF(F7>20%,1,IF(F7>12%,2,IF(F7>10%,3,IF(F7>8%,4,5)))) -> 1 | G31: =IF(G7>20%,1,IF(G7>12%,2,IF(G7>10%,3,IF(G7>8%,4,5)))) -> 1 | H31: =IF(H7>20%,1,IF(H7>12%,2,IF(H7>10%,3,IF(H7>8%,4,5)))) -> 1 | I31: =IF(I7>20%,1,IF(I7>12%,2,IF(I7>10%,3,IF(I7>8%,4,5)))) -> 1 | J31: =IF(J7>20%,1,IF(J7>12%,2,IF(J7>10%,3,IF(J7>8%,4,5)))) -> 1 | K31: =IF(K7>20%,1,IF(K7>12%,2,IF(K7>10%,3,IF(K7>8%,4,5)))) -> 1 | L31: =IF(L7>20%,1,IF(L7>12%,2,IF(L7>10%,3,IF(L7>8%,4,5)))) -> 1 | ... BF31: =IF(BF7>20%,1,IF(BF7>12%,2,IF(BF7>10%,3,IF(BF7>8%,4,5)))) -> 1
C32: Adjusted CCA | E32: =IF(E8>20%,1,IF(E8>15%,2,IF(E8>12%,3,IF(E8>10%,4,5)))) -> 1 | F32: =IF(F8>20%,1,IF(F8>15%,2,IF(F8>12%,3,IF(F8>10%,4,5)))) -> 1 | G32: =IF(G8>20%,1,IF(G8>15%,2,IF(G8>12%,3,IF(G8>10%,4,5)))) -> 1 | H32: =IF(H8>20%,1,IF(H8>15%,2,IF(H8>12%,3,IF(H8>10%,4,5)))) -> 1 | I32: =IF(I8>20%,1,IF(I8>15%,2,IF(I8>12%,3,IF(I8>10%,4,5)))) -> 1 | J32: =IF(J8>20%,1,IF(J8>15%,2,IF(J8>12%,3,IF(J8>10%,4,5)))) -> 1 | K32: =IF(K8>20%,1,IF(K8>15%,2,IF(K8>12%,3,IF(K8>10%,4,5)))) -> 1 | L32: =IF(L8>20%,1,IF(L8>15%,2,IF(L8>12%,3,IF(L8>10%,4,5)))) -> 1 | ... BF32: =IF(BF8>20%,1,IF(BF8>15%,2,IF(BF8>12%,3,IF(BF8>10%,4,5)))) -> 1
B34: ASSET QUALITY | C34: NPL30 | E34: =IF(E10<4,1,IF(E10<8,2,IF(E10<12,3,IF(E10<15,4,5)))) -> 1 | F34: =IF(F10<4,1,IF(F10<8,2,IF(F10<12,3,IF(F10<15,4,5)))) -> 1 | G34: =IF(G10<4,1,IF(G10<8,2,IF(G10<12,3,IF(G10<15,4,5)))) -> 1 | H34: =IF(H10<4,1,IF(H10<8,2,IF(H10<12,3,IF(H10<15,4,5)))) -> 1 | I34: =IF(I10<4,1,IF(I10<8,2,IF(I10<12,3,IF(I10<15,4,5)))) -> 1 | J34: =IF(J10<4,1,IF(J10<8,2,IF(J10<12,3,IF(J10<15,4,5)))) -> 1 | K34: =IF(K10<4,1,IF(K10<8,2,IF(K10<12,3,IF(K10<15,4,5)))) -> 1 | L34: =IF(L10<4,1,IF(L10<8,2,IF(L10<12,3,IF(L10<15,4,5)))) -> 1 | ... BF34: =IF(BF10<4,1,IF(BF10<8,2,IF(BF10<12,3,IF(BF10<15,4,5)))) -> 1
C35: A/L NPL30
B37: EARNINGS | C37: ROA | E37: =IF(E17>6,1,IF(E17>4,2,IF(E17>2,3,IF(E17>0,4,5)))) -> 4 | F37: =IF(F17>6,1,IF(F17>4,2,IF(F17>2,3,IF(F17>0,4,5)))) -> 4 | G37: =IF(G17>6,1,IF(G17>4,2,IF(G17>2,3,IF(G17>0,4,5)))) -> 4 | H37: =IF(H17>6,1,IF(H17>4,2,IF(H17>2,3,IF(H17>0,4,5)))) -> 4 | I37: =IF(I17>6,1,IF(I17>4,2,IF(I17>2,3,IF(I17>0,4,5)))) -> 4 | J37: =IF(J17>6,1,IF(J17>4,2,IF(J17>2,3,IF(J17>0,4,5)))) -> 4 | K37: =IF(K17>6,1,IF(K17>4,2,IF(K17>2,3,IF(K17>0,4,5)))) -> 4 | L37: =IF(L17>6,1,IF(L17>4,2,IF(L17>2,3,IF(L17>0,4,5)))) -> 4 | ... BF37: =IF(BF17>6,1,IF(BF17>4,2,IF(BF17>2,3,IF(BF17>0,4,5)))) -> 4
C38: C/I ratio | E38: =IF(E14<60,1,IF(E14<70,2,IF(E14<80,3,IF(E14<90,4,5)))) -> 1 | F38: =IF(F14<60,1,IF(F14<70,2,IF(F14<80,3,IF(F14<90,4,5)))) -> 1 | G38: =IF(G14<60,1,IF(G14<70,2,IF(G14<80,3,IF(G14<90,4,5)))) -> 1 | H38: =IF(H14<60,1,IF(H14<70,2,IF(H14<80,3,IF(H14<90,4,5)))) -> 1 | I38: =IF(I14<60,1,IF(I14<70,2,IF(I14<80,3,IF(I14<90,4,5)))) -> 1 | J38: =IF(J14<60,1,IF(J14<70,2,IF(J14<80,3,IF(J14<90,4,5)))) -> 1 | K38: =IF(K14<60,1,IF(K14<70,2,IF(K14<80,3,IF(K14<90,4,5)))) -> 1 | L38: =IF(L14<60,1,IF(L14<70,2,IF(L14<80,3,IF(L14<90,4,5)))) -> 1 | ... BF38: =IF(BF14<60,1,IF(BF14<70,2,IF(BF14<80,3,IF(BF14<90,4,5)))) -> 1
C39: OE ratio | E39: =IF(E15<4,1,IF(E15<6,2,IF(E15<8,3,IF(E15<10,4,5)))) -> 1 | F39: =IF(F15<4,1,IF(F15<6,2,IF(F15<8,3,IF(F15<10,4,5)))) -> 1 | G39: =IF(G15<4,1,IF(G15<6,2,IF(G15<8,3,IF(G15<10,4,5)))) -> 1 | H39: =IF(H15<4,1,IF(H15<6,2,IF(H15<8,3,IF(H15<10,4,5)))) -> 1 | I39: =IF(I15<4,1,IF(I15<6,2,IF(I15<8,3,IF(I15<10,4,5)))) -> 1 | J39: =IF(J15<4,1,IF(J15<6,2,IF(J15<8,3,IF(J15<10,4,5)))) -> 1 | K39: =IF(K15<4,1,IF(K15<6,2,IF(K15<8,3,IF(K15<10,4,5)))) -> 1 | L39: =IF(L15<4,1,IF(L15<6,2,IF(L15<8,3,IF(L15<10,4,5)))) -> 1 | ... BF39: =IF(BF15<4,1,IF(BF15<6,2,IF(BF15<8,3,IF(BF15<10,4,5)))) -> 1
B41: LIQUIDITY | C41: W NLIQ ratio | D41: Min 15% | E41: =IF(E17>30,1,IF(E17>25,2,IF(E17>20,3,IF(E17>15,4,5)))) -> 5 | F41: =IF(F17>30,1,IF(F17>25,2,IF(F17>20,3,IF(F17>15,4,5)))) -> 5 | G41: =IF(G17>30,1,IF(G17>25,2,IF(G17>20,3,IF(G17>15,4,5)))) -> 5 | H41: =IF(H17>30,1,IF(H17>25,2,IF(H17>20,3,IF(H17>15,4,5)))) -> 5 | I41: =IF(I17>30,1,IF(I17>25,2,IF(I17>20,3,IF(I17>15,4,5)))) -> 5 | J41: =IF(J17>30,1,IF(J17>25,2,IF(J17>20,3,IF(J17>15,4,5)))) -> 5 | K41: =IF(K17>30,1,IF(K17>25,2,IF(K17>20,3,IF(K17>15,4,5)))) -> 5 | L41: =IF(L17>30,1,IF(L17>25,2,IF(L17>20,3,IF(L17>15,4,5)))) -> 5 | ... BF41: =IF(BF17>30,1,IF(BF17>25,2,IF(BF17>20,3,IF(BF17>15,4,5)))) -> 5
C42: T NLIQ ratio | E42: =IF(E18>30,1,IF(E18>25,2,IF(E18>20,3,IF(E18>15,4,5)))) -> 5 | F42: =IF(F18>30,1,IF(F18>25,2,IF(F18>20,3,IF(F18>15,4,5)))) -> 5 | G42: =IF(G18>30,1,IF(G18>25,2,IF(G18>20,3,IF(G18>15,4,5)))) -> 5 | H42: =IF(H18>30,1,IF(H18>25,2,IF(H18>20,3,IF(H18>15,4,5)))) -> 5 | I42: =IF(I18>30,1,IF(I18>25,2,IF(I18>20,3,IF(I18>15,4,5)))) -> 5 | J42: =IF(J18>30,1,IF(J18>25,2,IF(J18>20,3,IF(J18>15,4,5)))) -> 5 | K42: =IF(K18>30,1,IF(K18>25,2,IF(K18>20,3,IF(K18>15,4,5)))) -> 5 | L42: =IF(L18>30,1,IF(L18>25,2,IF(L18>20,3,IF(L18>15,4,5)))) -> 5 | ... BF42: =IF(BF18>30,1,IF(BF18>25,2,IF(BF18>20,3,IF(BF18>15,4,5)))) -> 5
C43: EB ratio | D43: Max 25% | E43: =IF(E19<15,1,IF(E19<18,2,IF(E19<22,3,IF(E19<25,4,5)))) -> 1 | F43: =IF(F19<15,1,IF(F19<18,2,IF(F19<22,3,IF(F19<25,4,5)))) -> 1 | G43: =IF(G19<15,1,IF(G19<18,2,IF(G19<22,3,IF(G19<25,4,5)))) -> 1 | H43: =IF(H19<15,1,IF(H19<18,2,IF(H19<22,3,IF(H19<25,4,5)))) -> 1 | I43: =IF(I19<15,1,IF(I19<18,2,IF(I19<22,3,IF(I19<25,4,5)))) -> 1 | J43: =IF(J19<15,1,IF(J19<18,2,IF(J19<22,3,IF(J19<25,4,5)))) -> 1 | K43: =IF(K19<15,1,IF(K19<18,2,IF(K19<22,3,IF(K19<25,4,5)))) -> 1 | L43: =IF(L19<15,1,IF(L19<18,2,IF(L19<22,3,IF(L19<25,4,5)))) -> 1 | ... BF43: =IF(BF19<15,1,IF(BF19<18,2,IF(BF19<22,3,IF(BF19<25,4,5)))) -> 1
C44: LIQ to TA ratio | E44: =IF(E20>15,1,IF(E20>12,2,IF(E20>9,3,IF(E20>6,4,5)))) -> 5 | F44: =IF(F20>15,1,IF(F20>12,2,IF(F20>9,3,IF(F20>6,4,5)))) -> 5 | G44: =IF(G20>15,1,IF(G20>12,2,IF(G20>9,3,IF(G20>6,4,5)))) -> 5 | H44: =IF(H20>15,1,IF(H20>12,2,IF(H20>9,3,IF(H20>6,4,5)))) -> 5 | I44: =IF(I20>15,1,IF(I20>12,2,IF(I20>9,3,IF(I20>6,4,5)))) -> 5 | J44: =IF(J20>15,1,IF(J20>12,2,IF(J20>9,3,IF(J20>6,4,5)))) -> 5 | K44: =IF(K20>15,1,IF(K20>12,2,IF(K20>9,3,IF(K20>6,4,5)))) -> 5 | L44: =IF(L20>15,1,IF(L20>12,2,IF(L20>9,3,IF(L20>6,4,5)))) -> 5 | ... BF44: =IF(BF20>15,1,IF(BF20>12,2,IF(BF20>9,3,IF(BF20>6,4,5)))) -> 5
B46: STRUCTURE OF ASSETS | C46: LB ratio | D46: Max 5% | E46: =IF(E22<2,1,IF(E22<3,2,IF(E22<4,3,IF(E22<5,4,5)))) -> 1 | F46: =IF(F22<2,1,IF(F22<3,2,IF(F22<4,3,IF(F22<5,4,5)))) -> 1 | G46: =IF(G22<2,1,IF(G22<3,2,IF(G22<4,3,IF(G22<5,4,5)))) -> 1 | H46: =IF(H22<2,1,IF(H22<3,2,IF(H22<4,3,IF(H22<5,4,5)))) -> 1 | I46: =IF(I22<2,1,IF(I22<3,2,IF(I22<4,3,IF(I22<5,4,5)))) -> 1 | J46: =IF(J22<2,1,IF(J22<3,2,IF(J22<4,3,IF(J22<5,4,5)))) -> 1 | K46: =IF(K22<2,1,IF(K22<3,2,IF(K22<4,3,IF(K22<5,4,5)))) -> 1 | L46: =IF(L22<2,1,IF(L22<3,2,IF(L22<4,3,IF(L22<5,4,5)))) -> 1 | ... BF46: =IF(BF22<2,1,IF(BF22<3,2,IF(BF22<4,3,IF(BF22<5,4,5)))) -> 1
C47: FICC | D47: Max 40% | E47: =IF(E23<20,1,IF(E23<25,2,IF(E23<30,3,IF(E23<40,4,5)))) -> 1 | F47: =IF(F23<20,1,IF(F23<25,2,IF(F23<30,3,IF(F23<40,4,5)))) -> 1 | G47: =IF(G23<20,1,IF(G23<25,2,IF(G23<30,3,IF(G23<40,4,5)))) -> 1 | H47: =IF(H23<20,1,IF(H23<25,2,IF(H23<30,3,IF(H23<40,4,5)))) -> 1 | I47: =IF(I23<20,1,IF(I23<25,2,IF(I23<30,3,IF(I23<40,4,5)))) -> 1 | J47: =IF(J23<20,1,IF(J23<25,2,IF(J23<30,3,IF(J23<40,4,5)))) -> 1 | K47: =IF(K23<20,1,IF(K23<25,2,IF(K23<30,3,IF(K23<40,4,5)))) -> 1 | L47: =IF(L23<20,1,IF(L23<25,2,IF(L23<30,3,IF(L23<40,4,5)))) -> 1 | ... BF47: =IF(BF23<20,1,IF(BF23<25,2,IF(BF23<30,3,IF(BF23<40,4,5)))) -> 1
C48: FITD | D48: Max 5% | E48: =IF(E23<2,1,IF(E23<3,2,IF(E23<4,3,IF(E23<5,4,5)))) -> 1 | F48: =IF(F23<2,1,IF(F23<3,2,IF(F23<4,3,IF(F23<5,4,5)))) -> 1 | G48: =IF(G23<2,1,IF(G23<3,2,IF(G23<4,3,IF(G23<5,4,5)))) -> 1 | H48: =IF(H23<2,1,IF(H23<3,2,IF(H23<4,3,IF(H23<5,4,5)))) -> 1 | I48: =IF(I23<2,1,IF(I23<3,2,IF(I23<4,3,IF(I23<5,4,5)))) -> 1 | J48: =IF(J23<2,1,IF(J23<3,2,IF(J23<4,3,IF(J23<5,4,5)))) -> 1 | K48: =IF(K23<2,1,IF(K23<3,2,IF(K23<4,3,IF(K23<5,4,5)))) -> 1 | L48: =IF(L23<2,1,IF(L23<3,2,IF(L23<4,3,IF(L23<5,4,5)))) -> 1 | ... BF48: =IF(BF23<2,1,IF(BF23<3,2,IF(BF23<4,3,IF(BF23<5,4,5)))) -> 1
C49: NEA | D49: Max 10% | E49: =IF(E25<6,1,IF(E25<7,2,IF(E25<8,3,IF(E25<10,4,5)))) -> 1 | F49: =IF(F25<6,1,IF(F25<7,2,IF(F25<8,3,IF(F25<10,4,5)))) -> 1 | G49: =IF(G25<6,1,IF(G25<7,2,IF(G25<8,3,IF(G25<10,4,5)))) -> 1 | H49: =IF(H25<6,1,IF(H25<7,2,IF(H25<8,3,IF(H25<10,4,5)))) -> 1 | I49: =IF(I25<6,1,IF(I25<7,2,IF(I25<8,3,IF(I25<10,4,5)))) -> 1 | J49: =IF(J25<6,1,IF(J25<7,2,IF(J25<8,3,IF(J25<10,4,5)))) -> 1 | K49: =IF(K25<6,1,IF(K25<7,2,IF(K25<8,3,IF(K25<10,4,5)))) -> 1 | L49: =IF(L25<6,1,IF(L25<7,2,IF(L25<8,3,IF(L25<10,4,5)))) -> 1 | ... BF49: =IF(BF25<6,1,IF(BF25<7,2,IF(BF25<8,3,IF(BF25<10,4,5)))) -> 1
A52: INDICATOR WEIGHTS | B52: CAPITAL | C52: CORE CAPITAL | E52: 0.01 | F52: 0.01 | G52: 0.01 | H52: 0.01 | I52: 0.01 | J52: 0.01 | K52: 0.01 | L52: 0.01 | M52: 0.01 | N52: 0.01 | O52: 0.01 | P52: 0.01 | Q52: 0.01 | R52: 0.01 | S52: 0.01 | T52: 0.01 | U52: 0.01 | V52: 0.01 | W52: 0.01 | X52: 0.01 | Y52: 0.01 | Z52: 0.01 | AA52: 0.01 | AB52: 0.01 | AC52: 0.01 | AD52: 0.01 | AE52: 0.01 | AF52: 0.01 | AG52: 0.01 | AH52: 0.01 | AI52: 0.01 | AJ52: 0.01 | AK52: 0.01 | AL52: 0.01 | AM52: 0.01 | AN52: 0.01 | AO52: 0.01 | AP52: 0.01 | AQ52: 0.01 | AR52: 0.01 | AS52: 0.01 | AT52: 0.01 | AU52: 0.01 | AV52: 0.01 | AW52: 0.01 | AX52: 0.01 | AY52: 0.01 | AZ52: 0.01 | BA52: 0.01 | BB52: 0.01 | BC52: 0.01 | BD52: 0.01 | BE52: 0.01 | BF52: 0.01
...

Sheet Prudential Ratios
A1: IG SACCO SOCIETY LTD
A2: Afya Sacco Financial Performance
A4: FINANCIAL SOUNDNESS INDICATORS | B4: Prude. Std | C4: Ref. # | D4: Audited 2017 | E4: 43101 | F4: 43132 | G4: 43160 | H4: 43191 | I4: 43221 | J4: 43252 | K4: 43282 | L4: 43313 | M4: 43344 | N4: 43374 | O4: 43405 | P4: 43435 | Q4: Audited 2018
A5: CAPITAL ADEQUACY REQUIREMENTS | AE5: 43831 | AF5: 43862 | AG5: 43891 | AH5: 43922 | AI5: 43952 | AJ5: 43983 | AK5: 44013 | AL5: 44044 | AM5: 44075 | AN5: 44105 | AO5: 44136 | AP5: 44166 | AQ5: Audited 2020 | AR5: 44197 | AS5: 44228 | AT5: 44256 | AU5: 44287 | AV5: 44317 | AW5: 44348 | AX5: 44378 | AY5: 44409 | AZ5: 44440 | BA5: 44470 | BB5: 44501 | BC5: 44531 | BD5: Audited 2021 | BE5: 44562 | BF5: 44593 | BG5: 44621 | BH5: 44652 | BI5: 44682 | BJ5: 44713 | BK5: 44743 | BL5: 44774
A6: Core capital | B6: ≥ Ksh.10M | C6: 9.a | D6: =CAELS!E4 -> 2354.8772 | E6: =CAELS!#REF! -> #REF! | F6: =CAELS!#REF! -> #REF! | G6: =CAELS!#REF! -> #REF! | H6: =CAELS!#REF! -> #REF! | I6: =CAELS!#REF! -> #REF! | J6: =CAELS!#REF! -> #REF! | K6: =CAELS!#REF! -> #REF! | L6: =CAELS!#REF! -> #REF! | ... P6: =CAELS!#REF! -> #REF! | Q6: =CAELS!F4 -> 2112.2539 | R6: =CAELS!G4 -> 2260.4537 | S6: =CAELS!H4 -> 2296.4904 | T6: =CAELS!I4 -> 2316.8831 | U6: =CAELS!J4 -> 2350.464 | V6: =CAELS!K4 -> 2401.1642 | W6: =CAELS!L4 -> 2419.0936 | X6: =CAELS!M4 -> 2415.9595 | ... BQ6: =CAELS!BF4 -> 4484.427 | BR6: =CAELS!#REF! -> #REF! | BS6: =CAELS!BG4 -> 0 | BT6: =CAELS!BH4 -> 0 | BU6: =CAELS!BI4 -> 0 | BV6: =CAELS!BJ4 -> 0 | BW6: =CAELS!BK4 -> 0 | BX6: =CAELS!BL4 -> 0 | BY6: =CAELS!BM4 -> 0 | BZ6: =CAELS!BN4 -> 0
A7: Core capital /Total Assets | B7: ≥ 10% | C7: 9.b | D7: =CAELS!E5 -> 0.29049771 | E7: =CAELS!#REF! -> #REF! | F7: =CAELS!#REF! -> #REF! | G7: =CAELS!#REF! -> #REF! | H7: =CAELS!#REF! -> #REF! | I7: =CAELS!#REF! -> #REF! | J7: =CAELS!#REF! -> #REF! | K7: =CAELS!#REF! -> #REF! | L7: =CAELS!#REF! -> #REF! | ... P7: =CAELS!#REF! -> #REF! | Q7: =CAELS!F5 -> 0.24236128 | R7: =CAELS!G5 -> 0.25227516 | S7: =CAELS!H5 -> 0.25634815 | T7: =CAELS!I5 -> 0.25605685 | U7: =CAELS!J5 -> 0.27491438 | V7: =CAELS!K5 -> 0.28073567 | W7: =CAELS!L5 -> 0.27783371 | X7: =CAELS!M5 -> 0.27461853 | ... BQ7: =CAELS!BF5 -> 0.34607337 | BR7: =CAELS!#REF! -> #REF! | BS7: =CAELS!BG5 -> 0 | BT7: =CAELS!BH5 -> 0 | BU7: =CAELS!BI5 -> 0 | BV7: =CAELS!BJ5 -> 0 | BW7: =CAELS!BK5 -> 0 | BX7: =CAELS!BL5 -> 0 | BY7: =CAELS!BM5 -> 0 | BZ7: =CAELS!BN5 -> 0
A8: Core capital /Total Deposits | B8: ≥ 8% | C8: 9.d | D8: =CAELS!E6 -> 0.24331869 | E8: =CAELS!#REF! -> #REF! | F8: =CAELS!#REF! -> #REF! | G8: =CAELS!#REF! -> #REF! | H8: =CAELS!#REF! -> #REF! | I8: =CAELS!#REF! -> #REF! | J8: =CAELS!#REF! -> #REF! | K8: =CAELS!#REF! -> #REF! | L8: =CAELS!#REF! -> #REF! | ... P8: =CAELS!#REF! -> #REF! | Q8: =CAELS!F6 -> 0.19394967 | R8: =CAELS!G6 -> 0.17729934 | S8: =CAELS!H6 -> 0.18093922 | T8: =CAELS!I6 -> 0.18064482 | U8: =CAELS!J6 -> 0.19362637 | V8: =CAELS!K6 -> 0.19890984 | W8: =CAELS!L6 -> 0.19697259 | X8: =CAELS!M6 -> 0.19425579 | ... BQ8: =CAELS!BF6 -> 0.24534497 | BR8: =CAELS!#REF! -> #REF! | BS8: =CAELS!BG6 -> 0 | BT8: =CAELS!BH6 -> 0 | BU8: =CAELS!BI6 -> 0 | BV8: =CAELS!BJ6 -> 0 | BW8: =CAELS!BK6 -> 0 | BX8: =CAELS!BL6 -> 0 | BY8: =CAELS!BM6 -> 0 | BZ8: =CAELS!BN6 -> 0
A9: Share Capital/Total Assets | B9: ≤2% | C9: 9.c | D9: =CAELS!E7 -> 0.52513872 | E9: =CAELS!#REF! -> #REF! | F9: =CAELS!#REF! -> #REF! | G9: =CAELS!#REF! -> #REF! | H9: =CAELS!#REF! -> #REF! | I9: =CAELS!#REF! -> #REF! | J9: =CAELS!#REF! -> #REF! | K9: =CAELS!#REF! -> #REF! | L9: =CAELS!#REF! -> #REF! | ... P9: =CAELS!#REF! -> #REF! | Q9: =CAELS!F7 -> 0.42560133 | R9: =CAELS!G7 -> 0.45392085 | S9: =CAELS!H7 -> 0.45608835 | T9: =CAELS!I7 -> 0.4503879 | U9: =CAELS!J7 -> 0.45503927 | V9: =CAELS!K7 -> 0.46677668 | W9: =CAELS!L7 -> 0.46759655 | X9: =CAELS!M7 -> 0.46642965 | ... BQ9: =CAELS!BF7 -> 0.6365721 | BR9: =CAELS!#REF! -> #REF! | BS9: =CAELS!BG7 -> 0 | BT9: =CAELS!BH7 -> 0 | BU9: =CAELS!BI7 -> 0 | BV9: =CAELS!BJ7 -> 0 | BW9: =CAELS!BK7 -> 0 | BX9: =CAELS!BL7 -> 0 | BY9: =CAELS!BM7 -> 0 | BZ9: =CAELS!BN7 -> 0
A10: Institutional Capital/Total Assets | B10: ≥ 8% | C10: 9.c | D10: =CAELS!E8 -> 0.29049771 | E10: =CAELS!#REF! -> #REF! | F10: =CAELS!#REF! -> #REF! | G10: =CAELS!#REF! -> #REF! | H10: =CAELS!#REF! -> #REF! | I10: =CAELS!#REF! -> #REF! | J10: =CAELS!#REF! -> #REF! | K10: =CAELS!#REF! -> #REF! | L10: =CAELS!#REF! -> #REF! | ... P10: =CAELS!#REF! -> #REF! | Q10: =CAELS!F8 -> 0.24236128 | R10: =CAELS!G8 -> 0.25227516 | S10: =CAELS!H8 -> 0.25634815 | T10: =CAELS!I8 -> 0.25605685 | U10: =CAELS!J8 -> 0.27491438 | V10: =CAELS!K8 -> 0.28073567 | W10: =CAELS!L8 -> 0.27783371 | X10: =CAELS!M8 -> 0.27461853 | ... BQ10: =CAELS!BF8 -> 0.34607337 | BR10: =CAELS!#REF! -> #REF! | BS10: =CAELS!BG8 -> 0 | BT10: =CAELS!BH8 -> 0 | BU10: =CAELS!BI8 -> 0 | BV10: =CAELS!BJ8 -> 0 | BW10: =CAELS!BK8 -> 0 | BX10: =CAELS!BL8 -> 0 | BY10: =CAELS!BM8 -> 0 | BZ10: =CAELS!BN8 -> 0
A12: ASSET MIX AND QUALITY
A13: Non Earning Assets
A14: Non earning Assets/Total assets | B14: ≤ 10% | C14: 48.1 | D14: =CAELS!E25 -> 0.045089754 | E14: =CAELS!#REF! -> #REF! | F14: =CAELS!#REF! -> #REF! | G14: =CAELS!#REF! -> #REF! | H14: =CAELS!#REF! -> #REF! | I14: =CAELS!#REF! -> #REF! | J14: =CAELS!#REF! -> #REF! | K14: =CAELS!#REF! -> #REF! | L14: =CAELS!#REF! -> #REF! | ... P14: =CAELS!#REF! -> #REF! | Q14: =CAELS!F25 -> 0.041725469 | R14: =CAELS!G25 -> 0.059743996 | S14: =CAELS!H25 -> 0.050727611 | T14: =CAELS!I25 -> 0.050121236 | U14: =CAELS!J25 -> 0.048788143 | V14: =CAELS!K25 -> 0.0482892 | W14: =CAELS!L25 -> 0.048193307 | X14: =CAELS!M25 -> 0.053723507 | ... BQ14: =CAELS!BF25 -> 0.039741939 | BR14: =CAELS!#REF! -> #REF! | BS14: =CAELS!BG25 -> 0 | BT14: =CAELS!BH25 -> 0 | BU14: =CAELS!BI25 -> 0 | BV14: =CAELS!BJ25 -> 0 | BW14: =CAELS!BK25 -> 0 | BX14: =CAELS!BL25 -> 0 | BY14: =CAELS!BM25 -> 0 | BZ14: =CAELS!BN25 -> 0
A15: Property and Equipment/Total Assets | B15: ≤ 5% | C15: 48.1 | D15: =CAELS!E22 -> 0 | E15: =CAELS!#REF! -> #REF! | F15: =CAELS!#REF! -> #REF! | G15: =CAELS!#REF! -> #REF! | H15: =CAELS!#REF! -> #REF! | I15: =CAELS!#REF! -> #REF! | J15: =CAELS!#REF! -> #REF! | K15: =CAELS!#REF! -> #REF! | L15: =CAELS!#REF! -> #REF! | ... P15: =CAELS!#REF! -> #REF! | Q15: =CAELS!F22 -> 0 | R15: =CAELS!G22 -> 0 | S15: =CAELS!H22 -> 0 | T15: =CAELS!I22 -> 0 | U15: =CAELS!J22 -> 0 | V15: =CAELS!K22 -> 0 | W15: =CAELS!L22 -> 0 | X15: =CAELS!M22 -> 0 | ... BQ15: =CAELS!BF22 -> 0 | BR15: =CAELS!#REF! -> #REF! | BS15: =CAELS!BG22 -> 0 | BT15: =CAELS!BH22 -> 0 | BU15: =CAELS!BI22 -> 0 | BV15: =CAELS!BJ22 -> 0 | BW15: =CAELS!BK22 -> 0 | BX15: =CAELS!BL22 -> 0 | BY15: =CAELS!BM22 -> 0 | BZ15: =CAELS!BN22 -> 0
A16: Non Performing loans/Gross Loans | B16: ≤ 6% | C16: 41
A18: Earning Assets
A19: Equities & Investments/Deposits | B19: ≤ 5% | C19: 48.4 | D19: =CAELS!E22 -> 0 | E19: =CAELS!#REF! -> #REF! | F19: =CAELS!#REF! -> #REF! | G19: =CAELS!#REF! -> #REF! | H19: =CAELS!#REF! -> #REF! | I19: =CAELS!#REF! -> #REF! | J19: =CAELS!#REF! -> #REF! | K19: =CAELS!#REF! -> #REF! | L19: =CAELS!#REF! -> #REF! | ... P19: =CAELS!#REF! -> #REF! | Q19: =CAELS!F22 -> 0 | R19: =CAELS!G22 -> 0 | S19: =CAELS!H22 -> 0 | T19: =CAELS!I22 -> 0 | U19: =CAELS!J22 -> 0 | V19: =CAELS!K22 -> 0 | W19: =CAELS!L22 -> 0 | X19: =CAELS!M22 -> 0 | ... BQ19: =CAELS!BF22 -> 0 | BR19: =CAELS!#REF! -> #REF! | BS19: =CAELS!BG22 -> 0 | BT19: =CAELS!BH22 -> 0 | BU19: =CAELS!BI22 -> 0 | BV19: =CAELS!BJ22 -> 0 | BW19: =CAELS!BK22 -> 0 | BX19: =CAELS!BL22 -> 0 | BY19: =CAELS!BM22 -> 0 | BZ19: =CAELS!BN22 -> 0
A20: Equities & Investments/Core Capital | B20: ≤ 40% | C20: 48.4 | D20: =CAELS!E23 -> 0.18617178 | E20: =CAELS!#REF! -> #REF! | F20: =CAELS!#REF! -> #REF! | G20: =CAELS!#REF! -> #REF! | H20: =CAELS!#REF! -> #REF! | I20: =CAELS!#REF! -> #REF! | J20: =CAELS!#REF! -> #REF! | K20: =CAELS!#REF! -> #REF! | L20: =CAELS!#REF! -> #REF! | ... P20: =CAELS!#REF! -> #REF! | Q20: =CAELS!F23 -> 0.22770426 | R20: =CAELS!G23 -> 0.22298057 | S20: =CAELS!H23 -> 0.2082994 | T20: =CAELS!I23 -> 0.2066577 | U20: =CAELS!J23 -> 0.20389417 | V20: =CAELS!K23 -> 0.20135653 | W20: =CAELS!L23 -> 0.21575613 | X20: =CAELS!M23 -> 0.2183598 | ... BQ20: =CAELS!BF23 -> 0.34381851 | BR20: =CAELS!#REF! -> #REF! | BS20: =CAELS!BG23 -> 0 | BT20: =CAELS!BH23 -> 0 | BU20: =CAELS!BI23 -> 0 | BV20: =CAELS!BJ23 -> 0 | BW20: =CAELS!BK23 -> 0 | BX20: =CAELS!BL23 -> 0 | BY20: =CAELS!BM23 -> 0 | BZ20: =CAELS!BN23 -> 0
A21: Net Loans & advances /Total assets | B21: NPR | D21: =CAELS!E26 -> 0.80519061 | E21: =CAELS!#REF! -> #REF! | F21: =CAELS!#REF! -> #REF! | G21: =CAELS!#REF! -> #REF! | H21: =CAELS!#REF! -> #REF! | I21: =CAELS!#REF! -> #REF! | J21: =CAELS!#REF! -> #REF! | K21: =CAELS!#REF! -> #REF! | L21: =CAELS!#REF! -> #REF! | ... P21: =CAELS!#REF! -> #REF! | Q21: =CAELS!F26 -> 0.77284578 | R21: =CAELS!G26 -> 0.75035438 | S21: =CAELS!H26 -> 0.74810962 | T21: =CAELS!I26 -> 0.73219859 | U21: =CAELS!J26 -> 0.75662883 | V21: =CAELS!K26 -> 0.74689133 | W21: =CAELS!L26 -> 0.72993748 | X21: =CAELS!M26 -> 0.72144756 | ... BQ21: =CAELS!BF26 -> 0.70397292 | BR21: =CAELS!#REF! -> #REF! | BS21: =CAELS!BG26 -> 0 | BT21: =CAELS!BH26 -> 0 | BU21: =CAELS!BI26 -> 0 | BV21: =CAELS!BJ26 -> 0 | BW21: =CAELS!BK26 -> 0 | BX21: =CAELS!BL26 -> 0 | BY21: =CAELS!BM26 -> 0 | BZ21: =CAELS!BN26 -> 0
A23: FUNDING MIX
A24: Total Deposits/Total Assets | B24: NPR | D24: =Financials!C6/Financials!C5 -> 0.55318281 | E24: =Financials!#REF!/Financials!#REF! -> #REF! | F24: =Financials!#REF!/Financials!#REF! -> #REF! | G24: =Financials!#REF!/Financials!#REF! -> #REF! | H24: =Financials!#REF!/Financials!#REF! -> #REF! | I24: =Financials!#REF!/Financials!#REF! -> #REF! | J24: =Financials!#REF!/Financials!#REF! -> #REF! | K24: =Financials!#REF!/Financials!#REF! -> #REF! | L24: =Financials!#REF!/Financials!#REF! -> #REF! | ... P24: =Financials!#REF!/Financials!#REF! -> #REF! | Q24: =Financials!D6/Financials!D5 -> 0.56945613 | R24: =Financials!E6/Financials!E5 -> 0.55576904 | S24: =Financials!F6/Financials!F5 -> 0.56205809 | T24: =Financials!G6/Financials!G5 -> 0.56852516 | U24: =Financials!H6/Financials!H5 -> 0.60415529 | V24: =Financials!I6/Financials!I5 -> 0.60143466 | W24: =Financials!J6/Financials!J5 -> 0.594174 | X24: =Financials!K6/Financials!K5 -> 0.58876731 | ... BQ24: =Financials!BD6/Financials!BD5 -> 0.54365149 | BR24: =Financials!#REF!/Financials!#REF! -> #REF! | BS24: =Financials!#REF!/Financials!#REF! -> #REF! | BT24: =Financials!#REF!/Financials!#REF! -> #REF! | BU24: =Financials!BE6/Financials!BE5 -> #DIV/0! | BV24: =Financials!BF6/Financials!BF5 -> #DIV/0! | BW24: =Financials!BG6/Financials!BG5 -> #DIV/0! | BX24: =Financials!BH6/Financials!BH5 -> #DIV/0! | BY24: =Financials!BI6/Financials!BI5 -> #DIV/0! | BZ24: =Financials!BJ6/Financials!BJ5 -> #DIV/0!
A25: BOSA Deposits/Total Assets | B25: NPR | D25: =Financials!C7/Financials!C5 -> 0.50400779 | E25: =Financials!#REF!/Financials!#REF! -> #REF! | F25: =Financials!#REF!/Financials!#REF! -> #REF! | G25: =Financials!#REF!/Financials!#REF! -> #REF! | H25: =Financials!#REF!/Financials!#REF! -> #REF! | I25: =Financials!#REF!/Financials!#REF! -> #REF! | J25: =Financials!#REF!/Financials!#REF! -> #REF! | K25: =Financials!#REF!/Financials!#REF! -> #REF! | L25: =Financials!#REF!/Financials!#REF! -> #REF! | ... P25: =Financials!#REF!/Financials!#REF! -> #REF! | Q25: =Financials!D7/Financials!D5 -> 0.51105541 | R25: =Financials!E7/Financials!E5 -> 0.49241384 | S25: =Financials!F7/Financials!F5 -> 0.49747272 | T25: =Financials!G7/Financials!G5 -> 0.49612313 | U25: =Financials!H7/Financials!H5 -> 0.5304274 | V25: =Financials!I7/Financials!I5 -> 0.53273404 | W25: =Financials!J7/Financials!J5 -> 0.52864811 | X25: =Financials!K7/Financials!K5 -> 0.52553383 | ... BQ25: =Financials!BD7/Financials!BD5 -> 0.46054013 | BR25: =Financials!#REF!/Financials!#REF! -> #REF! | BS25: =Financials!#REF!/Financials!#REF! -> #REF! | BT25: =Financials!#REF!/Financials!#REF! -> #REF! | BU25: =Financials!BE7/Financials!BE5 -> #DIV/0! | BV25: =Financials!BF7/Financials!BF5 -> #DIV/0! | BW25: =Financials!BG7/Financials!BG5 -> #DIV/0! | BX25: =Financials!BH7/Financials!BH5 -> #DIV/0! | BY25: =Financials!BI7/Financials!BI5 -> #DIV/0! | BZ25: =Financials!BJ7/Financials!BJ5 -> #DIV/0!
A26: FOSA Deposits/Total Assets | B26: NPR | D26: =Financials!C8/Financials!C5 -> 0.033568879 | E26: =Financials!#REF!/Financials!#REF! -> #REF! | F26: =Financials!#REF!/Financials!#REF! -> #REF! | G26: =Financials!#REF!/Financials!#REF! -> #REF! | H26: =Financials!#REF!/Financials!#REF! -> #REF! | I26: =Financials!#REF!/Financials!#REF! -> #REF! | J26: =Financials!#REF!/Financials!#REF! -> #REF! | K26: =Financials!#REF!/Financials!#REF! -> #REF! | L26: =Financials!#REF!/Financials!#REF! -> #REF! | ... P26: =Financials!#REF!/Financials!#REF! -> #REF! | Q26: =Financials!D8/Financials!D5 -> 0.041111499 | R26: =Financials!E8/Financials!E5 -> 0.046933797 | S26: =Financials!F8/Financials!F5 -> 0.048728752 | T26: =Financials!G8/Financials!G5 -> 0.054293598 | U26: =Financials!H8/Financials!H5 -> 0.053978631 | V26: =Financials!I8/Financials!I5 -> 0.049246582 | W26: =Financials!J8/Financials!J5 -> 0.046932832 | X26: =Financials!K8/Financials!K5 -> 0.044796852 | ... BQ26: =Financials!BD8/Financials!BD5 -> 0.070527034 | BR26: =Financials!#REF!/Financials!#REF! -> #REF! | BS26: =Financials!#REF!/Financials!#REF! -> #REF! | BT26: =Financials!#REF!/Financials!#REF! -> #REF! | BU26: =Financials!BE8/Financials!BE5 -> #DIV/0! | BV26: =Financials!BF8/Financials!BF5 -> #DIV/0! | BW26: =Financials!BG8/Financials!BG5 -> #DIV/0! | BX26: =Financials!BH8/Financials!BH5 -> #DIV/0! | BY26: =Financials!BI8/Financials!BI5 -> #DIV/0! | BZ26: =Financials!BJ8/Financials!BJ5 -> #DIV/0!
A27: External Borrowing/Total assets | B27: ≤ 25% | C27: 35.1 | D27: =Financials!C9/Financials!C5 -> 0.04626001 | E27: =Financials!#REF!/Financials!#REF! -> #REF! | F27: =Financials!#REF!/Financials!#REF! -> #REF! | G27: =Financials!#REF!/Financials!#REF! -> #REF! | H27: =Financials!#REF!/Financials!#REF! -> #REF! | I27: =Financials!#REF!/Financials!#REF! -> #REF! | J27: =Financials!#REF!/Financials!#REF! -> #REF! | K27: =Financials!#REF!/Financials!#REF! -> #REF! | L27: =Financials!#REF!/Financials!#REF! -> #REF! | ... P27: =Financials!#REF!/Financials!#REF! -> #REF! | Q27: =Financials!D9/Financials!D5 -> 0.031553666 | R27: =Financials!E9/Financials!E5 -> 0.029761006 | S27: =Financials!F9/Financials!F5 -> 0.022354849 | T27: =Financials!G9/Financials!G5 -> 0.010542621 | U27: =Financials!H9/Financials!H5 -> 0.010753626 | V27: =Financials!I9/Financials!I5 -> 0 | W27: =Financials!J9/Financials!J5 -> 0 | X27: =Financials!K9/Financials!K5 -> 0 | ... BQ27: =Financials!BD9/Financials!BD5 -> 0 | BR27: =Financials!#REF!/Financials!#REF! -> #REF! | BS27: =Financials!#REF!/Financials!#REF! -> #REF! | BT27: =Financials!#REF!/Financials!#REF! -> #REF! | BU27: =Financials!BE9/Financials!BE5 -> #DIV/0! | BV27: =Financials!BF9/Financials!BF5 -> #DIV/0! | BW27: =Financials!BG9/Financials!BG5 -> #DIV/0! | BX27: =Financials!BH9/Financials!BH5 -> #DIV/0! | BY27: =Financials!BI9/Financials!BI5 -> #DIV/0! | BZ27: =Financials!BJ9/Financials!BJ5 -> #DIV/0!
A29: GROWTH RATIOS
A30: Total Assets | B30: NPR | D30: =(SFP!#REF!-SFP!U27)/SFP!U27 -> #REF! | E30: =(SFP!#REF!-SFP!#REF!)/SFP!#REF! -> #REF! | F30: =(SFP!#REF!-SFP!#REF!)/SFP!#REF! -> #REF! | G30: =(SFP!#REF!-SFP!#REF!)/SFP!#REF! -> #REF! | H30: =(SFP!#REF!-SFP!#REF!)/SFP!#REF! -> #REF! | I30: =(SFP!#REF!-SFP!#REF!)/SFP!#REF! -> #REF! | J30: =(SFP!#REF!-SFP!#REF!)/SFP!#REF! -> #REF! | K30: =(SFP!#REF!-SFP!#REF!)/SFP!#REF! -> #REF! | L30: =(SFP!#REF!-SFP!#REF!)/SFP!#REF! -> #REF! | ... O30: =(SFP!#REF!-SFP!#REF!)/SFP!#REF! -> #REF! | P30: =(SFP!V34-SFP!#REF!)/SFP!#REF! -> #REF! | Q30: =(SFP!W34-SFP!V27)/SFP!V27 -> -1 | R30: =(SFP!X34-SFP!W27)/SFP!W27 -> -1 | S30: =(SFP!Y34-SFP!X27)/SFP!X27 -> -1 | T30: =(SFP!Z34-SFP!Y27)/SFP!Y27 -> -1 | U30: =(SFP!AA34-SFP!Z27)/SFP!Z27 -> -1 | V30: =(SFP!AB34-SFP!AA27)/SFP!AA27 -> -1 | W30: =(SFP!AC34-SFP!AB27)/SFP!AB27 -> -1 | X30: =(SFP!AD34-SFP!AC27)/SFP!AC27 -> -1 | ... BZ30: =(SFP!CF34-SFP!CE27)/SFP!CE27 -> #DIV/0!
A31: Total Deposits | B31: NPR | D31: =(SFP!#REF!-SFP!U32)/SFP!U32 -> #REF! | E31: =(SFP!#REF!-SFP!#REF!)/SFP!#REF! -> #REF! | F31: =(SFP!#REF!-SFP!#REF!)/SFP!#REF! -> #REF! | G31: =(SFP!#REF!-SFP!#REF!)/SFP!#REF! -> #REF! | H31: =(SFP!#REF!-SFP!#REF!)/SFP!#REF! -> #REF! | I31: =(SFP!#REF!-SFP!#REF!)/SFP!#REF! -> #REF! | J31: =(SFP!#REF!-SFP!#REF!)/SFP!#REF! -> #REF! | K31: =(SFP!#REF!-SFP!#REF!)/SFP!#REF! -> #REF! | L31: =(SFP!#REF!-SFP!#REF!)/SFP!#REF! -> #REF! | ... O31: =(SFP!#REF!-SFP!#REF!)/SFP!#REF! -> #REF! | P31: =(SFP!V44-SFP!#REF!)/SFP!#REF! -> #REF! | Q31: =(SFP!W44-SFP!V32)/SFP!V32 -> -0.71108536 | R31: =(SFP!X44-SFP!W32)/SFP!W32 -> -0.71731629 | S31: =(SFP!Y44-SFP!X32)/SFP!X32 -> -0.71775523 | T31: =(SFP!Z44-SFP!Y32)/SFP!Y32 -> -0.71968157 | U31: =(SFP!AA44-SFP!Z32)/SFP!Z32 -> -0.71197439 | V31: =(SFP!AB44-SFP!AA32)/SFP!AA32 -> -0.70073346 | W31: =(SFP!AC44-SFP!AB32)/SFP!AB32 -> -0.70261148 | X31: =(SFP!AD44-SFP!AC32)/SFP!AC32 -> -0.69249043 | ... BZ31: =(SFP!CF44-SFP!CE32)/SFP!CE32 -> #DIV/0!
A32: FOSA Deposits | B32: NPR | D32: =(SFP!#REF!-SFP!U29)/SFP!U29 -> #REF! | E32: =(SFP!#REF!-SFP!#REF!)/SFP!#REF! -> #REF! | F32: =(SFP!#REF!-SFP!#REF!)/SFP!#REF! -> #REF! | G32: =(SFP!#REF!-SFP!#REF!)/SFP!#REF! -> #REF! | H32: =(SFP!#REF!-SFP!#REF!)/SFP!#REF! -> #REF! | I32: =(SFP!#REF!-SFP!#REF!)/SFP!#REF! -> #REF! | J32: =(SFP!#REF!-SFP!#REF!)/SFP!#REF! -> #REF! | K32: =(SFP!#REF!-SFP!#REF!)/SFP!#REF! -> #REF! | L32: =(SFP!#REF!-SFP!#REF!)/SFP!#REF! -> #REF! | ... O32: =(SFP!#REF!-SFP!#REF!)/SFP!#REF! -> #REF! | P32: =(SFP!V39-SFP!#REF!)/SFP!#REF! -> #REF! | Q32: =(SFP!W39-SFP!V29)/SFP!V29 -> -0.25574366 | R32: =(SFP!X39-SFP!W29)/SFP!W29 -> -0.52378905 | S32: =(SFP!Y39-SFP!X29)/SFP!X29 -> -0.78147729 | T32: =(SFP!Z39-SFP!Y29)/SFP!Y29 -> -0.81284789 | U32: =(SFP!AA39-SFP!Z29)/SFP!Z29 -> -1 | V32: =(SFP!AB39-SFP!AA29)/SFP!AA29 -> -1 | W32: =(SFP!AC39-SFP!AB29)/SFP!AB29 -> -1 | X32: =(SFP!AD39-SFP!AC29)/SFP!AC29 -> -1 | ... BZ32: =(SFP!CF39-SFP!CE29)/SFP!CE29 -> #DIV/0!
A33: BOSA Deposits | B33: NPR | D33: =(SFP!#REF!-SFP!U31)/SFP!U31 -> #REF! | E33: =(SFP!#REF!-SFP!#REF!)/SFP!#REF! -> #REF! | F33: =(SFP!#REF!-SFP!#REF!)/SFP!#REF! -> #REF! | G33: =(SFP!#REF!-SFP!#REF!)/SFP!#REF! -> #REF! | H33: =(SFP!#REF!-SFP!#REF!)/SFP!#REF! -> #REF! | I33: =(SFP!#REF!-SFP!#REF!)/SFP!#REF! -> #REF! | J33: =(SFP!#REF!-SFP!#REF!)/SFP!#REF! -> #REF! | K33: =(SFP!#REF!-SFP!#REF!)/SFP!#REF! -> #REF! | L33: =(SFP!#REF!-SFP!#REF!)/SFP!#REF! -> #REF! | ... O33: =(SFP!#REF!-SFP!#REF!)/SFP!#REF! -> #REF! | P33: =(SFP!V42-SFP!#REF!)/SFP!#REF! -> #REF! | Q33: =(SFP!W42-SFP!V31)/SFP!V31 -> -0.8491687 | R33: =(SFP!X42-SFP!W31)/SFP!W31 -> -0.84688921 | S33: =(SFP!Y42-SFP!X31)/SFP!X31 -> -0.84688961 | T33: =(SFP!Z42-SFP!Y31)/SFP!Y31 -> -0.84518059 | U33: =(SFP!AA42-SFP!Z31)/SFP!Z31 -> -0.84567631 | V33: =(SFP!AB42-SFP!AA31)/SFP!AA31 -> -0.84548425 | W33: =(SFP!AC42-SFP!AB31)/SFP!AB31 -> -0.84640392 | X33: =(SFP!AD42-SFP!AC31)/SFP!AC31 -> -0.82944919 | ... BZ33: =(SFP!CF42-SFP!CE31)/SFP!CE31 -> #DIV/0!
A34: Net Loans & advances | B34: NPR | D34: =(SFP!#REF!-SFP!U14)/SFP!U14 -> #REF! | E34: =(SFP!#REF!-SFP!#REF!)/SFP!#REF! -> #REF! | F34: =(SFP!#REF!-SFP!#REF!)/SFP!#REF! -> #REF! | G34: =(SFP!#REF!-SFP!#REF!)/SFP!#REF! -> #REF! | H34: =(SFP!#REF!-SFP!#REF!)/SFP!#REF! -> #REF! | I34: =(SFP!#REF!-SFP!#REF!)/SFP!#REF! -> #REF! | J34: =(SFP!#REF!-SFP!#REF!)/SFP!#REF! -> #REF! | K34: =(SFP!#REF!-SFP!#REF!)/SFP!#REF! -> #REF! | L34: =(SFP!#REF!-SFP!#REF!)/SFP!#REF! -> #REF! | ... O34: =(SFP!#REF!-SFP!#REF!)/SFP!#REF! -> #REF! | P34: =(SFP!V17-SFP!#REF!)/SFP!#REF! -> #REF! | Q34: =(SFP!W17-SFP!V14)/SFP!V14 -> -1 | R34: =(SFP!X17-SFP!W14)/SFP!W14 -> -1 | S34: =(SFP!Y17-SFP!X14)/SFP!X14 -> -1 | T34: =(SFP!Z17-SFP!Y14)/SFP!Y14 -> -1 | U34: =(SFP!AA17-SFP!Z14)/SFP!Z14 -> -1 | V34: =(SFP!AB17-SFP!AA14)/SFP!AA14 -> -1 | W34: =(SFP!AC17-SFP!AB14)/SFP!AB14 -> -1 | X34: =(SFP!AD17-SFP!AC14)/SFP!AC14 -> -1 | ... BZ34: =(SFP!CF17-SFP!CE14)/SFP!CE14 -> #DIV/0!
A35: Core capital | B35: NPR
A36: Total Gross Income | B36: NPR
A37: Membership | B37: NPR
A39: Efficiency Ratios
A40: FinCost-Deposits/Average Deposits | B40: NPR | D40: =(SCI!T13/(SFP!U31+SFP!#REF!)/SFP!U27) -> #REF! | E40: =(SCI!#REF!/(SFP!#REF!+SFP!#REF!)/SFP!#REF!) -> #REF! | F40: =(SCI!#REF!/(SFP!#REF!+SFP!#REF!)/SFP!#REF!) -> #REF! | G40: =(SCI!#REF!/(SFP!#REF!+SFP!#REF!)/SFP!#REF!) -> #REF! | H40: =(SCI!#REF!/(SFP!#REF!+SFP!#REF!)/SFP!#REF!) -> #REF! | I40: =(SCI!#REF!/(SFP!#REF!+SFP!#REF!)/SFP!#REF!) -> #REF! | J40: =(SCI!#REF!/(SFP!#REF!+SFP!#REF!)/SFP!#REF!) -> #REF! | K40: =(SCI!#REF!/(SFP!#REF!+SFP!#REF!)/SFP!#REF!) -> #REF! | L40: =(SCI!#REF!/(SFP!#REF!+SFP!#REF!)/SFP!#REF!) -> #REF! | ... O40: =(SCI!#REF!/(SFP!#REF!+SFP!#REF!)/SFP!#REF!) -> #REF! | P40: =(SCI!#REF!/(SFP!#REF!+SFP!V42)/SFP!#REF!) -> #REF! | Q40: =(SCI!U13/(SFP!V31+SFP!W42)/SFP!V27) -> 1.2337811e-11 | R40: =(SCI!V13/(SFP!W31+SFP!X42)/SFP!W27) -> 1.1930934e-12 | S40: =(SCI!W13/(SFP!X31+SFP!Y42)/SFP!X27) -> 2.360724e-12 | T40: =(SCI!X13/(SFP!Y31+SFP!Z42)/SFP!Y27) -> 3.4901371e-12 | U40: =(SCI!Y13/(SFP!Z31+SFP!AA42)/SFP!Z27) -> 4.9302611e-12 | V40: =(SCI!Z13/(SFP!AA31+SFP!AB42)/SFP!AA27) -> 6.1477593e-12 | W40: =(SCI!AA13/(SFP!AB31+SFP!AC42)/SFP!AB27) -> 7.2376791e-12 | X40: =(SCI!AB13/(SFP!AC31+SFP!AD42)/SFP!AC27) -> 8.4691285e-12 | ... BZ40: =(SCI!CD13/(SFP!CE31+SFP!CF42)/SFP!CE27) -> #DIV/0!
A41: FinCost-Shares/Average Share capital | B41: NPR | D41: =(SCI!T15/(SFP!U42+SFP!#REF!)/SFP!U27) -> #REF! | E41: =(SCI!#REF!/(SFP!#REF!+SFP!#REF!)/SFP!#REF!) -> #REF! | F41: =(SCI!#REF!/(SFP!#REF!+SFP!#REF!)/SFP!#REF!) -> #REF! | G41: =(SCI!#REF!/(SFP!#REF!+SFP!#REF!)/SFP!#REF!) -> #REF! | H41: =(SCI!#REF!/(SFP!#REF!+SFP!#REF!)/SFP!#REF!) -> #REF! | I41: =(SCI!#REF!/(SFP!#REF!+SFP!#REF!)/SFP!#REF!) -> #REF! | J41: =(SCI!#REF!/(SFP!#REF!+SFP!#REF!)/SFP!#REF!) -> #REF! | K41: =(SCI!#REF!/(SFP!#REF!+SFP!#REF!)/SFP!#REF!) -> #REF! | L41: =(SCI!#REF!/(SFP!#REF!+SFP!#REF!)/SFP!#REF!) -> #REF! | ... O41: =(SCI!#REF!/(SFP!#REF!+SFP!#REF!)/SFP!#REF!) -> #REF! | P41: =(SCI!#REF!/(SFP!#REF!+SFP!V42)/SFP!#REF!) -> #REF! | Q41: =(SCI!U15/(SFP!V42+SFP!W42)/SFP!V27) -> 0 | R41: =(SCI!V15/(SFP!W42+SFP!X42)/SFP!W27) -> 4.8036195e-13 | S41: =(SCI!W15/(SFP!X42+SFP!Y42)/SFP!X27) -> 9.5904248e-13 | T41: =(SCI!X15/(SFP!Y42+SFP!Z42)/SFP!Y27) -> 1.4189044e-12 | U41: =(SCI!Y15/(SFP!Z42+SFP!AA42)/SFP!Z27) -> 2.000432e-12 | V41: =(SCI!Z15/(SFP!AA42+SFP!AB42)/SFP!AA27) -> 2.5013822e-12 | W41: =(SCI!AA15/(SFP!AB42+SFP!AC42)/SFP!AB27) -> 2.9521837e-12 | X41: =(SCI!AB15/(SFP!AC42+SFP!AD42)/SFP!AC27) -> 4.3884261e-12 | ... BZ41: =(SCI!CD15/(SFP!CE42+SFP!CF42)/SFP!CE27) -> #DIV/0!
A42: FinCost-Ext Loans/Average Ext Loans | B42: NPR | D42: =(SCI!T14/(SFP!U39+SFP!#REF!)/SFP!U27) -> #REF! | E42: =(SCI!#REF!/(SFP!#REF!+SFP!#REF!)/SFP!#REF!) -> #REF! | F42: =(SCI!#REF!/(SFP!#REF!+SFP!#REF!)/SFP!#REF!) -> #REF! | G42: =(SCI!#REF!/(SFP!#REF!+SFP!#REF!)/SFP!#REF!) -> #REF! | H42: =(SCI!#REF!/(SFP!#REF!+SFP!#REF!)/SFP!#REF!) -> #REF! | I42: =(SCI!#REF!/(SFP!#REF!+SFP!#REF!)/SFP!#REF!) -> #REF! | J42: =(SCI!#REF!/(SFP!#REF!+SFP!#REF!)/SFP!#REF!) -> #REF! | K42: =(SCI!#REF!/(SFP!#REF!+SFP!#REF!)/SFP!#REF!) -> #REF! | L42: =(SCI!#REF!/(SFP!#REF!+SFP!#REF!)/SFP!#REF!) -> #REF! | ... O42: =(SCI!#REF!/(SFP!#REF!+SFP!#REF!)/SFP!#REF!) -> #REF! | P42: =(SCI!#REF!/(SFP!#REF!+SFP!V53)/SFP!#REF!) -> #REF! | Q42: =(SCI!U14/(SFP!V39+SFP!W53)/SFP!V27) -> 1.5857023e-12 | R42: =(SCI!V14/(SFP!W39+SFP!X53)/SFP!W27) -> 1.0530188e-13 | S42: =(SCI!W14/(SFP!X39+SFP!Y53)/SFP!X27) -> 2.7793185e-13 | T42: =(SCI!X14/(SFP!Y39+SFP!Z53)/SFP!Y27) -> 3.5502046e-13 | U42: =(SCI!Y14/(SFP!Z39+SFP!AA53)/SFP!Z27) -> 3.693807e-13 | V42: =(SCI!Z14/(SFP!AA39+SFP!AB53)/SFP!AA27) -> 4.243301e-13 | W42: =(SCI!AA14/(SFP!AB39+SFP!AC53)/SFP!AB27) -> 4.1373121e-13 | X42: =(SCI!AB14/(SFP!AC39+SFP!AD53)/SFP!AC27) -> 3.928136e-13 | ... BZ42: =(SCI!CD14/(SFP!CE39+SFP!CF53)/SFP!CE27) -> #DIV/0!
A43: OpEx/Average Total Assets | B43: NPR | D43: =SCI!T23/SFP!U27 -> 0.030348048 | E43: =SCI!#REF!/SFP!#REF! -> #REF! | F43: =SCI!#REF!/SFP!#REF! -> #REF! | G43: =SCI!#REF!/SFP!#REF! -> #REF! | H43: =SCI!#REF!/SFP!#REF! -> #REF! | I43: =SCI!#REF!/SFP!#REF! -> #REF! | J43: =SCI!#REF!/SFP!#REF! -> #REF! | K43: =SCI!#REF!/SFP!#REF! -> #REF! | L43: =SCI!#REF!/SFP!#REF! -> #REF! | ... P43: =SCI!#REF!/SFP!#REF! -> #REF! | Q43: =SCI!U23/SFP!V27 -> 0.030639167 | R43: =SCI!V23/SFP!W27 -> 0.002241998 | S43: =SCI!W23/SFP!X27 -> 0.0041844389 | T43: =SCI!X23/SFP!Y27 -> 0.0077121165 | U43: =SCI!Y23/SFP!Z27 -> 0.011427631 | V43: =SCI!Z23/SFP!AA27 -> 0.013509039 | W43: =SCI!AA23/SFP!AB27 -> 0.015158694 | X43: =SCI!AB23/SFP!AC27 -> 0.017169133 | ... BZ43: =SCI!CD23/SFP!CE27 -> #DIV/0!
