Workbook

Sheet Balance Sheet
B1: JAMII SACCO SOCIETY | Q1: =+V:V -> 0
B2: STATEMENT OF FINANCIAL POSITION
B3: FINANCIAL YEAR 2020 | C3: Jan | D3: Feb | E3: Mar | F3: Apr | G3: May | H3: Jun | I3: Jul | J3: Aug | K3: Sep | L3: Oct | M3: Nov | N3: Dec | O3: Aud-21 | P3: 44562 | Q3: 44593 | R3: 44621 | S3: 44652 | T3: 44682 | U3: 44713 | V3: 44743 | W3: 44774 | X3: 44805 | Y3: 44835 | Z3: 44866 | AA3: 44896 | AB3: 44927
A4: 1 | B4: Cash & Cash Equivalent | C4: =C5+C6 -> 1.3538988e+08 | D4: =D5+D6 -> 1.3112558e+08 | E4: =E5+E6 -> 1.3979133e+08 | F4: =F5+F6 -> 80204438 | G4: =G5+G6 -> 1.1373128e+08 | H4: =H5+H6 -> 2.0932728e+08 | I4: =I5+I6 -> 1.0485313e+08 | J4: =J5+J6 -> 1.3915132e+08 | ... AB4: =AB5+AB6 -> 962830488
A5: 1.1 | B5: Cash in hand(both local and foreign notes and coins) | C5: 31279115 | D5: 48127260 | E5: 37977415 | F5: 40077478 | G5: 30251499 | H5: 32422670 | I5: 32412927 | J5: 30878215 | K5: 39884446 | L5: 41553110 | M5: 32734773 | N5: 51067016 | O5: 11294294 | P5: 32909839 | Q5: 34036237 | R5: 34940335 | S5: 94164935 | T5: 12160944 | U5: 12344639 | V5: 8717409.6 | W5: 9616178.2 | X5: 11071927 | Y5: 6513818.8 | Z5: 9528453.7 | AA5: 9269846.5 | AB5: 4198511
A6: 1.2 | B6: Cash at bank:(placement with financial institutions) | C6: 1.0411077e+08 | D6: 82998318 | E6: 1.0181392e+08 | F6: 40126960 | G6: 83479781 | H6: 1.7690461e+08 | I6: 72440206 | J6: 1.0827311e+08 | K6: 1.581493e+08 | L6: 1.8178786e+08 | M6: 1.8515335e+08 | N6: 3.2028585e+08 | O6: 4.5095912e+08 | P6: 3.5028458e+08 | Q6: 2.757353e+08 | R6: 2.3776886e+08 | S6: 91371300 | T6: 1.4642135e+08 | U6: 2.003538e+08 | V6: 1.7277029e+08 | W6: 1.9141999e+08 | X6: 2.7368888e+08 | Y6: 1.7235934e+08 | Z6: 1.7100634e+08 | AA6: 1.683393e+08 | AB6: =962830488-4198511 -> 958631977
A7: 2 | B7: Prepayments & Sundry Receivables | C7: 16827815 | D7: 16854549 | E7: 16514528 | F7: 16640738 | G7: 16853397 | H7: 16890327 | I7: 17050970 | J7: 17176350 | K7: 16505983 | L7: 16542912 | M7: 16628413 | N7: 16629913 | O7: 48893961 | P7: 16697985 | Q7: 16773085 | R7: 16995228 | S7: 16694642 | T7: 17001286 | U7: 17236674 | V7: 17434299 | W7: 17619008 | X7: 16533164 | Y7: 16564307 | Z7: 16561807 | AA7: 15789218 | AB7: 52796232
A8: 3 | B8: Financial Investments | C8: =SUM(C9:C12) -> 5.1301281e+08 | D8: =SUM(D9:D12) -> 5.1312281e+08 | E8: =SUM(E9:E12) -> 4.8204902e+08 | F8: =SUM(F9:F12) -> 4.8215902e+08 | G8: =SUM(G9:G12) -> 4.3227902e+08 | H8: =SUM(H9:H12) -> 4.3064902e+08 | I8: =SUM(I9:I12) -> 4.8075902e+08 | J8: =SUM(J9:J12) -> 4.8086902e+08 | ... AB8: =SUM(AB9:AB12) -> 122325438
A9: 3.1 | B9: Government Securities - Treasury Bills/bonds, | C9: 0 | D9: 0 | E9: 0 | F9: 0 | G9: 0 | H9: 0 | I9: 0 | J9: 0 | K9: 0 | L9: 0 | M9: 0 | N9: 0 | P9: 0 | Q9: 0 | R9: 0 | S9: 0 | T9: 0 | U9: 0 | V9: 0 | W9: 0 | X9: 0 | Y9: 0 | Z9: 0 | AA9: 0
A10: 3.2 | B10: Other Securities - Commercial papers/Bonds | C10: 0 | D10: 0 | E10: 0 | F10: 0 | G10: 0 | H10: 0 | I10: 0 | J10: 0 | K10: 0 | L10: 0 | M10: 0 | N10: 0 | P10: 0 | Q10: 0 | R10: 0 | S10: 0 | T10: 0 | U10: 0 | V10: 0 | W10: 0 | X10: 0 | Y10: 0 | Z10: 0 | AA10: 0
A11: 3.3a | B11: Balances with other SACCO Societies | C11: 2.4127282e+08 | D11: 2.4138282e+08 | E11: 2.0630424e+08 | F11: 2.0641424e+08 | G11: 2.0653424e+08 | H11: 2.0490424e+08 | I11: 2.5501424e+08 | J11: 2.5512424e+08 | K11: 2.5523424e+08 | L11: 2.5349924e+08 | M11: 2.0544924e+08 | N11: 2.0751183e+08 | O11: 1.2209339e+08 | P11: 2.0751183e+08 | Q11: 2.0763183e+08 | R11: 2.0774183e+08 | S11: 2.1333393e+08 | T11: 2.3344393e+08 | U11: 2.3355393e+08 | V11: 2.3366393e+08 | W11: 2.3377393e+08 | X11: 2.3388393e+08 | Y11: 2.3399393e+08 | Z11: 2.3410393e+08 | AA11: 2.3421393e+08 | AB11: 122193386
A12: 3.3b | B12: Investments in companies - shares/stocks | C12: 2.7173999e+08 | D12: 2.7173999e+08 | E12: 2.7574478e+08 | F12: 2.7574478e+08 | G12: 2.2574478e+08 | H12: 2.2574478e+08 | I12: 2.2574478e+08 | J12: 2.2574478e+08 | K12: 2.2574478e+08 | L12: 2.2574478e+08 | M12: 3.1857274e+08 | N12: 3.2289028e+08 | O12: 3.2525309e+08 | P12: 3.2289028e+08 | Q12: 4.0289028e+08 | R12: 5.0289028e+08 | S12: 5.0525309e+08 | T12: 4.9312001e+08 | U12: 4.9312001e+08 | V12: 5.0036271e+08 | W12: 5.0036271e+08 | X12: 5.0036271e+08 | Y12: 6.0036271e+08 | Z12: 6.0036271e+08 | AA12: 6.2796232e+08 | AB12: 132052
A13: 4 | B13: Net Loan Portfolio | C13: =C14-C15 -> 3.8883889e+09 | D13: =D14-D15 -> 3.9328957e+09 | E13: =E14-E15 -> 3.9677061e+09 | F13: =F14-F15 -> 3.892842e+09 | G13: =G14-G15 -> 3.9379432e+09 | H13: =H14-H15 -> 3.93355e+09 | I13: =I14-I15 -> 4.0032915e+09 | J13: =J14-J15 -> 4.0416338e+09 | ... AB13: =AB14-AB15 -> 3971733824
A14: 4.1 | B14: Gross Loan Portfolio | C14: 4.122915e+09 | D14: 4.1674218e+09 | E14: 4.2022322e+09 | F14: 4.1273681e+09 | G14: 4.1724693e+09 | H14: 4.1680761e+09 | I14: 4.2378176e+09 | J14: 4.2761599e+09 | K14: 4.2844756e+09 | L14: 4.332006e+09 | M14: 4.3644751e+09 | N14: 4.3179048e+09 | O14: 4.318047e+09 | P14: 4.3442394e+09 | Q14: 4.3544537e+09 | R14: 4.3630507e+09 | S14: 4.2928083e+09 | T14: 4.3506076e+09 | U14: 4.3422299e+09 | V14: 4.3652313e+09 | W14: 4.3590049e+09 | X14: 4.3478436e+09 | Y14: 4.4083618e+09 | Z14: 4.4193841e+09 | AA14: 3.992287e+09 | AB14: 3992429178
A15: 4.2 | B15: Allowance for Loan Loss | C15: 2.345261e+08 | D15: 2.345261e+08 | E15: 2.345261e+08 | F15: 2.345261e+08 | G15: 2.345261e+08 | H15: 2.345261e+08 | I15: 2.345261e+08 | J15: 2.345261e+08 | K15: 2.345261e+08 | L15: 2.345261e+08 | M15: 2.345261e+08 | N15: 2.445261e+08 | O15: 2.845261e+08 | P15: 2.445261e+08 | Q15: 2.445261e+08 | R15: 2.445261e+08 | S15: 3.0530898e+08 | T15: 3.0530898e+08 | U15: 3.0530898e+08 | V15: 3.0530898e+08 | W15: 3.046104e+08 | X15: 3.046104e+08 | Y15: 3.046104e+08 | Z15: 3.046104e+08 | AA15: 20695354 | AB15: 20695354
A16: 5 | B16: Accounts Receivables | C16: =C17+C18+C19 -> 13007379 | D16: =D17+D18+D19 -> 12974904 | E16: =E17+E18+E19 -> 9976963.1 | F16: =F17+F18+F19 -> 0 | G16: =G17+G18+G19 -> 10837123 | H16: =H17+H18+H19 -> 11708382 | I16: =I17+I18+I19 -> 11711694 | J16: =J17+J18+J19 -> 11663107 | ... AE16: =AE17+AE18+AE19 -> 0
A17: 5.1 | B17: Tax Recoverable | C17: 0 | D17: 0 | E17: 0 | F17: 0 | G17: 10837123 | H17: 11708382 | I17: 11711694 | J17: 11663107 | K17: 12474650 | L17: 0 | M17: 13251686 | N17: 0 | P17: 0 | Q17: 13956388 | R17: 0 | S17: 0 | T17: 0 | U17: 0 | V17: 0 | W17: 0 | X17: 0 | Y17: 0 | Z17: 0 | AA17: 0
A18: 5.2 | B18: Deferred Tax Assets | C18: 13007379 | D18: 12974904 | E18: 9976963.1 | F18: 0 | G18: 0 | H18: 0 | I18: 0 | J18: 0 | K18: 0 | L18: 12455363 | M18: 0 | N18: 14115031 | O18: 10256378 | P18: 14029712 | Q18: 0 | R18: 14024670 | S18: 0 | T18: 12387372 | U18: 13251761 | V18: 13220498 | W18: 13226404 | X18: 14092585 | Y18: 14102150 | Z18: 14051054 | AA18: 14570278 | AB18: 6499338
A19: 5.3 | B19: Retirement Benefit Assets | C19: 0 | D19: 0 | E19: 0 | F19: 0 | G19: 0 | H19: 0 | I19: 0 | J19: 0 | K19: 0 | L19: 0 | M19: 0 | N19: 0 | P19: 0 | Q19: 0 | R19: 0 | S19: 0 | T19: 0 | U19: 0 | V19: 0 | W19: 0 | X19: 0 | Y19: 0 | Z19: 0 | AA19: 0
A20: 6 | B20: Property & Equipment & Other assets | C20: =SUM(C21:C25) -> 95527493 | D20: =SUM(D21:D25) -> 95527493 | E20: =SUM(E21:E25) -> 98694804 | F20: =SUM(F21:F25) -> 99677799 | G20: =SUM(G21:G25) -> 99802309 | H20: =SUM(H21:H25) -> 99856509 | I20: =SUM(I21:I25) -> 99856509 | J20: =SUM(J21:J25) -> 99856509 | ... AB20: =SUM(AB21:AB25) -> 3.269925e+08
A21: 6.1 | B21: Investment Properties | C21: 0 | D21: 0 | E21: 0 | F21: 0 | G21: 0 | H21: 0 | I21: 0 | J21: 0 | K21: 0 | L21: 0 | M21: 0 | N21: 0 | P21: 0 | Q21: 0 | R21: 0 | S21: 0 | T21: 0 | U21: 0 | V21: 0 | W21: 0 | X21: 0 | Y21: 0 | Z21: 0 | AA21: 0
A22: 6.2 | B22: Property & Equipment | C22: 66285950 | D22: 66285950 | E22: 69453260 | F22: 70436256 | G22: 70560766 | H22: 70614966 | I22: 70614966 | J22: 70614966 | K22: 70614966 | L22: 70614966 | M22: 70614966 | N22: 60804112 | O22: 60814112 | P22: 60804112 | Q22: 60804112 | R22: 60804112 | S22: 60814112 | T22: 60835412 | U22: 70471014 | V22: 70995952 | W22: 71075507 | X22: 68638905 | Y22: 68638905 | Z22: 68638905 | AA22: 64412981 | AB22: 46326425
A23: 6.3 | B23: Prepaid Lease rentals | C23: 28552631 | D23: 28552631 | E23: 28552631 | F23: 28552631 | G23: 28552631 | H23: 28552631 | I23: 28552631 | J23: 28552631 | K23: 28552631 | L23: 28552631 | M23: 28552631 | N23: 27838815 | O23: 27631577 | P23: 27838815 | Q23: 27838815 | R23: 27838815 | S23: 27631578 | T23: 27631578 | U23: 27631578 | V23: 27631578 | W23: 27631578 | X23: 27631578 | Y23: 27631578 | Z23: 27631578 | AA23: 26710525 | AB23: 26710525
A24: 6.4 | B24: Intangible Assets | C24: 0 | D24: 0 | E24: 0 | F24: 0 | G24: 0 | H24: 0 | I24: 0 | J24: 0 | K24: 0 | L24: 0 | M24: 0 | N24: 0 | P24: 0 | Q24: 0 | R24: 0 | S24: 0 | T24: 0 | U24: 0 | V24: 0 | W24: 0 | X24: 0 | Y24: 0 | Z24: 0 | AA24: 0 | AB24: 26438188
A25: 6.5 | B25: Other Assets | C25: 688912.18 | D25: 688912.18 | E25: 688912.18 | F25: 688912.18 | G25: 688912.18 | H25: 688912.18 | I25: 688912.18 | J25: 688912.18 | K25: 688912.18 | L25: 23251.98 | M25: 152027.78 | N25: 1249397.8 | O25: 1249397.8 | P25: 1243417.8 | Q25: 1242717.8 | R25: 1404733.8 | S25: 6054470.6 | T25: 6054470.6 | U25: 1912143 | V25: 1912143 | W25: 1912143 | X25: 1912143 | Y25: 1912143 | Z25: 1912143 | AA25: 2.2901613e+08 | AB25: =413372+227103991 -> 227517363
B26: Total Assets | C26: =C4+C7+C8+C13+C16+C20 -> 4.6621543e+09 | D26: =D4+D7+D8+D13+D16+D20 -> 4.702501e+09 | E26: =E4+E7+E8+E13+E16+E20 -> 4.7147327e+09 | F26: =F4+F7+F8+F13+F16+F20 -> 4.571524e+09 | G26: =G4+G7+G8+G13+G16+G20 -> 4.6114463e+09 | H26: =H4+H7+H8+H13+H16+H20 -> 4.7019816e+09 | I26: =I4+I7+I8+I13+I16+I20 -> 4.7175228e+09 | J26: =J4+J7+J8+J13+J16+J20 -> 4.7903501e+09 | ... AB26: =AB4+AB7+AB8+AB13+AB16+AB20 -> 5.4431778e+09
A27: 7 | B27: Savings Deposits - Withdrawable deposits - FOSA) | C27: 2.988705e+08 | D27: 2.7927583e+08 | E27: 2.6801859e+08 | F27: 3.6303309e+08 | G27: 3.2935868e+08 | H27: 3.1982291e+08 | I27: 3.1600407e+08 | J27: 2.9648294e+08 | K27: 3.0174047e+08 | L27: 3.1315081e+08 | M27: 3.1598697e+08 | N27: 3.060242e+08 | O27: 4.8897918e+08 | P27: 2.91646e+08 | Q27: 2.7727325e+08 | R27: 2.8374461e+08 | S27: 4.1729494e+08 | T27: 3.4445897e+08 | U27: 3.2443979e+08 | V27: 3.3646888e+08 | W27: 3.2137951e+08 | X27: 3.0945922e+08 | Y27: 3.3465821e+08 | Z27: 3.1969637e+08 | AA27: 3.0685273e+08 | AB27: 499703640
A28: 8 | B28: Short Term Deposits (e.g Fixed deposits, special savings) | C28: 27188604 | D28: 41678745 | E28: 40344961 | F28: 42852761 | G28: 44075338 | H28: 44276838 | I28: 50148838 | J28: 48396737 | K28: 48431737 | L28: 43979891 | M28: 34978951 | N28: 38939995 | P28: 39659184 | Q28: 44182596 | R28: 43924438 | S28: 43813699 | T28: 46044232 | U28: 45576995 | V28: 40398917 | W28: 43271125 | X28: 43116425 | Y28: 45911425 | Z28: 43737968 | AA28: 42830063
A29: 9 | B29: Non withdrawable deposits (BOSA member deposits) | C29: 3.1011724e+09 | D29: 3.1328854e+09 | E29: 3.1543848e+09 | F29: 3.1833637e+09 | G29: 3.2112928e+09 | H29: 3.200766e+09 | I29: 3.2296628e+09 | J29: 3.2484603e+09 | K29: 3.2761687e+09 | L29: 3.3077886e+09 | M29: 3.3476053e+09 | N29: 3.4036409e+09 | O29: 3.2596259e+09 | P29: 3.4203041e+09 | Q29: 3.4482502e+09 | R29: 3.4833511e+09 | S29: 3.5152658e+09 | T29: 3.5553864e+09 | U29: 3.5661464e+09 | V29: 3.5778793e+09 | W29: 3.5893805e+09 | X29: 3.6055411e+09 | Y29: 3.6220386e+09 | Z29: 3.6326952e+09 | AA29: 3.3083873e+09 | AB29: 3158371283
B30: Total Deposit liabilities | C30: =SUM(C27:C29) -> 3.4272315e+09 | D30: =SUM(D27:D29) -> 3.4538399e+09 | E30: =SUM(E27:E29) -> 3.4627484e+09 | F30: =SUM(F27:F29) -> 3.5892496e+09 | G30: =SUM(G27:G29) -> 3.5847268e+09 | H30: =SUM(H27:H29) -> 3.5648657e+09 | I30: =SUM(I27:I29) -> 3.5958157e+09 | J30: =SUM(J27:J29) -> 3.59334e+09 | ... AB30: =SUM(AB27:AB29) -> 3658074923
A31: 10 | B31: Accounts Payable & Other Liabilities | C31: =SUM(C32:C37) -> 3.9077193e+08 | D31: =SUM(D32:D37) -> 3.7162828e+08 | E31: =SUM(E32:E37) -> 371105085 | F31: =SUM(F32:F37) -> 18557296 | G31: =SUM(G32:G37) -> 31421570 | H31: =SUM(H32:H37) -> 86071787 | I31: =SUM(I32:I37) -> 40661149 | J31: =SUM(J32:J37) -> 92501007 | ... AB31: =SUM(AB32:AB37) -> 874557616
A32: 10.1 | B32: Tax Payable | C32: 0 | D32: 0 | E32: 0 | F32: 6544898.7 | G32: 0 | H32: 0 | I32: 0 | J32: 0 | K32: 0 | L32: 0 | M32: 0 | N32: 0 | P32: 0 | Q32: 0 | R32: 0 | S32: 7124079.5 | T32: 0 | U32: 0 | V32: 0 | W32: 0 | X32: 0 | Y32: 0 | Z32: 0 | AA32: 0
A33: 10.2 | B33: Dividends Payable | C33: 3.3873623e+08 | D33: 3.3873483e+08 | E33: 3.4909926e+08 | F33: 567400.82 | G33: 513678.82 | H33: 496854.82 | I33: 496854.82 | J33: 496854.82 | K33: 496854.82 | L33: 496854.82 | M33: 496854.82 | N33: 496854.82 | O33: 3.5373579e+08 | P33: 496854.82 | Q33: 496854.82 | R33: 496854.82 | S33: -21778542 | T33: -21998965 | U33: -22156127 | V33: -22162494 | W33: -22170055 | X33: -22228974 | Y33: -22228974 | Z33: -22228974 | AA33: -22306941 | AB33: =337189998+36026061 -> 373216059
A34: 10.3 | B34: Deferred Tax Liability | C34: 0 | D34: 0 | E34: 0 | F34: 0 | G34: 0 | H34: 0 | I34: 0 | J34: 0 | K34: 0 | L34: 0 | M34: 0 | N34: 0 | P34: 0 | Q34: 0 | R34: 0 | S34: 0 | T34: 0 | U34: 0 | V34: 0 | W34: 0 | X34: 0 | Y34: 0 | Z34: 0 | AA34: 0
A35: 10.4 | B35: Retirement Benefits Liability | C35: 0 | D35: 0 | E35: 0 | F35: 0 | G35: 0 | H35: 0 | I35: 0 | J35: 0 | K35: 0 | L35: 0 | M35: 0 | N35: 0 | P35: 0 | Q35: 0 | R35: 0 | S35: 0 | T35: 0 | U35: 0 | V35: 0 | W35: 0 | X35: 0 | Y35: 0 | Z35: 0 | AA35: 0
A36: 10.5 | B36: Other Liabilities | C36: 52035704 | D36: 32893449 | E36: 22005822 | F36: 11444996 | G36: 30907891 | H36: 85574933 | I36: 40164294 | J36: 92004152 | K36: 84732786 | L36: 81500713 | M36: 98293499 | N36: 59362784 | O36: 95432381 | P36: 78274141 | Q36: 44074788 | R36: 33428702 | S36: 492510 | T36: 66492280 | U36: 68554842 | V36: 28486872 | W36: 15173066 | X36: 45096688 | Y36: 21536564 | Z36: 4982914.7 | AA36: 4.1099655e+08 | AB36: =475334565+14440457+11566535 -> 501341557
A37: 10.6 | B37: External Borrowings | C37: 0 | D37: 0 | E37: 0 | F37: 0 | G37: 0 | H37: 0 | I37: 0 | J37: 0 | K37: 0 | L37: 0 | M37: 0 | N37: 0 | P37: 0 | Q37: 0 | R37: 0 | S37: 0 | T37: 0 | U37: 0 | V37: 0 | W37: 0 | X37: 0 | Y37: 0 | Z37: 0 | AA37: 0
B38: Total Liabilities | C38: =C30+C31 -> 3.8180034e+09 | D38: =D30+D31 -> 3.8254682e+09 | E38: =E30+E31 -> 3.8338535e+09 | F38: =F30+F31 -> 3607806859 | G38: =G30+G31 -> 3.6161484e+09 | H38: =H30+H31 -> 3.6509375e+09 | I38: =I30+I31 -> 3.6364769e+09 | J38: =J30+J31 -> 3.685841e+09 | ... AB38: =AB30+AB31 -> 4532632539
A39: 11 | B39: Share Capital (Members share capital per Bylaws) | C39: 1.9846475e+08 | D39: 2.0085832e+08 | E39: 2.0311138e+08 | F39: 2.3639846e+08 | G39: 2.3442261e+08 | H39: 2.3616693e+08 | I39: 2.3789426e+08 | J39: 2.3959834e+08 | K39: 2.4108061e+08 | L39: 2.4235171e+08 | M39: 2.4384621e+08 | N39: 2.4604456e+08 | O39: 2.4604456e+08 | P39: 2.4730803e+08 | Q39: 2.4854288e+08 | R39: 2.5056595e+08 | S39: 2.805752e+08 | T39: 2.8222965e+08 | U39: 2.8369952e+08 | V39: 2.8508204e+08 | W39: 2.8669136e+08 | X39: 2.8835376e+08 | Y39: 2.8948222e+08 | Z39: 2.9071014e+08 | AA39: 2.9224372e+08 | AB39: 2.9224372e+08
A40: 12 | B40: Capital Grants | C40: 0 | D40: 0 | E40: 0 | F40: 0 | G40: 0 | H40: 0 | I40: 0 | J40: 0 | K40: 0 | L40: 0 | M40: 0 | N40: 0 | P40: 0 | Q40: 0 | R40: 0 | S40: 0 | T40: 0 | U40: 0 | V40: 0 | W40: 0 | X40: 0 | Y40: 0 | Z40: 0 | AA40: 0
...

Sheet Income Stat.
A1: JAMII SACCO SOCIETY
A2: STATEMENT OF COMPREHENSIVE INCOME
A3: FINANCIAL YEAR 2020 | C3: Jan | D3: Feb | E3: Mar | F3: Apr | G3: May | H3: Jun | I3: Jul | J3: Aug | K3: Sep | L3: Oct | M3: Nov | N3: Dec | O3: Aud-21 | P3: 44562 | Q3: 44593 | R3: 44621 | S3: 44652 | T3: 44682 | U3: 44713 | V3: 44743 | W3: 44774 | X3: 44805 | Y3: 44835 | Z3: 44866 | AA3: 44896 | AB3: 44927 | AC3: 44958 | AD3: 44986
A4: 1 | B4: Financial Income | C4: 43309936 | D4: 92409923 | E4: 1.4385949e+08 | F4: 2.1540404e+08 | G4: 2.5639867e+08 | H4: 3.2490929e+08 | I4: 3.6893567e+08 | J4: 4.0711943e+08 | K4: 4.6487471e+08 | L4: 5.0828162e+08 | M4: 5.7379475e+08 | N4: 6.5861043e+08 | O4: =O5+O8 -> 6.6210617e+08 | P4: =P5+P8 -> 36013476 | Q4: =Q5+Q8 -> 81518886 | R4: =R5+R8 -> 1.4026381e+08 | S4: =S5+S8 -> 2.1933528e+08 | T4: =T5+T8 -> 2.6849838e+08 | U4: =U5+U8 -> 3.3612211e+08 | V4: =V5+V8 -> 3.814215e+08 | ... AB4: =AB5+AB8 -> 657859922
A5: 2 | B5: Financial Income from Loans Portfolio | C5: 41847106 | D5: 89541382 | E5: 1.4012892e+08 | F5: 2.0735378e+08 | G5: 2.4732478e+08 | H5: 3.0295656e+08 | I5: 3.4545685e+08 | J5: 3.8232006e+08 | K5: 4.3892116e+08 | L5: 4.8142547e+08 | M5: 5.258926e+08 | N5: 5.9944129e+08 | O5: =O6+O7 -> 6.0380602e+08 | P5: 34362243 | Q5: 79159053 | R5: 1.364551e+08 | S5: 2.1130745e+08 | T5: 2.5103055e+08 | U5: 2.9561522e+08 | V5: 3.3978241e+08 | W5: 3.8303553e+08 | X5: 4.2917183e+08 | Y5: 4.742406e+08 | Z5: 5.217306e+08 | AA5: 5.7521333e+08 | AB5: 579452977
A6: 2.1 | B6: Interest on Loan Portfolio | C6: 41847106 | D6: 89541382 | E6: 1.4012892e+08 | F6: 2.0735378e+08 | G6: 2.4732478e+08 | H6: 3.0295656e+08 | I6: 3.4545685e+08 | J6: 3.8232006e+08 | K6: 4.3892116e+08 | L6: 4.8142547e+08 | M6: 5.258926e+08 | N6: 5.9944129e+08 | O6: 6.0380602e+08 | P6: 34362243 | Q6: 79159053 | R6: 1.364551e+08 | S6: 2.1130745e+08 | T6: 2.5103055e+08 | U6: 2.9561522e+08 | V6: 3.3978241e+08 | W6: 3.8303553e+08 | X6: 4.2917183e+08 | Y6: 4.742406e+08 | Z6: 5.217306e+08 | AA6: 5.7521333e+08
A7: 2.2 | B7: Fees & Commission on Loan Portfolio | C7: 0 | D7: 0 | E7: 0 | F7: 0 | G7: 0 | H7: 0 | I7: 0 | J7: 0 | K7: 0 | L7: 0 | M7: 0 | N7: 0 | O7: 0 | P7: 0 | Q7: 0 | R7: 0 | S7: 0 | T7: 0 | U7: 0 | V7: 0 | W7: 0 | X7: 0 | Y7: 0 | Z7: 0 | AA7: 0
A8: 3 | B8: Financial Income from Investments in: | C8: 0 | D8: 317271 | E8: 326850.05 | F8: 2171850 | G8: 2171850 | H8: 15555880 | I8: 15565735 | J8: 15565735 | K8: 15565735 | L8: 15565735 | M8: 35379150 | N8: 43389283 | O8: =O9+O10+O11+O12 -> 58300151 | P8: =P9+P10+P11+P12 -> 1651232.8 | Q8: =Q9+Q10+Q11+Q12 -> 2359833.5 | R8: =R9+R10+R11+R12 -> 3808710.5 | S8: =S9+S10+S11+S12 -> 8027823.4 | T8: =T9+T10+T11+T12 -> 17467837 | U8: =U9+U10+U11+U12 -> 40506884 | V8: =V9+V10+V11+V12 -> 41639087 | ... AB8: =AB9+AB10+AB11+AB12 -> 78406945
A9: 3.1 | B9: Government Securities | C9: 0 | D9: 0 | E9: 0 | F9: 0 | G9: 0 | H9: 0 | I9: 0 | J9: 0 | K9: 0 | L9: 0 | M9: 0 | N9: 0 | P9: 0 | Q9: 0 | R9: 0 | S9: 0 | T9: 0 | U9: 0 | V9: 0 | W9: 0 | X9: 0 | Y9: 0 | Z9: 0 | AA9: 0
A10: 3.2 | B10: Deposit with Banks and Other Financial Inst. | C10: 0 | D10: 0 | E10: 0 | F10: 1845000 | G10: 1845000 | H10: 1845000 | I10: 1845000 | J10: 1845000 | K10: 1845000 | L10: 1845000 | M10: 21412957 | N10: 29315494 | O10: 32908833 | P10: 0 | Q10: 0 | R10: 0 | S10: 1845000 | T10: 9711925.1 | U10: 18694627 | V10: 18694627 | W10: 18694627 | X10: 18694627 | Y10: 18694627 | Z10: 18694627 | AA10: 46294238 | AB10: 51638444
A11: 3.3 | B11: Other Investments - dividend & Interest incomes from investments | C11: 0 | D11: 317271 | E11: 326850.05 | F11: 326850.05 | G11: 326850.05 | H11: 13710880 | I11: 13720735 | J11: 13720735 | K11: 13720735 | L11: 13720735 | M11: 13966193 | N11: 14073789 | O11: 15535602 | P11: 0 | Q11: 0 | R11: 11494.9 | S11: 11494.9 | T11: 11494.9 | U11: 12914537 | V11: 12914537 | W11: 12914537 | X11: 12914537 | Y11: 12914537 | Z11: 12914537 | AA11: 12914537 | AB11: 26768501
A12: 3.4 | B12: Other Operating Income- Salary processing fees, transaction fees, membership fees | C12: 1462829.4 | D12: 2551269.9 | E12: 3403726.4 | F12: 5878405 | G12: 6902038.8 | H12: 6396856.2 | I12: 7913089.3 | J12: 9233635.8 | K12: 10387808 | L12: 11290416 | M12: 12522999 | N12: 15779855 | O12: 9855716.9 | P12: 1651232.8 | Q12: 2359833.5 | R12: 3797215.6 | S12: 6171328.5 | T12: 7744417.3 | U12: 8897719.6 | V12: 10029923 | W12: 10805321 | X12: 12041264 | Y12: 12675391 | Z12: 13758129 | AA12: 17795166
A13: 4 | B13: Financial Expense | C13: 429286.68 | D13: 1072556.6 | E13: 1568692.4 | F13: 1641141.8 | G13: 1929575.3 | H13: 1958675.3 | I13: 1965695.3 | J13: 2296617.2 | K13: 2344112.2 | L13: 2787080.5 | M13: 3072208.2 | N13: 3118778.2 | O13: =O14+O15+O16+O17+O18+O19 -> 3.5685457e+08 | P13: =P14+P15+P16+P17+P18+P19 -> 554185.64 | Q13: =Q14+Q15+Q16+Q17+Q18+Q19 -> 1423744.9 | R13: =R14+R15+R16+R17+R18+R19 -> 1657194.9 | S13: =S14+S15+S16+S17+S18+S19 -> 1837591.4 | T13: =T14+T15+T16+T17+T18+T19 -> 2073504.9 | U13: =U14+U15+U16+U17+U18+U19 -> 2123600.5 | V13: =V14+V15+V16+V17+V18+V19 -> 2396785.9 | ... AB13: =AB14+AB15+AB16+AB17+AB18+AB19 -> 364771623
A14: 4.2 | B14: Interest Expense on Deposits | C14: 0 | D14: 0 | E14: 0 | F14: 0 | G14: 0 | H14: 0 | I14: 0 | J14: 0 | K14: 0 | L14: 0 | M14: 0 | N14: 0 | O14: 3.5685457e+08 | P14: 0 | Q14: 0 | R14: 0 | S14: 0 | T14: 0 | U14: 0 | V14: 0 | W14: 0 | X14: 0 | Y14: 0 | Z14: 0 | AA14: 0 | AB14: 362995573
A15: 4.3 | B15: Cost of External Borrowings | C15: 0 | D15: 0 | E15: 0 | F15: 0 | G15: 0 | H15: 0 | I15: 0 | J15: 0 | K15: 0 | L15: 0 | M15: 0 | N15: 0 | P15: 0 | Q15: 0 | R15: 0 | S15: 0 | T15: 0 | U15: 0 | V15: 0 | W15: 0 | X15: 0 | Y15: 0 | Z15: 0 | AA15: 0
A16: 4.4 | B16: Dividend Expenses (on member shares) | C16: 0 | D16: 0 | E16: 0 | F16: 0 | G16: 0 | H16: 0 | I16: 0 | J16: 0 | K16: 0 | L16: 0 | M16: 0 | N16: 0 | P16: 0 | Q16: 0 | R16: 0 | S16: 0 | T16: 0 | U16: 0 | V16: 0 | W16: 0 | X16: 0 | Y16: 0 | Z16: 0 | AA16: 0
A17: 4.5 | B17: Other Financial Expense | C17: 429286.68 | D17: 1072556.6 | E17: 1568692.4 | F17: 1641141.8 | G17: 1929575.3 | H17: 1958675.3 | I17: 1965695.3 | J17: 2296617.2 | K17: 2344112.2 | L17: 2787080.5 | M17: 3072208.2 | N17: 3118778.2 | P17: 554185.64 | Q17: 1423744.9 | R17: 1657194.9 | S17: 1837591.4 | T17: 2073504.9 | U17: 2123600.5 | V17: 2396785.9 | W17: 2556692.5 | X17: 2697992.5 | Y17: 2787992.5 | Z17: 3218639.2 | AA17: 3498633.2 | AB17: 1776050
A18: 4.6 | B18: Fees & Commission Expense | C18: 0 | D18: 0 | E18: 0 | F18: 0 | G18: 0 | H18: 0 | I18: 0 | J18: 0 | K18: 0 | L18: 0 | M18: 0 | N18: 0 | P18: 0 | Q18: 0 | R18: 0 | S18: 0 | T18: 0 | U18: 0 | V18: 0 | W18: 0 | X18: 0 | Y18: 0 | Z18: 0 | AA18: 0
A19: 4.7 | B19: Other Expense | C19: 0 | D19: 0 | E19: 0 | F19: 0 | G19: 0 | H19: 0 | I19: 0 | J19: 0 | K19: 0 | L19: 0 | M19: 0 | N19: 0 | P19: 0 | Q19: 0 | R19: 0 | S19: 0 | T19: 0 | U19: 0 | V19: 0 | W19: 0 | X19: 0 | Y19: 0 | Z19: 0 | AA19: 0
A20: 5 | B20: Net Financial Income/(Loss) | C20: 42880649 | D20: 91337366 | E20: 1.422908e+08 | F20: 2.137629e+08 | G20: 2.5446909e+08 | H20: 3.2295062e+08 | I20: 3.6696998e+08 | J20: 4.0482282e+08 | K20: 4.625306e+08 | L20: 5.0549454e+08 | M20: 5.7072254e+08 | N20: 6.5549165e+08 | O20: =O4-O13 -> 3.0525161e+08 | P20: =P4-P13 -> 35459290 | Q20: =Q4-Q13 -> 80095141 | R20: =R4-R13 -> 1.3860662e+08 | S20: =S4-S13 -> 2.1749769e+08 | T20: =T4-T13 -> 2.6642488e+08 | U20: =U4-U13 -> 3.339985e+08 | V20: =V4-V13 -> 3.7902471e+08 | ... AB20: =AB4-AB13 -> 293088299
A21: 6 | B21: Allowance for Loan Loss | C21: 0 | D21: 0 | E21: 0 | F21: 0 | G21: 0 | H21: 0 | I21: 0 | J21: 0 | K21: 0 | L21: 0 | M21: 0 | N21: 10000000 | O21: =O22-O23 -> 50000000 | P21: =P22-P23 -> 0 | Q21: =Q22-Q23 -> 0 | R21: =R22-R23 -> 0 | S21: =S22-S23 -> 0 | T21: =T22-T23 -> 0 | U21: =U22-U23 -> 0 | V21: =V22-V23 -> 0 | ... AB21: =AB22-AB23 -> 20000000
A22: 6.1 | B22: Provision for Loan Losses | C22: 0 | D22: 0 | E22: 0 | F22: 0 | G22: 0 | H22: 0 | I22: 0 | J22: 0 | K22: 0 | L22: 0 | M22: 0 | N22: 10000000 | O22: 50000000 | P22: 0 | Q22: 0 | R22: 0 | S22: 0 | T22: 0 | U22: 0 | V22: 0 | W22: 0 | X22: 0 | Y22: 0 | Z22: 0 | AA22: 20000000 | AB22: 20000000
A23: 6.2 | B23: Value of Loans Recovered | C23: 0 | D23: 0 | E23: 0 | F23: 0 | G23: 0 | H23: 0 | I23: 0 | J23: 0 | K23: 0 | L23: 0 | M23: 0 | N23: 0 | P23: 0 | Q23: 0 | R23: 0 | S23: 0 | T23: 0 | U23: 0 | V23: 0 | W23: 0 | X23: 0 | Y23: 0 | Z23: 0 | AA23: 0
A24: 7 | B24: Operating Expenses | C24: 15671901 | D24: 33640314 | E24: 43721282 | F24: 65642605 | G24: 72792157 | H24: 87271846 | I24: 1.0301667e+08 | J24: 1.1911041e+08 | K24: 1.365808e+08 | L24: 1.4570753e+08 | M24: 1.900699e+08 | N24: 1.8342836e+08 | O24: =O25+O26+O27+O28+O29 -> 1.8754347e+08 | P24: =P25+P26+P27+P28+P29 -> 20485373 | Q24: =Q25+Q26+Q27+Q28+Q29 -> 33340926 | R24: =R25+R26+R27+R28+R29 -> 52446435 | S24: =S25+S26+S27+S28+S29 -> 70211002 | T24: =T25+T26+T27+T28+T29 -> 97425468 | U24: =U25+U26+U27+U28+U29 -> 1.0620641e+08 | V24: =V25+V26+V27+V28+V29 -> 1.312873e+08 | ... AB24: =AB25+AB26+AB27+AB28+AB29 -> 222359048
A25: 7.1 | B25: Personnel Expenses | C25: 6686475 | D25: 12744693 | E25: 18959598 | F25: 26270822 | G25: 32370250 | H25: 37119634 | I25: 44306330 | J25: 54805313 | K25: 61862049 | L25: 66447100 | M25: 76979354 | N25: 84077731 | O25: 88374501 | P25: 6767045.8 | Q25: 13186874 | R25: 22446304 | S25: 29365467 | T25: 38138352 | U25: 45122755 | V25: 55985379 | W25: 63791232 | X25: 70449821 | Y25: 76801359 | Z25: 84877858 | AA25: 92153642 | AB25: 96243768
A26: 7.2 | B26: Governance Expenses | C26: 790398 | D26: 5651098 | E26: 6873675 | F26: 14824799 | G26: 15369653 | H26: 16983381 | I26: 17804244 | J26: 19067210 | K26: 22647331 | L26: 23535653 | M26: 25050666 | N26: 25042416 | O26: 24493516 | P26: 3287686 | Q26: 4988976 | R26: 10468807 | S26: 16567999 | T26: 21327289 | U26: 22894940 | V26: 26231782 | W26: 27548988 | X26: 31219087 | Y26: 33109421 | Z26: 34267973 | AA26: 35645098 | AB26: =14016127+21628970 -> 35645097
A27: 7.3 | B27: Marketing Expenses | C27: 328490 | D27: 663958 | E27: 712118 | F27: 751248 | G27: 910812 | H27: 1649100.3 | I27: 3128880.3 | J27: 3837093.8 | K27: 3892973.8 | L27: 4677570.7 | M27: 6986208.7 | N27: 7600558.4 | O27: 7620558.4 | P27: 1025120.1 | Q27: 1974231.7 | R27: 3197260.9 | S27: 3820759.9 | T27: 7685021.1 | U27: 8653011.8 | V27: 10813451 | W27: 14923950 | X27: 15363064 | Y27: 15598645 | Z27: 16033272 | AA27: 19384103 | AB27: 19384103
A28: 7.4 | B28: Depreciation and Amortization Charges | C28: 0 | D28: 0 | E28: 0 | F28: 0 | G28: 0 | H28: 0 | I28: 0 | J28: 500 | K28: 500 | L28: 500 | M28: 500 | N28: 10525171 | O28: 10731908 | P28: 0 | Q28: 0 | R28: 0 | S28: 0 | T28: 0 | U28: 0 | V28: 0 | W28: 0 | X28: 0 | Y28: 0 | Z28: 0 | AA28: 11630777 | AB28: 11630777
A29: 7.5 | B29: Administrative Expenses | C29: 7866538.5 | D29: 14580565 | E29: 17175891 | F29: 23795736 | G29: 24141442 | H29: 31519730 | I29: 37777218 | J29: 41400296 | K29: 48177947 | L29: 51046708 | M29: 81053173 | N29: 56182487 | O29: 56322987 | P29: 9405521.1 | Q29: 13190844 | R29: 16334063 | S29: 20456776 | T29: 30274805 | U29: 29535704 | V29: 38256683 | W29: 42063005 | X29: 44121728 | Y29: 48535780 | Z29: 52466241 | AA29: 59775372 | AB29: =90470183-11630777-19384103 -> 59455303
A30: 8 | B30: Net Operating Income | C30: =C20-C24 -> 27208747 | D30: =D20-D24 -> 57697052 | E30: =E20-E24 -> 98569518 | F30: =F20-F24 -> 1.4812029e+08 | G30: =G20-G24 -> 1.8167694e+08 | H30: =H20-H24 -> 2.3567877e+08 | I30: =I20-I24 -> 2.6395331e+08 | J30: =J20-J24 -> 2.857124e+08 | ... AA30: =AA20-AA24 -> 4.3012964e+08 | AB30: =AB20-AB21-AB24 -> 50729251
A31: 9 | B31: Net Non- Operating Income/ (Expense) | C31: 0 | D31: 0 | E31: 0 | F31: 0 | G31: 0 | H31: 0 | I31: 0 | J31: 0 | K31: 0 | L31: 0 | M31: 0 | N31: 0 | O31: =O32-O33 -> 0 | P31: 0 | Q31: 0 | R31: 0 | S31: 0 | T31: 0 | U31: 0 | V31: 0 | W31: 0 | X31: 0 | Y31: 0 | Z31: 0 | AA31: 0
A32: 9.1 | B32: Non- Operating Income | C32: 0 | D32: 0 | E32: 0 | F32: 0 | G32: 0 | H32: 0 | I32: 0 | J32: 0 | K32: 0 | L32: 0 | M32: 0 | N32: 0 | P32: 0 | Q32: 0 | R32: 0 | S32: 0 | T32: 0 | U32: 0 | V32: 0 | W32: 0 | X32: 0 | Y32: 0 | Z32: 0 | AA32: 0
A33: 9.2 | B33: Non- Operating Expense | C33: 0 | D33: 0 | E33: 0 | F33: 0 | G33: 0 | H33: 0 | I33: 0 | J33: 0 | K33: 0 | L33: 0 | M33: 0 | N33: 0 | P33: 0 | Q33: 0 | R33: 0 | S33: 0 | T33: 0 | U33: 0 | V33: 0 | W33: 0 | X33: 0 | Y33: 0 | Z33: 0 | AA33: 0
A34: 10 | B34: Net Income (Before Taxes and Donations) | C34: 27208747 | D34: 57697052 | E34: 98569518 | F34: 1.4812029e+08 | G34: 1.8167694e+08 | H34: 2.3567877e+08 | I34: 2.6395331e+08 | J34: 2.857124e+08 | K34: 3.259498e+08 | L34: 3.5978701e+08 | M34: 3.8065264e+08 | N34: 4.6206329e+08 | O34: =O30-O31 -> 1.1770814e+08 | P34: =P30-P31 -> 14973917 | Q34: =Q30-Q31 -> 46754215 | R34: =R30-R31 -> 86160183 | S34: =S30-S31 -> 1.4728668e+08 | T34: =T30-T31 -> 1.6899941e+08 | U34: =U30-U31 -> 2.2779209e+08 | V34: =V30-V31 -> 2.4773741e+08 | ... AB34: =AB30-AB31 -> 50729251
A35: 11 | B35: Taxes (Incomes taxes & Other payable to KRA) | C35: 0 | D35: 0 | E35: 0 | F35: 0 | G35: 0 | H35: 0 | I35: 0 | J35: 0 | K35: 0 | L35: 0 | M35: 0 | N35: 0 | O35: 3146101.7 | P35: 0 | Q35: 0 | R35: 0 | S35: 0 | T35: 0 | U35: 0 | V35: 0 | W35: 0 | X35: 0 | Y35: 0 | Z35: 0 | AA35: 0
A36: 12 | B36: Net Income (After Taxes before Donations) | C36: 27208747 | D36: 57697052 | E36: 98569518 | F36: 1.4812029e+08 | G36: 1.8167694e+08 | H36: 2.3567877e+08 | I36: 2.6395331e+08 | J36: 2.857124e+08 | K36: 3.259498e+08 | L36: 3.5978701e+08 | M36: 3.8065264e+08 | N36: 4.6206329e+08 | O36: =O34-O35 -> 1.1456204e+08 | P36: =P34-P35 -> 14973917 | Q36: =Q34-Q35 -> 46754215 | R36: =R34-R35 -> 86160183 | S36: =S34-S35 -> 1.4728668e+08 | T36: =T34-T35 -> 1.6899941e+08 | U36: =U34-U35 -> 2.2779209e+08 | V36: =V34-V35 -> 2.4773741e+08 | ... AB36: =AB34-AB35 -> 50729251
A37: 13 | B37: Donations | C37: 0 | D37: 0 | E37: 0 | F37: 0 | G37: 0 | H37: 0 | I37: 0 | J37: 0 | K37: 0 | L37: 0 | M37: 0 | N37: 0 | P37: 0 | Q37: 0 | R37: 0 | S37: 0 | T37: 0 | U37: 0 | V37: 0 | W37: 0 | X37: 0 | Y37: 0 | Z37: 0 | AA37: 0
A38: 14 | B38: Net Income/(After Taxes and Donations) | C38: 27208747 | D38: 57697052 | E38: 98569518 | F38: 1.4812029e+08 | G38: 1.8167694e+08 | H38: 2.3567877e+08 | I38: 2.6395331e+08 | J38: 2.857124e+08 | K38: 3.259498e+08 | L38: 3.5978701e+08 | M38: 3.8065264e+08 | N38: 4.6206329e+08 | O38: =O36-O37 -> 1.1456204e+08 | P38: =P36-P37 -> 14973917 | Q38: =Q36-Q37 -> 46754215 | R38: =R36-R37 -> 86160183 | S38: =S36-S37 -> 1.4728668e+08 | T38: =T36-T37 -> 1.6899941e+08 | U38: =U36-U37 -> 2.2779209e+08 | V38: =V36-V37 -> 2.4773741e+08 | ... AB38: =AB36-AB37 -> 50729251

Sheet Form 4
C6: FORM 4
E29: 44348
C30: CLASSIFICATION | D30: NO. OF A/Cs | E30: OUTSTANDING LOAN PORTFOLIO(Kshs) | F30: REQUIRED PROVISION | G30: REQUIRED PROVISION AMOUNT(Kshs)
C31: Performing | D31: 16101 | E31: 3.5400636e+09 | F31: 0.01 | G31: =E31*F31 -> 35400636
C32: Watch | D32: 1040 | E32: 2.8993494e+08 | F32: 0.05 | G32: =E32*F32 -> 14496747
C33: Substandard | D33: 1464 | E33: 1.8458271e+08 | F33: 0.25 | G33: =E33*F33 -> 46145678
C34: Doubtful | D34: 406 | E34: 1.3317314e+08 | F34: 0.5 | G34: =E34*F34 -> 66586572
C35: Loss | D35: 775 | E35: 2.6086212e+08 | F35: 1 | G35: =E35*F35 -> 2.6086212e+08
C36: subtotal | D36: =SUM(D31:D35) -> 19786 | E36: =SUM(E31:E35) -> 4.4086166e+09 | F36: 1.81 | G36: =SUM(G31:G35) -> 4.2349176e+08
E38: =E33+E34+E35 -> 5.7861798e+08
E39: =E38/E36 -> 0.13124706
E41: Aud-21
C42: Ageing for impairement of loans
D43: No.of loans | E43: Outstanding Portfolio | F43: Rate
G44: PAR | I44: PAR
C45: Performing | D45: 9165 | E45: 1.8952641e+09 | F45: 1% | G45: =E45*F45 -> 18952641 | I45: 33772054
C46: Watch | D46: 1368 | E46: 3.3728356e+08 | F46: 5% | G46: =E46*F46 -> 16864178 | I46: 15230338
C47: Substandard | D47: 3556 | E47: 8.5105985e+08 | F47: 25% | G47: =E47*F47 -> 2.1276496e+08 | I47: 57087294
C48: Doubtful | D48: 2408 | E48: 4.5597962e+08 | F48: 50% | G48: =E48*F48 -> 2.2798981e+08 | I48: 48207557
C49: Loss | D49: =3943+1499 -> 5442 | E49: =778051453.98+408430.33 -> 7.7845988e+08 | F49: 100% | G49: =E49*F49 -> 7.7845988e+08 | I49: 80228859
C50: Current Loan portofolio | D50: =SUM(D45:D49) -> 21939 | E50: =SUM(E45:E49) -> 4.318047e+09 | G50: =SUM(G45:G49) -> 1.2550315e+09 | I50: 2.345261e+08
E52: =E47+E48+E49 -> 2.0854994e+09
E53: =E52/E50 -> 0.48297282
E54: 44621
C55: CLASSIFICATION | D55: NO. OF A/Cs | E55: OUTSTANDING LOAN PORTFOLIO(Kshs) | F55: REQUIRED PROVISION | G55: REQUIRED PROVISION AMOUNT(Kshs)
C56: Performing | D56: 9240 | E56: 2.29332e+09 | F56: 0.01 | G56: =E56*F56 -> 22933200
C57: Watch | D57: 1227 | E57: 3.3644533e+08 | F57: 0.05 | G57: =E57*F57 -> 16822267
C58: Substandard | D58: 3263 | E58: 7.4872951e+08 | F58: 0.25 | G58: =E58*F58 -> 1.8718238e+08
C59: Doubtful | D59: 2493 | E59: 3.9830754e+08 | F59: 0.5 | G59: =E59*F59 -> 1.9915377e+08
C60: Loss | D60: 4355 | E60: 8.357435e+08 | F60: 1 | G60: =E60*F60 -> 8.357435e+08
C61: subtotal | D61: =SUM(D56:D60) -> 20578 | E61: =SUM(E56:E60) -> 4612545857 | F61: 1.81 | G61: =SUM(G56:G60) -> 1.2618351e+09
E63: =E60+E59+E58 -> 1.9827805e+09
E64: =E63/E61 -> 0.42986685
E68: Aud-22
C69: CLASSIFICATION | D69: NO. OF A/Cs | E69: OUTSTANDING LOAN PORTFOLIO(Kshs) | F69: REQUIRED PROVISION | G69: REQUIRED PROVISION AMOUNT(Kshs)
C70: Performing | D70: 12045 | E70: 2535713603 | F70: 0.01 | G70: =E70*F70 -> 25357136
C71: Watch | D71: 1873 | E71: 570077198 | F71: 0.05 | G71: =E71*F71 -> 28503860
C72: Substandard | D72: 2291 | E72: 696737247 | F72: 0.25 | G72: =E72*F72 -> 1.7418431e+08
C73: Doubtful | D73: 310 | E73: 68757017 | F73: 0.5 | G73: =E73*F73 -> 34378508
C74: Loss | D74: 689 | E74: 121144113 | F74: 1 | G74: =E74*F74 -> 121144113
...

Sheet Financials
A1: ASILI SACCO FINANCIALS
A3: Year/month | B3: Jan | C3: Feb | D3: Mar | E3: Apr | F3: May | G3: Jun | H3: Jul | I3: Aug | J3: Sep | K3: Oct | L3: Nov | M3: Dec | N3: Aud-21 | O3: 44562 | P3: 44593 | Q3: 44621 | R3: 44652 | S3: 44682 | T3: 44713 | U3: 44743 | V3: 44774 | W3: 44805 | X3: 44835 | Y3: 44866 | Z3: 44896
A4: Membership
A5: Total Assets | B5: ='Balance Sheet'!C26 -> 4.6621543e+09 | C5: ='Balance Sheet'!D26 -> 4.702501e+09 | D5: ='Balance Sheet'!E26 -> 4.7147327e+09 | E5: ='Balance Sheet'!F26 -> 4.571524e+09 | F5: ='Balance Sheet'!G26 -> 4.6114463e+09 | G5: ='Balance Sheet'!H26 -> 4.7019816e+09 | H5: ='Balance Sheet'!I26 -> 4.7175228e+09 | I5: ='Balance Sheet'!J26 -> 4.7903501e+09 | ... AW5: ='Balance Sheet'!AX26 -> 0
A6: Total Deposits | B6: =B7+B8 -> 3.4000429e+09 | C6: =C7+C8 -> 3.4121612e+09 | D6: =D7+D8 -> 3.4224034e+09 | E6: =E7+E8 -> 3.5463968e+09 | F6: =F7+F8 -> 3.5406515e+09 | G6: =G7+G8 -> 3.5205889e+09 | H6: =H7+H8 -> 3.5456669e+09 | I6: =I7+I8 -> 3.5449433e+09 | ... AW6: =AW7+AW8 -> 0
A7: Deposits-Members(BOSA) | B7: ='Balance Sheet'!C29 -> 3.1011724e+09 | C7: ='Balance Sheet'!D29 -> 3.1328854e+09 | D7: ='Balance Sheet'!E29 -> 3.1543848e+09 | E7: ='Balance Sheet'!F29 -> 3.1833637e+09 | F7: ='Balance Sheet'!G29 -> 3.2112928e+09 | G7: ='Balance Sheet'!H29 -> 3.200766e+09 | H7: ='Balance Sheet'!I29 -> 3.2296628e+09 | I7: ='Balance Sheet'!J29 -> 3.2484603e+09 | ... AW7: ='Balance Sheet'!AX29 -> 0
A8: Deposits-Customers(FOSA) | B8: ='Balance Sheet'!C27 -> 2.988705e+08 | C8: ='Balance Sheet'!D27 -> 2.7927583e+08 | D8: ='Balance Sheet'!E27 -> 2.6801859e+08 | E8: ='Balance Sheet'!F27 -> 3.6303309e+08 | F8: ='Balance Sheet'!G27 -> 3.2935868e+08 | G8: ='Balance Sheet'!H27 -> 3.1982291e+08 | H8: ='Balance Sheet'!I27 -> 3.1600407e+08 | I8: ='Balance Sheet'!J27 -> 2.9648294e+08 | ... AW8: ='Balance Sheet'!AX27 -> 0
A9: Deposits-Term | B9: ='Balance Sheet'!C28 -> 27188604 | C9: ='Balance Sheet'!D28 -> 41678745 | D9: ='Balance Sheet'!E28 -> 40344961 | E9: ='Balance Sheet'!F28 -> 42852761 | F9: ='Balance Sheet'!G28 -> 44075338 | G9: ='Balance Sheet'!H28 -> 44276838 | H9: ='Balance Sheet'!I28 -> 50148838 | I9: ='Balance Sheet'!J28 -> 48396737 | ... AW9: ='Balance Sheet'!AX28 -> 0
A10: External Borrowing | B10: ='Balance Sheet'!C38 -> 3.8180034e+09 | C10: ='Balance Sheet'!D38 -> 3.8254682e+09 | D10: ='Balance Sheet'!E38 -> 3.8338535e+09 | E10: ='Balance Sheet'!F38 -> 3607806859 | F10: ='Balance Sheet'!G38 -> 3.6161484e+09 | G10: ='Balance Sheet'!H38 -> 3.6509375e+09 | H10: ='Balance Sheet'!I38 -> 3.6364769e+09 | I10: ='Balance Sheet'!J37 -> 0 | J10: ='Balance Sheet'!K37 -> 0 | K10: ='Balance Sheet'!L37 -> 0 | L10: ='Balance Sheet'!M37 -> 0 | M10: ='Balance Sheet'!N37 -> 0 | N10: ='Balance Sheet'!O37 -> 0 | O10: ='Balance Sheet'!P38 -> 3.8303803e+09 | P10: ='Balance Sheet'!Q38 -> 3.8142776e+09 | Q10: ='Balance Sheet'!R38 -> 3.8449457e+09 | R10: ='Balance Sheet'!S38 -> 3.9622125e+09 | S10: ='Balance Sheet'!T38 -> 3.9903829e+09 | T10: ='Balance Sheet'!U38 -> 3.9825619e+09 | U10: ='Balance Sheet'!V38 -> 3.9610715e+09 | V10: ='Balance Sheet'!W38 -> 3.9470341e+09 | ... AW10: ='Balance Sheet'!AX38 -> 0
A12: Share capital and Reserves
A13: Core Capital | B13: =B15-B28 -> 4.4695926e+08 | C13: =C15-C28 -> 4.7984114e+08 | D13: =D15-D28 -> 5.1490397e+08 | E13: =E15-E28 -> 5.9774182e+08 | F13: =F15-F28 -> 6.7932262e+08 | G13: =G15-G28 -> 7.3506878e+08 | H13: =H15-H28 -> 7.6507064e+08 | I13: =I15-I28 -> 1.0142786e+09 | ... AW13: =AW15-AW28 -> 0
A14: Institutional Capital | B14: =B13-B16 -> 2.4849451e+08 | C14: =C13-C16 -> 2.7898282e+08 | D14: =D13-D16 -> 3.1179259e+08 | E14: =E13-E16 -> 3.6134337e+08 | F14: =F13-F16 -> 4.4490001e+08 | G14: =G13-G16 -> 4.9890185e+08 | H14: =H13-H16 -> 5.2717638e+08 | I14: =I13-I16 -> 7.7468026e+08 | ... AW14: =AW13-AW16 -> 0
A15: Total Capital | B15: =B16+B17+B18+B19+B20+B21 -> 7.1869925e+08 | C15: =C16+C17+C18+C19+C20+C21 -> 7.5158113e+08 | D15: =D16+D17+D18+D19+D20+D21 -> 7.9064876e+08 | E15: =E16+E17+E18+E19+E20+E21 -> 8.7348661e+08 | F15: =F16+F17+F18+F19+F20+F21 -> 9.0506741e+08 | G15: =G16+G17+G18+G19+G20+G21 -> 9.6081356e+08 | H15: =H16+H17+H18+H19+H20+H21 -> 9.9081542e+08 | I15: =I16+I17+I18+I19+I20+I21 -> 1.0142786e+09 | ... AW15: =AW16+AW17+AW18+AW19+AW20+AW21 -> 0
A16: Members Share Capital | B16: ='Balance Sheet'!C39 -> 1.9846475e+08 | C16: ='Balance Sheet'!D39 -> 2.0085832e+08 | D16: ='Balance Sheet'!E39 -> 2.0311138e+08 | E16: ='Balance Sheet'!F39 -> 2.3639846e+08 | F16: ='Balance Sheet'!G39 -> 2.3442261e+08 | G16: ='Balance Sheet'!H39 -> 2.3616693e+08 | H16: ='Balance Sheet'!I39 -> 2.3789426e+08 | I16: ='Balance Sheet'!J39 -> 2.3959834e+08 | ... AA16: ='Balance Sheet'!AB39 -> 2.9224372e+08 | AB16: ='Balance Sheet'!AC40 -> 0 | AC16: ='Balance Sheet'!AD40 -> 0 | AD16: ='Balance Sheet'!AE40 -> 0 | AE16: ='Balance Sheet'!AF40 -> 0 | AF16: ='Balance Sheet'!AG40 -> 0 | AG16: ='Balance Sheet'!AH40 -> 0 | AH16: ='Balance Sheet'!AI40 -> 0 | AI16: ='Balance Sheet'!AJ40 -> 0 | ... AW16: ='Balance Sheet'!AX40 -> 0
A17: Entrance Fees
A18: Retained Earnings | B18: ='Balance Sheet'!C41 -> 2.1560997e+08 | C18: ='Balance Sheet'!D41 -> 2.4609828e+08 | D18: ='Balance Sheet'!E41 -> 2.7953053e+08 | E18: ='Balance Sheet'!F41 -> 3.290813e+08 | F18: ='Balance Sheet'!G41 -> 3.6263795e+08 | G18: ='Balance Sheet'!H41 -> 4.1663978e+08 | H18: ='Balance Sheet'!I41 -> 4.4491432e+08 | I18: ='Balance Sheet'!J41 -> 4.6667341e+08 | ... AW18: ='Balance Sheet'!AX41 -> 0
A19: Appropriation Account | B19: ='Balance Sheet'!C48 -> 0 | C19: ='Balance Sheet'!D48 -> 0 | D19: ='Balance Sheet'!E48 -> 0 | E19: ='Balance Sheet'!F48 -> 0 | F19: ='Balance Sheet'!G48 -> 0 | G19: ='Balance Sheet'!H48 -> 0 | H19: ='Balance Sheet'!I48 -> 0 | I19: ='Balance Sheet'!J48 -> 0 | ... AW19: ='Balance Sheet'!AX48 -> 0
A20: Statutory Reserves | B20: ='Balance Sheet'!C45 -> 1.2280721e+08 | C20: ='Balance Sheet'!D45 -> 1.2280721e+08 | D20: ='Balance Sheet'!E45 -> 1.2618953e+08 | E20: ='Balance Sheet'!F45 -> 1.2618953e+08 | F20: ='Balance Sheet'!G45 -> 1.2618953e+08 | G20: ='Balance Sheet'!H45 -> 1.2618953e+08 | H20: ='Balance Sheet'!I45 -> 1.2618953e+08 | I20: ='Balance Sheet'!J45 -> 1.2618953e+08 | ... AW20: ='Balance Sheet'!AX45 -> 0
A21: Capital Reserves | B21: ='Balance Sheet'!C46 -> 1.8181732e+08 | C21: ='Balance Sheet'!D46 -> 1.8181732e+08 | D21: ='Balance Sheet'!E46 -> 1.8181732e+08 | E21: ='Balance Sheet'!F46 -> 1.8181732e+08 | F21: ='Balance Sheet'!G46 -> 1.8181732e+08 | G21: ='Balance Sheet'!H46 -> 1.8181732e+08 | H21: ='Balance Sheet'!I46 -> 1.8181732e+08 | I21: ='Balance Sheet'!J46 -> 1.8181732e+08 | ... AW21: ='Balance Sheet'!AX46 -> 0
A22: Supplementary Capital & reserves
A23: Proposed Dividends
A24: Benevolent Fund
A25: Investments | B25: =B26+B27+B29 -> 7.5428564e+08 | C25: =C26+C27+C29 -> 7.5450564e+08 | D25: =D26+D27+D29 -> 6.8835326e+08 | E25: =E26+E27+E29 -> 6.8857326e+08 | F25: =F26+F27+F29 -> 6.3881326e+08 | G25: =G26+G27+G29 -> 6.3555326e+08 | H25: =H26+H27+H29 -> 7.3577326e+08 | I25: =I26+I27+I29 -> 7.3599326e+08 | ... AW25: =AW26+AW27+AW29 -> 0
A26: Govt bills | B26: ='Balance Sheet'!C8 -> 5.1301281e+08 | C26: ='Balance Sheet'!D8 -> 5.1312281e+08 | D26: ='Balance Sheet'!E8 -> 4.8204902e+08 | E26: ='Balance Sheet'!F8 -> 4.8215902e+08 | F26: ='Balance Sheet'!G8 -> 4.3227902e+08 | G26: ='Balance Sheet'!H8 -> 4.3064902e+08 | H26: ='Balance Sheet'!I8 -> 4.8075902e+08 | I26: ='Balance Sheet'!J8 -> 4.8086902e+08 | ... AW26: ='Balance Sheet'!AX8 -> 0
A27: Investments in naccos | B27: ='Balance Sheet'!C11 -> 2.4127282e+08 | C27: ='Balance Sheet'!D11 -> 2.4138282e+08 | D27: ='Balance Sheet'!E11 -> 2.0630424e+08 | E27: ='Balance Sheet'!F11 -> 2.0641424e+08 | F27: ='Balance Sheet'!G11 -> 2.0653424e+08 | G27: ='Balance Sheet'!H11 -> 2.0490424e+08 | H27: ='Balance Sheet'!I11 -> 2.5501424e+08 | I27: ='Balance Sheet'!J11 -> 2.5512424e+08 | ... AW27: ='Balance Sheet'!AX11 -> 0
A28: Equity Investments (at cost) | B28: ='Balance Sheet'!C12 -> 2.7173999e+08 | C28: ='Balance Sheet'!D12 -> 2.7173999e+08 | D28: ='Balance Sheet'!E12 -> 2.7574478e+08 | E28: ='Balance Sheet'!F12 -> 2.7574478e+08 | F28: ='Balance Sheet'!G12 -> 2.2574478e+08 | G28: ='Balance Sheet'!H12 -> 2.2574478e+08 | H28: ='Balance Sheet'!I12 -> 2.2574478e+08 | I28: ='Balance Sheet'!J9 -> 0 | J28: ='Balance Sheet'!K9 -> 0 | K28: ='Balance Sheet'!L9 -> 0 | L28: ='Balance Sheet'!M9 -> 0 | M28: ='Balance Sheet'!N9 -> 0 | N28: ='Balance Sheet'!O9 -> 0 | O28: ='Balance Sheet'!P9 -> 0 | P28: ='Balance Sheet'!Q9 -> 0 | ... AW28: ='Balance Sheet'!AX9 -> 0
A29: Deposits in KUSCCO CFP | B29: ='Balance Sheet'!C10 -> 0 | C29: ='Balance Sheet'!D10 -> 0 | D29: ='Balance Sheet'!E10 -> 0 | E29: ='Balance Sheet'!F10 -> 0 | F29: ='Balance Sheet'!G10 -> 0 | G29: ='Balance Sheet'!H10 -> 0 | H29: ='Balance Sheet'!I10 -> 0 | I29: ='Balance Sheet'!J10 -> 0 | ... AW29: ='Balance Sheet'!AX10 -> 0
A30: Net Loans & Advances | B30: =B31-B32 -> 3.8883889e+09 | C30: =C31-C32 -> 3.9328957e+09 | D30: =D31-D32 -> 3.9677061e+09 | E30: =E31-E32 -> 3.892842e+09 | F30: =F31-F32 -> 3.9379432e+09 | G30: =G31-G32 -> 3.93355e+09 | H30: =H31-H32 -> 4.0032915e+09 | I30: =I31-I32 -> 4.0416338e+09 | ... AW30: =AW31-AW32 -> 0
A31: Gross Loans & advances | B31: ='Balance Sheet'!C14 -> 4.122915e+09 | C31: ='Balance Sheet'!D14 -> 4.1674218e+09 | D31: ='Balance Sheet'!E14 -> 4.2022322e+09 | E31: ='Balance Sheet'!F14 -> 4.1273681e+09 | F31: ='Balance Sheet'!G14 -> 4.1724693e+09 | G31: ='Balance Sheet'!H14 -> 4.1680761e+09 | H31: ='Balance Sheet'!I14 -> 4.2378176e+09 | I31: ='Balance Sheet'!J14 -> 4.2761599e+09 | ... AW31: ='Balance Sheet'!AX14 -> 0
A32: Allowance for loan losses | B32: ='Balance Sheet'!C15 -> 2.345261e+08 | C32: ='Balance Sheet'!D15 -> 2.345261e+08 | D32: ='Balance Sheet'!E15 -> 2.345261e+08 | E32: ='Balance Sheet'!F15 -> 2.345261e+08 | F32: ='Balance Sheet'!G15 -> 2.345261e+08 | G32: ='Balance Sheet'!H15 -> 2.345261e+08 | H32: ='Balance Sheet'!I15 -> 2.345261e+08 | I32: ='Balance Sheet'!J15 -> 2.345261e+08 | ... AW32: ='Balance Sheet'!AX15 -> 0
A34: Non-Earning Assets | B34: ='Balance Sheet'!C6+'Balance Sheet'!C15+'Balance Sheet'!C19 -> 3.3863687e+08 | C34: ='Balance Sheet'!D6+'Balance Sheet'!D15+'Balance Sheet'!D19 -> 3.1752442e+08 | D34: ='Balance Sheet'!E6+'Balance Sheet'!E15+'Balance Sheet'!E19 -> 3.3634002e+08 | E34: ='Balance Sheet'!F6+'Balance Sheet'!F15+'Balance Sheet'!F19 -> 2.7465306e+08 | F34: ='Balance Sheet'!G6+'Balance Sheet'!G15+'Balance Sheet'!G19 -> 3.1800588e+08 | G34: ='Balance Sheet'!H6+'Balance Sheet'!H15+'Balance Sheet'!H19 -> 4.1143071e+08 | H34: ='Balance Sheet'!I6+'Balance Sheet'!I15+'Balance Sheet'!I19 -> 3.0696631e+08 | I34: ='Balance Sheet'!J6+'Balance Sheet'!J15+'Balance Sheet'!J19 -> 3.4279921e+08 | ... AW34: ='Balance Sheet'!AX6+'Balance Sheet'!AX15+'Balance Sheet'!AX19 -> 0
A35: Property and Equipment | B35: ='Balance Sheet'!C19 -> 0 | C35: ='Balance Sheet'!D19 -> 0 | D35: ='Balance Sheet'!E19 -> 0 | E35: ='Balance Sheet'!F19 -> 0 | F35: ='Balance Sheet'!G19 -> 0 | G35: ='Balance Sheet'!H19 -> 0 | H35: ='Balance Sheet'!I19 -> 0 | I35: ='Balance Sheet'!J19 -> 0 | ... AW35: ='Balance Sheet'!AX19 -> 0
A38: Turnover | B38: =B39+B41+B42 -> 41847106 | C38: =C39+C41+C42 -> 89858653 | D38: =D39+D41+D42 -> 1.4045577e+08 | E38: =E39+E41+E42 -> 2.0952563e+08 | F38: =F39+F41+F42 -> 2.4949663e+08 | G38: =G39+G41+G42 -> 3.1851244e+08 | H38: =H39+H41+H42 -> 3.6102259e+08 | I38: =I39+I41+I42 -> 3.978858e+08 | ... AW38: =AW39+AW41+AW42 -> 0
A39: Loan Interest | B39: ='Income Stat.'!C6 -> 41847106 | C39: ='Income Stat.'!D6 -> 89541382 | D39: ='Income Stat.'!E6 -> 1.4012892e+08 | E39: ='Income Stat.'!F6 -> 2.0735378e+08 | F39: ='Income Stat.'!G6 -> 2.4732478e+08 | G39: ='Income Stat.'!H6 -> 3.0295656e+08 | H39: ='Income Stat.'!I6 -> 3.4545685e+08 | I39: ='Income Stat.'!J6 -> 3.8232006e+08 | ... AW39: ='Income Stat.'!AX6 -> 0
A40: Yield on loans | B40: ='Income Stat.'!C6/'Income Stat.'!C14 -> #DIV/0! | C40: ='Income Stat.'!D6/'Income Stat.'!D14 -> #DIV/0! | D40: ='Income Stat.'!E6/'Income Stat.'!E14 -> #DIV/0! | E40: ='Income Stat.'!F6/'Income Stat.'!F14 -> #DIV/0! | F40: ='Income Stat.'!G6/'Income Stat.'!G14 -> #DIV/0! | G40: ='Income Stat.'!H6/'Income Stat.'!H14 -> #DIV/0! | H40: ='Income Stat.'!I6/'Income Stat.'!I14 -> #DIV/0! | I40: ='Income Stat.'!J6/'Income Stat.'!J14 -> #DIV/0! | ... AW40: ='Income Stat.'!AX6/'Income Stat.'!AX14 -> #DIV/0!
A41: Income from investments | B41: ='Income Stat.'!C8 -> 0 | C41: ='Income Stat.'!D8 -> 317271 | D41: ='Income Stat.'!E8 -> 326850.05 | E41: ='Income Stat.'!F8 -> 2171850 | F41: ='Income Stat.'!G8 -> 2171850 | G41: ='Income Stat.'!H8 -> 15555880 | H41: ='Income Stat.'!I8 -> 15565735 | I41: ='Income Stat.'!J8 -> 15565735 | ... AW41: ='Income Stat.'!AX8 -> 0
A42: Fees & Commissions | B42: ='Income Stat.'!C7 -> 0 | C42: ='Income Stat.'!D7 -> 0 | D42: ='Income Stat.'!E7 -> 0 | E42: ='Income Stat.'!F7 -> 0 | F42: ='Income Stat.'!G7 -> 0 | G42: ='Income Stat.'!H7 -> 0 | H42: ='Income Stat.'!I7 -> 0 | I42: ='Income Stat.'!J7 -> 0 | ... AW42: ='Income Stat.'!AX7 -> 0
A44: Finanacial and Operating costs | B44: =B45+B46+B47+B48 -> 27208747 | C44: =C45+C46+C47+C48 -> 57697052 | D44: =D45+D46+D47+D48 -> 98569518 | E44: =E45+E46+E47+E48 -> 1.4812029e+08 | F44: =F45+F46+F47+F48 -> 1.8167694e+08 | G44: =G45+G46+G47+G48 -> 2.3567877e+08 | H44: =H45+H46+H47+H48 -> 2.6395331e+08 | I44: =I45+I46+I47+I48 -> 2.857124e+08 | ... AW44: =AW45+AW46+AW47+AW48 -> 0
A45: Interest expense on deposits | B45: ='Income Stat.'!C14 -> 0 | C45: ='Income Stat.'!D14 -> 0 | D45: ='Income Stat.'!E14 -> 0 | E45: ='Income Stat.'!F14 -> 0 | F45: ='Income Stat.'!G14 -> 0 | G45: ='Income Stat.'!H14 -> 0 | H45: ='Income Stat.'!I14 -> 0 | I45: ='Income Stat.'!J14 -> 0 | ... AW45: ='Income Stat.'!AX14 -> 0
A46: Dividend expense on share capital | B46: ='Income Stat.'!C16 -> 0 | C46: ='Income Stat.'!D16 -> 0 | D46: ='Income Stat.'!E16 -> 0 | E46: ='Income Stat.'!F16 -> 0 | F46: ='Income Stat.'!G16 -> 0 | G46: ='Income Stat.'!H16 -> 0 | H46: ='Income Stat.'!I16 -> 0 | I46: ='Income Stat.'!J16 -> 0 | ... AW46: ='Income Stat.'!AX16 -> 0
...

Sheet CAEL
A1: JAMII SACCO CAELS 2020
C2: Regulatory Stds | D2: Jan | E2: Feb | F2: Mar | G2: Apr | H2: May | I2: Jun | J2: Jul | K2: Aug | L2: Sep | M2: Oct | N2: Nov | O2: Dec | P2: Aud-21 | Q2: 44562 | R2: 44593 | S2: 44621 | T2: 44652 | U2: 44682 | V2: 44713 | W2: 44743 | X2: 44774 | Y2: 44805 | Z2: 44835 | AA2: 44866 | AB2: 44896 | AC2: Aud-22
A3: CAPITAL ADEQUACY | B3: Core Capital | C3: 10 M | D3: =Financials!B13 -> 4.4695926e+08 | E3: =Financials!C13 -> 4.7984114e+08 | F3: =Financials!D13 -> 5.1490397e+08 | G3: =Financials!E13 -> 5.9774182e+08 | H3: =Financials!F13 -> 6.7932262e+08 | I3: =Financials!G13 -> 7.3506878e+08 | J3: =Financials!H13 -> 7.6507064e+08 | K3: =Financials!I13 -> 1.0142786e+09 | ... AN3: =Financials!AL13 -> 0
B4: CCA | C4: 0.1 | D4: =Financials!B13/Financials!B5 -> 0.095869685 | E4: =Financials!C13/Financials!C5 -> 0.10203956 | F4: =Financials!D13/Financials!D5 -> 0.1092117 | G4: =Financials!E13/Financials!E5 -> 0.13075329 | H4: =Financials!F13/Financials!F5 -> 0.14731227 | I4: =Financials!G13/Financials!G5 -> 0.1563317 | J4: =Financials!H13/Financials!H5 -> 0.16217635 | K4: =Financials!I13/Financials!I5 -> 0.21173371 | ... AN4: =Financials!AL13/Financials!AL5 -> #DIV/0!
B5: CCD | C5: 0.08 | D5: =Financials!B13/Financials!B6 -> 0.13145695 | E5: =Financials!C13/Financials!C6 -> 0.14062675 | F5: =Financials!D13/Financials!D6 -> 0.15045099 | G5: =Financials!E13/Financials!E6 -> 0.16854905 | H5: =Financials!F13/Financials!F6 -> 0.19186374 | I5: =Financials!G13/Financials!G6 -> 0.20879143 | J5: =Financials!H13/Financials!H6 -> 0.21577623 | K5: =Financials!I13/Financials!I6 -> 0.28611984 | ... AN5: =Financials!AL13/Financials!AL6 -> #DIV/0!
B6: ICA | C6: 0.08 | D6: =(Financials!B13-Financials!B16)/Financials!B5 -> 0.053300362 | E6: =(Financials!C13-Financials!C16)/Financials!C5 -> 0.059326477 | F6: =(Financials!D13-Financials!D16)/Financials!D5 -> 0.066131552 | G6: =(Financials!E13-Financials!E16)/Financials!E5 -> 0.079042212 | H6: =(Financials!F13-Financials!F16)/Financials!F5 -> 0.096477326 | I6: =(Financials!G13-Financials!G16)/Financials!G5 -> 0.10610459 | J6: =(Financials!H13-Financials!H16)/Financials!H5 -> 0.11174856 | K6: =(Financials!I15-Financials!I16)/Financials!I5 -> 0.16171684 | L6: =(Financials!J15-Financials!J16)/Financials!J5 -> 0.16775449 | M6: =(Financials!K15-Financials!K16)/Financials!K5 -> 0.17222222 | N6: =(Financials!L15-Financials!L16)/Financials!L5 -> 0.17388728 | O6: =(Financials!M15-Financials!M16)/Financials!M5 -> 0.18663145 | P6: =(Financials!N15-Financials!N16)/Financials!N5 -> 0.10871218 | Q6: =(Financials!O15-Financials!O16)/Financials!O5 -> 0.18816116 | R6: =(Financials!P15-Financials!P16)/Financials!P5 -> 0.19371327 | ... AN6: =(Financials!AL15-Financials!AL16)/Financials!AL5 -> #DIV/0!
A7: ASSET QUALITY | B7: A/LNPL30 | AB7: 0.22 | AC7: 0.22
B8: NPL30 | I8: 0.13 | J8: 1.13 | P8: 0.48 | S8: 0.43
B9: Non-earning Asset ratio | C9: Max 10% | D9: =('Balance Sheet'!C7+'Balance Sheet'!C20)/'Balance Sheet'!C26 -> 0.02409944 | E9: =('Balance Sheet'!D7+'Balance Sheet'!D20)/'Balance Sheet'!D26 -> 0.023898356 | F9: =('Balance Sheet'!E7+'Balance Sheet'!E20)/'Balance Sheet'!E26 -> 0.024436026 | G9: =('Balance Sheet'!F7+'Balance Sheet'!F20)/'Balance Sheet'!F26 -> 0.025444149 | H9: =('Balance Sheet'!G7+'Balance Sheet'!G20)/'Balance Sheet'!G26 -> 0.025296989 | I9: =('Balance Sheet'!H7+'Balance Sheet'!H20)/'Balance Sheet'!H26 -> 0.024829284 | J9: =('Balance Sheet'!I7+'Balance Sheet'!I20)/'Balance Sheet'!I26 -> 0.02478154 | K9: =('Balance Sheet'!J7+'Balance Sheet'!J20)/'Balance Sheet'!J26 -> 0.024430961 | ... AN9: =('Balance Sheet'!AM7+'Balance Sheet'!AM20)/'Balance Sheet'!AM26 -> #DIV/0!
B10: Land and Building ratio | C10: Max 5% | D10: =('Balance Sheet'!C21+'Balance Sheet'!C22)/'Balance Sheet'!C26 -> 0.01421788 | E10: =('Balance Sheet'!D21+'Balance Sheet'!D22)/'Balance Sheet'!D26 -> 0.014095893 | F10: =('Balance Sheet'!E21+'Balance Sheet'!E22)/'Balance Sheet'!E26 -> 0.014731113 | G10: =('Balance Sheet'!F21+'Balance Sheet'!F22)/'Balance Sheet'!F26 -> 0.015407609 | H10: =('Balance Sheet'!G21+'Balance Sheet'!G22)/'Balance Sheet'!G26 -> 0.015301222 | I10: =('Balance Sheet'!H21+'Balance Sheet'!H22)/'Balance Sheet'!H26 -> 0.015018129 | J10: =('Balance Sheet'!I21+'Balance Sheet'!I22)/'Balance Sheet'!I26 -> 0.014968654 | K10: =('Balance Sheet'!J21+'Balance Sheet'!J22)/'Balance Sheet'!J26 -> 0.014741087 | ... AN10: =('Balance Sheet'!AM21+'Balance Sheet'!AM22)/'Balance Sheet'!AM26 -> #DIV/0!
A11: EARNINGS | B11: Non-Government Investment to Deposit ratio | C11: Max 5% | D11: ='Balance Sheet'!C11/'Balance Sheet'!C29 -> 0.077800521 | E11: ='Balance Sheet'!D11/'Balance Sheet'!D29 -> 0.077048087 | F11: ='Balance Sheet'!E11/'Balance Sheet'!E29 -> 0.065402368 | G11: ='Balance Sheet'!F11/'Balance Sheet'!F29 -> 0.06484155 | H11: ='Balance Sheet'!G11/'Balance Sheet'!G29 -> 0.064314981 | I11: ='Balance Sheet'!H11/'Balance Sheet'!H29 -> 0.064017251 | J11: ='Balance Sheet'!I11/'Balance Sheet'!I29 -> 0.078960019 | K11: ='Balance Sheet'!J11/'Balance Sheet'!J29 -> 0.078536972 | ... AN11: ='Balance Sheet'!AM11/'Balance Sheet'!AM29 -> #DIV/0!
B12: Non-Government Investment to Core Capital ratio | C12: Max 40% | D12: ='Balance Sheet'!C11/Financials!B13 -> 0.53980943 | E12: ='Balance Sheet'!D11/Financials!C13 -> 0.50304738 | F12: ='Balance Sheet'!E11/Financials!D13 -> 0.40066546 | G12: ='Balance Sheet'!F11/Financials!E13 -> 0.3453234 | H12: ='Balance Sheet'!G11/Financials!F13 -> 0.30402968 | I12: ='Balance Sheet'!H11/Financials!G13 -> 0.27875519 | J12: ='Balance Sheet'!I11/Financials!H13 -> 0.33332117 | K12: ='Balance Sheet'!J11/Financials!I13 -> 0.2515327 | ... AN12: ='Balance Sheet'!AM11/Financials!AL13 -> #DIV/0!
B13: Gross loans/TA | D13: =Financials!B31/Financials!B5 -> 0.88433689 | E13: =Financials!C31/Financials!C5 -> 0.8862139 | F13: =Financials!D31/Financials!D5 -> 0.89129807 | G13: =Financials!E31/Financials!E5 -> 0.90284293 | H13: =Financials!F31/Financials!F5 -> 0.90480708 | I13: =Financials!G31/Financials!G5 -> 0.88645098 | J13: =Financials!H31/Financials!H5 -> 0.89831417 | K13: =Financials!I31/Financials!I5 -> 0.89266125 | ... AN13: =Financials!AL31/Financials!AL5 -> #DIV/0!
B14: ROA | D14: ='Income Stat.'!C38/Financials!B5 -> 0.005836089 | E14: ='Income Stat.'!D38/Financials!C5 -> 0.01226944 | F14: ='Income Stat.'!E38/Financials!D5 -> 0.020906703 | G14: ='Income Stat.'!F38/Financials!E5 -> 0.032400637 | H14: ='Income Stat.'!G38/Financials!F5 -> 0.039396953 | I14: ='Income Stat.'!H38/Financials!G5 -> 0.050123287 | J14: ='Income Stat.'!I38/Financials!H5 -> 0.055951676 | K14: ='Income Stat.'!J38/Financials!I5 -> 0.059643324 | ... AN14: ='Income Stat.'!AM38/Financials!AL5 -> #DIV/0!
B15: Cost Income ratio | D15: ='Income Stat.'!C24/('Income Stat.'!C20-'Income Stat.'!C22) -> 0.36547725 | E15: ='Income Stat.'!D24/('Income Stat.'!D20-'Income Stat.'!D22) -> 0.36830834 | F15: ='Income Stat.'!E24/('Income Stat.'!E20-'Income Stat.'!E22) -> 0.3072671 | G15: ='Income Stat.'!F24/('Income Stat.'!F20-'Income Stat.'!F22) -> 0.30708138 | H15: ='Income Stat.'!G24/('Income Stat.'!G20-'Income Stat.'!G22) -> 0.286055 | I15: ='Income Stat.'!H24/('Income Stat.'!H20-'Income Stat.'!H22) -> 0.27023279 | J15: ='Income Stat.'!I24/('Income Stat.'!I20-'Income Stat.'!I22) -> 0.28072234 | K15: ='Income Stat.'!J24/('Income Stat.'!J20-'Income Stat.'!J22) -> 0.29422851 | ... AN15: ='Income Stat.'!AM24/('Income Stat.'!AM20-'Income Stat.'!AM22) -> #DIV/0!
B16: Operating Expense ratio | D16: ='Income Stat.'!C24/'Income Stat.'!C4 -> 0.36185465 | E16: ='Income Stat.'!D24/'Income Stat.'!D4 -> 0.36403357 | F16: ='Income Stat.'!E24/'Income Stat.'!E4 -> 0.30391656 | G16: ='Income Stat.'!F24/'Income Stat.'!F4 -> 0.30474176 | H16: ='Income Stat.'!G24/'Income Stat.'!G4 -> 0.28390224 | I16: ='Income Stat.'!H24/'Income Stat.'!H4 -> 0.26860372 | J16: ='Income Stat.'!I24/'Income Stat.'!I4 -> 0.27922665 | K16: ='Income Stat.'!J24/'Income Stat.'!J4 -> 0.29256872 | ... AN16: ='Income Stat.'!AM24/'Income Stat.'!AM4 -> #DIV/0!
A17: LIQUIDITY | B17: MIN LIQ ratio | C17: Min 15% | D17: ='Balance Sheet'!C4/'Balance Sheet'!C27 -> 0.45300518 | E17: ='Balance Sheet'!D4/'Balance Sheet'!D27 -> 0.46951997 | F17: ='Balance Sheet'!E4/'Balance Sheet'!E27 -> 0.52157326 | G17: ='Balance Sheet'!F4/'Balance Sheet'!F27 -> 0.22092873 | H17: ='Balance Sheet'!G4/'Balance Sheet'!G27 -> 0.34531132 | I17: ='Balance Sheet'!H4/'Balance Sheet'!H27 -> 0.65450996 | J17: ='Balance Sheet'!I4/'Balance Sheet'!I27 -> 0.33180944 | K17: ='Balance Sheet'!J4/'Balance Sheet'!J27 -> 0.46934007 | ... AN17: ='Balance Sheet'!AM4/'Balance Sheet'!AM27 -> #DIV/0!
B18: Technical LIQ ratio | D18: ='Balance Sheet'!C4/'Balance Sheet'!C29 -> 0.043657646 | E18: ='Balance Sheet'!D4/'Balance Sheet'!D29 -> 0.041854572 | F18: ='Balance Sheet'!E4/'Balance Sheet'!E29 -> 0.044316511 | G18: ='Balance Sheet'!F4/'Balance Sheet'!F29 -> 0.025194871 | H18: ='Balance Sheet'!G4/'Balance Sheet'!G29 -> 0.035416041 | I18: ='Balance Sheet'!H4/'Balance Sheet'!H29 -> 0.06539912 | J18: ='Balance Sheet'!I4/'Balance Sheet'!I29 -> 0.032465659 | K18: ='Balance Sheet'!J4/'Balance Sheet'!J29 -> 0.042836085 | ... AN18: ='Balance Sheet'!AM4/'Balance Sheet'!AM29 -> #DIV/0!
B19: External Borrowing ratio | C19: Max 25% | D19: ='Balance Sheet'!C37/'Balance Sheet'!C26 -> 0 | E19: ='Balance Sheet'!D37/'Balance Sheet'!D26 -> 0 | F19: ='Balance Sheet'!E37/'Balance Sheet'!E26 -> 0 | G19: ='Balance Sheet'!F37/'Balance Sheet'!F26 -> 0 | H19: ='Balance Sheet'!G37/'Balance Sheet'!G26 -> 0 | I19: ='Balance Sheet'!H37/'Balance Sheet'!H26 -> 0 | J19: ='Balance Sheet'!I37/'Balance Sheet'!I26 -> 0 | K19: ='Balance Sheet'!J37/'Balance Sheet'!J26 -> 0 | ... AJ19: ='Balance Sheet'!AI37/'Balance Sheet'!AI26 -> #DIV/0! | AK19: ='Balance Sheet'!AJ38/'Balance Sheet'!AJ26 -> #DIV/0! | AL19: ='Balance Sheet'!AK38/'Balance Sheet'!AK26 -> #DIV/0! | AM19: ='Balance Sheet'!AL38/'Balance Sheet'!AL26 -> #DIV/0! | AN19: ='Balance Sheet'!AM38/'Balance Sheet'!AM26 -> #DIV/0!
