Workbook
Name BALANCE1_LDA01: '[1]Financial Statements'!$E$112
Name BALANCE1_LDA12: '[1]Financial Statements'!$E$123
Name BALANCE2_LDA01: '[1]Financial Statements'!$F$112
Name BALANCE2_LDA12: '[1]Financial Statements'!$F$123
Name BALANCE3_LDA01: '[1]Financial Statements'!$G$112
Name BALANCE3_LDA12: '[1]Financial Statements'!$G$123
Name BALANCE4_LDA01: '[1]Financial Statements'!$H$112
Name BALANCE4_LDA12: '[1]Financial Statements'!$H$123
Name BALANCE5_LDA01: '[1]Financial Statements'!$I$112
Name BALANCE5_LDA12: '[1]Financial Statements'!$I$123
Name BALANCE6_LDA01: '[1]Financial Statements'!$J$112
Name BALANCE6_LDA12: '[1]Financial Statements'!$J$123
Name PEARLS1_LA002: '[1]Financial Statements'!$E$280
Name PEARLS1_LE008: '[1]Financial Statements'!$E$275
Name PEARLS1_LE009: '[1]Financial Statements'!$E$276
Name PEARLS1_LR001: '[1]Financial Statements'!$E$282
Name PEARLS1_LR005: '[1]Financial Statements'!$E$286
Name PEARLS1_LR006: '[1]Financial Statements'!$E$287
Name PEARLS1_LR007: '[1]Financial Statements'!$E$288
Name PEARLS1_LR009: '[1]Financial Statements'!$E$290
Name PEARLS1_LS001: '[1]Financial Statements'!$E$298
Name PEARLS1_LS005: '[1]Financial Statements'!$E$302
Name PEARLS1_LS011: '[1]Financial Statements'!$E$308
Name PEARLS2_LA002: '[1]Financial Statements'!$F$280
Name PEARLS2_LE008: '[1]Financial Statements'!$F$275
Name PEARLS2_LE009: '[1]Financial Statements'!$F$276
Name PEARLS2_LR001: '[1]Financial Statements'!$F$282
Name PEARLS2_LR005: '[1]Financial Statements'!$F$286
Name PEARLS2_LR006: '[1]Financial Statements'!$F$287
Name PEARLS2_LR007: '[1]Financial Statements'!$F$288
Name PEARLS2_LR009: '[1]Financial Statements'!$F$290
Name PEARLS2_LS001: '[1]Financial Statements'!$F$298
Name PEARLS2_LS005: '[1]Financial Statements'!$F$302
Name PEARLS2_LS010: '[1]Financial Statements'!$F$307
Name PEARLS2_LS011: '[1]Financial Statements'!$F$308
Name PEARLS3_LA002: '[1]Financial Statements'!$G$280
Name PEARLS3_LE008: '[1]Financial Statements'!$G$275
Name PEARLS3_LE009: '[1]Financial Statements'!$G$276
Name PEARLS3_LR001: '[1]Financial Statements'!$G$282
Name PEARLS3_LR005: '[1]Financial Statements'!$G$286
Name PEARLS3_LR006: '[1]Financial Statements'!$G$287
Name PEARLS3_LR007: '[1]Financial Statements'!$G$288
Name PEARLS3_LR009: '[1]Financial Statements'!$G$290
Name PEARLS3_LS001: '[1]Financial Statements'!$G$298
Name PEARLS3_LS005: '[1]Financial Statements'!$G$302
Name PEARLS3_LS010: '[1]Financial Statements'!$G$307
Name PEARLS3_LS011: '[1]Financial Statements'!$G$308
Name PEARLS4_LA002: '[1]Financial Statements'!$H$280
Name PEARLS4_LE008: '[1]Financial Statements'!$H$275
Name PEARLS4_LE009: '[1]Financial Statements'!$H$276
Name PEARLS4_LR001: '[1]Financial Statements'!$H$282
Name PEARLS4_LR005: '[1]Financial Statements'!$H$286
Name PEARLS4_LR006: '[1]Financial Statements'!$H$287
Name PEARLS4_LR007: '[1]Financial Statements'!$H$288
Name PEARLS4_LR009: '[1]Financial Statements'!$H$290
Name PEARLS4_LS001: '[1]Financial Statements'!$H$298
Name PEARLS4_LS005: '[1]Financial Statements'!$H$302
Name PEARLS4_LS010: '[1]Financial Statements'!$H$307
Name PEARLS4_LS011: '[1]Financial Statements'!$H$308
Name PEARLS5_LA002: '[1]Financial Statements'!$I$280

Sheet Evolutive SFP
B3: 43831 | C3: 43862 | D3: 43891 | E3: 43922 | F3: 43952 | G3: 43983 | H3: 44013 | I3: 44044 | J3: 44075 | K3: 44105 | L3: 44136 | M3: 44166 | N3: AUDITED 2020 | O3: 44197 | P3: 44228 | Q3: 44256 | R3: 44287 | S3: 44317 | T3: 44348 | U3: 44378 | V3: 44409 | W3: 44440 | X3: 44470 | Y3: 44501 | Z3: 44531 | AA3: Audited 2021 | AB3: 44562 | AC3: 44593 | AD3: 44621 | AE3: 44652 | AF3: 44682 | AG3: 44713 | AH3: 44743 | AI3: 44774 | AJ3: 44805 | AK3: 44835 | AL3: 44866 | AM3: 44896 | AN3: Aud-22
A4: Cash & cash Equivalent | B4: =(B5+B6) -> 1.0101863e+09 | C4: =(C5+C6) -> 1.0585918e+09 | D4: =(D5+D6) -> 7.869912e+08 | E4: =(E5+E6) -> 5.3780551e+08 | F4: =(F5+F6) -> 6.7427165e+08 | G4: =(G5+G6) -> 8.8731409e+08 | H4: =(H5+H6) -> 9.8082857e+08 | I4: =(I5+I6) -> 9.8415191e+08 | ... AN4: =(AN5+AN6) -> 1954092000
A5: Cash In Hand | B5: 1.010153e+09 | C5: 21969.49 | D5: 35966.49 | E5: 29941.49 | F5: 31473.49 | G5: 160465.77 | H5: 148928.77 | I5: 196968.77 | J5: 208221.77 | K5: 241659.57 | L5: 219890.57 | M5: 1255040.3 | N5: 252000 | O5: 1583728.3 | P5: 1757108.3 | Q5: 1035713.6 | R5: 2389981.6 | S5: 6111924.6 | T5: 3088383.6 | U5: 6155297.6 | V5: 4862203.4 | W5: 4344987 | X5: 3175001 | Y5: 1957830 | Z5: 1303599.1 | AA5: 1000 | AB5: 913220.8 | AC5: 4023647 | AD5: 4471649.9 | AE5: 3896218 | AF5: 1220087.7 | AG5: 3743930.5 | AH5: 3687296.4 | AI5: 2451256.4 | AJ5: 2146417.1 | AK5: 5876491.1 | AL5: 4789067.1 | AM5: 2433359.4 | AN5: 82435000
A6: Cash at Bank | B6: 33343.49 | C6: 1.0585698e+09 | D6: 7.8695523e+08 | E6: 5.3777557e+08 | F6: 6.7424017e+08 | G6: 8.8715363e+08 | H6: 9.8067964e+08 | I6: 9.8395494e+08 | J6: 9.9408861e+08 | K6: 1082914258 | L6: 1.2203478e+09 | M6: 1.2425879e+09 | N6: =16333000+1113000+12103000+573000+1349000+1003000+17210000 -> 49684000 | O6: 1.3352814e+09 | P6: 1.4116783e+09 | Q6: 1.0427998e+09 | R6: 9.9210255e+08 | S6: 9.4874057e+08 | T6: 9.7306423e+08 | U6: 1.1811607e+09 | V6: 1.2052931e+09 | W6: 1.1854755e+09 | X6: 1.2554971e+09 | Y6: 1.302692e+09 | Z6: 1.3368233e+09 | AA6: =116148000+71416000+320222000+162000+343255000+336605000+150319000 -> 1338127000 | AB6: 1.3079433e+09 | AC6: 1.2284454e+09 | AD6: 1.3749216e+09 | AE6: 1.2992514e+09 | AF6: 1.3300062e+09 | AG6: 1.4736664e+09 | AH6: 1.4422755e+09 | AI6: 1.4491563e+09 | AJ6: 1.0706931e+09 | AK6: 1.1383077e+09 | AL6: 1.1606487e+09 | AM6: 1.1960837e+09 | AN6: 1871657000
A7: Prepayment and Sundry | B7: 1.3214172e+08 | C7: 1.4246224e+08 | D7: 0 | E7: 1.4458991e+08 | F7: 1.4390946e+08 | G7: 64235857 | H7: 69710925 | I7: 75746422 | J7: 82061838 | K7: 80631380 | L7: 80715944 | M7: 88025263 | N7: 90910000 | O7: 70956448 | P7: 1.4670054e+08 | Q7: 1.4076959e+08 | R7: 1.5874134e+08 | S7: 1.5564367e+08 | T7: 1.5872149e+08 | U7: 1.6416e+08 | V7: 1.6352983e+08 | W7: 1.719237e+08 | X7: 1.7311523e+08 | Y7: 1.6883048e+08 | Z7: 1.686447e+08 | AA7: 104846000 | AB7: 1.8176984e+08 | AC7: 1.9089697e+08 | AD7: 2.0224698e+08 | AE7: 2.1003406e+08 | AF7: 1.9992038e+08 | AG7: 2.0528994e+08 | AH7: 2.1426977e+08 | AI7: 2.0885843e+08 | AJ7: 2.0829975e+08 | AK7: 2.1228848e+08 | AL7: 223925472 | AM7: 2.0611555e+08 | AN7: 24210000
A8: Financial Investment | B8: =(B9+B10+B11+B13+B12) -> 1.4835578e+08 | C8: =(C9+C10+C11+C13+C12) -> 1.8635578e+08 | D8: =(D9+D10+D11+D13+D12) -> 1.9135578e+08 | E8: =(E9+E10+E11+E13+E12) -> 4.4135578e+08 | F8: =(F9+F10+F11+F13+F12) -> 4.4135578e+08 | G8: =(G9+G10+G11+G13+G12) -> 4.4938528e+08 | H8: =(H9+H10+H11+H13+H12) -> 4.5227775e+08 | I8: =(I9+I10+I11+I13+I12) -> 4.8627775e+08 | ... K8: =(K9+K10+K11+K13+K12) -> 3.8516373e+08 | L8: =(L9+L10+L11+L12+L13) -> 3.8516373e+08 | M8: =(M9+M10+M11+M13+M12) -> 4.6163073e+08 | N8: =(N9+N10+N11+N13+N12) -> 1653199000 | O8: =(O9+O10+O11+O13+O12) -> 4.3595943e+08 | P8: =(P9+P10+P11+P13+P12) -> 3.9176941e+08 | Q8: =(Q9+Q10+Q11+Q13+Q12) -> 6.5109522e+08 | R8: =(R9+R10+R11+R13+R12) -> 6.9909522e+08 | S8: =(S9+S10+S11+S13+S12) -> 6.9909522e+08 | T8: =(T9+T10+T11+T13+T12) -> 7.0892257e+08 | ... AN8: =(AN9+AN10+AN11+AN13+AN12) -> 241010000
A9: Government Security | B9: 129759730 | C9: 167759730 | D9: 172759730 | E9: 172759730 | F9: 172759730 | G9: 166759730 | H9: 166759730 | I9: 166759730 | J9: 141759730 | K9: 76759730 | L9: 76759730 | M9: 76759730 | N9: 76760000 | O9: 50759730 | P9: 5000000 | Q9: 210000000 | R9: 258000000 | S9: 258000000 | T9: 258000000 | U9: 258000000 | V9: 258000000 | W9: 258000000 | X9: 258000000 | Y9: 258000000 | Z9: 258000000 | AA9: 258000000 | AB9: 258000000 | AC9: 407000000 | AD9: 197000000 | AE9: 149000000 | AF9: 149000000 | AG9: 149000000 | AH9: 149000000 | AI9: 149000000 | AJ9: 564823940 | AK9: 564823940 | AL9: 576000000 | AM9: 623000000 | AN9: 220000000
A10: Other Securities | B10: 0 | C10: 0 | D10: 0 | E10: 0 | F10: 0 | G10: 0 | H10: 0 | I10: 0 | J10: 0 | K10: 0 | L10: 0 | M10: 0 | O10: 0 | P10: 0 | Q10: 0 | R10: 0 | S10: 0 | T10: 0 | U10: 0 | V10: 0 | W10: 0 | X10: 0 | Y10: 0 | Z10: 0 | AB10: 0 | AC10: 0 | AD10: 0 | AE10: 0 | AF10: 0 | AG10: 0 | AH10: 0 | AI10: 0 | AJ10: 0 | AK10: 0 | AL10: 0 | AM10: 0
A11: Balances in NACCOS (E.g Jungu Kuu, ESS, Savings,Money Market,Coop FD, CFP) | B11: 0 | C11: 0 | D11: 0 | E11: 250000000 | F11: 250000000 | G11: 264029491 | H11: 266921968 | I11: 300921968 | J11: 303399524 | K11: 289807943 | L11: 289807943 | M11: 366274944 | N11: 1560028000 | O11: 368789447 | P11: 370359160 | Q11: 424684965 | R11: 424684965 | S11: 424684965 | T11: 434512313 | U11: 300257150 | V11: 301898294 | W11: 307195170 | X11: 307195170 | Y11: 308919696 | Z11: 344430948 | AA11: 344431000 | AB11: 344430948 | AC11: 346871431 | AD11: 282584769 | AE11: 332584769 | AF11: 333480645 | AG11: 287759709 | AH11: 338909709 | AI11: 339826190 | AJ11: 344486816 | AK11: 346813266 | AL11: 347750902 | AM11: 352561426
A12: Equity Investments in NACCOs(Shares in- CIC, KUSCCO, COOP BANK,CAK, KERUSSU) | L12: 0 | M12: 0 | N12: =2079000+4720000+1575000+3415000 -> 11789000
A13: Equity Investments in companies - shares/stocks | B13: 18596054 | C13: 18596054 | D13: 18596054 | E13: 18596054 | F13: 18596054 | G13: 18596054 | H13: 18596054 | I13: 18596054 | J13: 18596054 | K13: 18596054 | L13: 18596054 | M13: 18596054 | N13: =2640000+1982000 -> 4622000 | O13: 16410254 | P13: 16410254 | Q13: 16410254 | R13: 16410254 | S13: 16410254 | T13: 16410254 | U13: 16410254 | V13: 16410254 | W13: 16410254 | X13: 16410254 | Y13: 16410254 | Z13: 16410254 | AA13: =17040000+2066000 -> 19106000 | AB13: 19105609 | AC13: 19105609 | AD13: 19105609 | AE13: 19105609 | AF13: 19105609 | AG13: 19105609 | AH13: 21105609 | AI13: 21105609 | AJ13: 21105609 | AK13: 21105609 | AL13: 21105609 | AM13: 21009425 | AN13: 21010000
A14: Net Loan Portfolio | B14: =(B15-B16) -> 5.2541832e+09 | C14: =(C15-C16) -> 5.165615e+09 | D14: =(D15-D16) -> 5.2067397e+09 | E14: =(E15-E16) -> 5.214632e+09 | F14: =(F15-F16) -> 5.1847667e+09 | G14: =(G15-G16) -> 5.1656339e+09 | H14: =(H15-H16) -> 5.2006949e+09 | I14: =(I15-I16) -> 5.2552086e+09 | ... AN14: =(AN15-AN16) -> 6927369000
A15: Gross Loan Portfolio | B15: 5.394204e+09 | C15: 5.3056358e+09 | D15: 5.3686268e+09 | E15: 5.3765191e+09 | F15: 5.3466538e+09 | G15: 5.327521e+09 | H15: 5.362582e+09 | I15: 5.4276033e+09 | J15: 5.5516486e+09 | K15: 5.6023668e+09 | L15: 5.6337173e+09 | M15: 5.6729643e+09 | N15: =5504745000+165551000 -> 5670296000 | O15: 5.6985851e+09 | P15: 5.741567e+09 | Q15: 5.7151278e+09 | R15: 5.7959051e+09 | S15: 5.8497818e+09 | T15: 5.8511896e+09 | U15: 5.9209457e+09 | V15: 6.063743e+09 | W15: 6.1594623e+09 | X15: 6.1956509e+09 | Y15: 6.2238862e+09 | Z15: 6.2750579e+09 | AA15: 6334627000 | AB15: 6.4057229e+09 | AC15: 6.4288761e+09 | AD15: 6.3608269e+09 | AE15: 6.447651e+09 | AF15: 6.5043329e+09 | AG15: 6.4816222e+09 | AH15: 6.6054459e+09 | AI15: 6.6927014e+09 | AJ15: 6.7769328e+09 | AK15: 6.8902866e+09 | AL15: 7.0239582e+09 | AM15: 7.0886847e+09 | AN15: 7258848000
A16: Allowance For Loan Loss | B16: 1.4002079e+08 | C16: 1.4002079e+08 | D16: 1.6188709e+08 | E16: 1.6188709e+08 | F16: 1.6188709e+08 | G16: 1.6188709e+08 | H16: 1.6188709e+08 | I16: 1.7239471e+08 | J16: 1.7239471e+08 | K16: 1.7239471e+08 | L16: 1.7239471e+08 | M16: 1.8488671e+08 | N16: 184886000 | O16: 2.7035547e+08 | P16: 3.934329e+08 | Q16: 2.3973918e+08 | R16: 2.4681637e+08 | S16: 2.5389355e+08 | T16: 2.5389355e+08 | U16: 2.5904846e+08 | V16: 2.714612e+08 | W16: 2.714612e+08 | X16: 2.8672624e+08 | Y16: 2.3923267e+08 | Z16: 2.5686472e+08 | AA16: 222885000 | AB16: 2.5546166e+08 | AC16: 2.5546166e+08 | AD16: 2.5546166e+08 | AE16: 2.5546166e+08 | AF16: 2.5546166e+08 | AG16: 2.5546166e+08 | AH16: 2.5546166e+08 | AI16: 2.5546166e+08 | AJ16: 2.5546166e+08 | AK16: 2.5546166e+08 | AL16: 2.5546166e+08 | AM16: 2.5546166e+08 | AN16: 331479000
A17: Accounts Recievables | B17: =(B18+B19+B20) -> -3692461.6 | C17: =(C18+C19+C20) -> -3441691.7 | D17: =(D18+D19+D20) -> 1.370186e+08 | E17: =(E18+E19+E20) -> 21406077 | F17: =(F18+F19+F20) -> 21540228 | G17: =(G18+G19+G20) -> 21622703 | H17: =(H18+H19+H20) -> 21624637 | I17: =(I18+I19+I20) -> 21703385 | ... AA17: =(AA18+AA19+AA20) -> 178000 | AB17: 178080 | AC17: 178080 | AD17: 178080 | AE17: 178080 | AF17: 178080 | AG17: 178080 | AH17: 178080 | AI17: 178080 | AJ17: 178080 | AK17: 178080 | AL17: 178080 | AM17: 178080
A18: Tax Recoverable | B18: -3727741.6 | C18: -3476971.7 | D18: -4027588.2 | E18: 21370797 | F18: 21504948 | G18: 21587423 | H18: 21589357 | I18: 21668105 | J18: 21577630 | K18: 21462789 | L18: 21517463 | M18: -3668660.4 | N18: 0 | O18: -806971.81 | P18: -16257.22 | Q18: 12221657 | R18: 38829.51 | S18: 1242022.7 | T18: 1764568.1 | U18: 2411821.3 | V18: 5055542.7 | W18: 5237080.5 | X18: 5555790.9 | Y18: 5586403.8 | Z18: 0 | AA18: 178000 | AB18: 0 | AC18: 0 | AD18: 0 | AE18: 0 | AF18: 0 | AG18: 178080 | AH18: 178080 | AI18: 178080 | AJ18: 178080 | AK18: 178080 | AL18: 178080 | AM18: 178080
A19: Deffered Tax Assets | B19: 35280 | C19: 35280 | D19: 35280 | E19: 35280 | F19: 35280 | G19: 35280 | H19: 35280 | I19: 35280 | J19: 35280 | K19: 35280 | L19: 35280 | M19: 35280 | N19: 203000 | O19: 203280 | P19: 203280 | Q19: 203280 | R19: 203280 | S19: 203280 | T19: 203280 | U19: 203280 | V19: 203280 | W19: 203280 | X19: 203280 | Y19: 203280 | Z19: 203280 | AB19: 178080 | AC19: 178080 | AD19: 178080 | AE19: 178080 | AF19: 178080 | AG19: 0 | AH19: 0 | AI19: 0 | AJ19: 0 | AK19: 0 | AL19: 0 | AM19: 0
A20: Retirement Benefit Assets | B20: 0 | C20: 0 | D20: 1.4101091e+08 | E20: 0 | F20: 0 | G20: 0 | H20: 0 | I20: 0 | J20: 0 | K20: 0 | L20: 0 | M20: 0 | N20: 0 | O20: 0 | P20: 0 | Q20: 0 | R20: 0 | S20: 0 | T20: 0 | U20: 0 | V20: 0 | W20: 0 | X20: 0 | Y20: 0 | Z20: 0 | AB20: 0 | AC20: 0 | AD20: 0 | AE20: 0 | AF20: 0
A21: Property&Equipments&Other Assets | B21: =(B22+B23+B24+B25+B26) -> 3.7778544e+08 | C21: =(C22+C23+C24+C25+C26) -> 3.799367e+08 | D21: =(D22+D23+D24+D25+D26) -> 3.8482724e+08 | E21: =(E22+E23+E24+E25+E26) -> 3.8685266e+08 | F21: =(F22+F23+F24+F25+F26) -> 3.8766205e+08 | G21: =(G22+G23+G24+G25+G26) -> 3.8713425e+08 | H21: =(H22+H23+H24+H25+H26) -> 3.8775507e+08 | I21: =(I22+I23+I24+I25+I26) -> 3.8835257e+08 | ... AN21: =(AN22+AN23+AN24+AN25+AN26) -> 395991000
A22: Investment Properties | B22: 0 | C22: 3.547409e+08 | D22: 0 | E22: 0 | F22: 0 | G22: 0 | H22: 0 | I22: 0 | J22: 0 | K22: 0 | L22: 0 | M22: 0 | N22: 0 | O22: 0 | P22: 0 | Q22: 0 | R22: 0 | S22: 0 | T22: 0 | U22: 0 | V22: 0 | W22: 0 | X22: 0 | Y22: 0 | Z22: 0 | AB22: 0 | AC22: 0 | AD22: 0 | AE22: 0 | AF22: 0 | AG22: 0 | AH22: 0 | AI22: 0 | AJ22: 0 | AK22: 0 | AL22: 0 | AM22: 0
A23: Property and Equipment | B23: 3.5479938e+08 | C23: 0 | D23: 3.5984937e+08 | E23: 3.6214789e+08 | F23: 3.6320642e+08 | G23: 3.6286959e+08 | H23: 3.6326091e+08 | I23: 3.6414576e+08 | J23: 3.2829728e+08 | K23: 3.3211655e+08 | L23: 3.3250428e+08 | M23: 3.492099e+08 | N23: 349209000 | O23: 3.4908543e+08 | P23: 3.487866e+08 | Q23: 3.4737702e+08 | R23: 3.4689648e+08 | S23: 3.463183e+08 | T23: 3.5333545e+08 | U23: 3.5438394e+08 | V23: 3.5236651e+08 | W23: 3.5193949e+08 | X23: 3.5136213e+08 | Y23: 3.5105313e+08 | Z23: 3.5132793e+08 | AA23: 352686000 | AB23: 3.5217774e+08 | AC23: 3.5166933e+08 | AD23: 3.5129753e+08 | AE23: 3.5034675e+08 | AF23: 3.5229715e+08 | AG23: 3.5120761e+08 | AH23: 3.5011212e+08 | AI23: 3.4900868e+08 | AJ23: 3.4834609e+08 | AK23: 3.47238e+08 | AL23: 3.4613662e+08 | AM23: 3.499129e+08 | AN23: 351329000
A24: Prepaid Lease Rentals | B24: 0 | C24: 0 | D24: 0 | E24: 0 | F24: 0 | G24: 0 | H24: 0 | I24: 0 | J24: 0 | K24: 0 | L24: 0 | M24: 0 | N24: 0 | O24: 0 | P24: 0 | Q24: 0 | R24: 0 | S24: 0 | T24: 0 | U24: 0 | V24: 0 | W24: 0 | X24: 0 | Y24: 0 | Z24: 0 | AB24: 0 | AC24: 0 | AD24: 0 | AE24: 0 | AF24: 0 | AG24: 0 | AH24: 0 | AI24: 0 | AJ24: 0 | AK24: 0 | AL24: 0 | AM24: 0
A25: Intangible Assets | B25: 22986061 | C25: 25195801 | D25: 24977872 | E25: 24704774 | F25: 24455633 | G25: 24264663 | H25: 24494159 | I25: 24206810 | J25: 29683436 | K25: 29773316 | L25: 29490118 | M25: 32771380 | N25: 32771000 | O25: 32546618 | P25: 32028424 | Q25: 31977927 | R25: 31922884 | S25: 31870306 | T25: 31815768 | U25: 31758964 | V25: 35069935 | W25: 39398730 | X25: 39296901 | Y25: 39362063 | Z25: 39303746 | AA25: 41154000 | AB25: 41652071 | AC25: 41493377 | AD25: 41323508 | AE25: 41159356 | AF25: 42446992 | AG25: 45790665 | AH25: 44785047 | AI25: 43745774 | AJ25: 42742281 | AK25: 42323570 | AL25: 41360038 | AM25: 44662431 | AN25: 44662000
A26: Other Assets | B26: 0 | C26: 0 | D26: 0 | E26: 0 | F26: 0 | G26: 0 | H26: 0 | I26: 0 | J26: 0 | K26: 0 | L26: 0 | M26: 0 | N26: 0 | O26: 0 | P26: 0 | Q26: 0 | R26: 0 | S26: 0 | T26: 0 | U26: 0 | V26: 0 | W26: 0 | X26: 0 | Y26: 0 | Z26: 0 | AB26: 0 | AC26: 0 | AD26: 0 | AE26: 0 | AF26: 0 | AG26: 0 | AH26: 0 | AI26: 0 | AJ26: 0 | AK26: 0 | AL26: 0 | AM26: 0
A27: Total Assets | B27: =(B21+B17+B14+B8+B7+B4) -> 6.91896e+09 | C27: =(C21+C17+C14+C8+C7+C4) -> 6.9295198e+09 | D27: =(D21+D17+D14+D8+D7+D4) -> 6.7069325e+09 | E27: =(E21+E17+E14+E8+E7+E4) -> 6.746642e+09 | F27: =(F21+F17+F14+F8+F7+F4) -> 6.8535059e+09 | G27: =(G21+G17+G14+G8+G7+G4) -> 6.9753261e+09 | H27: =(H21+H17+H14+H8+H7+H4) -> 7.1128919e+09 | I27: =(I21+I17+I14+I8+I7+I4) -> 7.2114407e+09 | ... AO27: =(AO21+AO17+AO14+AO8+AO7+AO4) -> 0
A28: Savings and Deposits | B28: 0 | C28: 0 | D28: 0 | E28: 0 | F28: 0 | G28: 0 | H28: 0 | I28: 0 | J28: 0 | K28: 0 | L28: 0 | M28: 64332 | N28: 5916911000 | O28: 968053.02 | P28: 1.9277926e+08 | Q28: 93474883 | R28: 81845472 | S28: 69739721 | T28: 69211526 | U28: 1.0386625e+08 | V28: 1.5482055e+08 | W28: 1.419525e+08 | X28: 1.2397897e+08 | Y28: 1.4311435e+08 | Z28: 1.2485343e+08 | AA28: 126447000 | AB28: 1.4926346e+08 | AC28: 1.4166661e+08 | AD28: 3.447683e+08 | AE28: 2.607424e+08 | AF28: 2.3884634e+08 | AG28: 2.4489044e+08 | AH28: 2.7654407e+08 | AI28: 2.5459203e+08 | AJ28: 2.2856712e+08 | AK28: 2.4457975e+08 | AL28: 2.4297308e+08 | AM28: 2.3655047e+08 | AN28: 330931000
A29: Short Terrm Deposits | B29: 55125212 | C29: 57687510 | D29: 60972993 | E29: 66344454 | F29: 70243155 | G29: 91522596 | H29: 91259010 | I29: 84437462 | J29: 90906172 | K29: 96133734 | L29: 96863484 | M29: 87694688 | O29: 92991143 | P29: 86014808 | Q29: 91141092 | R29: 94488018 | S29: 95995000 | T29: 96429405 | U29: 98704366 | V29: 1.0440746e+08 | W29: 1.0444308e+08 | X29: 1.0104332e+08 | Y29: 94490230 | Z29: 92485835 | AA29: =28142000+32183000+30567000+47000 -> 90939000 | AB29: 90373961 | AC29: 92665757 | AD29: 91130919 | AE29: 89318494 | AF29: 92232097 | AG29: 94753382 | AH29: 96432774 | AI29: 93433199 | AJ29: 94451326 | AK29: 97702518 | AL29: 96305855 | AM29: 94247370
A30: Non Withdrawable Deposits | B30: 5.3494077e+09 | C30: 5425374401 | D30: 5.4994885e+09 | E30: 5.5300382e+09 | F30: 5576806617 | G30: 5.6119058e+09 | H30: 5.6953443e+09 | I30: 5.749134e+09 | J30: 5.7856993e+09 | K30: 5.8599787e+09 | L30: 5.9079874e+09 | M30: 5.916898e+09 | N30: 88107000 | O30: 5.9714998e+09 | P30: 6.0437252e+09 | Q30: 6.1382567e+09 | R30: 6.1953535e+09 | S30: 6.1708658e+09 | T30: 6.1544773e+09 | U30: 6.2047627e+09 | V30: 6.2403096e+09 | W30: 6.2457152e+09 | X30: 6.2991952e+09 | Y30: 6.2823982e+09 | Z30: 6.3476863e+09 | AA30: 6347686000 | AB30: 6.4134089e+09 | AC30: 6.4418425e+09 | AD30: 6.5425059e+09 | AE30: 6.6105472e+09 | AF30: 6.6532933e+09 | AG30: 6.6496016e+09 | AH30: 6.7033456e+09 | AI30: 6.7443433e+09 | AJ30: 6.7836691e+09 | AK30: 6.8604398e+09 | AL30: 6.9494994e+09 | AM30: 7.0062215e+09 | AN30: 7006250000
A31: Total Deposit Liabilities | B31: =SUM(B28:B30) -> 5.4045329e+09 | C31: =SUM(C28:C30) -> 5.4830619e+09 | D31: =SUM(D28:D30) -> 5.5604615e+09 | E31: =SUM(E28:E30) -> 5.5963827e+09 | F31: =SUM(F28:F30) -> 5.6470498e+09 | G31: =SUM(G28:G30) -> 5.7034284e+09 | H31: =SUM(H28:H30) -> 5.7866033e+09 | I31: =SUM(I28:I30) -> 5.8335715e+09 | ... AN31: =SUM(AN28:AN30) -> 7337181000
A32: Tax Payable | B32: 10332188 | C32: 10332188 | D32: 10332188 | E32: 3039879.4 | F32: 3039879.4 | G32: 3039879.4 | H32: 3039879.4 | I32: 3039879.4 | J32: 3039879.4 | K32: 3039879.4 | L32: 3039879.4 | M32: 13064682 | N32: 12817000 | O32: 12817308 | P32: 12817308 | Q32: 12817308 | R32: -3451056.8 | S32: -3451056.8 | T32: -3451056.8 | U32: -3451056.8 | V32: -3451056.8 | W32: -3451056.8 | X32: -3451056.8 | Y32: -3451056.8 | Z32: 19083326 | AA32: 15379000 | AB32: 11325272 | AC32: 10820854 | AD32: 10456260 | AE32: -23040670 | AF32: -39949661 | AG32: -40657750 | AH32: 196942.33 | AI32: 103456.85 | AJ32: -210726.57 | AK32: -159557.23 | AL32: 157459.18 | AM32: 14319700 | AN32: 2240000
A33: Dividends Payable | B33: 0 | C33: 0 | D33: 0 | E33: 0 | F33: 0 | G33: 0 | H33: 0 | I33: 0 | J33: 0 | K33: 0 | L33: 0 | M33: 0 | N33: 0 | O33: 0 | P33: 0 | Q33: 0 | R33: 0 | S33: 0 | T33: 0 | U33: 0 | V33: 0 | W33: 0 | X33: 0 | Y33: 0 | Z33: 0 | AB33: 0 | AC33: 0 | AD33: 0 | AE33: 0 | AF33: 0 | AG33: 0 | AH33: 0 | AI33: 0 | AJ33: 0 | AK33: 0 | AL33: 0 | AM33: 0 | AN33: 762218000
A34: Deferred Tax Liability | B34: 0 | C34: 0 | D34: 0 | E34: 0 | F34: 0 | G34: 0 | H34: 0 | I34: 0 | J34: 0 | K34: 0 | L34: 0 | M34: 0 | N34: 0 | O34: 0 | P34: 0 | Q34: 0 | R34: 0 | S34: 0 | T34: 0 | U34: 0 | V34: 0 | W34: 0 | X34: 0 | Y34: 0 | Z34: 0 | AB34: 0 | AC34: 0 | AD34: 0 | AE34: 0 | AF34: 0 | AG34: 0 | AH34: 0 | AI34: 0 | AJ34: 0 | AK34: 0 | AL34: 0 | AM34: 0
A35: Retirement Benefits Liabilty | B35: 0 | C35: 0 | D35: 0 | E35: 0 | F35: 0 | G35: 0 | H35: 0 | I35: 0 | J35: 0 | K35: 0 | L35: 0 | M35: 0 | N35: 0 | O35: 0 | P35: 0 | Q35: 0 | R35: 0 | S35: 0 | T35: 0 | U35: 0 | V35: 0 | W35: 0 | X35: 0 | Y35: 0 | Z35: 0 | AB35: 0 | AC35: 0 | AD35: 0 | AE35: 0 | AF35: 0 | AG35: 0 | AH35: 0 | AI35: 0 | AJ35: 0 | AK35: 0 | AL35: 0 | AM35: 0
A36: Other Liabilities | B36: 7.1218939e+08 | C36: 6.0643112e+08 | D36: 3.0872809e+08 | E36: 3.0129029e+08 | F36: 3.3508129e+08 | G36: 3.7629147e+08 | H36: 4.0954176e+08 | I36: 4.5232466e+08 | J36: 4.7767995e+08 | K36: 5.0732925e+08 | L36: 5.468888e+08 | M36: 6.509614e+08 | N36: 562738000 | O36: 6.2440856e+08 | P36: 3.8386607e+08 | Q36: 3.106408e+08 | R36: 3.4210022e+08 | S36: 3.6687118e+08 | T36: 3.6800003e+08 | U36: 4.099255e+08 | V36: 4.6916319e+08 | W36: 5.3639067e+08 | X36: 5.8534089e+08 | Y36: 6.2272632e+08 | Z36: 7.6431255e+08 | AA36: =151848000+576222000 -> 728070000 | AB36: 7.8814388e+08 | AC36: 8.2954885e+08 | AD36: 3.0815161e+08 | AE36: 3.5121546e+08 | AF36: 3.8241967e+08 | AG36: 4.2216949e+08 | AH36: 4.2848511e+08 | AI36: 4.715406e+08 | AJ36: 5.3655065e+08 | AK36: 5.8583919e+08 | AL36: 6.4384857e+08 | AM36: 8.020594e+08 | AN36: 89935000
A37: External Borrowings | B37: 0 | C37: 13804980 | D37: 0 | E37: 0 | F37: 0 | G37: 0 | H37: 0 | I37: 0 | J37: 0 | K37: 0 | L37: -95628.4 | M37: 8044913.8 | O37: 14029968 | P37: 12367621 | Q37: 7653936.5 | R37: 5131884 | S37: 5016337.2 | T37: 5063251.8 | U37: 2542171.3 | V37: 2679824.5 | W37: 2770985.6 | X37: 2706446.5 | Y37: 50138.87 | Z37: 18644831 | AB37: 16642260 | AC37: 16422883 | AD37: 7999025.4 | AE37: 5206074.7 | AF37: 5054477.4 | AG37: 5033276.8 | AH37: 5079730.7 | AI37: 5074863 | AJ37: 5024366.3 | AK37: 4966674.5 | AL37: 2828503.2 | AM37: 39213462
A38: Total Liabilities | B38: =SUM(B31:B37) -> 6.1270545e+09 | C38: =SUM(C31:C37) -> 6.1136302e+09 | D38: =SUM(D31:D37) -> 5.8795218e+09 | E38: =SUM(E31:E37) -> 5.9007129e+09 | F38: =SUM(F31:F37) -> 5.9851709e+09 | G38: =SUM(G31:G37) -> 6.0827598e+09 | H38: =SUM(H31:H37) -> 6.199185e+09 | I38: =SUM(I31:I37) -> 6.288936e+09 | ... AN38: =SUM(AN31:AN37) -> 8191574000
A39: Share Capital | B39: 3.3896874e+08 | C39: 345632751 | D39: 3.4843312e+08 | E39: 3.524745e+08 | F39: 3.5511752e+08 | G39: 3.5851755e+08 | H39: 3.6270301e+08 | I39: 3.6591878e+08 | J39: 3.6881766e+08 | K39: 3.7418783e+08 | L39: 3.7827165e+08 | M39: 4.3274797e+08 | N39: 432735000 | O39: 4.3535137e+08 | P39: 4.3895028e+08 | Q39: 4.434157e+08 | R39: 4.497373e+08 | S39: 4.5338392e+08 | T39: 4.5767317e+08 | U39: 4.61847e+08 | V39: 4.6542189e+08 | W39: 4.7002729e+08 | X39: 4.7418366e+08 | Y39: 4.7946819e+08 | Z39: 4.8574187e+08 | AA39: 485742000 | AB39: 4.8925978e+08 | AC39: 4.9453395e+08 | AD39: 5.0580535e+08 | AE39: 5.1132762e+08 | AF39: 5.1730788e+08 | AG39: 5.229283e+08 | AH39: 5.288884e+08 | AI39: 5.3555807e+08 | AJ39: 5.4303538e+08 | AK39: 5.5419559e+08 | AL39: 5.627931e+08 | AM39: 5.7003526e+08 | AN39: 570035000
A40: Capital Grants | B40: 0 | C40: 0 | D40: 0 | E40: 0 | F40: 0 | G40: 0 | H40: 0 | I40: 0 | J40: 0 | K40: 0 | L40: 0 | M40: 0 | N40: 0 | O40: 0 | P40: 0 | Q40: 0 | R40: 0 | S40: 0 | T40: 0 | U40: 0 | V40: 0 | W40: 0 | X40: 0 | Y40: 0 | Z40: 0 | AA40: 0 | AB40: 0 | AC40: 0 | AD40: 0 | AE40: 0 | AF40: 0 | AG40: 0 | AH40: 0 | AI40: 0 | AJ40: 0 | AK40: 0 | AL40: 0 | AM40: 0
A41: Prior Year Retained Earnigs | B41: 1.4389978e+08 | C41: 1.4424767e+08 | D41: 1.4421888e+08 | E41: 1.4410894e+08 | F41: 1.4410883e+08 | G41: 1.4410883e+08 | H41: 1.4410883e+08 | I41: 1.4410883e+08 | J41: 1.4341243e+08 | K41: 1.435261e+08 | L41: 1.434741e+08 | M41: 1.4605558e+08 | N41: 154932000 | O41: 1.1716123e+08 | P41: 1.1866549e+08 | Q41: 1.1860358e+08 | R41: 1.1860358e+08 | S41: 1.1859333e+08 | T41: 1.1859333e+08 | U41: 118483746 | V41: 1.1846944e+08 | W41: 1.1843865e+08 | X41: 1.1824667e+08 | Y41: 1.1822687e+08 | Z41: 1.1847687e+08 | AA41: 118477000 | AB41: 1.3706386e+08 | AC41: 1.3642706e+08 | AD41: 1.3635327e+08 | AE41: 1.3674492e+08 | AF41: 1.4183943e+08 | AG41: 1.459391e+08 | AH41: 1.4592546e+08 | AI41: 1.4592546e+08 | AJ41: 1.4592546e+08 | AK41: 1.4596592e+08 | AL41: 1.4596592e+08 | AM41: 1.4596592e+08 | AN41: 72861000
A42: Current Year Surplus | B42: -2595393.7 | C42: 13971720 | D42: 18261707 | E42: 32893276 | F42: 51343483 | G42: 71169876 | H42: 86717528 | I42: 89353494 | J42: 1.0372004e+08 | K42: 1.1692171e+08 | L42: 1.2574752e+08 | M42: 38280842 | N42: =174512000-34903000-64910000-99839000-6980000-6400000 -> -38520000 | O42: -77843073 | P42: -71467527 | Q42: 21557751 | R42: 28838470 | S42: 37547016 | T42: 88368236 | U42: 1.0428261e+08 | V42: 1.0255548e+08 | W42: 1.2854885e+08 | X42: 1.316829e+08 | Y42: 2.1130151e+08 | Z42: 44314382 | AA42: =175176000-35035000-72861000-33978000-7007000-8527000 -> 17768000 | AB42: -82589.46 | AC42: 36127469 | AD42: 66430022 | AE42: 88345425 | AF42: 1.1574185e+08 | AG42: 1.4724918e+08 | AH42: 1.5666965e+08 | AI42: 1.7406948e+08 | AJ42: 2.0759098e+08 | AK42: 2.3781501e+08 | AL42: 2.6025636e+08 | AM42: 90561573 | AN42: =85505000-72861000 -> 12644000
...

Sheet Evolutitve SCI
B2: 43831 | C2: 43862 | D2: 43891 | E2: 43922 | F2: 43952 | G2: 43983 | H2: 44013 | I2: 44044 | J2: 44075 | K2: 44105 | L2: 44136 | M2: 44166 | N2: AUDITED 2020 | O2: 44197 | P2: 44228 | Q2: 44256 | R2: 44287 | S2: 44317 | T2: 44348 | U2: 44378 | V2: 44409 | W2: 44440 | X2: 44470 | Y2: 44501 | Z2: 44531 | AA2: Audited 2021 | AB2: 44562 | AC2: 44593 | AD2: 44621 | AE2: 44652 | AF2: 44682 | AG2: 44713 | AH2: 44743 | AI2: 44774 | AJ2: 44805 | AK2: 44835 | AL2: 44866 | AM2: 44896 | AN2: Aud-22
A3: Financial Income | B3: =B4+B7 -> 52306145 | C3: =C4+C7 -> 1.1536999e+08 | D3: =D4+D7 -> 1.9583627e+08 | E3: =E4+E7 -> 2.5886877e+08 | F3: =F4+F7 -> 3.3201075e+08 | G3: =G4+G7 -> 4.0716797e+08 | H3: =H4+H7 -> 9.5332453e+08 | I3: =I4+I7 -> 5.4696414e+08 | ... AN3: =AN4+AN7 -> 1162675000
A4: Financial Income From Loans Portfolio | B4: =SUM(B5:B6) -> 43406556 | C4: =SUM(C5:C6) -> 97662235 | D4: =SUM(D5:D6) -> 1.7249303e+08 | E4: =SUM(E5:E6) -> 2.2997502e+08 | F4: =SUM(F5:F6) -> 2.972804e+08 | G4: =SUM(G5:G6) -> 3.5556035e+08 | H4: =SUM(H5:H6) -> 8.3092834e+08 | I4: =SUM(I5:I6) -> 4.7885759e+08 | ... AN4: =SUM(AN5:AN6) -> 1026147000
A5: Interest from Loans Portfolio | B5: 38601227 | C5: 90310521 | D5: 1.5531162e+08 | E5: 2.0771087e+08 | F5: 2.7051616e+08 | G5: 3.2530323e+08 | H5: 7.6513805e+08 | I5: 4.4216336e+08 | J5: 5.0337658e+08 | K5: 5.6458979e+08 | L5: 6.239282e+08 | M5: 7.1884011e+08 | N5: 715367000 | O5: 36935438 | P5: 1.6673137e+08 | Q5: 2.1407774e+08 | R5: 2.5896048e+08 | S5: 3.1748233e+08 | T5: 3.9208572e+08 | U5: 4.5556344e+08 | V5: 5.2427204e+08 | W5: 5.9583431e+08 | X5: 6.638262e+08 | Y5: 7.4756162e+08 | Z5: 8.0859846e+08 | AA5: =835521*1000-AA6 -> 803226000 | AB5: 74525992 | AC5: 1.5000407e+08 | AD5: 2.3063693e+08 | AE5: 3.063592e+08 | AF5: 3.8828414e+08 | AG5: 4.7046956e+08 | AH5: 5.49043e+08 | AI5: 6.2680262e+08 | AJ5: 7.1433301e+08 | AK5: 8.008878e+08 | AL5: 8.8925939e+08 | AM5: 9.8298313e+08 | AN5: 1026147000
A6: Fees&Commision on Loan Portfolio | B6: 4805328.3 | C6: 7351713.5 | D6: 17181414 | E6: 22264157 | F6: 26764236 | G6: 30257122 | H6: 65790294 | I6: 36694228 | J6: 39031002 | K6: 41367776 | L6: 43714148 | M6: 46361591 | N6: =46362000+1364000+2300000 -> 50026000 | O6: 1634874.6 | P6: 3407779.8 | Q6: 5269207 | R6: 8382611.2 | S6: 11347975 | T6: 13749145 | U6: 15564610 | V6: 20332139 | W6: 24160161 | X6: 26920231 | Y6: 30276736 | Z6: 32914307 | AA6: =32295*1000 -> 32295000 | AB6: 2144530.7 | AC6: 4984721.8 | AD6: 7106502.7 | AE6: 10671649 | AF6: 14906003 | AG6: 18300244 | AH6: 21613307 | AI6: 27516536 | AJ6: 33768241 | AK6: 39951843 | AL6: 46278387 | AM6: 50479757
A7: Financial Income from Investments | B7: =SUM(B8:B11) -> 8899589.1 | C7: =SUM(C8:C11) -> 17707757 | D7: =SUM(D8:D11) -> 23343240 | E7: =SUM(E8:E11) -> 28893744 | F7: =SUM(F8:F11) -> 34730356 | G7: =SUM(G8:G11) -> 51607621 | H7: =SUM(H8:H11) -> 1.2239619e+08 | I7: =SUM(I8:I11) -> 68106553 | ... AN7: =SUM(AN8:AN11) -> 136528000
A8: Government Securities | B8: 2624927.4 | C8: 5634922.6 | D8: 5979263.5 | E8: 6014345.6 | F8: 6052570.1 | G8: 6071437 | H8: 12235590 | I8: 6150231.7 | J8: 6183508.1 | K8: 6216784.6 | L8: 6267339.8 | M8: 12831208 | O8: 21123.7 | P8: 38391.7 | Q8: 12141848 | R8: 14383597 | S8: 14402857 | T8: 14414647 | U8: 14484163 | V8: 14497211 | W8: 14526933 | X8: 14544884 | Y8: 14556828 | Z8: 14565289 | AB8: 0 | AC8: 9300509.8 | AD8: 13148313 | AE8: 13550834 | AF8: 13576161 | AG8: 13694747 | AH8: 13730071 | AI8: 13739094 | AJ8: 16995818 | AK8: 18304376 | AL8: 21629152 | AM8: 21850105
A9: Deposits with Banks & other Financial Institutions | B9: 6265195.7 | C9: 12056687 | D9: 16131981 | E9: 21021931 | F9: 25532240 | G9: 41802227 | H9: 1.0176454e+08 | I9: 57663248 | J9: 66483375 | K9: 75303503 | L9: 80426526 | M9: 1.0110281e+08 | N9: 113934000 | O9: 9007367.9 | P9: 17905092 | Q9: 27625198 | R9: 33447054 | S9: 39703030 | T9: 55587243 | U9: 65186353 | V9: 74729122 | W9: 87732121 | X9: 95890161 | Y9: 1.0625949e+08 | Z9: 1.2296866e+08 | AA9: =137534*1000 -> 137534000 | AB9: 9241872.1 | AC9: 17940010 | AD9: 28738515 | AE9: 36236792 | AF9: 44973648 | AG9: 59797487 | AH9: 58002044 | AI9: 67829839 | AJ9: 78136462 | AK9: 86484165 | AL9: 93748750 | AM9: 1.0901051e+08 | AN9: 118976000
A10: Other Investments | B10: 0 | C10: 0 | D10: 234080 | E10: 839312.1 | F10: 839312.1 | G10: 839312.1 | H10: 1678624.2 | I10: 839312.1 | J10: 839312.1 | K10: 839312.1 | L10: 839312.1 | M10: 839312.1 | N10: 0 | O10: 0 | P10: 98743 | Q10: 98743 | R10: 696939.3 | S10: 696939.3 | T10: 696939.3 | U10: 696939.3 | V10: 696939.3 | W10: 829863.3 | X10: 829863.3 | Y10: 829863.3 | Z10: 904908.3 | AB10: 0 | AC10: 0 | AD10: 0 | AE10: 0 | AF10: 159508.8 | AG10: 741943.1 | AH10: 741943.1 | AI10: 741943.1 | AJ10: 741943.1 | AK10: 741943.1 | AL10: 741943.1 | AM10: 741943.1
A11: Other Operating Income | B11: 9466.02 | C11: 16146.59 | D11: 997915.59 | E11: 1018155.9 | F11: 2306234.7 | G11: 2894644.7 | H11: 6717429.3 | I11: 3453761.9 | J11: 3556770.7 | K11: 3659779.5 | L11: 4546021.1 | M11: 6126845.1 | N11: =10421000-2300000-1364000 -> 6757000 | O11: 62028 | P11: 569006 | Q11: 1412021.9 | R11: 3547332.8 | S11: 3918766.6 | T11: 4184460.5 | U11: 5350088 | V11: 6593192.3 | W11: 6884237.1 | X11: 8809181 | Y11: 8956232.8 | Z11: 8813784.9 | AA11: =15711*1000 -> 15711000 | AB11: 651102.94 | AC11: 724652.32 | AD11: 3672962.6 | AE11: 3918571.4 | AF11: 4226784.8 | AG11: 5239683.9 | AH11: 5542343.2 | AI11: 5705811.3 | AJ11: 7433180 | AK11: 8350093.9 | AL11: 9333022.8 | AM11: 9531428.5 | AN11: 17552000
A12: Financial Expenses | B12: =SUM(B13:B18) -> 35841893 | C12: =SUM(C13:C18) -> 70623452 | D12: =SUM(D13:D18) -> 1.1108601e+08 | E12: =SUM(E13:E18) -> 1.483571e+08 | F12: =SUM(F13:F18) -> 1.9139303e+08 | G12: =SUM(G13:G18) -> 2.3492764e+08 | H12: =SUM(H13:H18) -> 5.509844e+08 | I12: =SUM(I13:I18) -> 3.1619005e+08 | ... AN12: =SUM(AN13:AN18) -> 601754000
A13: Interest Expense on Deposits | B13: 35916788 | C13: 70620497 | D13: 1.1108601e+08 | E13: 1.4869413e+08 | F13: 1.9139303e+08 | G13: 2.344911e+08 | H13: 5.4977442e+08 | I13: 3.1539068e+08 | J13: 3.5651565e+08 | K13: 3.9764062e+08 | L13: 4.3995638e+08 | M13: 485343088 | N13: 485441000 | O13: 27335989 | P13: 27692885 | Q13: 1.4617999e+08 | R13: 1.7928103e+08 | S13: 2.1753203e+08 | T13: 2.4564154e+08 | U13: 2.8436825e+08 | V13: 3.2720803e+08 | W13: 3.7235533e+08 | X13: 4.1349026e+08 | Y13: 4.630795e+08 | Z13: 5.0568202e+08 | AA13: =531044*1000 -> 531044000 | AB13: 41014531 | AC13: 86605494 | AD13: 1.3872804e+08 | AE13: 1.8155551e+08 | AF13: 2.2826598e+08 | AG13: 2.7825209e+08 | AH13: 3.1771244e+08 | AI13: 3.6358741e+08 | AJ13: 4.169386e+08 | AK13: 4.6751372e+08 | AL13: 5.1951708e+08 | AM13: 5.7509341e+08 | AN13: 601754000
A14: Cost of External Borrowings | B14: 0 | C14: 0 | D14: 0 | E14: 0 | F14: 0 | G14: 0 | H14: 0 | I14: 0 | J14: 0 | K14: 0 | L14: 0 | M14: 0 | N14: 0 | O14: 0 | P14: 0 | Q14: 0 | R14: 0 | S14: 0 | T14: 0 | U14: 0 | V14: 0 | W14: 0 | X14: 0 | Y14: 0 | Z14: 0 | AB14: 0 | AC14: 0 | AD14: 0 | AE14: 0 | AF14: 0 | AG14: 0 | AH14: 0 | AI14: 0 | AJ14: 0 | AK14: 0 | AL14: 0 | AM14: 0
A15: Dividend Expenses | B15: 0 | C15: 0 | D15: 0 | E15: 0 | F15: 0 | G15: 0 | H15: 0 | I15: 0 | J15: 0 | K15: 0 | L15: 0 | M15: 64912195 | N15: 0 | O15: 0 | P15: 0 | Q15: 0 | R15: 0 | S15: 0 | T15: 0 | U15: 0 | V15: 0 | W15: 0 | X15: 0 | Y15: 0 | Z15: 72861280 | AB15: 0 | AC15: 0 | AD15: 0 | AE15: 0 | AF15: 0 | AG15: 0 | AH15: 0 | AI15: 0 | AJ15: 0 | AK15: 0 | AL15: 0 | AM15: 85505289
A16: Other Financial Expense | B16: -74894.97 | C16: 2954.69 | D16: 0 | E16: -337024.44 | F16: 0 | G16: 436535.01 | H16: 1209982.4 | I16: 799362.39 | J16: 990812.79 | K16: 1182263.2 | L16: 1337061.9 | M16: 1553773.7 | N16: 0 | O16: 169639.25 | P16: 312982.15 | Q16: 559481.63 | R16: 719551.98 | S16: 874209.92 | T16: 1046852.2 | U16: 1199903.4 | V16: 1373085.4 | W16: 1504913.1 | X16: 1666506.2 | Y16: 1819899.6 | Z16: 1992512.7 | AB16: 118373.07 | AC16: 303431.21 | AD16: 511292.73 | AE16: 692487.51 | AF16: 878974.79 | AG16: 1066687.1 | AH16: 1202043 | AI16: 1349778.6 | AJ16: 1502232.7 | AK16: 1653649.9 | AL16: 1782796.4 | AM16: 1924310.9
A17: Fees & Commision Expense | B17: 0 | C17: 0 | D17: 0 | E17: 0 | F17: 0 | G17: 0 | H17: 0 | I17: 0 | J17: 0 | K17: 0 | L17: 0 | M17: 0 | N17: 0 | O17: 0 | P17: 0 | Q17: 0 | R17: 0 | S17: 0 | T17: 0 | U17: 0 | V17: 0 | W17: 0 | X17: 0 | Y17: 0 | Z17: 0 | AB17: 0 | AC17: 0 | AD17: 0 | AE17: 0 | AF17: 0 | AG17: 0 | AH17: 0 | AI17: 0 | AJ17: 0 | AK17: 0 | AL17: 0 | AM17: 0
A18: Other Expenses | B18: 0 | C18: 0 | D18: 0 | E18: 0 | F18: 0 | G18: 0 | H18: 0 | I18: 0 | J18: 0 | K18: 0 | L18: 0 | M18: 0 | N18: 0 | O18: 0 | P18: 0 | Q18: 0 | R18: 0 | S18: 0 | T18: 0 | U18: 0 | V18: 0 | W18: 0 | X18: 0 | Y18: 0 | Z18: 0 | AB18: 0 | AC18: 0 | AD18: 0 | AE18: 0 | AF18: 0 | AG18: 0 | AH18: 0 | AI18: 0 | AJ18: 0 | AK18: 0 | AL18: 0 | AM18: 62672939
A19: Net Financial Income | B19: =B3-B12 -> 16464252 | C19: =C3-C12 -> 44746540 | D19: =D3-D12 -> 84750265 | E19: =E3-E12 -> 1.1051166e+08 | F19: =F3-F12 -> 1.4061773e+08 | G19: =G3-G12 -> 1.7224033e+08 | H19: =H3-H12 -> 4.0234013e+08 | I19: =I3-I12 -> 2.3077409e+08 | ... AN19: =AN3-AN12 -> 560921000
A20: Allowance for Loan Loss | B20: =B21-B22 -> 8097355.9 | C20: =C21-C22 -> 8097355.9 | D20: =D21-D22 -> 29963659 | E20: =E21-E22 -> 29963659 | F20: =F21-F22 -> 29963659 | G20: =G21-G22 -> 29963659 | H20: =H21-H22 -> 59927318 | I20: =I21-I22 -> 40471280 | ... AN20: =AN21-AN22 -> 75680000
A21: Provision for Loan Losses | B21: 8097355.9 | C21: 8097355.9 | D21: 29963659 | E21: 29963659 | F21: 29963659 | G21: 29963659 | H21: 59927318 | I21: 40471280 | J21: 40471280 | K21: 40471280 | L21: 40471280 | M21: 52963275 | N21: 52963000 | O21: 85468766 | P21: 2.0854619e+08 | Q21: 54852479 | R21: 61929664 | S21: 69006848 | T21: 69006848 | U21: 74161752 | V21: 86574497 | W21: 86574497 | X21: 1.0183954e+08 | Y21: 54345968 | Z21: 71978013 | AA21: =37999*1000 -> 37999000 | AB21: 32576462 | AC21: 32576462 | AD21: 32576462 | AE21: 32576462 | AF21: 32576462 | AG21: 32576462 | AH21: 32576462 | AI21: 32576462 | AJ21: 32576462 | AK21: 32576462 | AL21: 32576462 | AM21: 32576462 | AN21: 75680000
A22: Value of Loans Recovered | B22: 0 | C22: 0 | D22: 0 | E22: 0 | F22: 0 | G22: 0 | H22: 0 | I22: 0 | J22: 0 | K22: 0 | L22: 0 | M22: 0 | N22: 0 | O22: 0 | P22: 0 | Q22: 0 | R22: 0 | S22: 0 | T22: 0 | U22: 0 | V22: 0 | W22: 0 | X22: 0 | Y22: 0 | Z22: 0 | AB22: 0 | AC22: 0 | AD22: 0 | AE22: 0 | AF22: 0 | AG22: 0 | AH22: 0 | AI22: 0 | AJ22: 0 | AK22: 0 | AL22: 0 | AM22: 0
A23: Operating Expeses | B23: =SUM(B24:B28) -> 10962290 | C23: =SUM(C24:C28) -> 22677464 | D23: =SUM(D24:D28) -> 36524899 | E23: =SUM(E24:E28) -> 47354729 | F23: =SUM(F24:F28) -> 58963797 | G23: =SUM(G24:G28) -> 70663335 | H23: =SUM(H24:H28) -> 1.6809083e+08 | I23: =SUM(I24:I28) -> 1.0049586e+08 | ... AN23: =SUM(AN24:AN28) -> 308034000
A24: Personel Expenses | B24: 7566742.5 | C24: 14935998 | D24: 22021168 | E24: 28928438 | F24: 35822844 | G24: 42826651 | H24: 99571304 | I24: 56721001 | J24: 65846904 | K24: 74972807 | L24: 80565064 | M24: 92315991 | N24: 0 | O24: 7367618.5 | P24: 14337990 | Q24: 22608881 | R24: 30947496 | S24: 39570440 | T24: 49938208 | U24: 59228699 | V24: 68272835 | W24: 77528728 | X24: 87012238 | Y24: 97030580 | Z24: 1.1204564e+08 | AA24: =112046*1000 -> 112046000 | AB24: 9366631.9 | AC24: 17756228 | AD24: 27754893 | AE24: 38553645 | AF24: 48745477 | AG24: 59348842 | AH24: 70833354 | AI24: 81776884 | AJ24: 92977517 | AK24: 1.0357181e+08 | AL24: 1.15256e+08 | AM24: 1.265911e+08 | AN24: 127549000
A25: Governance Expenses | B25: 657026 | C25: 1577277 | D25: 2878632 | E25: 3216939 | F25: 3758126 | G25: 4193370 | H25: 10603894 | I25: 5805233 | J25: 6438271 | K25: 7071309 | L25: 9083546 | M25: 18026583 | N25: 23485000 | O25: 353040 | P25: 732369 | Q25: 1419910 | R25: 1879860 | S25: 2821970 | T25: 3314720 | U25: 5455800 | V25: 7110742 | W25: 8035942 | X25: 9899777 | Y25: 11964613 | Z25: 20903487 | AA25: =7174*1000+16565*1000 -> 23739000 | AB25: 794988 | AC25: 1684348 | AD25: 3522245.7 | AE25: 5066488 | AF25: 6838060 | AG25: 7986578 | AH25: 11181078 | AI25: 12173541 | AJ25: 13636138 | AK25: 15000868 | AL25: 17795520 | AM25: 45346944 | AN25: 56947000
A26: Marketing Expenses | B26: 454203.51 | C26: 1668843.7 | D26: 4520654.6 | E26: 5675864.2 | F26: 7279396 | G26: 9144668.1 | H26: 22155182 | I26: 14255656 | J26: 16281045 | K26: 18306435 | L26: 19996023 | M26: 24839927 | N26: 0 | O26: 719413.22 | P26: 1369365 | Q26: 3841872.6 | R26: 4524009.1 | S26: 5425600.6 | T26: 6215024.8 | U26: 7576044.8 | V26: 8518428.9 | W26: 10223945 | X26: 11565980 | Y26: 12553604 | Z26: 17104098 | AB26: 65471.67 | AC26: 1819877.7 | AD26: 3646381.1 | AE26: 6416016.5 | AF26: 8938656.6 | AG26: 11534697 | AH26: 15007593 | AI26: 19103730 | AJ26: 22804135 | AK26: 27067498 | AL26: 31874855 | AM26: 39780697 | AN26: 9712000
A27: Depreciation and Amortization | B27: 648295.53 | C27: 1254723.7 | D27: 1927095.1 | E27: 2606455.5 | F27: 3330662.1 | G27: 4031459.2 | H27: 9574314.6 | I27: 5550797.9 | J27: 6289752.7 | K27: 7028707.5 | L27: 7795826.7 | M27: 8725551 | N27: =5331000+3395000 -> 8726000 | O27: 836153.1 | P27: 1508878.2 | Q27: 2143158 | R27: 2757733.6 | S27: 3392795.3 | T27: 4008164 | U27: 4667852 | V27: 5327459.5 | W27: 6018051.5 | X27: 6742231.4 | Y27: 7450056.6 | Z27: 8200619.6 | AA27: =1825*1000+7184*1000 -> 9009000 | AB27: 690109.39 | AC27: 1357215.6 | AD27: 2074815.6 | AE27: 3260289.2 | AF27: 5381727.4 | AG27: 7477764.2 | AH27: 9643999.4 | AI27: 11809712 | AJ27: 13915719 | AK27: 16110519 | AL27: 18231978 | AM27: 20701432 | AN27: 20702000
A28: Administrative Expenses | B28: 1636022.3 | C28: 3240621.8 | D28: 5177349.2 | E28: 6927032.2 | F28: 8772769.3 | G28: 10467187 | H28: 26186138 | I28: 18163171 | J28: 22789643 | K28: 27416115 | L28: 34465576 | M28: 47700503 | N28: =162236000-5331000-3395000 -> 153510000 | O28: 1570006.1 | P28: 4033976.2 | Q28: 7461236.1 | R28: 8540209.1 | S28: 11380993 | T28: 13178567 | U28: 15904687 | V28: 34180092 | W28: 39177370 | X28: 46921081 | Y28: 50927585 | Z28: 72459008 | AA28: =45208000+40406*1000-AA27 -> 76605000 | AB28: 1819520.4 | AC28: 4523440.7 | AD28: 7859067 | AE28: 14070721 | AF28: 18559049 | AG28: 22551370 | AH28: 33646094 | AI28: 45688846 | AJ28: 49266876 | AK28: 53210683 | AL28: 63499593 | AM28: 72658833 | AN28: 93124000
A29: Net Operating Income | B29: =B19-B20-B23 -> -2595393.6 | C29: =C19-C20-C23 -> 13971720 | D29: =D19-D20-D23 -> 18261707 | E29: =E19-E20-E23 -> 33193275 | F29: =F19-F20-F23 -> 51690269 | G29: =G19-G20-G23 -> 71613336 | H29: =H19-H20-H23 -> 1.7432198e+08 | I29: =I19-I20-I23 -> 89806954 | ... AN29: =AN19-AN20-AN23 -> 177207000
A30: Net Non operating Income/Expense | B30: =B31-B32 -> -35280 | C30: =C31-C32 -> -35280 | D30: =D31-D32 -> 0 | E30: =E31-E32 -> -35280 | F30: =F31-F32 -> -35280 | G30: =G31-G32 -> -35280 | H30: =H31-H32 -> -70560 | I30: =I31-I32 -> -35280 | ... AN30: =AN31-AN32 -> 0
A31: Non Operating Income | B31: 0 | C31: 0 | D31: 0 | E31: 0 | F31: 0 | G31: 0 | H31: 0 | I31: 0 | J31: 0 | K31: 0 | L31: 0 | M31: 0 | N31: 0 | O31: 0 | P31: 0 | Q31: 0 | R31: 0 | S31: 0 | T31: 0 | U31: 0 | V31: 0 | W31: 0 | X31: 0 | Y31: 0 | Z31: 0 | AB31: 0 | AC31: 0 | AD31: 0 | AE31: 0 | AF31: 0 | AG31: 0 | AH31: 0 | AI31: 0 | AJ31: 0 | AK31: 0 | AL31: 0 | AM31: 0
A32: Non Operating Expense | B32: 35280 | C32: 35280 | D32: 0 | E32: 35280 | F32: 35280 | G32: 35280 | H32: 70560 | I32: 35280 | J32: 35280 | K32: 35280 | L32: 35280 | M32: 35280 | N32: 0 | O32: 203280 | P32: 203280 | Q32: 203280 | R32: 203280 | S32: 203280 | T32: 203280 | U32: 203280 | V32: 203280 | W32: 203280 | X32: 203280 | Y32: 203280 | Z32: 203280 | AB32: 0 | AC32: 0 | AD32: 0 | AE32: 0 | AF32: 0 | AG32: 0 | AH32: 0 | AI32: 0 | AJ32: 0 | AK32: 0 | AL32: 0 | AM32: 0
A33: Net Income(Before Tax & Donations) | B33: =B29+B30 -> -2630673.6 | C33: =C29+C30 -> 13936440 | D33: =D29+D30 -> 18261707 | E33: =E29+E30 -> 33157995 | F33: =F29+F30 -> 51654989 | G33: =G29+G30 -> 71578056 | H33: =H29+H30 -> 1.7425142e+08 | I33: =I29+I30 -> 89771674 | ... AN33: =AN29+AN30 -> 177207000
A34: Taxes | B34: 0 | C34: 0 | D34: 0 | E34: 0 | F34: 0 | G34: 0 | H34: 0 | I34: 0 | J34: 0 | K34: 0 | L34: 0 | M34: 15983292 | N34: 0 | O34: 0 | P34: 0 | Q34: 0 | R34: 0 | S34: 0 | T34: 0 | U34: 0 | V34: 0 | W34: 0 | X34: 0 | Y34: 0 | Z34: 22503826 | AA34: =23147*1000 -> 23147000 | AB34: 0 | AC34: 0 | AD34: 0 | AE34: 0 | AF34: 0 | AG34: 0 | AH34: 0 | AI34: 0 | AJ34: 0 | AK34: 0 | AL34: 0 | AM34: 20982677
A35: Net Income(After Tax Before Donations) | B35: =B33-B34 -> -2630673.6 | C35: =C33-C34 -> 13936440 | D35: =D33-D34 -> 18261707 | E35: =E33-E34 -> 33157995 | F35: =F33-F34 -> 51654989 | G35: =G33-G34 -> 71578056 | H35: =H33-H34 -> 1.7425142e+08 | I35: =I33-I34 -> 89771674 | ... AN35: =AN33-AN34 -> 177207000
A36: Donations | B36: 0 | C36: 0 | D36: 0 | E36: 300000 | F36: 300000 | G36: 304560 | H36: 609120 | I36: 304560 | J36: 304560 | K36: 304560 | L36: -304560 | M36: -304560 | N36: 15736000 | AB36: -200000 | AC36: -200000 | AD36: -200000 | AE36: -200000 | AF36: -200000 | AG36: -200000 | AH36: -200000 | AI36: -200000 | AJ36: -200000 | AK36: -200000 | AL36: -200000 | AM36: -201210
A37: Net Income/(After Tax & Donations) | B37: =B35-B36 -> -2630673.6 | C37: =C35-C36 -> 13936440 | D37: =D35-D36 -> 18261707 | E37: =E35-E36 -> 32857995 | F37: =F35-F36 -> 51354989 | G37: =G35-G36 -> 71273496 | H37: =H35-H36 -> 1.736423e+08 | I37: =I35-I36 -> 89467114 | ... AN37: =AN35-AN36 -> 177207000
A39: Total Expenses | B39: =B12+B23 -> 46804182 | C39: =C12+C23 -> 93300915 | D39: =D12+D23 -> 1.4761091e+08 | E39: =E12+E23 -> 1.9571183e+08 | F39: =F12+F23 -> 2.5035682e+08 | G39: =G12+G23 -> 3.0559097e+08 | H39: =H12+H23 -> 7.1907523e+08 | I39: =I12+I23 -> 4.1668591e+08 | ... AF39: =AF12+AF23 -> 3.1760793e+08

Sheet FORM 4
D2: 43891
B3: CLASSIFICATION | C3: NO. OF A/Cs | D3: OUTSTANDING LOAN PORTFOLIO(Kshs) | E3: REQUIRED PROVISION | F3: REQUIRED PROVISION AMOUNT(Kshs)
B4: Performing | C4: 11812 | D4: 7.6526299e+09 | E4: 0.01 | F4: =D4*E4 -> 76526299
B5: Watch | C5: 3404 | D5: 2.188066e+09 | E5: 0.05 | F5: =D5*E5 -> 1.094033e+08
B6: Substandard | C6: 1506 | D6: 6.8259044e+08 | E6: 0.25 | F6: =D6*E6 -> 1.7064761e+08
B7: Doubtful | C7: 508 | D7: 1.4039815e+08 | E7: 0.5 | F7: =D7*E7 -> 70199075
B8: Loss | C8: 1206 | D8: 1.3261675e+08 | E8: 1 | F8: =D8*E8 -> 1.3261675e+08
B9: Sub-total | C9: =SUM(C4:C8) -> 18436 | D9: =SUM(D4:D8) -> 1.0796301e+10 | E9: 1.81 | F9: =SUM(F4:F8) -> 5.5939303e+08
C10: NPL | D10: =SUM(D6:D8) -> 9.5560534e+08
C11: PAR | D11: =D10/D9 -> 0.088512289
D14: 43983
B15: CLASSIFICATION | C15: NO. OF A/Cs | D15: OUTSTANDING LOAN PORTFOLIO(Kshs) | E15: REQUIRED PROVISION | F15: REQUIRED PROVISION AMOUNT(Kshs)
B16: Performing | C16: 5661 | D16: 3.5091131e+09 | E16: 0.01 | F16: =D16*E16 -> 35091131
B17: Watch | C17: 1712 | D17: 1.1514882e+09 | E17: 0.05 | F17: =D17*E17 -> 57574410 | H17: 11812
B18: Substandard | C18: 1187 | D18: 5.5435741e+08 | E18: 0.25 | F18: =D18*E18 -> 1.3858935e+08 | H18: 3404
B19: Doubtful | C19: 246 | D19: 62601627 | E19: 0.5 | F19: =D19*E19 -> 31300813 | H19: 1506
B20: Loss | C20: 670 | D20: 72780269 | E20: 1 | F20: =D20*E20 -> 72780269 | H20: 508
B21: Sub-total | C21: =SUM(C16:C20) -> 9476 | D21: =SUM(D16:D20) -> 5.3503406e+09 | E21: 1.81 | F21: =SUM(F16:F20) -> 3.3533598e+08 | H21: 1206
C22: NPL | D22: =SUM(D18:D20) -> 6.897393e+08 | H22: KIMISITU
C23: PAR | D23: =D22/D21 -> 0.12891503 | H23: 7.6526299e+09
H24: 2.188066e+09
H25: 6.8259044e+08
H26: 1.4039815e+08
D27: 44075 | H27: 1.3261675e+08
B28: CLASSIFICATION | C28: NO. OF A/Cs | D28: OUTSTANDING LOAN PORTFOLIO(Kshs) | E28: REQUIRED PROVISION | F28: REQUIRED PROVISION AMOUNT(Kshs)
B29: Performing | C29: 5914 | D29: 3.5082788e+09 | E29: 0.01 | F29: =D29*E29 -> 35082788
B30: Watch | C30: 2272 | D30: 1.3035993e+09 | E30: 0.05 | F30: =D30*E30 -> 65179965
B31: Substandard | C31: 1287 | D31: 6.4721095e+08 | E31: 0.25 | F31: =D31*E31 -> 1.6180274e+08
B32: Doubtful | C32: 210 | D32: 56010066 | E32: 0.5 | F32: =D32*E32 -> 28005033
B33: Loss | C33: 754 | D33: 80879265 | E33: 1 | F33: =D33*E33 -> 80879265
B34: Sub-total | C34: =SUM(C29:C33) -> 10437 | D34: =SUM(D29:D33) -> 5.5959784e+09 | E34: 1.81 | F34: =SUM(F29:F33) -> 3.7094979e+08
C35: NPL | D35: =SUM(D31:D33) -> 7.8410028e+08
C36: PAR | D36: =D35/D34 -> 0.14011853
D38: 44621
B39: CLASSIFICATION | C39: NO. OF A/Cs | D39: OUTSTANDING LOAN PORTFOLIO(Kshs) | E39: REQUIRED PROVISION | F39: REQUIRED PROVISION AMOUNT(Kshs)
B40: Performing | C40: 6895 | D40: 4.8188063e+09 | E40: 0.01 | F40: =D40*E40 -> 48188063
B41: Watch | C41: 1462 | D41: 1.0290779e+09 | E41: 0.05 | F41: =D41*E41 -> 51453897
B42: Substandard | C42: 664 | D42: 3.7026432e+08 | E42: 0.25 | F42: =D42*E42 -> 92566080
B43: Doubtful | C43: 198 | D43: 1.1730296e+08 | E43: 0.5 | F43: =D43*E43 -> 58651480
B44: Loss | C44: 645 | D44: 86302149 | E44: 1 | F44: =D44*E44 -> 86302149
...

Sheet CAELS
A1: STIMA SACCO 2017 CAELS
D2: 43831 | E2: 43862 | F2: 43891 | G2: 43922 | H2: 43952 | I2: 43983 | J2: 44013 | K2: 44044 | L2: 44075 | M2: 44105 | N2: 44136 | O2: 44166 | P2: AUDITED 2020 | Q2: 44197 | R2: 44228 | S2: 44256 | T2: 44287 | U2: 44317 | V2: 44348 | W2: 44378 | X2: 44409 | Y2: 44440 | Z2: 44470 | AA2: 44501 | AB2: 44531 | AC2: Audited 2021 | AD2: 44562 | AE2: 44593 | AF2: 44621 | AG2: 44652 | AH2: 44682 | AI2: 44713 | AJ2: 44743 | AK2: 44774 | AL2: 44805 | AM2: 44835 | AN2: 44866 | AO2: 44896 | AP2: Aud-22
A3: CAPITAL ADEQUACY | B3: Core Capital | C3: 10 M | D3: =(('Evolutive SFP'!B39+'Evolutive SFP'!B40+'Evolutive SFP'!B41+'Evolutive SFP'!B42+'Evolutive SFP'!B43+'Evolutive SFP'!B44)-'Evolutive SFP'!B10)/1000000 -> 755.77413 | E3: =(('Evolutive SFP'!C39+'Evolutive SFP'!C40+'Evolutive SFP'!C41+'Evolutive SFP'!C42+'Evolutive SFP'!C43+'Evolutive SFP'!C44)-'Evolutive SFP'!C10)/1000000 -> 779.79157 | F3: =(('Evolutive SFP'!D39+'Evolutive SFP'!D40+'Evolutive SFP'!D41+'Evolutive SFP'!D42+'Evolutive SFP'!D43+'Evolutive SFP'!D44)-'Evolutive SFP'!D10)/1000000 -> 791.31272 | G3: =(('Evolutive SFP'!E39+'Evolutive SFP'!E40+'Evolutive SFP'!E41+'Evolutive SFP'!E42+'Evolutive SFP'!E43+'Evolutive SFP'!E44)-'Evolutive SFP'!E10)/1000000 -> 809.83102 | H3: =(('Evolutive SFP'!F39+'Evolutive SFP'!F40+'Evolutive SFP'!F41+'Evolutive SFP'!F42+'Evolutive SFP'!F43+'Evolutive SFP'!F44)-'Evolutive SFP'!F10)/1000000 -> 832.23689 | I3: =(('Evolutive SFP'!G39+'Evolutive SFP'!G40+'Evolutive SFP'!G41+'Evolutive SFP'!G42+'Evolutive SFP'!G43+'Evolutive SFP'!G44)-'Evolutive SFP'!G10)/1000000 -> 856.46827 | J3: =(('Evolutive SFP'!H39+'Evolutive SFP'!H40+'Evolutive SFP'!H41+'Evolutive SFP'!H42+'Evolutive SFP'!H43+'Evolutive SFP'!H44)-'Evolutive SFP'!H10)/1000000 -> 877.60884 | K3: =(('Evolutive SFP'!I39+'Evolutive SFP'!I40+'Evolutive SFP'!I41+'Evolutive SFP'!I42+'Evolutive SFP'!I43+'Evolutive SFP'!I44)-'Evolutive SFP'!I10)/1000000 -> 886.4066 | ... AT3: =(('Evolutive SFP'!AR39+'Evolutive SFP'!AR40+'Evolutive SFP'!AR41+'Evolutive SFP'!AR42+'Evolutive SFP'!AR43+'Evolutive SFP'!AR44)-'Evolutive SFP'!AR10)/1000000 -> 0
B4: CCA | C4: Min 10% | D4: =D3/(('Evolutive SFP'!B27)/1000000) -> 0.10923233 | E4: =E3/(('Evolutive SFP'!C27)/1000000) -> 0.11253183 | F4: =F3/(('Evolutive SFP'!D27)/1000000) -> 0.1179843 | G4: =G3/(('Evolutive SFP'!E27)/1000000) -> 0.12003468 | H4: =H3/(('Evolutive SFP'!F27)/1000000) -> 0.12143229 | I4: =I3/(('Evolutive SFP'!G27)/1000000) -> 0.12278541 | J4: =J3/(('Evolutive SFP'!H27)/1000000) -> 0.12338285 | K4: =K3/(('Evolutive SFP'!I27)/1000000) -> 0.12291671 | ... AT4: =AT3/(('Evolutive SFP'!AR27)/1000000) -> #DIV/0!
B5: CCD | C5: Min 8% | D5: =D3/('Evolutive SFP'!B31/1000000) -> 0.13984079 | E5: =E3/('Evolutive SFP'!C31/1000000) -> 0.14221827 | F5: =F3/('Evolutive SFP'!D31/1000000) -> 0.14231062 | G5: =G3/('Evolutive SFP'!E31/1000000) -> 0.14470615 | H5: =H3/('Evolutive SFP'!F31/1000000) -> 0.14737552 | I5: =I3/('Evolutive SFP'!G31/1000000) -> 0.15016727 | J5: =J3/('Evolutive SFP'!H31/1000000) -> 0.15166217 | K5: =K3/('Evolutive SFP'!I31/1000000) -> 0.15194921 | ... AT5: =AT3/('Evolutive SFP'!AR31/1000000) -> #DIV/0!
B6: ICA | C6: Min 8% | D6: =((D3*1000000)-'Evolutive SFP'!B39)/'Evolutive SFP'!B27 -> 0.060241046 | E6: =((E3*1000000)-'Evolutive SFP'!C39)/'Evolutive SFP'!C27 -> 0.062653521 | F6: =((F3*1000000)-'Evolutive SFP'!D39)/'Evolutive SFP'!D27 -> 0.066033108 | G6: =((G3*1000000)-'Evolutive SFP'!E39)/'Evolutive SFP'!E27 -> 0.067790246 | H6: =((H3*1000000)-'Evolutive SFP'!F39)/'Evolutive SFP'!F27 -> 0.069616831 | I6: =((I3*1000000)-'Evolutive SFP'!G39)/'Evolutive SFP'!G27 -> 0.071387448 | J6: =((J3*1000000)-'Evolutive SFP'!H39)/'Evolutive SFP'!H27 -> 0.072390505 | K6: =((K3*1000000)-'Evolutive SFP'!I39)/'Evolutive SFP'!I27 -> 0.072175289 | ... AT6: =((AT3*1000000)-'Evolutive SFP'!AR39)/'Evolutive SFP'!AR27 -> #DIV/0!
A7: ASSET QUALITY | B7: A/LNPL30
B8: NPL30 | D8: =('FORM 4'!#REF!+'FORM 4'!#REF!+'FORM 4'!#REF!)/'Evolutive SFP'!B15 -> #REF! | E8: =('FORM 4'!#REF!+'FORM 4'!#REF!+'FORM 4'!#REF!)/'Evolutive SFP'!C15 -> #REF! | F8: =('FORM 4'!#REF!+'FORM 4'!#REF!+'FORM 4'!#REF!)/'Evolutive SFP'!D15 -> #REF! | G8: =('FORM 4'!#REF!+'FORM 4'!#REF!+'FORM 4'!#REF!)/'Evolutive SFP'!E15 -> #REF! | H8: =('FORM 4'!#REF!+'FORM 4'!#REF!+'FORM 4'!#REF!)/'Evolutive SFP'!F15 -> #REF! | I8: =('FORM 4'!#REF!+'FORM 4'!#REF!+'FORM 4'!#REF!)/'Evolutive SFP'!G15 -> #REF! | J8: =('FORM 4'!#REF!+'FORM 4'!#REF!+'FORM 4'!#REF!)/'Evolutive SFP'!H15 -> #REF! | K8: =('FORM 4'!#REF!+'FORM 4'!#REF!+'FORM 4'!#REF!)/'Evolutive SFP'!I15 -> #REF! | ... AT8: =('FORM 4'!#REF!+'FORM 4'!#REF!+'FORM 4'!#REF!)/'Evolutive SFP'!AR15 -> #REF!
A9: EARNINGS | B9: ROA | D9: ='Evolutitve SCI'!B33/(('Evolutive SFP'!#REF!+'Evolutive SFP'!B27)/2) -> #REF! | E9: ='Evolutitve SCI'!C33/(('Evolutive SFP'!B27+'Evolutive SFP'!C27)/2) -> 0.0020127032 | F9: ='Evolutitve SCI'!D33/(('Evolutive SFP'!C27+'Evolutive SFP'!D27)/2) -> 0.0026783662 | G9: ='Evolutitve SCI'!E33/(('Evolutive SFP'!D27+'Evolutive SFP'!E27)/2) -> 0.0049292469 | H9: ='Evolutitve SCI'!F33/(('Evolutive SFP'!E27+'Evolutive SFP'!F27)/2) -> 0.0075962393 | I9: ='Evolutitve SCI'!G33/(('Evolutive SFP'!F27+'Evolutive SFP'!G27)/2) -> 0.010352003 | J9: ='Evolutitve SCI'!H33/(('Evolutive SFP'!G27+'Evolutive SFP'!H27)/2) -> 0.024737184 | K9: ='Evolutitve SCI'!I33/(('Evolutive SFP'!H27+'Evolutive SFP'!I27)/2) -> 0.012534151 | L9: ='Evolutitve SCI'!J33/(('Evolutive SFP'!I27+'Evolutive SFP'!J27)/2) -> 0.014308618 | ... AT9: ='Evolutitve SCI'!AR33/(('Evolutive SFP'!AQ27+'Evolutive SFP'!AR27)/2) -> #DIV/0!
B10: Cost Income ratio | D10: ='Evolutitve SCI'!B23/'Evolutitve SCI'!B19 -> 0.66582373 | E10: ='Evolutitve SCI'!C23/'Evolutitve SCI'!C19 -> 0.50679815 | F10: ='Evolutitve SCI'!D23/'Evolutitve SCI'!D19 -> 0.43097091 | G10: ='Evolutitve SCI'!E23/'Evolutitve SCI'!E19 -> 0.42850435 | H10: ='Evolutitve SCI'!F23/'Evolutitve SCI'!F19 -> 0.41931981 | I10: ='Evolutitve SCI'!G23/'Evolutitve SCI'!G19 -> 0.4102601 | J10: ='Evolutitve SCI'!H23/'Evolutitve SCI'!H19 -> 0.41778292 | K10: ='Evolutitve SCI'!I23/'Evolutitve SCI'!I19 -> 0.43547288 | ... AT10: ='Evolutitve SCI'!AR23/'Evolutitve SCI'!AR19 -> #DIV/0!
B11: Operating Expense ratio | D11: =('Evolutitve SCI'!B23+'Evolutitve SCI'!B12)/(('Evolutive SFP'!B27+'Evolutive SFP'!D27)/2) -> 0.0068698887 | E11: =('Evolutitve SCI'!C23+'Evolutitve SCI'!C12)/(('Evolutive SFP'!C27+'Evolutive SFP'!E27)/2) -> 0.013644313 | F11: =('Evolutitve SCI'!D23+'Evolutitve SCI'!D12)/(('Evolutive SFP'!D27+'Evolutive SFP'!F27)/2) -> 0.021770816 | G11: =('Evolutitve SCI'!E23+'Evolutitve SCI'!E12)/(('Evolutive SFP'!E27+'Evolutive SFP'!G27)/2) -> 0.02852533 | H11: =('Evolutitve SCI'!F23+'Evolutitve SCI'!F12)/(('Evolutive SFP'!F27+'Evolutive SFP'!H27)/2) -> 0.03585131 | I11: =('Evolutitve SCI'!G23+'Evolutitve SCI'!G12)/(('Evolutive SFP'!G27+'Evolutive SFP'!I27)/2) -> 0.04308113 | J11: =('Evolutitve SCI'!H23+'Evolutitve SCI'!H12)/(('Evolutive SFP'!H27+'Evolutive SFP'!J27)/2) -> 0.099789418 | K11: =('Evolutitve SCI'!I23+'Evolutitve SCI'!I12)/(('Evolutive SFP'!I27+'Evolutive SFP'!K27)/2) -> 0.057183066 | L11: =('Evolutitve SCI'!J23+'Evolutitve SCI'!J12)/(('Evolutive SFP'!J27+'Evolutive SFP'!#REF!)/2) -> #REF! | M11: =('Evolutitve SCI'!K23+'Evolutitve SCI'!K12)/(('Evolutive SFP'!K27+'Evolutive SFP'!#REF!)/2) -> #REF! | N11: =('Evolutitve SCI'!L23+'Evolutitve SCI'!L12)/(('Evolutive SFP'!L27+'Evolutive SFP'!#REF!)/2) -> #REF! | O11: =('Evolutitve SCI'!M23+'Evolutitve SCI'!M12)/(('Evolutive SFP'!M27+'Evolutive SFP'!#REF!)/2) -> #REF! | P11: =('Evolutitve SCI'!N23+'Evolutitve SCI'!N12)/(('Evolutive SFP'!N27+'Evolutive SFP'!#REF!)/2) -> #REF! | Q11: =('Evolutitve SCI'!O23+'Evolutitve SCI'!O12)/(('Evolutive SFP'!O27+'Evolutive SFP'!#REF!)/2) -> #REF! | R11: =('Evolutitve SCI'!P23+'Evolutitve SCI'!P12)/(('Evolutive SFP'!P27+'Evolutive SFP'!#REF!)/2) -> #REF! | S11: =('Evolutitve SCI'!Q23+'Evolutitve SCI'!Q12)/(('Evolutive SFP'!Q27+'Evolutive SFP'!#REF!)/2) -> #REF! | ... AT11: =('Evolutitve SCI'!AR23+'Evolutitve SCI'!AR12)/(('Evolutive SFP'!AR27+'Evolutive SFP'!#REF!)/2) -> #REF!
A12: LIQUIDITY | B12: MIN LIQ ratio | C12: Min 15% | D12: =('Evolutive SFP'!B4)/('Evolutive SFP'!B28+'Evolutive SFP'!B29+'Evolutive SFP'!B32+'Evolutive SFP'!B33+'Evolutive SFP'!B34+'Evolutive SFP'!B35+'Evolutive SFP'!B36) -> 1.2990298 | E12: =('Evolutive SFP'!C4)/('Evolutive SFP'!C28+'Evolutive SFP'!C29+'Evolutive SFP'!C32+'Evolutive SFP'!C33+'Evolutive SFP'!C34+'Evolutive SFP'!C35+'Evolutive SFP'!C36) -> 1.5695611 | F12: =('Evolutive SFP'!D4)/('Evolutive SFP'!D28+'Evolutive SFP'!D29+'Evolutive SFP'!D32+'Evolutive SFP'!D33+'Evolutive SFP'!D34+'Evolutive SFP'!D35+'Evolutive SFP'!D36) -> 2.0708482 | G12: =('Evolutive SFP'!E4)/('Evolutive SFP'!E28+'Evolutive SFP'!E29+'Evolutive SFP'!E32+'Evolutive SFP'!E33+'Evolutive SFP'!E34+'Evolutive SFP'!E35+'Evolutive SFP'!E36) -> 1.450883 | H12: =('Evolutive SFP'!F4)/('Evolutive SFP'!F28+'Evolutive SFP'!F29+'Evolutive SFP'!F32+'Evolutive SFP'!F33+'Evolutive SFP'!F34+'Evolutive SFP'!F35+'Evolutive SFP'!F36) -> 1.6511522 | I12: =('Evolutive SFP'!G4)/('Evolutive SFP'!G28+'Evolutive SFP'!G29+'Evolutive SFP'!G32+'Evolutive SFP'!G33+'Evolutive SFP'!G34+'Evolutive SFP'!G35+'Evolutive SFP'!G36) -> 1.8844784 | J12: =('Evolutive SFP'!H4)/('Evolutive SFP'!H28+'Evolutive SFP'!H29+'Evolutive SFP'!H32+'Evolutive SFP'!H33+'Evolutive SFP'!H34+'Evolutive SFP'!H35+'Evolutive SFP'!H36) -> 1.9467039 | K12: =('Evolutive SFP'!I4)/('Evolutive SFP'!I28+'Evolutive SFP'!I29+'Evolutive SFP'!I32+'Evolutive SFP'!I33+'Evolutive SFP'!I34+'Evolutive SFP'!I35+'Evolutive SFP'!I36) -> 1.823172 | ... AT12: =('Evolutive SFP'!AR4)/('Evolutive SFP'!AR28+'Evolutive SFP'!AR29+'Evolutive SFP'!AR32+'Evolutive SFP'!AR33+'Evolutive SFP'!AR34+'Evolutive SFP'!AR35+'Evolutive SFP'!AR36) -> #DIV/0!
B13: T/LIQ ratio | D13: ='Evolutive SFP'!B4/('Evolutive SFP'!B31+'Evolutive SFP'!B36) -> 0.16515158 | E13: ='Evolutive SFP'!C4/('Evolutive SFP'!C31+'Evolutive SFP'!C36) -> 0.17383907 | F13: ='Evolutive SFP'!D4/('Evolutive SFP'!D31+'Evolutive SFP'!D36) -> 0.13408856 | G13: ='Evolutive SFP'!E4/('Evolutive SFP'!E31+'Evolutive SFP'!E36) -> 0.091189443 | H13: ='Evolutive SFP'!F4/('Evolutive SFP'!F31+'Evolutive SFP'!F36) -> 0.11271429 | I13: ='Evolutive SFP'!G4/('Evolutive SFP'!G31+'Evolutive SFP'!G36) -> 0.14594654 | J13: ='Evolutive SFP'!H4/('Evolutive SFP'!H31+'Evolutive SFP'!H36) -> 0.15829658 | K13: ='Evolutive SFP'!I4/('Evolutive SFP'!I31+'Evolutive SFP'!I36) -> 0.15656509 | ... AT13: ='Evolutive SFP'!AR4/('Evolutive SFP'!AR31+'Evolutive SFP'!AR36) -> #DIV/0!
B14: EB ratio | C14: Max 25% | D14: ='Evolutive SFP'!B37/'Evolutive SFP'!B27 -> 0 | E14: ='Evolutive SFP'!C37/'Evolutive SFP'!C27 -> 0.0019921987 | F14: ='Evolutive SFP'!D37/'Evolutive SFP'!D27 -> 0 | G14: ='Evolutive SFP'!E37/'Evolutive SFP'!E27 -> 0 | H14: ='Evolutive SFP'!F37/'Evolutive SFP'!F27 -> 0 | I14: ='Evolutive SFP'!G37/'Evolutive SFP'!G27 -> 0 | J14: ='Evolutive SFP'!H37/'Evolutive SFP'!H27 -> 0 | K14: ='Evolutive SFP'!I37/'Evolutive SFP'!I27 -> 0 | ... AT14: ='Evolutive SFP'!AR37/'Evolutive SFP'!AR27 -> #DIV/0!
B15: LA to TA ratio | D15: ='Evolutive SFP'!B4/'Evolutive SFP'!B27 -> 0.14600263 | E15: ='Evolutive SFP'!C4/'Evolutive SFP'!C27 -> 0.15276553 | F15: ='Evolutive SFP'!D4/'Evolutive SFP'!D27 -> 0.11733996 | G15: ='Evolutive SFP'!E4/'Evolutive SFP'!E27 -> 0.079714548 | H15: ='Evolutive SFP'!F4/'Evolutive SFP'!F27 -> 0.098383464 | I15: ='Evolutive SFP'!G4/'Evolutive SFP'!G27 -> 0.12720754 | J15: ='Evolutive SFP'!H4/'Evolutive SFP'!H27 -> 0.13789449 | K15: ='Evolutive SFP'!I4/'Evolutive SFP'!I27 -> 0.13647092 | ... AT15: ='Evolutive SFP'!AR4/'Evolutive SFP'!AR27 -> #DIV/0!
A16: STRUCTURE | B16: NEA ratio | C16: Max 10% | D16: =('Evolutive SFP'!B7+'Evolutive SFP'!B21)/'Evolutive SFP'!B27 -> 0.073699972 | E16: =('Evolutive SFP'!C7+'Evolutive SFP'!C21)/'Evolutive SFP'!C27 -> 0.075387466 | F16: =('Evolutive SFP'!D7+'Evolutive SFP'!D21)/'Evolutive SFP'!D27 -> 0.057377533 | G16: =('Evolutive SFP'!E7+'Evolutive SFP'!E21)/'Evolutive SFP'!E27 -> 0.078771422 | H16: =('Evolutive SFP'!F7+'Evolutive SFP'!F21)/'Evolutive SFP'!F27 -> 0.077561983 | I16: =('Evolutive SFP'!G7+'Evolutive SFP'!G21)/'Evolutive SFP'!G27 -> 0.064709535 | J16: =('Evolutive SFP'!H7+'Evolutive SFP'!H21)/'Evolutive SFP'!H27 -> 0.06431505 | K16: =('Evolutive SFP'!I7+'Evolutive SFP'!I21)/'Evolutive SFP'!I27 -> 0.064355933 | ... AT16: =('Evolutive SFP'!AR7+'Evolutive SFP'!AR21)/'Evolutive SFP'!AR27 -> #DIV/0!
