Workbook
Name BALANCE1_LDA01: '[1]Financial Statements'!$E$112
Name BALANCE1_LDA12: '[1]Financial Statements'!$E$123
Name BALANCE2_LDA01: '[1]Financial Statements'!$F$112
Name BALANCE2_LDA12: '[1]Financial Statements'!$F$123
Name BALANCE3_LDA01: '[1]Financial Statements'!$G$112
Name BALANCE3_LDA12: '[1]Financial Statements'!$G$123
Name BALANCE4_LDA01: '[1]Financial Statements'!$H$112
Name BALANCE4_LDA12: '[1]Financial Statements'!$H$123
Name BALANCE5_LDA01: '[1]Financial Statements'!$I$112
Name BALANCE5_LDA12: '[1]Financial Statements'!$I$123
Name BALANCE6_LDA01: '[1]Financial Statements'!$J$112
Name BALANCE6_LDA12: '[1]Financial Statements'!$J$123
Name PEARLS1_LA002: '[1]Financial Statements'!$E$280
Name PEARLS1_LE008: '[1]Financial Statements'!$E$275
Name PEARLS1_LE009: '[1]Financial Statements'!$E$276
Name PEARLS1_LR001: '[1]Financial Statements'!$E$282
Name PEARLS1_LR005: '[1]Financial Statements'!$E$286
Name PEARLS1_LR006: '[1]Financial Statements'!$E$287
Name PEARLS1_LR007: '[1]Financial Statements'!$E$288
Name PEARLS1_LR009: '[1]Financial Statements'!$E$290
Name PEARLS1_LS001: '[1]Financial Statements'!$E$298
Name PEARLS1_LS005: '[1]Financial Statements'!$E$302
Name PEARLS1_LS011: '[1]Financial Statements'!$E$308
Name PEARLS2_LA002: '[1]Financial Statements'!$F$280
Name PEARLS2_LE008: '[1]Financial Statements'!$F$275
Name PEARLS2_LE009: '[1]Financial Statements'!$F$276
Name PEARLS2_LR001: '[1]Financial Statements'!$F$282
Name PEARLS2_LR005: '[1]Financial Statements'!$F$286
Name PEARLS2_LR006: '[1]Financial Statements'!$F$287
Name PEARLS2_LR007: '[1]Financial Statements'!$F$288
Name PEARLS2_LR009: '[1]Financial Statements'!$F$290
Name PEARLS2_LS001: '[1]Financial Statements'!$F$298
Name PEARLS2_LS005: '[1]Financial Statements'!$F$302
Name PEARLS2_LS010: '[1]Financial Statements'!$F$307
Name PEARLS2_LS011: '[1]Financial Statements'!$F$308
Name PEARLS3_LA002: '[1]Financial Statements'!$G$280
Name PEARLS3_LE008: '[1]Financial Statements'!$G$275
Name PEARLS3_LE009: '[1]Financial Statements'!$G$276
Name PEARLS3_LR001: '[1]Financial Statements'!$G$282
Name PEARLS3_LR005: '[1]Financial Statements'!$G$286
Name PEARLS3_LR006: '[1]Financial Statements'!$G$287
Name PEARLS3_LR007: '[1]Financial Statements'!$G$288
Name PEARLS3_LR009: '[1]Financial Statements'!$G$290
Name PEARLS3_LS001: '[1]Financial Statements'!$G$298
Name PEARLS3_LS005: '[1]Financial Statements'!$G$302
Name PEARLS3_LS010: '[1]Financial Statements'!$G$307
Name PEARLS3_LS011: '[1]Financial Statements'!$G$308
Name PEARLS4_LA002: '[1]Financial Statements'!$H$280
Name PEARLS4_LE008: '[1]Financial Statements'!$H$275
Name PEARLS4_LE009: '[1]Financial Statements'!$H$276
Name PEARLS4_LR001: '[1]Financial Statements'!$H$282
Name PEARLS4_LR005: '[1]Financial Statements'!$H$286
Name PEARLS4_LR006: '[1]Financial Statements'!$H$287
Name PEARLS4_LR007: '[1]Financial Statements'!$H$288
Name PEARLS4_LR009: '[1]Financial Statements'!$H$290
Name PEARLS4_LS001: '[1]Financial Statements'!$H$298
Name PEARLS4_LS005: '[1]Financial Statements'!$H$302
Name PEARLS4_LS010: '[1]Financial Statements'!$H$307
Name PEARLS4_LS011: '[1]Financial Statements'!$H$308
Name PEARLS5_LA002: '[1]Financial Statements'!$I$280

Sheet Evolutive SFP
B3: AUDITED 2011 | C3: AUDITED 2012 | D3: AUDITED 2013 | E3: AUDITED 2014 | F3: AUDITED 2015 | G3: AUDITED 2016 | H3: AUDITED 2017 | I3: 43101 | J3: 43132 | K3: 43160 | L3: 43191 | M3: 43221 | N3: 43252 | O3: 43282 | P3: 43313 | Q3: 43344 | R3: 43374 | S3: 43405 | T3: 43435 | U3: AUDITED 2018 | V3: 43466 | W3: 43497 | X3: 43525 | Y3: 43556 | Z3: 43586 | AA3: 43617 | AB3: 43647 | AC3: 43678 | AD3: 43709 | AE3: 43739 | AF3: 43770 | AG3: 43800 | AH3: AUDITED 2019 | AI3: 43831 | AJ3: 43862 | AK3: 43891 | AL3: 43922 | AM3: 43952 | AN3: 43983 | AO3: 44044 | AP3: 44075 | AQ3: 44105 | AR3: 44136 | AS3: 44166 | AT3: Audited 2020 | AU3: 44197 | AV3: 44228 | AW3: 44256 | AX3: 44287 | AY3: 44317 | AZ3: 44348 | BA3: 44378 | BB3: 44409 | BC3: 44440 | BD3: 44470 | BE3: 44501 | BF3: 44531 | BG3: Audited 2021 | BH3: 44562 | BI3: 44593 | BJ3: 44621 | BK3: 44652 | BL3: 44682 | BM3: 44713 | BN3: 44743 | BO3: 44774 | BP3: 44805 | BQ3: 44835 | BR3: 44866 | BS3: 44896 | BT3: Audited 2022 | BU3: 44927 | BV3: 44958 | BW3: 44986 | BX3: 45017 | BY3: 45047 | BZ3: 45078 | CA3: 45108 | CB3: 45139 | CC3: 45170
A4: Cash & cash Equivalent | B4: =(B5+B6) -> 4171061 | C4: =(C5+C6) -> 2005744 | D4: =(D5+D6) -> 8488741 | E4: =(E5+E6) -> 13617624 | F4: =(F5+F6) -> 37177 | G4: =(G5+G6) -> 11883011 | H4: =(H5+H6) -> 42565374 | I4: =(I5+I6) -> 5094394.7 | ... CC4: =(CC5+CC6) -> 8208949.6
A5: Cash In Hand | B5: 4171061 | C5: 57008 | D5: 332646 | E5: 1730565 | F5: 37177 | G5: 65515 | H5: =2605926+300000+45078 -> 2951004 | I5: 2100894.4 | J5: 2840718.9 | K5: 2948528.9 | L5: 3616298.9 | M5: 3715914.9 | N5: 3993690.9 | O5: 5662806.8 | P5: 5249447.9 | Q5: 3867987.9 | R5: 4106300.9 | S5: 3993895.9 | T5: 6081154.9 | U5: 2243873 | V5: 3051990.8 | W5: 1952496.8 | X5: 1595603.8 | Y5: 4392495.8 | Z5: 5063685.8 | AA5: 1991970.8 | AB5: 2091535.8 | AC5: 3503758.8 | AD5: 5119051.8 | AE5: 2816540.8 | AF5: 2707491.5 | AG5: 2893023.5 | AH5: =1302655+300000 -> 1602655 | AI5: 4472837.5 | AJ5: 2707137.4 | AK5: 3765246.4 | AL5: 5676413.3 | AM5: 3006496.4 | AN5: 5635720 | AO5: 1602603 | AP5: 3007278 | AQ5: 2304652 | AR5: 910635.01 | AS5: 1117021 | AT5: =350000+767021 -> 1117021 | AU5: 841826.01 | AV5: 788748 | AW5: 3515180 | AX5: 2921068 | AY5: 3590315 | AZ5: 1243230 | BA5: 1386686 | BB5: 663432 | BC5: 540291 | BD5: 2948963 | BE5: 1133778 | BF5: 3138609.6 | BG5: =2788610+350000 -> 3138610 | BH5: 3478146.6 | BI5: 2466128 | BJ5: 3902992 | BK5: 1762070 | BL5: 3494705 | BM5: 1524682 | BN5: 3230642 | BO5: 3653246 | BP5: 2222849 | BQ5: 3421109 | BR5: 1811561 | BS5: 1523834 | BU5: 2267414 | BV5: 3612357 | BW5: 2426230 | BX5: 2095832 | BY5: 1168771 | BZ5: 3055884 | CA5: 1218725 | CB5: 3040357 | CC5: 644681
A6: Cash at Bank | C6: 1948736 | D6: 8156095 | E6: =13617624-E5 -> 11887059 | G6: =11883011-G5 -> 11817496 | H6: 39614370 | I6: 2993500.4 | J6: 4154969.8 | K6: 4732580.9 | L6: 4322904.8 | M6: 3996510.4 | N6: 2946237.8 | O6: 9186720.9 | P6: 4517338.4 | Q6: 10717274 | R6: 3432788.3 | S6: 11499159 | T6: 4082318.4 | U6: 9929688 | V6: 8574049.7 | W6: 4121185.3 | X6: 13109253 | Y6: 7833877.6 | Z6: 7836180.2 | AA6: 12326245 | AB6: 10240519 | AC6: 6468864.8 | AD6: 6771801.4 | AE6: 10257214 | AF6: 7282896.5 | AG6: 5600758.1 | AH6: =544474+809141+3448869+1159907+2614052+92466 -> 8668909 | AI6: 9904371.9 | AJ6: 11880178 | AK6: 6479516.6 | AL6: 6369183.7 | AM6: 10755203 | AN6: 7080660.5 | AO6: 18440443 | AP6: 15155242 | AQ6: 15528568 | AR6: 19850371 | AS6: 12512192 | AT6: =244474+8683434+827268+2757016 -> 12512192 | AU6: 9248375.1 | AV6: 9376232.4 | AW6: 12224670 | AX6: 11607855 | AY6: 11533765 | AZ6: 16106893 | BA6: 13898816 | BB6: 16437043 | BC6: 8310209.3 | BD6: 12323350 | BE6: 18075658 | BF6: 14060782 | BG6: =17087703-BG5 -> 13949093 | BH6: 13919000 | BI6: 16253029 | BJ6: 14535557 | BK6: 11669398 | BL6: 11023327 | BM6: 16080812 | BN6: 12992833 | BO6: 14025631 | BP6: 14593393 | BQ6: 15621493 | BR6: 16752223 | BS6: 13821847 | BU6: 12781319 | BV6: 11864595 | BW6: 12346481 | BX6: 12123127 | BY6: 12496725 | BZ6: 11800794 | CA6: 11790408 | CB6: 11409835 | CC6: 7564268.6
A7: Prepayment and Sundry | B7: 2679219 | C7: 863066 | D7: 2510315 | E7: 4516636 | F7: 2688882 | G7: 9292482 | H7: 2280087 | I7: 354051.21 | J7: 342674.14 | K7: 357893.57 | L7: 303292.64 | M7: 393785.73 | N7: 3283807.1 | O7: 412895.66 | P7: 2375574.3 | Q7: -7330670.1 | R7: 458062.56 | S7: -6529366.6 | T7: 3412095.9 | U7: 3966017 | V7: 1371464.7 | W7: 550435.84 | X7: 2047954.6 | Y7: 394102.95 | Z7: 414766.83 | AA7: -5886338.7 | AB7: 172169.78 | AC7: 445819.29 | AD7: 459521.24 | AE7: 314946.33 | AF7: 535417.06 | AG7: 418535.32 | AH7: 2019383 | AI7: 307618.88 | AJ7: 360688.41 | AK7: 578196.16 | AL7: 604875.16 | AM7: 236812.78 | AN7: 632852.16 | AO7: 560108 | AP7: 572430 | AQ7: 585589 | AR7: 599132 | AS7: 867414.81 | AT7: 1866499 | AU7: 611529 | AV7: 626207 | AW7: 637392 | AX7: 637392 | AY7: 665954 | AZ7: 685382 | BA7: 699317 | BB7: 699317 | BC7: 718911 | BD7: 741143 | BE7: 729142 | BF7: 652111.11 | BG7: =164500+1418098 -> 1582598 | BH7: 620660 | BI7: 631010 | BJ7: 636933 | BK7: 636933 | BL7: 655349 | BM7: 164500 | BN7: 172811 | BO7: 180705 | BP7: 192103 | BQ7: 192103 | BR7: 210346 | BS7: 164500 | BU7: 175667 | BV7: 187995 | BW7: 187995 | BX7: 187995 | BY7: 223545 | BZ7: 223545 | CA7: 223545 | CB7: 223545 | CC7: 164500
A8: Financial Investment | B8: =(B9+B10+B11+B13+B12) -> 4301970 | C8: =(C9+C10+C11+C13+C12) -> 4689870 | D8: =(D9+D10+D11+D13+D12) -> 6970410 | E8: =(E9+E10+E11+E13+E12) -> 9680814 | F8: =(F9+F10+F11+F13+F12) -> 11873268 | G8: =(G9+G10+G11+G13+G12) -> 13123495 | H8: =(H9+H10+H11+H13+H12) -> 14112600 | I8: =(I9+I10+I11+I13+I12) -> 0 | ... CC8: =(CC9+CC10+CC11+CC13+CC12) -> 8633989.4
A9: Government Security | I9: 0 | J9: 0 | K9: 0 | L9: 0 | M9: 0 | N9: 0 | O9: 0 | P9: 0 | Q9: 0 | R9: 0 | S9: 0 | T9: 0 | V9: 0 | W9: 0 | X9: 0 | Y9: 0 | Z9: 0 | AA9: 0 | AB9: 0 | AC9: 0 | AD9: 0 | AE9: 0 | AF9: 0 | AG9: 0 | AI9: 0 | AJ9: 0 | AK9: 0 | AL9: 0 | AM9: 0 | AN9: 0 | AO9: 0 | AP9: 0 | AQ9: 0 | AR9: 0 | AS9: 0 | AU9: 0 | AV9: 0 | AW9: 0 | AX9: 0 | AY9: 0 | AZ9: 0 | BA9: 0 | BB9: 0 | BC9: 0 | BD9: 0 | BE9: 0 | BF9: 0 | BH9: 0 | BI9: 0 | BJ9: 0 | BK9: 0 | BL9: 0 | BM9: 0 | BN9: 0 | BO9: 0 | BP9: 0 | BQ9: 0 | BR9: 0 | BS9: 0 | BU9: 0 | BV9: 0 | BW9: 0 | BX9: 0 | BY9: 0 | BZ9: 0 | CA9: 0 | CB9: 0 | CC9: 0
A10: Other Securities | I10: 0 | J10: 0 | K10: 0 | L10: 0 | M10: 0 | N10: 0 | O10: 0 | P10: 0 | Q10: 0 | R10: 0 | S10: 0 | T10: 0 | V10: 0 | W10: 0 | X10: 0 | Y10: 0 | Z10: 0 | AA10: 0 | AB10: 0 | AC10: 0 | AD10: 0 | AE10: 0 | AF10: 0 | AG10: 0 | AI10: 0 | AJ10: 0 | AK10: 0 | AL10: 0 | AM10: 0 | AN10: 0 | AO10: 0 | AP10: 0 | AQ10: 0 | AR10: 0 | AS10: 0 | AU10: 0 | AV10: 0 | AW10: 0 | AX10: 0 | AY10: 0 | AZ10: 0 | BA10: 0 | BB10: 0 | BC10: 0 | BD10: 0 | BE10: 0 | BF10: 0 | BH10: 0 | BI10: 0 | BJ10: 0 | BK10: 0 | BL10: 0 | BM10: 0 | BN10: 0 | BO10: 0 | BP10: 0 | BQ10: 0 | BR10: 0 | BS10: 0 | BU10: 0 | BV10: 0 | BW10: 0 | BX10: 0 | BY10: 0 | BZ10: 0 | CA10: 0 | CB10: 0 | CC10: 0
A11: Balances in NACCOS (E.g Jungu Kuu, ESS, Savings,Money Market,Coop FD, CFP) | I11: 0 | J11: 0 | K11: 0 | L11: 0 | M11: 0 | N11: 0 | O11: 0 | P11: 0 | Q11: 0 | R11: 0 | S11: 0 | T11: 0 | U11: 15098011 | V11: 0 | W11: 0 | X11: 0 | Y11: 0 | Z11: 0 | AA11: 0 | AB11: 0 | AC11: 0 | AD11: 0 | AE11: 0 | AF11: 0 | AG11: 0 | AI11: 0 | AJ11: 0 | AK11: 0 | AL11: 0 | AM11: 0 | AN11: 0 | AO11: 0 | AP11: 0 | AQ11: 0 | AR11: 0 | AS11: 0 | AU11: 0 | AV11: 0 | AW11: 0 | AX11: 0 | AY11: 0 | AZ11: 0 | BA11: 0 | BB11: 0 | BC11: 0 | BD11: 0 | BE11: 0 | BF11: 0 | BH11: 0 | BI11: 0 | BJ11: 0 | BK11: 0 | BL11: 0 | BM11: 0 | BN11: 0 | BO11: 0 | BP11: 0 | BQ11: 0 | BR11: 0 | BS11: 0 | BU11: 0 | BV11: 0 | BW11: 0 | BX11: 0 | BY11: 0 | BZ11: 0 | CA11: 0 | CB11: 0 | CC11: 0
A12: Equity Investments in NACCOs(Shares in- CIC, KUSCCO, COOP BANK,CAK, KERUSSU) | B12: 1250000 | C12: 1520000 | D12: 3580540 | E12: 6070944 | F12: 7763398 | G12: =161100+8613625+2270870+1967900 -> 13013495 | H12: 14112600 | I12: 0 | J12: 0 | K12: 0 | L12: 0 | M12: 0 | N12: 0 | O12: 0 | P12: 0 | Q12: 0 | R12: 0 | S12: 0 | T12: 0 | U12: 0 | V12: 0 | W12: 0 | X12: 0 | Y12: 0 | Z12: 0 | AA12: 0 | AB12: 0 | AC12: 0 | AD12: 0 | AE12: 0 | AF12: 0 | AG12: 0 | AH12: 16146154 | AI12: 0 | AJ12: 0 | AK12: 0 | AL12: 0 | AM12: 0 | AN12: 0 | AO12: 6954009.4 | AP12: 6994009.4 | AQ12: 7034009.4 | AR12: 7074009.4 | AS12: 7114009.4 | AT12: =95000+66100+10000+2270870+4572039 -> 7014009 | AX12: 0 | AY12: 0 | BH12: 7834009.4 | BI12: 7874009.4 | BJ12: 7914009.4 | BK12: 7954009.4 | BL12: 7994009.4 | BM12: 8034009.4 | BN12: 8074009.4 | BO12: 8114009.4 | BP12: 8154009.4 | BQ12: 8194009.4 | BR12: 8234009.4 | BS12: 8274009.4 | BU12: 0 | BV12: 0 | BW12: 0 | BX12: 0 | BY12: 0 | BZ12: 0 | CA12: 0 | CB12: 0 | CC12: 0
A13: Equity Investments in companies - shares/stocks | B13: =4301970-B12 -> 3051970 | C13: =4689870-C12 -> 3169870 | D13: =6970410-D12 -> 3389870 | E13: =9680814-E12 -> 3609870 | F13: =161100+100000+10000+2270870+1567900 -> 4109870 | G13: =100000+10000 -> 110000 | AH13: 100000 | AT13: 100000 | AU13: 7154009.4 | AV13: 7194009.4 | AW13: 7234009.4 | AX13: 7274009.4 | AY13: 7514009.4 | AZ13: 7554009.4 | BA13: 7594009.4 | BB13: 7634009.4 | BC13: 7674009.4 | BD13: 7714009.4 | BE13: 7754009.4 | BF13: 7794009.4 | BG13: 7920080 | BT13: 0 | BU13: 8314009.4 | BV13: 8354009.4 | BW13: 8394009.4 | BX13: 8434009.4 | BY13: 8474009.4 | BZ13: 8514009.4 | CA13: 8553989.4 | CB13: 8593989.4 | CC13: 8633989.4
A14: Net Loan Portfolio | B14: =(B15-B16) -> 31524548 | C14: =(C15-C16) -> 36920493 | D14: =(D15-D16) -> 36085793 | E14: =(E15-E16) -> 34456354 | F14: =(F15-F16) -> 32589509 | G14: =(G15-G16) -> 28504566 | H14: =(H15-H16) -> 29086031 | I14: =(I15-I16) -> 34575531 | ... CD14: =(CD15-CD16) -> 0
A15: Gross Loan Portfolio | B15: 31524548 | C15: 36920493 | D15: 36085793 | E15: 34456354 | F15: 33389509 | G15: 29854566 | H15: =244076+209632+3631769+6187564+9770913+10967804 -> 31011758 | I15: 34575531 | J15: 33764918 | K15: 34798281 | L15: 33789021 | M15: 33733276 | N15: 32870616 | O15: 28885717 | P15: 30209044 | Q15: 33253484 | R15: 33151954 | S15: 32745821 | T15: 29862145 | U15: 29862147 | V15: 30995823 | W15: 33706035 | X15: 29395402 | Y15: 28721214 | Z15: 28162168 | AA15: 31706424 | AB15: 28304800 | AC15: 29946706 | AD15: 28715854 | AE15: 28645058 | AF15: 30717200 | AG15: 29988726 | AH15: =95098+298550+4019181+7599174+8825713+9151010 -> 29988726 | AI15: 32516881 | AJ15: 32613412 | AK15: 33997628 | AL15: 31247366 | AM15: 30958397 | AN15: 30678214 | AO15: 30545196 | AP15: 31716573 | AQ15: 32368564 | AR15: 32015043 | AS15: 33586812 | AT15: =114242+1722923+3952080+6913347+8515373+12368848 -> 33586813 | AU15: 36565988 | AV15: 36228626 | AW15: 32981570 | AX15: 32830265 | AY15: 32865277 | AZ15: 36734980 | BA15: 36367144 | BB15: 35006595 | BC15: 38888360 | BD15: 34801220 | BE15: 34158311 | BF15: 32943350 | BG15: =28704269+BG16 -> 32943349 | BH15: 32485709 | BI15: 32189804 | BJ15: 32363227 | BK15: 34461139 | BL15: 34226908 | BM15: 34400949 | BN15: 34103925 | BO15: 33606644 | BP15: 34468468 | BQ15: 33927412 | BR15: 35206291 | BS15: 35777040 | BU15: 36888220 | BV15: 36898782 | BW15: 38683835 | BX15: 35204596 | BY15: 35975078 | BZ15: 36203370 | CA15: 37794329 | CB15: 37181777 | CC15: 42574709
A16: Allowance For Loan Loss | F16: 800000 | G16: 1350000 | H16: 1925727 | I16: 0 | J16: 0 | K16: 0 | L16: 0 | M16: 0 | N16: 0 | O16: 0 | P16: 0 | Q16: 0 | R16: 0 | S16: 0 | T16: 0 | U16: 2960451 | V16: 0 | W16: 0 | X16: 0 | Y16: 0 | Z16: 0 | AA16: 0 | AB16: 0 | AC16: 0 | AD16: 0 | AE16: 0 | AF16: 0 | AG16: 0 | AH16: 3560451 | AI16: 0 | AJ16: 0 | AK16: 0 | AL16: 0 | AM16: 0 | AN16: 0 | AO16: 0 | AP16: 0 | AQ16: 3560451 | AR16: 3560451 | AS16: 3560451 | AT16: 3560451 | AU16: 3560451 | AV16: 3560451 | AW16: 4142551 | AX16: 4142551 | AY16: 4142551 | AZ16: 4142551 | BA16: 4142551 | BB16: 4142551 | BC16: 4142551 | BD16: 4142551 | BE16: 4142551 | BF16: 4142551 | BG16: 4239080 | BH16: 4142551 | BI16: 4142551 | BJ16: 4239080 | BK16: 4239080 | BL16: 4239080 | BM16: 4239080 | BN16: 4239080 | BO16: 4239080 | BP16: 4239080 | BQ16: 4239080 | BR16: 4239080 | BS16: 4239080 | BU16: 4239080 | BV16: 4239080 | BW16: 3698400 | BX16: 3698400 | BY16: 3698400 | BZ16: 3698400 | CA16: 3698400 | CB16: 3698400 | CC16: 3698400
A17: Accounts Recievables | B17: =(B18+B19+B20) -> 0 | C17: =(C18+C19+C20) -> 0 | D17: =(D18+D19+D20) -> 0 | E17: =(E18+E19+E20) -> 0 | F17: =(F18+F19+F20) -> 0 | G17: =(G18+G19+G20) -> 0 | H17: =(H18+H19+H20) -> 0 | I17: =(I18+I19+I20) -> 0 | ... CC17: =(CC18+CC19+CC20) -> 0
A18: Tax Recoverable | I18: 0 | J18: 0 | K18: 0 | L18: 0 | M18: 0 | N18: 0 | O18: 0 | P18: 0 | Q18: 0 | R18: 0 | S18: 0 | T18: 0 | U18: 0 | V18: 0 | W18: 0 | X18: 0 | Y18: 0 | Z18: 0 | AA18: 0 | AB18: 0 | AC18: 0 | AD18: 0 | AE18: 0 | AF18: 0 | AG18: 0 | AI18: 0 | AJ18: 0 | AK18: 0 | AL18: 0 | AM18: 0 | AN18: 0 | AO18: 0 | AP18: 0 | AQ18: 0 | AR18: 0 | AS18: 0 | AU18: 0 | AV18: 0 | AW18: 0 | AX18: 0 | AY18: 0 | AZ18: 0 | BA18: 0 | BB18: 0 | BC18: 0 | BH18: 0 | BI18: 0 | BJ18: 0 | BK18: 0 | BL18: 0 | BM18: 0 | BN18: 0 | BO18: 0 | BP18: 0 | BQ18: 0 | BR18: 0 | BS18: 0 | BU18: 0 | BV18: 0 | BW18: 0 | BX18: 0 | BY18: 0 | BZ18: 0 | CA18: 0 | CB18: 0 | CC18: 0
A19: Deffered Tax Assets | I19: 0 | J19: 0 | K19: 0 | L19: 0 | M19: 0 | N19: 0 | O19: 0 | P19: 0 | Q19: 0 | R19: 0 | S19: 0 | T19: 0 | U19: 0 | V19: 0 | W19: 0 | X19: 0 | Y19: 0 | Z19: 0 | AA19: 0 | AB19: 0 | AC19: 0 | AD19: 0 | AE19: 0 | AF19: 0 | AG19: 0 | AI19: 0 | AJ19: 0 | AK19: 0 | AL19: 0 | AM19: 0 | AN19: 0 | AO19: 0 | AP19: 0 | AQ19: 0 | AR19: 0 | AS19: 0 | AU19: 0 | AV19: 0 | AW19: 0 | AX19: 0 | AY19: 0 | AZ19: 0 | BA19: 0 | BB19: 0 | BC19: 0 | BH19: 0 | BI19: 0 | BJ19: 0 | BK19: 0 | BL19: 0 | BM19: 0 | BN19: 0 | BO19: 0 | BP19: 0 | BQ19: 0 | BR19: 0 | BS19: 0 | BU19: 0 | BV19: 0 | BW19: 0 | BX19: 0 | BY19: 0 | BZ19: 0 | CA19: 0 | CB19: 0 | CC19: 0
A20: Retirement Benefit Assets | I20: 0 | J20: 0 | K20: 0 | L20: 0 | M20: 0 | O20: 0 | P20: 0 | Q20: 0 | R20: 0 | S20: 0 | T20: 0 | U20: 0 | V20: 0 | W20: 0 | X20: 0 | Y20: 0 | Z20: 0 | AA20: 0 | AB20: 0 | AC20: 0 | AD20: 0 | AE20: 0 | AF20: 0 | AG20: 0 | AI20: 0 | AJ20: 0 | AK20: 0 | AL20: 0 | AM20: 0 | AN20: 0 | AO20: 0 | AP20: 0 | AQ20: 0 | AR20: 0 | AS20: 0 | AU20: 0 | AV20: 0 | AW20: 0 | AX20: 0 | AY20: 0 | AZ20: 0 | BA20: 0 | BB20: 0 | BC20: 0 | BH20: 0 | BI20: 0 | BJ20: 0 | BK20: 0 | BL20: 0 | BM20: 0 | BN20: 0 | BO20: 0 | BP20: 0 | BQ20: 0 | BR20: 0 | BS20: 0 | BU20: 0 | BV20: 0 | BW20: 0 | BX20: 0 | BY20: 0 | BZ20: 0 | CA20: 0 | CB20: 0 | CC20: 0
A21: Property&Equipments&Other Assets | B21: =(B22+B23+B24+B25+B26) -> 1733278 | C21: =(C22+C23+C24+C25+C26) -> 1653529 | D21: =(D22+D23+D24+D25+D26) -> 2207010 | E21: =(E22+E23+E24+E25+E26) -> 2317124 | F21: =(F22+F23+F24+F25+F26) -> 1896351 | G21: =(G22+G23+G24+G25+G26) -> 6240222 | H21: =(H22+H23+H24+H25+H26) -> 9597930 | I21: =(I22+I23+I24+I25+I26) -> 26288006 | ... CC21: =(CC22+CC23+CC24+CC25+CC26) -> 22056438
A22: Investment Properties | I22: 16378525 | J22: 16501280 | K22: 16551280 | L22: 16551280 | M22: 17019070 | N22: 17069070 | O22: 17172190 | P22: 17222190 | Q22: 17332900 | R22: 17382900 | S22: 17456691 | T22: 17506691 | V22: 17637656 | W22: 17687655 | X22: 17767655 | Y22: 17817655 | Z22: 17867655 | AA22: 18217655 | AB22: 18374121 | AC22: 18474121 | AD22: 18597631 | AE22: 18647631 | AF22: 18697631 | AG22: 18717631 | AI22: 13767631 | AJ22: 13960207 | AK22: 14010207 | AL22: 14060207 | AM22: 14110207 | AN22: 14194798 | AO22: 0 | AP22: 0 | AQ22: 0 | AR22: 0 | AS22: 0 | AU22: 0 | AV22: 0 | AW22: 0 | AX22: 0 | AY22: 0 | AZ22: 0 | BA22: 0 | BB22: 0 | BC22: 0 | BD22: 0 | BE22: 0 | BF22: 0 | BG22: 21049644 | BH22: 0 | BI22: 0 | BJ22: 0 | BK22: 0 | BL22: 0 | BM22: 0 | BN22: 0 | BO22: 0 | BP22: 0 | BQ22: 0 | BR22: 0 | BS22: 0 | BU22: 0 | BV22: 0 | BW22: 0 | BX22: 0 | BY22: 0 | BZ22: 0 | CA22: 21018454 | CB22: 21018454 | CC22: 21018454
A23: Property and Equipment | B23: 1610246 | C23: 1189141 | D23: 1332352 | E23: 1803019 | F23: 1749407 | G23: =5761062+376299 -> 6137361 | H23: =588430+8937497 -> 9525927 | I23: 9909480.8 | J23: 9765784.8 | K23: 9599442.8 | L23: 9599442.8 | M23: 9602687.8 | N23: 9621212.8 | O23: 11629408 | P23: 12631333 | Q23: 12810659 | R23: 12829289 | S23: 12831507 | T23: 12833131 | U23: =12126808+574661 -> 12701469 | V23: 12753070 | W23: 12759270 | X23: 13068270 | Y23: 13097008 | Z23: 13098758 | AA23: 13099108 | AB23: 15465635 | AC23: 15465635 | AD23: 15465635 | AE23: 16463885 | AF23: 16508035 | AG23: 16220775 | AH23: =676154+15542646 -> 16218800 | AI23: 16238775 | AJ23: 17608718 | AK23: 17632998 | AL23: 18632998 | AM23: 19669198 | AN23: 19823168 | AO23: 20957465 | AP23: 20957465 | AQ23: 21473465 | AR23: 21493465 | AS23: 21714448 | AT23: =623278+21066475 -> 21689753 | AU23: 21730448 | AV23: 21730448 | AW23: 21788448 | AX23: 21788448 | AY23: 21788448 | AZ23: 21788448 | BA23: 21788448 | BB23: 21788448 | BC23: 21788448 | BD23: 21788448 | BE23: 21788448 | BF23: 21665049 | BG23: 543019 | BH23: 21665049 | BI23: 21725081 | BJ23: 21727981 | BK23: 21727981 | BL23: 21727981 | BM23: 21727981 | BN23: 21727981 | BO23: 21727981 | BP23: 21727981 | BQ23: 21727981 | BR23: 21921981 | BS23: 21750380 | BU23: 21750380 | BV23: 21750380 | BW23: 21692317 | BX23: 21692317 | BY23: 21692317 | BZ23: 21692317 | CA23: 661760.4 | CB23: 681755.4 | CC23: 681755.4
A24: Prepaid Lease Rentals | I24: 0 | J24: 0 | K24: 0 | L24: 0 | M24: 0 | N24: 0 | O24: 0 | P24: 0 | Q24: 0 | R24: 0 | S24: 0 | T24: 0 | V24: 0 | W24: 0 | X24: 0 | Y24: 0 | Z24: 0 | AA24: 0 | AB24: 0 | AC24: 0 | AD24: 0 | AE24: 0 | AF24: 0 | AG24: 0 | AI24: 0 | AJ24: 0 | AK24: 0 | AL24: 0 | AM24: 0 | AN24: 0 | AO24: 0 | AP24: 0 | AQ24: 0 | AR24: 0 | AS24: 0 | AU24: 0 | AV24: 0 | AW24: 0 | AX24: 0 | AY24: 0 | AZ24: 0 | BA24: 0 | BB24: 0 | BC24: 0 | BD24: 0 | BE24: 0 | BF24: 0 | BH24: 0 | BI24: 0 | BJ24: 0 | BK24: 0 | BL24: 0 | BM24: 0 | BN24: 0 | BO24: 0 | BP24: 0 | BQ24: 0 | BR24: 0 | BS24: 0 | BU24: 0 | BV24: 0 | BW24: 0 | BX24: 0 | BY24: 0 | BZ24: 0 | CA24: 0 | CB24: 0 | CC24: 0
A25: Intangible Assets | C25: 326422 | D25: 299885 | E25: 209920 | F25: 146944 | G25: 102861 | H25: 72003 | I25: 0 | J25: 0 | K25: 0 | L25: 0 | M25: 0 | N25: 0 | O25: 0 | P25: 0 | Q25: 0 | R25: 0 | S25: 0 | T25: 0 | U25: 50402.1 | V25: 0 | W25: 0 | X25: 0 | Y25: 0 | Z25: 0 | AA25: 0 | AB25: 0 | AC25: 0 | AD25: 0 | AE25: 0 | AF25: 0 | AG25: 0 | AH25: 35281 | AI25: 0 | AJ25: 0 | AK25: 0 | AL25: 0 | AM25: 0 | AN25: 0 | AO25: 0 | AP25: 0 | AQ25: 0 | AR25: 0 | AS25: 0 | AU25: 0 | AV25: 0 | AW25: 0 | AX25: 0 | AY25: 0 | AZ25: 0 | BA25: 0 | BB25: 0 | BC25: 0 | BD25: 0 | BE25: 0 | BF25: 0 | BG25: 17288 | BH25: 0 | BI25: 0 | BJ25: 0 | BK25: 0 | BL25: 0 | BM25: 0 | BN25: 0 | BO25: 0 | BP25: 0 | BQ25: 0 | BR25: 0 | BS25: 0 | BU25: 0 | BV25: 0 | BW25: 0 | BX25: 0 | BY25: 0 | BZ25: 0 | CA25: 12102 | CB25: 12102 | CC25: 12102
A26: Other Assets | B26: 123032 | C26: 137966 | D26: 574773 | E26: 304185 | I26: 0 | J26: 0 | K26: 0 | L26: 0 | M26: 0 | N26: 0 | O26: 0 | P26: 0 | Q26: 0 | R26: 0 | S26: 0 | T26: 0 | V26: 0 | W26: 0 | X26: 0 | Y26: 0 | Z26: 0 | AA26: 0 | AB26: 0 | AC26: 0 | AD26: 0 | AE26: 0 | AF26: 0 | AG26: 0 | AI26: 0 | AJ26: 0 | AK26: 0 | AL26: 0 | AM26: 0 | AN26: 0 | AO26: 904842.6 | AP26: 1249387.8 | AQ26: 1208578.6 | AR26: 1075284.1 | AS26: 1013375.2 | AT26: 24697 | AU26: 1042547.2 | AV26: 1420576.2 | AW26: 1137207.8 | AX26: 1184653.5 | AY26: 812931.16 | AZ26: -6983355.1 | BA26: 795052.62 | BB26: 662064.16 | BC26: 846467.76 | BD26: 833587.76 | BE26: 473541.16 | BF26: 572316 | BH26: 573054.13 | BI26: 266011.12 | BJ26: 557994.3 | BK26: 820011.27 | BL26: 560528.77 | BM26: 222909.05 | BN26: 548994 | BO26: 559394 | BP26: 536807.45 | BQ26: 536987.75 | BR26: 568747.53 | BS26: 618464 | BU26: 591956.55 | BV26: 598547.55 | BW26: 521576.35 | BX26: 496956.29 | BY26: 502194.29 | BZ26: 507343.24 | CA26: 506575.24 | CB26: 487105.27 | CC26: 344126
A27: Total Assets | B27: =(B21+B17+B14+B8+B7+B4) -> 44410076 | C27: =(C21+C17+C14+C8+C7+C4) -> 46132702 | D27: =(D21+D17+D14+D8+D7+D4) -> 56262269 | E27: =(E21+E17+E14+E8+E7+E4) -> 64588552 | F27: =(F21+F17+F14+F8+F7+F4) -> 49085187 | G27: =(G21+G17+G14+G8+G7+G4) -> 69043776 | H27: =(H21+H17+H14+H8+H7+H4) -> 97642022 | I27: =(I21+I17+I14+I8+I7+I4) -> 66311983 | ... CC27: =(CC21+CC17+CC14+CC8+CC7+CC4) -> 77940186
A28: Savings and Deposits | B28: =990000+4500274+351704 -> 5841978 | C28: 2653947 | D28: =6014250+327188 -> 6341438 | E28: =5535219+364748 -> 5899967 | F28: 5271989 | G28: 11473284 | H28: 10112825 | I28: 5565483.4 | J28: 5498954.3 | K28: 5371536.1 | L28: 5400807.5 | M28: 5455184.6 | N28: 5520622.7 | O28: 7084385.9 | P28: 6590844.8 | Q28: 5628970.7 | R28: 5691367.9 | S28: 6002402.5 | T28: 10142094 | U28: 10680343 | V28: 9786846.9 | W28: 7052454.5 | X28: 11373016 | Y28: 8312811.2 | Z28: 8195703.1 | AA28: 7108323.1 | AB28: 8345786.9 | AC28: 6903334 | AD28: 7368454.6 | AE28: 8145216.7 | AF28: 7126454.4 | AG28: 8049085.5 | AH28: 8496850 | AI28: 9846861.8 | AJ28: 10952432 | AK28: 7487515.6 | AL28: 8818164.4 | AM28: 10399099 | AN28: 8507267 | AO28: 8903541.5 | AP28: 7918113.7 | AQ28: 7517876 | AR28: 9104854.2 | AS28: 7020972.5 | AT28: 7533678 | AU28: 6693158.2 | AV28: 5736169.2 | AW28: 6861768.3 | AX28: 7030776.9 | AY28: 6960556.3 | AZ28: 6262415.9 | BA28: 9745764.9 | BB28: 9428957.1 | BC28: 5928484.7 | BD28: 6842797.4 | BE28: 9198733.9 | BF28: 9462491 | BG28: 9462491 | BH28: 8629384.5 | BI28: 9431571.3 | BJ28: 8982236.3 | BK28: 8818689.9 | BL28: 8435070.9 | BM28: 10022393 | BN28: 8129915 | BO28: 7969492.5 | BP28: 7251560.9 | BQ28: 8261406.7 | BR28: 8114650.8 | BS28: 8802818 | BU28: 8329361.4 | BV28: 7913593.9 | BW28: 7511956 | BX28: 8073478.9 | BY28: 6918568.1 | BZ28: 7104839.7 | CA28: 6106546 | CB28: 6387619.1 | CC28: 5671158.4
A29: Short Terrm Deposits | I29: 561679.16 | J29: 956410.72 | K29: 1295332.7 | L29: 1622577.8 | M29: 1858109.4 | N29: 2544787 | O29: 3160275.5 | P29: 3143337.1 | Q29: 2915929.1 | R29: 3237983.6 | S29: 3562797.4 | T29: 480448.72 | V29: 936053.44 | W29: 824803.44 | X29: 1683487.3 | Y29: 2075890.9 | Z29: 2278353.3 | AA29: 2300071.3 | AB29: 2868594.2 | AC29: 2939817.1 | AD29: 3168302.2 | AE29: 3470478.5 | AF29: 3767390.8 | AG29: 447794.02 | AI29: 883553.23 | AJ29: 1196533.4 | AK29: 1456072 | AL29: 1901452 | AM29: 2134407 | AN29: 2487851 | AO29: 3229416.6 | AP29: 3485620.5 | AQ29: 3794574.5 | AR29: 4437220.8 | AS29: 512704.77 | AT29: 0 | AU29: 520991.92 | AV29: 927433.22 | AW29: 1844113.4 | AX29: 2401010.2 | AY29: 2735742.3 | AZ29: 2473207.8 | BA29: 2954285.8 | BB29: 3138063.5 | BC29: 2932850.3 | BD29: 3607978.1 | BE29: 4044725.4 | BF29: 386054.76 | BH29: 841120.4 | BI29: 1149223.4 | BJ29: 1424991.8 | BK29: 2122107.4 | BL29: 2435619.5 | BM29: 2752388.1 | BN29: 2959673.8 | BO29: 3272490 | BP29: 3607114.2 | BQ29: 3852247.1 | BR29: 4285933.4 | BS29: 367642.02 | BU29: 709595.59 | BV29: 1031997.1 | BW29: 1719348.9 | BX29: 2038824 | BY29: 2311067.1 | BZ29: 2493914.4 | CA29: 2766434.4 | CB29: 3006856.4 | CC29: 2944016.4
A30: Non Withdrawable Deposits | B30: 24860593 | C30: 29607983 | D30: 32984337 | E30: 34606608 | F30: 33623566 | G30: 36128593 | H30: 37576767 | I30: 37552128 | J30: 37893569 | K30: 38081672 | L30: 38286717 | M30: 38646303 | N30: 38815296 | O30: 39273754 | P30: 38628823 | Q30: 38662147 | R30: 38642403 | S30: 38519201 | T30: 39141848 | U30: 39141848 | V30: 39507482 | W30: 38796403 | X30: 39084608 | Y30: 39255914 | Z30: 39040292 | AA30: 38559038 | AB30: 39202952 | AC30: 39296828 | AD30: 39393936 | AE30: 39518110 | AF30: 39221601 | AG30: 39316438 | AH30: 39316438 | AI30: 39319865 | AJ30: 39445819 | AK30: 39673950 | AL30: 40064569 | AM30: 40137074 | AN30: 40546454 | AO30: 40731541 | AP30: 41031928 | AQ30: 41384370 | AR30: 41334696 | AS30: 41809421 | AT30: 41809421 | AU30: 41852139 | AV30: 42191489 | AW30: 41979586 | AX30: 42344451 | AY30: 42464929 | AZ30: 42211695 | BA30: 42747288 | BB30: 42938956 | BC30: 42177479 | BD30: 42191463 | BE30: 42294830 | BF30: 42157242 | BG30: 42157242 | BH30: 42293657 | BI30: 41935393 | BJ30: 41699911 | BK30: 41876442 | BL30: 42202629 | BM30: 42352986 | BN30: 42266788 | BO30: 42524871 | BP30: 42557524 | BQ30: 42857234 | BR30: 42767812 | BS30: 43161599 | BU30: 43831373 | BV30: 44146264 | BW30: 44202266 | BX30: 43072564 | BY30: 43279709 | BZ30: 44109508 | CA30: 43904872 | CB30: 43788834 | CC30: 43270702
A31: Total Deposit Liabilities | B31: =SUM(B28:B30) -> 30702571 | C31: =SUM(C28:C30) -> 32261930 | D31: =SUM(D28:D30) -> 39325775 | E31: =SUM(E28:E30) -> 40506575 | F31: =SUM(F28:F30) -> 38895555 | G31: =SUM(G28:G30) -> 47601877 | H31: =SUM(H28:H30) -> 47689592 | I31: =SUM(I28:I30) -> 43679291 | ... CC31: =SUM(CC28:CC30) -> 51885876
A32: Tax Payable | F32: 79999 | G32: 43968 | I32: 5411.2 | J32: 5339.7 | K32: 5401.7 | L32: 6229.2 | M32: 5583.7 | N32: 5111.2 | O32: 12668.7 | P32: 10506.2 | Q32: 7236.7 | R32: 19122.7 | S32: 23628.7 | T32: 33350.7 | U32: 51709 | V32: 23402.7 | W32: 15971.7 | X32: 80114.7 | Y32: 42386.7 | Z32: 34139.7 | AA32: 27007.7 | AB32: 22372.7 | AC32: 23052.7 | AD32: 18737.7 | AE32: 15281.7 | AF32: 23513.7 | AG32: 20447.7 | AH32: 64642 | AI32: 21417.7 | AJ32: 18860.7 | AK32: 22214.7 | AL32: 17473.7 | AM32: 15410.7 | AN32: 19080.7 | AO32: 15170.7 | AP32: 19131.7 | AQ32: 18882.7 | AR32: 15386.7 | AS32: 28694.7 | AT32: 28817 | AU32: 12853.7 | AV32: 20462.7 | AW32: 23558.7 | AX32: 21185.7 | AY32: 20468.7 | AZ32: 18004.7 | BA32: 27005.7 | BB32: 20179.7 | BC32: 15517.7 | BD32: 25243.7 | BE32: 16554.7 | BF32: 22971.7 | BG32: 2242 | BH32: 18155.7 | BI32: 15545.7 | BJ32: 20998.7 | BK32: 26503.7 | BL32: 20303.7 | BM32: 16854.7 | BN32: 21477.7 | BO32: 17453.7 | BP32: 20770.7 | BQ32: 14284.7 | BR32: 19919.7 | BS32: 20845.7 | BU32: 18435.7 | BV32: 15907.7 | BW32: 29533.7 | BX32: 26159.7 | BY32: 33189.7 | BZ32: 22749.7 | CA32: 30984.7 | CB32: 17719.7 | CC32: 14579.7
A33: Dividends Payable | C33: =2672099 -> 2672099 | D33: =2638747+200000+540001 -> 3378748 | G33: 2480651 | H33: 1503071 | I33: 0 | J33: 0 | K33: 0 | L33: 0 | M33: 0 | N33: 0 | O33: 0 | P33: 0 | Q33: 0 | R33: 0 | S33: 0 | T33: 0 | U33: 1957092.4 | V33: 0 | W33: 0 | X33: 0 | Y33: 0 | Z33: 0 | AA33: 0 | AB33: 0 | AC33: 0 | AD33: 0 | AE33: 0 | AF33: 0 | AG33: 0 | AH33: 2358986 | AI33: 0 | AJ33: 0 | AK33: 0 | AL33: 0 | AM33: 0 | AN33: 0 | AO33: 0 | AP33: 0 | AQ33: 0 | AR33: 0 | AS33: 0 | AT33: 3344754 | AU33: 0 | AV33: 0 | AW33: 0 | AX33: 0 | AY33: 0 | AZ33: 0 | BA33: 0 | BB33: 0 | BC33: 0 | BD33: 0 | BE33: 0 | BF33: 0 | BG33: 2951007 | BH33: 0 | BI33: 0 | BJ33: 0 | BK33: 0 | BL33: 0 | BM33: 0 | BN33: 0 | BO33: 0 | BP33: 0 | BQ33: 0 | BR33: 0 | BS33: 0 | BU33: 0 | BV33: 0 | BW33: 0 | BX33: 0 | BY33: 0 | BZ33: 0 | CA33: 0 | CB33: 0 | CC33: 0
A34: Deferred Tax Liability | I34: 0 | J34: 0 | K34: 0 | L34: 0 | M34: 0 | N34: 0 | O34: 0 | P34: 0 | Q34: 0 | R34: 0 | S34: 0 | T34: 0 | U34: 0 | V34: 0 | W34: 0 | X34: 0 | Y34: 0 | Z34: 0 | AA34: 0 | AB34: 0 | AC34: 0 | AD34: 0 | AE34: 0 | AF34: 0 | AG34: 0 | AI34: 0 | AJ34: 0 | AK34: 0 | AL34: 0 | AM34: 0 | AN34: 0 | AO34: 0 | AP34: 0 | AQ34: 0 | AR34: 0 | AS34: 0 | AT34: 0 | AU34: 0 | AV34: 0 | AW34: 0 | AX34: 0 | AY34: 0 | AZ34: 0 | BA34: 0 | BB34: 0 | BC34: 0 | BD34: 0 | BE34: 0 | BF34: 0 | BH34: 0 | BI34: 0 | BJ34: 0 | BK34: 0 | BL34: 0 | BM34: 0 | BN34: 0 | BO34: 0 | BP34: 0 | BQ34: 0 | BR34: 0 | BS34: 0 | BU34: 0 | BV34: 0 | BW34: 0 | BX34: 0 | BY34: 0 | BZ34: 0 | CA34: 0 | CB34: 0 | CC34: 0
A35: Retirement Benefits Liabilty | G35: 2167716 | I35: 0 | J35: 0 | K35: 0 | L35: 0 | M35: 0 | N35: 0 | O35: 0 | P35: 0 | Q35: 0 | R35: 0 | S35: 0 | T35: 0 | U35: 0 | V35: 0 | W35: 0 | X35: 0 | Y35: 0 | Z35: 0 | AA35: 0 | AB35: 0 | AC35: 0 | AD35: 0 | AE35: 0 | AF35: 0 | AG35: 0 | AI35: 0 | AJ35: 0 | AK35: 0 | AL35: 0 | AM35: 0 | AN35: 0 | AO35: 0 | AP35: 0 | AQ35: 0 | AR35: 0 | AS35: 0 | AT35: 0 | AU35: 0 | AV35: 0 | AW35: 0 | AX35: 0 | AY35: 0 | AZ35: 0 | BA35: 0 | BB35: 0 | BC35: 0 | BD35: 0 | BE35: 0 | BF35: 0 | BH35: 0 | BI35: 0 | BJ35: 0 | BK35: 0 | BL35: 0 | BM35: 0 | BN35: 0 | BO35: 0 | BP35: 0 | BQ35: 0 | BR35: 0 | BS35: 0 | BU35: 0 | BV35: 0 | BW35: 0 | BX35: 0 | BY35: 0 | BZ35: 0 | CA35: 0 | CB35: 0 | CC35: 0
A36: Other Liabilities | B36: 3470185 | C36: =1787148+321686 -> 2108834 | D36: =2600712+656204 -> 3256916 | E36: =5076866+150000+606579 -> 5833445 | F36: =1717414+3437605 -> 5155019 | H36: 350096 | I36: 2341274.1 | J36: 2617476.2 | K36: 3525343.3 | L36: 2242713.8 | M36: 1684888.4 | N36: 1573570.5 | O36: 1641539.9 | P36: 1624192.4 | Q36: 1695237.6 | R36: 1874551.4 | S36: 1930573.3 | T36: 1939943.5 | U36: 761254 | V36: 6264105 | W36: 6227222.1 | X36: 5659216.2 | Y36: 3231363 | Z36: 3097656 | AA36: 3143998.2 | AB36: 3042708.6 | AC36: 3472678.6 | AD36: 3044796.8 | AE36: 3323035.8 | AF36: 3386759.9 | AG36: 4124370.8 | AH36: 2022756 | AI36: 8237697.4 | AJ36: 8269920 | AK36: 7441499.5 | AL36: 5063911.8 | AM36: 4841286 | AN36: 4819427.3 | AO36: 4279100.8 | AP36: 3956450 | AQ36: 423017.86 | AR36: 372991.86 | AS36: 1049732 | AT36: 2247051 | AU36: 5365014.4 | AV36: 5541733.1 | AW36: 4049323.7 | AX36: 1294075.9 | AY36: 998203.13 | AZ36: 76321.6 | BA36: 173648.15 | BB36: 66432.08 | BC36: -36681.05 | BD36: 32028.05 | BE36: -58343.8 | BF36: 156344.25 | BG36: 1068513 | BH36: 4311541.7 | BI36: 4299392.9 | BJ36: 2992515.2 | BK36: -726678.24 | BL36: -794465.05 | BM36: -826567.04 | BN36: -866289.44 | BO36: -852790.2 | BP36: -1020657.2 | BQ36: -1003694.4 | BR36: -951943.4 | BS36: -740099.86 | BU36: 3826265.6 | BV36: 3869746.4 | BW36: 3738295.5 | BX36: -118074.66 | BY36: 220798.17 | BZ36: 94194.22 | CA36: -122479.65 | CB36: -110999.87 | CC36: 5553.27
A37: External Borrowings | B37: 3635383 | C37: 361622 | D37: 637835 | E37: 4500000 | F37: 2420583 | H37: 3576860 | I37: 3176106 | J37: 3015984.9 | K37: 2748772.3 | L37: 2489256.3 | M37: 2211045 | N37: 1911045.1 | O37: 1666964.5 | P37: 1666964.5 | Q37: 1102544.3 | R37: 802544.3 | S37: 516553.35 | T37: 216553.35 | U37: 216553.35 | V37: 0 | W37: 0 | X37: 0 | Y37: 0 | Z37: 0 | AA37: 0 | AB37: 0 | AC37: 0 | AD37: 0 | AE37: 0 | AF37: 0 | AG37: 0 | AI37: 0 | AJ37: 0 | AK37: 0 | AL37: 0 | AM37: 0 | AN37: 0 | AO37: 0 | AP37: 0 | AQ37: 0 | AR37: 0 | AS37: 0 | AU37: 0 | AV37: 0 | AW37: 0 | AX37: 0 | AY37: 0 | AZ37: 0 | BA37: 0 | BB37: 0 | BC37: 0 | BD37: 0 | BE37: 0 | BF37: 0 | BH37: 0 | BI37: 0 | BJ37: 0 | BK37: 0 | BL37: 0 | BM37: 0 | BN37: 0 | BO37: 0 | BP37: 0 | BQ37: 0 | BR37: 0 | BS37: 0 | BU37: 0 | BV37: 0 | BW37: 0 | BX37: 0 | BY37: 0 | BZ37: 0 | CA37: 0 | CB37: 0 | CC37: 0
A38: Total Liabilities | B38: =SUM(B31:B37) -> 37808139 | C38: =SUM(C31:C37) -> 37404485 | D38: =SUM(D31:D37) -> 46599274 | E38: =SUM(E31:E37) -> 50840020 | F38: =SUM(F31:F37) -> 46551156 | G38: =SUM(G31:G37) -> 52294212 | H38: =SUM(H31:H37) -> 53119619 | I38: =SUM(I31:I37) -> 49202082 | ... CC38: =SUM(CC31:CC37) -> 51906009
A39: Share Capital | B39: 5621296 | C39: =6905081+992000 -> 7897081 | D39: =6905021+1319000 -> 8224021 | E39: =8509483+1331000+824457 -> 10664940 | F39: =8509483+960817+1331500 -> 10801800 | G39: =9823239+187532 -> 10010771 | H39: =10010771+1185542+1335000 -> 12531313 | I39: 12531313 | J39: 12539557 | K39: 12546957 | L39: 12552757 | M39: 12560747 | N39: 12636693 | O39: 12651209 | P39: 12656809 | Q39: 12656809 | R39: 12662109 | S39: 12671009 | T39: 12684723 | U39: =10084216+2600506 -> 12684722 | V39: 12691760 | W39: 12691760 | X39: 12705860 | Y39: 12713659 | Z39: 12716660 | AA39: 12718660 | AB39: 12728260 | AC39: 12730560 | AD39: 12732560 | AE39: 12734860 | AF39: 12988600 | AG39: 12966352 | AH39: =10310909+1315943+1339500 -> 12966352 | AI39: 12971152 | AJ39: 12973152 | AK39: 12974152 | AL39: 12975652 | AM39: 12977152 | AN39: 12979008 | AO39: 13104844 | AP39: 13106344 | AQ39: 13108844 | AR39: 13110344 | AS39: 13112644 | AT39: =10433245+1339899+1339500 -> 13112644 | AU39: 13112644 | AV39: 13113644 | AW39: 13116144 | AX39: 13119624 | AY39: 13122624 | AZ39: 13240686 | BA39: 13245186 | BB39: 13245898 | BC39: 13245898 | BD39: 13249698 | BE39: 13251498 | BF39: 13305823 | BG39: 10604628 | BH39: 13307323 | BI39: 13308823 | BJ39: 13311623 | BK39: 13312123 | BL39: 13315623 | BM39: 13316123 | BN39: 13318623 | BO39: 13319246 | BP39: 13360452 | BQ39: 13360952 | BR39: 13360952 | BS39: 13384352 | BU39: 13385652 | BV39: 13386952 | BW39: 13387452 | BX39: 13388452 | BY39: 13388952 | BZ39: 13389452 | CA39: 13389952 | CB39: 13395279 | CC39: 13395279
A40: Capital Grants | I40: 0 | J40: 0 | K40: 0 | L40: 0 | M40: 0 | N40: 0 | O40: 0 | P40: 0 | Q40: 0 | R40: 0 | S40: 0 | T40: 0 | U40: 0 | V40: 0 | W40: 0 | X40: 0 | Y40: 0 | Z40: 0 | AA40: 0 | AB40: 0 | AC40: 0 | AD40: 0 | AE40: 0 | AF40: 0 | AG40: 0 | AI40: 0 | AJ40: 0 | AK40: 0 | AL40: 0 | AM40: 0 | AN40: 0 | AO40: 0 | AP40: 0 | AQ40: 0 | AR40: 0 | AS40: 0 | AU40: 0 | AV40: 0 | AW40: 0 | AX40: 0 | AY40: 0 | AZ40: 0 | BA40: 0 | BB40: 0 | BC40: 0 | BD40: 0 | BE40: 0 | BF40: 0 | BH40: 0 | BI40: 0 | BJ40: 0 | BK40: 0 | BL40: 0 | BM40: 0 | BN40: 0 | BO40: 0 | BP40: 0 | BQ40: 0 | BR40: 0 | BS40: 0 | BU40: 0 | BV40: 0 | BW40: 0 | BX40: 0 | BY40: 0 | BZ40: 0 | CA40: 0 | CB40: 0 | CC40: 0
A41: Prior Year Retained Earnigs | B41: 461312 | C41: 461314.45 | E41: 629358 | G41: 1392830 | H41: 1579427 | I41: 1579426.8 | J41: 1579426.8 | K41: 1748020.8 | L41: 1748020.8 | M41: 1748020.8 | N41: 1748020.8 | O41: 1748020.8 | P41: 1748020.8 | Q41: 1748020.8 | R41: 1748020.8 | S41: 1748020.8 | T41: 1748020.8 | U41: 1748020.8 | V41: 1748020.8 | W41: 1748020.8 | X41: 2256870.9 | Y41: 2256870.9 | Z41: 2256870.9 | AA41: 2256870.9 | AB41: 2256870.9 | AC41: 2256870.9 | AD41: 2256870.9 | AE41: 2256870.9 | AF41: 2256870.9 | AG41: 2256870.9 | AH41: 2279446 | AI41: 2256870.9 | AJ41: 2256870.9 | AK41: 2741685.9 | AL41: 2741685.9 | AM41: 2741685.9 | AN41: 2741685.9 | AO41: 2741685 | AP41: 2741685 | AQ41: 2741685 | AR41: 2741685 | AS41: 2741685 | AT41: 2741685 | AU41: 2741685.9 | AV41: 2741685.9 | AW41: 3253606.9 | AX41: 3253606.9 | AY41: 3253606.9 | AZ41: 3253606.9 | BA41: 3253606.9 | BB41: 3253606.9 | BC41: 3253606.9 | BD41: 3253606.9 | BE41: 3253606.9 | BF41: 3253606.9 | BG41: =4164333-BG42 -> 2008198 | BH41: 3253606.9 | BI41: 3253606.9 | BJ41: 4164332.9 | BK41: 4164332.9 | BL41: 4164332.9 | BM41: 4164332.9 | BN41: 4164332.9 | BO41: 4164332.9 | BP41: 4164332.9 | BQ41: 4164332.9 | BR41: 4164332.9 | BS41: 4164332.9 | BU41: 4164332.9 | BV41: 4164332.9 | BW41: 4427856.9 | BX41: 4427856.9 | BY41: 4164332.9 | BZ41: 4164332.9 | CA41: 4427856.9 | CB41: 4427856.9 | CC41: 4427856.9
A42: Current Year Surplus | C42: =291088-C41 -> -170226.45 | D42: 338270 | E42: 744861 | F42: 18611 | G42: 186597 | H42: =210743-42149 -> 168594 | I42: 55977.45 | J42: 320443.54 | K42: 679638.53 | L42: 847828.42 | M42: 1306029.5 | N42: 2044155.4 | O42: 2725587.9 | P42: 3150097.4 | Q42: 3249407.1 | R42: 3697877.8 | S42: 4038187.8 | T42: 4405220.3 | U42: 531426 | V42: 441050.57 | W42: 435110.81 | X42: 1022777.8 | Y42: 1249269.5 | Z42: 1705351.6 | AA42: 2222907.8 | AB42: 3063047.2 | AC42: 3563575.3 | AD42: 4027647.6 | AE42: 4563232.5 | AF42: 4559291.2 | AG42: 3539901.2 | AH42: =2741685-2279446 -> 462239 | AI42: 552509.1 | AJ42: 898564.59 | AK42: 1432954 | AL42: 1774386 | AM42: 2256452.2 | AN42: 2710890.5 | AO42: 3725619 | AP42: 4159363.6 | AQ42: 4719976.6 | AR42: 5106561.6 | AS42: 4855217.7 | AT42: =298736-59747 -> 238989 | AU42: 102035.83 | AV42: 298030.17 | AW42: 886096.07 | AX42: 1274680.8 | AY42: 1710290.1 | AZ42: 2089370 | BA42: 2878408.2 | BB42: 3294536.2 | BC42: 3745262.3 | BD42: 4443626.8 | BE42: 4607003.5 | BF42: 4577413.6 | BG42: 2156135 | BH42: 416559.37 | BI42: 507237.14 | BJ42: 1010049.6 | BK42: 1405986 | BL42: 1871658.4 | BM42: 2325296.2 | BN42: 2824639.1 | BO42: 3420479.6 | BP42: 3922478 | BQ42: 4082297.1 | BR42: 4911466.9 | BS42: 4736549.2 | BU42: 471915 | BV42: 705837 | BW42: 1426046.1 | BX42: 1515883.5 | BY42: 2406334.1 | BZ42: 2808582.9 | CA42: 3466033.4 | CB42: 3926066.4 | CC42: 4099752
...

Sheet Evolutitve SCI
B1: "000" | C1: "000" | D1: "000" | E1: "000" | F1: "000" | G1: "000" | H1: "000" | I1: "000" | AG1: "000"
B2: Audited 2011 | C2: Audited 2012 | D2: Audited 2013 | E2: Audited 2014 | F2: Audited 2015 | G2: Audited 2016 | H2: Audited 2017 | I2: 43101 | J2: 43132 | K2: 43160 | L2: 43191 | M2: 43221 | N2: 43252 | O2: 43282 | P2: 43313 | Q2: 43344 | R2: 43405 | S2: 43435 | T2: AUDITED 2018 | U2: 43466 | V2: 43497 | W2: 43525 | X2: 43556 | Y2: 43586 | Z2: 43617 | AA2: 43647 | AB2: 43678 | AC2: 43709 | AD2: 43739 | AE2: 43770 | AF2: 43800 | AG2: Audited 2019 | AH2: 43831 | AI2: 43862 | AJ2: 43891 | AK2: 43922 | AL2: 43952 | AM2: 43983 | AN2: 44044 | AO2: 44075 | AP2: 44105 | AQ2: 44136 | AR2: 44166 | AS2: Audited 2020 | AT2: 44197 | AU2: 44228 | AV2: 44256 | AW2: 44287 | AX2: 44317 | AY2: 44348 | AZ2: 44378 | BA2: 44409 | BB2: 44440 | BC2: 44470 | BD2: 44501 | BE2: 44531 | BF2: Audited 2021 | BG2: 44562 | BH2: 44593 | BI2: 44621 | BJ2: 44652 | BK2: 44682 | BL2: 44713 | BM2: 44743 | BN2: 44774 | BO2: 44805 | BP2: 44835 | BQ2: 44866 | BR2: 44896 | BS2: Audited 2022 | BT2: 44927 | BU2: 44958 | BV2: 44986 | BW2: 45017 | BX2: 45047 | BY2: 45078 | BZ2: 45108 | CA2: 45139 | CB2: 45170
A3: Financial Income | B3: =B4+B7 -> 4618217 | C3: =C4+C7 -> 5184217 | D3: =D4+D7 -> 7952957 | E3: =E4+E7 -> 8542749 | F3: =F4+F7 -> 8421094 | G3: =G4+G7 -> 8907817 | H3: =H4+H7 -> 8230050 | I3: =I4+I7 -> 232839.35 | ... CB3: =CB4+CB7 -> 8166071.4
A4: Financial Income From Loans Portfolio | B4: =SUM(B5:B6) -> 3294763 | C4: =SUM(C5:C6) -> 4288884 | D4: =SUM(D5:D6) -> 6035735 | E4: =SUM(E5:E6) -> 7524715 | F4: =SUM(F5:F6) -> 4986862 | G4: =SUM(G5:G6) -> 3743538 | H4: =SUM(H5:H6) -> 3567572 | I4: =SUM(I5:I6) -> 11651.35 | ... CB4: =SUM(CB5:CB6) -> 7206908.2
A5: Interest from Loans Portfolio | B5: =2885192+409571 -> 3294763 | C5: =2929622+1359262 -> 4288884 | D5: 3512831 | E5: 4843673 | F5: 4986862 | G5: 3743538 | H5: 3567572 | I5: 11651.35 | J5: 301453.9 | K5: 585768.16 | L5: 874257.55 | M5: 1148206.2 | N5: 1424737.3 | O5: 1935845.3 | P5: 2208519.6 | Q5: 2218615.1 | R5: 2795560.9 | S5: 3321955.7 | T5: 3321956 | U5: 285791.57 | V5: 304362.23 | W5: 825717.24 | X5: 1100922.9 | Y5: 1368129.2 | Z5: 1387377.9 | AA5: 1861531.9 | AB5: 2126795.3 | AC5: 2407641.4 | AD5: 2662890 | AE5: 2955324.9 | AF5: 3214668 | AG5: =2960343+254325 -> 3214668 | AH5: 292294.1 | AI5: 594618.59 | AJ5: 878858.52 | AK5: 1163295.3 | AL5: 1431499.5 | AM5: 1706433.5 | AN5: 2247354.5 | AO5: 2524122.9 | AP5: 2837829 | AQ5: 3125492.1 | AR5: 3390721.3 | AS5: =3124887+265833 -> 3390720 | AT5: 16718.83 | AU5: 297804.17 | AV5: 865337.64 | AW5: 1175347.7 | AX5: 1474867.3 | AY5: 1511971.8 | AZ5: 2130246.5 | BA5: 2468885 | BB5: 2526325.8 | BC5: 3152612 | BD5: 3471549.2 | BE5: 3814191.9 | BF5: 3859683 | BG5: 310141.87 | BH5: 610009.64 | BI5: 930395.63 | BJ5: 1259346 | BK5: 1594549.7 | BL5: 1918860.2 | BM5: 2273366.1 | BN5: 2613963.7 | BO5: 2958270.1 | BP5: 3291439.1 | BQ5: 3623793 | BR5: 3962796.8 | BS5: =3666592+408725 -> 4075317 | BT5: 345293 | BU5: 700748 | BV5: 1055101 | BW5: 1455961.4 | BX5: 1802684.2 | BY5: 2122977.2 | BZ5: 2693298 | CA5: 3112864 | CB5: 3173667.1
A6: Fees&Commision on Loan Portfolio | D6: 2522904 | E6: 2681042 | I6: 0 | J6: 0 | K6: 0 | L6: 0 | M6: 0 | N6: 0 | O6: 0 | P6: 0 | Q6: 0 | R6: 0 | S6: 0 | U6: 0 | V6: 0 | W6: 0 | X6: 0 | Y6: 0 | Z6: 0 | AA6: 0 | AB6: 0 | AC6: 0 | AD6: 0 | AE6: 0 | AF6: 0 | AH6: 0 | AI6: 0 | AJ6: 0 | AK6: 0 | AL6: 0 | AM6: 0 | AN6: 0 | AO6: 0 | AP6: 0 | AQ6: 0 | AR6: 0 | AS6: 0 | AT6: 0 | AU6: 0 | AV6: 0 | AW6: 0 | AX6: 0 | AY6: 0 | AZ6: 0 | BA6: 0 | BB6: 0 | BC6: 0 | BD6: 0 | BE6: 0 | BG6: 0 | BH6: 0 | BI6: 0 | BJ6: 0 | BK6: 0 | BL6: 0 | BM6: 0 | BN6: 0 | BO6: 0 | BP6: 0 | BQ6: 0 | BR6: 0 | BS6: =4004977 -> 4004977 | BT6: 0 | BU6: 0 | BV6: 0 | BW6: 0 | BX6: 0 | BY6: 0 | BZ6: 3189815 | CA6: 3527469 | CB6: 4033241
A7: Financial Income from Investments | B7: =SUM(B8:B11) -> 1323454 | C7: =SUM(C8:C11) -> 895333 | D7: =SUM(D8:D11) -> 1917222 | E7: =SUM(E8:E11) -> 1018034 | F7: =SUM(F8:F11) -> 3434232 | G7: =SUM(G8:G11) -> 5164279 | H7: =SUM(H8:H11) -> 4662478 | I7: =SUM(I8:I11) -> 221188 | ... CB7: =SUM(CB8:CB11) -> 959163.25
A8: Government Securities | I8: 0 | J8: 0 | K8: 0 | L8: 0 | M8: 0 | N8: 0 | O8: 0 | P8: 0 | Q8: 0 | R8: 0 | S8: 0 | U8: 0 | V8: 0 | W8: 0 | X8: 0 | Y8: 0 | Z8: 0 | AA8: 0 | AB8: 0 | AC8: 0 | AD8: 0 | AE8: 0 | AF8: 0 | AH8: 0 | AI8: 0 | AJ8: 0 | AK8: 0 | AL8: 0 | AM8: 0 | AN8: 0 | AO8: 0 | AP8: 0 | AQ8: 0 | AR8: 0 | AS8: 0 | AT8: 0 | AU8: 0 | AV8: 0 | AW8: 0 | AX8: 0 | AY8: 0 | AZ8: 0 | BA8: 0 | BB8: 0 | BC8: 0 | BD8: 0 | BE8: 0 | BG8: 0 | BH8: 0 | BI8: 0 | BJ8: 0 | BK8: 0 | BL8: 0 | BM8: 0 | BN8: 0 | BO8: 0 | BP8: 0 | BQ8: 0 | BR8: 0 | BT8: 0 | BU8: 0 | BV8: 0 | BW8: 0 | BX8: 0 | BY8: 0 | BZ8: 0 | CA8: 0 | CB8: 0
A9: Deposits with Banks & other Financial Institutions | H9: 282010 | I9: 36150 | J9: 81669 | K9: 127759 | L9: 181563.5 | M9: 233935 | N9: 279885 | O9: 377888 | P9: 480034 | Q9: 560013.5 | R9: 745427.5 | S9: 858937.5 | T9: 370004 | U9: 77890 | V9: 157282.5 | W9: 252618 | X9: 390914.25 | Y9: 487738.15 | Z9: 570827.65 | AA9: 662317.6 | AB9: 774057.6 | AC9: 859705.1 | AD9: 929055.1 | AE9: 1029089.6 | AF9: 1107864.6 | AG9: 293533 | AH9: 68700 | AI9: 143220 | AJ9: 249124 | AK9: 320091 | AL9: 386758.5 | AM9: 470638.4 | AN9: 619445.55 | AO9: 707428.55 | AP9: 794024.55 | AQ9: 850484.55 | AR9: 965764.55 | AS9: 62070 | AT9: 53160 | AU9: 135165 | AV9: 224910 | AW9: 319040.5 | AX9: 403499.2 | AY9: 499601.7 | AZ9: 603459.2 | BA9: 695526.7 | BB9: 777804.2 | BC9: 873282.5 | BD9: 939485 | BE9: 1030260 | BF9: =6283120-BF11 -> 2762988 | BG9: 64472.5 | BH9: 129107.5 | BI9: 217495 | BJ9: 327465 | BK9: 412556 | BL9: 483468 | BM9: 573743 | BN9: 646224 | BO9: 733738 | BP9: 792640 | BQ9: 870905 | BR9: 956635 | BS9: 287713 | BT9: 61302 | BU9: 120568 | BV9: 258831 | BW9: 367926 | BX9: 507961 | BY9: 608999 | BZ9: 0 | CA9: 0 | CB9: 0
A10: Other Investments | B10: 67805 | C10: 196592 | D10: 187787 | E10: 128575 | F10: 259249 | G10: 188122 | I10: 600 | J10: 12510 | K10: 23910 | L10: 34440 | M10: 45990 | N10: 57090 | O10: 79050 | P10: 90270 | Q10: 90870 | R10: 113250 | S10: 135330 | T10: 433128 | U10: 11160 | V10: 11550 | W10: 32550 | X10: 44104.07 | Y10: 53974.07 | Z10: 54394.07 | AA10: 74254.07 | AB10: 84754.07 | AC10: 94744.07 | AD10: 104254.07 | AE10: 113914.07 | AF10: 123064.07 | AH10: 9420 | AI10: 18750 | AJ10: 27600 | AK10: 37110 | AL10: 45720 | AM10: 54390 | AN10: 71040 | AO10: 78870 | AP10: 86670 | AQ10: 94140 | AR10: 102120 | AT10: 270 | AU10: 8250 | AV10: 23490 | AW10: 31200 | AX10: 39030 | AY10: 39560.32 | AZ10: 54200.32 | BA10: 61730.32 | BB10: 61970.32 | BC10: 76280.32 | BD10: 83540.32 | BE10: 90530.32 | BG10: 6840 | BH10: 13740 | BI10: 21360 | BJ10: 29310 | BK10: 37110 | BL10: 44880 | BM10: 52380 | BN10: 60480 | BO10: 68550 | BP10: 76380 | BQ10: 84840 | BR10: 92940 | BT10: 8640 | BU10: 17670 | BV10: 26310 | BW10: 34890 | BX10: 43620 | BY10: 51690 | BZ10: 673333.25 | CA10: 733273.25 | CB10: 778273.25
A11: Other Operating Income | B11: 1255649 | C11: =698741 -> 698741 | D11: 1729435 | E11: 889459 | F11: =3174983-F6 -> 3174983 | G11: 4976157 | H11: 4380468 | I11: 184438 | J11: 370159 | K11: 571354 | L11: 766958 | M11: 975012 | N11: 1193261 | O11: 1411815 | P11: 1660374.6 | Q11: 1881679.6 | R11: 2422437.6 | S11: 2659460.8 | T11: =5214289-433123 -> 4781166 | U11: 212633 | V11: 452982 | W11: 657761 | X11: 873148 | Y11: 1081540 | Z11: 1307047 | AA11: 1561150 | AB11: 1852080 | AC11: 2038071 | AD11: 2269137 | AE11: 2569224 | AF11: 2751429 | AG11: 5697204 | AH11: 226799 | AI11: 450979 | AJ11: 791196 | AK11: 867906 | AL11: 1097380 | AM11: 1322105 | AN11: 1835454 | AO11: 2113090 | AP11: 2392360 | AQ11: 2654450 | AR11: 3016123 | AS11: 5570903 | AT11: 145131 | AU11: 421096 | AV11: 671823 | AW11: 912785 | AX11: 1176275 | AY11: 1487045 | AZ11: 1826940 | BA11: 2099720 | BB11: 2409165 | BC11: 2723050 | BD11: 2975260 | BE11: 3222151 | BF11: 3520132 | BG11: 268760 | BH11: 534010 | BI11: 826766 | BJ11: 1155324 | BK11: 1422236 | BL11: 1711669 | BM11: 2011319 | BN11: 2302441 | BO11: 2686231 | BP11: 2871971 | BQ11: 3260876 | BR11: 3608331 | BS11: =1257889+592000+130400+120083 -> 2100372 | BT11: 294612 | BU11: 507131 | BV11: 937749 | BW11: 1060969 | BX11: 1449635 | BY11: 1676646 | BZ11: 158090 | CA11: 177840 | CB11: 180890
A12: Financial Expenses | B12: =SUM(B13:B18) -> 2292847 | C12: =SUM(C13:C18) -> 2761880 | D12: =SUM(D13:D18) -> 743203.78 | E12: =SUM(E13:E18) -> 2960790 | F12: =SUM(F13:F18) -> 2422107 | G12: =SUM(G13:G18) -> 2651211 | H12: =SUM(H13:H18) -> 2073568 | I12: =SUM(I13:I18) -> 4999.5 | ... CB12: =SUM(CB13:CB18) -> 58111
A13: Interest Expense on Deposits | B13: =1864544+184222 -> 2048766 | C13: =2220599+275212 -> 2495811 | D13: =191967 -> 191967 | E13: =2422463+75051 -> 2497514 | F13: =1717414+270545 -> 1987959 | G13: =321048+2167716 -> 2488764 | H13: =1503071+203637 -> 1706708 | I13: 4999.5 | J13: 12617 | K13: 13447.5 | L13: 27329.5 | M13: 37187.5 | N13: 47885 | O13: 61184 | P13: 72178.5 | Q13: 74034 | R13: 94756.5 | S13: 117900.5 | T13: =186488+1957092+233000+201684 -> 2578264 | U13: 15984 | V13: 19248 | W13: 23178 | X13: 43202 | Y13: 51132 | Z13: 71356 | AA13: 71456 | AB13: 83011 | AC13: 90167 | AD13: 96183 | AE13: 107927 | AF13: 115961 | AG13: =179592+2358986 -> 2538578 | AH13: 10728 | AI13: 19344 | AJ13: 30582 | AK13: 46108 | AL13: 49512 | AM13: 61687 | AN13: 74693.46 | AO13: 92137.42 | AP13: 102067.44 | AQ13: 106111.7 | AR13: 261531.35 | AS13: 2941600 | AT13: 12160 | AU13: 21874 | AV13: 37443.57 | AW13: 50199.4 | AX13: 51105.4 | AY13: 64807.42 | AZ13: 83150.42 | BA13: 91334.42 | BB13: 101801.1 | BC13: 115487.1 | BD13: 117629.1 | BE13: 143274.44 | BF13: 3154973 | BG13: 10104 | BH13: 12726 | BI13: 21672 | BJ13: 29976 | BK13: 45756 | BL13: 49566 | BM13: 64883 | BN13: 84315 | BO13: 97519 | BP13: 107089 | BQ13: 117307 | BR13: 135042.57 | BS13: 3021312 | BT13: 12550 | BU13: 22108 | BV13: 30403.92 | BW13: 38449.92 | BX13: 48007.92 | BY13: 55453.92 | BZ13: 0 | CA13: 0 | CB13: 0
A14: Cost of External Borrowings | B14: =178862+17556+47663 -> 244081 | C14: =50936+84651+130482 -> 266069 | D14: =35132+74114+3977+193986.78 -> 307209.78 | E14: 40009 | F14: 434148 | G14: 162447 | H14: 366860 | I14: 0 | J14: 39125.1 | K14: 71912.55 | L14: 71912.55 | M14: 134185.35 | N14: 134185.35 | O14: 190104.45 | P14: 190104.45 | Q14: 225684.5 | R14: 10957 | S14: 239693.6 | T14: 262484 | U14: 0 | V14: 0 | W14: 0 | X14: 0 | Y14: 0 | Z14: 0 | AA14: 0 | AB14: 44608 | AC14: 44608 | AD14: 44608 | AE14: 44608 | AF14: 44608 | AG14: 44608 | AH14: 0 | AI14: 0 | AJ14: 0 | AK14: 0 | AL14: 0 | AM14: 0 | AN14: 0 | AO14: 0 | AP14: 0 | AQ14: 0 | AR14: 0 | AS14: 0 | AT14: 0 | AU14: 0 | AV14: 0 | AW14: 0 | AX14: 0 | AY14: 0 | AZ14: 0 | BA14: 0 | BB14: 0 | BC14: 0 | BD14: 0 | BE14: 0 | BG14: 0 | BH14: 0 | BI14: 0 | BJ14: 0 | BK14: 0 | BL14: 0 | BM14: 0 | BN14: 0 | BO14: 0 | BP14: 0 | BQ14: 0 | BR14: 0 | BT14: 0 | BU14: 0 | BV14: 0 | BW14: 0 | BX14: 0 | BY14: 0 | BZ14: 0 | CA14: 0 | CB14: 0
A15: Dividend Expenses | I15: 0 | J15: 0 | K15: 0 | L15: 0 | M15: 0 | N15: 0 | O15: 0 | P15: 0 | Q15: 0 | R15: 0 | S15: 0 | U15: 0 | V15: 0 | W15: 0 | X15: 0 | Y15: 0 | Z15: 0 | AA15: 0 | AB15: 0 | AC15: 0 | AD15: 0 | AE15: 0 | AF15: 0 | AG15: =150000+133950+515545 -> 799495 | AH15: 0 | AI15: 0 | AJ15: 0 | AK15: 0 | AL15: 0 | AM15: 0 | AN15: 0 | AO15: 0 | AP15: 0 | AQ15: 0 | AR15: 0 | AS15: 0 | AT15: 0 | AU15: 0 | AV15: 0 | AW15: 0 | AX15: 0 | AY15: 0 | AZ15: 0 | BA15: 0 | BB15: 0 | BC15: 0 | BD15: 0 | BE15: 0 | BG15: 0 | BH15: 0 | BI15: 0 | BJ15: 0 | BK15: 0 | BL15: 0 | BM15: 0 | BN15: 0 | BO15: 0 | BP15: 0 | BQ15: 0 | BR15: 0 | BS15: 215684 | BT15: 0 | BU15: 0 | BV15: 0 | BW15: 0 | BX15: 0 | BY15: 0 | BZ15: 0 | CA15: 0 | CB15: 0
A16: Other Financial Expense | D16: =42757+149210 -> 191967 | I16: 0 | J16: 1146 | K16: 2065 | L16: 3101 | M16: 4205 | N16: 5332 | O16: 6359 | P16: 7442 | Q16: 8528 | R16: 239693.6 | S16: 198298.29 | U16: 0 | V16: 0 | W16: 0 | X16: 0 | Y16: 2517 | Z16: 2517 | AA16: 2517 | AB16: 0 | AC16: 0 | AD16: 0 | AE16: 0 | AF16: 0 | AH16: 0 | AI16: 0 | AJ16: 0 | AK16: 19122.81 | AL16: 19976.81 | AM16: 90795.03 | AN16: 94393.03 | AO16: 140042.03 | AP16: 140735.03 | AQ16: 141448.03 | AR16: 487889.43 | AS16: =150000+133950+521662 -> 805612 | AT16: 0 | AU16: 122573 | AV16: 123160 | AW16: 143160 | AX16: 144665 | AY16: 145688 | AZ16: 146422 | BA16: 146422 | BB16: 169319 | BC16: 190957 | BD16: 191826 | BE16: 396554.41 | BF16: 0 | BG16: 0 | BH16: 545 | BI16: 857 | BJ16: 20857 | BK16: 21827 | BL16: 21827 | BM16: 22265 | BN16: 22681 | BO16: 23281 | BP16: 296881 | BQ16: 297843 | BR16: 513527.18 | BS16: 0 | BT16: 0 | BU16: 649 | BV16: 649 | BW16: 649 | BX16: 2521 | BY16: 124321 | BZ16: 2521 | CA16: 2521 | CB16: 58111
A17: Fees & Commision Expense | I17: 0 | J17: 0 | K17: 0 | L17: 0 | M17: 0 | N17: 0 | O17: 0 | P17: 0 | Q17: 0 | R17: 0 | S17: 0 | U17: 0 | V17: 0 | W17: 0 | X17: 0 | Y17: 0 | Z17: 0 | AA17: 44608 | AB17: 68734.7 | AC17: 69403.7 | AD17: 69403.7 | AE17: 70832.7 | AF17: 372224.5 | AH17: 0 | AI17: 0 | AJ17: 0 | AK17: 0 | AL17: 0 | AM17: 0 | AN17: 0 | AO17: 0 | AP17: 0 | AQ17: 0 | AR17: 0 | AS17: 0 | AT17: 0 | AU17: 0 | AV17: 0 | AW17: 0 | AX17: 0 | AY17: 0 | AZ17: 0 | BA17: 0 | BB17: 0 | BC17: 0 | BD17: 0 | BE17: 0 | BG17: 0 | BH17: 0 | BI17: 0 | BJ17: 0 | BK17: 0 | BL17: 0 | BM17: 0 | BN17: 0 | BO17: 0 | BP17: 0 | BQ17: 0 | BR17: 0 | BT17: 0 | BU17: 0 | BV17: 0 | BW17: 0 | BX17: 0 | BY17: 0 | BZ17: 0 | CA17: 0 | CB17: 0
A18: Other Expenses | D18: 52060 | E18: =293758+129509 -> 423267 | I18: 0 | J18: 0 | K18: 0 | L18: 0 | M18: 0 | N18: 0 | O18: 0 | P18: 0 | Q18: 0 | R18: 0 | S18: 0 | U18: 0 | V18: 0 | W18: 0 | X18: 0 | Y18: 0 | Z18: 0 | AA18: 0 | AB18: 0 | AC18: 0 | AD18: 0 | AE18: 0 | AF18: 0 | AH18: 0 | AI18: 0 | AJ18: 0 | AK18: 0 | AL18: 0 | AM18: 0 | AN18: 0 | AO18: 0 | AP18: 0 | AQ18: 0 | AR18: 0 | AS18: 0 | AT18: 0 | AU18: 0 | AV18: 0 | AW18: 0 | AX18: 0 | AY18: 0 | AZ18: 0 | BA18: 0 | BB18: 0 | BC18: 0 | BD18: 0 | BE18: 0 | BG18: 0 | BH18: 0 | BI18: 0 | BJ18: 0 | BK18: 0 | BL18: 0 | BM18: 0 | BN18: 0 | BO18: 0 | BP18: 0 | BQ18: 0 | BR18: 0 | BT18: 0 | BU18: 0 | BV18: 0 | BW18: 0 | BX18: 0 | BY18: 0 | BZ18: 0 | CA18: 0 | CB18: 0
A19: Net Financial Income | B19: =B3-B12 -> 2325370 | C19: =C3-C12 -> 2422337 | D19: =D3-D12 -> 7209753.2 | E19: =E3-E12 -> 5581959 | F19: =F3-F12 -> 5998987 | G19: =G3-G12 -> 6256606 | H19: =H3-H12 -> 6156482 | I19: =I3-I12 -> 227839.85 | ... CB19: =CB3-CB12 -> 8107960.4
A20: Allowance for Loan Loss | B20: =B21-B22 -> 0 | C20: =C21-C22 -> 0 | D20: =D21-D22 -> 0 | E20: =E21-E22 -> 0 | F20: =F21-F22 -> 800000 | G20: =G21-G22 -> 550000 | H20: =H21-H22 -> 575767 | I20: =I21-I22 -> 0 | ... CB20: =CB21-CB22 -> 0
A21: Provision for Loan Losses | F21: 800000 | G21: 550000 | H21: 575767 | I21: 0 | J21: 0 | K21: 0 | L21: 0 | M21: 0 | N21: 0 | O21: 0 | P21: 0 | Q21: 0 | R21: 0 | S21: 0 | T21: 1034684 | U21: 0 | V21: 0 | W21: 0 | X21: 0 | Y21: 0 | Z21: 0 | AA21: 0 | AB21: 0 | AC21: 0 | AD21: 0 | AE21: 0 | AF21: 0 | AG21: 600000 | AH21: 0 | AI21: 0 | AJ21: 0 | AK21: 0 | AL21: 0 | AM21: 0 | AN21: 0 | AO21: 0 | AP21: 0 | AQ21: 0 | AR21: 0 | AS21: 582100 | AT21: 0 | AU21: 0 | AV21: 0 | AW21: 0 | AX21: 0 | AY21: 0 | AZ21: 0 | BA21: 0 | BB21: 0 | BF21: 96529 | BG21: 0 | BH21: 0 | BI21: 0 | BJ21: 0 | BK21: 0 | BL21: 0 | BM21: 0 | BN21: 0 | BO21: 0 | BP21: 0 | BQ21: 0 | BR21: 0 | BS21: 0 | BT21: 0 | BU21: 0 | BV21: 0 | BW21: 0 | BX21: 0 | BY21: 0 | BZ21: 0 | CA21: 0 | CB21: 0
A22: Value of Loans Recovered | I22: 0 | J22: 0 | K22: 0 | L22: 0 | M22: 0 | N22: 0 | O22: 0 | P22: 0 | Q22: 0 | R22: 0 | S22: 0 | U22: 0 | V22: 0 | W22: 0 | X22: 0 | Y22: 0 | Z22: 0 | AA22: 0 | AB22: 0 | AC22: 0 | AD22: 0 | AE22: 0 | AF22: 0 | AH22: 0 | AI22: 0 | AJ22: 0 | AK22: 0 | AL22: 0 | AM22: 0 | AN22: 0 | AO22: 0 | AP22: 0 | AQ22: 0 | AR22: 0 | AS22: 0 | AT22: 0 | AU22: 0 | AV22: 0 | AW22: 0 | AX22: 0 | AY22: 0 | AZ22: 0 | BA22: 0 | BB22: 0 | BG22: 0 | BH22: 0 | BI22: 0 | BJ22: 0 | BK22: 0 | BL22: 0 | BM22: 0 | BN22: 0 | BO22: 0 | BP22: 0 | BQ22: 0 | BR22: 0 | BT22: 0 | BU22: 0 | BV22: 0 | BW22: 0 | BX22: 0 | BY22: 0 | BZ22: 0 | CA22: 0 | CB22: 0
A23: Operating Expeses | B23: =SUM(B24:B28) -> 2188331 | C23: =SUM(C24:C28) -> 2142423 | D23: =SUM(D24:D28) -> 3280896 | E23: =SUM(E24:E28) -> 3663861 | F23: =SUM(F24:F28) -> 4191173 | G23: =SUM(G24:G28) -> 4447942 | H23: =SUM(H24:H28) -> 5369973 | I23: =SUM(I24:I28) -> 193026.22 | ... CB23: =SUM(CB24:CB28) -> 4008208.4
A24: Personel Expenses | B24: 191449 | C24: =1223055 -> 1223055 | D24: 1344891 | E24: 1357118 | F24: 1588884 | G24: 1675820 | H24: 1803481 | I24: 127475 | J24: 257903 | K24: 387932 | L24: 609382 | M24: 737262 | N24: 862873 | O24: 988307 | P24: 1123380 | Q24: 1267192 | R24: 1537503 | S24: 1703992 | T24: 1839286 | U24: 147224 | V24: 324430 | W24: 500926 | X24: 731175 | Y24: 887063 | Z24: 1032215 | AA24: 1139164 | AB24: 1281120 | AC24: 1408250 | AD24: 1416600 | AE24: 1794528.6 | AF24: 1966473.6 | AG24: 2137339 | AH24: 115904 | AI24: 206892 | AJ24: 315730 | AK24: 470266 | AL24: 588743 | AM24: 690251 | AN24: 895445 | AO24: 996940 | AP24: 1109467 | AQ24: 1221132 | AR24: 1338669 | AS24: 1588761 | AT24: 10272 | AU24: 124370 | AV24: 415912 | AW24: 588180 | AX24: 832337 | AY24: 837844 | AZ24: 1183667 | BA24: 1375140 | BB24: 1382736 | BC24: 1751440 | BD24: 1937943 | BE24: 2130920 | BF24: 2130920 | BG24: 178359 | BH24: 356267 | BI24: 540240 | BJ24: 717827 | BK24: 896702 | BL24: 1228531 | BM24: 1405884 | BN24: 1580555 | BO24: 1889750 | BP24: 2088932 | BQ24: 2288915 | BR24: 2501397 | BS24: =28246+138354+51429+82330+2201038 -> 2501397 | BT24: 201281 | BU24: 401355 | BV24: 612245 | BW24: 821390 | BX24: 1165258 | BY24: 1192178 | BZ24: 1588639 | CA24: 1797291 | CB24: 2007211
A25: Governance Expenses | B25: 508737 | C25: =265661 -> 265661 | D25: =516344+305261 -> 821605 | E25: =416562+416562 -> 833124 | F25: 870700 | G25: 1068794 | H25: 827193 | I25: 33891.22 | J25: 138714.26 | K25: 185135.58 | L25: 220795.58 | M25: 270568.82 | N25: 298168.82 | O25: 382937.42 | P25: 470457.62 | Q25: 525367.62 | R25: 952001.9 | S25: 981719.9 | T25: 796588 | U25: 31580 | V25: 78601.92 | W25: 227074.48 | X25: 269288.8 | Y25: 306501.84 | Z25: 335768.24 | AA25: 370518.24 | AB25: 426286.3 | AC25: 470408.96 | AD25: 488422.64 | AE25: 828644.82 | AF25: 864717.17 | AG25: 842346 | AH25: 35057 | AI25: 76982 | AJ25: 213555.49 | AK25: 261911.88 | AL25: 304029.44 | AM25: 358671.98 | AN25: 447826.76 | AO25: 495938.54 | AP25: 524022.54 | AQ25: 852579.32 | AR25: 894744.32 | AS25: 592227 | AT25: 70838 | AU25: 186952 | AV25: 250101 | AW25: 306117 | AX25: 345722 | AY25: 387223 | AZ25: 410425 | BA25: 506578 | BB25: 534018 | BC25: 581270 | BD25: 897492 | BE25: 960165 | BF25: 734300 | BG25: 112879 | BH25: 160431 | BI25: 195129 | BJ25: 309727 | BK25: 355225 | BL25: 385553 | BM25: 421039 | BN25: 436056 | BO25: 455578 | BP25: 476742 | BQ25: 518682 | BR25: 843489.8 | BS25: =74730+309390+215524+363700+184256 -> 1147600 | BT25: 20912 | BU25: 136427 | BV25: 167912 | BW25: 198642 | BX25: 222582 | BY25: 274598 | BZ25: 734532 | CA25: 854141 | CB25: 954804
A26: Marketing Expenses | C26: =15391 -> 15391 | F26: 66795 | G26: 50845 | H26: 88581 | I26: 31660 | J26: 63820 | K26: 97580 | L26: 153254 | M26: 208614 | N26: 239774 | O26: 323239 | P26: 392399 | Q26: 431299 | R26: 492713 | S26: 527373 | T26: 26107 | U26: 28840 | V26: 164880 | W26: 187160 | X26: 230654 | Y26: 285294 | Z26: 322534 | AA26: 400488 | AB26: 423728 | AC26: 466768 | AD26: 508808 | AE26: 544448 | AF26: 611288 | AG26: 73120 | AH26: 40240 | AI26: 197880 | AJ26: 220280 | AK26: 245392 | AL26: 271432 | AM26: 298537 | AN26: 391617 | AO26: 441943 | AP26: 498643 | AQ26: 532571 | AR26: 592227 | AS26: 30792 | AT26: 79312 | AU26: 183024 | AV26: 262150 | AW26: 309548 | AX26: 371760 | AY26: 411786 | AZ26: 454098 | BA26: 523810 | BB26: 555022 | BC26: 584834 | BD26: 625702 | BE26: 658228 | BF26: 23744 | BG26: 23240 | BH26: 417324 | BI26: 446780 | BJ26: 497050 | BK26: 599094 | BL26: 633178 | BM26: 669076 | BN26: 702488 | BO26: 730400 | BP26: 753640 | BQ26: 824411 | BR26: 857346 | BS26: 34594 | BT26: 40963 | BU26: 180326 | BV26: 210309 | BW26: 271108 | BX26: 359091 | BY26: 414554 | BZ26: 15956 | CA26: 15956 | CB26: 29656
