Workbook
Name BALANCE1_LDA01: '[1]Financial Statements'!$E$112
Name BALANCE1_LDA12: '[1]Financial Statements'!$E$123
Name BALANCE2_LDA01: '[1]Financial Statements'!$F$112
Name BALANCE2_LDA12: '[1]Financial Statements'!$F$123
Name BALANCE3_LDA01: '[1]Financial Statements'!$G$112
Name BALANCE3_LDA12: '[1]Financial Statements'!$G$123
Name BALANCE4_LDA01: '[1]Financial Statements'!$H$112
Name BALANCE4_LDA12: '[1]Financial Statements'!$H$123
Name BALANCE5_LDA01: '[1]Financial Statements'!$I$112
Name BALANCE5_LDA12: '[1]Financial Statements'!$I$123
Name BALANCE6_LDA01: '[1]Financial Statements'!$J$112
Name BALANCE6_LDA12: '[1]Financial Statements'!$J$123
Name NotApplicable: 'Prudential Ratios'!$B$76
Name PEARLS1_LA002: '[1]Financial Statements'!$E$280
Name PEARLS1_LE008: '[1]Financial Statements'!$E$275
Name PEARLS1_LE009: '[1]Financial Statements'!$E$276
Name PEARLS1_LR001: '[1]Financial Statements'!$E$282
Name PEARLS1_LR005: '[1]Financial Statements'!$E$286
Name PEARLS1_LR006: '[1]Financial Statements'!$E$287
Name PEARLS1_LR007: '[1]Financial Statements'!$E$288
Name PEARLS1_LR009: '[1]Financial Statements'!$E$290
Name PEARLS1_LS001: '[1]Financial Statements'!$E$298
Name PEARLS1_LS005: '[1]Financial Statements'!$E$302
Name PEARLS1_LS011: '[1]Financial Statements'!$E$308
Name PEARLS2_LA002: '[1]Financial Statements'!$F$280
Name PEARLS2_LE008: '[1]Financial Statements'!$F$275
Name PEARLS2_LE009: '[1]Financial Statements'!$F$276
Name PEARLS2_LR001: '[1]Financial Statements'!$F$282
Name PEARLS2_LR005: '[1]Financial Statements'!$F$286
Name PEARLS2_LR006: '[1]Financial Statements'!$F$287
Name PEARLS2_LR007: '[1]Financial Statements'!$F$288
Name PEARLS2_LR009: '[1]Financial Statements'!$F$290
Name PEARLS2_LS001: '[1]Financial Statements'!$F$298
Name PEARLS2_LS005: '[1]Financial Statements'!$F$302
Name PEARLS2_LS010: '[1]Financial Statements'!$F$307
Name PEARLS2_LS011: '[1]Financial Statements'!$F$308
Name PEARLS3_LA002: '[1]Financial Statements'!$G$280
Name PEARLS3_LE008: '[1]Financial Statements'!$G$275
Name PEARLS3_LE009: '[1]Financial Statements'!$G$276
Name PEARLS3_LR001: '[1]Financial Statements'!$G$282
Name PEARLS3_LR005: '[1]Financial Statements'!$G$286
Name PEARLS3_LR006: '[1]Financial Statements'!$G$287
Name PEARLS3_LR007: '[1]Financial Statements'!$G$288
Name PEARLS3_LR009: '[1]Financial Statements'!$G$290
Name PEARLS3_LS001: '[1]Financial Statements'!$G$298
Name PEARLS3_LS005: '[1]Financial Statements'!$G$302
Name PEARLS3_LS010: '[1]Financial Statements'!$G$307
Name PEARLS3_LS011: '[1]Financial Statements'!$G$308
Name PEARLS4_LA002: '[1]Financial Statements'!$H$280
Name PEARLS4_LE008: '[1]Financial Statements'!$H$275
Name PEARLS4_LE009: '[1]Financial Statements'!$H$276
Name PEARLS4_LR001: '[1]Financial Statements'!$H$282
Name PEARLS4_LR005: '[1]Financial Statements'!$H$286
Name PEARLS4_LR006: '[1]Financial Statements'!$H$287
Name PEARLS4_LR007: '[1]Financial Statements'!$H$288
Name PEARLS4_LR009: '[1]Financial Statements'!$H$290
Name PEARLS4_LS001: '[1]Financial Statements'!$H$298
Name PEARLS4_LS005: '[1]Financial Statements'!$H$302
Name PEARLS4_LS010: '[1]Financial Statements'!$H$307
Name PEARLS4_LS011: '[1]Financial Statements'!$H$308

Sheet compliance status
B2: audited2017 | C2: 43101 | D2: 43133 | E2: 43165 | F2: 43197 | G2: 43229 | H2: 43261 | I2: 43293 | J2: 43325 | K2: 43357 | L2: 43389 | M2: 43421 | N2: 43453
A3: CORE CAPITAL | B3: =IF('Prudential Ratios'!#REF!>10,"compliant","not compliant") -> #REF! | C3: =IF('Prudential Ratios'!#REF!>10,"compliant","not compliant") -> #REF! | D3: =IF('Prudential Ratios'!#REF!>10,"compliant","not compliant") -> #REF! | E3: =IF('Prudential Ratios'!#REF!>10,"compliant","not compliant") -> #REF! | F3: =IF('Prudential Ratios'!#REF!>10,"compliant","not compliant") -> #REF! | G3: =IF('Prudential Ratios'!#REF!>10,"compliant","not compliant") -> #REF! | H3: =IF('Prudential Ratios'!#REF!>10,"compliant","not compliant") -> #REF! | I3: =IF('Prudential Ratios'!#REF!>10,"compliant","not compliant") -> #REF! | ... N3: =IF('Prudential Ratios'!#REF!>10,"compliant","not compliant") -> #REF!
A4: CCA (Min 10%) | B4: =IF('Prudential Ratios'!#REF!>10%,"compliant","not compliant") -> #REF! | C4: =IF('Prudential Ratios'!#REF!>10%,"compliant","not compliant") -> #REF! | D4: =IF('Prudential Ratios'!#REF!>10%,"compliant","not compliant") -> #REF! | E4: =IF('Prudential Ratios'!#REF!>10%,"compliant","not compliant") -> #REF! | F4: =IF('Prudential Ratios'!#REF!>10%,"compliant","not compliant") -> #REF! | G4: =IF('Prudential Ratios'!#REF!>10%,"compliant","not compliant") -> #REF! | H4: =IF('Prudential Ratios'!#REF!>10%,"compliant","not compliant") -> #REF! | I4: =IF('Prudential Ratios'!#REF!>10%,"compliant","not compliant") -> #REF! | ... N4: =IF('Prudential Ratios'!#REF!>10%,"compliant","not compliant") -> #REF!
A5: ICA (Min 8%) | B5: =IF('Prudential Ratios'!#REF!>8%,"compliant","not compliant") -> #REF! | C5: =IF('Prudential Ratios'!#REF!>8%,"compliant","not compliant") -> #REF! | D5: =IF('Prudential Ratios'!#REF!>8%,"compliant","not compliant") -> #REF! | E5: =IF('Prudential Ratios'!#REF!>8%,"compliant","not compliant") -> #REF! | F5: =IF('Prudential Ratios'!#REF!>8%,"compliant","not compliant") -> #REF! | G5: =IF('Prudential Ratios'!#REF!>8%,"compliant","not compliant") -> #REF! | H5: =IF('Prudential Ratios'!#REF!>8%,"compliant","not compliant") -> #REF! | I5: =IF('Prudential Ratios'!#REF!>8%,"compliant","not compliant") -> #REF! | ... N5: =IF('Prudential Ratios'!#REF!>8%,"compliant","not compliant") -> #REF!
A6: CCD (Min 8%) | B6: =IF('Prudential Ratios'!#REF!>8%,"compliant","not compliant") -> #REF! | C6: =IF('Prudential Ratios'!#REF!>8%,"compliant","not compliant") -> #REF! | D6: =IF('Prudential Ratios'!#REF!>8%,"compliant","not compliant") -> #REF! | E6: =IF('Prudential Ratios'!#REF!>8%,"compliant","not compliant") -> #REF! | F6: =IF('Prudential Ratios'!#REF!>8%,"compliant","not compliant") -> #REF! | G6: =IF('Prudential Ratios'!#REF!>8%,"compliant","not compliant") -> #REF! | H6: =IF('Prudential Ratios'!#REF!>8%,"compliant","not compliant") -> #REF! | I6: =IF('Prudential Ratios'!#REF!>8%,"compliant","not compliant") -> #REF! | ... N6: =IF('Prudential Ratios'!#REF!>8%,"compliant","not compliant") -> #REF!
A7: NPL(5%)
A8: Liquidity(15%) | B8: =IF('Prudential Ratios'!#REF!>15%,"compliant","not compliant") -> #REF! | C8: =IF('Prudential Ratios'!#REF!>15%,"compliant","not compliant") -> #REF! | D8: =IF('Prudential Ratios'!#REF!>15%,"compliant","not compliant") -> #REF! | E8: =IF('Prudential Ratios'!#REF!>15%,"compliant","not compliant") -> #REF! | F8: =IF('Prudential Ratios'!#REF!>15%,"compliant","not compliant") -> #REF! | G8: =IF('Prudential Ratios'!#REF!>15%,"compliant","not compliant") -> #REF! | H8: =IF('Prudential Ratios'!#REF!>15%,"compliant","not compliant") -> #REF! | I8: =IF('Prudential Ratios'!#REF!>15%,"compliant","not compliant") -> #REF! | ... N8: =IF('Prudential Ratios'!#REF!>15%,"compliant","not compliant") -> #REF!
A9: NEA (Max 10%) | B9: =IF('Prudential Ratios'!#REF!<10%,"compliant","not compliant") -> #REF! | C9: =IF('Prudential Ratios'!#REF!<10%,"compliant","not compliant") -> #REF! | D9: =IF('Prudential Ratios'!#REF!<10%,"compliant","not compliant") -> #REF! | E9: =IF('Prudential Ratios'!#REF!<10%,"compliant","not compliant") -> #REF! | F9: =IF('Prudential Ratios'!#REF!<10%,"compliant","not compliant") -> #REF! | G9: =IF('Prudential Ratios'!#REF!<10%,"compliant","not compliant") -> #REF! | H9: =IF('Prudential Ratios'!#REF!<10%,"compliant","not compliant") -> #REF! | I9: =IF('Prudential Ratios'!#REF!<10%,"compliant","not compliant") -> #REF! | ... N9: =IF('Prudential Ratios'!#REF!<10%,"compliant","not compliant") -> #REF!
A10: LB ratio (Max 5%) | B10: =IF('Prudential Ratios'!#REF!<5%,"compliant","not compliant") -> #REF! | C10: =IF('Prudential Ratios'!#REF!<5%,"compliant","not compliant") -> #REF! | D10: =IF('Prudential Ratios'!#REF!<5%,"compliant","not compliant") -> #REF! | E10: =IF('Prudential Ratios'!#REF!<5%,"compliant","not compliant") -> #REF! | F10: =IF('Prudential Ratios'!#REF!<5%,"compliant","not compliant") -> #REF! | G10: =IF('Prudential Ratios'!#REF!<5%,"compliant","not compliant") -> #REF! | H10: =IF('Prudential Ratios'!#REF!<5%,"compliant","not compliant") -> #REF! | I10: =IF('Prudential Ratios'!#REF!<5%,"compliant","not compliant") -> #REF! | ... N10: =IF('Prudential Ratios'!#REF!<5%,"compliant","not compliant") -> #REF!
A11: FITD (Max 5%) | B11: =IF('Prudential Ratios'!#REF!<5%,"compliant","not compliant") -> #REF! | C11: =IF('Prudential Ratios'!#REF!<5%,"compliant","not compliant") -> #REF! | D11: =IF('Prudential Ratios'!#REF!<5%,"compliant","not compliant") -> #REF! | E11: =IF('Prudential Ratios'!#REF!<5%,"compliant","not compliant") -> #REF! | F11: =IF('Prudential Ratios'!#REF!<5%,"compliant","not compliant") -> #REF! | G11: =IF('Prudential Ratios'!#REF!<5%,"compliant","not compliant") -> #REF! | H11: =IF('Prudential Ratios'!#REF!<5%,"compliant","not compliant") -> #REF! | I11: =IF('Prudential Ratios'!#REF!<5%,"compliant","not compliant") -> #REF! | ... N11: =IF('Prudential Ratios'!#REF!<5%,"compliant","not compliant") -> #REF!
A12: FICC (Max 40%) | B12: =IF('Prudential Ratios'!#REF!<40%,"compliant","not compliant") -> #REF! | C12: =IF('Prudential Ratios'!#REF!<40%,"compliant","not compliant") -> #REF! | D12: =IF('Prudential Ratios'!#REF!<40%,"compliant","not compliant") -> #REF! | E12: =IF('Prudential Ratios'!#REF!<40%,"compliant","not compliant") -> #REF! | F12: =IF('Prudential Ratios'!#REF!<40%,"compliant","not compliant") -> #REF! | G12: =IF('Prudential Ratios'!#REF!<40%,"compliant","not compliant") -> #REF! | H12: =IF('Prudential Ratios'!#REF!<40%,"compliant","not compliant") -> #REF! | I12: =IF('Prudential Ratios'!#REF!<40%,"compliant","not compliant") -> #REF! | ... N12: =IF('Prudential Ratios'!#REF!<40%,"compliant","not compliant") -> #REF!
A13: EB ratio | B13: =IF('Prudential Ratios'!#REF!<25%,"compliant","not compliant") -> #REF! | C13: =IF('Prudential Ratios'!#REF!<25%,"compliant","not compliant") -> #REF! | D13: =IF('Prudential Ratios'!#REF!<25%,"compliant","not compliant") -> #REF! | E13: =IF('Prudential Ratios'!#REF!<25%,"compliant","not compliant") -> #REF! | F13: =IF('Prudential Ratios'!#REF!<25%,"compliant","not compliant") -> #REF! | G13: =IF('Prudential Ratios'!#REF!<25%,"compliant","not compliant") -> #REF! | H13: =IF('Prudential Ratios'!#REF!<25%,"compliant","not compliant") -> #REF! | I13: =IF('Prudential Ratios'!#REF!<25%,"compliant","not compliant") -> #REF! | ... N13: =IF('Prudential Ratios'!#REF!<25%,"compliant","not compliant") -> #REF!
A14: A=S+L | B14: =IF('SFP-2022'!#REF!='SFP-2022'!#REF!,"balancing","notbalancing") -> #REF! | C14: =IF('SFP-2022'!#REF!='SFP-2022'!#REF!,"balancing","notbalancing") -> #REF! | D14: =IF('SFP-2022'!#REF!='SFP-2022'!#REF!,"balancing","notbalancing") -> #REF! | E14: =IF('SFP-2022'!#REF!='SFP-2022'!#REF!,"balancing","notbalancing") -> #REF! | F14: =IF('SFP-2022'!#REF!='SFP-2022'!#REF!,"balancing","notbalancing") -> #REF! | G14: =IF('SFP-2022'!#REF!='SFP-2022'!#REF!,"balancing","notbalancing") -> #REF! | H14: =IF('SFP-2022'!#REF!='SFP-2022'!#REF!,"balancing","notbalancing") -> #REF! | I14: =IF('SFP-2022'!#REF!='SFP-2022'!#REF!,"balancing","notbalancing") -> #REF! | ... N14: =IF('SFP-2022'!#REF!='SFP-2022'!#REF!,"balancing","notbalancing") -> #REF!

Sheet Prudential Ratios
C1: KWETU SACCO SOCIETY LTD
C2: Sacco Financial Performance
C4: FINANCIAL SOUNDNESS INDICATORS | D4: Prude. Std | E4: Audited 2020 | F4: 44197 | G4: 44228 | H4: 44256 | I4: 44287 | J4: 44317 | K4: 44348 | L4: 44378 | M4: 44409 | N4: 44440 | O4: 44470 | P4: 44501 | Q4: 44531 | R4: Audited 2021 | S4: 44562 | T4: 44593 | U4: 44621 | V4: 44652 | W4: 44682 | X4: 44713 | Y4: 44743 | Z4: 44774 | AA4: 44805 | AB4: 44835 | AC4: 44866 | AD4: 44896 | AE4: Audited-2022 | AF4: 44949 | AG4: 44980 | AH4: 45008 | AI4: 45039 | AJ4: 45069 | AK4: 45100
B5: 1 | C5: CAPITAL ADEQUACY REQUIREMENTS
B6: 1.1 | C6: Core capital | D6: ≥ Ksh.10M | E6: =Financials!C14/1000000 -> 629.59023 | F6: =Financials!D14/1000000 -> 637.74636 | G6: =Financials!E14/1000000 -> 670.01584 | H6: =Financials!F14/1000000 -> 689.21991 | I6: =Financials!G14/1000000 -> 727.8007 | J6: =Financials!H14/1000000 -> 707.23569 | K6: =Financials!I14/1000000 -> 716.34862 | L6: =Financials!J14/1000000 -> 724.18982 | ... AK6: =Financials!AI14/1000000 -> 1198.318
B7: 1.2 | C7: Core capital /Total Assets | D7: ≥ 10% | E7: =Financials!C14/Financials!C5 -> 0.14376602 | F7: =Financials!D14/Financials!D5 -> 0.14528077 | G7: =Financials!E14/Financials!E5 -> 0.15149908 | H7: =Financials!F14/Financials!F5 -> 0.15561639 | I7: =Financials!G14/Financials!G5 -> 0.16282358 | J7: =Financials!H14/Financials!H5 -> 0.15929066 | K7: =Financials!I14/Financials!I5 -> 0.16085586 | L7: =Financials!J14/Financials!J5 -> 0.1580466 | ... AK7: =Financials!AI14/Financials!AI5 -> 0.2328877
B8: 1.3 | C8: Core capital /Total Deposits | D8: ≥ 8% | E8: =Financials!C14/Financials!C6 -> 0.26221751 | F8: =Financials!D14/Financials!D6 -> 0.26444542 | G8: =Financials!E14/Financials!E6 -> 0.27423695 | H8: =Financials!F14/Financials!F6 -> 0.28252581 | I8: =Financials!G14/Financials!G6 -> 0.29340121 | J8: =Financials!H14/Financials!H6 -> 0.28654143 | K8: =Financials!I14/Financials!I6 -> 0.28894288 | L8: =Financials!J14/Financials!J6 -> 0.27781485 | ... AK8: =Financials!AI14/Financials!AI6 -> 0.44084484
B9: 1.4 | C9: Share Capital/Total Assets | D9: ≤2% | E9: =Financials!C18/Financials!C5 -> 0.06447744 | F9: =Financials!D18/Financials!D5 -> 0.064535888 | G9: =Financials!E18/Financials!E5 -> 0.064304703 | H9: =Financials!F18/Financials!F5 -> 0.064477695 | I9: =Financials!G18/Financials!G5 -> 0.064149519 | J9: =Financials!H18/Financials!H5 -> 0.064808329 | K9: =Financials!I18/Financials!I5 -> 0.064940823 | L9: =Financials!J18/Financials!J5 -> 0.063402115 | ... AK9: =Financials!AI18/Financials!AI5 -> 0.079479255
B10: 1.5 | C10: Institutional Capital/Total Assets | D10: ≥ 8% | E10: =Financials!C15/Financials!C5 -> 0.079288584 | F10: =Financials!D15/Financials!D5 -> 0.080744884 | G10: =Financials!E15/Financials!E5 -> 0.087194377 | H10: =Financials!F15/Financials!F5 -> 0.09113869 | I10: =Financials!G15/Financials!G5 -> 0.098674062 | J10: =Financials!H15/Financials!H5 -> 0.094482328 | K10: =Financials!I15/Financials!I5 -> 0.095915038 | L10: =Financials!J15/Financials!J5 -> 0.094644481 | ... AK10: =Financials!AI15/Financials!AI5 -> 0.15340844
B12: 2 | C12: ASSET MIX AND QUALITY
B13: 2.1 | C13: Non Earning Assets
B14: 2.1.1 | C14: Non earning Assets/Total assets | D14: ≤ 10% | E14: =Financials!C38/Financials!C5 -> 0.27231684 | F14: =Financials!D38/Financials!D5 -> 0.27381193 | G14: =Financials!E38/Financials!E5 -> 0.27168583 | H14: =Financials!F38/Financials!F5 -> 0.27195813 | I14: =Financials!G38/Financials!G5 -> 0.26486552 | J14: =Financials!H38/Financials!H5 -> 0.27000834 | K14: =Financials!I38/Financials!I5 -> 0.26543324 | L14: =Financials!J38/Financials!J5 -> 0.25780748 | ... AK14: =Financials!AI38/Financials!AI5 -> 0.22392615
B15: 2.1.2 | C15: Property and Equipment/Total Assets | D15: ≤ 5% | E15: =Financials!C39/Financials!C5 -> 0.031560111 | F15: =Financials!D39/Financials!D5 -> 0.03132349 | G15: =Financials!E39/Financials!E5 -> 0.031069599 | H15: =Financials!F39/Financials!F5 -> 0.030932915 | I15: =Financials!G39/Financials!G5 -> 0.031384934 | J15: =Financials!H39/Financials!H5 -> 0.031646156 | K15: =Financials!I39/Financials!I5 -> 0.03159001 | L15: =Financials!J39/Financials!J5 -> 0.03072233 | ... AK15: =Financials!AI39/Financials!AI5 -> 0.031187136
B16: 2.1.3 | C16: Non Performing loans/Gross Loans | D16: ≤ 6%
B18: 2.2 | C18: Earning Assets
B19: 2.2.1 | C19: Equities & Investments/Deposits | D19: ≤ 5% | E19: =Financials!C26/Financials!C6 -> 0.35331811 | F19: =Financials!D26/Financials!D6 -> 0.34926009 | G19: =Financials!E26/Financials!E6 -> 0.3448504 | H19: =Financials!F26/Financials!F6 -> 0.34543073 | I19: =Financials!G26/Financials!G6 -> 0.33976311 | J19: =Financials!H26/Financials!H6 -> 0.34148828 | K19: =Financials!I26/Financials!I6 -> 0.34002568 | L19: =Financials!J26/Financials!J6 -> 0.32339045 | ... AK19: =Financials!AI26/Financials!AI6 -> 0.28311329
B20: 2.2.2 | C20: Equities & Investments/Core Capital | D20: ≤ 40% | E20: =Financials!C26/Financials!C14 -> 1.3474238 | F20: =Financials!D26/Financials!D14 -> 1.3207265 | G20: =Financials!E26/Financials!E14 -> 1.2574906 | H20: =Financials!F26/Financials!F14 -> 1.2226519 | I20: =Financials!G26/Financials!G14 -> 1.1580154 | J20: =Financials!H26/Financials!H14 -> 1.1917588 | K20: =Financials!I26/Financials!I14 -> 1.176792 | L20: =Financials!J26/Financials!J14 -> 1.1640503 | ... AK20: =Financials!AI26/Financials!AI14 -> 0.64220619
B21: 2.2.3 | C21: Net Loans & advances /Total assets | D21: NPR | E21: =Financials!C31/Financials!C5 -> 0.47658656 | F21: =Financials!D31/Financials!D5 -> 0.47787352 | G21: =Financials!E31/Financials!E5 -> 0.47921217 | H21: =Financials!F31/Financials!F5 -> 0.48191869 | I21: =Financials!G31/Financials!G5 -> 0.47989055 | J21: =Financials!H31/Financials!H5 -> 0.48221068 | K21: =Financials!I31/Financials!I5 -> 0.48725956 | L21: =Financials!J31/Financials!J5 -> 0.48320864 | ... AK21: =Financials!AI31/Financials!AI5 -> 0.55616217
B23: 3 | C23: FUNDING MIX
B24: 3.1 | C24: Total Deposits/Total Assets | D24: NPR | E24: =Financials!C6/Financials!C5 -> 0.54827012 | F24: =Financials!D6/Financials!D5 -> 0.54937903 | G24: =Financials!E6/Financials!E5 -> 0.55243861 | H24: =Financials!F6/Financials!F5 -> 0.55080414 | I24: =Financials!G6/Financials!G5 -> 0.55495198 | J24: =Financials!H6/Financials!H5 -> 0.55590795 | K24: =Financials!I6/Financials!I5 -> 0.55670471 | L24: =Financials!J6/Financials!J5 -> 0.56889183 | ... AK24: =Financials!AI6/Financials!AI5 -> 0.52827588
B25: 3.1.1 | C25: BOSA Deposits/Total Assets | D25: NPR | E25: =Financials!C7/Financials!C5 -> 0.54827012 | F25: =Financials!D7/Financials!D5 -> 0.54937903 | G25: =Financials!E7/Financials!E5 -> 0.55243861 | H25: =Financials!F7/Financials!F5 -> 0.55080414 | I25: =Financials!G7/Financials!G5 -> 0.55495198 | J25: =Financials!H7/Financials!H5 -> 0.55590795 | K25: =Financials!I7/Financials!I5 -> 0.55670471 | L25: =Financials!J7/Financials!J5 -> 0.56889183 | ... AK25: =Financials!AI7/Financials!AI5 -> 0.52827588
B26: 3.1.2 | C26: FOSA Deposits/Total Assets | D26: NPR | E26: =Financials!C8/Financials!C5 -> 0.12563503 | F26: =Financials!D8/Financials!D5 -> 0.074312766 | G26: =Financials!E8/Financials!E5 -> 0.077185346 | H26: =Financials!F8/Financials!F5 -> 0.073284241 | I26: =Financials!G8/Financials!G5 -> 0.080028241 | J26: =Financials!H8/Financials!H5 -> 0.074455919 | K26: =Financials!I8/Financials!I5 -> 0.07191886 | L26: =Financials!J8/Financials!J5 -> 0.091701426 | ... AK26: =Financials!AI8/Financials!AI5 -> 0.073962086
B27: 3.2 | C27: External Borrowing/Total assets | D27: ≤ 25% | E27: =Financials!C9/Financials!C5 -> 0.10637237 | F27: =Financials!D9/Financials!D5 -> 0.10365053 | G27: =Financials!E9/Financials!E5 -> 0.10043172 | H27: =Financials!F9/Financials!F5 -> 0.097840713 | I27: =Financials!G9/Financials!G5 -> 0.094521704 | J27: =Financials!H9/Financials!H5 -> 0.092719661 | K27: =Financials!I9/Financials!I5 -> 0.090007001 | L27: =Financials!J9/Financials!J5 -> 0.085113282 | ... AK27: =Financials!AI9/Financials!AI5 -> 0.082110965
B29: 4 | C29: GROWTH RATIOS
B30: 4.1 | C30: Total Assets | D30: NPR | F30: =Financials!D5/Financials!B5-1 -> #VALUE! | G30: =Financials!E5/Financials!D5-1 -> 0.0074771871 | H30: =Financials!F5/Financials!E5-1 -> 0.0014457338 | I30: =Financials!G5/Financials!F5-1 -> 0.0092358729 | J30: =Financials!H5/Financials!G5-1 -> -0.0067039718 | K30: =Financials!I5/Financials!H5-1 -> 0.0030294205 | L30: =Financials!J5/Financials!I5-1 -> 0.028915543 | M30: =Financials!K5/Financials!J5-1 -> 0.0055837948 | N30: =Financials!L5/Financials!K5-1 -> 0.0019569454 | ... AK30: =Financials!AI5/Financials!AH5-1 -> 0.0052249869
B31: 4.2 | C31: Total Deposits | D31: NPR | F31: =Financials!D6/Financials!B6-1 -> #VALUE! | G31: =Financials!E6/Financials!D6-1 -> 0.013087988 | H31: =Financials!F6/Financials!E6-1 -> -0.0015171974 | I31: =Financials!G6/Financials!F6-1 -> 0.016835937 | J31: =Financials!H6/Financials!G6-1 -> -0.004992898 | K31: =Financials!I6/Financials!H6-1 -> 0.004467022 | L31: =Financials!J6/Financials!I6-1 -> 0.051440076 | M31: =Financials!K6/Financials!J6-1 -> 0.0057482085 | N31: =Financials!L6/Financials!K6-1 -> 0.0011621312 | ... AK31: =Financials!AI6/Financials!AH6-1 -> 0.029730503
B32: 4.2.1 | C32: FOSA Deposits | D32: NPR | F32: =Financials!D8/Financials!B8-1 -> #VALUE! | G32: =Financials!E8/Financials!D8-1 -> 0.046421484 | H32: =Financials!F8/Financials!E8-1 -> -0.049169375 | I32: =Financials!G8/Financials!F8-1 -> 0.10211104 | J32: =Financials!H8/Financials!G8-1 -> -0.075866624 | K32: =Financials!I8/Financials!H8-1 -> -0.031148444 | L32: =Financials!J8/Financials!I8-1 -> 0.31193711 | M32: =Financials!K8/Financials!J8-1 -> -0.044282159 | N32: =Financials!L8/Financials!K8-1 -> -0.023522112 | ... AK32: =Financials!AI8/Financials!AH8-1 -> 0.11722684
B33: 4.2.2 | C33: BOSA Deposits | D33: NPR | F33: =Financials!D7/Financials!B7-1 -> #VALUE! | G33: =Financials!E7/Financials!D7-1 -> 0.013087988 | H33: =Financials!F7/Financials!E7-1 -> -0.0015171974 | I33: =Financials!G7/Financials!F7-1 -> 0.016835937 | J33: =Financials!H7/Financials!G7-1 -> -0.004992898 | K33: =Financials!I7/Financials!H7-1 -> 0.004467022 | L33: =Financials!J7/Financials!I7-1 -> 0.051440076 | M33: =Financials!K7/Financials!J7-1 -> 0.0057482085 | N33: =Financials!L7/Financials!K7-1 -> 0.0011621312 | ... AK33: =Financials!AI7/Financials!AH7-1 -> 0.029730503
B34: 4.3 | C34: Net Loans & advances | D34: NPR | F34: =Financials!D31/Financials!B31-1 -> #VALUE! | G34: =Financials!E31/Financials!D31-1 -> 0.01029939 | H34: =Financials!F31/Financials!E31-1 -> 0.0071017602 | I34: =Financials!G31/Financials!F31-1 -> 0.004988531 | J34: =Financials!H31/Financials!G31-1 -> -0.0019016746 | K34: =Financials!I31/Financials!H31-1 -> 0.013531405 | L34: =Financials!J31/Financials!I31-1 -> 0.020361482 | M34: =Financials!K31/Financials!J31-1 -> -0.0092507579 | N34: =Financials!L31/Financials!K31-1 -> 0.011612861 | ... AK34: =Financials!AI31/Financials!AH31-1 -> -0.029506738
B35: 4.4 | C35: Core capital | D35: NPR | F35: =Financials!D14/Financials!B14-1 -> #VALUE! | G35: =Financials!E14/Financials!D14-1 -> 0.050599237 | H35: =Financials!F14/Financials!E14-1 -> 0.028662116 | I35: =Financials!G14/Financials!F14-1 -> 0.055977481 | J35: =Financials!H14/Financials!G14-1 -> -0.028256374 | K35: =Financials!I14/Financials!H14-1 -> 0.01288528 | L35: =Financials!J14/Financials!I14-1 -> 0.010946062 | M35: =Financials!K14/Financials!J14-1 -> 0.022292771 | N35: =Financials!L14/Financials!K14-1 -> 0.012804155 | ... AK35: =Financials!AI14/Financials!AH14-1 -> 0.066256889
B36: 4.5 | C36: Total Gross Income | D36: NPR | F36: =Financials!D41/Financials!B41-1 -> #VALUE! | G36: =Financials!E41/Financials!D41-1 -> 0.099146334 | H36: =Financials!F41/Financials!E41-1 -> 0.020988053 | I36: =Financials!G41/Financials!F41-1 -> -0.062053427 | J36: =Financials!H41/Financials!G41-1 -> -0.095693316 | K36: =Financials!I41/Financials!H41-1 -> 0.019166248 | L36: =Financials!J41/Financials!I41-1 -> 0.0072405752 | M36: =Financials!K41/Financials!J41-1 -> 0.040751732 | N36: =Financials!L41/Financials!K41-1 -> 0.00892081 | ... AK36: =Financials!AI41/Financials!AH41-1 -> -0.038768986
B37: 4.6 | C37: Membership | D37: NPR
B39: 5 | C39: Efficiency Ratios
B40: 5.1 | C40: FinCost-Deposits/Average Deposits | D40: NPR | E40: =Financials!C48/((Financials!C6+Financials!A6)/2) -> 0.18416553 | F40: =Financials!D48/((Financials!D6+Financials!B6)/2) -> #VALUE! | G40: =Financials!E48/((Financials!E6+Financials!D6)/2) -> 0.0022826208 | H40: =Financials!F48/((Financials!F6+Financials!E6)/2) -> 0.0036078733 | I40: =Financials!G48/((Financials!G6+Financials!F6)/2) -> 0.027252862 | J40: =Financials!H48/((Financials!H6+Financials!G6)/2) -> 0.032661346 | K40: =Financials!I48/((Financials!I6+Financials!H6)/2) -> 0.036367464 | L40: =Financials!J48/((Financials!J6+Financials!I6)/2) -> 0.039238108 | M40: =Financials!K48/((Financials!K6+Financials!J6)/2) -> 0.041493454 | N40: =Financials!L48/((Financials!L6+Financials!K6)/2) -> 0.045098839 | ... AK40: =Financials!AI48/((Financials!AI6+Financials!AH6)/2) -> 0.041851975
B41: 5.2 | C41: FinCost-Shares/Average Share capital | D41: NPR | E41: =Financials!C49/((Financials!C18+Financials!A18)/2) -> #VALUE! | F41: =Financials!D49/((Financials!D18+Financials!B18)/2) -> #VALUE! | G41: =Financials!E49/((Financials!E18+Financials!D18)/2) -> 0 | H41: =Financials!F49/((Financials!F18+Financials!E18)/2) -> 0 | I41: =Financials!G49/((Financials!G18+Financials!F18)/2) -> 0 | J41: =Financials!H49/((Financials!H18+Financials!G18)/2) -> 0 | K41: =Financials!I49/((Financials!I18+Financials!H18)/2) -> 0 | L41: =Financials!J49/((Financials!J18+Financials!I18)/2) -> 0 | M41: =Financials!K49/((Financials!K18+Financials!J18)/2) -> 0 | N41: =Financials!L49/((Financials!L18+Financials!K18)/2) -> 0 | ... AK41: =Financials!AI49/((Financials!AI18+Financials!AH18)/2) -> 0
B42: 5.3 | C42: FinCost-Ext Loans/Average Ext Loans | D42: NPR | E42: =Financials!C50/((Financials!C9+Financials!A9)/2) -> 0 | F42: =Financials!D50/((Financials!D9+Financials!B9)/2) -> #VALUE! | G42: =Financials!E50/((Financials!E9+Financials!D9)/2) -> 0.022342732 | H42: =Financials!F50/((Financials!F9+Financials!E9)/2) -> 0.032888655 | I42: =Financials!G50/((Financials!G9+Financials!F9)/2) -> 0.044786464 | J42: =Financials!H50/((Financials!H9+Financials!G9)/2) -> 0.056653018 | K42: =Financials!I50/((Financials!I9+Financials!H9)/2) -> 0.069288449 | L42: =Financials!J50/((Financials!J9+Financials!I9)/2) -> 0.081976958 | M42: =Financials!K50/((Financials!K9+Financials!J9)/2) -> 0.095353948 | N42: =Financials!L50/((Financials!L9+Financials!K9)/2) -> 0.10919112 | ... AK42: =Financials!AI50/((Financials!AI9+Financials!AH9)/2) -> 0.06851627
B43: 5.4 | C43: OpEx/Average Total Assets | D43: NPR | E43: =(Financials!C52+Financials!C53)/((Financials!C5+Financials!A5)/2) -> 0.080372012 | F43: =(Financials!D52+Financials!D53)/((Financials!D5+Financials!B5)/2) -> #VALUE! | G43: =(Financials!E52+Financials!E53)/((Financials!E5+Financials!D5)/2) -> 0.0058310399 | H43: =(Financials!F52+Financials!F53)/((Financials!F5+Financials!E5)/2) -> 0.0094401883 | I43: =(Financials!G52+Financials!G53)/((Financials!G5+Financials!F5)/2) -> 0.012740571 | J43: =(Financials!H52+Financials!H53)/((Financials!H5+Financials!G5)/2) -> 0.014708069 | K43: =(Financials!I52+Financials!I53)/((Financials!I5+Financials!H5)/2) -> 0.016542346 | L43: =(Financials!J52+Financials!J53)/((Financials!J5+Financials!I5)/2) -> 0.018489481 | M43: =(Financials!K52+Financials!K53)/((Financials!K5+Financials!J5)/2) -> 0.019694143 | N43: =(Financials!L52+Financials!L53)/((Financials!L5+Financials!K5)/2) -> 0.021510843 | ... AK43: =(Financials!AI52+Financials!AI53)/((Financials!AI5+Financials!AH5)/2) -> 0.021005275
B44: 5.5 | C44: Avge yield on Net loans | D44: NPR | E44: =Financials!C42/((Financials!C31+Financials!A31)/2) -> 0.097304206 | F44: =Financials!D42/((Financials!D31+Financials!B31)/2) -> #VALUE! | G44: =Financials!E42/((Financials!E31+Financials!D31)/2) -> 0.048157238 | H44: =Financials!F42/((Financials!F31+Financials!E31)/2) -> 0.047742244 | I44: =Financials!G42/((Financials!G31+Financials!F31)/2) -> 0.047455546 | J44: =Financials!H42/((Financials!H31+Financials!G31)/2) -> 0.04738282 | K44: =Financials!I42/((Financials!I31+Financials!H31)/2) -> 0.047109232 | L44: =Financials!J42/((Financials!J31+Financials!I31)/2) -> 0.046323156 | M44: =Financials!K42/((Financials!K31+Financials!J31)/2) -> 0.046074073 | N44: =Financials!L42/((Financials!L31+Financials!K31)/2) -> 0.04602195 | ... AK44: =Financials!AI42/((Financials!AI31+Financials!AH31)/2) -> 0.052502872
B46: 6 | C46: Liquidity Ratio
B47: 6.1 | C47: minimum Liquidity | D47: 0.15 | E47: =('SFP-2022'!B4+'SFP-2022'!B11)/('SFP-2022'!#REF!+'SFP-2022'!B33+'SFP-2022'!B34+'SFP-2022'!B35+'SFP-2022'!B36+'SFP-2022'!B37) -> #REF! | F47: =('SFP-2022'!C4+'SFP-2022'!C11)/('SFP-2022'!#REF!+'SFP-2022'!C33+'SFP-2022'!C34+'SFP-2022'!C35+'SFP-2022'!C36+'SFP-2022'!C37) -> #REF! | G47: ='SFP-2022'!D4/('SFP-2022'!D28+'SFP-2022'!D37) -> 0.58941618 | H47: ='SFP-2022'!E4/('SFP-2022'!E28+'SFP-2022'!E37) -> 0.5827146 | I47: ='SFP-2022'!F4/('SFP-2022'!F28+'SFP-2022'!F37) -> 0.69405351 | J47: ='SFP-2022'!G4/('SFP-2022'!G28+'SFP-2022'!G37) -> 0.61783139 | K47: ='SFP-2022'!H4/('SFP-2022'!H28+'SFP-2022'!H37) -> 0.6296639 | L47: ='SFP-2022'!I4/('SFP-2022'!I28+'SFP-2022'!I37) -> 0.66839464 | M47: ='SFP-2022'!J4/('SFP-2022'!J28+'SFP-2022'!J37) -> 0.63491466 | N47: ='SFP-2022'!K4/('SFP-2022'!K28+'SFP-2022'!K37) -> 0.60259415 | ... AK47: ='SFP-2022'!AH4/('SFP-2022'!AH28+'SFP-2022'!AH37) -> 0.73228622
...

Sheet CAELS
B1: KWETU SACCO
B2: FINANCIAL SOUNDNESS INDICATORS | C2: Prude. Std | E2: 44197 | F2: 44228 | G2: 44256 | H2: 44287 | I2: 44317 | J2: 44348 | K2: 44378 | L2: 44409 | M2: 44440 | N2: 44470 | O2: 44501 | P2: 44531 | Q2: Audited 2021 | R2: 44562 | S2: 44593 | T2: 44621 | U2: 44652 | V2: 44682 | W2: 44713 | X2: 44743 | Y2: 44774 | Z2: 44805 | AA2: 44835 | AB2: 44866 | AC2: 44896 | AD2: Audited-2022 | AE2: 44949 | AF2: 44980 | AG2: 45008 | AH2: 45039 | AI2: 45069 | AJ2: 45100
B3: CAPITAL
B4: CORE CAPITAL | C4: ≥ Ksh.10M | E4: ='Prudential Ratios'!F6 -> 637.74636 | F4: ='Prudential Ratios'!G6 -> 670.01584 | G4: ='Prudential Ratios'!H6 -> 689.21991 | H4: ='Prudential Ratios'!I6 -> 727.8007 | I4: ='Prudential Ratios'!J6 -> 707.23569 | J4: ='Prudential Ratios'!K6 -> 716.34862 | K4: ='Prudential Ratios'!L6 -> 724.18982 | L4: ='Prudential Ratios'!M6 -> 740.33402 | ... AJ4: ='Prudential Ratios'!AK6 -> 1198.318
B5: CCA | C5: ≥ 10% | E5: ='Prudential Ratios'!F7 -> 0.14528077 | F5: ='Prudential Ratios'!G7 -> 0.15149908 | G5: ='Prudential Ratios'!H7 -> 0.15561639 | H5: ='Prudential Ratios'!I7 -> 0.16282358 | I5: ='Prudential Ratios'!J7 -> 0.15929066 | J5: ='Prudential Ratios'!K7 -> 0.16085586 | K5: ='Prudential Ratios'!L7 -> 0.1580466 | L5: ='Prudential Ratios'!M7 -> 0.16067273 | ... AJ5: ='Prudential Ratios'!AK7 -> 0.2328877
B6: ICA | C6: ≥ 8% | E6: ='Prudential Ratios'!F10 -> 0.080744884 | F6: ='Prudential Ratios'!G10 -> 0.087194377 | G6: ='Prudential Ratios'!H10 -> 0.09113869 | H6: ='Prudential Ratios'!I10 -> 0.098674062 | I6: ='Prudential Ratios'!J10 -> 0.094482328 | J6: ='Prudential Ratios'!K10 -> 0.095915038 | K6: ='Prudential Ratios'!L10 -> 0.094644481 | L6: ='Prudential Ratios'!M10 -> 0.097171832 | ... AJ6: ='Prudential Ratios'!AK10 -> 0.15340844
B7: CCD | C7: ≥ 8% | E7: ='Prudential Ratios'!F8 -> 0.26444542 | F7: ='Prudential Ratios'!G8 -> 0.27423695 | G7: ='Prudential Ratios'!H8 -> 0.28252581 | H7: ='Prudential Ratios'!I8 -> 0.29340121 | I7: ='Prudential Ratios'!J8 -> 0.28654143 | J7: ='Prudential Ratios'!K8 -> 0.28894288 | K7: ='Prudential Ratios'!L8 -> 0.27781485 | L7: ='Prudential Ratios'!M8 -> 0.2823849 | ... AJ7: ='Prudential Ratios'!AK8 -> 0.44084484
B8: Asset Quality
B9: NPL | C9: ≤ 6%
B10: Earnings
B11: ROA | E11: ='Prudential Ratios'!F55 -> #VALUE! | F11: ='Prudential Ratios'!G55 -> 0.0017874322 | G11: ='Prudential Ratios'!H55 -> 0.0037483423 | H11: ='Prudential Ratios'!I55 -> 0.011588337 | I11: ='Prudential Ratios'!J55 -> 0.011548673 | J11: ='Prudential Ratios'!K55 -> 0.012149707 | K11: ='Prudential Ratios'!L55 -> 0.012754219 | L11: ='Prudential Ratios'!M55 -> 0.013294606 | ... AJ11: ='Prudential Ratios'!AK55 -> 0.014986211
B12: CIR | E12: ='Prudential Ratios'!F56 -> 0.79133968 | F12: ='Prudential Ratios'!G56 -> 0.73809658 | G12: ='Prudential Ratios'!H56 -> 0.76385029 | H12: ='Prudential Ratios'!I56 -> 0.56201554 | I12: ='Prudential Ratios'!J56 -> 0.59990835 | J12: ='Prudential Ratios'!K56 -> 0.60566817 | K12: ='Prudential Ratios'!L56 -> 0.61095265 | L12: ='Prudential Ratios'!M56 -> 0.62006393 | ... AJ12: ='Prudential Ratios'!AK56 -> 0.59457625
B13: OER | E13: ='Prudential Ratios'!F57 -> 0.005507729 | F13: ='Prudential Ratios'!G57 -> 0.010870896 | G13: ='Prudential Ratios'!H57 -> 0.016796479 | H13: ='Prudential Ratios'!I57 -> 0.02257956 | I13: ='Prudential Ratios'!J57 -> 0.027443319 | J13: ='Prudential Ratios'!K57 -> 0.031808396 | K13: ='Prudential Ratios'!L57 -> 0.035697671 | L13: ='Prudential Ratios'!M57 -> 0.040267143 | ... AJ13: ='Prudential Ratios'!AK57 -> 0.035594681
B14: LIQUIDITY
B15: MIN LIQ | C15: 0.15 | E15: ='SFP-2022'!O4/('SFP-2022'!O30+'SFP-2022'!O29+'SFP-2022'!O37) -> 0.10102816 | F15: ='SFP-2022'!P4/('SFP-2022'!P30+'SFP-2022'!P29+'SFP-2022'!P37) -> 0.10838936 | G15: ='SFP-2022'!Q4/('SFP-2022'!Q30+'SFP-2022'!Q29+'SFP-2022'!Q37) -> 0.11472779 | H15: ='SFP-2022'!R4/('SFP-2022'!R30+'SFP-2022'!R29+'SFP-2022'!R37) -> 0.093479761 | I15: ='SFP-2022'!S4/('SFP-2022'!S30+'SFP-2022'!S29+'SFP-2022'!S37) -> 0.092817819 | J15: ='SFP-2022'!T4/('SFP-2022'!T30+'SFP-2022'!T29+'SFP-2022'!T37) -> 0.084539188 | K15: ='SFP-2022'!U4/('SFP-2022'!U30+'SFP-2022'!U29+'SFP-2022'!U37) -> 0.12296439 | L15: ='SFP-2022'!V4/('SFP-2022'!V30+'SFP-2022'!V29+'SFP-2022'!V37) -> 0.13015376 | ... P15: ='SFP-2022'!Z4/('SFP-2022'!Z30+'SFP-2022'!Z29+'SFP-2022'!Z37) -> 0.082986787 | Q15: ='SFP-2022'!O4/('SFP-2022'!O29+'SFP-2022'!O30+'SFP-2022'!O37) -> 0.10102816 | R15: ='SFP-2022'!P4/('SFP-2022'!P29+'SFP-2022'!P30+'SFP-2022'!P37) -> 0.10838936 | S15: ='SFP-2022'!Q4/('SFP-2022'!Q29+'SFP-2022'!Q30+'SFP-2022'!Q37) -> 0.11472779 | T15: ='SFP-2022'!R4/('SFP-2022'!R29+'SFP-2022'!R30+'SFP-2022'!R37) -> 0.093479761 | U15: ='SFP-2022'!S4/('SFP-2022'!S29+'SFP-2022'!S30+'SFP-2022'!S37) -> 0.092817819 | V15: ='SFP-2022'!T4/('SFP-2022'!T29+'SFP-2022'!T30+'SFP-2022'!T37) -> 0.084539188 | W15: ='SFP-2022'!U4/('SFP-2022'!U29+'SFP-2022'!U30+'SFP-2022'!U37) -> 0.12296439 | X15: ='SFP-2022'!V4/('SFP-2022'!V29+'SFP-2022'!V30+'SFP-2022'!V37) -> 0.13015376 | ... AJ15: ='SFP-2022'!AH4/('SFP-2022'!AH29+'SFP-2022'!AH30+'SFP-2022'!AH37) -> 0.14766321
B16: TEC LIQ | E16: ='Prudential Ratios'!F48 -> 0.43079737 | F16: ='Prudential Ratios'!G48 -> 0.43344427 | G16: ='Prudential Ratios'!H48 -> 0.42921403 | H16: ='Prudential Ratios'!I48 -> 0.44691535 | I16: ='Prudential Ratios'!J48 -> 0.43069803 | J16: ='Prudential Ratios'!K48 -> 0.428631 | K16: ='Prudential Ratios'!L48 -> 0.43931959 | L16: ='Prudential Ratios'!M48 -> 0.42665873 | ... AJ16: ='Prudential Ratios'!AK48 -> 0.39947235
B17: EB | C17: ≤ 25% | E17: ='Prudential Ratios'!F27 -> 0.10365053 | F17: ='Prudential Ratios'!G27 -> 0.10043172 | G17: ='Prudential Ratios'!H27 -> 0.097840713 | H17: ='Prudential Ratios'!I27 -> 0.094521704 | I17: ='Prudential Ratios'!J27 -> 0.092719661 | J17: ='Prudential Ratios'!K27 -> 0.090007001 | K17: ='Prudential Ratios'!L27 -> 0.085113282 | L17: ='Prudential Ratios'!M27 -> 0.082289537 | ... AJ17: ='Prudential Ratios'!AK27 -> 0.082110965
B18: LIQ/TA | E18: ='Prudential Ratios'!F58 -> 0.24831455 | F18: ='Prudential Ratios'!G58 -> 0.249102 | G18: ='Prudential Ratios'!H58 -> 0.24612317 | H18: ='Prudential Ratios'!I58 -> 0.25524393 | I18: ='Prudential Ratios'!J58 -> 0.24778097 | J18: ='Prudential Ratios'!K58 -> 0.2473072 | K18: ='Prudential Ratios'!L58 -> 0.25898388 | L18: ='Prudential Ratios'!M58 -> 0.2520009 | ... AJ18: ='Prudential Ratios'!AK58 -> 0.21991168
B19: STRUCTURE
B20: NEA | C20: ≤ 10% | E20: ='Prudential Ratios'!F14 -> 0.27381193 | F20: ='Prudential Ratios'!G14 -> 0.27168583 | G20: ='Prudential Ratios'!H14 -> 0.27195813 | H20: ='Prudential Ratios'!I14 -> 0.26486552 | I20: ='Prudential Ratios'!J14 -> 0.27000834 | J20: ='Prudential Ratios'!K14 -> 0.26543324 | K20: ='Prudential Ratios'!L14 -> 0.25780748 | L20: ='Prudential Ratios'!M14 -> 0.27191884 | ... AJ20: ='Prudential Ratios'!AK14 -> 0.22392615
B21: LB | C21: ≤ 5% | E21: ='Prudential Ratios'!F15 -> 0.03132349 | F21: ='Prudential Ratios'!G15 -> 0.031069599 | G21: ='Prudential Ratios'!H15 -> 0.030932915 | H21: ='Prudential Ratios'!I15 -> 0.031384934 | I21: ='Prudential Ratios'!J15 -> 0.031646156 | J21: ='Prudential Ratios'!K15 -> 0.03159001 | K21: ='Prudential Ratios'!L15 -> 0.03072233 | L21: ='Prudential Ratios'!M15 -> 0.030832037 | ... AJ21: ='Prudential Ratios'!AK15 -> 0.031187136
B22: FITD | C22: ≤ 5% | E22: ='Prudential Ratios'!F19 -> 0.34926009 | F22: ='Prudential Ratios'!G19 -> 0.3448504 | G22: ='Prudential Ratios'!H19 -> 0.34543073 | H22: ='Prudential Ratios'!I19 -> 0.33976311 | I22: ='Prudential Ratios'!J19 -> 0.34148828 | J22: ='Prudential Ratios'!K19 -> 0.34002568 | K22: ='Prudential Ratios'!L19 -> 0.32339045 | L22: ='Prudential Ratios'!M19 -> 0.32157778 | ... AJ22: ='Prudential Ratios'!AK19 -> 0.28311329
B23: FICC | C23: ≤ 40% | E23: ='Prudential Ratios'!F20 -> 1.3207265 | F23: ='Prudential Ratios'!G20 -> 1.2574906 | G23: ='Prudential Ratios'!H20 -> 1.2226519 | H23: ='Prudential Ratios'!I20 -> 1.1580154 | I23: ='Prudential Ratios'!J20 -> 1.1917588 | J23: ='Prudential Ratios'!K20 -> 1.176792 | K23: ='Prudential Ratios'!L20 -> 1.1640503 | L23: ='Prudential Ratios'!M20 -> 1.1387924 | ... AJ23: ='Prudential Ratios'!AK20 -> 0.64220619

Sheet Financials
B1: KWETU SACCO SOCIETY
B3: Year | C3: Audited 2020 | D3: 44197 | E3: 44228 | F3: 44256 | G3: 44287 | H3: 44317 | I3: 44348 | J3: 44378 | K3: 44409 | L3: 44440 | M3: 44470 | N3: 44501 | O3: 44531 | P3: Audited 2021 | Q3: 44562 | R3: 44593 | S3: 44621 | T3: 44652 | U3: 44682 | V3: 44713 | W3: 44743 | X3: 44774 | Y3: 44805 | Z3: 44835 | AA3: 44866 | AB3: 44896 | AC3: Audited-2022 | AD3: 44949 | AE3: 44980 | AF3: 45008 | AG3: 45039 | AH3: 45069 | AI3: 45100 | AJ3: 45130 | AK3: 45161
A4: 1 | B4: Membership
A5: 2 | B5: Total Assets | C5: ='SFP-2022'!B27 -> 4379269975 | D5: ='SFP-2022'!C27 -> 4.3897506e+09 | E5: ='SFP-2022'!D27 -> 4.4225736e+09 | F5: ='SFP-2022'!E27 -> 4.4289675e+09 | G5: ='SFP-2022'!F27 -> 4.4698728e+09 | H5: ='SFP-2022'!G27 -> 4.4399069e+09 | I5: ='SFP-2022'!H27 -> 4.4533573e+09 | J5: ='SFP-2022'!I27 -> 4.5821285e+09 | ... AI5: ='SFP-2022'!AH27 -> 5.145476e+09
A6: 3 | B6: Total Deposits | C6: ='SFP-2022'!B31 -> 2401022868 | D6: ='SFP-2022'!C31 -> 2.411637e+09 | E6: ='SFP-2022'!D31 -> 2.4432004e+09 | F6: ='SFP-2022'!E31 -> 2.4394936e+09 | G6: ='SFP-2022'!F31 -> 2.4805648e+09 | H6: ='SFP-2022'!G31 -> 2.4681796e+09 | I6: ='SFP-2022'!H31 -> 2.479205e+09 | J6: ='SFP-2022'!I31 -> 2.6067355e+09 | ... AI6: ='SFP-2022'!AH31 -> 2.7182308e+09
A7: 3.1 | B7: Deposits-Members(BOSA) | C7: ='SFP-2022'!B31 -> 2401022868 | D7: ='SFP-2022'!C31 -> 2.411637e+09 | E7: ='SFP-2022'!D31 -> 2.4432004e+09 | F7: ='SFP-2022'!E31 -> 2.4394936e+09 | G7: ='SFP-2022'!F31 -> 2.4805648e+09 | H7: ='SFP-2022'!G31 -> 2.4681796e+09 | I7: ='SFP-2022'!H31 -> 2.479205e+09 | J7: ='SFP-2022'!I31 -> 2.6067355e+09 | ... AI7: ='SFP-2022'!AH31 -> 2.7182308e+09
A8: 3.2 | B8: Deposits-Customers(FOSA) | C8: ='SFP-2022'!B28 -> 550189731 | D8: ='SFP-2022'!C28 -> 3.2621451e+08 | E8: ='SFP-2022'!D28 -> 3.4135787e+08 | F8: ='SFP-2022'!E28 -> 3.2457352e+08 | G8: ='SFP-2022'!F28 -> 3.5771606e+08 | H8: ='SFP-2022'!G28 -> 3.3057735e+08 | I8: ='SFP-2022'!H28 -> 3.2028038e+08 | J8: ='SFP-2022'!I28 -> 4.2018772e+08 | ... AI8: ='SFP-2022'!AH28 -> 3.8057014e+08
A9: 4 | B9: External Borrowing | C9: ='SFP-2022'!B38 -> 465833333 | D9: ='SFP-2022'!C38 -> 4.55e+08 | E9: ='SFP-2022'!D38 -> 4.4416667e+08 | F9: ='SFP-2022'!E38 -> 4.3333333e+08 | G9: ='SFP-2022'!F38 -> 4.225e+08 | H9: ='SFP-2022'!G38 -> 4.1166667e+08 | I9: ='SFP-2022'!H38 -> 4.0083333e+08 | J9: ='SFP-2022'!I38 -> 3.9e+08 | ... AI9: ='SFP-2022'!AH38 -> 4.225e+08
A10: 4.1 | B10: Short term Liabilities | C10: ='SFP-2022'!B33+'SFP-2022'!B34+'SFP-2022'!B35+'SFP-2022'!B36+'SFP-2022'!B37 -> 93989880 | D10: ='SFP-2022'!C33+'SFP-2022'!C34+'SFP-2022'!C35+'SFP-2022'!C36+'SFP-2022'!C37 -> 1.186453e+08 | E10: ='SFP-2022'!D33+'SFP-2022'!D34+'SFP-2022'!D35+'SFP-2022'!D36+'SFP-2022'!D37 -> 98468666 | F10: ='SFP-2022'!E33+'SFP-2022'!E34+'SFP-2022'!E35+'SFP-2022'!E36+'SFP-2022'!E37 -> 1.0019861e+08 | G10: ='SFP-2022'!F33+'SFP-2022'!F34+'SFP-2022'!F35+'SFP-2022'!F36+'SFP-2022'!F37 -> 72285368 | H10: ='SFP-2022'!G33+'SFP-2022'!G34+'SFP-2022'!G35+'SFP-2022'!G36+'SFP-2022'!G37 -> 86103015 | I10: ='SFP-2022'!H33+'SFP-2022'!H34+'SFP-2022'!H35+'SFP-2022'!H36+'SFP-2022'!H37 -> 90248352 | J10: ='SFP-2022'!I33+'SFP-2022'!I34+'SFP-2022'!I35+'SFP-2022'!I36+'SFP-2022'!I37 -> 94481239 | ... AI10: ='SFP-2022'!AH33+'SFP-2022'!AH34+'SFP-2022'!AH35+'SFP-2022'!AH36+'SFP-2022'!AH37 -> 1.143814e+08
A13: 5 | B13: Share capital and Reserves
A14: 5.1 | B14: Core Capital | C14: =C17 -> 629590233 | D14: =D17 -> 6.3774636e+08 | E14: =E17 -> 6.7001584e+08 | F14: =F17 -> 6.8921991e+08 | G14: =G17 -> 7.278007e+08 | H14: =H17 -> 7.0723569e+08 | I14: =I17 -> 7.1634862e+08 | J14: =J17 -> 7.2418982e+08 | ... AI14: =AI17 -> 1.198318e+09
A15: 5.2 | B15: Institutional Capital | C15: =C14-C18 -> 347226115 | D15: =D14-D18 -> 3.544499e+08 | E15: =E14-E18 -> 3.8562355e+08 | F15: =F14-F18 -> 4.0365029e+08 | G15: =G14-G18 -> 4.4106051e+08 | H15: =H14-H18 -> 4.1949274e+08 | I15: =I14-I18 -> 4.2714393e+08 | J15: =J14-J18 -> 4.3367318e+08 | ... AI15: =AI14-AI18 -> 7.8935945e+08
A17: 5.3 | B17: Total Capital | C17: =SUM(C18:C21) -> 629590233 | D17: =SUM(D18:D21) -> 6.3774636e+08 | E17: =SUM(E18:E21) -> 6.7001584e+08 | F17: =SUM(F18:F21) -> 6.8921991e+08 | G17: =SUM(G18:G21) -> 7.278007e+08 | H17: =SUM(H18:H21) -> 7.0723569e+08 | I17: =SUM(I18:I21) -> 7.1634862e+08 | J17: =SUM(J18:J21) -> 7.2418982e+08 | ... AI17: =SUM(AI18:AI21) -> 1.198318e+09
A18: 5.3.1 | B18: Members Share Capital | C18: ='SFP-2022'!B41 -> 282364118 | D18: ='SFP-2022'!C41 -> 2.8329645e+08 | E18: ='SFP-2022'!D41 -> 2.8439228e+08 | F18: ='SFP-2022'!E41 -> 2.8556961e+08 | G18: ='SFP-2022'!F41 -> 2.8674019e+08 | H18: ='SFP-2022'!G41 -> 2.8774295e+08 | I18: ='SFP-2022'!H41 -> 2.8920469e+08 | J18: ='SFP-2022'!I41 -> 2.9051664e+08 | ... AI18: ='SFP-2022'!AH41 -> 4.089586e+08
A19: 5.3.3 | B19: Retained Earnings | C19: ='SFP-2022'!B44 -> 198992818 | D19: ='SFP-2022'!C44 -> 2.0388238e+08 | E19: ='SFP-2022'!D44 -> 2.1379173e+08 | F19: ='SFP-2022'!E44 -> 2.2687078e+08 | G19: ='SFP-2022'!F44 -> 2.7921638e+08 | H19: ='SFP-2022'!G44 -> 2.7925144e+08 | I19: ='SFP-2022'!H44 -> 2.8298988e+08 | J19: ='SFP-2022'!I44 -> 2.8801265e+08 | ... AI19: ='SFP-2022'!AH44 -> 5.4506888e+08
A20: 5.3.5 | B20: Statutory Reserves | C20: ='SFP-2022'!B49 -> 101541864 | D20: ='SFP-2022'!C49 -> 1.0154186e+08 | E20: ='SFP-2022'!D49 -> 1.0154186e+08 | F20: ='SFP-2022'!E49 -> 1.0154186e+08 | G20: ='SFP-2022'!F49 -> 1.0154186e+08 | H20: ='SFP-2022'!G49 -> 1.0154186e+08 | I20: ='SFP-2022'!H49 -> 1.0154186e+08 | J20: ='SFP-2022'!I49 -> 1.0154186e+08 | ... AI20: ='SFP-2022'!AH49 -> 1.5253254e+08
A21: 5.3.6 | B21: Capital Reserve | C21: ='SFP-2022'!B50 -> 46691433 | D21: ='SFP-2022'!C50 -> 49025656 | E21: ='SFP-2022'!D50 -> 70289962 | F21: ='SFP-2022'!E50 -> 75237648 | G21: ='SFP-2022'!F50 -> 60302261 | H21: ='SFP-2022'!G50 -> 38699442 | I21: ='SFP-2022'!H50 -> 42612189 | J21: ='SFP-2022'!I50 -> 44118666 | ... AI21: ='SFP-2022'!AH50 -> 91758030
A22: 5.3.7 | B22: Supplementary Capital & reserves
A23: a | B23: Proposed Dividends | C23: ='SFP-2022'!B52 -> 22111655 | D23: ='SFP-2022'!C52 -> 7.0281558e+08 | E23: ='SFP-2022'!D52 -> 7.0281558e+08 | F23: ='SFP-2022'!E52 -> 7.0281558e+08 | G23: ='SFP-2022'!F52 -> 7.0281558e+08 | H23: ='SFP-2022'!G52 -> 7.0281558e+08 | I23: ='SFP-2022'!H52 -> 7.0281558e+08 | J23: ='SFP-2022'!I52 -> 7.0281558e+08 | ... AI23: ='SFP-2022'!AH52 -> 6.2813928e+08
A24: b
A26: 6 | B26: Investments | C26: =C27+C28+C29 -> 848324872 | D26: =D27+D28+D29 -> 8.4228853e+08 | E26: =E27+E28+E29 -> 8.4253864e+08 | F26: =F27+F28+F29 -> 8.4267606e+08 | G26: =G27+G28+G29 -> 8.428044e+08 | H26: =H27+H28+H29 -> 8.428544e+08 | I26: =I27+I28+I29 -> 8.4299336e+08 | J26: =J27+J28+J29 -> 8.4299336e+08 | ... AI26: =AI27+AI28+AI29 -> 7.6956727e+08
A27: 6.1 | B27: Investments in Coop bank, CIC, Kuscco, Kerussu & Codic | C27: ='SFP-2022'!B12 -> 0 | D27: ='SFP-2022'!C12 -> 0 | E27: ='SFP-2022'!D12 -> 0 | F27: ='SFP-2022'!E12 -> 0 | G27: ='SFP-2022'!F12 -> 0 | H27: ='SFP-2022'!G12 -> 0 | I27: ='SFP-2022'!H12 -> 0 | J27: ='SFP-2022'!I12 -> 0 | ... AI27: ='SFP-2022'!AH12 -> 0
A28: 6.2 | B28: Equity Investments (at cost) | C28: ='SFP-2022'!B13 -> 0 | D28: ='SFP-2022'!C13 -> 0 | E28: ='SFP-2022'!D13 -> 0 | F28: ='SFP-2022'!E13 -> 0 | G28: ='SFP-2022'!F13 -> 0 | H28: ='SFP-2022'!G13 -> 0 | I28: ='SFP-2022'!H13 -> 0 | J28: ='SFP-2022'!I13 -> 0 | ... AI28: ='SFP-2022'!AH13 -> 0
A29: 6.3 | B29: Deposits in KUSCCO CFP | C29: ='SFP-2022'!B11 -> 848324872 | D29: ='SFP-2022'!C11 -> 8.4228853e+08 | E29: ='SFP-2022'!D11 -> 8.4253864e+08 | F29: ='SFP-2022'!E11 -> 8.4267606e+08 | G29: ='SFP-2022'!F11 -> 8.428044e+08 | H29: ='SFP-2022'!G11 -> 8.428544e+08 | I29: ='SFP-2022'!H11 -> 8.4299336e+08 | J29: ='SFP-2022'!I11 -> 8.4299336e+08 | ... AI29: ='SFP-2022'!AH11 -> 7.6956727e+08
A31: 7 | B31: Net Loans & advances | C31: =C32-C33 -> 2087101217 | D31: =D32-D33 -> 2.0977456e+09 | E31: =E32-E33 -> 2.1193511e+09 | F31: =F32-F33 -> 2.1344022e+09 | G31: =G32-G33 -> 2.1450497e+09 | H31: =H32-H33 -> 2.1409706e+09 | I31: =I32-I33 -> 2.1699409e+09 | J31: =J32-J33 -> 2.2141241e+09 | ... AI31: =AI32-AI33 -> 2.8617191e+09
A32: 7.1 | B32: Gross Loans & advances | C32: ='SFP-2022'!B15 -> 2153084789 | D32: ='SFP-2022'!C15 -> 2.1652147e+09 | E32: ='SFP-2022'!D15 -> 2.1905953e+09 | F32: ='SFP-2022'!E15 -> 2.1985063e+09 | G32: ='SFP-2022'!F15 -> 2.2124638e+09 | H32: ='SFP-2022'!G15 -> 2.2109571e+09 | I32: ='SFP-2022'!H15 -> 2.247154e+09 | J32: ='SFP-2022'!I15 -> 2.2982481e+09 | ... AI32: ='SFP-2022'!AH15 -> 2.9519508e+09
A33: 7.3 | B33: Allowance for loan losses | C33: ='SFP-2022'!B16 -> 65983572 | D33: ='SFP-2022'!C16 -> 67469142 | E33: ='SFP-2022'!D16 -> 71244246 | F33: ='SFP-2022'!E16 -> 64104130 | G33: ='SFP-2022'!F16 -> 67414041 | H33: ='SFP-2022'!G16 -> 69986500 | I33: ='SFP-2022'!H16 -> 77213148 | J33: ='SFP-2022'!I16 -> 84124003 | ... AI33: ='SFP-2022'!AH16 -> 90231735
A34: 7.4 | B34: Non Performing Loans | C34: =(#REF!+#REF!+#REF!) -> #REF! | D34: =(#REF!+#REF!+#REF!) -> #REF! | E34: =(#REF!+#REF!+#REF!) -> #REF! | F34: =(#REF!+#REF!+#REF!) -> #REF! | G34: =(#REF!+#REF!+#REF!) -> #REF! | H34: =(#REF!+#REF!+#REF!) -> #REF! | I34: =(#REF!+#REF!+#REF!) -> #REF! | J34: =(#REF!+#REF!+#REF!) -> #REF! | ... AC34: =(#REF!+#REF!+#REF!) -> #REF!
A35: 7.5 | B35: Required loan loss provision | C35: =#REF! -> #REF! | D35: =#REF! -> #REF! | E35: =#REF! -> #REF! | F35: =#REF! -> #REF! | G35: =#REF! -> #REF! | H35: =#REF! -> #REF! | I35: =#REF! -> #REF! | J35: =#REF! -> #REF! | ... AC35: =#REF! -> #REF!
A36: 7.6 | B36: Cash and Cash equipments | C36: ='SFP-2022'!B4 -> 251294928 | D36: ='SFP-2022'!C4 -> 2.477504e+08 | E36: ='SFP-2022'!D4 -> 2.5913327e+08 | F36: ='SFP-2022'!E4 -> 2.4739548e+08 | G36: ='SFP-2022'!F4 -> 2.9810352e+08 | H36: ='SFP-2022'!G4 -> 2.5727008e+08 | I36: ='SFP-2022'!H4 -> 2.5835399e+08 | J36: ='SFP-2022'!I4 -> 3.4370407e+08 | ... AI36: ='SFP-2022'!AH4 -> 3.6198302e+08
A38: 8 | B38: Non-Earning Assets | C38: ='SFP-2022'!B7+'SFP-2022'!B17+'SFP-2022'!B23+'SFP-2022'!B24+'SFP-2022'!B25+'SFP-2022'!B26 -> 1192548958 | D38: ='SFP-2022'!C7+'SFP-2022'!C17+'SFP-2022'!C23+'SFP-2022'!C24+'SFP-2022'!C25+'SFP-2022'!C26 -> 1.2019661e+09 | E38: ='SFP-2022'!D7+'SFP-2022'!D17+'SFP-2022'!D23+'SFP-2022'!D24+'SFP-2022'!D25+'SFP-2022'!D26 -> 1.2015506e+09 | F38: ='SFP-2022'!E7+'SFP-2022'!E17+'SFP-2022'!E23+'SFP-2022'!E24+'SFP-2022'!E25+'SFP-2022'!E26 -> 1.2044937e+09 | G38: ='SFP-2022'!F7+'SFP-2022'!F17+'SFP-2022'!F23+'SFP-2022'!F24+'SFP-2022'!F25+'SFP-2022'!F26 -> 1.1839152e+09 | H38: ='SFP-2022'!G7+'SFP-2022'!G17+'SFP-2022'!G23+'SFP-2022'!G24+'SFP-2022'!G25+'SFP-2022'!G26 -> 1.1988119e+09 | I38: ='SFP-2022'!H7+'SFP-2022'!H17+'SFP-2022'!H23+'SFP-2022'!H24+'SFP-2022'!H25+'SFP-2022'!H26 -> 1.182069e+09 | J38: ='SFP-2022'!I7+'SFP-2022'!I17+'SFP-2022'!I23+'SFP-2022'!I24+'SFP-2022'!I25+'SFP-2022'!I26 -> 1.181307e+09 | ... AI38: ='SFP-2022'!AH7+'SFP-2022'!AH17+'SFP-2022'!AH23+'SFP-2022'!AH24+'SFP-2022'!AH25+'SFP-2022'!AH26 -> 1.1522066e+09
A39: 8.1 | B39: Property and Equipment | C39: ='SFP-2022'!B23 -> 138210245 | D39: ='SFP-2022'!C23 -> 1.3750231e+08 | E39: ='SFP-2022'!D23 -> 1.3740759e+08 | F39: ='SFP-2022'!E23 -> 1.3700087e+08 | G39: ='SFP-2022'!F23 -> 140286665 | H39: ='SFP-2022'!G23 -> 1.4050599e+08 | I39: ='SFP-2022'!H23 -> 1.406816e+08 | J39: ='SFP-2022'!I23 -> 1.4077366e+08 | ... AI39: ='SFP-2022'!AH23 -> 1.6047266e+08
A41: 9 | B41: Turnover | C41: =C42+C43+C44 -> 914955301 | D41: =D42+D43+D44 -> 2.1447394e+08 | E41: =E42+E43+E44 -> 2.3573825e+08 | F41: =F42+F43+F44 -> 2.4068594e+08 | G41: =G42+G43+G44 -> 2.2575055e+08 | H41: =H42+H43+H44 -> 2.0414773e+08 | I41: =I42+I43+I44 -> 2.0806048e+08 | J41: =J42+J43+J44 -> 2.0956695e+08 | ... AI41: =AI42+AI43+AI44 -> 3.0819699e+08
A42: 9.1 | B42: Loan Interest | C42: ='SFP-2022'!B49 -> 101541864 | D42: ='SFP-2022'!C49 -> 1.0154186e+08 | E42: ='SFP-2022'!D49 -> 1.0154186e+08 | F42: ='SFP-2022'!E49 -> 1.0154186e+08 | G42: ='SFP-2022'!F49 -> 1.0154186e+08 | H42: ='SFP-2022'!G49 -> 1.0154186e+08 | I42: ='SFP-2022'!H49 -> 1.0154186e+08 | J42: ='SFP-2022'!I49 -> 1.0154186e+08 | ... AI42: ='SFP-2022'!AH49 -> 1.5253254e+08
B43: Income from investments | C43: ='SFP-2022'!B50 -> 46691433 | D43: ='SFP-2022'!C50 -> 49025656 | E43: ='SFP-2022'!D50 -> 70289962 | F43: ='SFP-2022'!E50 -> 75237648 | G43: ='SFP-2022'!F50 -> 60302261 | H43: ='SFP-2022'!G50 -> 38699442 | I43: ='SFP-2022'!H50 -> 42612189 | J43: ='SFP-2022'!I50 -> 44118666 | ... AI43: ='SFP-2022'!AH50 -> 91758030
A44: 9.2 | B44: Fees & Commissions | C44: ='SFP-2022'!B51 -> 766722004 | D44: ='SFP-2022'!C51 -> 63906424 | E44: ='SFP-2022'!D51 -> 63906424 | F44: ='SFP-2022'!E51 -> 63906424 | G44: ='SFP-2022'!F51 -> 63906424 | H44: ='SFP-2022'!G51 -> 63906424 | I44: ='SFP-2022'!H51 -> 63906424 | J44: ='SFP-2022'!I51 -> 63906424 | ... AI44: ='SFP-2022'!AH51 -> 63906424
B45: Average yield on loans
A47: 10 | B47: Total Expenses (FinCosts + OpEx) | C47: =SUM(C48:C53) -> 397078190 | D47: =SUM(D48:D53) -> 21371654 | E47: =SUM(E48:E53) -> 41278304 | F47: =SUM(F48:F53) -> 65018075 | G47: =SUM(G48:G53) -> 1.4289587e+08 | H47: =SUM(H48:H53) -> 1.6996819e+08 | I47: =SUM(I48:I53) -> 1.9166807e+08 | J47: =SUM(J48:J53) -> 2.1572712e+08 | ... AI47: =SUM(AI48:AI53) -> 2.4941283e+08
A48: 10.1 | B48: Financial Exp. (Interest on deposits) | C48: ='SCI-2022'!B13 -> 221092820 | D48: ='SCI-2022'!C13 -> 4002490.3 | E48: ='SCI-2022'!D13 -> 5540876.4 | F48: ='SCI-2022'!E13 -> 8808070.7 | G48: ='SCI-2022'!F13 -> 67042836 | H48: ='SCI-2022'!G13 -> 80816326 | I48: ='SCI-2022'!H13 -> 89961915 | J48: ='SCI-2022'!I13 -> 99781340 | ... AI48: ='SCI-2022'!AH13 -> 1.1212104e+08
A49: 10.2 | B49: Financial Exp. (Dividends) | C49: ='SCI-2022'!B15 -> 0 | D49: ='SCI-2022'!C15 -> 0 | E49: ='SCI-2022'!D15 -> 0 | F49: ='SCI-2022'!E15 -> 0 | G49: ='SCI-2022'!F15 -> 0 | H49: ='SCI-2022'!G15 -> 0 | I49: ='SCI-2022'!H15 -> 0 | J49: ='SCI-2022'!I15 -> 0 | ... AI49: ='SCI-2022'!AH15 -> 0
...

Sheet form4
D3: RISK CLASSIFICATION OF ASSETS AND PROVISIONING | L3: RISK CLASSIFICATION OF ASSETS AND PROVISIONING
D4: SACCO SOCIETY CS NUMBER | L4: SACCO SOCIETY CS NUMBER
D5: FINANCIAL YEAR | L5: FINANCIAL YEAR
D6: START DATE: | L6: START DATE:
D7: END DATE: | L7: END DATE:
D8: PORTFOLIO AGEING REPORT | L8: PORTFOLIO AGEING REPORT
E9: A | F9: B | G9: C | H9: D | M9: A | N9: B | O9: C | P9: D
C10: NO. | D10: CLASSIFICATION | E10: NO. OF A/Cs | F10: OUTSTANDING LOAN PORTFOLIO(Kshs) | G10: REQUIRED PROVISION | H10: REQUIRED PROVISION AMOUNT(Kshs) | K10: NO. | L10: CLASSIFICATION | M10: NO. OF A/Cs | N10: OUTSTANDING LOAN PORTFOLIO(Kshs) | O10: REQUIRED PROVISION | P10: REQUIRED PROVISION AMOUNT(Kshs)
C11: 1 | D11: Performing | K11: 1 | L11: Performing
C12: 2 | D12: Watch | K12: 2 | L12: Watch
C13: 3 | D13: Substandard | K13: 3 | L13: Substandard
C14: 4 | D14: Doubtful | K14: 4 | L14: Doubtful
C15: 5 | D15: Loss | K15: 5 | L15: Loss
D16: subtotal | L16: subtotal | M16: =SUM(M11:M15) -> 0 | N16: =SUM(N11:N15) -> 0 | P16: =SUM(P11:P15) -> 0
D17: Reschedule/Renegotiated loans | L17: Reschedule/Renegotiated loans
C18: 1 | D18: Performing | K18: 1 | L18: Performing | M18: 0 | N18: 0 | O18: 0.01 | P18: =N18*O18 -> 0
C19: 2 | D19: Watch | K19: 2 | L19: Watch | M19: 0 | N19: 0 | O19: 0.05 | P19: =N19*O19 -> 0
C20: 3 | D20: Substandard | K20: 3 | L20: Substandard | M20: 0 | N20: 0 | O20: 0.25 | P20: =N20*O20 -> 0
C21: 4 | D21: Doubtful | K21: 4 | L21: Doubtful | M21: 0 | N21: 0 | O21: 0.5 | P21: =N21*O21 -> 0
C22: 5 | D22: Loss | K22: 5 | L22: Loss | M22: 0 | N22: 0 | O22: 1 | P22: =N22*O22 -> 0
D23: subtotal | E23: =SUM(E17:E22) -> 0 | F23: =SUM(F17:F22) -> 0 | H23: =SUM(H17:H22) -> 0 | L23: subtotal | M23: =SUM(M17:M22) -> 0 | N23: =SUM(N17:N22) -> 0 | P23: =SUM(P17:P22) -> 0
D24: GRAND TOTAL | E24: =E16+E23 -> 0 | F24: =F16+F23 -> 0 | H24: =H16+H23 -> 0 | L24: GRAND TOTAL | M24: =M16+M23 -> 0 | N24: =N16+N23 -> 0 | P24: =P16+P23 -> 0
F26: =F13+F14+F15 -> 0 | N26: =N13+N14+N15 -> 0
F27: =F26/F24 -> #DIV/0! | N27: =N26/N24 -> #DIV/0!
D30: RISK CLASSIFICATION OF ASSETS AND PROVISIONING
D31: SACCO SOCIETY CS NUMBER
D32: FINANCIAL YEAR
D33: START DATE:
D34: END DATE:
D35: PORTFOLIO AGEING REPORT
E36: A | F36: B | G36: C | H36: D
C37: NO. | D37: CLASSIFICATION | E37: NO. OF A/Cs | F37: OUTSTANDING LOAN PORTFOLIO(Kshs) | G37: REQUIRED PROVISION | H37: REQUIRED PROVISION AMOUNT(Kshs)
C38: 1 | D38: Performing
C39: 2 | D39: Watch
C40: 3 | D40: Substandard
C41: 4 | D41: Doubtful
C42: 5 | D42: Loss
D43: subtotal
D44: Reschedule/Renegotiated loans
C45: 1 | D45: Performing | H45: =F45*G45 -> 0
...

Sheet SFP-2022
A1: KWETU SACCO SOCIETY LTD
A2: STATEMENT OF FINANCIAL POSITION
B3: Audited 2020 | C3: 44197 | D3: 44228 | E3: 44256 | F3: 44287 | G3: 44317 | H3: 44348 | I3: 44378 | J3: 44409 | K3: 44440 | L3: 44470 | M3: 44501 | N3: 44531 | O3: AUDITED 2021 | P3: 44562 | Q3: 44593 | R3: 44621 | S3: 44652 | T3: 44682 | U3: 44713 | V3: 44743 | W3: 44774 | X3: 44805 | Y3: 44835 | Z3: 44866 | AA3: 44896 | AB3: Audited-22 | AC3: 44949 | AD3: 44980 | AE3: 45008 | AF3: 45039 | AG3: 45069 | AH3: 45100 | AI3: 45130 | AJ3: 45161 | AK3: 45192 | AL3: 45222
A4: Cash & Cash Equivalent | B4: =SUM(B5:B6) -> 251294928 | C4: =SUM(C5:C6) -> 2.477504e+08 | D4: =SUM(D5:D6) -> 2.5913327e+08 | E4: =SUM(E5:E6) -> 2.4739548e+08 | F4: =SUM(F5:F6) -> 2.9810352e+08 | G4: =SUM(G5:G6) -> 2.5727008e+08 | H4: =SUM(H5:H6) -> 2.5835399e+08 | I4: =SUM(I5:I6) -> 3.4370407e+08 | ... AH4: =SUM(AH5:AH6) -> 3.6198302e+08
A5: Cash in hand | B5: =14623898+23902605 -> 38526503 | C5: 32528616 | D5: 25335508 | E5: 18428547 | F5: 12460689 | G5: 45531114 | H5: 35558284 | I5: 26373154 | J5: 12476967 | K5: 47584095 | L5: 42570464 | M5: 36022000 | N5: 39816394 | O5: =5753282+21912855 -> 27666137 | P5: 32888431 | Q5: 23517965 | R5: 40496648 | S5: 46022747 | T5: 41374151 | U5: 52623479 | V5: 36421180 | W5: 31360313 | X5: 34000824 | Y5: 28637228 | Z5: 27662293 | AA5: 33257684 | AB5: =15230372+17362560 -> 32592932 | AC5: 27601432 | AD5: 17489748 | AE5: 45002038 | AF5: 25213498 | AG5: 27502421 | AH5: 22731417
A6: Cash at bank | B6: =251294928-B5 -> 212768425 | C6: 2.1522178e+08 | D6: 2.3379777e+08 | E6: 2.2896693e+08 | F6: 2.8564283e+08 | G6: 2.1173896e+08 | H6: 2.227957e+08 | I6: 3.1733092e+08 | J6: 3.055844e+08 | K6: 2.5312544e+08 | L6: 1.8040812e+08 | M6: 2.0332463e+08 | N6: 1.8439005e+08 | O6: =212893091-27666137 -> 185226954 | P6: 2.2886186e+08 | Q6: 2.5979991e+08 | R6: 1.9237364e+08 | S6: 1.8701894e+08 | T6: 1.615964e+08 | U6: 2.5128943e+08 | V6: 2.8518586e+08 | W6: 2.6265012e+08 | X6: 2.9407062e+08 | Y6: 2.3549603e+08 | Z6: 1.7760646e+08 | AA6: 1.9699832e+08 | AB6: =12903743+106983802+36217395+7373629+5937365+100586+1329838+14211017 -> 185057375 | AC6: 2.6122478e+08 | AD6: 2.4700314e+08 | AE6: 2.3337181e+08 | AF6: 2.7380339e+08 | AG6: 1.9783838e+08 | AH6: 3.392516e+08
A7: Prepayments & Sundry Receivables | B7: 65659257 | C7: 75087891 | D7: 76667654 | E7: 79744435 | F7: 57780653 | G7: 74358599 | H7: 58815661 | I7: 59806984 | J7: 1.3203329e+08 | K7: 1.3353619e+08 | L7: 1.6673873e+08 | M7: 1.4961383e+08 | N7: 1.3407878e+08 | O7: 136459664 | P7: 1.3663357e+08 | Q7: 1.4112411e+08 | R7: 1.4293937e+08 | S7: 1.4453977e+08 | T7: 1.3930261e+08 | U7: 1.4227755e+08 | V7: 70421877 | W7: 1.2093578e+08 | X7: 1.4623243e+08 | Y7: 1.496084e+08 | Z7: 1.6665143e+08 | AA7: 50340483 | AB7: =27912536+1381710+20385292+1308490+183574 -> 51171602 | AC7: 51546559 | AD7: 55408558 | AE7: 53601259 | AF7: -20444604 | AG7: 79309561 | AH7: 56744759
A8: Financial Investments | B8: =SUM(B9:B13) -> 848324872 | C8: =SUM(C9:C13) -> 8.4228853e+08 | D8: =SUM(D9:D13) -> 8.4253864e+08 | E8: =SUM(E9:E13) -> 8.4267606e+08 | F8: =SUM(F9:F13) -> 8.428044e+08 | G8: =SUM(G9:G13) -> 8.428544e+08 | H8: =SUM(H9:H13) -> 8.4299336e+08 | I8: =SUM(I9:I13) -> 8.4299336e+08 | ... AH8: =SUM(AH9:AH13) -> 7.6956727e+08
A9: Government Securities - Treasury Bills/bonds, | C9: 0 | D9: 0 | E9: 0 | F9: 0 | G9: 0 | H9: 0 | I9: 0 | J9: 0 | K9: 0 | L9: 0 | M9: 0 | N9: 0 | P9: 0 | Q9: 0 | R9: 0 | S9: 0 | T9: 0 | U9: 0 | V9: 0 | W9: 0 | X9: 0 | Y9: 0 | Z9: 0 | AA9: 0 | AB9: 0 | AC9: 0 | AD9: 0 | AE9: 0 | AF9: 0 | AG9: 0 | AH9: 0
A10: Other Securities - Commercial papers/Bonds | C10: 0 | D10: 0 | E10: 0 | F10: 0 | G10: 0 | H10: 0 | I10: 0 | J10: 0 | K10: 0 | L10: 0 | M10: 0 | N10: 0 | P10: 0 | Q10: 0 | R10: 0 | S10: 0 | T10: 0 | U10: 0 | V10: 0 | W10: 0 | X10: 0 | Y10: 0 | Z10: 0 | AA10: 0 | AB10: 0 | AC10: 0 | AD10: 0 | AE10: 0 | AF10: 0 | AG10: 0 | AH10: 0
A11: Balances in NACCOS (E.g Jungu Kuu, ESS, Savings,Money Market,Coop FD, CFP) | B11: 848324872 | C11: 8.4228853e+08 | D11: 8.4253864e+08 | E11: 8.4267606e+08 | F11: 8.428044e+08 | G11: 8.428544e+08 | H11: 8.4299336e+08 | I11: 8.4299336e+08 | J11: 8.4308674e+08 | K11: 8.4508674e+08 | L11: 8.4508674e+08 | M11: 8.4518224e+08 | N11: 9.1904483e+08 | O11: 927895776 | P11: 8.7839408e+08 | Q11: 8.7839408e+08 | R11: 8.7839408e+08 | S11: 8.7839408e+08 | T11: 8.7839408e+08 | U11: 8.7832525e+08 | V11: 8.7832525e+08 | W11: 8.7832525e+08 | X11: 7.7717525e+08 | Y11: 7.7717525e+08 | Z11: 7.7717525e+08 | AA11: 7.772083e+08 | AB11: 1586437 | AC11: 7.706709e+08 | AD11: 7.706709e+08 | AE11: 7.706709e+08 | AF11: 7.6956727e+08 | AG11: 7.6956727e+08 | AH11: 7.6956727e+08
A12: Equity Investments in NACCOs(Shares in- CIC, KUSCCO, COOP BANK,CAK, KERUSSU) | C12: 0 | D12: 0 | E12: 0 | F12: 0 | G12: 0 | H12: 0 | I12: 0 | J12: 0 | K12: 0 | L12: 0 | M12: 0 | N12: 0 | W12: 0 | X12: 0 | Y12: 0 | Z12: 0 | AA12: 0 | AB12: =3738508+706586638+17363209 -> 727688355 | AC12: 0 | AD12: 0 | AE12: 0 | AF12: 0 | AG12: 0 | AH12: 0
A13: Equity Investments in companies - shares/stocks | P13: 0 | Q13: 0 | R13: 0 | S13: 0 | T13: 0 | U13: 0 | V13: 0 | AB13: =260155+11850950+250000+40885950 -> 53247055
A14: Net Loan Portfolio | B14: =B15-B16 -> 2087101217 | C14: =C15-C16 -> 2.0977456e+09 | D14: =D15-D16 -> 2.1193511e+09 | E14: =E15-E16 -> 2.1344022e+09 | F14: =F15-F16 -> 2.1450497e+09 | G14: =G15-G16 -> 2.1409706e+09 | H14: =H15-H16 -> 2.1699409e+09 | I14: =I15-I16 -> 2.2141241e+09 | ... AH14: =AH15-AH16 -> 2.8617191e+09
A15: Gross Loan Portfolio | B15: 2153084789 | C15: 2.1652147e+09 | D15: 2.1905953e+09 | E15: 2.1985063e+09 | F15: 2.2124638e+09 | G15: 2.2109571e+09 | H15: 2.247154e+09 | I15: 2.2982481e+09 | J15: 2.2817658e+09 | K15: 2.3112402e+09 | L15: 2.3484129e+09 | M15: 2.3837482e+09 | N15: 2.3973787e+09 | O15: 2397378724 | P15: 2.3950174e+09 | Q15: 2.3993314e+09 | R15: 2.4601313e+09 | S15: 2.4820924e+09 | T15: 2.4506419e+09 | U15: 2.4455341e+09 | V15: 2.5231802e+09 | W15: 2.510259e+09 | X15: 2.5471861e+09 | Y15: 2.5795909e+09 | Z15: 2.6477768e+09 | AA15: 2.7202943e+09 | AB15: 2720294275 | AC15: 2.8201613e+09 | AD15: 2.8446898e+09 | AE15: 2.8989791e+09 | AF15: 3.0154808e+09 | AG15: 3.0389581e+09 | AH15: 2.9519508e+09
