Workbook
Name BALANCE1_LDA01: '[1]Financial Statements'!$E$112
Name BALANCE1_LDA12: '[1]Financial Statements'!$E$123
Name BALANCE2_LDA01: '[1]Financial Statements'!$F$112
Name BALANCE2_LDA12: '[1]Financial Statements'!$F$123
Name BALANCE3_LDA01: '[1]Financial Statements'!$G$112
Name BALANCE3_LDA12: '[1]Financial Statements'!$G$123
Name BALANCE4_LDA01: '[1]Financial Statements'!$H$112
Name BALANCE4_LDA12: '[1]Financial Statements'!$H$123
Name BALANCE5_LDA01: '[1]Financial Statements'!$I$112
Name BALANCE5_LDA12: '[1]Financial Statements'!$I$123
Name BALANCE6_LDA01: '[1]Financial Statements'!$J$112
Name BALANCE6_LDA12: '[1]Financial Statements'!$J$123
Name PEARLS1_LA002: '[1]Financial Statements'!$E$280
Name PEARLS1_LE008: '[1]Financial Statements'!$E$275
Name PEARLS1_LE009: '[1]Financial Statements'!$E$276
Name PEARLS1_LR001: '[1]Financial Statements'!$E$282
Name PEARLS1_LR005: '[1]Financial Statements'!$E$286
Name PEARLS1_LR006: '[1]Financial Statements'!$E$287
Name PEARLS1_LR007: '[1]Financial Statements'!$E$288
Name PEARLS1_LR009: '[1]Financial Statements'!$E$290
Name PEARLS1_LS001: '[1]Financial Statements'!$E$298
Name PEARLS1_LS005: '[1]Financial Statements'!$E$302
Name PEARLS1_LS011: '[1]Financial Statements'!$E$308
Name PEARLS2_LA002: '[1]Financial Statements'!$F$280
Name PEARLS2_LE008: '[1]Financial Statements'!$F$275
Name PEARLS2_LE009: '[1]Financial Statements'!$F$276
Name PEARLS2_LR001: '[1]Financial Statements'!$F$282
Name PEARLS2_LR005: '[1]Financial Statements'!$F$286
Name PEARLS2_LR006: '[1]Financial Statements'!$F$287
Name PEARLS2_LR007: '[1]Financial Statements'!$F$288
Name PEARLS2_LR009: '[1]Financial Statements'!$F$290
Name PEARLS2_LS001: '[1]Financial Statements'!$F$298
Name PEARLS2_LS005: '[1]Financial Statements'!$F$302
Name PEARLS2_LS010: '[1]Financial Statements'!$F$307
Name PEARLS2_LS011: '[1]Financial Statements'!$F$308
Name PEARLS3_LA002: '[1]Financial Statements'!$G$280
Name PEARLS3_LE008: '[1]Financial Statements'!$G$275
Name PEARLS3_LE009: '[1]Financial Statements'!$G$276
Name PEARLS3_LR001: '[1]Financial Statements'!$G$282
Name PEARLS3_LR005: '[1]Financial Statements'!$G$286
Name PEARLS3_LR006: '[1]Financial Statements'!$G$287
Name PEARLS3_LR007: '[1]Financial Statements'!$G$288
Name PEARLS3_LR009: '[1]Financial Statements'!$G$290
Name PEARLS3_LS001: '[1]Financial Statements'!$G$298
Name PEARLS3_LS005: '[1]Financial Statements'!$G$302
Name PEARLS3_LS010: '[1]Financial Statements'!$G$307
Name PEARLS3_LS011: '[1]Financial Statements'!$G$308
Name PEARLS4_LA002: '[1]Financial Statements'!$H$280
Name PEARLS4_LE008: '[1]Financial Statements'!$H$275
Name PEARLS4_LE009: '[1]Financial Statements'!$H$276
Name PEARLS4_LR001: '[1]Financial Statements'!$H$282
Name PEARLS4_LR005: '[1]Financial Statements'!$H$286
Name PEARLS4_LR006: '[1]Financial Statements'!$H$287
Name PEARLS4_LR007: '[1]Financial Statements'!$H$288
Name PEARLS4_LR009: '[1]Financial Statements'!$H$290
Name PEARLS4_LS001: '[1]Financial Statements'!$H$298
Name PEARLS4_LS005: '[1]Financial Statements'!$H$302
Name PEARLS4_LS010: '[1]Financial Statements'!$H$307
Name PEARLS4_LS011: '[1]Financial Statements'!$H$308
Name PEARLS5_LA002: '[1]Financial Statements'!$I$280

Sheet Evolutive SFP
B3: AUDITED 2007 | C3: AUDITED 2008 | D3: AUDITED 2009 | E3: AUDITED 2010 | F3: AUDITED 2011 | G3: AUDITED 2012 | H3: AUDITED 2013 | I3: AUDITED 2014 | J3: 42005 | K3: 42036 | L3: 42064 | M3: 42095 | N3: 42125 | O3: 42156 | P3: 42186 | Q3: 42217 | R3: 42248 | S3: 42278 | T3: 42309 | U3: 42339 | V3: AUDITED 2015 | W3: 42370 | X3: 42401 | Y3: 42430 | Z3: 42461 | AA3: 42491 | AB3: 42522 | AC3: 42552 | AD3: 42583 | AE3: 42614 | AF3: 42644 | AG3: 42675 | AH3: 42705 | AI3: AUDITED 2016 | AJ3: 42736 | AK3: 42767 | AL3: 42795 | AM3: 42826 | AN3: 42856 | AO3: 42887 | AP3: 42917 | AQ3: 42948 | AR3: 42979 | AS3: 43009 | AT3: 43040 | AU3: 43070 | AV3: AUDITED 2017 | AW3: 43101 | AX3: 43132 | AY3: 43160 | AZ3: 43191 | BA3: 43221 | BB3: 43252 | BC3: 43282 | BD3: 43313 | BE3: 43344 | BF3: 43374 | BG3: 43405 | BH3: 43435 | BI3: AUDITED 2018 | BJ3: 43466 | BK3: 43497 | BL3: 43525 | BM3: 43556 | BN3: 43586 | BO3: 43617 | BP3: 43647 | BQ3: 43678 | BR3: 43709 | BS3: 43739 | BT3: 43770 | BU3: 43800 | BV3: AUDITED 2019 | BW3: 43831 | BX3: 43862 | BY3: 43891 | BZ3: 43922 | CA3: 43952 | CB3: 43983 | CC3: 44044 | CD3: 44075 | CE3: 44105 | CF3: 44136 | CG3: 44166 | CH3: Audited 2020 | CI3: 44197 | CJ3: 44228 | CK3: 44256 | CL3: 44287 | CM3: 44317 | CN3: 44348 | CO3: 44378 | CP3: 44409 | CQ3: 44440 | CR3: 44470 | CS3: 44501 | CT3: 44531 | CU3: AUDITED 2021 | CV3: AUDITED 2022 | CW3: 44927 | CX3: 44958 | CY3: 44986 | CZ3: 45017 | DA3: 45047 | DB3: 45078 | DC3: 45108 | DD3: 45139 | DE3: 45170
A4: Cash & cash Equivalent | B4: =(B5+B6) -> 9072837 | C4: =(C5+C6) -> 9652154 | D4: =(D5+D6) -> 11606332 | E4: =(E5+E6) -> 11999140 | F4: =(F5+F6) -> 11850442 | G4: =(G5+G6) -> 2.0963163e+08 | H4: =(H5+H6) -> 14295816 | I4: =(I5+I6) -> 93164187 | ... DE4: =(DE5+DE6) -> 2.0526233e+08
A5: Cash In Hand | B5: 2129508 | C5: 9652154 | D5: 11606332 | E5: 11999140 | F5: 11850442 | G5: 2.0963163e+08 | H5: =18750+39802 -> 58552 | I5: =1239424+9246254+36226+2337631+18452 -> 12877987 | J5: 3073882.1 | K5: 4646176.1 | L5: 2338283.1 | M5: 5020582.1 | N5: 3075818.1 | O5: 3258057.1 | P5: 866181.09 | Q5: 6631522.4 | R5: 3738090.8 | S5: 3782067.5 | T5: 4504077.8 | U5: 7426930.3 | V5: =9880+4051665 -> 4061545 | W5: 7907096.3 | X5: 9369994.3 | Y5: 9133012.3 | Z5: 7563564.3 | AA5: 9330171 | AB5: 21218903 | AC5: 14724428 | AD5: 10521856 | AE5: 14358579 | AF5: 10445879 | AG5: 8877148.4 | AH5: 5635660.2 | AI5: =10476+950850+1314529+955069 -> 3230924 | AJ5: 8133853.2 | AK5: 10776231 | AL5: 6887292.2 | AM5: 6554107 | AN5: 19436134 | AO5: 13185120 | AP5: 7499782.4 | AQ5: 9338495.4 | AR5: 7490234.6 | AS5: 10637681 | AT5: 8842445.9 | AU5: 8198740.8 | AV5: =3626919+2353+1065239+721786 -> 5416297 | AW5: 6861473.8 | AX5: 8049032.8 | AY5: 9808796.2 | AZ5: 9879877.2 | BA5: 22777270 | BB5: 7115197.2 | BC5: 10666300 | BD5: 9414093.5 | BE5: 7443120 | BF5: 9473993.8 | BG5: 14227305 | BH5: 9952482.6 | BI5: 3821043.6 | BJ5: 7753825.1 | BK5: 10373715 | BL5: 5788558.4 | BM5: 6894236.7 | BN5: 6137764 | BO5: 7940988.4 | BP5: 15061291 | BQ5: 8022872.6 | BR5: 8284175.1 | BS5: 7927205.1 | BT5: 9407027.5 | BU5: 7816909.2 | BV5: 5025922 | BW5: 8896704.1 | BX5: 8250773.4 | BY5: 6994773.8 | BZ5: 10231233 | CA5: 12925229 | CB5: 6039112.7 | CC5: 9491651.7 | CD5: 10354059 | CE5: 11543880 | CF5: 5854286 | CG5: 13064694 | CH5: 11627268 | CI5: 7344350.2 | CJ5: 6615362.3 | CK5: 7730487.1 | CL5: 11107950 | CM5: 13547426 | CN5: 10595249 | CO5: 11012328 | CP5: 6650639.6 | CQ5: 8883353.9 | CR5: 7896906.6 | CS5: 9786459.9 | CT5: 11604850 | CU5: =233362462-CU6 -> 11604851 | CV5: 0 | CW5: 18520446 | CX5: 13683271 | CY5: 15124040 | CZ5: 25630525 | DA5: 19899522 | DB5: 29281101 | DC5: 21504524 | DD5: 25489447 | DE5: 20865878
A6: Cash at Bank | B6: 6943329 | H6: =114295816-100000000-H5 -> 14237264 | I6: =93164187-12877987 -> 80286200 | J6: 94044947 | K6: 89952488 | L6: 93617578 | M6: 88592744 | N6: 87210682 | O6: 1.5175587e+08 | P6: 1.3057663e+08 | Q6: 1.064813e+08 | R6: 1.0785348e+08 | S6: 97690580 | T6: 71671948 | U6: 74669409 | V6: =69012969-V5 -> 64951424 | W6: 69041046 | X6: 64102302 | Y6: 47512557 | Z6: 44524367 | AA6: 42147811 | AB6: 157295064 | AC6: 1.3177994e+08 | AD6: 108049675 | AE6: 71957443 | AF6: 66846945 | AG6: 59581214 | AH6: 69687916 | AI6: =75323576-AI5 -> 72092652 | AJ6: 64161534 | AK6: 65942847 | AL6: 78192077 | AM6: 76257474 | AN6: 2.0021383e+08 | AO6: 1.5814187e+08 | AP6: 1.3179803e+08 | AQ6: 1.0797819e+08 | AR6: 99553409 | AS6: 89316298 | AT6: 81529537 | AU6: 82079655 | AV6: =90278396-5416297 -> 84862099 | AW6: 84985628 | AX6: 82808160 | AY6: 83744832 | AZ6: 76134736 | BA6: 1.7227249e+08 | BB6: 1.4301726e+08 | BC6: 1.1049705e+08 | BD6: 87185064 | BE6: 83103410 | BF6: 79858547 | BG6: 68602626 | BH6: 62214296 | BI6: 68345735 | BJ6: 77589941 | BK6: 53508070 | BL6: 51550108 | BM6: 45306980 | BN6: 43178937 | BO6: 49939682 | BP6: 1.4788614e+08 | BQ6: 1.3628562e+08 | BR6: 82582777 | BS6: 55983230 | BT6: 29984061 | BU6: 15966365 | BV6: =11371837.65+1294570.79+3299956.75+6187+795862.68+524195+688497.5+112815+150740+104785+78911+150000+178994 -> 18757352 | BW6: 20916391 | BX6: 22744819 | BY6: 25338049 | BZ6: 1.210785e+08 | CA6: 79666095 | CB6: 1.7889953e+08 | CC6: 73236977 | CD6: 2.153357e+08 | CE6: 87471702 | CF6: 24703877 | CG6: 30758136 | CH6: =43822830-11627268 -> 32195562 | CI6: 11483467 | CJ6: 32987253 | CK6: 42686986 | CL6: 58001777 | CM6: 50242431 | CN6: 45609153 | CO6: 51401396 | CP6: 42512510 | CQ6: 2.0487868e+08 | CR6: 3.1465648e+08 | CS6: 2.1673047e+08 | CT6: 2.0587439e+08 | CU6: =38177946+43996018+13700430+125883217 -> 221757611 | CV6: =18997845+484619+793570+10902544+1592223+71171+320190+5500+542803+300000+211749+160790+130314072+215461 -> 164912537 | CW6: 1.2725124e+08 | CX6: 1.2636003e+08 | CY6: 1.3271081e+08 | CZ6: 1.2701929e+08 | DA6: 1.1855572e+08 | DB6: 1.3535299e+08 | DC6: 2.8111174e+08 | DD6: 2.1120252e+08 | DE6: 1.8439645e+08
A7: Prepayment and Sundry | B7: =241235 -> 241235 | C7: 210238 | D7: 23363689 | E7: 21063691 | F7: 5577314 | G7: 1759918.6 | H7: 3482697 | I7: 7204334 | J7: 1310705 | K7: 2948933.1 | L7: 1441059.8 | M7: 1515755.8 | N7: 1717323 | O7: 28325030 | P7: 1214917 | Q7: 2035161 | R7: 1845830 | S7: 1409415.1 | T7: 1409415.1 | U7: 8752386 | V7: 24942726 | W7: 8213164.8 | X7: 6948220.4 | Y7: 23754253 | Z7: 18463213 | AA7: 21294198 | AB7: 13657950 | AC7: 13059154 | AD7: 12975869 | AE7: 23189672 | AF7: 22568136 | AG7: 23276423 | AH7: 5557216.8 | AI7: 5557217 | AJ7: 6689660 | AK7: 5850693 | AL7: 4823659.3 | AM7: 5733891.9 | AN7: 7700206.2 | AO7: 3904046.1 | AP7: 4095944.8 | AQ7: 6431976.1 | AR7: 2797303.2 | AS7: 3021493 | AT7: 3036333.1 | AU7: 2939722.3 | AV7: 3775087 | AW7: 4245869.5 | AX7: 4736502.8 | AY7: 4918009.9 | AZ7: 4748069.7 | BA7: 44583187 | BB7: =4045872.94+40000000 -> 44045873 | BC7: 33617176 | BD7: 23611042 | BE7: 15036260 | BF7: 15005012 | BG7: 5173387.5 | BH7: 6971773.9 | BI7: 6787025 | BJ7: 6739591.5 | BK7: 5064049.1 | BL7: 5241965.7 | BM7: 5172855.6 | BN7: 5064954.5 | BO7: 5957568.9 | BP7: 7292830.4 | BQ7: 8245290 | BR7: 9035168.2 | BS7: 9082646.4 | BT7: 9246945.2 | BU7: 12284230 | BW7: 12178438 | BX7: 10565509 | BY7: 10447542 | BZ7: 11809242 | CA7: 12059778 | CB7: 11951870 | CC7: 12889324 | CD7: 13074393 | CE7: 15885199 | CF7: 14929667 | CG7: 17415014 | CH7: 17053152 | CI7: 17668646 | CJ7: 17150062 | CK7: 17074630 | CL7: 18363109 | CM7: 18165302 | CN7: 18431218 | CO7: 19189432 | CP7: 18420830 | CQ7: 19626455 | CR7: 20512573 | CS7: 19943223 | CT7: 22171337 | CU7: 5979284 | CV7: 5029726 | CW7: 5070360 | CX7: 5080039.2 | CY7: 4750756.3 | CZ7: 4660863.5 | DA7: 3770981.9 | DB7: 4248424.8 | DC7: 3818805.4 | DD7: 5167046.8 | DE7: 5394188
A8: Financial Investment | B8: =(B9+B10+B11+B13+B12) -> 3099100 | C8: =(C9+C10+C11+C13+C12) -> 3153280 | D8: =(D9+D10+D11+D13+D12) -> 3153280 | E8: =(E9+E10+E11+E13+E12) -> 3187680 | F8: =(F9+F10+F11+F13+F12) -> 3213000 | G8: =(G9+G10+G11+G13+G12) -> 3837498 | H8: =(H9+H10+H11+H13+H12) -> 109136598 | I8: =(I9+I10+I11+I13+I12) -> 13336598 | ... CP8: =(CP9+CP10+CP11+CP13+CP12) -> 16940857 | CQ8: =(CQ9+CQ10+CQ11+CQ12+CQ13) -> 16940857 | CR8: =(CR9+CR10+CR11+CR12+CR13) -> 16940857 | CS8: =(CS9+CS10+CS11+CS12+CS13) -> 16940857 | CT8: =(CT9+CT10+CT11+CT12+CT13) -> 16940857 | CU8: =(CU9+CU10+CU11+CU12+CU13) -> 16940857 | CV8: =(CV9+CV10+CV11+CV12+CV13) -> 49524309 | CW8: =(CW9+CW10+CW11+CW12+CW13) -> 49524309 | CX8: =(CX9+CX10+CX11+CX12+CX13) -> 49524309 | ... DE8: =(DE9+DE10+DE11+DE12+DE13) -> 49524309
A9: Government Security | J9: 0 | K9: 0 | L9: 0 | M9: 0 | N9: 0 | O9: 0 | P9: 0 | Q9: 0 | R9: 0 | S9: 0 | T9: 0 | U9: 0 | W9: 0 | X9: 0 | Y9: 0 | Z9: 0 | AA9: 0 | AB9: 0 | AC9: 0 | AD9: 0 | AE9: 0 | AF9: 0 | AG9: 0 | AH9: 0 | AI9: 0 | AJ9: 0 | AK9: 0 | AL9: 0 | AM9: 0 | AN9: 0 | AO9: 0 | AP9: 0 | AQ9: 0 | AR9: 0 | AS9: 0 | AT9: 0 | AU9: 0 | AV9: 0 | AW9: 0 | AX9: 0 | AY9: 0 | AZ9: 0 | BA9: 0 | BB9: 0 | BC9: 0 | BD9: 0 | BE9: 0 | BF9: 0 | BG9: 0 | BH9: 0 | BJ9: 0 | BK9: 0 | BL9: 0 | BM9: 0 | BN9: 0 | BO9: 0 | BP9: 0 | BQ9: 0 | BR9: 0 | BS9: 0 | BT9: 0 | BU9: 0 | BW9: 0 | BX9: 0 | BY9: 0 | BZ9: 0 | CA9: 0 | CB9: 0 | CC9: 0 | CD9: 0 | CE9: 0 | CF9: 0 | CG9: 0 | CI9: 0 | CJ9: 0 | CK9: 0 | CL9: 0 | CM9: 0 | CN9: 0 | CO9: 0 | CP9: 0 | CQ9: 0 | CR9: 0 | CS9: 0 | CT9: 0 | CW9: 0 | CX9: 0 | CY9: 0 | CZ9: 0 | DA9: 0 | DB9: 0 | DC9: 0 | DD9: 0 | DE9: 0
A10: Other Securities | J10: 0 | K10: 0 | L10: 0 | M10: 0 | N10: 0 | O10: 0 | P10: 0 | Q10: 0 | R10: 0 | S10: 0 | T10: 0 | U10: 0 | W10: 0 | X10: 0 | Y10: 0 | Z10: 0 | AA10: 0 | AB10: 0 | AC10: 0 | AD10: 0 | AE10: 0 | AF10: 0 | AG10: 0 | AH10: 0 | AI10: 0 | AJ10: 0 | AK10: 0 | AL10: 0 | AM10: 0 | AN10: 0 | AO10: 0 | AP10: 0 | AQ10: 0 | AR10: 0 | AS10: 0 | AT10: 0 | AU10: 0 | AV10: 0 | AW10: 0 | AX10: 0 | AY10: 0 | AZ10: 0 | BA10: 0 | BB10: 0 | BC10: 0 | BD10: 0 | BE10: 0 | BF10: 0 | BG10: 0 | BH10: 0 | BJ10: 0 | BK10: 0 | BL10: 0 | BM10: 0 | BN10: 0 | BO10: 0 | BP10: 0 | BQ10: 0 | BR10: 0 | BS10: 0 | BT10: 0 | BU10: 0 | BW10: 0 | BX10: 0 | BY10: 0 | BZ10: 0 | CA10: 0 | CB10: 0 | CC10: 0 | CD10: 0 | CE10: 0 | CF10: 0 | CG10: 0 | CI10: 0 | CJ10: 0 | CK10: 0 | CL10: 0 | CM10: 0 | CN10: 0 | CO10: 0 | CP10: 0 | CQ10: 0 | CR10: 0 | CS10: 0 | CT10: 0 | CW10: 0 | CX10: 0 | CY10: 0 | CZ10: 0 | DA10: 0 | DB10: 0 | DC10: 0 | DD10: 0 | DE10: 0
A11: Balances in NACCOS (E.g Jungu Kuu, ESS, Savings,Money Market,Coop FD, CFP) | J11: 0 | K11: 0 | L11: 0 | M11: 0 | N11: 0 | O11: 0 | P11: 0 | Q11: 0 | R11: 0 | S11: 0 | T11: 0 | U11: 0 | W11: 0 | X11: 0 | Y11: 0 | Z11: 0 | AA11: 0 | AB11: 0 | AC11: 0 | AD11: 0 | AE11: 0 | AF11: 0 | AG11: 0 | AH11: 0 | AI11: 13277355 | AJ11: 0 | AK11: 0 | AL11: 0 | AM11: 0 | AN11: 0 | AO11: 0 | AP11: 0 | AQ11: 0 | AR11: 0 | AS11: 0 | AT11: 0 | AU11: 0 | AV11: 14314587 | AW11: 0 | AX11: 0 | AY11: 0 | AZ11: 0 | BA11: 0 | BB11: 0 | BC11: 0 | BD11: 0 | BE11: 0 | BF11: 0 | BG11: 0 | BH11: 0 | BJ11: 0 | BK11: 0 | BL11: 0 | BM11: 0 | BN11: 0 | BO11: 0 | BP11: 0 | BQ11: 0 | BR11: 0 | BS11: 0 | BT11: 0 | BU11: 0 | BW11: 0 | BX11: 0 | BY11: 0 | BZ11: 0 | CA11: 0 | CB11: 0 | CC11: 0 | CD11: 0 | CE11: 0 | CF11: 0 | CG11: 0 | CI11: 0 | CJ11: 0 | CK11: 0 | CL11: 0 | CM11: 0 | CN11: 0 | CO11: 0 | CP11: 0 | CQ11: 0 | CR11: 0 | CS11: 0 | CT11: 0 | CW11: 0 | CX11: 0 | CY11: 0 | CZ11: 0 | DA11: 0 | DB11: 0 | DC11: 0 | DD11: 0 | DE11: 0
A12: Equity Investments in NACCOs(Shares in- CIC, KUSCCO, COOP BANK,CAK, KERUSSU) | G12: 3837498 | H12: =100000000+9136598 -> 109136598 | I12: 13336598 | J12: 4832498 | K12: 4832498 | L12: 4832498 | M12: 4832498 | N12: 4832498 | O12: 4832498 | P12: 12823062 | Q12: 12823062 | R12: 12823062 | S12: 13308498 | T12: 13199798 | U12: 13308498 | W12: 13308498 | X12: 13272498 | Y12: 13272498 | Z12: 13272498 | AA12: 13277355 | AB12: 13277355 | AC12: 13277355 | AD12: 13277355 | AE12: 13277355 | AF12: 13277355 | AG12: 13277355 | AH12: 13277355 | AJ12: 13277355 | AK12: 13277355 | AL12: 13277355 | AM12: 13277355 | AN12: 13277355 | AO12: 13277355 | AP12: 13277355 | AQ12: 13277355 | AR12: 14314587 | AS12: 14314587 | AT12: 14314587 | AU12: 14314587 | AW12: 14314587 | AX12: 14314587 | AY12: 14314587 | AZ12: 14314587 | BA12: 14314587 | BB12: 14314587 | BC12: 34314587 | BD12: 34314587 | BE12: 34314587 | BF12: 34314587 | BG12: 34314587 | BH12: 34314587 | BI12: 94611870 | BJ12: 14314587 | BK12: 34314587 | BL12: 34264587 | BM12: 34264587 | BN12: 34264587 | BO12: 34264587 | BP12: 84264587 | BQ12: 84264587 | BR12: 84264587 | BS12: 84264587 | BT12: 84264587 | BU12: 84264587 | BW12: 64264587 | BX12: 64264587 | BY12: 64264587 | BZ12: 64264587 | CA12: 66264027 | CB12: 116264027 | CC12: 116264027 | CD12: 116940857 | CE12: 116940857 | CF12: 116940857 | CG12: 66940857 | CH12: 50000000 | CI12: 66940857 | CJ12: 46940857 | CK12: 46940857 | CW12: 0 | CX12: 0 | CY12: 0 | CZ12: 0 | DA12: 0 | DB12: 0 | DC12: 0 | DD12: 0 | DE12: 0
A13: Equity Investments in companies - shares/stocks | B13: 3099100 | C13: 3153280 | D13: 3153280 | E13: 3187680 | F13: 3213000 | V13: 13272498 | BV13: 11722912 | CH13: =125044646-58103789-50000000 -> 16940857 | CL13: 46940857 | CM13: 46940857 | CN13: 46940857 | CO13: 16940857 | CP13: 16940857 | CQ13: 16940857 | CR13: 16940857 | CS13: 16940857 | CT13: 16940857 | CU13: =73992051-CU22 -> 16940857 | CV13: 49524309 | CW13: 49524309 | CX13: 49524309 | CY13: 49524309 | CZ13: 49524309 | DA13: 49524309 | DB13: 49524309 | DC13: 49524309 | DD13: 49524309 | DE13: 49524309
A14: Net Loan Portfolio | B14: =(B15-B16) -> 49447375 | C14: =(C15-C16) -> 55470816 | D14: =(D15-D16) -> 55516677 | E14: =(E15-E16) -> 60516357 | F14: =(F15-F16) -> 70473718 | G14: =(G15-G16) -> 4079328.1 | H14: =(H15-H16) -> 80748696 | I14: =(I15-I16) -> 102052227 | ... DE14: =(DE15-DE16) -> 3.500674e+08
A15: Gross Loan Portfolio | B15: 53169220 | C15: 63674472 | D15: 72197161 | E15: 78490493 | F15: 79987012 | G15: 4079328.1 | H15: 80748696 | I15: 105659865 | J15: 92638072 | K15: 94271916 | L15: 97321100 | M15: 99708968 | N15: 1.0078959e+08 | O15: 60774670 | P15: 86671810 | Q15: 1.0003238e+08 | R15: 1.0811192e+08 | S15: 1.1667158e+08 | T15: 1.2987107e+08 | U15: 1.3888909e+08 | V15: 143895127 | W15: 1.4112429e+08 | X15: 145038005 | Y15: 145426284 | Z15: 1.4936527e+08 | AA15: 151757044 | AB15: 106119121 | AC15: 1.3892526e+08 | AD15: 154196845 | AE15: 162998012 | AF15: 168301782 | AG15: 170676237 | AH15: 173376620 | AI15: 173376620 | AJ15: 174327576 | AK15: 1.743573e+08 | AL15: 1.7396032e+08 | AM15: 1.737757e+08 | AN15: 1.1295082e+08 | AO15: 1.3461454e+08 | AP15: 1.6351659e+08 | AQ15: 1.7347583e+08 | AR15: 1.78145e+08 | AS15: 1.8181614e+08 | AT15: 1.8819663e+08 | AU15: 1.8343272e+08 | AV15: 183432718 | AW15: 1.8108397e+08 | AX15: 1.7891374e+08 | AY15: 1.7666565e+08 | AZ15: 1.8635001e+08 | BA15: 1.2103648e+08 | BB15: 1.4111859e+08 | BC15: 1.6320818e+08 | BD15: 1.944307e+08 | BE15: 2.0149485e+08 | BF15: 2.0152659e+08 | BG15: 2.1205298e+08 | BH15: 2.1556213e+08 | BI15: 215562132 | BJ15: 2.2036328e+08 | BK15: 2.2340304e+08 | BL15: 2.2857003e+08 | BM15: 2.3008694e+08 | BN15: 2.315006e+08 | BO15: 2.3257777e+08 | BP15: 2.1043968e+08 | BQ15: 2.2136321e+08 | BR15: 2.391268e+08 | BS15: 2.5474266e+08 | BT15: 2.5828705e+08 | BU15: 2.5704619e+08 | BV15: 257046189 | BW15: 2.6187878e+08 | BX15: 2.6513021e+08 | BY15: 2.6075478e+08 | BZ15: 2.1748328e+08 | CA15: 2.3165045e+08 | CB15: 1.8150484e+08 | CC15: 2.4022561e+08 | CD15: 2.6760297e+08 | CE15: 2.9827748e+08 | CF15: 3.1687263e+08 | CG15: 3.2818425e+08 | CH15: 328184248 | CI15: 3.3973494e+08 | CJ15: 3.357611e+08 | CK15: 3.2659681e+08 | CL15: 3.1369754e+08 | CM15: 3.1465328e+08 | CN15: 3.2033375e+08 | CO15: 3.419853e+08 | CP15: 3.528156e+08 | CQ15: 3.5504548e+08 | CR15: 2.4331791e+08 | CS15: 2.8182567e+08 | CT15: 2.7083649e+08 | CU15: 270836485 | CV15: 366357901 | CW15: 3.7787302e+08 | CX15: 3.8334447e+08 | CY15: 3.817687e+08 | CZ15: 3.7576055e+08 | DA15: 3.865305e+08 | DB15: 3.7870679e+08 | DC15: 3.3029772e+08 | DD15: 3.728836e+08 | DE15: 391328588
A16: Allowance For Loan Loss | B16: 3721845 | C16: 8203656 | D16: 16680484 | E16: 17974136 | F16: 9513294 | I16: 3607638 | J16: 1525420.1 | K16: -2457614 | L16: -4710331.1 | M16: -6224922.3 | N16: -8270916.8 | O16: 1819986 | P16: -41795250 | Q16: 2667629.1 | R16: -77564797 | S16: 3193905.9 | T16: 3338256.9 | U16: 3736596.3 | V16: 7344235 | W16: 5311572.9 | X16: 5067241 | Y16: 5028488.4 | Z16: 6090124.9 | AA16: 7701680 | AB16: 7227703 | AC16: 7948965.7 | AD16: 8700631 | AE16: 9887556 | AF16: 11305305 | AG16: 12212990 | AH16: 13505608 | AI16: 13505608 | AJ16: 14728312 | AK16: 15461939 | AL16: 16669390 | AM16: 18239457 | AN16: 16506665 | AO16: 18607033 | AP16: 19910086 | AQ16: 20536817 | AR16: 21154773 | AS16: 21541207 | AT16: 18637024 | AU16: 19450261 | AV16: 20450261 | AW16: 20780274 | AX16: 19141626 | AY16: 19978169 | AZ16: 20069891 | BA16: 18383270 | BB16: 19666720 | BC16: 20902182 | BD16: 21620474 | BE16: 22776647 | BF16: 23595547 | BG16: 24984065 | BH16: 27464068 | BI16: 27464068 | BJ16: 28980330 | BK16: 30204412 | BL16: 28568179 | BM16: 29109466 | BN16: 30517054 | BO16: 32395094 | BP16: 26212332 | BQ16: 29313639 | BR16: 29714131 | BS16: 30988944 | BT16: 33949049 | BU16: 28463507 | BV16: 28463507 | BW16: 28954455 | BX16: 34613448 | BY16: 36104841 | BZ16: 38924517 | CA16: 40195425 | CB16: 32301539 | CC16: 33517598 | CD16: 32976203 | CE16: 32340275 | CF16: 34341464 | CG16: 35406123 | CH16: 35406123 | CI16: 37754496 | CJ16: 41621690 | CK16: 43072777 | CL16: 43304904 | CM16: 47314570 | CN16: 51277948 | CO16: 55002071 | CP16: 62564410 | CQ16: 67891436 | CR16: 52631077 | CS16: 48046888 | CT16: 36416868 | CU16: 36416868 | CV16: 36416868 | CW16: 37327939 | CX16: 39901396 | CY16: 40966925 | CZ16: 43965964 | DA16: 50529402 | DB16: 50516941 | DC16: 34272450 | DD16: 38459878 | DE16: 41261191
A17: Accounts Recievables | B17: =(B18+B19+B20) -> 0 | C17: =(C18+C19+C20) -> 0 | D17: =(D18+D19+D20) -> 0 | E17: =(E18+E19+E20) -> 0 | F17: =(F18+F19+F20) -> 0 | G17: =(G18+G19+G20) -> 0 | H17: =(H18+H19+H20) -> 0 | I17: =(I18+I19+I20) -> 0 | ... DE17: =(DE18+DE19+DE20) -> 0
A18: Tax Recoverable | J18: 0 | K18: 0 | L18: 0 | M18: 0 | N18: 0 | O18: 0 | P18: 0 | Q18: 0 | R18: 0 | S18: 0 | T18: 0 | U18: 0 | W18: 0 | X18: 0 | Y18: 0 | Z18: 0 | AA18: 0 | AB18: 0 | AC18: 0 | AD18: 0 | AE18: 0 | AF18: 0 | AG18: 0 | AH18: 0 | AI18: 0 | AJ18: 0 | AK18: 0 | AL18: 0 | AM18: 0 | AN18: 0 | AO18: 0 | AP18: 0 | AQ18: 0 | AR18: 0 | AS18: 0 | AT18: 0 | AU18: 0 | AV18: 0 | AW18: 0 | AX18: 0 | AY18: 0 | AZ18: 0 | BA18: 0 | BB18: 0 | BC18: 0 | BD18: 0 | BE18: 0 | BF18: 0 | BG18: 0 | BH18: 0 | BJ18: 0 | BK18: 0 | BL18: 0 | BM18: 0 | BN18: 0 | BO18: 0 | BP18: 0 | BQ18: 0 | BR18: 0 | BS18: 0 | BT18: 0 | BU18: 0 | BW18: 0 | BX18: 0 | BY18: 0 | BZ18: 0 | CA18: 0 | CB18: 0 | CC18: 0 | CD18: 0 | CE18: 0 | CF18: 0 | CG18: 0 | CI18: 0 | CJ18: 0 | CK18: 0 | CL18: 0 | CM18: 0 | CN18: 0 | CO18: 0 | CP18: 0 | CW18: 0 | CX18: 0 | CY18: 0 | CZ18: 0 | DA18: 0 | DB18: 0 | DC18: 0 | DD18: 0 | DE18: 0
A19: Deffered Tax Assets | J19: 0 | K19: 0 | L19: 0 | M19: 0 | N19: 0 | O19: 0 | P19: 0 | Q19: 0 | R19: 0 | S19: 0 | T19: 0 | U19: 0 | W19: 0 | X19: 0 | Y19: 0 | Z19: 0 | AA19: 0 | AB19: 0 | AC19: 0 | AD19: 0 | AE19: 0 | AF19: 0 | AG19: 0 | AH19: 0 | AI19: 0 | AJ19: 0 | AK19: 0 | AL19: 0 | AM19: 0 | AN19: 0 | AO19: 0 | AP19: 0 | AQ19: 0 | AR19: 0 | AS19: 0 | AT19: 0 | AU19: 0 | AV19: 0 | AW19: 0 | AX19: 0 | AY19: 0 | AZ19: 0 | BA19: 0 | BB19: 0 | BC19: 0 | BD19: 0 | BE19: 0 | BF19: 0 | BG19: 0 | BH19: 0 | BJ19: 0 | BK19: 0 | BL19: 0 | BM19: 0 | BN19: 0 | BO19: 0 | BP19: 0 | BQ19: 0 | BR19: 0 | BS19: 0 | BT19: 0 | BU19: 0 | BW19: 0 | BX19: 0 | BY19: 0 | BZ19: 0 | CA19: 0 | CB19: 0 | CC19: 0 | CD19: 0 | CE19: 0 | CF19: 0 | CG19: 0 | CI19: 0 | CJ19: 0 | CK19: 0 | CL19: 0 | CM19: 0 | CN19: 0 | CO19: 0 | CP19: 0 | CW19: 0 | CX19: 0 | CY19: 0 | CZ19: 0 | DA19: 0 | DB19: 0 | DC19: 0 | DD19: 0 | DE19: 0
A20: Retirement Benefit Assets | J20: 0 | K20: 0 | L20: 0 | M20: 0 | N20: 0 | O20: 0 | P20: 0 | Q20: 0 | R20: 0 | S20: 0 | T20: 0 | U20: 0 | W20: 0 | X20: 0 | Y20: 0 | Z20: 0 | AA20: 0 | AB20: 0 | AC20: 0 | AD20: 0 | AE20: 0 | AF20: 0 | AG20: 0 | AH20: 0 | AI20: 0 | AJ20: 0 | AK20: 0 | AL20: 0 | AM20: 0 | AN20: 0 | AO20: 0 | AP20: 0 | AQ20: 0 | AR20: 0 | AS20: 0 | AT20: 0 | AU20: 0 | AV20: 0 | AW20: 0 | AX20: 0 | AY20: 0 | AZ20: 0 | BA20: 0 | BB20: 0 | BC20: 0 | BD20: 0 | BE20: 0 | BF20: 0 | BG20: 0 | BH20: 0 | BJ20: 0 | BK20: 0 | BL20: 0 | BM20: 0 | BN20: 0 | BO20: 0 | BP20: 0 | BQ20: 0 | BR20: 0 | BS20: 0 | BT20: 0 | BU20: 0 | BW20: 0 | BX20: 0 | BY20: 0 | BZ20: 0 | CA20: 0 | CB20: 0 | CC20: 0 | CD20: 0 | CE20: 0 | CF20: 0 | CG20: 0 | CI20: 0 | CJ20: 0 | CK20: 0 | CL20: 0 | CM20: 0 | CN20: 0 | CO20: 0 | CP20: 0 | CW20: 0 | CX20: 0 | CY20: 0 | CZ20: 0 | DA20: 0 | DB20: 0 | DC20: 0 | DD20: 0 | DE20: 0
A21: Property&Equipments&Other Assets | B21: =(B22+B23+B24+B25+B26) -> 39181612 | C21: =(C22+C23+C24+C25+C26) -> 38465275 | D21: =(D22+D23+D24+D25+D26) -> 37319422 | E21: =(E22+E23+E24+E25+E26) -> 36083711 | F21: =(F22+F23+F24+F25+F26) -> 35187188 | G21: =(G22+G23+G24+G25+G26) -> 34119364 | H21: =(H22+H23+H24+H25+H26) -> 35001409 | I21: =(I22+I23+I24+I25+I26) -> 68742772 | ... DE21: =(DE22+DE23+DE24+DE25+DE26) -> 72733533
A22: Investment Properties | J22: 0 | K22: 0 | L22: 0 | M22: 0 | N22: 0 | O22: 0 | P22: 0 | Q22: 0 | R22: 0 | S22: 0 | T22: 0 | U22: 0 | W22: 0 | X22: 0 | Y22: 0 | Z22: 0 | AA22: 0 | AB22: 0 | AC22: 0 | AD22: 0 | AE22: 0 | AF22: 0 | AG22: 0 | AH22: 0 | AI22: 0 | AJ22: 0 | AK22: 0 | AL22: 0 | AM22: 0 | AN22: 0 | AO22: 0 | AP22: 0 | AR22: 0 | AS22: 0 | AT22: 0 | AU22: 60556766 | AW22: 60463940 | AX22: 60371113 | AY22: 60278287 | AZ22: 60605767 | BA22: 61045315 | BB22: 61096684 | BC22: 60992722 | BD22: 60898054 | BE22: 60803386 | BF22: 60708718 | BG22: 60614050 | BH22: 60297283 | BJ22: 60204994 | BK22: 60112494 | BL22: 59994288 | BM22: 59902468 | BN22: 59810894 | BO22: 59719511 | BP22: 59628318 | BQ22: 59537315 | BR22: 59446502 | BS22: 59461027 | BT22: 59370353 | BU22: 59442985 | BV22: 143707572 | BW22: 59628202 | BX22: 60172154 | BY22: 60080018 | BZ22: 59988100 | CA22: 59896348 | CB22: 59803339 | CC22: 59617167 | CD22: 59523741 | CE22: 59431334 | CF22: 59338901 | CG22: 58103789 | CH22: 58103789 | CI22: 58016072 | CJ22: 57928539 | CK22: 57840640 | CL22: 57752924 | CM22: 57665208 | CN22: 57577491 | CO22: 57489775 | CP22: 57402059 | CQ22: 57314343 | CR22: 57226626 | CS22: 57138900 | CT22: 57051194 | CU22: 57051194 | CV22: 56024914 | CW22: 55941528 | CX22: 55858143 | CY22: 55774758 | CZ22: 55691373 | DA22: 55607987 | DB22: 55524601 | DC22: 55441216 | DD22: 55357813 | DE22: 55274428
A23: Property and Equipment | B23: 38899150 | C23: 38222790 | D23: 37083833 | E23: 35801719 | F23: 34764877 | G23: 33634899 | H23: 34529467 | I23: 68602755 | J23: 81820805 | K23: 81626203 | L23: 81434968 | M23: 81275547 | N23: 81127540 | O23: 80947852 | P23: 66139055 | Q23: 66005431 | R23: 65942098 | S23: 66502906 | T23: 65853324 | U23: 65688133 | V23: 67183766 | W23: 65821598 | X23: 65674810 | Y23: 66551962 | Z23: 66368220 | AA23: 66332668 | AB23: 66868520 | AC23: 66752159 | AD23: 66589310 | AE23: 67135670 | AF23: 66744795 | AG23: 68815078 | AH23: 65420012 | AI23: =66635551-AI25 -> 65997591 | AJ23: 65691619 | AK23: 65661070 | AL23: 65488205 | AM23: 65599196 | AN23: 65405868 | AO23: 65230122 | AP23: 65600456 | AQ23: 65190740 | AR23: 65017736 | AS23: 64662690 | AT23: 64724750 | AU23: 4434899.9 | AV23: =66635364-637961 -> 65997403 | AW23: 4358754.8 | AX23: 4301478 | AY23: 4228706.2 | AZ23: 4590950 | BA23: 4549799.1 | BB23: 4490022.2 | BC23: 4767228.3 | BD23: 4969646.8 | BE23: 4901768.6 | BF23: 5280579 | BG23: 5279015.2 | BH23: 4626937.9 | BI23: 7592189 | BJ23: 4906334.4 | BK23: 4936595.2 | BL23: 4857251.3 | BM23: 4809192.5 | BN23: 5067602 | BO23: 4771818 | BP23: 4671285.5 | BQ23: 4695247.6 | BR23: 8044766.8 | BS23: 8019247.5 | BT23: 7914948.3 | BU23: 7020122.9 | BV23: 9153451 | BW23: 6920479 | BX23: 6778829.9 | BY23: 6691681.3 | BZ23: 6556567.4 | CA23: 6617545.6 | CB23: 6758640.2 | CC23: 6525401.9 | CD23: 6487237.4 | CE23: 6329159 | CF23: 6171225.2 | CG23: 6051200.5 | CH23: =7544530-1493330 -> 6051200 | CI23: 5935931.1 | CJ23: 5822302.7 | CK23: 5705401.6 | CL23: 5588330.6 | CM23: 5609924.4 | CN23: 5544603.7 | CO23: 5432321.2 | CP23: 5485539.4 | CQ23: 5362391.7 | CR23: 5246380.7 | CS23: 5286203.9 | CT23: 5158193 | CU23: 6203525 | CV23: 8299778 | CW23: 8159712.3 | CX23: 8023159.5 | CY23: 7884534.9 | CZ23: 7748104.5 | DA23: 7622913.2 | DB23: 7631502.6 | DC23: 7571749.7 | DD23: 7256570.6 | DE23: 7196848.3
A24: Prepaid Lease Rentals | J24: 34170 | K24: 62170 | L24: 83170 | M24: 79170 | N24: 77170 | O24: 111170 | P24: 93170 | Q24: 73170 | R24: 74170 | S24: 72170 | T24: 77170 | U24: 0 | W24: 0 | X24: 0 | Y24: 0 | Z24: 0 | AA24: 0 | AB24: 0 | AC24: 0 | AD24: 0 | AE24: 0 | AF24: 0 | AG24: 0 | AH24: 0 | AI24: 0 | AJ24: 0 | AK24: 0 | AL24: 0 | AM24: 0 | AN24: 0 | AO24: 0 | AP24: 0 | AR24: 0 | AS24: 0 | AT24: 0 | AU24: 0 | AW24: 0 | AX24: 0 | AY24: 0 | AZ24: 0 | BA24: 0 | BB24: 0 | BC24: 0 | BD24: 0 | BE24: 0 | BG24: 0 | BH24: 0 | BJ24: 0 | BK24: 0 | BL24: 0 | BM24: 0 | BN24: 0 | BO24: 0 | BP24: 0 | BQ24: 0 | BR24: 0 | BS24: 0 | BT24: 0 | BU24: 0 | BW24: 0 | BX24: 0 | BY24: 0 | BZ24: 0 | CA24: 0 | CB24: 0 | CC24: 0 | CD24: 0 | CE24: 0 | CF24: 0 | CG24: 0 | CI24: 0 | CJ24: 0 | CK24: 0 | CL24: 0 | CM24: 0 | CN24: 0 | CO24: 0 | CP24: 0 | CQ24: 0 | CR24: 0 | CS24: 0 | CT24: 0 | CV24: 10122308 | CW24: 0 | CX24: 0 | CY24: 0 | CZ24: 0 | DA24: 0 | DB24: 0 | DC24: 0 | DD24: 0 | DE24: 0
A25: Intangible Assets | J25: 7989641.1 | K25: 7876453.5 | L25: 7841728.8 | M25: 7652727.2 | N25: 7542144.6 | O25: 7464572.1 | P25: 1689266.9 | Q25: 1658671.1 | R25: 1628840.2 | S25: 1128495.3 | T25: 1100282.9 | U25: 1077359.9 | W25: 1045956.8 | X25: 1019807.9 | Y25: 0 | Z25: 0 | AA25: 0 | AB25: 0 | AC25: 0 | AD25: 0 | AE25: 0 | AF25: 0 | AG25: 0 | AH25: 637960.4 | AI25: 637960.4 | AJ25: 622010.99 | AK25: 606460.69 | AL25: 591299 | AM25: 576515.69 | AN25: 560713.99 | AO25: 545805.79 | AP25: 3989511.2 | AQ25: 4853570.9 | AR25: 4732231.6 | AS25: 4579191.3 | AT25: 4499446 | AU25: 4310881.7 | AV25: 637961 | AW25: 4203969.8 | AX25: 4096657.4 | AY25: 3989376.6 | AZ25: 3882126.4 | BA25: 3774905.8 | BB25: 3667723.2 | BC25: 4086455.6 | BD25: 3965788.1 | BE25: 3858605.5 | BF25: 3751422.9 | BG25: 3680378.7 | BH25: 2965251.3 | BJ25: 2900782.8 | BK25: 2818143 | BL25: 2748316.5 | BM25: 2675938.7 | BN25: 2645833.9 | BO25: 2578464.7 | BP25: 2512734 | BQ25: 2449589.3 | BR25: 2429493.3 | BS25: 2365696.3 | BT25: 2306133.3 | BU25: 2133327.9 | BW25: 2079578.4 | BX25: 2027260.3 | BY25: 1976252.5 | BZ25: 1926896.2 | CA25: 1878406.9 | CB25: 1831129.8 | CC25: 1706655 | CD25: 1653329.1 | CE25: 1599995.9 | CF25: 1546662.7 | CG25: 1493329.5 | CH25: 1493330 | CI25: 1455996.3 | CJ25: 1419596.4 | CK25: 1381339.8 | CL25: 1343073.2 | CM25: 1306663.4 | CN25: 1269330.1 | CO25: 1231996.9 | CP25: 1194663.6 | CQ25: 1157330.4 | CR25: 1119997.2 | CS25: 1082663.9 | CT25: 1045330.7 | CV25: 807332 | CW25: 10726972 | CX25: 10662353 | CY25: 10597638 | CZ25: 10537608 | DA25: 10504967 | DB25: 10440530 | DC25: 10349137 | DD25: 10319993 | DE25: 10262257
A26: Other Assets | B26: 282462 | C26: 242485 | D26: 235589 | E26: 281992 | F26: 422311 | G26: 484464.8 | H26: 471942 | I26: 140017 | J26: 11386542 | K26: 11150285 | L26: 5809887.1 | M26: 5679460.9 | N26: 5624742.5 | O26: 23508249 | P26: 5439213.4 | Q26: 20420890 | R26: 5254148.3 | S26: 9603160.1 | T26: 26183386 | U26: 0 | V26: 185954 | W26: 0 | X26: 0 | Y26: 0 | Z26: 3782806.4 | AA26: 206422 | AB26: 192866 | AC26: 216700 | AD26: 0 | AE26: 0 | AF26: 0 | AG26: 0 | AH26: 188499.7 | AI26: 188500 | AJ26: 168864.7 | AK26: 0 | AL26: 0 | AM26: 0 | AN26: 0 | AO26: 0 | AP26: 0 | AQ26: 0 | AR26: 0 | AS26: 0 | AT26: 0 | AU26: 0 | AV26: 146861 | AW26: 0 | AX26: 0 | AY26: 0 | AZ26: 0 | BA26: 0 | BB26: 0 | BC26: 0 | BD26: 0 | BE26: 0 | BG26: 0 | BH26: 0 | BI26: 184749 | BJ26: 0 | BK26: 0 | BL26: 0 | BM26: 0 | BN26: 0 | BO26: 0 | BP26: 0 | BQ26: 0 | BR26: 0 | BS26: 0 | BT26: 0 | BU26: 0 | BV26: 561318 | BW26: 0 | BX26: 0 | BY26: 0 | BZ26: 0 | CA26: 0 | CB26: 0 | CC26: 0 | CD26: 0 | CE26: 0 | CF26: 0 | CG26: 0 | CH26: 361862 | CI26: 0 | CJ26: 0 | CK26: 0 | CL26: 0 | CM26: 0 | CN26: 0 | CO26: 0 | CP26: 0 | CQ26: 0 | CR26: 0 | CS26: 0 | CT26: 0 | CU26: 308836 | CV26: 277687 | CW26: 0 | CX26: 0 | CY26: 0 | CZ26: 0 | DA26: 0 | DB26: 0 | DC26: 0 | DD26: 0 | DE26: 0
A27: Total Assets | B27: =(B21+B17+B14+B8+B7+B4) -> 101042159 | C27: =(C21+C17+C14+C8+C7+C4) -> 106951763 | D27: =(D21+D17+D14+D8+D7+D4) -> 130959400 | E27: =(E21+E17+E14+E8+E7+E4) -> 132850579 | F27: =(F21+F17+F14+F8+F7+F4) -> 1.2630166e+08 | G27: =(G21+G17+G14+G8+G7+G4) -> 2.5342774e+08 | H27: =(H21+H17+H14+H8+H7+H4) -> 242665216 | I27: =(I21+I17+I14+I8+I7+I4) -> 284500118 | ... DE27: =(DE21+DE17+DE14+DE8+DE7+DE4) -> 6.8298175e+08
A28: Savings and Deposits | B28: 47903083 | C28: 49187636 | D28: 48437747 | E28: 48437747 | F28: 85304630 | G28: =42085730.1+145020+28086.53+23367955.35+12503253 -> 78130045 | H28: =18227509+9386042+144353 -> 27757904 | I28: =101506537-72218472 -> 29288065 | J28: 25114982 | K28: 25462821 | L28: 24471914 | M28: 24597731 | N28: 26079998 | O28: 94663575 | P28: 61871615 | Q28: 43266174 | R28: 38620458 | S28: 36730143 | T28: 38339741 | U28: 34694880 | V28: 34968731 | W28: 31005437 | X28: 31294881 | Y28: 28693138 | Z28: 28077067 | AA28: 28152801 | AB28: 81865550 | AC28: 74456950 | AD28: 60562986 | AE28: 46909980 | AF28: 45343284 | AG28: 39478956 | AH28: 37978118 | AI28: 37978118 | AJ28: 35707716 | AK28: 39805563 | AL28: 46251171 | AM28: 45643638 | AN28: 1.1295355e+08 | AO28: 81835798 | AP28: 74451398 | AQ28: 61751109 | AR28: 55872667 | AS28: 52880183 | AT28: 47979528 | AU28: 45097081 | AV28: 46990567 | AW28: 42575519 | AX28: 38973246 | AY28: 37876191 | AZ28: 42110381 | BA28: 1.1550149e+08 | BB28: 88892029 | BC28: 81711392 | BD28: 77180553 | BE28: 73292762 | BF28: 73617816 | BG28: 65216431 | BH28: 58834888 | BI28: 60006858 | BJ28: 55246692 | BK28: 56487575 | BL28: 53595962 | BM28: 49652052 | BN28: 48949135 | BO28: 53756186 | BP28: 1.6663096e+08 | BQ28: 1.5224484e+08 | BR28: 1.1683412e+08 | BS28: 1.0564632e+08 | BT28: 85169406 | BU28: 75021439 | BV28: 77305996 | BW28: 67371608 | BX28: 68738339 | BY28: 66715778 | BZ28: 1.1318954e+08 | CA28: 1.129156e+08 | CB28: 1.7331063e+08 | CC28: 1.2512086e+08 | CD28: 2.5823128e+08 | CE28: 1.8720633e+08 | CF28: 1.3778075e+08 | CG28: 1.1258053e+08 | CH28: 116282188 | CI28: 99048951 | CJ28: 91994700 | CK28: 91318467 | CL28: 97616332 | CM28: 94226503 | CN28: 92864639 | CO28: 89521526 | CP28: 86599721 | CQ28: 1.7038283e+08 | CR28: 2.1733685e+08 | CS28: 1.6526133e+08 | CT28: 1.4481464e+08 | CU28: 151885246 | CV28: 144662107 | CW28: 1.2764875e+08 | CX28: 1.2620993e+08 | CY28: 1.2861542e+08 | CZ28: 1.3246865e+08 | DA28: 1.2752404e+08 | DB28: 1.3530791e+08 | DC28: 1.960286e+08 | DD28: 1.6349904e+08 | DE28: 1.5177236e+08
A29: Short Terrm Deposits | B29: 594854 | C29: 594854 | D29: 594854 | E29: 594854 | F29: 39525985 | J29: 0 | K29: 0 | L29: 0 | M29: 0 | N29: 0 | O29: 0 | P29: 0 | Q29: 0 | R29: 0 | S29: 0 | T29: 260000 | U29: 260000 | W29: 275000 | X29: 275000 | Y29: 275000 | Z29: 265000 | AA29: 265000 | AB29: 0 | AC29: 0 | AD29: 0 | AE29: 0 | AF29: 0 | AG29: 0 | AH29: 0 | AI29: 0 | AJ29: 0 | AK29: 0 | AL29: 0 | AM29: 0 | AN29: 0 | AO29: 0 | AP29: 180000 | AQ29: 790000 | AR29: 760000 | AS29: 410000 | AT29: 710000 | AU29: 710000 | AW29: 814998 | AX29: 914996 | AY29: 854996 | AZ29: 504996 | BA29: 1022182.9 | BB29: 1062182.9 | BC29: 1062182.9 | BD29: 1111980.9 | BE29: 1111970.9 | BF29: 1456970.9 | BG29: 1271970 | BH29: 1171970 | BJ29: 1066980 | BK29: 1066980 | BL29: 1237182 | BM29: 1261749 | BN29: 1304567 | BO29: 1304567 | BP29: 2281754 | BQ29: 2441754 | BR29: 2546754 | BS29: 2619754 | BT29: 2364567 | BU29: 2284557 | BV29: 109252459 | BW29: 2286157 | BX29: 3281157 | BY29: 3370167 | BZ29: 4056000 | CA29: 4554400 | CB29: 4309400 | CC29: 4116200 | CD29: 3631200 | CE29: 3782460 | CF29: 3932460 | CG29: 3701660 | CI29: 3500400 | CJ29: 4850400 | CK29: 6085000 | CL29: 6085000 | CM29: 6150000 | CN29: 5672050 | CO29: 5626800 | CP29: 5601400 | CQ29: 4255050 | CR29: 6294154 | CS29: 6220904 | CT29: 7070604 | CW29: 6503285 | CX29: 6631385 | CY29: 7004485 | CZ29: 6746193 | DA29: 7038293 | DB29: 4990693 | DC29: 5538797 | DD29: 5390497 | DE29: 5590497
A30: Non Withdrawable Deposits | B30: 39804485 | C30: 39804485 | D30: 39525985 | E30: 39525985 | F30: 5978896 | G30: =39525985 -> 39525985 | H30: 65012036 | I30: 72218472 | J30: 72437415 | K30: 72746392 | L30: 73080937 | M30: 73444770 | N30: 73979692 | O30: 75456788 | P30: 77480018 | Q30: 79938926 | R30: 80414495 | S30: 81425798 | T30: 84524458 | U30: 84274209 | V30: 79759358 | W30: 79808845 | X30: 80665221 | Y30: 82086292 | Z30: 83087102 | AA30: 83685610 | AB30: 88045834 | AC30: 90935673 | AD30: 92736142 | AE30: 93486726 | AF30: 91958826 | AG30: 94543744 | AH30: 89586054 | AI30: 89650681 | AJ30: 90251415 | AK30: 90940015 | AL30: 91229290 | AM30: 91520602 | AN30: 93030414 | AO30: 95071534 | AP30: 97197282 | AQ30: 97792761 | AR30: 98354890 | AS30: 98961025 | AT30: 99553496 | AU30: 99641667 | AV30: 94380497 | AW30: 94864059 | AX30: 95534037 | AY30: 96189608 | AZ30: 96483421 | BA30: 1.0007996e+08 | BB30: 1.0189561e+08 | BC30: 1.0606116e+08 | BD30: 1.0702818e+08 | BE30: 1.0686529e+08 | BF30: 1.0321255e+08 | BG30: 1.0338553e+08 | BH30: 99022261 | BI30: 99022261 | BJ30: 99345353 | BK30: 99471042 | BL30: 1.007383e+08 | BM30: 1.0122515e+08 | BN30: 101827212 | BO30: 1.0278297e+08 | BP30: 1.0854551e+08 | BQ30: 1.1299435e+08 | BR30: 1.1584463e+08 | BS30: 1.1721558e+08 | BT30: 1.1843542e+08 | BU30: 1.0925246e+08 | BW30: 1.0883129e+08 | BX30: 1.0917769e+08 | BY30: 1.0834248e+08 | BZ30: 1.0909378e+08 | CA30: 91930311 | CB30: 1.1649716e+08 | CC30: 1.2017729e+08 | CD30: 1.2260357e+08 | CE30: 1.2799435e+08 | CF30: 1.2994695e+08 | CG30: 1.3090945e+08 | CH30: 130909445 | CI30: 1.3131777e+08 | CJ30: 1.3238356e+08 | CK30: 1.327135e+08 | CL30: 1.3314603e+08 | CM30: 1.3376227e+08 | CN30: 1.3424132e+08 | CO30: 1.3570885e+08 | CP30: 1.3600388e+08 | CQ30: 1.3664754e+08 | CR30: 1.4313259e+08 | CS30: 1.4058583e+08 | CT30: 1.3840726e+08 | CU30: 138407264 | CV30: 160511165 | CW30: 1.6296771e+08 | CX30: 1.6392101e+08 | CY30: 1.6588523e+08 | CZ30: 1.6786545e+08 | DA30: 1.7059832e+08 | DB30: 1.7223813e+08 | DC30: 1.7786135e+08 | DD30: 1.8153271e+08 | DE30: 1.8415523e+08
A31: Total Deposit Liabilities | B31: =SUM(B28:B30) -> 88302422 | C31: =SUM(C28:C30) -> 89586975 | D31: =SUM(D28:D30) -> 88558586 | E31: =SUM(E28:E30) -> 88558586 | F31: =SUM(F28:F30) -> 130809511 | G31: =SUM(G28:G30) -> 1.1765603e+08 | H31: =SUM(H28:H30) -> 92769940 | I31: =SUM(I28:I30) -> 101506537 | ... DE31: =SUM(DE28:DE30) -> 3.4151808e+08
A32: Tax Payable | B32: 44330 | C32: 44330 | D32: 224330 | E32: 224330 | F32: 393743 | J32: 0 | K32: 0 | L32: 0 | M32: 0 | N32: 162492 | O32: 0 | P32: 0 | Q32: 0 | R32: 0 | S32: 0 | T32: 651967 | U32: 651967 | W32: 651967 | X32: 651967 | Y32: 651967 | Z32: 651967 | AA32: 651967 | AB32: 651967 | AC32: 651967 | AD32: 651967 | AE32: 353160 | AF32: 179126 | AG32: 179126 | AH32: 1716001 | AI32: 1311634 | AJ32: 1716001 | AK32: 1418808 | AL32: 0 | AM32: 0 | AN32: 0 | AO32: 0 | AP32: 0 | AQ32: 0 | AR32: 0 | AS32: 0 | AT32: 0 | AU32: 0 | AV32: 0 | AW32: 0 | AX32: 0 | AY32: 0 | AZ32: 0 | BA32: 0 | BB32: 0 | BC32: 0 | BD32: 0 | BE32: 0 | BF32: 0 | BG32: 0 | BH32: 0 | BJ32: 0 | BK32: 0 | BL32: 0 | BM32: 0 | BN32: 0 | BO32: 0 | BP32: 0 | BQ32: 0 | BR32: 0 | BS32: 0 | BT32: 0 | BU32: 0 | BW32: 0 | BX32: 0 | BY32: 0 | BZ32: 0 | CA32: 0 | CB32: 0 | CC32: 0 | CD32: 539534.95 | CE32: 361223.95 | CF32: 182912.95 | CG32: 0 | CH32: 0 | CI32: 0 | CJ32: 0 | CK32: 0 | CL32: 0 | CM32: 0 | CN32: 0 | CO32: 0 | CP32: 0 | CQ32: 0 | CR32: 0 | CS32: 0 | CT32: 0 | CU32: 6543446 | CV32: 4113004 | CW32: 0 | CX32: 0 | CY32: 0 | CZ32: 0 | DA32: 0 | DB32: 0 | DC32: 0 | DD32: 0 | DE32: 0
A33: Dividends Payable | J33: 0 | K33: 0 | L33: 0 | M33: 0 | N33: 0 | O33: 0 | P33: 0 | Q33: 0 | R33: 0 | S33: 0 | T33: 0 | U33: 0 | W33: 0 | X33: 0 | Y33: 0 | Z33: 0 | AA33: 0 | AB33: 0 | AC33: 0 | AD33: 0 | AE33: 0 | AF33: 0 | AG33: 0 | AH33: 0 | AI33: 0 | AJ33: 0 | AK33: 0 | AL33: 0 | AM33: 0 | AN33: 0 | AO33: 0 | AP33: 0 | AQ33: 0 | AR33: 0 | AS33: 0 | AT33: 0 | AU33: 0 | AV33: 4275560 | AW33: 0 | AX33: 0 | AY33: 0 | AZ33: 0 | BA33: 0 | BB33: 0 | BC33: 0 | BD33: 0 | BE33: 0 | BF33: 0 | BG33: 0 | BH33: 0 | BI33: 5000000 | BJ33: 0 | BK33: 0 | BL33: 0 | BM33: 0 | BN33: 0 | BO33: 0 | BP33: 0 | BQ33: 0 | BR33: 0 | BS33: 0 | BT33: 0 | BU33: 0 | BW33: 0 | BX33: 0 | BY33: 0 | BZ33: 0 | CA33: 0 | CB33: 0 | CC33: 0 | CD33: 0 | CE33: 0 | CF33: 0 | CG33: 0 | CH33: 0 | CI33: 7000000 | CJ33: 7000000 | CK33: 7000000 | CL33: 45029.55 | CM33: 45029.55 | CN33: 45029.55 | CO33: 45029.55 | CP33: 0 | CQ33: 0 | CR33: 0 | CS33: 0 | CT33: 0 | CW33: 0 | CX33: 0 | CY33: 0 | CZ33: 0 | DA33: 0 | DB33: 0 | DC33: 0 | DD33: 0 | DE33: 0
A34: Deferred Tax Liability | C34: 9039797 | D34: 31164651 | E34: 32763062 | F34: 30784235 | M34: 0 | N34: 0 | O34: 0 | P34: 0 | Q34: 0 | R34: 0 | S34: 0 | T34: 0 | U34: 0 | W34: 0 | X34: 0 | Y34: 0 | Z34: 0 | AA34: 0 | AB34: 1042028 | AC34: 1159690 | AD34: 1059710 | AE34: 0 | AF34: 0 | AG34: 0 | AH34: 0 | AI34: 0 | AJ34: 0 | AK34: 0 | AL34: 0 | AM34: 0 | AN34: 0 | AO34: 0 | AP34: 0 | AQ34: 0 | AR34: 0 | AS34: 0 | AT34: 0 | AU34: 0 | AV34: 0 | AW34: 0 | AX34: 0 | AY34: 0 | AZ34: 0 | BA34: 0 | BB34: 0 | BC34: 0 | BD34: 0 | BE34: 0 | BF34: 0 | BG34: 0 | BH34: 0 | BJ34: 0 | BK34: 0 | BL34: 0 | BM34: 0 | BN34: 0 | BO34: 0 | BP34: 0 | BQ34: 0 | BR34: 0 | BS34: 0 | BT34: 0 | BU34: 0 | BW34: 0 | BX34: 0 | BY34: 0 | BZ34: 0 | CA34: 0 | CB34: 0 | CC34: 0 | CD34: 0 | CE34: 0 | CF34: 0 | CG34: 0 | CH34: 0 | CI34: 0 | CJ34: 0 | CK34: 0 | CL34: 0 | CM34: 0 | CN34: 0 | CO34: 0 | CP34: 0 | CQ34: 0 | CR34: 0 | CS34: 0 | CT34: 0 | CW34: 0 | CX34: 0 | CY34: 0 | CZ34: 0 | DA34: 0 | DB34: 0 | DC34: 0 | DD34: 0 | DE34: 0
A35: Retirement Benefits Liabilty | B35: 5005464 | C35: 5220296 | D35: 5418645 | E35: 5418645 | J35: 1223471.3 | K35: 1326475.9 | L35: 993408.4 | M35: 1081892.9 | N35: 1172922.8 | O35: 1266320.3 | P35: 1001671.6 | Q35: 1105083.4 | R35: 1212035.1 | S35: 1318986.6 | T35: 1011412 | U35: 1123693 | V35: 11725823 | W35: 1023241.1 | X35: 1152847 | Y35: 1024493 | Z35: 1283450 | AA35: 1408487 | AB35: 10083404 | AC35: 7085661 | AD35: 6052202 | AE35: 1059710 | AF35: 1161902 | AG35: 1264509.6 | AH35: 1051361.3 | AJ35: 1168066.3 | AK35: 493414.95 | AL35: 376705.95 | AM35: 0 | AN35: 0 | AO35: 0 | AP35: 0 | AQ35: 0 | AR35: 0 | AS35: 0 | AT35: 0 | AU35: 0 | AV35: 0 | AW35: 0 | AX35: 0 | AY35: 0 | AZ35: 0 | BA35: 0 | BB35: 0 | BC35: 0 | BD35: 0 | BE35: 0 | BF35: 0 | BJ35: 7714596.7 | BK35: 7302673.1 | BL35: 7461822.2 | BM35: 7741287.6 | BN35: 7201286.4 | BS35: 0 | BW35: 0 | BX35: 0 | BY35: 0 | BZ35: 0 | CA35: 0 | CB35: 0 | CC35: 0 | CD35: 591083.59 | CE35: 569475.89 | CF35: 601107.79 | CG35: 412846 | CI35: 0 | CJ35: 0 | CK35: 0 | CL35: 0 | CM35: 713139.85 | CN35: 731282.85 | CO35: 764363.02 | CP35: 796846.02 | CQ35: 803839.02 | CR35: 834132.02 | CS35: 838754.52 | CT35: 872447.52 | CW35: 1048167.5 | CX35: 1080029.5 | CY35: 1112527.9 | CZ35: 1144744.2 | DA35: 1110826 | DB35: 1141857.9 | DC35: 1161726.4 | DD35: 1406399.3 | DE35: 1195236
A36: Other Liabilities | B36: =33883+64158+167379+8428187+13200000 -> 21893607 | G36: =19443773.41+393743.4+178213656 -> 1.9805117e+08 | H36: =4362880+10817111+178213656 -> 193393647 | I36: 10157592 | J36: 6727894.1 | K36: 6742858.3 | L36: 6277336 | M36: 6806684.2 | N36: 6331607.8 | O36: -6106433.7 | P36: 24113829 | Q36: 7369849.1 | R36: 10046738 | S36: 11050821 | T36: 9347244.4 | U36: 8486407.2 | W36: 8394823.5 | X36: 6604477 | Y36: 7740138.6 | Z36: 6533790.7 | AA36: 7718599 | AB36: 0 | AC36: 0 | AD36: 0 | AE36: 7842750 | AF36: 7002474 | AG36: 6693157.7 | AH36: 2893506.8 | AI36: =4034281+3999868 -> 8034149 | AJ36: 2893505.8 | AK36: 6681300.3 | AL36: 8567645.2 | AM36: 7669947.6 | AN36: 6964469.5 | AO36: 3065908.1 | AP36: 2668084.2 | AQ36: 4010665.1 | AR36: 4183358.2 | AS36: 4111078.7 | AT36: 4242112 | AU36: 2198262.9 | AV36: 2233621 | AW36: 2749440 | AX36: 2640228.3 | AY36: 2759673.2 | AZ36: 1818411.3 | BA36: 1177797.1 | BB36: 195312.3 | BC36: 1420285.1 | BD36: 1827256.9 | BE36: 1293035.6 | BF36: 2046605.5 | BG36: 4539384.6 | BH36: 8004071.8 | BI36: 3004072 | BJ36: 0 | BK36: 0 | BL36: 0 | BM36: 0 | BN36: 0 | BO36: 6916192 | BP36: 3366208 | BQ36: 3629076 | BR36: 6431941.9 | BS36: 6291352.8 | BT36: 4763249.6 | BU36: 11600951 | BV36: =9600951+3878837.5 -> 13479788 | BW36: 11464601 | BX36: 12411077 | BY36: 12015102 | BZ36: 10514832 | CA36: 5183510.2 | CB36: 4364729.5 | CC36: 3439965.8 | CD36: 34676669 | CE36: 4991838.4 | CF36: 2731401.4 | CG36: 10685643 | CH36: =11098489+2554227 -> 13652716 | CI36: 4161802.1 | CJ36: 4914619.5 | CK36: 5376745.1 | CL36: 5387752.9 | CM36: 3206020.4 | CN36: 3541266.4 | CO36: 2715412.8 | CP36: 2921561.9 | CQ36: 88544509 | CR36: 7541690.3 | CS36: 3808915.7 | CT36: 11945442 | CU36: 12817890 | CV36: 17166685 | CW36: 15435563 | CX36: 15424156 | CY36: 15602246 | CZ36: 7820357.4 | DA36: 3862057.1 | DB36: 4830228.9 | DC36: 5835191.4 | DD36: 8544929.3 | DE36: 8570291.2
A37: External Borrowings | B37: 23369140 | C37: 22592216 | D37: 21733302 | E37: 20582216 | F37: 19635543 | G37: 28914 | H37: 28914 | J37: 0 | K37: 0 | L37: 0 | M37: 0 | N37: 0 | O37: 0 | P37: 0 | W37: 0 | X37: 0 | Y37: 0 | Z37: 0 | AA37: 0 | AE37: 0 | AF37: 0 | AG37: 0 | AH37: 0 | AI37: 0 | AJ37: 0 | AK37: 0 | AL37: 0 | AM37: 0 | AN37: 0 | AO37: 0 | AP37: 0 | AQ37: 0 | AR37: 0 | AS37: 0 | AT37: 0 | AU37: 0 | AV37: 0 | AW37: 0 | AX37: 0 | AY37: 0 | AZ37: 0 | BA37: 0 | BB37: 0 | BC37: 0 | BD37: 0 | BE37: 0 | BF37: 0 | BG37: 0 | BH37: 0 | BS37: 0 | BT37: 0 | BU37: 0 | BW37: 0 | BX37: 0 | BY37: 0 | BZ37: 0 | CA37: 0 | CB37: 0 | CC37: 0 | CD37: 0 | CE37: 0 | CF37: 0 | CG37: 0 | CH37: 0 | CI37: 0 | CJ37: 0 | CK37: 0 | CL37: 0 | CM37: 0 | CN37: 0 | CO37: 0 | CP37: 0 | CQ37: 0 | CR37: 0 | CS37: 0 | CT37: 0 | CW37: 0 | CX37: 0 | CY37: 0 | CZ37: 0 | DA37: 0 | DB37: 0 | DC37: 0 | DD37: 0 | DE37: 0
A38: Total Liabilities | B38: =SUM(B31:B37) -> 138614963 | C38: =SUM(C31:C37) -> 126483614 | D38: =SUM(D31:D37) -> 147099514 | E38: =SUM(E31:E37) -> 147546839 | F38: =SUM(F31:F37) -> 1.8162303e+08 | G38: =SUM(G31:G37) -> 3.1573612e+08 | H38: =SUM(H31:H37) -> 286192501 | I38: =SUM(I31:I37) -> 111664129 | ... DE38: =SUM(DE31:DE37) -> 3.5128361e+08
A39: Share Capital | B39: 39654157 | C39: 42633397 | D39: 45827379 | E39: 46758589 | F39: 7234210 | G39: 6384515 | H39: 29031754 | I39: 30295797 | J39: 30374854 | K39: 30458377 | L39: 30496327 | M39: 30601194 | N39: 30741444 | O39: 30982542 | P39: 31205332 | Q39: 31359394 | R39: 31478786 | S39: 31560786 | T39: 31690048 | U39: 31816457 | V39: 37302914 | W39: 37326707 | X39: 37355231 | Y39: 37499688 | Z39: 37614688 | AA39: 37739780 | AB39: 38173480 | AC39: 38695298 | AD39: 38894098 | AE39: 38977898 | AF39: 39026898 | AG39: 39061898 | AH39: 44659170 | AI39: 44659171 | AJ39: 44743259 | AK39: 44817259 | AL39: 44880859 | AM39: 44950459 | AN39: 45097359 | AO39: 45354840 | AP39: 45459140 | AQ39: 45598940 | AR39: 45677790 | AS39: 45771505 | AT39: 45885591 | AU39: 45958981 | AV39: 51220150 | AW39: 51274918 | AX39: 51389970 | AY39: 51449946 | AZ39: 51557960 | BA39: 52114502 | BB39: 52450928 | BC39: 52710774 | BD39: 52889882 | BE39: 52997068 | BF39: 53128365 | BG39: 53410692 | BH39: 58962034 | BI39: 58962034 | BJ39: 59174647 | BK39: 59307947 | BL39: 59510137 | BM39: 59661537 | BN39: 59793337 | BO39: 59900537 | BP39: 60573193 | BQ39: 60859093 | BR39: 61012093 | BS39: 61139610 | BT39: 61290690 | BU39: 66711730 | BV39: 66711729 | BW39: 66839130 | BX39: 66942030 | BY39: 67024730 | BZ39: 67228416 | CA39: 67195060 | CB39: 67539981 | CC39: 67783453 | CD39: 67986283 | CE39: 68176578 | CF39: 68306878 | CG39: 68433278 | CH39: 68433278 | CI39: 68636428 | CJ39: 68700328 | CK39: 68784228 | CL39: 68852728 | CM39: 68933138 | CN39: 69003738 | CO39: 69120988 | CP39: 69151988 | CQ39: 69504626 | CR39: 70390202 | CS39: 70538002 | CT39: 70707252 | CU39: 70707252 | CV39: 77017592 | CW39: 77287991 | CX39: 77557841 | CY39: 77824566 | CZ39: 78015216 | DA39: 78347332 | DB39: 78671212 | DC39: 79543392 | DD39: 80174491 | DE39: 80618050
A40: Capital Grants | J40: 0 | K40: 0 | L40: 0 | M40: 0 | N40: 0 | O40: 0 | P40: 0 | Q40: 0 | R40: 0 | S40: 0 | T40: 0 | U40: 0 | W40: 0 | X40: 0 | Y40: 0 | Z40: 0 | AA40: 0 | AB40: 163561391 | AC40: 163561391 | AD40: 163561391 | AE40: 163561391 | AF40: 163561391 | AG40: 163561391 | AH40: 163561391 | AI40: 79163018 | AJ40: 163561391 | AK40: 163561391 | AL40: 163561391 | AM40: 163561391 | AN40: 163561391 | AO40: 163561391 | AP40: 163561391 | AQ40: 163561391 | AR40: 163561391 | AS40: 163561391 | AT40: 163561391 | AU40: 163561391 | AV40: 163561391 | AW40: 163561391 | AX40: 163561391 | AY40: 163561391 | AZ40: 163561391 | BA40: 163561391 | BB40: 163561391 | BC40: 163561391 | BD40: 163561391 | BE40: 163561391 | BF40: 163561391 | BG40: 163561391 | BH40: 163561391 | BI40: 163561391 | BJ40: 163561391 | BK40: 163561391 | BL40: 163561391 | BM40: 163561391 | BN40: 163561391 | BO40: 163561391 | BP40: 163561391 | BQ40: 163561391 | BR40: 163561391 | BS40: 163561391 | BT40: 163561391 | BU40: 163561391 | BV40: 163561391 | BW40: 163561391 | BX40: 163561391 | BY40: 163561391 | BZ40: 163561391 | CA40: 163561391 | CB40: 163561391 | CC40: 163561391 | CD40: 163561391 | CE40: 163561391 | CF40: 163561391 | CG40: 163561391 | CH40: 163561391 | CI40: 163561391 | CJ40: 163561391 | CK40: 163561391 | CL40: 163561391 | CM40: 163561391 | CN40: 163561391 | CO40: 163561391 | CP40: 163561391 | CQ40: 163561391 | CR40: 163561391 | CS40: 163561391 | CT40: 163561391 | CU40: 163561391 | CV40: 163561391 | CW40: 163561391 | CX40: 163561391 | CY40: 163561391 | CZ40: 163561391 | DA40: 163561391 | DB40: 163561391 | DC40: 163561391 | DD40: 163561391 | DE40: 163561391
A41: Prior Year Retained Earnigs | F41: -115950062 | G41: -116905773 | H41: -123040086 | I41: 49993382 | J41: 57092304 | K41: 57835132 | L41: 57835132 | M41: 57835132 | N41: 54585301 | O41: 54585301 | P41: 54585301 | Q41: 54585301 | R41: 54585301 | S41: -81477078 | T41: -82127078 | U41: -82127078 | V41: =-82339117-27338672 -> -109677789 | W41: -82127078 | X41: -82163214 | Y41: -82224151 | Z41: -82225841 | AA41: -82546764 | AB41: -106964013 | AC41: -1.0696338e+08 | AD41: -1.0696338e+08 | AE41: -106984383 | AF41: -106987284 | AG41: -106987284 | AH41: -116058311 | AI41: -107127007 | AJ41: -112205112 | AK41: -115411797 | AL41: -115411797 | AM41: -1.1462557e+08 | AN41: -1.1462557e+08 | AO41: -1.139161e+08 | AP41: -1.1406151e+08 | AQ41: -1.1405802e+08 | AR41: -1.1405802e+08 | AS41: -1.1427865e+08 | AT41: -1.1428205e+08 | AU41: -1.1427865e+08 | AV41: -114885111 | AW41: -1.0744527e+08 | AX41: -1.0742332e+08 | AY41: -1.0745267e+08 | AZ41: -1.0744017e+08 | BA41: -1.1166081e+08 | BB41: -1.1166081e+08 | BC41: -1.1310365e+08 | BD41: -1.1318899e+08 | BE41: -1.1317677e+08 | BF41: -1.1316032e+08 | BG41: -1.1316032e+08 | BH41: -1.1330413e+08 | BJ41: -1.1131316e+08 | BK41: -1.1131316e+08 | BL41: -1.1128443e+08 | BM41: -1.1128443e+08 | BN41: -1.1128938e+08 | BO41: -1.1128938e+08 | BP41: -1.1126688e+08 | BQ41: -1.1126688e+08 | BR41: -1.1126688e+08 | BS41: -1.1318168e+08 | BT41: -1.1317673e+08 | BU41: -1.134572e+08 | BW41: -1.0252601e+08 | BX41: -1.0252601e+08 | BY41: -1.0252601e+08 | BZ41: -1.0252601e+08 | CA41: -1.0252601e+08 | CB41: -1.037163e+08 | CC41: -1.054817e+08 | CD41: -1.0548041e+08 | CE41: -1.0548041e+08 | CF41: -1.0548041e+08 | CG41: -1.0561029e+08 | CH41: =-100842397-8514089 -> -109356486 | CI41: -97094425 | CJ41: -97094425 | CK41: -97094425 | CL41: -97094425 | CM41: -97317647 | CN41: -97316647 | CO41: -97316647 | CP41: -99263019 | CQ41: -99263019 | CR41: -99263019 | CS41: -99449782 | CT41: -99533275 | CU41: -87318842 | CV41: =-87318842 -> -87318842 | CW41: -67562652 | CX41: -67658261 | CY41: -67759932 | CZ41: -67859932 | DA41: -69979229 | DB41: -70179229 | DC41: -70999128 | DD41: -70366496 | DE41: -70366496
A42: Current Year Surplus | B42: -130940764 | C42: -116486412 | D42: -116181177 | E42: -115950062 | F42: -955711.15 | G42: =-1402826.62-4731486.71 -> -6134313.3 | H42: =6650208-1311042-95000-4200000-6224355 -> -5180189 | I42: =-4913141-651967+9577031-1785013 -> 2226910 | J42: 47850246 | K42: 45789586 | L42: 48191825 | M42: 45716944 | N42: 45642436 | O42: 1.0959294e+08 | P42: 1.0655574e+08 | Q42: 94673557 | R42: 95635875 | S42: -177104.95 | T42: 291803.16 | U42: 352055.5 | V42: =3533017-637695-344540 -> 2550782 | W42: -1751482 | X42: -2020632 | Y42: -1667106 | Z42: -4580025.6 | AA42: -6974110 | AB42: 3984840 | AC42: 10245189 | AD42: 9397571 | AE42: 6864348 | AF42: 4675375 | AG42: 3537371.7 | AH42: 3275621.6 | AI42: -8272686 | AJ42: -1273664.9 | AK42: -2418322.6 | AL42: -4026833 | AM42: -6271929.5 | AN42: 4970410.1 | AO42: 4232213.1 | AP42: 9325556.5 | AQ42: 9476242.6 | AR42: 5457402.7 | AS42: 4304103.2 | AT42: 7770391.7 | AU42: 6088530.1 | AV42: =268110+893699-178740 -> 983069 | AW42: 256615.05 | AX42: 1772847.8 | AY42: 1644693.8 | AZ42: 753600.8 | BA42: 13088010 | BB42: 11716333 | BC42: 16625033 | BD42: 15559286 | BE42: 11035639 | BF42: 11261568 | BG42: 9536226.5 | BH42: 1989229.5 | BJ42: -202442.76 | BK42: -2757121.5 | BL42: -1572399.7 | BM42: -3013962.1 | BN42: -5392383.8 | BO42: -2776123.2 | BP42: 20653432 | BQ42: 19887512 | BR42: 17337132 | BS42: 15958595 | BT42: 12817639 | BU42: 10929458 | BW42: -1625892.4 | BX42: -7871405.1 | BY42: -9667210.7 | BZ42: -2310492.3 | CA42: -3658232.4 | CB42: 13277539 | CC42: 14305206 | CD42: 18238936 | CE42: 20559541 | CF42: 17036661 | CG42: 8514088.8 | CH42: 8514089 | CI42: -2723103.5 | CJ42: -6723743.5 | CK42: -8277081.9 | CL42: -1525729.3 | CM42: -5879876.9 | CN42: -10736905 | CO42: -13482934 | CP42: -21124000 | CQ42: -27727835 | CR42: 9850147.1 | CS42: 14713687 | CT42: 21811485 | CV42: =13710012-1919402-4113004+4921767+494802 -> 13094175 | CW42: -1363497.8 | CX42: -4306039.1 | CY42: -4890257.2 | CZ42: -7368355 | DA42: -12707884 | DB42: -2501231.4 | DC42: 34683084 | DD42: 32866118 | DE42: 25752856
...

Sheet Evolutitve SCI
BV1: "000"
B2: Audited 2007 | C2: Audited 2008 | D2: Audited 2009 | E2: Audited 2010 | F2: Audited 2011 | G2: Audited 2012 | H2: Audited 2013 | I2: Audited 2014 | J2: 42005 | K2: 42036 | L2: 42064 | M2: 42095 | N2: 42125 | O2: 42156 | P2: 42186 | Q2: 42217 | R2: 42248 | S2: 42278 | T2: 42309 | U2: 42339 | V2: Audited 2015 | W2: 42370 | X2: 42401 | Y2: 42430 | Z2: 42461 | AA2: 42491 | AB2: 42522 | AC2: 42552 | AD2: 42583 | AE2: 42614 | AF2: 42644 | AG2: 42675 | AH2: 42705 | AI2: Audited 2016 | AJ2: 42736 | AK2: 42767 | AL2: 42795 | AM2: 42826 | AN2: 42856 | AO2: 42887 | AP2: 42917 | AQ2: 42948 | AR2: 42979 | AS2: 43009 | AT2: 43040 | AU2: 43070 | AV2: AUDITED 2017 | AW2: 43101 | AX2: 43132 | AY2: 43160 | AZ2: 43191 | BA2: 43221 | BB2: 43252 | BC2: 43282 | BD2: 43313 | BE2: 43344 | BF2: 43374 | BG2: 43405 | BH2: 43435 | BI2: Audited 2018 | BJ2: 43466 | BK2: 43497 | BL2: 43525 | BM2: 43556 | BN2: 43586 | BO2: 43617 | BP2: 43647 | BQ2: 43678 | BR2: 43709 | BS2: 43739 | BT2: 43770 | BU2: 43800 | BV2: Audited 2019 | BW2: 43831 | BX2: 43862 | BY2: 43891 | BZ2: 43922 | CA2: 43952 | CB2: 43983 | CC2: 44044 | CD2: 44075 | CE2: 44105 | CF2: 44136 | CG2: 44166 | CH2: Audited 2020 | CI2: 44197 | CJ2: 44228 | CK2: 44256 | CL2: 44287 | CM2: 44317 | CN2: 44348 | CO2: 44378 | CP2: 44409 | CQ2: 44440 | CR2: 44470 | CS2: 44501 | CT2: 44531 | CU2: AUDITED 2021 | CV2: AUDITED 2022 | CW2: 44927 | CX2: 44958 | CY2: 44986 | CZ2: 45017 | DA2: 45047 | DB2: 45078 | DC2: 45108 | DD2: 45139 | DE2: 45170
A3: Financial Income | B3: =B4+B7 -> 13158687 | C3: =C4+C7 -> 11857416 | D3: =D4+D7 -> 15384310 | E3: =E4+E7 -> 15961562 | F3: =F4+F7 -> 11480294 | G3: =G4+G7 -> 8973589.6 | H3: =H4+H7 -> 22684355 | I3: =I4+I7 -> 20513783 | ... DE3: =DE4+DE7 -> 73275129
A4: Financial Income From Loans Portfolio | B4: =SUM(B5:B6) -> 11379426 | C4: =SUM(C5:C6) -> 11438776 | D4: =SUM(D5:D6) -> 13726979 | E4: =SUM(E5:E6) -> 9328665 | F4: =SUM(F5:F6) -> 6088928 | G4: =SUM(G5:G6) -> 2789845.9 | H4: =SUM(H5:H6) -> 12329678 | I4: =SUM(I5:I6) -> 18685473 | ... DE4: =SUM(DE5:DE6) -> 50915900
A5: Interest from Loans Portfolio | B5: 10152482 | C5: 10211832 | D5: 12399467 | E5: 9281285 | F5: 6040159 | G5: 2789845.9 | H5: 7897863 | I5: =17456381+2277287 -> 19733668 | J5: 1162807.6 | K5: 1216044.4 | L5: 1586685.7 | M5: 1711984.9 | N5: 1921596.9 | O5: 9601630.1 | P5: 9767452.4 | Q5: 9953574 | R5: 10138157 | S5: 10316477 | T5: 11347332 | U5: 12517818 | V5: 19575641 | W5: 649462.04 | X5: 2663614 | Y5: 1947234 | Z5: 2636333.9 | AA5: 3491603 | AB5: 14227993 | AC5: 16738052 | AD5: 18333463 | AE5: 19694355 | AF5: 20684019 | AG5: 22023584 | AH5: 26354999 | AI5: 26354999 | AJ5: 1210333.4 | AK5: 1998296.3 | AL5: 2653801.4 | AM5: 3930006.4 | AN5: 14840284 | AO5: 16274655 | AP5: 19234639 | AQ5: 21208747 | AR5: 18337606 | AS5: 18668439 | AT5: 19907077 | AU5: 20641122 | AV5: 20641122 | AW5: 1521953.9 | AX5: 2792545.5 | AY5: 4105261.5 | AZ5: 5683462.5 | BA5: 16508988 | BB5: 18350279 | BC5: 19604598 | BD5: 20262501 | BE5: 21089272 | BF5: 22786412 | BG5: 23785976 | BH5: 25234232 | BI5: 25234232 | BJ5: 2147516.7 | BK5: 2796959.3 | BL5: 4053433.1 | BM5: 5168948 | BN5: 6568291.8 | BO5: 7360664.3 | BP5: 24339366 | BQ5: 26791529 | BR5: 27459301 | BS5: 28478076 | BT5: 29740382 | BU5: 32292356 | BV5: 32292356 | BW5: 885005.09 | BX5: 2669645.9 | BY5: 4156606.2 | BZ5: 8922644.2 | CA5: 10198918 | CB5: 20458900 | CC5: 23151979 | CD5: 28027805 | CE5: 29207338 | CF5: 30722944 | CG5: 32014808 | CH5: 32014808 | CI5: 1290259.8 | CJ5: 3189198.6 | CK5: 4721226.8 | CL5: 6563958.4 | CM5: 7907017.2 | CN5: 8963019.7 | CO5: 9991014.4 | CP5: 11381188 | CQ5: 12440411 | CR5: 36404952 | CS5: 38936870 | CT5: 43172690 | CU5: 43172690 | CV5: =526780+3135093+1595106+25864+15413073+770044+5505486+190780+30383+739704+733782+10417+768033+161850+1238588+489138 -> 31334121 | CW5: 2100203.5 | CX5: 3624906.6 | CY5: 6165554.7 | CZ5: 9360454.8 | DA5: 12293423 | DB5: 15773278 | DC5: 37460627 | DD5: 39790891 | DE5: 41082932
A6: Fees&Commision on Loan Portfolio | B6: =1166114+60830 -> 1226944 | C6: 1226944 | D6: 1327512 | E6: 47380 | F6: 48769 | H6: 4431815 | I6: =28901-3205-147756-926135 -> -1048195 | J6: 144309.5 | K6: 294814.8 | L6: 527926.8 | M6: 712380.8 | N6: 828785.6 | O6: 3416219.1 | P6: 4346846.1 | Q6: 4898474.7 | R6: 5433783.7 | S6: 5814868.7 | T6: 8078754.3 | U6: 5492273.2 | W6: 333197 | X6: 0 | Y6: 551892 | Z6: 691823 | AA6: 844113 | AB6: 1325244 | AC6: 2607385.9 | AD6: 3291983 | AE6: 3632122 | AF6: 3843085 | AG6: 4045534.8 | AH6: 4251404.8 | AI6: =4251404 -> 4251404 | AJ6: 189534 | AK6: 302675 | AL6: 424125.2 | AM6: 550085.2 | AN6: 695375 | AO6: 1433389 | AP6: 2630467.3 | AQ6: 3014789.7 | AR6: 3252005.8 | AS6: 3416575.4 | AT6: 3745274.4 | AU6: 3827118.4 | AV6: 3133581 | AW6: 282321 | AX6: 223477 | AY6: 346383 | AZ6: 631819.3 | BA6: 806702.3 | BB6: 3128075.9 | BC6: 2733255.1 | BD6: 3607007.1 | BE6: 3918449.1 | BF6: 4158088.6 | BG6: 4563784.6 | BH6: 4822610.6 | BI6: 4795166 | BJ6: 349162 | BK6: 561314 | BL6: 952901 | BM6: 1103350.3 | BN6: 1268652.2 | BO6: 1419501 | BP6: 2768146.6 | BQ6: 4180596.4 | BR6: 4821724.5 | BS6: 5363610.4 | BT6: 5873725 | BU6: 6189275.8 | BW6: 299084.7 | BX6: 550611.6 | BY6: 759043.6 | BZ6: 869645.6 | CA6: 1331582.4 | CB6: 2015553 | CC6: 4418391.5 | CD6: 5203757.2 | CE6: 6046948.3 | CF6: 6666721 | CG6: 7074173.5 | CI6: 388419.8 | CJ6: 752916.9 | CK6: 1163475.4 | CL6: 1519211.8 | CM6: 1821745.2 | CN6: 2106217.7 | CO6: 3079633.2 | CP6: 3712954.6 | CQ6: 3943552.1 | CR6: 5078648 | CS6: 6671438.2 | CT6: 7315271.1 | CU6: 4810957 | CV6: 14946316 | CW6: 709445.5 | CX6: 1139994.8 | CY6: 1516157.1 | CZ6: 1998602 | DA6: 2913913.2 | DB6: 3321826.4 | DC6: 6130097.6 | DD6: 8808486.7 | DE6: 9832968.4
A7: Financial Income from Investments | B7: =SUM(B8:B11) -> 1779261 | C7: =SUM(C8:C11) -> 418640 | D7: =SUM(D8:D11) -> 1657331 | E7: =SUM(E8:E11) -> 6632897 | F7: =SUM(F8:F11) -> 5391365.8 | G7: =SUM(G8:G11) -> 6183743.7 | H7: =SUM(H8:H11) -> 10354677 | I7: =SUM(I8:I11) -> 1828310 | ... DE7: =SUM(DE8:DE11) -> 22359229
