Workbook
Name BALANCE1_LDA01: '[1]Financial Statements'!$E$112
Name BALANCE1_LDA12: '[1]Financial Statements'!$E$123
Name BALANCE2_LDA01: '[1]Financial Statements'!$F$112
Name BALANCE2_LDA12: '[1]Financial Statements'!$F$123
Name BALANCE3_LDA01: '[1]Financial Statements'!$G$112
Name BALANCE3_LDA12: '[1]Financial Statements'!$G$123
Name BALANCE4_LDA01: '[1]Financial Statements'!$H$112
Name BALANCE4_LDA12: '[1]Financial Statements'!$H$123
Name BALANCE5_LDA01: '[1]Financial Statements'!$I$112
Name BALANCE5_LDA12: '[1]Financial Statements'!$I$123
Name BALANCE6_LDA01: '[1]Financial Statements'!$J$112
Name BALANCE6_LDA12: '[1]Financial Statements'!$J$123
Name NotApplicable: 'Prudential Ratios'!#REF!
Name PEARLS1_LA002: '[1]Financial Statements'!$E$280
Name PEARLS1_LE008: '[1]Financial Statements'!$E$275
Name PEARLS1_LE009: '[1]Financial Statements'!$E$276
Name PEARLS1_LR001: '[1]Financial Statements'!$E$282
Name PEARLS1_LR005: '[1]Financial Statements'!$E$286
Name PEARLS1_LR006: '[1]Financial Statements'!$E$287
Name PEARLS1_LR007: '[1]Financial Statements'!$E$288
Name PEARLS1_LR009: '[1]Financial Statements'!$E$290
Name PEARLS1_LS001: '[1]Financial Statements'!$E$298
Name PEARLS1_LS005: '[1]Financial Statements'!$E$302
Name PEARLS1_LS011: '[1]Financial Statements'!$E$308
Name PEARLS2_LA002: '[1]Financial Statements'!$F$280
Name PEARLS2_LE008: '[1]Financial Statements'!$F$275
Name PEARLS2_LE009: '[1]Financial Statements'!$F$276
Name PEARLS2_LR001: '[1]Financial Statements'!$F$282
Name PEARLS2_LR005: '[1]Financial Statements'!$F$286
Name PEARLS2_LR006: '[1]Financial Statements'!$F$287
Name PEARLS2_LR007: '[1]Financial Statements'!$F$288
Name PEARLS2_LR009: '[1]Financial Statements'!$F$290
Name PEARLS2_LS001: '[1]Financial Statements'!$F$298
Name PEARLS2_LS005: '[1]Financial Statements'!$F$302
Name PEARLS2_LS010: '[1]Financial Statements'!$F$307
Name PEARLS2_LS011: '[1]Financial Statements'!$F$308
Name PEARLS3_LA002: '[1]Financial Statements'!$G$280
Name PEARLS3_LE008: '[1]Financial Statements'!$G$275
Name PEARLS3_LE009: '[1]Financial Statements'!$G$276
Name PEARLS3_LR001: '[1]Financial Statements'!$G$282
Name PEARLS3_LR005: '[1]Financial Statements'!$G$286
Name PEARLS3_LR006: '[1]Financial Statements'!$G$287
Name PEARLS3_LR007: '[1]Financial Statements'!$G$288
Name PEARLS3_LR009: '[1]Financial Statements'!$G$290
Name PEARLS3_LS001: '[1]Financial Statements'!$G$298
Name PEARLS3_LS005: '[1]Financial Statements'!$G$302
Name PEARLS3_LS010: '[1]Financial Statements'!$G$307
Name PEARLS3_LS011: '[1]Financial Statements'!$G$308
Name PEARLS4_LA002: '[1]Financial Statements'!$H$280
Name PEARLS4_LE008: '[1]Financial Statements'!$H$275
Name PEARLS4_LE009: '[1]Financial Statements'!$H$276
Name PEARLS4_LR001: '[1]Financial Statements'!$H$282
Name PEARLS4_LR005: '[1]Financial Statements'!$H$286
Name PEARLS4_LR006: '[1]Financial Statements'!$H$287
Name PEARLS4_LR007: '[1]Financial Statements'!$H$288
Name PEARLS4_LR009: '[1]Financial Statements'!$H$290
Name PEARLS4_LS001: '[1]Financial Statements'!$H$298
Name PEARLS4_LS005: '[1]Financial Statements'!$H$302
Name PEARLS4_LS010: '[1]Financial Statements'!$H$307
Name PEARLS4_LS011: '[1]Financial Statements'!$H$308

Sheet SFP
A1: MENTOR SACCO LTD | AA1: =W29+W36+W37 -> 3.2550511e+08
A2: STATEMENT OF FINANCIAL POSITION | T2: =G29+G37 -> 599293835
B3: 2011 AUDITED | C3: 2012 AUDITED | D3: 2013 AUDITED | E3: 2014 AUDITED | F3: Audited 2015 | G3: Audited 2016 | H3: 42736 | I3: 42767 | J3: 42795 | K3: 42826 | L3: 42856 | M3: 42887 | N3: 42917 | O3: 42948 | P3: 42979 | Q3: 43009 | R3: 43040 | S3: 43070 | T3: Audited 2017 | U3: 43101 | V3: 43132 | W3: 43160 | X3: 43191 | Y3: 43221 | Z3: 43252 | AA3: 43282 | AB3: 43313 | AC3: 43344 | AD3: 43374 | AE3: 43405 | AF3: 43435 | AG3: Audited 2018 | AH3: 43466 | AI3: 43497 | AJ3: 43525 | AK3: 43556 | AL3: 43586 | AM3: 43617 | AN3: 43647 | AO3: 43678 | AP3: 43709 | AQ3: 43739 | AR3: 43770 | AS3: 43800 | AT3: Audited-19 | AU3: 43831 | AV3: 43862 | AW3: 43891 | AX3: 43922 | AY3: 43952 | AZ3: 43983 | BA3: 44013 | BB3: 44044 | BC3: 44075 | BD3: 44105 | BE3: 44136 | BF3: 44166 | BG3: Audited-20 | BH3: 44197 | BI3: 44228 | BJ3: 44256 | BK3: 44287 | BL3: 44317 | BM3: 44348 | BN3: 44378 | BO3: 44409 | BP3: 44440 | BQ3: 44470 | BR3: 44501 | BS3: 44531 | BT3: Audited 2021 | BU3: 44562 | BV3: 44593 | BW3: 44621 | BX3: 44652 | BY3: 44682 | BZ3: 44713 | CA3: 44743 | CB3: 44774 | CC3: 44805 | CD3: 44835 | CE3: 44866 | CF3: 44896 | CG3: Audited 2022 | CH3: 44927 | CI3: 44958 | CJ3: 44986 | CK3: 45017 | CL3: 45047 | CM3: 45078 | CN3: 45108 | CO3: 45139 | CP3: 45170 | CQ3: 45200 | CR3: 45231 | CS3: 45261 | CT3: 45292
A4: Cash & Cash Equivalent | B4: =B5+B6 -> 283849000 | C4: =SUM(C5:C6) -> 110263000 | D4: =SUM(D5:D6) -> 201351000 | E4: =SUM(E5:E6) -> 182728629 | F4: =SUM(F5:F6) -> 214035021 | G4: =G5+G6 -> 258656183 | H4: =H5+H6 -> 2.6039096e+08 | I4: =I5+I6 -> 2.060013e+08 | J4: =J5+J6 -> 1.0801628e+08 | K4: =K5+K6 -> 14196015 | L4: =L5+L6 -> 1.0980475e+08 | M4: =M5+M6 -> 3.0429329e+08 | N4: =N5+N6 -> 1.7228961e+08 | ... CT4: =CT5+CT6 -> 0
A5: Cash in hand | B5: 11890000 | C5: 11448000 | D5: 9314000 | E5: 13696359 | F5: 14717887 | G5: 13984867 | H5: 35143309 | I5: 26264561 | J5: 44358499 | K5: 43330869 | L5: 49061791 | M5: 36316107 | N5: 22025163 | O5: 37004143 | P5: 70548604 | Q5: 58248806 | R5: 43484491 | S5: 48699124 | T5: 38502052 | U5: 94212113 | V5: 30945812 | W5: 46177858 | X5: 46531909 | Y5: 50359866 | Z5: 45193443 | AA5: 57753553 | AB5: 48345214 | AC5: 29655766 | AD5: 47543125 | AE5: 49112474 | AF5: 40714606 | AG5: 40714606 | AH5: 35588028 | AI5: 52941129 | AJ5: 51049723 | AK5: 40476884 | AL5: 44279602 | AM5: 48540718 | AN5: 70466476 | AO5: 37316349 | AP5: 41215416 | AQ5: 43392514 | AR5: 31611042 | AS5: 36928070 | AT5: 37108170 | AU5: 70501994 | AV5: 68837451 | AW5: 56149989 | AX5: 90734149 | AY5: 54762587 | AZ5: 50711831 | BA5: 75916162 | BB5: 77209066 | BC5: 64098527 | BD5: 89383375 | BE5: 69358932 | BF5: 95087912 | BG5: 95087912 | BH5: 93608224 | BI5: 96070443 | BJ5: 65165218 | BK5: 85967749 | BL5: 1.0035976e+08 | BM5: 69289471 | BN5: 59743888 | BO5: 54801305 | BP5: 72432908 | BQ5: 76585214 | BR5: 61423807 | BS5: 71614010 | BT5: 71614010 | BU5: 55238333 | BV5: 90694612 | BW5: 61292454 | BX5: 87027470 | BY5: 59032999 | BZ5: 44678209 | CA5: 88328946 | CB5: 97253998 | CC5: 1.0376684e+08 | CD5: 88603868 | CE5: 76011280 | CF5: 1.113003e+08 | CG5: 112430117 | CH5: 54774550 | CI5: 88163721 | CJ5: 1.2730836e+08 | CK5: 77437439 | CL5: 90238416 | CM5: 96989477 | CN5: 88377095 | CO5: 1.2804257e+08 | CP5: 68546524
A6: Cash at bank | B6: 271959000 | C6: =81972000+16843000 -> 98815000 | D6: 192037000 | E6: =50323695+118708575 -> 169032270 | F6: =118899613+80417521 -> 199317134 | G6: =181414760+63256556 -> 244671316 | H6: 2.2524765e+08 | I6: 1.7973674e+08 | J6: 63657780 | K6: -29134854 | L6: 60742963 | M6: 2.6797718e+08 | N6: 1.5026445e+08 | O6: 33321793 | P6: 18074529 | Q6: 2.3037456e+08 | R6: 65179884 | S6: 1.1396201e+08 | T6: 113944466 | U6: 2.3320839e+08 | V6: -12960349 | W6: 84919556 | X6: 11688599 | Y6: 84426721 | Z6: 1.6266697e+08 | AA6: 1.0140057e+08 | AB6: 1.3019334e+08 | AC6: 2.0525131e+08 | AD6: 1.8390621e+08 | AE6: 1.8911156e+08 | AF6: 1.8714287e+08 | AG6: =123605753+63313356 -> 186919109 | AH6: 3.0978772e+08 | AI6: 3.3048856e+08 | AJ6: 3.571304e+08 | AK6: 2.8681085e+08 | AL6: 5.1439929e+08 | AM6: 4.661812e+08 | AN6: 4.8131121e+08 | AO6: 6.400575e+08 | AP6: 5.4370434e+08 | AQ6: 6.4545303e+08 | AR6: 7.477479e+08 | AS6: 7.617262e+08 | AT6: 761724576 | AU6: 6.6865175e+08 | AV6: 6.5355856e+08 | AW6: 6.6563703e+08 | AX6: 8.6558653e+08 | AY6: 1.0239525e+09 | AZ6: 1.2556211e+09 | BA6: 1.1563399e+09 | BB6: 1.0488559e+09 | BC6: 1.1679097e+09 | BD6: 1.0894321e+09 | BE6: 1.3235119e+09 | BF6: 1.1854314e+09 | BG6: 1185431357 | BH6: 1.2367631e+09 | BI6: 1.2306368e+09 | BJ6: 1.2815229e+09 | BK6: 1.469488e+09 | BL6: 1.3336836e+09 | BM6: 1.5895219e+09 | BN6: 1.7176034e+09 | BO6: 1.7815225e+09 | BP6: 2.1146008e+09 | BQ6: 1.9174287e+09 | BR6: 1.9671777e+09 | BS6: 2.1530978e+09 | BT6: =2224711816-BT5 -> 2153097806 | BU6: 1.8403474e+09 | BV6: 1.7386821e+09 | BW6: 1.601886e+09 | BX6: 1.5075133e+09 | BY6: 1.6229175e+09 | BZ6: 1.941945e+09 | CA6: 1.8145568e+09 | CB6: 1.8295875e+09 | CC6: 1.7623086e+09 | CD6: 1.8287338e+09 | CE6: 1.9705585e+09 | CF6: 1.9200011e+09 | CG6: =2033555086-CG5 -> 1921124969 | CH6: 1.6143013e+09 | CI6: 1.5189528e+09 | CJ6: 1.386027e+09 | CK6: 1.4970817e+09 | CL6: 1.6593924e+09 | CM6: 2.055872e+09 | CN6: 2.132503e+09 | CO6: 2.0724994e+09 | CP6: 2.1520789e+09
A7: Prepayments & Sundry Receivables | B7: 80742000 | C7: 157802000 | D7: 3.5042493e+08 | E7: 270176551 | F7: 229086382 | G7: 214520369 | H7: 1.3999113e+08 | I7: 1.2352411e+08 | J7: 2.0780945e+08 | K7: 2.2550666e+08 | L7: 1.0702057e+08 | M7: 1.2099601e+08 | N7: 2.1594307e+08 | O7: 2.0080532e+08 | P7: 2.3879896e+08 | Q7: 1.2496983e+08 | R7: 2.4157564e+08 | S7: 1.4594799e+08 | T7: 145940535 | U7: 3.1776137e+08 | V7: 2.4301911e+08 | W7: 1.2430703e+08 | X7: 1.2035957e+08 | Y7: 1.100997e+08 | Z7: 1.1677677e+08 | AA7: 2.6216769e+08 | AB7: 1.3144614e+08 | AC7: 1.2748276e+08 | AD7: 2.4566809e+08 | AE7: 2.7592658e+08 | AF7: 3.2413739e+08 | AG7: 326646200 | AH7: 3.3360807e+08 | AI7: 3.0189081e+08 | AJ7: 3.2094147e+08 | AK7: 3.1127279e+08 | AL7: 1.6231158e+08 | AM7: 3.2488625e+08 | AN7: 4.5861151e+08 | AO7: 1.8689115e+08 | AP7: 3.1194967e+08 | AQ7: 3.3452979e+08 | AR7: 2.3369236e+08 | AS7: 1.5679987e+08 | AT7: 221973821 | AU7: 3.4666681e+08 | AV7: 3.5994937e+08 | AW7: 3.6822632e+08 | AX7: 3.7530246e+08 | AY7: 3.9533228e+08 | AZ7: 2.2811918e+08 | BA7: 4.1405969e+08 | BB7: 4.2390266e+08 | BC7: 3.0089762e+08 | BD7: 4.0214201e+08 | BE7: 2.2784826e+08 | BF7: 4.2399877e+08 | BG7: 487149053 | BH7: 4.6123653e+08 | BI7: 4.4312419e+08 | BJ7: 4.5791043e+08 | BK7: 2.4266969e+08 | BL7: 4.6482451e+08 | BM7: 2.5875842e+08 | BN7: 4.2831425e+08 | BO7: 4.1459534e+08 | BP7: 2.0747715e+08 | BQ7: 4.0680765e+08 | BR7: 4.0746645e+08 | BS7: 1.8478803e+08 | BT7: 187408031 | BU7: 3.7861221e+08 | BV7: 4.3621138e+08 | BW7: 4.1575786e+08 | BX7: 4.2732627e+08 | BY7: 4.693709e+08 | BZ7: 2.3024234e+08 | CA7: 4.6829452e+08 | CB7: 466614669 | CC7: 4.8606502e+08 | CD7: 5.1795276e+08 | CE7: 5.0409518e+08 | CF7: 4.8257375e+08 | CG7: 400156900 | CH7: 5.1287388e+08 | CI7: 5.5253662e+08 | CJ7: 6.2877602e+08 | CK7: 5.9459769e+08 | CL7: 5.3517112e+08 | CM7: 3.8535251e+08 | CN7: 5.6484034e+08 | CO7: 6.4019452e+08 | CP7: 5.859976e+08
A8: Financial Investments | B8: =SUM(B9:B12) -> 140316000 | C8: =SUM(C9:C12) -> 136004000 | D8: =SUM(D9:D12) -> 269992000 | E8: =SUM(E9:E12) -> 267823506 | F8: =SUM(F9:F12) -> 249273506 | G8: 232172149 | H8: =SUM(H9:H12) -> 2.2073579e+08 | I8: =SUM(I9:I12) -> 193214051 | J8: =SUM(J9:J12) -> 193214051 | K8: =SUM(K9:K12) -> 193214051 | L8: =SUM(L9:L12) -> 194114051 | M8: =SUM(M9:M12) -> 194114051 | N8: =SUM(N9:N12) -> 194114051 | O8: =SUM(O9:O12) -> 194514051 | ... CT8: =SUM(CT9:CT12) -> 0
A9: Government Securities - Treasury Bills/bonds, | B9: 0 | H9: 0 | I9: 0 | J9: 0 | L9: 0 | M9: 0 | N9: 0 | O9: 0 | P9: 0 | Q9: 0 | R9: 0 | S9: 0 | T9: 0 | U9: 0 | V9: 0 | W9: 0 | X9: 0 | Y9: 0 | Z9: 0 | AA9: 0 | AB9: 0 | AC9: 0 | AD9: 0 | AE9: 0 | AF9: 0 | AG9: 0 | AH9: 0 | AI9: 0 | AJ9: 0 | AK9: 0 | AL9: 0 | AM9: 0 | AN9: 0 | AO9: 0 | AP9: 0 | AQ9: 0 | AR9: 0 | AS9: 0 | AT9: 0 | AU9: 0 | AV9: 0 | AW9: 0 | AX9: 0 | AY9: 0 | AZ9: 0 | BA9: 0 | BB9: 0 | BC9: 0 | BD9: 0 | BE9: 0 | BF9: 0 | BG9: 0 | BH9: 0 | BI9: 0 | BJ9: 0 | BK9: 0 | BL9: 0 | BM9: 0 | BN9: 0 | BO9: 0 | BP9: 0 | BQ9: 0 | BR9: 0 | BS9: 0 | BU9: 0 | BV9: 0 | BW9: 0 | BX9: 0 | BY9: 0 | BZ9: 0 | CA9: 0 | CB9: 0 | CC9: 0 | CD9: 0 | CE9: 0 | CF9: 0 | CH9: 0 | CI9: 0 | CJ9: 0 | CK9: 0 | CL9: 0 | CM9: 0 | CN9: 0 | CO9: 0 | CP9: 0
A10: Other Securities - Commercial papers/Bonds | B10: 140316000 | H10: 0 | I10: 0 | J10: 0 | L10: 0 | M10: 0 | N10: 0 | O10: 0 | P10: 0 | Q10: 0 | R10: 0 | S10: 0 | T10: 0 | U10: 0 | V10: 0 | W10: 0 | X10: 0 | Y10: 0 | Z10: 0 | AA10: 0 | AB10: 0 | AC10: 0 | AD10: 0 | AE10: 0 | AF10: 0 | AG10: 0 | AH10: 0 | AI10: 0 | AJ10: 0 | AK10: 0 | AL10: 0 | AM10: 0 | AN10: 0 | AO10: 0 | AP10: 0 | AQ10: 0 | AR10: 0 | AS10: 0 | AT10: 0 | AU10: 0 | AV10: 0 | AW10: 0 | AX10: 0 | AY10: 0 | AZ10: 0 | BA10: 0 | BB10: 0 | BC10: 0 | BD10: 0 | BE10: 0 | BF10: 0 | BG10: 0 | BH10: 0 | BI10: 0 | BJ10: 0 | BK10: 0 | BL10: 0 | BM10: 0 | BN10: 0 | BO10: 0 | BP10: 0 | BQ10: 0 | BR10: 0 | BS10: 0 | BU10: 0 | BV10: 0 | BW10: 0 | BX10: 0 | BY10: 0 | BZ10: 0 | CA10: 0 | CB10: 0 | CC10: 0 | CD10: 0 | CE10: 0 | CF10: 0 | CH10: 0 | CI10: 0 | CJ10: 0 | CK10: 0 | CL10: 0 | CM10: 0 | CN10: 0 | CO10: 0 | CP10: 0
A11: Balances with other SACCO Societies | B11: 0 | H11: 0 | I11: 0 | J11: 0 | L11: 0 | M11: 0 | N11: 0 | O11: 0 | P11: 0 | Q11: 0 | R11: 0 | S11: 0 | T11: 0 | U11: 0 | V11: 0 | W11: 0 | X11: 0 | Y11: 0 | Z11: 0 | AA11: 0 | AB11: 0 | AC11: 0 | AD11: 0 | AE11: 0 | AF11: 0 | AG11: 5050000 | AH11: 0 | AI11: 0 | AJ11: 0 | AK11: 0 | AL11: 0 | AM11: 0 | AN11: 0 | AO11: 0 | AP11: 0 | AQ11: 0 | AR11: 0 | AS11: 0 | AT11: =15748623 -> 15748623 | AU11: 0 | AV11: 0 | AW11: 0 | AX11: 0 | AY11: 0 | AZ11: 0 | BA11: 0 | BB11: 0 | BC11: 0 | BD11: 0 | BE11: 0 | BF11: 0 | BG11: =149997404+10000000+2101780 -> 162099184 | BH11: 0 | BI11: 0 | BJ11: 0 | BK11: 0 | BL11: 0 | BM11: 0 | BN11: 0 | BO11: 0 | BP11: 0 | BQ11: 0 | BR11: 0 | BS11: 0 | BT11: =255575965+12805000+2101780 -> 270482745 | BU11: 17883954 | BV11: 17883954 | BW11: 17883954 | BX11: 17883954 | BY11: 17883954 | BZ11: 17883954 | CA11: 17883954 | CB11: 17883954 | CC11: 17883954 | CD11: 17883954 | CE11: 17883954 | CF11: 17883954 | CG11: =197057330-CG12 -> 178120686 | CH11: 178425686 | CI11: 178725686 | CJ11: 179035686 | CK11: 179335686 | CL11: 179645686 | CM11: 179950686 | CN11: 180255686 | CO11: 180560686 | CP11: 180965686
A12: Investments in companies - shares/stocks | B12: 0 | C12: =132292000+143968000-140256000 -> 136004000 | D12: =184621000+18684000+5881000+2491000+21000+50000+300000+57944000 -> 269992000 | E12: 267823506 | F12: 249273506 | H12: 2.2073579e+08 | I12: 193214051 | J12: 193214051 | K12: 193214051 | L12: 194114051 | M12: 194114051 | N12: 194114051 | O12: 194514051 | P12: 194514051 | Q12: 194614051 | R12: 195114051 | S12: 195614051 | T12: 212113083 | U12: 391228102 | V12: 236613083 | W12: 236713083 | X12: 238990740 | Y12: 239090740 | Z12: 239190740 | AA12: 239290740 | AB12: 239290740 | AC12: 215690740 | AD12: 215790740 | AE12: 215890740 | AF12: 215990740 | AG12: 189994836 | AH12: 216688611 | AI12: 195942707 | AJ12: 196142707 | AK12: 196842707 | AL12: 197042707 | AM12: 197242707 | AN12: 197442707 | AO12: 197642707 | AP12: 197842707 | AQ12: 1.9814346e+08 | AR12: 1.9834346e+08 | AS12: 1.9854346e+08 | AT12: 201602738 | AU12: 1.9874346e+08 | AV12: 217667338 | AW12: 218267309 | AX12: 218467309 | AY12: 218667309 | AZ12: 218867309 | BA12: 219067309 | BB12: 219267309 | BC12: 219467309 | BD12: 219667309 | BE12: 220767309 | BF12: 221917309 | BG12: =206000+10651836 -> 10857836 | BH12: 172414104 | BI12: 172614104 | BJ12: 174383138 | BK12: 1.7458314e+08 | BL12: 1.7578314e+08 | BM12: 1.7598314e+08 | BN12: 1.7648314e+08 | BO12: 1.7698314e+08 | BP12: 1.7748314e+08 | BQ12: 1.7798314e+08 | BR12: 1.7848314e+08 | BS12: 1.7898814e+08 | BT12: 14083954 | BU12: 173149342 | BV12: 173454342 | BW12: 1.7376434e+08 | BX12: 174069342 | BY12: 174374342 | BZ12: 174679342 | CA12: 174984342 | CB12: 175289342 | CC12: 180950462 | CD12: 181255462 | CE12: 181560462 | CF12: 181865462 | CG12: 18936644 | CH12: 17883954 | CI12: 18936644 | CJ12: 18936644 | CK12: 24148066 | CL12: 24148066 | CM12: 24148066 | CN12: 24148066 | CO12: 24148066 | CP12: 24148066
A13: Net Loan Portfolio | B13: =B14-B15 -> 1447463000 | C13: =C14-C15 -> 1669487000 | D13: =D14-D15 -> 1976393000 | E13: =E14-E15 -> 2511315580 | F13: =F14-F15 -> 3150143542 | G13: =G14-G15 -> 4068599457 | H13: =H14-H15 -> 4.0453554e+09 | I13: =I14-I15 -> 4.060404e+09 | ... CT13: =CT14-CT15 -> 0
A14: Gross Loan Portfolio | B14: 1458954000 | C14: =1379419000+307755000 -> 1687174000 | D14: 1994080000 | E14: =2018922702+520080194 -> 2539002896 | F14: =2549758075+633072783 -> 3182830858 | G14: =3211069464+905029993 -> 4116099457 | H14: 4.0900427e+09 | I14: 4.115904e+09 | J14: 4.1189591e+09 | K14: 4187669091 | L14: 4.2389847e+09 | M14: 4.3553488e+09 | N14: 4.4689274e+09 | O14: 4.777266e+09 | P14: 4.8561686e+09 | Q14: 4.9767383e+09 | R14: 5.1654906e+09 | S14: 5.2846032e+09 | T14: 5284603210 | U14: 1.0616962e+10 | V14: 5.2867716e+09 | W14: 5.2813699e+09 | X14: 5.3863046e+09 | Y14: 5.3928834e+09 | Z14: 5.434176e+09 | AA14: 5.4835737e+09 | AB14: 5.7088185e+09 | AC14: 5.691086e+09 | AD14: 5.6936377e+09 | AE14: 5.7803049e+09 | AF14: 5.842582e+09 | AG14: 5.842582e+09 | AH14: 5.8312835e+09 | AI14: 5.7329808e+09 | AJ14: 5.7233535e+09 | AK14: 5.7738519e+09 | AL14: 5.7585449e+09 | AM14: 5.7748863e+09 | AN14: 5.7717548e+09 | AO14: 5.9352799e+09 | AP14: 5961879039 | AQ14: 5.9394012e+09 | AR14: 6.0948893e+09 | AS14: 6.3019321e+09 | AT14: 6239183746 | AU14: 6.2786665e+09 | AV14: 6.137941e+09 | AW14: 6.0968277e+09 | AX14: 6.0144043e+09 | AY14: 5.9504236e+09 | AZ14: 5.9946589e+09 | BA14: 6.0457836e+09 | BB14: 6.2984433e+09 | BC14: 6.4145722e+09 | BD14: 6.4977427e+09 | BE14: 6.5444039e+09 | BF14: 6.6411301e+09 | BG14: 6580599847 | BH14: 6.5020714e+09 | BI14: 6.4381125e+09 | BJ14: 6.4655145e+09 | BK14: 6.5669295e+09 | BL14: 6.6021417e+09 | BM14: 6.6720977e+09 | BN14: 6.7332468e+09 | BO14: 6.7508116e+09 | BP14: 6.8050678e+09 | BQ14: 7.0037444e+09 | BR14: 7.1347103e+09 | BS14: 7.3453139e+09 | BT14: 7345313859 | BU14: 7.2706676e+09 | BV14: 7.3079378e+09 | BW14: 7.5720804e+09 | BX14: 7.6981923e+09 | BY14: 7.7928833e+09 | BZ14: 7.8931031e+09 | CA14: 8.0072904e+09 | CB14: 8.1210119e+09 | CC14: 8.2589067e+09 | CD14: 8.3630602e+09 | CE14: 8.4539099e+09 | CF14: 8.6716295e+09 | CG14: 8683011938 | CH14: 8.6818253e+09 | CI14: 8.6896773e+09 | CJ14: 8.7666961e+09 | CK14: 8.8853504e+09 | CL14: 8.9216015e+09 | CM14: 9.0415623e+09 | CN14: 9.1130199e+09 | CO14: 9.2999382e+09 | CP14: 9.4379687e+09
A15: Allowance for Loan Loss | B15: 11491000 | C15: 17687000 | D15: 17687000 | E15: 27687316 | F15: 32687316 | G15: 47500000 | H15: 44687316 | I15: 55500000 | J15: 59500000 | K15: 63500000 | L15: 67500000 | M15: 71500000 | N15: 75500000 | O15: 79500000 | P15: 83500000 | Q15: 87500000 | R15: 91500000 | S15: 95500000 | T15: 95500000 | U15: 191000000 | V15: 105500000 | W15: 110500000 | X15: 115500000 | Y15: 120500000 | Z15: 125500000 | AA15: 130500000 | AB15: 135500000 | AC15: 140500000 | AD15: 145500000 | AE15: 150500000 | AF15: 155500000 | AG15: 155500000 | AH15: 164500000 | AI15: 173500000 | AJ15: 182500000 | AK15: 191500000 | AL15: 200500000 | AM15: 209500000 | AN15: 218500000 | AO15: 227500000 | AP15: 236500000 | AQ15: 245500000 | AR15: 254500000 | AS15: 263500000 | AT15: 267784035 | AU15: 272500000 | AV15: 281500000 | AW15: 292894330 | AX15: 302692440 | AY15: 312490550 | AZ15: 322288660 | BA15: 332086770 | BB15: 341884880 | BC15: 351682990 | BD15: 361481100 | BE15: 371279210 | BF15: 385361355 | BG15: 339861355 | BH15: 349861355 | BI15: 353261355 | BJ15: 359961355 | BK15: 366661355 | BL15: 373361355 | BM15: 380061355 | BN15: 386761355 | BO15: 393461355 | BP15: 400161355 | BQ15: 406861355 | BR15: 413561355 | BS15: 420261355 | BT15: 370261355 | BU15: 377765355 | BV15: 385269355 | BW15: 392773355 | BX15: 400277355 | BY15: 407781355 | BZ15: 415285355 | CA15: 422789355 | CB15: 430293355 | CC15: 437797355 | CD15: 437797355 | CE15: 437797355 | CF15: 437797355 | CG15: 407797355 | CH15: 411797355 | CI15: 413797355 | CJ15: 416797355 | CK15: 419797355 | CL15: 422797355 | CM15: 425797355 | CN15: 428797355 | CO15: 431797355 | CP15: 434797355
A16: Accounts Receivables | B16: =SUM(B17:B19) -> 0 | C16: =SUM(C17:C19) -> 0 | D16: =SUM(D17:D19) -> 0 | E16: =SUM(E17:E19) -> 0 | F16: =SUM(F17:F19) -> 0 | G16: =SUM(G17:G19) -> 0 | H16: =SUM(H17:H19) -> 0 | I16: =SUM(I17:I19) -> 0 | K16: 0 | L16: 0 | M16: 0 | N16: 0 | O16: 0 | P16: 0 | Q16: 0 | R16: 0 | S16: 0 | T16: 0 | U16: 0 | V16: 0 | W16: 0 | X16: 0 | Y16: 0 | Z16: 0 | AA16: 0 | AB16: 0 | AC16: 0 | AD16: 0 | AE16: 0 | AF16: 0 | AG16: 0 | AH16: 0 | AI16: 0 | AJ16: 0 | AK16: 0 | AL16: 0 | AM16: 0 | AN16: 0 | AO16: 0 | AP16: 0 | AQ16: 0 | AR16: 0 | AS16: 0 | AT16: 0 | AU16: 0 | AV16: 0 | AW16: 0 | AX16: 0 | AY16: 0 | AZ16: 0 | BA16: 0 | BB16: 0 | BC16: 0 | BD16: 0 | BE16: 0 | BF16: 0 | BG16: 0 | BH16: 0 | BI16: 0 | BJ16: 0 | BK16: 0 | BL16: 0 | BM16: 0 | BN16: 0 | BO16: 0 | BP16: 0 | BQ16: 0 | BR16: 0 | BS16: 0 | BT16: 0 | BU16: 0 | BV16: 0 | BW16: 0 | BX16: 0 | BY16: 0 | BZ16: 0 | CA16: 0 | CB16: 0 | CC16: 0 | CD16: 0 | CE16: 0 | CF16: 0 | CG16: 0 | CH16: 0 | CI16: 0 | CJ16: 0 | CK16: 0 | CL16: 0 | CM16: 0 | CN16: 0 | CO16: 0 | CP16: 0 | CQ16: 0 | CR16: 0 | CS16: 0 | CT16: 0 | CU16: 0
A17: Tax Recoverable | B17: 0 | H17: 0 | I17: 0 | J17: 0 | K17: 0 | L17: 0 | M17: 0 | N17: 0 | O17: 0 | P17: 0 | Q17: 0 | R17: 0 | S17: 0 | T17: 0 | U17: 0 | V17: 0 | W17: 0 | X17: 0 | Y17: 0 | Z17: 0 | AA17: 0 | AB17: 0 | AC17: 0 | AD17: 0 | AE17: 0 | AF17: 0 | AG17: 0 | AH17: 0 | AI17: 0 | AJ17: 0 | AK17: 0 | AL17: 0 | AM17: 0 | AN17: 0 | AO17: 0 | AP17: 0 | AQ17: 0 | AR17: 0 | AS17: 0 | AT17: 0 | AU17: 0 | AV17: 0 | AW17: 0 | AX17: 0 | AY17: 0 | AZ17: 0 | BA17: 0 | BB17: 0 | BC17: 0 | BD17: 0 | BE17: 0 | BF17: 0 | BG17: 0 | BH17: 0 | BI17: 0 | BJ17: 0 | BK17: 0 | BL17: 0 | BM17: 0 | BN17: 0 | BO17: 0 | BP17: 0 | BQ17: 0 | BR17: 0 | BS17: 0 | BU17: 0 | BV17: 0 | BW17: 0 | BX17: 0 | BY17: 0 | BZ17: 0 | CA17: 0 | CB17: 0 | CC17: 0 | CD17: 0 | CE17: 0 | CF17: 0 | CH17: 0 | CI17: 0 | CJ17: 0 | CK17: 0 | CL17: 0 | CM17: 0 | CN17: 0 | CO17: 0 | CP17: 0
A18: Deferred Tax Assets | B18: 0 | H18: 0 | I18: 0 | J18: 0 | K18: 0 | L18: 0 | M18: 0 | N18: 0 | O18: 0 | P18: 0 | Q18: 0 | R18: 0 | S18: 0 | T18: 0 | U18: 0 | V18: 0 | W18: 0 | X18: 0 | Y18: 0 | Z18: 0 | AA18: 0 | AB18: 0 | AC18: 0 | AD18: 0 | AE18: 0 | AF18: 0 | AG18: 0 | AH18: 0 | AI18: 0 | AJ18: 0 | AK18: 0 | AL18: 0 | AM18: 0 | AN18: 0 | AO18: 0 | AP18: 0 | AQ18: 0 | AR18: 0 | AS18: 0 | AT18: 0 | AU18: 0 | AV18: 0 | AW18: 0 | AX18: 0 | AY18: 0 | AZ18: 0 | BA18: 0 | BB18: 0 | BC18: 0 | BD18: 0 | BE18: 0 | BF18: 0 | BG18: 0 | BH18: 0 | BI18: 0 | BJ18: 0 | BK18: 0 | BL18: 0 | BM18: 0 | BN18: 0 | BO18: 0 | BP18: 0 | BQ18: 0 | BR18: 0 | BS18: 0 | BU18: 0 | BV18: 0 | BW18: 0 | BX18: 0 | BY18: 0 | BZ18: 0 | CA18: 0 | CB18: 0 | CC18: 0 | CD18: 0 | CE18: 0 | CF18: 0 | CH18: 0 | CI18: 0 | CJ18: 0 | CK18: 0 | CL18: 0 | CM18: 0 | CN18: 0 | CO18: 0 | CP18: 0
A19: Retirement Benefit Assets | B19: 0 | H19: 0 | I19: 0 | J19: 0 | K19: 0 | L19: 0 | M19: 0 | N19: 0 | O19: 0 | P19: 0 | Q19: 0 | R19: 0 | S19: 0 | T19: 0 | U19: 0 | V19: 0 | W19: 0 | X19: 0 | Y19: 0 | Z19: 0 | AA19: 0 | AB19: 0 | AC19: 0 | AD19: 0 | AE19: 0 | AF19: 0 | AG19: 0 | AH19: 0 | AI19: 0 | AJ19: 0 | AK19: 0 | AL19: 0 | AM19: 0 | AN19: 0 | AO19: 0 | AP19: 0 | AQ19: 0 | AR19: 0 | AS19: 0 | AT19: 0 | AU19: 0 | AV19: 0 | AW19: 0 | AX19: 0 | AY19: 0 | AZ19: 0 | BA19: 0 | BB19: 0 | BC19: 0 | BD19: 0 | BE19: 0 | BF19: 0 | BG19: 0 | BH19: 0 | BI19: 0 | BJ19: 0 | BK19: 0 | BL19: 0 | BM19: 0 | BN19: 0 | BO19: 0 | BP19: 0 | BQ19: 0 | BR19: 0 | BS19: 0 | BU19: 0 | BV19: 0 | BW19: 0 | BX19: 0 | BY19: 0 | BZ19: 0 | CA19: 0 | CB19: 0 | CC19: 0 | CD19: 0 | CE19: 0 | CF19: 0 | CH19: 0 | CI19: 0 | CJ19: 0 | CK19: 0 | CL19: 0 | CM19: 0 | CN19: 0 | CO19: 0 | CP19: 0
A20: Property & Equipment & Other assets | B20: =SUM(B21:B25) -> 30561000 | C20: =SUM(C21:C25) -> 172627000 | D20: =SUM(D21:D25) -> 36204000 | E20: =SUM(E21:E25) -> 51908954 | F20: =SUM(F21:F25) -> 83695847 | G20: =SUM(G21:G25) -> 103160569 | H20: =SUM(H21:H25) -> 2.8750153e+08 | I20: =SUM(I21:I25) -> 2.83721e+08 | ... CU20: =SUM(CU21:CU25) -> 0
A21: Investment Properties | B21: 0 | C21: 140256000 | H21: 0 | I21: 0 | J21: 0 | L21: 0 | M21: 0 | N21: 0 | O21: 0 | P21: 0 | Q21: 0 | R21: 0 | S21: 0 | T21: 0 | U21: 0 | V21: 0 | W21: 4.9494235e+08 | X21: 4.9494235e+08 | Y21: 5.2679428e+08 | Z21: 5.3538136e+08 | AA21: 5.3539136e+08 | AB21: 5.3731034e+08 | AC21: 5.7373003e+08 | AD21: 5.7720249e+08 | AE21: 5.8117958e+08 | AF21: 6.3502798e+08 | AG21: 6.3502798e+08 | AH21: 6.3765069e+08 | AI21: 6.4408747e+08 | AJ21: 6.4463607e+08 | AK21: 6.4463607e+08 | AL21: 6.4463607e+08 | AM21: 6.4740434e+08 | AN21: 6.4748996e+08 | AO21: 6.4748996e+08 | AP21: 6.4748996e+08 | AQ21: 6.4748996e+08 | AR21: 6.4748996e+08 | AS21: 6.4748996e+08 | AT21: 635027979 | AU21: 6.4748996e+08 | AV21: 6.4805496e+08 | AW21: 6.4805496e+08 | AX21: 6.4805496e+08 | AY21: 6.4805496e+08 | AZ21: 6.4805496e+08 | BA21: 6.3559298e+08 | BB21: 6.3559298e+08 | BC21: 6.3559298e+08 | BD21: 6.3609298e+08 | BE21: 6.4141385e+08 | BF21: 6.4353054e+08 | BG21: 641578411 | BH21: 6.4157841e+08 | BI21: 6.4157841e+08 | BJ21: 6.4157841e+08 | BK21: 6.4157841e+08 | BL21: 6.4157841e+08 | BM21: 6.4903683e+08 | BN21: 6.4955616e+08 | BO21: 6.4955616e+08 | BP21: 6.4955616e+08 | BQ21: 6.4955616e+08 | BR21: 6.4955616e+08 | BS21: 6.4955616e+08 | BT21: 649556155 | BU21: 6.4955616e+08 | BV21: 6.4955616e+08 | BW21: 6.4955616e+08 | BX21: 6.4955616e+08 | BY21: 6.4955616e+08 | BZ21: 6.4955616e+08 | CA21: 6.4955616e+08 | CB21: 6.5491228e+08 | CC21: 6.4955616e+08 | CD21: 6.4955616e+08 | CE21: 6.4955616e+08 | CF21: 6.4955616e+08 | CG21: 734528001 | CH21: 6.4955616e+08 | CI21: 6.4955616e+08 | CJ21: 6.4955616e+08 | CK21: 6.4955616e+08 | CL21: 6.4955616e+08 | CM21: 6.4955616e+08 | CN21: 6.4955616e+08 | CO21: 6.4955616e+08 | CP21: 6.4955616e+08
A22: Property & Equipment | B22: 30561000 | C22: 32371000 | D22: 36204000 | E22: 51908954 | F22: 69245464 | G22: 103160569 | H22: 2.8750153e+08 | I22: 2.5621178e+08 | J22: 2.836322e+08 | K22: 3.0235245e+08 | L22: 3.2550446e+08 | M22: 3.6390347e+08 | N22: 3.9684084e+08 | O22: 4.3942418e+08 | P22: 4.6937879e+08 | Q22: 5.2098278e+08 | R22: 5.2715923e+08 | S22: 5.524183e+08 | T22: 551045563 | U22: 1.177155e+09 | V22: 5.9187039e+08 | W22: 97838612 | X22: 97823012 | Y22: 97823012 | Z22: 98614052 | AA22: 1.0142069e+08 | AB22: 99101594 | AC22: 1.0062143e+08 | AD22: 1.0083453e+08 | AE22: 1.0078453e+08 | AF22: 1.0048976e+08 | AG22: 74914831 | AH22: 1.0677359e+08 | AI22: 75120154 | AJ22: 75626219 | AK22: 75642294 | AL22: 84050272 | AM22: 84850772 | AN22: 90161580 | AO22: 91622440 | AP22: 92450582 | AQ22: 92533610 | AR22: 93359518 | AS22: 97960048 | AT22: 77497991 | AU22: 99659474 | AV22: 67373440 | AW22: 68643250 | AX22: 71617514 | AY22: 79765990 | AZ22: 81086010 | BA22: 95933663 | BB22: 97750558 | BC22: 98303343 | BD22: 1.0099088e+08 | BE22: 1.0221091e+08 | BF22: 1.0418958e+08 | BG22: 71351099 | BH22: 1.0617915e+08 | BI22: 74272961 | BJ22: 79418054 | BK22: 80346109 | BL22: 83165372 | BM22: 83407051 | BN22: 83790881 | BO22: 85758421 | BP22: 89870120 | BQ22: 90303137 | BR22: 90467230 | BS22: 91361770 | BT22: 70645484 | BU22: 72251980 | BV22: 72342272 | BW22: 73596129 | BX22: 74630897 | BY22: 87816701 | BZ22: 90110696 | CA22: 94096976 | CB22: 96503426 | CC22: 1.0162697e+08 | CD22: 1.0649072e+08 | CE22: 1.1061685e+08 | CF22: 1.1089234e+08 | CG22: 90247140 | CH22: 92616666 | CI22: 99499734 | CJ22: 1.0069273e+08 | CK22: 1.0282611e+08 | CL22: 1.0329998e+08 | CM22: 1.0802566e+08 | CN22: 1.0889217e+08 | CO22: 1.0968867e+08 | CP22: 1.1162517e+08
A23: Prepaid Lease rentals | B23: 0 | H23: 0 | I23: 0 | J23: 0 | L23: 0 | M23: 0 | N23: 0 | O23: 0 | P23: 0 | Q23: 0 | R23: 0 | S23: 0 | U23: 0 | V23: 0 | W23: 0 | X23: 0 | Y23: 0 | Z23: 0 | AA23: 0 | AB23: 0 | AC23: 2415000 | AD23: 2415000 | AE23: 2415000 | AF23: 2415000 | AH23: 2415000 | AI23: 2415000 | AJ23: 2415000 | AK23: 2415000 | AL23: 2415000 | AM23: 2415000 | AN23: 2415000 | AO23: 2415000 | AP23: 2415000 | AQ23: 2415000 | AR23: 2415000 | AS23: 2415000 | AT23: 0 | AU23: 2595000 | AV23: 2595000 | AW23: 2595000 | AX23: 2608200 | AY23: 2608200 | AZ23: 2608200 | BA23: 2608200 | BB23: 2608200 | BC23: 2620000 | BD23: 2620000 | BE23: 2620000 | BF23: 2620000 | BG23: 0 | BH23: 2620000 | BI23: 2620000 | BJ23: 2620000 | BK23: 2620000 | BL23: 2620000 | BM23: 2620000 | BN23: 2620000 | BO23: 2620000 | BP23: 2620000 | BQ23: 2620000 | BR23: 2620000 | BS23: 2620000 | BU23: 2620000 | BV23: 2620000 | BW23: 2620000 | BX23: 2620000 | BY23: 2620000 | BZ23: 2620000 | CA23: 2620000 | CB23: 2620000 | CC23: 2620000 | CD23: 2620000 | CE23: 2620000 | CF23: 2620000 | CH23: 2620000 | CI23: 2620000 | CJ23: 2620000 | CK23: 2620000 | CL23: 3370000 | CM23: 3370000 | CN23: 3370000 | CO23: 2920000 | CP23: 2920000
A24: Intangible Assets | B24: 0 | F24: 14450383 | H24: 0 | I24: 27509216 | J24: 27509216 | K24: 27509216 | L24: 27509216 | M24: 27509216 | N24: 28147216 | O24: 28147216 | P24: 28147216 | Q24: 28147216 | R24: 28161716 | S24: 28161716 | T24: 22007373 | U24: 56323432 | V24: 22659874 | W24: 22659874 | X24: 0 | Y24: 0 | Z24: 0 | AA24: 0 | AB24: 22659874 | AC24: 22659874 | AD24: 22659874 | AE24: 22659874 | AF24: 22659874 | AG24: 17605898 | AH24: 22659874 | AI24: 18258399 | AJ24: 18258399 | AK24: 18258399 | AL24: 18258399 | AM24: 18258399 | AN24: 18258399 | AO24: 18258399 | AP24: 18258399 | AQ24: 18258399 | AR24: 18258399 | AS24: 18258399 | AT24: 18498997 | AU24: 18258399 | AV24: 30161999 | AW24: 30161999 | AX24: 30161999 | AY24: 22076799 | AZ24: 22076799 | BA24: 22076799 | BB24: 22076799 | BC24: 23246399 | BD24: 28196415 | BE24: 28130295 | BF24: 28370893 | BG24: 23460394 | BH24: 28370893 | BI24: 23460694 | BJ24: 23460694 | BK24: 23460694 | BL24: 23460694 | BM24: 23460694 | BN24: 23460694 | BO24: 23662344 | BP24: 23662344 | BQ24: 23675294 | BR24: 23675294 | BS24: 25484764 | BT24: 20387812 | BU24: 20387812 | BV24: 20387812 | BW24: 20847232 | BX24: 20861612 | BY24: 23241492 | BZ24: 25148854 | CA24: 34138749 | CB24: 41760456 | CC24: 42016628 | CD24: 42016628 | CE24: 44372100 | CF24: 45073695 | CG24: 36058956 | CH24: 37258306 | CI24: 38463276 | CJ24: 39399096 | CK24: 40895475 | CL24: 41690372 | CM24: 42947602 | CN24: 42969422 | CO24: 44127014 | CP24: 44127014
A25: Other Assets | B25: 0 | H25: 0 | I25: 0 | J25: 0 | L25: 0 | M25: 0 | N25: 0 | O25: 0 | P25: 0 | Q25: 0 | R25: 0 | S25: 0 | U25: 0 | V25: 0 | W25: 0 | X25: 22659874 | Y25: 22659874 | Z25: 22659874 | AA25: 22659874 | AB25: 0 | AC25: 0 | AD25: 0 | AE25: 0 | AF25: 0 | AG25: 0 | AH25: 0 | AI25: 0 | AJ25: 0 | AK25: 0 | AL25: 0 | AM25: 0 | AN25: 0 | AO25: 0 | AP25: 0 | AQ25: 0 | AR25: 0 | AS25: 0 | AT25: 0 | AU25: 0 | AV25: 0 | AW25: 0 | AX25: 0 | AY25: 0 | AZ25: 0 | BA25: 0 | BB25: 0 | BC25: 0 | BD25: 0 | BE25: 0 | BF25: 0 | BG25: 0 | BH25: 0 | BI25: 0 | BJ25: 0 | BK25: 0 | BL25: 0 | BM25: 0 | BN25: 0 | BO25: 0 | BP25: 0 | BQ25: 0 | BR25: 0 | BS25: 0 | BU25: 0 | BV25: 0 | BW25: 0 | BX25: 0 | BY25: 0 | BZ25: 0 | CA25: 0 | CB25: 0 | CC25: 0 | CD25: 0 | CE25: 0 | CF25: 0 | CH25: 0 | CI25: 0 | CJ25: 0 | CK25: 0 | CL25: 0 | CM25: 0 | CN25: 0 | CO25: 0 | CP25: 0
A26: Total Assets | B26: =B4+B7+B8+B13+B16+B20 -> 1982931000 | C26: =C4+C7+C8+C13+C16+C20 -> 2246183000 | D26: =D4+D7+D8+D13+D16+D20 -> 2.8343649e+09 | E26: =E4+E7+E8+E13+E16+E20 -> 3283953220 | F26: =F4+F7+F8+F13+F16+F20 -> 3926234298 | G26: =G4+G7+G8+G13+G16+G20 -> 4877108727 | H26: =H4+H7+H8+H13+H16+H20 -> 4.9539748e+09 | I26: =I4+I7+I8+I13+I16+I20 -> 4.8668645e+09 | ... CT26: =CT4+CT7+CT8+CT13+CT16+CT20 -> 0
A27: LIABILITIES
A28: Savings Deposits - Withdrawable deposits - FOSA) | B28: 231784000 | C28: 295250000 | D28: =255216000+25824000 -> 281040000 | E28: =340104982+130154418 -> 470259400 | F28: =802585086-93508240 -> 709076846 | G28: =1039952796-169467928 -> 870484868 | H28: 6.6357237e+08 | I28: 8.575616e+08 | J28: 7.7867401e+08 | K28: 7.060101e+08 | L28: 6.7478755e+08 | M28: 7.552045e+08 | N28: 7.7449626e+08 | O28: 7.9182659e+08 | P28: 7.5439305e+08 | Q28: 8.0076958e+08 | R28: 8.3889495e+08 | S28: 8.4638712e+08 | T28: =845689214+166870517 -> 1012559731 | U28: 1.6496088e+09 | V28: 1.0727991e+09 | W28: 9.4118713e+08 | X28: 8.6361089e+08 | Y28: 9.002975e+08 | Z28: 9.0060125e+08 | AA28: 9.3175511e+08 | AB28: 8.4087444e+08 | AC28: 8.3669399e+08 | AD28: 8.3986133e+08 | AE28: 8.4478993e+08 | AF28: 8.668944e+08 | AG28: 1113131850 | AH28: 8.6981707e+08 | AI28: 1.102212e+09 | AJ28: 1.0171218e+09 | AK28: 9.6083387e+08 | AL28: 9.380954e+08 | AM28: 9.4614015e+08 | AN28: 1.0240645e+09 | AO28: 9.8244957e+08 | AP28: 9.9483811e+08 | AQ28: 1.0567557e+09 | AR28: 1.0210911e+09 | AS28: 1068718094 | AT28: 1044401969 | AU28: 1.0521322e+09 | AV28: 1.3766238e+09 | AW28: 1.2156317e+09 | AX28: 1.2599495e+09 | AY28: 1.1935774e+09 | AZ28: 1.2446125e+09 | BA28: 1.2592962e+09 | BB28: 1.264537e+09 | BC28: 1.2404931e+09 | BD28: 1.2234482e+09 | BE28: 1.169445e+09 | BF28: 1.2613943e+09 | BG28: 1316646547 | BH28: 1.7206967e+09 | BI28: 1.4714235e+09 | BJ28: 1.4081926e+09 | BK28: 1.3907992e+09 | BL28: 1.341004e+09 | BM28: 1.2897406e+09 | BN28: 1.4478553e+09 | BO28: 1.3999098e+09 | BP28: 1.4313115e+09 | BQ28: 1.4525743e+09 | BR28: 1.4483924e+09 | BS28: 1.4712819e+09 | BT28: 1523215887 | BU28: 1.8941279e+09 | BV28: 1.7348896e+09 | BW28: 1.6771324e+09 | BX28: 1.5595995e+09 | BY28: 1.5778586e+09 | BZ28: 1.561895e+09 | CA28: 1.6404028e+09 | CB28: 1.5805744e+09 | CC28: 1489211113 | CD28: 1.4624322e+09 | CE28: 1.4635855e+09 | CF28: 1.4940718e+09 | CG28: 1551178695 | CH28: 1.9093209e+09 | CI28: 1.7405702e+09 | CJ28: 1.6352992e+09 | CK28: 1.5956036e+09 | CL28: 1.5321929e+09 | CM28: 1.5704042e+09 | CN28: 1.6421796e+09 | CO28: 1.6497224e+09 | CP28: 1.5199615e+09
A29: Short Term Deposits (e.g Fixed deposits, special savings) | B29: 0 | D29: 108217000 | E29: =38697335+57549083 -> 96246418 | F29: 93508240 | G29: 169467928 | H29: 0 | I29: 0 | J29: 0 | L29: 0 | M29: 0 | N29: 0 | O29: 0 | P29: 0 | Q29: 0 | R29: 0 | S29: 0 | T29: =270087385+89041333 -> 359128718 | U29: 0 | V29: 0 | W29: 0 | X29: 0 | Y29: 0 | Z29: 0 | AA29: 0 | AB29: 86459308 | AC29: 82037207 | AD29: 79915724 | AE29: 80054724 | AF29: 75425724 | AG29: 533621828 | AH29: 77358930 | AI29: 68838930 | AJ29: 74228892 | AK29: 71089475 | AL29: 64596429 | AM29: 64591175 | AN29: 56203245 | AO29: 61315274 | AP29: 60074267 | AQ29: 64427021 | AR29: 63457017 | AS29: 63217017 | AT29: =530439545+263432355 -> 793871900 | AU29: 62933136 | AV29: 61358589 | AW29: 56554589 | AX29: 60378565 | AY29: 63495458 | AZ29: 63845458 | BA29: 62675444 | BB29: 61279222 | BC29: 60430222 | BD29: 61920222 | BE29: 59820222 | BF29: 55252222 | BG29: 0 | BH29: 56232222 | BI29: 57752222 | BJ29: 57564000 | BK29: 59752000 | BL29: 58365000 | BM29: 58911000 | BN29: 61095000 | BO29: 61196000 | BP29: 61551000 | BQ29: 61607000 | BR29: 56474000 | BS29: 51934000 | BU29: 48428403 | BV29: 45108403 | BW29: 45572403 | BX29: 43641000 | BY29: 48173000 | BZ29: 50473000 | CA29: 47043000 | CB29: 46588000 | CC29: 42338000 | CD29: 44077000 | CE29: 48630000 | CF29: 45725500 | CG29: 45725500 | CH29: 44396500 | CI29: 45396500 | CJ29: 45875200 | CK29: 40937200 | CL29: 39337200 | CM29: 90553000 | CN29: 91688000 | CO29: 86488000 | CP29: 85740000
A30: Non withdrawable deposits (BOSA member deposits) | B30: 1309041000 | C30: 1412967000 | D30: 1638628000 | E30: 1909635651 | F30: 2204621249 | G30: 2548520382 | H30: 2.9156687e+09 | I30: 2.9495685e+09 | J30: 3.0007471e+09 | K30: 3.0380822e+09 | L30: 3.0861625e+09 | M30: 3.1380294e+09 | N30: 3.174952e+09 | O30: 3.2314918e+09 | P30: 3.2763935e+09 | Q30: 3.3255117e+09 | R30: 3.3845389e+09 | S30: 3.416673e+09 | T30: 2979715072 | U30: 6.9472519e+09 | V30: 3.5310138e+09 | W30: 3.60518e+09 | X30: 3.6557248e+09 | Y30: 3.691673e+09 | Z30: 3.7470154e+09 | AA30: 3792366999 | AB30: 3.8408767e+09 | AC30: 3.8878325e+09 | AD30: 3.9460004e+09 | AE30: 3.9983527e+09 | AF30: 4.0332867e+09 | AG30: 3488295940 | AH30: 4.0911833e+09 | AI30: 4.3025887e+09 | AJ30: 4.3850462e+09 | AK30: 4.4128937e+09 | AL30: 4.4659512e+09 | AM30: 4.5123082e+09 | AN30: 4.5719484e+09 | AO30: 4.6394924e+09 | AP30: 4.6684274e+09 | AQ30: 4.7263117e+09 | AR30: 4.8187225e+09 | AS30: 4.8409901e+09 | AT30: 4134637410 | AU30: 4.8964286e+09 | AV30: 4.9461011e+09 | AW30: 5.0269878e+09 | AX30: 5.0858533e+09 | AY30: 5.1520075e+09 | AZ30: 5.1376724e+09 | BA30: 5.2235408e+09 | BB30: 5.2921537e+09 | BC30: 5.3367628e+09 | BD30: 5.3972264e+09 | BE30: 5.4607011e+09 | BF30: 5.4588113e+09 | BG30: 5458811312 | BH30: 5.528779e+09 | BI30: 5.6168593e+09 | BJ30: 5.6963139e+09 | BK30: 5.7586531e+09 | BL30: 5.8313061e+09 | BM30: 5.9038546e+09 | BN30: 6.0007245e+09 | BO30: 6.033339e+09 | BP30: 6.1115931e+09 | BQ30: 6.1962111e+09 | BR30: 6.2735678e+09 | BS30: 6.3162116e+09 | BT30: 6316211595 | BU30: 6.3922039e+09 | BV30: 6.4861692e+09 | BW30: 6.565832e+09 | BX30: 6.6712638e+09 | BY30: 6.7841946e+09 | BZ30: 6.8547903e+09 | CA30: 6.9696178e+09 | CB30: 7.0611481e+09 | CC30: 7.1453804e+09 | CD30: 7.2443676e+09 | CE30: 7.3269811e+09 | CF30: 7.3573529e+09 | CG30: =7357287925-CG29 -> 7311562425 | CH30: 7.4246863e+09 | CI30: 7.5066947e+09 | CJ30: 7.5890967e+09 | CK30: 7.6886922e+09 | CL30: 7.7922286e+09 | CM30: 7.9237572e+09 | CN30: 8.0790294e+09 | CO30: 8.2095667e+09 | CP30: 8.3161393e+09
A31: Total Deposit liabilities | B31: =SUM(B28:B30) -> 1540825000 | C31: =SUM(C28:C30) -> 1708217000 | D31: =SUM(D28:D30) -> 2027885000 | E31: =SUM(E28:E30) -> 2476141469 | F31: =SUM(F28:F30) -> 3007206335 | G31: =SUM(G28:G30) -> 3588473178 | H31: =SUM(H28:H30) -> 3.5792411e+09 | I31: =SUM(I28:I30) -> 3.8071301e+09 | ... CT31: =SUM(CT28:CT30) -> 0
A32: Accounts Payable & Other Liabilities | B32: =SUM(B33:B38) -> 56399000 | C32: =SUM(C33:C38) -> 273714000 | D32: =SUM(D33:D38) -> 11930000 | E32: =SUM(E33:E38) -> 278665461 | F32: =SUM(F33:F38) -> 3.5486019e+08 | G32: =SUM(G33:G38) -> 612597954 | H32: =SUM(H33:H38) -> 6.6680284e+08 | I32: =SUM(I33:I38) -> 4.0464208e+08 | ... CT32: =SUM(CT33:CT38) -> 0
A33: Tax Payable | B33: 296000 | C33: 627000 | D33: 542000 | E33: 4130450 | F33: 2596929.8 | G33: -561286 | H33: 0 | I33: 0 | J33: 0 | L33: 0 | M33: 0 | N33: 0 | O33: 0 | P33: 0 | Q33: 0 | R33: 0 | S33: 0 | T33: 1103303 | U33: 0 | V33: 0 | W33: 0 | X33: 0 | Y33: 0 | Z33: 0 | AA33: 0 | AB33: 0 | AC33: 0 | AD33: 0 | AE33: 0 | AF33: 0 | AG33: 2484330 | AH33: 0 | AI33: 95000000 | AJ33: 0 | AK33: 190000000 | AL33: 0 | AM33: 0 | AN33: 0 | AO33: 0 | AP33: 0 | AQ33: 0 | AR33: 0 | AS33: 0 | AT33: 3125556 | AU33: 0 | AV33: 0 | AW33: 0 | AX33: 0 | AY33: 0 | AZ33: 0 | BA33: 0 | BB33: 0 | BC33: 0 | BD33: 0 | BE33: 0 | BF33: 0 | BG33: 10285340 | BH33: 0 | BI33: 0 | BJ33: 0 | BK33: 0 | BL33: 0 | BM33: 0 | BN33: 0 | BO33: 0 | BP33: 0 | BQ33: 0 | BR33: 0 | BS33: 0 | BT33: 5625813 | BU33: 0 | BV33: 0 | BW33: 0 | BX33: 0 | BY33: 0 | BZ33: 0 | CA33: 0 | CB33: 0 | CC33: 0 | CD33: 0 | CE33: 0 | CF33: 0 | CG33: 14525411 | CH33: 0 | CI33: 0 | CJ33: 0 | CK33: 0 | CL33: 0 | CM33: 0 | CN33: 0 | CO33: 0 | CP33: 0
A34: Dividends Payable | B34: 0 | C34: 175761000 | H34: 0 | I34: 0 | J34: 0 | L34: 0 | M34: 0 | N34: 0 | O34: 0 | P34: 0 | Q34: 0 | R34: 0 | S34: 0 | U34: 0 | V34: 0 | W34: 0 | X34: 0 | Y34: 0 | Z34: 0 | AA34: 0 | AB34: 321600000 | AC34: 321600000 | AD34: 402000000 | AE34: 442200000 | AF34: 482400000 | AH34: 527400000 | AI34: 0 | AJ34: 142500000 | AK34: 0 | AL34: 237500000 | AM34: 285000000 | AN34: 332500000 | AO34: 380000000 | AP34: 427500000 | AQ34: 475000000 | AR34: 522500000 | AS34: 570000000 | AT34: 564645701 | AU34: 617500000 | AV34: 62051444 | AW34: 150000000 | AX34: 200000000 | AY34: 250000000 | AZ34: 300000000 | BA34: 350000000 | BB34: 400000000 | BC34: 450000000 | BD34: 500000000 | BE34: 550000000 | BF34: 600000000 | BG34: 645500000 | BH34: 55000000 | BI34: 120000000 | BJ34: 180000000 | BK34: 240000000 | BL34: 300000000 | BM34: 360000000 | BN34: 420000000 | BO34: 480000000 | BP34: 540000000 | BQ34: 600000000 | BR34: 660000000 | BS34: 720000000 | BT34: 764541806 | BU34: 76666667 | BV34: 153333334 | BW34: 230000001 | BX34: 306666668 | BY34: 383333335 | BZ34: 460000002 | CA34: 536666669 | CB34: 613333336 | CC34: 690000000 | CD34: 7.6666667e+08 | CE34: 843333334 | CF34: 920000000 | CG34: 904946415 | CH34: 92000000 | CI34: 184000000 | CJ34: 271912217 | CK34: 351648868 | CL34: 439561085 | CM34: 527473302 | CN34: 615385519 | CO34: 703297736 | CP34: 791209953
A35: Deferred Tax Liability | B35: 0 | H35: 0 | I35: 0 | J35: 0 | L35: 0 | M35: 0 | N35: 0 | O35: 0 | P35: 0 | Q35: 0 | R35: 0 | S35: 0 | T35: 0 | U35: 0 | V35: 0 | W35: 0 | X35: 0 | Y35: 0 | Z35: 0 | AA35: 0 | AB35: 0 | AC35: 0 | AD35: 0 | AE35: 0 | AF35: 0 | AH35: 0 | AI35: 0 | AJ35: 0 | AK35: 0 | AL35: 0 | AM35: 0 | AN35: 0 | AO35: 0 | AP35: 0 | AQ35: 0 | AR35: 0 | AS35: 0 | AT35: 0 | AU35: 0 | AV35: 0 | AW35: 0 | AX35: 0 | AY35: 0 | AZ35: 0 | BA35: 0 | BB35: 0 | BC35: 0 | BD35: 0 | BE35: 0 | BF35: 0 | BG35: 0 | BH35: 0 | BI35: 0 | BJ35: 0 | BK35: 0 | BL35: 0 | BM35: 0 | BN35: 0 | BO35: 0 | BP35: 0 | BQ35: 0 | BR35: 0 | BS35: 0 | BU35: 0 | BV35: 0 | BW35: 0 | BX35: 0 | BY35: 0 | BZ35: 0 | CA35: 0 | CB35: 0 | CC35: 0 | CD35: 0 | CE35: 0 | CF35: 0 | CH35: 0 | CI35: 0 | CJ35: 0 | CK35: 0 | CL35: 0 | CM35: 0 | CN35: 0 | CO35: 0 | CP35: 0
A36: Retirement Benefits Liability | B36: 0 | H36: 17393917 | I36: 19393917 | J36: 20393917 | K36: 21393917 | L36: 22393917 | M36: 6737962.1 | N36: 7737962.1 | O36: 3334753 | P36: 4334753 | Q36: 4334753 | R36: 4334753 | S36: 3334753 | U36: 4669506 | V36: 2643761 | W36: 2643761 | X36: 2643761 | Y36: 2643761 | Z36: 2643761 | AA36: 3643761 | AB36: 1643761 | AC36: 643761.02 | AD36: 1643761 | AE36: 1643761 | AF36: 643761.02 | AH36: 643761.02 | AI36: 643761.02 | AJ36: 643761.02 | AK36: 1643761 | AL36: 643761.02 | AM36: 862924.22 | AN36: 0 | AO36: 0 | AP36: 0 | AQ36: 0 | AR36: 0 | AS36: 0 | AT36: 0 | AU36: 0 | AV36: 0 | AW36: 0 | AX36: 0 | AY36: 0 | AZ36: 0 | BA36: 0 | BB36: 0 | BC36: 0 | BD36: 0 | BE36: 0 | BF36: 0 | BG36: 0 | BH36: 0 | BI36: 0 | BJ36: 0 | BK36: 0 | BL36: 0 | BM36: 0 | BN36: 0 | BO36: 0 | BP36: 0 | BQ36: 0 | BR36: 0 | BS36: 0 | BU36: 0 | BV36: 0 | BW36: 0 | BX36: 0 | BY36: 0 | BZ36: 0 | CA36: 0 | CB36: 0 | CC36: 0 | CD36: 0 | CE36: 0 | CF36: 0 | CH36: 0 | CI36: 0 | CJ36: 0 | CK36: 0 | CL36: 0 | CM36: 0 | CN36: 0 | CO36: 0 | CP36: 0
A37: Other Liabilities | B37: 6936000 | C37: =88420000+8906000 -> 97326000 | D37: =155000+12000+17000+27000+806000+8552000+36000+477000+121000+1185000 -> 11388000 | E37: =251475140+23059871 -> 274535011 | F37: =306347796+45915461 -> 352263257 | G37: =87213374+342612533 -> 429825907 | H37: 4.6607559e+08 | I37: 2.185815e+08 | J37: 2.5232542e+08 | K37: 2.9773305e+08 | L37: 3.2547814e+08 | M37: 3.7017674e+08 | N37: 4.1080733e+08 | O37: 4.5603781e+08 | P37: 5.0020308e+08 | Q37: 5.452702e+08 | R37: 590240855 | S37: 6.3141081e+08 | T37: =67893441+374569299 -> 442462740 | U37: 1.2667611e+09 | V37: 2.6878764e+08 | W37: 3.2286135e+08 | X37: 3.7643395e+08 | Y37: 4.0061704e+08 | Z37: 4.2638194e+08 | AA37: 4.8341306e+08 | AB37: 2.0696278e+08 | AC37: 2.37707e+08 | AD37: 2.0831584e+08 | AE37: 2.2407055e+08 | AF37: 2.3147792e+08 | AG37: =83043250+468684234 -> 551727484 | AH37: 2.4417613e+08 | AI37: 89946581 | AJ37: 1.0978236e+08 | AK37: 84100921 | AL37: 93554185 | AM37: 1.1078147e+08 | AN37: 1.0719783e+08 | AO37: 1.2529733e+08 | AP37: 1.4247191e+08 | AQ37: 1.5856674e+08 | AR37: 1.7603689e+08 | AS37: 1.3846716e+08 | AT37: 88124106 | AU37: 1.537726e+08 | AV37: 1.4891903e+08 | AW37: 1.0519672e+08 | AX37: 75459348 | AY37: 82006126 | AZ37: 93418760 | BA37: 86477155 | BB37: 94568826 | BC37: 97172933 | BD37: 1.0372597e+08 | BE37: 1.1072696e+08 | BF37: 1.1231847e+08 | BG37: =18872704+82534142+1500000 -> 102906846 | BH37: 1.2212012e+08 | BI37: 92602416 | BJ37: 92016796 | BK37: 68006373 | BL37: 73655597 | BM37: 79738053 | BN37: 76219978 | BO37: 86913229 | BP37: 1.0410044e+08 | BQ37: 1.2150464e+08 | BR37: 1.4287154e+08 | BS37: 1.5560798e+08 | BT37: =7010120+93875670+1800000 -> 102685790 | BU37: 91291615 | BV37: 95571669 | BW37: 70599495 | BX37: 85385286 | BY37: 1.0529991e+08 | BZ37: 1.12859e+08 | CA37: 1.1411713e+08 | CB37: 1.2570592e+08 | CC37: 1.3677807e+08 | CD37: 1.5040582e+08 | CE37: 1.6536768e+08 | CF37: 89295345 | CG37: =1017976559-CG34+19404423 -> 132434567 | CH37: 1.1732018e+08 | CI37: 1.2204532e+08 | CJ37: 88444346 | CK37: 1.0082471e+08 | CL37: 1.0613773e+08 | CM37: 1.224506e+08 | CN37: 1.0843725e+08 | CO37: 1.2167381e+08 | CP37: 1.2742136e+08
A38: External Borrowings | B38: 49167000 | G38: 183333333 | H38: 183333333 | I38: 166666666 | J38: 166666666 | K38: 166666666 | L38: 166666666 | M38: 349999999 | N38: 349999999 | O38: 433333332 | P38: 5.2291667e+08 | Q38: 6.1875e+08 | R38: 5.875e+08 | S38: 5.7708333e+08 | T38: 577083332 | U38: 1.1333333e+09 | V38: 5.3958333e+08 | W38: 5.2916666e+08 | X38: 5.1875e+08 | Y38: 4.9166666e+08 | Z38: 4.812583e+08 | AA38: 4.7084164e+08 | AB38: 4.6042497e+08 | AC38: 4.3334164e+08 | AD38: 4.2292497e+08 | AE38: 4.125083e+08 | AF38: 3.8542497e+08 | AG38: 3.8542497e+08 | AH38: 3.750083e+08 | AI38: 3.6459164e+08 | AJ38: 3.375083e+08 | AK38: 2.9375831e+08 | AL38: 2.8334169e+08 | AM38: 2.7675867e+08 | AN38: 2.625514e+08 | AO38: 1.4913473e+08 | AP38: 89293633 | AQ38: -1221150.5 | AR38: 0 | AS38: 0 | AT38: 0 | AU38: 0 | AV38: 0 | AW38: 0 | AX38: 0 | AY38: 0 | AZ38: 0 | BA38: 0 | BB38: 0 | BC38: 0 | BD38: 0 | BE38: 0 | BF38: 0 | BG38: 0 | BH38: 0 | BI38: 0 | BJ38: 0 | BK38: 0 | BL38: 0 | BM38: 0 | BN38: 0 | BO38: 0 | BP38: 0 | BQ38: 0 | BR38: 0 | BS38: 0 | BU38: 0 | BV38: 0 | BW38: 0 | BX38: 0 | BY38: 0 | BZ38: 0 | CA38: 0 | CB38: 0 | CC38: 0 | CD38: 0 | CE38: 0 | CF38: 0 | CH38: 0 | CI38: 0 | CJ38: 0 | CK38: 0 | CL38: 0 | CM38: 0 | CN38: 0 | CO38: 0 | CP38: 0
A39: Total Liabilities | B39: =B31+B32 -> 1597224000 | C39: =C31+C32 -> 1981931000 | D39: =D31+D32 -> 2039815000 | E39: =E31+E32 -> 2754806930 | F39: =F31+F32 -> 3.3620665e+09 | G39: =G31+G32 -> 4201071132 | H39: =H31+H32 -> 4.2460439e+09 | I39: =I31+I32 -> 4.2117722e+09 | ... CT39: =CT31+CT32 -> 0
A40: EQUITY
...

Sheet SCI
B2: 2011 AUDITED | C2: 2012 AUDITED | D2: 2013 AUDITED | E2: 2014 AUDITED | F2: audited 2015 | G2: Audited 2016 | H2: 42736 | I2: 42767 | J2: 42795 | K2: 42826 | L2: 42856 | M2: 42887 | N2: 42917 | O2: 42948 | P2: 42979 | Q2: 43009 | R2: 43040 | S2: 43070 | T2: Audited 2017 | U2: 43101 | V2: 43132 | W2: 43160 | X2: 43191 | Y2: 43221 | Z2: 43252 | AA2: 43282 | AB2: 43313 | AC2: 43344 | AD2: 43374 | AE2: 43405 | AF2: 43435 | AG2: Audited 2018 | AH2: 43466 | AI2: 43497 | AJ2: 43525 | AK2: 43556 | AL2: 43586 | AM2: 43617 | AN2: 43647 | AO2: 43678 | AP2: 43709 | AQ2: 43739 | AR2: 43770 | AS2: 43800 | AT2: Audited-19 | AU2: 43831 | AV2: 43862 | AW2: 43891 | AX2: 43922 | AY2: 43952 | AZ2: 43983 | BA2: 44013 | BB2: 44044 | BC2: 44075 | BD2: 44105 | BE2: 44136 | BF2: 44166 | BG2: Audited-20 | BH2: 44197 | BI2: 44228 | BJ2: 44256 | BK2: 44287 | BL2: 44317 | BM2: 44348 | BN2: 44378 | BO2: 44409 | BP2: 44440 | BQ2: 44470 | BR2: 44501 | BS2: 44531 | BT2: Audited 2021 | BU2: 44562 | BV2: 44593 | BW2: 44621 | BX2: 44652 | BY2: 44682 | BZ2: 44713 | CA2: 44743 | CB2: 44774 | CC2: 44805 | CD2: 44835 | CE2: 44866 | CF2: 44896 | CG2: Audited 2022 | CH2: 44927 | CI2: 44958 | CJ2: 44986 | CK2: 45017 | CL2: 45047 | CM2: 45078 | CN2: 45108 | CO2: 45139 | CP2: 45170 | CQ2: 45200 | CR2: 45231 | CS2: 45261
A3: Financial Income | B3: 272737000 | C3: =C4+C7 -> 315395000 | D3: =D4+D7 -> 391908000 | E3: =E4+E7 -> 486302029 | F3: =F4+F7 -> 557411649 | G3: =G4+G7 -> 691077004 | H3: =H4+H7 -> 60018212 | I3: =I4+I7 -> 1.1929711e+08 | J3: =J4+J7 -> 1.82223e+08 | ... CS3: =CS4+CS7 -> 0
A4: Financial Income from Loans Portfolio | B4: 254043000 | C4: =C5+C6 -> 310677000 | D4: =D5+D6 -> 363369000 | E4: =E5+E6 -> 442597728 | F4: =F5+F6 -> 519200042 | G4: =G5+G6 -> 645382510 | H4: =H5+H6 -> 56614856 | I4: =I5+I6 -> 1.1177208e+08 | J4: =J5+J6 -> 1.7018352e+08 | ... CS4: =CS5+CS6 -> 0
A5: Interest on Loan Portfolio | B5: 253602000 | C5: 289168000 | D5: 356158000 | E5: 442597728 | F5: 503688132 | G5: 635979383 | H5: 56614856 | I5: 1.1177208e+08 | J5: 1.7018352e+08 | K5: 2.3215714e+08 | L5: 2.9495932e+08 | M5: 3.5979667e+08 | N5: 4.2774414e+08 | O5: 5.1038563e+08 | P5: 5.9673823e+08 | Q5: 6.7240514e+08 | R5: 7.509777e+08 | S5: 8.3783551e+08 | T5: 837835511 | U5: 1.5081321e+08 | V5: 1.4386766e+08 | W5: 2.2065185e+08 | X5: 3.019857e+08 | Y5: 3.8159725e+08 | Z5: 4.5724309e+08 | AA5: 5.3582301e+08 | AB5: 6.2999948e+08 | AC5: 7.0534261e+08 | AD5: 7.8567222e+08 | AE5: 8.7534744e+08 | AF5: 9.6967851e+08 | AG5: 969678514 | AH5: 83871107 | AI5: 1.6288703e+08 | AJ5: 2.463056e+08 | AK5: 3.3564803e+08 | AL5: 4.1758611e+08 | AM5: 5.017181e+08 | AN5: 5.8952797e+08 | AO5: 6.8930236e+08 | AP5: 7.7556576e+08 | AQ5: 8.5928326e+08 | AR5: 9.5559684e+08 | AS5: 1.0437813e+09 | AT5: 1043781324 | AU5: 86861126 | AV5: 1.7023577e+08 | AW5: 2.5688825e+08 | AX5: 3.3671949e+08 | AY5: 4.1746785e+08 | AZ5: 4.9561048e+08 | BA5: 577932569 | BB5: 6.7336089e+08 | BC5: 7.6311549e+08 | BD5: 854738566 | BE5: 9.4519752e+08 | BF5: 1.0345234e+09 | BG5: 1034523352 | BH5: 85521103 | BI5: 1.6809339e+08 | BJ5: 2.5701691e+08 | BK5: 3.4923213e+08 | BL5: 4.3970593e+08 | BM5: 5.3117806e+08 | BN5: 6.3141356e+08 | BO5: 7.1429947e+08 | BP5: 7.9976236e+08 | BQ5: 8.9512929e+08 | BR5: 9.853325e+08 | BS5: 1.0781276e+09 | BT5: 1078127618 | BU5: 90384420 | BV5: 1.8425522e+08 | BW5: 2.8183036e+08 | BX5: 3.7975309e+08 | BY5: 4.7743814e+08 | BZ5: 5.7622051e+08 | CA5: 6.7970578e+08 | CB5: 7.8326126e+08 | CC5: 8.9306085e+08 | CD5: 1.001066e+09 | CE5: 1.1107351e+09 | CF5: 1.3220519e+09 | CG5: 1222051910 | CH5: 1.1040754e+08 | CI5: 2.2047827e+08 | CJ5: 3.317881e+08 | CK5: 4.4475594e+08 | CL5: 5.6023906e+08 | CM5: 6.7440579e+08 | CN5: 7.903733e+08 | CO5: 9.1359402e+08 | CP5: 1.0340612e+09
A6: Fees & Commission on Loan Portfolio | B6: 441000 | C6: 21509000 | D6: =2131000+5080000 -> 7211000 | F6: 15511910 | G6: 9403127 | H6: 0 | I6: 0 | J6: 0 | L6: 0 | M6: 0 | N6: 0 | O6: 0 | P6: 0 | Q6: 0 | R6: 0 | S6: 0 | T6: 51453557 | U6: 0 | V6: 0 | W6: 0 | X6: 0 | Y6: 0 | Z6: 0 | AA6: 0 | AB6: 0 | AC6: 21966026 | AD6: 24277059 | AE6: 26624007 | AF6: 0 | AG6: 0 | AH6: 2417191.9 | AI6: 5295197.1 | AJ6: 0 | AK6: 0 | AL6: 0 | AM6: 17167750 | AN6: 0 | AO6: 22344149 | AP6: 25051257 | AQ6: 27785828 | AR6: 31200650 | AS6: 33178858 | AU6: 2856228.7 | AV6: 6522594.5 | AW6: 10211472 | AX6: 12544931 | AY6: 15275572 | AZ6: 17610374 | BA6: 20793774 | BB6: 24211550 | BC6: 26440217 | BD6: 29618294 | BE6: 32754598 | BF6: 35899447 | BH6: 11025132 | BI6: 17737654 | BJ6: 26730070 | BK6: 43529160 | BL6: 52147675 | BM6: 0 | BN6: 26631296 | BO6: 30183022 | BP6: 33989228 | BQ6: 38151114 | BR6: 41795194 | BS6: 51361864 | BT6: 41456567 | BU6: 4353745 | BV6: 8459541.6 | BW6: 13379120 | BX6: 17554676 | BY6: 21683209 | BZ6: 27831422 | CA6: 32636720 | CB6: 37279164 | CC6: 41997668 | CD6: 46615707 | CE6: 34548487 | CF6: 39288543 | CG6: =5816395+2424080+3384554+22285852 -> 33910881 | CH6: 6658215.2 | CI6: 11737248 | CJ6: 17010359 | CK6: 21738356 | CL6: 30032580 | CM6: 36627813 | CN6: 42846817 | CO6: 49513792 | CP6: 55936221
A7: Financial Income from Investments in: | B7: 18694000 | C7: =SUM(C9:C11) -> 4718000 | D7: =SUM(D9:D11) -> 28539000 | E7: =SUM(E9:E11) -> 43704301 | F7: =SUM(F9:F11) -> 38211607 | G7: =SUM(G9:G11) -> 45694494 | H7: =SUM(H9:H11) -> 3403356.2 | I7: =SUM(I9:I11) -> 7525036.9 | J7: =SUM(J9:J11) -> 12039484 | ... CS7: =SUM(CS9:CS11) -> 0
A8: Government Securities | B8: 0 | H8: 0 | I8: 0 | J8: 0 | L8: 0 | M8: 0 | N8: 0 | O8: 0 | P8: 0 | Q8: 0 | R8: 0 | S8: 0 | U8: 0 | V8: 0 | W8: 0 | X8: 0 | Y8: 0 | Z8: 0 | AA8: 0 | AB8: 0 | AC8: 0 | AD8: 0 | AE8: 0 | AF8: 0 | AG8: 0 | AH8: 0 | AI8: 0 | AJ8: 0 | AK8: 0 | AL8: 0 | AM8: 0 | AN8: 0 | AO8: 0 | AP8: 0 | AQ8: 0 | AR8: 0 | AS8: 0 | AT8: 0 | AU8: 0 | AV8: 0 | AW8: 0 | AX8: 0 | AY8: 0 | AZ8: 0 | BA8: 0 | BB8: 0 | BC8: 0 | BD8: 0 | BE8: 0 | BF8: 0 | BH8: 0 | BI8: 0 | BJ8: 0 | BK8: 0 | BL8: 0 | BM8: 0 | BN8: 0 | BO8: 0 | BP8: 0 | BQ8: 0 | BR8: 0 | BS8: 0 | BU8: 0 | BV8: 0 | BW8: 0 | BX8: 0 | BY8: 0 | BZ8: 0 | CA8: 0 | CB8: 0 | CC8: 0 | CD8: 0 | CE8: 0 | CF8: 0 | CH8: 0 | CI8: 0 | CJ8: 0 | CK8: 0 | CL8: 0 | CM8: 0 | CN8: 0 | CO8: 0 | CP8: 0
A9: Deposit with Banks and Other Financial Inst. | B9: 2376000 | C9: 4180000 | E9: 9995324 | H9: 0 | I9: 0 | J9: 0 | L9: 0 | M9: 0 | N9: 0 | O9: 0 | P9: 0 | Q9: 0 | R9: 0 | S9: 0 | T9: 7030991 | U9: 0 | V9: 0 | W9: 0 | X9: 0 | Y9: 0 | Z9: 0 | AA9: 0 | AB9: 0 | AC9: 0 | AD9: 0 | AE9: 0 | AF9: 15317368 | AH9: 0 | AI9: 0 | AJ9: 1164687.8 | AK9: 1608670.2 | AL9: 1731344 | AM9: 0 | AN9: 19168067 | AO9: 0 | AP9: 0 | AQ9: 0 | AR9: 0 | AS9: 0 | AT9: 0 | AU9: 0 | AV9: 0 | AW9: 0 | AX9: 0 | AY9: 0 | AZ9: 0 | BA9: 0 | BB9: 0 | BC9: 0 | BD9: 0 | BE9: 0 | BF9: 0 | BG9: 72113370 | BH9: 0 | BI9: 0 | BJ9: 0 | BK9: 0 | BL9: 0 | BM9: 0 | BN9: 0 | BO9: 0 | BP9: 0 | BQ9: 0 | BR9: 0 | BS9: 0 | BT9: 136913280 | BU9: 0 | BV9: 0 | BW9: 0 | BX9: 0 | BY9: 0 | BZ9: 0 | CA9: 0 | CB9: 0 | CC9: 0 | CD9: 0 | CE9: 0 | CF9: 0 | CG9: 145851486 | CH9: 0 | CI9: 0 | CJ9: 0 | CK9: 0 | CL9: 0 | CM9: 0 | CN9: 0 | CO9: 0 | CP9: 0
A10: Other Investments - dividend & Interest incomes from investments | B10: 0 | H10: 0 | I10: 0 | J10: 0 | L10: 0 | M10: 10382382 | N10: 11620662 | O10: 11620662 | P10: 11054511 | Q10: 11054511 | R10: 11054511 | S10: 11054511 | U10: 2096398 | V10: 3605517 | W10: 489936.92 | X10: 636913.82 | Y10: 717436.82 | Z10: 14379340 | AA10: 14194008 | AB10: 14317493 | AC10: 14439313 | AD10: 14787490 | AE10: 15195967 | AF10: 20886748 | AG10: 4227975 | AH10: 651686.77 | AI10: 786042.34 | AJ10: 9341817.3 | AK10: 11080490 | AL10: 13689207 | AM10: 18860633 | AN10: 20826675 | AO10: 21954320 | AP10: 22049873 | AQ10: 22362171 | AR10: 22766472 | AS10: 23032866 | AT10: =27723128+20660701 -> 48383829 | AU10: 99445.95 | AV10: 172840.5 | AW10: 714496.9 | AX10: 19167419 | AY10: 19228743 | AZ10: 19683827 | BA10: 19782874 | BB10: 19860389 | BC10: 20156777 | BD10: 20262246 | BE10: 20379323 | BF10: 20794064 | BG10: =18538297 -> 18538297 | BH10: 0 | BI10: 523459.24 | BJ10: 1257465.6 | BK10: 19647403 | BL10: 20351648 | BM10: 43733255 | BN10: 21740727 | BO10: 22051260 | BP10: 22305370 | BQ10: 22602407 | BR10: 22914358 | BS10: 23714209 | BT10: 18250100 | BU10: 318872.3 | BV10: 665924.3 | BW10: 1408023.7 | BX10: 1324001.8 | BY10: 1652414.5 | BZ10: 19530288 | CA10: 22832326 | CB10: 23175653 | CC10: 23555838 | CD10: 23829994 | CE10: 24729877 | CF10: 25243947 | CG10: 18058312 | CH10: 359204.68 | CI10: 769068.42 | CJ10: 1178932.2 | CK10: 2407665.2 | CL10: 3258127.2 | CM10: 30038971 | CN10: 30859407 | CO10: 31478855 | CP10: 32256213
A11: Other Operating Income- Salary processing fees, transaction fees, membership fees | B11: 16318000 | C11: 538000 | D11: =7060000+946000+27744000-D6 -> 28539000 | E11: 33708977 | F11: 38211607 | G11: 45694494 | H11: 3403356.2 | I11: 7525036.9 | J11: 12039484 | K11: 14673097 | L11: 19243738 | M11: 22718288 | N11: 26208338 | O11: 32138665 | P11: 35842328 | Q11: 39011027 | R11: 34080445 | S11: 47430036 | U11: 4603522.7 | V11: 5420515.5 | W11: 13173824 | X11: 16700631 | Y11: 20120938 | Z11: 23518415 | AA11: 27915923 | AB11: 32504410 | AC11: 14673582 | AD11: 16801616 | AE11: 18626911 | AF11: 30812315 | AG11: 64579420 | AH11: 2188601.4 | AI11: 7108139.4 | AJ11: 8883035.5 | AK11: 11841612 | AL11: 14598352 | AM11: 16947658 | AN11: 18718204 | AO11: 26087340 | AP11: 30782264 | AQ11: 34481217 | AR11: 38453892 | AS11: 45331479 | AT11: 93728335 | AU11: 2906373.6 | AV11: 12834070 | AW11: 17580449 | AX11: 21536782 | AY11: 25696481 | AZ11: 32634424 | BA11: 41175578 | BB11: 46872883 | BC11: 55368582 | BD11: 63670277 | BE11: 68578667 | BF11: 83442391 | BG11: =54428983+5391390 -> 59820373 | BH11: 3360824.2 | BI11: 7251179 | BJ11: 11003044 | BK11: 14514916 | BL11: 17769288 | BM11: 59220393 | BN11: 72792458 | BO11: 81641574 | BP11: 1.0471878e+08 | BQ11: 1.1351785e+08 | BR11: 1.2422801e+08 | BS11: 1.5629705e+08 | BT11: 34753173 | BU11: 7723379.4 | BV11: 30016586 | BW11: 44628919 | BX11: 46950258 | BY11: 66038514 | BZ11: 76752948 | CA11: 80057878 | CB11: 1.0252716e+08 | CC11: 1.2515824e+08 | CD11: 1.3828256e+08 | CE11: 1.5087529e+08 | CF11: 1.6513517e+08 | CG11: =164047337-CG6-CG10 -> 112078144 | CH11: 17573806 | CI11: 20199308 | CJ11: 46959355 | CK11: 56408714 | CL11: 63005460 | CM11: 76831060 | CN11: 85801021 | CO11: 89903450 | CP11: 1.2961477e+08
A12: Financial Expense | B12: 161587000 | C12: =SUM(C13:C16)+C17+C18 -> 179955000 | D12: =SUM(D13:D16)+D17+D18 -> 202204000 | E12: =SUM(E13:E16)+E17+E18 -> 253507699 | F12: =F13+F14+F15+F16+F17+F18 -> 3.0907542e+08 | G12: =G13+G14+G15+G16+G17+G18 -> 377000555 | H12: =H13+H14+H15+H16+H17+H18 -> 3576601.2 | I12: =I13+I14+I15+I16+I17+I18 -> 93484527 | J12: =J13+J14+J15+J16+J17+J18 -> 1.3603003e+08 | K12: =K13+K14+K15+K16+K17+K18 -> 1.7881736e+08 | L12: =L13+L14+L15+L16+L17+L18 -> 2.2153768e+08 | M12: =M13+M14+M15+M16+M17+M18 -> 2.7071822e+08 | ... CS12: =CS13+CS14+CS15+CS16+CS17+CS18 -> 0
A13: Interest Expense on Deposits | B13: 148036000 | C13: 172768000 | D13: =192153000+8690000 -> 200843000 | E13: 252903029 | F13: 307717763 | G13: 374176451 | H13: 432589.6 | I13: 77703090 | J13: 1.1645913e+08 | K13: 1.5516839e+08 | L13: 1.9373689e+08 | M13: 2.3266265e+08 | N13: 2.7156256e+08 | O13: 3.1015966e+08 | P13: 3.4915531e+08 | Q13: 3.8896937e+08 | R13: 4.2752865e+08 | S13: 4.6656716e+08 | T13: 374569299 | U13: 935398 | V13: 90901486 | W13: 136689278 | X13: 182294326 | Y13: 2.0258499e+08 | Z13: 2.4308037e+08 | AA13: 2.8381469e+08 | AB13: 0 | AC13: 3.6544453e+08 | AD13: 4.0680262e+08 | AE13: 447239436 | AF13: 500193931 | AG13: 468684234 | AH13: 45513264 | AI13: 95671409 | AJ13: 145543167 | AK13: 193917757 | AL13: 2.4176373e+08 | AM13: 2.8931245e+08 | AN13: 3.3721477e+08 | AO13: 3.8505402e+08 | AP13: 4.3260626e+08 | AQ13: 4.8063212e+08 | AR13: 5.2849379e+08 | AS13: 5.7611797e+08 | AT13: 564645701 | AU13: 47864450 | AV13: 95599250 | AW13: 1.5073424e+08 | AX13: 2.010419e+08 | AY13: 2.5138476e+08 | AZ13: 3.014158e+08 | BA13: 3.5185781e+08 | BB13: 4.019834e+08 | BC13: 4.5113647e+08 | BD13: 5.0136708e+08 | BE13: 5.5260185e+08 | BF13: 6.0310091e+08 | BG13: 648599707 | BH13: 55532892 | BI13: 1.2065285e+08 | BJ13: 1.8085273e+08 | BK13: 2.4108133e+08 | BL13: 3.0138393e+08 | BM13: 3.6154889e+08 | BN13: 4.2201158e+08 | BO13: 4.821146e+08 | BP13: 5.4233551e+08 | BQ13: 6.0259242e+08 | BR13: 6.6278942e+08 | BS13: 7.2298217e+08 | BT13: 767523975 | BU13: 77350542 | BV13: 1.5427091e+08 | BW13: 2.3100224e+08 | BX13: 3.0802188e+08 | BY13: 3.8513893e+08 | BZ13: 4.6169185e+08 | CA13: 5.3873317e+08 | CB13: 6.1576181e+08 | CC13: 6.9261547e+08 | CD13: 7.6948905e+08 | CE13: 8.4617972e+08 | CF13: 9.230281e+08 | CG13: 904946415 | CH13: 92549279 | CI13: 184952029 | CJ13: 272895787 | CK13: 3.5305016e+08 | CL13: 4.4110104e+08 | CM13: 5.2905276e+08 | CN13: 6.1719248e+08 | CO13: 7.055632e+08 | CP13: 7.9849479e+08
A14: Cost of External Borrowings | B14: 9065000 | C14: 5096000 | D14: 0 | H14: 2761000 | I14: 9804164.1 | J14: 10011613 | K14: 10781408 | L14: 11682753 | M14: 18579360 | N14: 22592659 | O14: 30228768 | P14: 37774430 | Q14: 41672836 | R14: 54178898 | S14: 60308343 | T14: =4567162+60308343 -> 64875505 | U14: 12944687 | V14: 20157629 | W14: 25491057 | X14: 31844224 | Y14: 40971042 | Z14: 46739542 | AA14: 52039725 | AB14: 56482704 | AC14: 63933922 | AD14: 68191191 | AE14: 72204165 | AF14: 78131445 | AG14: 83702936 | AH14: 3750443.3 | AI14: 7374003.9 | AJ14: 12180265 | AK14: 16338525 | AL14: 19491189 | AM14: 22622334 | AN14: 25584196 | AO14: 28482484 | AP14: 29417892 | AQ14: 30447267 | AR14: 31668417 | AS14: 31668417 | AT14: =31668417+6117967 -> 37786384 | AU14: 0 | AV14: 0 | AW14: 0 | AX14: 0 | AY14: 0 | AZ14: 0 | BA14: 0 | BB14: 0 | BC14: 0 | BD14: 0 | BE14: 0 | BF14: 0 | BG14: 0 | BH14: 0 | BI14: 0 | BJ14: 0 | BK14: 0 | BL14: 0 | BM14: 0 | BN14: 0 | BO14: 0 | BP14: 0 | BQ14: 0 | BR14: 0 | BS14: 0 | BU14: 0 | BV14: 0 | BW14: 0 | BX14: 0 | BY14: 0 | BZ14: 0 | CA14: 0 | CB14: 0 | CC14: 0 | CD14: 0 | CE14: 0 | CF14: 0 | CH14: 0 | CI14: 0 | CJ14: 0 | CK14: 0 | CL14: 0 | CM14: 0 | CN14: 0 | CO14: 0 | CP14: 0
