Workbook

Sheet Evolutive SFP
B3: 2019 Audited | C3: 43831 | D3: 43891 | E3: 43922 | F3: 43952 | G3: 43983 | H3: 44075 | I3: 44105 | J3: 44136 | K3: 44166 | L3: 2020 Audited | M3: 44197 | N3: 44228 | O3: 44256 | P3: 44287 | Q3: 44317 | R3: 44348 | S3: 44378 | T3: 44409 | U3: 44440 | V3: 44470 | W3: 44501 | X3: 44531 | Y3: Audited 2021 | Z3: 44562 | AA3: 44593 | AB3: 44621 | AC3: 44652 | AD3: 44682 | AE3: 44713 | AF3: 44743 | AG3: 44774 | AH3: 44805 | AI3: 44835 | AJ3: 44866 | AK3: 44896 | AL3: Audit 2022 | AM3: 44927 | AN3: 44958 | AO3: 44986 | AP3: 45017 | AQ3: 45047 | AR3: 45078 | AS3: 45108 | AT3: 45139 | AU3: 45170
A4: Cash & cash Equivalent | B4: =SUM(B5:B6) -> 175549981 | C4: =SUM(C5:C6) -> 1.157514e+08 | D4: =SUM(D5:D6) -> 125385395 | E4: =SUM(E5:E6) -> 1.179096e+08 | F4: =SUM(F5:F6) -> 126001573 | G4: =SUM(G5:G6) -> 148703736 | H4: =SUM(H5:H6) -> 1.2921568e+08 | I4: =SUM(I5:I6) -> 1.2338319e+08 | ... AU4: =SUM(AU5:AU6) -> 79311802
A5: Cash In Hand | B5: 8591212 | C5: 17832612 | D5: 15586292 | E5: 15056377 | F5: 12355166 | G5: 10652458 | H5: 14669693 | I5: 16702119 | J5: 13350145 | K5: 9681170.4 | L5: 6227987 | M5: 13331270 | N5: 15844732 | O5: 11710705 | P5: 12317590 | Q5: 17336531 | R5: 16573995 | S5: 13036614 | T5: 19169044 | U5: 18630358 | V5: 21827599 | W5: 13262105 | X5: 16753691 | Y5: 9062258 | Z5: 14111195 | AA5: 19339799 | AB5: 15725381 | AC5: 9274176.4 | AD5: 12990645 | AE5: 12403405 | AF5: 12499839 | AG5: 15903644 | AH5: 15952756 | AI5: 22610230 | AJ5: 19019582 | AK5: 17040235 | AL5: 10576584 | AM5: 16438713 | AN5: 16148057 | AO5: 10043356 | AP5: 13390029 | AQ5: 17560632 | AR5: 15457613 | AS5: 12803728 | AT5: 16200090 | AU5: 13812725
A6: Cash at Bank | B6: 166958769 | C6: 97918785 | D6: 109799103 | E6: 1.0285322e+08 | F6: 113646407 | G6: 138051278 | H6: 1.1454598e+08 | I6: 1.0668107e+08 | J6: 1.1022427e+08 | K6: 1.1526995e+08 | L6: 1.7397932e+08 | M6: 1.0004873e+08 | N6: 101855561 | O6: 95857220 | P6: 89764090 | Q6: 76661529 | R6: 81225205 | S6: 91622066 | T6: 95270418 | U6: 1.0585771e+08 | V6: 99382522 | W6: 1.1464897e+08 | X6: 114945395 | Y6: 180854127 | Z6: 1.3112243e+08 | AA6: 1.2869697e+08 | AB6: 1.1310081e+08 | AC6: 93222784 | AD6: 92773814 | AE6: 1.226478e+08 | AF6: 98856232 | AG6: 96443830 | AH6: 96634886 | AI6: 1.0079811e+08 | AJ6: 1.1300765e+08 | AK6: 1.2256137e+08 | AL6: =186297973+5634445 -> 191932418 | AM6: 1.0964733e+08 | AN6: 1.1106953e+08 | AO6: 1.039034e+08 | AP6: 78067028 | AQ6: 69516244 | AR6: 90275916 | AS6: 81405867 | AT6: 74693236 | AU6: 65499077
A7: Prepayment and Sundry | B7: 30658423 | C7: 49059837 | D7: 53633771 | E7: 55448583 | F7: 56053750 | G7: 37613575 | H7: 50010771 | I7: 50209894 | J7: 51738791 | K7: 46830377 | L7: 50040207 | M7: 53438434 | N7: 54872394 | O7: 56410640 | P7: 49352949 | Q7: 58299742 | R7: 56254662 | S7: 66279487 | T7: 70186680 | U7: 67762721 | V7: 73793352 | W7: 75645352 | X7: 78688571 | Y7: 67454301 | Z7: 73311975 | AA7: 77422792 | AB7: 76487391 | AC7: 76030076 | AD7: 69064605 | AE7: 55974276 | AF7: 71472081 | AG7: 78914063 | AH7: 74315450 | AI7: 76980173 | AJ7: 71098043 | AK7: 75085842 | AL7: =875745+75586335.24 -> 76462080 | AM7: 79871425 | AN7: 78773193 | AO7: 78872340 | AP7: 67739111 | AQ7: 81463015 | AR7: 62101770 | AS7: 80672122 | AT7: 84631843 | AU7: 85004676
A8: Financial Investment | B8: =SUM(B9:B12) -> 9221631 | C8: =SUM(C9:C12) -> 57779478 | D8: =SUM(D9:D12) -> 58489478 | E8: =SUM(E9:E12) -> 59744505 | F8: =SUM(F9:F12) -> 60099478 | G8: =SUM(G9:G12) -> 60454478 | H8: =SUM(H9:H12) -> 61519478 | I8: =SUM(I9:I12) -> 62774478 | ... AU8: =SUM(AU9:AU12) -> 75323929
A9: Government Security | C9: 0 | D9: 0 | E9: 0 | F9: 0 | G9: 0 | H9: 0 | I9: 0 | J9: 0 | K9: 0 | M9: 0 | N9: 0 | O9: 0 | P9: 0 | Q9: 0 | R9: 0 | S9: 0 | T9: 0 | U9: 0 | V9: 0 | W9: 0 | X9: 0 | Z9: 0 | AA9: 0 | AB9: 0 | AC9: 0 | AD9: 0 | AE9: 0 | AF9: 0 | AG9: 0 | AH9: 0 | AI9: 0 | AJ9: 0 | AK9: 0 | AM9: 0 | AN9: 0 | AO9: 0 | AP9: 0 | AQ9: 0 | AR9: 0 | AS9: 0 | AT9: 0 | AU9: 0
A10: Other Securities | C10: 0 | D10: 0 | E10: 0 | F10: 0 | G10: 0 | H10: 0 | I10: 0 | J10: 0 | K10: 0 | M10: 0 | N10: 0 | O10: 0 | P10: 0 | Q10: 0 | R10: 0 | S10: 0 | T10: 0 | U10: 0 | V10: 0 | W10: 0 | X10: 0 | Z10: 0 | AA10: 0 | AB10: 0 | AC10: 0 | AD10: 0 | AE10: 0 | AF10: 0 | AG10: 0 | AH10: 0 | AI10: 0 | AJ10: 0 | AK10: 0 | AM10: 0 | AN10: 0 | AO10: 0 | AP10: 0 | AQ10: 0 | AR10: 0 | AS10: 0 | AT10: 0 | AU10: 0
A11: Balances with Other Saccos | B11: 9221631 | C11: 48557847 | D11: 49267847 | E11: 50522874 | F11: 50877847 | G11: 51232847 | H11: 52297847 | I11: 53552847 | J11: 54507847 | K11: 56592358 | L11: 9317364 | M11: 56947358 | N11: 57302358 | O11: 57657358 | P11: 58012358 | Q11: 58367358 | R11: 58722358 | S11: 56442298 | T11: 56797298 | U11: 57152298 | V11: 57507298 | W11: 57862298 | X11: 58217298 | Y11: 9150631 | Z11: 58572298 | AA11: 58927298 | AB11: 59712298 | AC11: 60067298 | AD11: 60422298 | AE11: 60777298 | AF11: 61132298 | AG11: 61487298 | AH11: 61842298 | AI11: 62197298 | AJ11: 62552298 | AK11: 62907298 | AL11: =203767+307580+8639284+41000 -> 9191631 | AM11: 63262298 | AN11: 63617298 | AO11: 63972298 | AP11: 64327298 | AQ11: 64682298 | AR11: 65037298 | AS11: 65392298 | AT11: 65747298 | AU11: 66102298
A12: Investment In Companies | C12: 9221631 | D12: 9221631 | E12: 9221631 | F12: 9221631 | G12: 9221631 | H12: 9221631.3 | I12: 9221631.3 | J12: 9221631.3 | K12: 9221631 | M12: 9221631 | N12: 9221631 | O12: 9221631 | P12: 9221631 | Q12: 9221631 | R12: 9221631 | S12: 9221631 | T12: 9221631 | U12: 9221631 | V12: 9221631 | W12: 9221631 | X12: 9221631 | Y12: 71000 | Z12: 9221631 | AA12: 9221631 | AB12: 9221631 | AC12: 9221631 | AD12: 9221631 | AE12: 9221631 | AF12: 9221631 | AG12: 9221631 | AH12: 9221631 | AI12: 9221631 | AJ12: 9221631 | AK12: 9221631 | AL12: 30000 | AM12: 9221631 | AN12: 9221631 | AO12: 9221631 | AP12: 9221631 | AQ12: 9221631 | AR12: 9221631 | AS12: 9221631 | AT12: 9221631 | AU12: 9221631
A13: Net Loan Portfolio | B13: =B14-B15 -> 360423402 | C13: =C14-C15 -> 3.5757131e+08 | D13: =D14-D15 -> 3.4700111e+08 | E13: =E14-E15 -> 340745739 | F13: =F14-F15 -> 331981703 | G13: =G14-G15 -> 324174103 | H13: =H14-H15 -> 3.2941099e+08 | I13: =I14-I15 -> 3.361167e+08 | ... AU13: =AU14-AU15 -> 4.9239623e+08
A14: Gross Loan Portfolio | B14: 369086787 | C14: 366682836 | D14: 3.5626197e+08 | E14: 350006594 | F14: 341242558 | G14: 333434958 | H14: 3.496496e+08 | I14: 3.5635532e+08 | J14: 3.5601312e+08 | K14: 3.7668332e+08 | L14: 393314726 | M14: 3.7693815e+08 | N14: 3.758275e+08 | O14: 3.8291083e+08 | P14: 3.8593014e+08 | Q14: 3.9492702e+08 | R14: 3.9388915e+08 | S14: 4.0752463e+08 | T14: 4.0862996e+08 | U14: 4.0635407e+08 | V14: 4.0928779e+08 | W14: 4.1003297e+08 | X14: 4.0937931e+08 | Y14: 409379310 | Z14: 4.160264e+08 | AA14: 4.1652954e+08 | AB14: 422681669 | AC14: 4.3395563e+08 | AD14: 4.4003127e+08 | AE14: 4.3666859e+08 | AF14: 4.4320895e+08 | AG14: 4.4322052e+08 | AH14: 4.442866e+08 | AI14: 4.4600293e+08 | AJ14: 4.4944439e+08 | AK14: 4.5117654e+08 | AL14: 4.5117654e+08 | AM14: 4.6686895e+08 | AN14: 4.6781576e+08 | AO14: 4.7477445e+08 | AP14: 4.8917091e+08 | AQ14: 4.8977436e+08 | AR14: 4.9759461e+08 | AS14: 4.9921479e+08 | AT14: 5.107986e+08 | AU14: 5.1685656e+08
A15: Allowance For Loan Loss | B15: 8663385 | C15: 9111524.9 | D15: 9260855 | E15: 9260855 | F15: 9260855 | G15: 9260855 | H15: 20238613 | I15: 20238613 | J15: 20238613 | K15: 27703571 | L15: 27690971 | M15: 27703571 | N15: 27703571 | O15: 27690971 | P15: 27690971 | Q15: 27690971 | R15: 27690971 | S15: 27690971 | T15: 27690971 | U15: 27690971 | V15: 27690971 | W15: 27690971 | X15: 24223709 | Y15: 24223709 | Z15: 24223709 | AA15: 24223709 | AB15: 24223709 | AC15: 24223709 | AD15: 24223709 | AE15: 24223709 | AF15: 24223709 | AG15: 24223709 | AH15: 24223709 | AI15: 24223709 | AJ15: 24223709 | AK15: 24460329 | AL15: 24460329 | AM15: 24460329 | AN15: 24460329 | AO15: 24460329 | AP15: 24460329 | AQ15: 24460329 | AR15: 24460329 | AS15: 24460329 | AT15: 24460329 | AU15: 24460329
A16: Accounts Recievables | B16: =SUM(B17:B18) -> 0 | C16: =SUM(C17:C18) -> 0 | D16: =SUM(D17:D18) -> 0 | E16: =SUM(E17:E18) -> 0 | F16: =SUM(F17:F18) -> 0 | G16: =SUM(G17:G18) -> 0 | H16: =SUM(H17:H18) -> 0 | I16: =SUM(I17:I18) -> 0 | ... AU16: =SUM(AU17:AU18) -> 0
A17: Tax Recoverable | C17: 0 | D17: 0 | E17: 0 | F17: 0 | G17: 0 | H17: 0 | I17: 0 | J17: 0 | K17: 0 | M17: 0 | N17: 0 | O17: 0 | P17: 0 | Q17: 0 | R17: 0 | S17: 0 | T17: 0 | Z17: 0 | AA17: 0 | AB17: 0 | AC17: 0 | AD17: 0 | AE17: 0 | AF17: 0 | AG17: 0 | AH17: 0 | AI17: 0 | AJ17: 0 | AK17: 0 | AM17: 0 | AN17: 0 | AO17: 0 | AP17: 0 | AQ17: 0 | AR17: 0 | AS17: 0 | AT17: 0 | AU17: 0
A18: Deffered Tax Assets | C18: 0 | D18: 0 | E18: 0 | F18: 0 | G18: 0 | H18: 0 | I18: 0 | J18: 0 | K18: 0 | M18: 0 | N18: 0 | O18: 0 | P18: 0 | Q18: 0 | R18: 0 | S18: 0 | T18: 0 | Z18: 0 | AA18: 0 | AB18: 0 | AC18: 0 | AD18: 0 | AE18: 0 | AF18: 0 | AG18: 0 | AH18: 0 | AI18: 0 | AJ18: 0 | AK18: 0 | AM18: 0 | AN18: 0 | AO18: 0 | AP18: 0 | AQ18: 0 | AR18: 0 | AS18: 0 | AT18: 0 | AU18: 0
A19: Retirement Benefit Assets | C19: 0 | D19: 0 | E19: 0 | F19: 0 | G19: 0 | H19: 0 | I19: 0 | J19: 0 | K19: 0 | M19: 0 | N19: 0 | O19: 0 | P19: 0 | Q19: 0 | R19: 0 | S19: 0 | T19: 0 | Z19: 0 | AA19: 0 | AB19: 0 | AC19: 0 | AD19: 0 | AE19: 0 | AF19: 0 | AG19: 0 | AH19: 0 | AI19: 0 | AJ19: 0 | AK19: 0 | AM19: 0 | AN19: 0 | AO19: 0 | AP19: 0 | AQ19: 0 | AR19: 0 | AS19: 0 | AT19: 0 | AU19: 0
A20: Property&Equipments&Other Assets | B20: =SUM(B21:B25) -> 40896479 | C20: =SUM(C21:C25) -> 181645018 | D20: =SUM(D21:D25) -> 181645018 | E20: =SUM(E21:E25) -> 181645038 | F20: =SUM(F21:F25) -> 181645038 | G20: =SUM(G21:G25) -> 181645038 | H20: =SUM(H21:H25) -> 1.8350993e+08 | I20: =SUM(I21:I25) -> 1.842383e+08 | ... AU20: =SUM(AU21:AU25) -> 1.6703031e+08
A21: Investment Properties | C21: 0 | D21: 0 | E21: 0 | F21: 0 | G21: 0 | H21: 0 | I21: 0 | J21: 0 | K21: 0 | M21: 0 | N21: 0 | O21: 0 | P21: 0 | Q21: 0 | R21: 0 | S21: 0 | T21: 0 | U21: 0 | V21: 0 | W21: 0 | X21: 0 | Z21: 0 | AA21: 0 | AB21: 0 | AC21: 0 | AD21: 0 | AE21: 0 | AF21: 0 | AG21: 0 | AH21: 0 | AI21: 0 | AJ21: 0 | AK21: 0 | AM21: 0 | AN21: 0 | AO21: 0 | AP21: 0 | AQ21: 0 | AR21: 0 | AS21: 0 | AT21: 0 | AU21: 0
A22: Property and Equipment | B22: 23963774 | C22: 22863775 | D22: 22863775 | E22: 22863775 | F22: 22863775 | G22: 22863775 | H22: 23946128 | I22: 24674503 | J22: 24674503 | K22: 25397132 | L22: 23660693 | M22: 26062032 | N22: 24547049 | O22: 24594849 | P22: 24594849 | Q22: 24820149 | R22: 25138439 | S22: 25146039 | T22: 25193739 | U22: 25555779 | V22: 25555779 | W22: 25555779 | X22: 25577679 | Y22: 22963419 | Z22: 25639209 | AA22: 25639209 | AB22: 23024950 | AC22: 23024950 | AD22: 23525650 | AE22: 23525650 | AF22: 23525650 | AG22: 23525650 | AH22: 23525650 | AI22: 23525650 | AJ22: 23686650 | AK22: 23686650 | AL22: 21262616 | AM22: 23686650 | AN22: 23850350 | AO22: 21478316 | AP22: 21478316 | AQ22: 21478316 | AR22: 21478316 | AS22: 24678316 | AT22: 24969746 | AU22: 24969746
A23: Prepaid Lease Rentals | C23: 0 | D23: 0 | E23: 0 | F23: 0 | G23: 0 | H23: 0 | I23: 0 | J23: 0 | K23: 0 | M23: 0 | N23: 0 | O23: 0 | P23: 0 | Q23: 0 | R23: 0 | S23: 0 | T23: 0 | U23: 0 | V23: 0 | W23: 0 | X23: 0 | Z23: 0 | AA23: 0 | AB23: 0 | AC23: 0 | AD23: 0 | AE23: 0 | AF23: 0 | AG23: 0 | AH23: 0 | AI23: 0 | AJ23: 0 | AK23: 0 | AM23: 0 | AN23: 0 | AO23: 0 | AP23: 0 | AQ23: 0 | AR23: 0 | AS23: 0 | AT23: 0 | AU23: 0
A24: Intangible Assets | B24: 1105020 | C24: 655020 | D24: 655020 | E24: 655020 | F24: 655020 | G24: 655020 | H24: 1437557.5 | I24: 1437557.5 | J24: 1437557.5 | K24: 1437557.5 | L24: 771182 | M24: 1437557.5 | N24: 1244762 | O24: 771181.68 | P24: 771181.68 | Q24: 771181.68 | R24: 771181.68 | S24: 771181.68 | T24: 771181.68 | U24: 771181.68 | V24: 771181.68 | W24: 771181.68 | X24: 771181.68 | Y24: 616945 | Z24: 771181.68 | AA24: 771181.68 | AB24: 616945.28 | AC24: 616945.28 | AD24: 616945.28 | AE24: 616945.28 | AF24: 616945.28 | AG24: 616945.28 | AH24: 616945.28 | AI24: 616945.28 | AJ24: 616945.28 | AK24: 616945.28 | AL24: 462709.1 | AM24: 616945.28 | AN24: 616945.28 | AO24: 462708.78 | AP24: 462708.78 | AQ24: 462708.78 | AR24: 462708.78 | AS24: 462708.78 | AT24: 462708.78 | AU24: 462708.78
A25: Other Assets | B25: 15827685 | C25: 158126223 | D25: 158126223 | E25: 158126243 | F25: 158126243 | G25: 158126243 | H25: 1.5812624e+08 | I25: 1.5812624e+08 | J25: 1.5812624e+08 | K25: 1.5462624e+08 | L25: 15827685 | M25: 1.5462017e+08 | N25: 1.5462017e+08 | O25: 1.5462017e+08 | P25: 1.5462017e+08 | Q25: 1.5462017e+08 | R25: 1.5462017e+08 | S25: 1.5462019e+08 | T25: 1.5462019e+08 | U25: 1.5462019e+08 | V25: 1.5462019e+08 | W25: 1.5462019e+08 | X25: 1.5112019e+08 | Y25: =148126223+13621436.3 -> 1.6174766e+08 | Z25: 1.5112019e+08 | AA25: 1.5110806e+08 | AB25: 1.4810806e+08 | AC25: 1.4810806e+08 | AD25: 1.4810806e+08 | AE25: 1.4810806e+08 | AF25: 1.4810806e+08 | AG25: 1.4810806e+08 | AH25: 1.4810806e+08 | AI25: 1.4810806e+08 | AJ25: 1.4810606e+08 | AK25: 1.4160406e+08 | AL25: =6300000+7321436.3+141626223 -> 1.5524766e+08 | AM25: 1.4160202e+08 | AN25: 1.4159786e+08 | AO25: 1.4159786e+08 | AP25: 1.4159786e+08 | AQ25: 1.4159786e+08 | AR25: 1.4159786e+08 | AS25: 1.4159786e+08 | AT25: 1.4159786e+08 | AU25: 1.4159786e+08
A26: Total Assets | B26: =B20+B16+B13+B8+B7+B4 -> 616749916 | C26: =C20+C16+C13+C8+C7+C4 -> 7.6180704e+08 | D26: =D20+D16+D13+D8+D7+D4 -> 7.6615477e+08 | E26: =E20+E16+E13+E8+E7+E4 -> 7.5549346e+08 | F26: =F20+F16+F13+F8+F7+F4 -> 7.5578154e+08 | G26: =G20+G16+G13+G8+G7+G4 -> 7.5259093e+08 | H26: =H20+H16+H13+H8+H7+H4 -> 7.5366684e+08 | I26: =I20+I16+I13+I8+I7+I4 -> 7.5672257e+08 | ... AU26: =AU20+AU16+AU13+AU8+AU7+AU4 -> 8.9906695e+08
A27: Savings and Deposits | B27: 127986727 | C27: 97743215 | D27: 103735571 | E27: 1.130541e+08 | F27: 1.0809158e+08 | G27: 1.0286644e+08 | H27: 1.1367251e+08 | I27: 1.1411871e+08 | J27: 1.11392e+08 | K27: 1.2545408e+08 | L27: 145871163 | M27: 1.1410223e+08 | N27: 1.1415724e+08 | O27: 1.356129e+08 | P27: 1.1310659e+08 | Q27: 1.1752093e+08 | R27: 1.1608396e+08 | S27: 1.2354028e+08 | T27: 1.2996222e+08 | U27: 1.2266211e+08 | V27: 1.2318017e+08 | W27: 1.2506294e+08 | X27: 1.2457183e+08 | Y27: 143820589 | Z27: 1.2691902e+08 | AA27: 1.3250748e+08 | AB27: 1.5232834e+08 | AC27: 1.3149993e+08 | AD27: 1.2332032e+08 | AE27: 1.3099475e+08 | AF27: 1.2790434e+08 | AG27: 1.2502628e+08 | AH27: 1.1855901e+08 | AI27: 1.2786296e+08 | AJ27: 1.3187994e+08 | AK27: 1.3860573e+08 | AL27: =138605725+12616719+4706998+411650+1604200+622144 -> 158567436 | AM27: 1.3420874e+08 | AN27: 1.2738977e+08 | AO27: 1.5178706e+08 | AP27: 1.2787914e+08 | AQ27: 1.2992657e+08 | AR27: 1.3069846e+08 | AS27: 1.379955e+08 | AT27: 1.397159e+08 | AU27: 1.3180921e+08
A28: Short Terrm Deposits | B28: 27362889 | C28: 48022408 | D28: 51077224 | E28: 52285954 | F28: 53544527 | G28: 54705990 | H28: 56248600 | I28: 56010701 | J28: 56202227 | K28: 58128748 | L28: 37711665 | M28: 60067995 | N28: 58383273 | O28: 54593574 | P28: 57936327 | Q28: 56706975 | R28: 55940179 | S28: 57885735 | T28: 59894932 | U28: 66021396 | V28: 64409910 | W28: 65271957 | X28: 65200524 | Y28: 45951567 | Z28: 69289523 | AA28: 67210468 | AB28: 68322544 | AC28: 67443281 | AD28: 70614372 | AE28: 73247487 | AF28: 75113729 | AG28: 75689517 | AH28: 75676983 | AI28: 76451572 | AJ28: 77134666 | AK28: 73888005 | AL28: 53926294 | AM28: 78937745 | AN28: 81864015 | AO28: 80719162 | AP28: 81874989 | AQ28: 79310674 | AR28: 80573118 | AS28: 77454987 | AT28: 83604355 | AU28: 78021902
A29: Non Withdrawable Deposits | B29: 418806431 | C29: 4.2198244e+08 | D29: 427325266 | E29: 4.2916071e+08 | F29: 4.3220893e+08 | G29: 4.3426279e+08 | H29: 4.4005123e+08 | I29: 4.4155717e+08 | J29: 4.4332697e+08 | K29: 4.4463522e+08 | L29: 444635223 | M29: 4.4719704e+08 | N29: 4.4989727e+08 | O29: 4.5203289e+08 | P29: 4.5356745e+08 | Q29: 4.5647932e+08 | R29: 4.4982749e+08 | S29: 4.5087945e+08 | T29: 4.5354175e+08 | U29: 4.5538079e+08 | V29: 4.5762464e+08 | W29: 4.5927695e+08 | X29: 4.6201706e+08 | Y29: 462017056 | Z29: 4.6480839e+08 | AA29: 4.6707999e+08 | AB29: 4.7070883e+08 | AC29: 4.7292531e+08 | AD29: 4.7617714e+08 | AE29: 4.7941537e+08 | AF29: 4.7750452e+08 | AG29: 4.8137474e+08 | AH29: 4.8284536e+08 | AI29: 4.8333572e+08 | AJ29: 4.8233205e+08 | AK29: 4.7901831e+08 | AL29: 479018315 | AM29: 4.8162851e+08 | AN29: 4.847309e+08 | AO29: 4.8966111e+08 | AP29: 4.9289653e+08 | AQ29: 4.949934e+08 | AR29: 4.9724728e+08 | AS29: 4.9908491e+08 | AT29: 4.9826451e+08 | AU29: 5.0059285e+08
A30: Total Deposit Liabilities | B30: =SUM(B27:B29) -> 574156047 | C30: =SUM(C27:C29) -> 5.6774807e+08 | D30: =SUM(D27:D29) -> 582138061 | E30: =SUM(E27:E29) -> 5.9450076e+08 | F30: =SUM(F27:F29) -> 5.9384504e+08 | G30: =SUM(G27:G29) -> 5.9183523e+08 | H30: =SUM(H27:H29) -> 6.0997234e+08 | I30: =SUM(I27:I29) -> 6.1168659e+08 | ... AU30: =SUM(AU27:AU29) -> 7.1042396e+08
A31: Tax Payable | B31: 1800000 | C31: 0 | D31: 0 | E31: 0 | F31: 0 | G31: 0 | H31: 0 | I31: 0 | J31: 0 | K31: 0 | L31: 1500000 | M31: 0 | N31: 0 | O31: 0 | P31: 0 | Q31: 0 | R31: 0 | S31: 0 | T31: 0 | U31: 0 | V31: 0 | W31: 0 | X31: 0 | Y31: 2500000 | Z31: 0 | AA31: 0 | AB31: 0 | AC31: 0 | AD31: 0 | AE31: 0 | AF31: 0 | AG31: 0 | AH31: 0 | AI31: 0 | AJ31: 0 | AK31: 0 | AL31: 706224 | AM31: 0 | AN31: 0 | AO31: 0 | AQ31: 0 | AR31: 0 | AS31: 0 | AT31: 0 | AU31: 0
A32: Dividends Payable | B32: 31410482 | C32: 49781424 | D32: 45072728 | E32: 12898801 | F32: 17441784 | G32: 21445740 | H32: 0 | I32: 0 | J32: 0 | K32: 0 | L32: 35570818 | M32: 0 | N32: 0 | O32: 0 | P32: 0 | Q32: 0 | R32: 0 | S32: 0 | T32: 0 | U32: 0 | V32: 0 | W32: 0 | X32: 0 | Y32: 39271450 | Z32: 50000000 | AA32: 50000000 | AB32: 0 | AC32: 0 | AD32: 0 | AE32: 0 | AF32: 0 | AG32: 0 | AH32: 0 | AI32: 0 | AJ32: 0 | AK32: 0 | AL32: 38321465 | AM32: 0 | AN32: 0 | AO32: 0 | AP32: 0 | AQ32: 0 | AR32: 0 | AS32: 0 | AT32: 0 | AU32: 0
A33: Deferred Tax Liability | C33: 0 | D33: 0 | E33: 0 | F33: 0 | G33: 0 | H33: 0 | I33: 0 | J33: 0 | K33: 0 | M33: 0 | N33: 0 | O33: 0 | P33: 0 | Q33: 0 | R33: 0 | S33: 0 | T33: 0 | U33: 0 | V33: 0 | W33: 0 | X33: 0 | Z33: 0 | AA33: 0 | AB33: 0 | AC33: 0 | AD33: 0 | AE33: 0 | AF33: 0 | AG33: 0 | AH33: 0 | AI33: 0 | AJ33: 0 | AK33: 0 | AM33: 0 | AN33: 0 | AO33: 0 | AP33: 0 | AQ33: 0 | AR33: 0 | AS33: 0 | AT33: 0 | AU33: 0
A34: Retirement Benefits Liabilty | C34: 0 | D34: 0 | E34: 0 | F34: 0 | G34: 0 | H34: 0 | I34: 0 | J34: 0 | K34: 0 | M34: 0 | N34: 0 | O34: 0 | P34: 0 | Q34: 0 | R34: 0 | S34: 0 | T34: 0 | U34: 0 | V34: 0 | W34: 0 | X34: 0 | Z34: 0 | AA34: 0 | AB34: 0 | AC34: 0 | AD34: 0 | AE34: 0 | AF34: 0 | AG34: 0 | AH34: 0 | AI34: 0 | AJ34: 0 | AK34: 0 | AM34: 0 | AN34: 0 | AO34: 0 | AP34: 0 | AQ34: 0 | AR34: 0 | AS34: 0 | AT34: 0 | AU34: 0
A35: Other Liabilities | B35: 11233128 | C35: 9394483 | D35: 9449472 | E35: 9206836 | F35: 8770448 | G35: 6857934 | H35: 5404385 | I35: 4988367.3 | J35: 5498614.6 | K35: -5923672.9 | L35: 7359120 | M35: -5970032 | N35: 32416732 | O35: -2657389.3 | P35: 382751.23 | Q35: 568958.8 | R35: 45111.87 | S35: 10862855 | T35: 9655862.9 | U35: 9635729.4 | V35: 10891535 | W35: 11843905 | X35: 6402788.6 | Y35: 7224159 | Z35: 5888900.5 | AA35: 8522411.1 | AB35: 9762219 | AC35: 8376563.8 | AD35: 8791570.2 | AE35: 5699462.8 | AF35: 7217666.5 | AG35: 7886425.2 | AH35: 8180742.2 | AI35: 9237083.6 | AJ35: 10013380 | AK35: 32473318 | AL35: 5863487 | AM35: 41251590 | AN35: 42099275 | AO35: 5078318.4 | AP35: 5878765.8 | AQ35: 7241519.8 | AR35: 6947017.2 | AS35: 8320309.8 | AT35: 9285533.9 | AU35: 9693076.4
A36: External Borrowings | B36: 30000000 | C36: 26040073 | D36: 20587500 | E36: 19480080 | F36: 16342580 | G36: 13205080 | H36: 3792579.8 | I36: 2197660.8 | J36: -79939.3 | K36: -1830436.2 | L36: 0 | M36: -4967936.2 | N36: -4967936.2 | O36: 3039457.8 | P36: 3039457.8 | Q36: 3039457.8 | R36: 0 | S36: 0 | T36: 0 | U36: 0 | V36: 0 | W36: 0 | X36: 0 | Z36: 0 | AA36: 0 | AB36: 0 | AC36: 0 | AD36: 0 | AE36: 0 | AF36: 0 | AG36: 0 | AH36: 0 | AI36: 0 | AJ36: 0 | AK36: 0 | AL36: 0 | AM36: 0 | AN36: 0 | AO36: 0 | AP36: 0 | AQ36: 0 | AR36: 0 | AS36: 0 | AT36: 0 | AU36: 0
A37: Total Liabilities | B37: =SUM(B30:B36) -> 6.4859966e+08 | C37: =SUM(C30:C36) -> 6.5296405e+08 | D37: =SUM(D30:D36) -> 6.5724776e+08 | E37: =SUM(E30:E36) -> 6.3608647e+08 | F37: =SUM(F30:F36) -> 6.3639985e+08 | G37: =SUM(G30:G36) -> 6.3334398e+08 | H37: =SUM(H30:H36) -> 6.1916931e+08 | I37: =SUM(I30:I36) -> 6.1887261e+08 | ... AU37: =SUM(AU30:AU36) -> 7.2011704e+08
A38: Share Capital | B38: 48764688 | C38: 48777188 | D38: 48771288 | E38: 48771288 | F38: 48771288 | G38: 48771288 | H38: 49431500 | I38: 49432000 | J38: 49434000 | K38: 49435000 | L38: 49435000 | M38: 49435000 | N38: 49435200 | O38: 49438421 | P38: 49438421 | Q38: 49442421 | R38: 58592805 | S38: 58594805 | T38: 58594805 | U38: 58595805 | V38: 58595805 | W38: 58606805 | X38: 58607805 | Y38: 58607805 | Z38: 58607805 | AA38: 58609305 | AB38: 58498533 | AC38: 58498533 | AD38: 58498533 | AE38: 58498533 | AF38: 58498533 | AG38: 58498533 | AH38: 58520308 | AI38: 59285431 | AJ38: 59285431 | AK38: 68817747 | AL38: 68817747 | AM38: 68817747 | AN38: 68817747 | AO38: 68802747 | AP38: 68815247 | AQ38: 69000962 | AR38: 68985962 | AS38: 68987162 | AT38: 68989362 | AU38: 68990362
A39: Capital Grants | C39: 0 | D39: 0 | E39: 0 | F39: 0 | G39: 0 | H39: 0 | I39: 0 | J39: 0 | K39: 0 | M39: 0 | N39: 0 | O39: 0 | P39: 0 | Q39: 0 | R39: 0 | S39: 0 | T39: 0 | U39: 0 | V39: 0 | W39: 0 | X39: 0 | Z39: 0 | AA39: 0 | AB39: 0 | AC39: 0 | AD39: 0 | AE39: 0 | AF39: 0 | AG39: 0 | AH39: 0 | AI39: 0 | AJ39: 0 | AK39: 0 | AL39: 0 | AM39: 0 | AN39: 0 | AO39: 0 | AP39: 0 | AQ39: 0 | AR39: 0 | AS39: 0 | AT39: 0 | AU39: 0
A40: Prior Year Retained Earnigs | B40: 30492146 | C40: 30942146 | D40: 30942146 | E40: 38134753 | F40: 38134753 | G40: 38134753 | H40: 21503348 | I40: 21503348 | J40: 21503348 | K40: 21503295 | L40: 38134753 | M40: 47693974 | N40: 0 | O40: 0 | P40: 0 | Q40: 0 | R40: 27089696 | S40: 29196279 | T40: 29196279 | U40: 29196279 | V40: 29196279 | W40: 29196279 | X40: 29196232 | Y40: 45827684 | Z40: 39951182 | AA40: 38251182 | AB40: 36283733 | AC40: 36283693 | AD40: 36283733 | AE40: 36283733 | AF40: 36283833 | AG40: 36283833 | AH40: 36283833 | AI40: 36283833 | AJ40: 36283833 | AK40: 36283833 | AL40: 36283733 | AM40: 42219097 | AN40: 42219097 | AO40: 35587821 | AP40: 31755354 | AQ40: 31713783 | AR40: 31713725 | AS40: 32547970 | AT40: 32547970 | AU40: 32547970
A41: Current Year Surplus | B41: =-4643649+12286256.35 -> 7642607.3 | C41: 855316.06 | D41: 925234.67 | E41: 1161015.3 | F41: 1135746.2 | G41: 1001002.5 | H41: 0 | I41: 0 | J41: 0 | K41: 0 | L41: 7692930 | M41: 21503348 | N41: 27992993 | O41: 29196279 | P41: 29196279 | Q41: 29196279 | R41: 27820931 | S41: 32688113 | T41: 37997672 | U41: 43417208 | V41: 47052383 | W41: 51345032 | X41: 61129358 | Y41: =7087454.1-16631405 -> -9543950.9 | Z41: 4193655.6 | AA41: 5237610.3 | AB41: 12133302 | AC41: 17852612 | AD41: 22427625 | AE41: 25162694 | AF41: 25477436 | AG41: 32040693 | AH41: 33796411 | AI41: 36962810 | AJ41: 39182322 | AK41: 13935382 | AL41: =14259291.55-2851858.31-300000 -> 11107433 | AM41: 3274284.2 | AN41: 4711561.6 | AO41: 8960035.9 | AP41: 12624759 | AQ41: 19840040 | AR41: 23332044 | AS41: 27328372 | AT41: 32185270 | AU41: 38141805
A42: Statutory Reserves | B42: 13603823 | C42: 10532259 | D42: 10532259 | E42: 13603823 | F42: 13603823 | G42: 13603823 | H42: 0 | I42: 0 | J42: 0 | K42: 0 | L42: 15589556 | M42: 0 | N42: 0 | O42: 0 | P42: 0 | Q42: 0 | R42: 15589556 | S42: 15589556 | T42: 15589556 | U42: 15589556 | V42: 15589556 | W42: 15589556 | X42: 15589556 | Y42: 18681835 | Z42: 18278235 | AA42: 18278235 | AB42: 18681835 | AC42: 18681835 | AD42: 18681835 | AE42: 18681835 | AF42: 18681835 | AG42: 18681835 | AH42: 18681835 | AI42: 18681835 | AJ42: 18681835 | AK42: 18681835 | AL42: 21533693 | AM42: 18681835 | AN42: 18681835 | AO42: 21533694 | AP42: 21533694 | AQ42: 21533694 | AR42: 21533694 | AS42: 21533694 | AT42: 21533694 | AU42: 21533694
...

Sheet Evolutitve SCI
B2: 2019 Audited | C2: 43831 | D2: 43891 | E2: 43922 | F2: 43952 | G2: 43983 | H2: 44075 | I2: 44105 | J2: 44136 | K2: 44166 | L2: 2020 Audited | M2: 44197 | N2: 44228 | O2: 44256 | P2: 44287 | Q2: 44317 | R2: 44348 | S2: 44378 | T2: 44409 | U2: 44440 | V2: 44470 | W2: 44501 | X2: 44531 | Y2: Audited 2021 | Z2: 44562 | AA2: 44593 | AB2: 44621 | AC2: 44652 | AD2: 44682 | AE2: 44713 | AF2: 44743 | AG2: 44774 | AH2: 44805 | AI2: 44835 | AJ2: 44866 | AK2: 44896 | AL2: Audit 2022 | AM2: 44927 | AN2: 44958 | AO2: 44986 | AP2: 45017 | AQ2: 45047 | AR2: 45078 | AS2: 45108 | AT2: 45139 | AU2: 45170
A3: Financial Income | B3: =B4+B7 -> 96487681 | C3: =C4+C7 -> 12861103 | D3: =D4+D7 -> 26935221 | E3: =E4+E7 -> 34915525 | F3: =F4+F7 -> 42684260 | G3: =G4+G7 -> 50417367 | H3: =H4+H7 -> 75135052 | I3: =I4+I7 -> 84769011 | ... AU3: =AU4+AU7 -> 77624275
A4: Financial Income From Loans Portfolio | B4: =SUM(B5:B6) -> 77566990 | C4: =SUM(C5:C6) -> 7835719.5 | D4: =SUM(D5:D6) -> 21312529 | E4: =SUM(E5:E6) -> 27052029 | F4: =SUM(F5:F6) -> 32952055 | G4: =SUM(G5:G6) -> 39366821 | H4: =SUM(H5:H6) -> 59356592 | I4: =SUM(I5:I6) -> 67027324 | ... AU4: =SUM(AU5:AU6) -> 67516324
A5: Interest from Loans Portfolio | B5: 77566990 | C5: 6732613.4 | D5: 19015406 | E5: 24439884 | F5: 30141958 | G5: 35979618 | H5: 53936455 | I5: 60560876 | J5: 66932004 | K5: 72832194 | L5: 75449048 | M5: 6276569.2 | N5: 13209014 | O5: 20411142 | P5: 27727065 | Q5: 35762505 | R5: 43141143 | S5: 51508820 | T5: 59246778 | U5: 66917748 | V5: 74752209 | W5: 82125927 | X5: 90279888 | Y5: 90924708 | Z5: 7101003 | AA5: 14133425 | AB5: 22523119 | AC5: 31123896 | AD5: 39848385 | AE5: 46604783 | AF5: 50134503 | AG5: 61629315 | AH5: 66891279 | AI5: 73429223 | AJ5: 76893658 | AK5: 86721719 | AL5: 86721720 | AM5: 6924024.7 | AN5: 13986055 | AO5: 21833612 | AP5: 27929546 | AQ5: 36881736 | AR5: 44059876 | AS5: 51189565 | AT5: 58666439 | AU5: 66918164
A6: Fees&Commision on Loan Portfolio | C6: 1103106.1 | D6: 2297122.6 | E6: 2612145.2 | F6: 2810097.7 | G6: 3387203.7 | H6: 5420137.4 | I6: 6466447.1 | J6: 7466629.3 | K6: 8325578.6 | M6: 28300 | N6: 61500 | O6: 105700 | P6: 146800 | Q6: 201000 | R6: 233300 | S6: 297200 | T6: 341300 | U6: 375400 | V6: 421400 | W6: 460900 | X6: 503700 | Z6: 42200 | AA6: 76200 | AB6: 124100 | AC6: 185200 | AD6: 238900 | AE6: 274400 | AF6: 325700 | AG6: 368200 | AH6: 411600 | AI6: 456400 | AJ6: 500800 | AK6: 540900 | AL6: =534800+6100 -> 540900 | AM6: 64800 | AN6: 110000 | AO6: 168100 | AP6: 233800 | AQ6: 330600 | AR6: 402520 | AS6: 460420 | AT6: 543350 | AU6: 598160
A7: Financial Income from Investments | B7: =SUM(B8:B11) -> 18920691 | C7: =SUM(C8:C11) -> 5025383.4 | D7: =SUM(D8:D11) -> 5622692.2 | E7: =SUM(E8:E11) -> 7863496.3 | F7: =SUM(F8:F11) -> 9732204.7 | G7: =SUM(G8:G11) -> 11050546 | H7: =SUM(H8:H11) -> 15778460 | I7: =SUM(I8:I11) -> 17741687 | ... AU7: =SUM(AU8:AU11) -> 10107951
A8: Government Securities | C8: 0 | D8: 0 | E8: 0 | F8: 0 | G8: 0 | H8: 0 | I8: 0 | J8: 0 | K8: 0 | M8: 0 | N8: 0 | O8: 0 | P8: 0 | Q8: 0 | R8: 0 | S8: 0 | T8: 0 | U8: 0 | V8: 0 | W8: 0 | X8: 0 | Z8: 0 | AA8: 0 | AB8: 0 | AC8: 0 | AD8: 0 | AE8: 0 | AF8: 0 | AG8: 0 | AH8: 0 | AI8: 0 | AJ8: 0 | AK8: 0 | AM8: 0 | AN8: 0 | AO8: 0 | AP8: 0 | AQ8: 0 | AR8: 0 | AS8: 0 | AT8: 0 | AU8: 0
A9: Deposits with Banks & other Financial Institutions | B9: 516362 | C9: 0 | D9: 0 | E9: 0 | F9: 0 | G9: 0 | H9: 0 | I9: 0 | J9: 0 | K9: 0 | L9: 1050595 | M9: 0 | N9: 0 | O9: 0 | P9: 0 | Q9: 0 | R9: 0 | S9: 0 | T9: 0 | U9: 0 | V9: 0 | W9: 0 | X9: 0 | Y9: 437375 | Z9: 0 | AA9: 0 | AB9: 0 | AC9: 0 | AD9: 0 | AE9: 0 | AF9: 0 | AG9: 0 | AH9: 0 | AI9: 0 | AJ9: 0 | AK9: 0 | AL9: 1371524 | AM9: 0 | AN9: 0 | AO9: 0 | AP9: 0 | AQ9: 0 | AR9: 0 | AS9: 0 | AT9: 0 | AU9: 0
A10: Other Investments | C10: 3252227 | D10: 433399.55 | E10: 1921172.1 | F10: 1921172.1 | G10: 1921172.1 | H10: 2220703.7 | I10: 2329211.7 | J10: 2534831.6 | K10: 3101631.6 | M10: 4000 | N10: 68000 | O10: 1854300 | P10: 2045032 | Q10: 2049032 | R10: 2137032 | S10: 2619429.1 | T10: 2635685.6 | U10: 2658035.6 | V10: 2719855.6 | W10: 2748901.6 | X10: 3015901.6 | Y10: 1966684.4 | Z10: 476188 | AA10: 484243.39 | AB10: 2816325.4 | AC10: 2883125.4 | AD10: 2955625.4 | AE10: 3157351.2 | AF10: 3254299.2 | AG10: 3262299.2 | AH10: 3330299.2 | AI10: 3212618 | AJ10: 4592142 | AK10: 4609642 | AL10: 2770405 | AM10: 4000 | AN10: 249576.45 | AO10: 1086047.4 | AP10: 1094047.4 | AQ10: 3401205.5 | AR10: 3413461.9 | AS10: 3693657.3 | AT10: 3754157.3 | AU10: 3814657.3
A11: Other Operating Income | B11: 18404329 | C11: 1773156.4 | D11: 5189292.7 | E11: 5942324.3 | F11: 7811032.6 | G11: 9129374 | H11: 13557756 | I11: 15412475 | J11: 17387354 | K11: 19567528 | L11: 19530533 | M11: 491632 | N11: 1017832.5 | O11: 1955343.1 | P11: 2617278.6 | Q11: 3204313.1 | R11: 3812354.1 | S11: 4515596.1 | T11: 5211628.1 | U11: 5821971.1 | V11: 6500385.1 | W11: 7132707.6 | X11: 22199463 | Y11: =24637069-Y10 -> 22670385 | Z11: 600397.5 | AA11: 1115901.5 | AB11: 2176355 | AC11: 2906483 | AD11: 3548642.5 | AE11: 4132019.5 | AF11: 4672350.5 | AG11: 5275788 | AH11: 5913288.5 | AI11: 6503356 | AJ11: 7071293 | AK11: 20354111 | AL11: =24967374-AL10-AL31-AL6 -> 20354111 | AM11: 592917 | AN11: 1185396 | AO11: 2277281 | AP11: 2859771.5 | AQ11: 3620316.5 | AR11: 4315317 | AS11: 4928429.5 | AT11: 5579654 | AU11: 6293293.6
A12: Financial Expenses | B12: =SUM(B13:B18) -> 35880704 | C12: =SUM(C13:C18) -> 302470.65 | D12: =SUM(D13:D18) -> 741170 | E12: =SUM(E13:E18) -> 1001490.8 | F12: =SUM(F13:F18) -> 1073810.1 | G12: =SUM(G13:G18) -> 1353220.2 | H12: =SUM(H13:H18) -> 1761001.9 | I12: =SUM(I13:I18) -> 1763521.9 | ... AU12: =SUM(AU13:AU18) -> 5583916.2
A13: Interest Expense on Deposits | B13: 31410482 | C13: 302470.65 | D13: 741170 | E13: 1001490.8 | F13: 1073810.1 | G13: 1353220.2 | H13: 1761001.9 | I13: 1763521.9 | J13: 1893062.8 | K13: 13600868 | L13: 35570818 | M13: 442387.58 | N13: 587817.37 | O13: 1232932.1 | P13: 1507700.3 | Q13: 1647941 | R13: 1917672.1 | S13: 2432275.1 | T13: 2498725.1 | U13: 2812688.2 | V13: 3270822.4 | W13: 3427981.1 | X13: 3927469.2 | Y13: =3927469+39271449.75 -> 43198919 | Z13: 593702.9 | AA13: 681355.19 | AB13: 1270476.1 | AC13: 1700851.1 | AD13: 1827557.5 | AE13: 2267319.1 | AF13: 2925786.8 | AG13: 3082880.5 | AH13: 3623548.2 | AI13: 4152968.5 | AJ13: 4225431 | AK13: 5005476.4 | AL13: =38321465+5005476 -> 43326941 | AM13: 690599.48 | AN13: 892365.88 | AO13: 1448869.6 | AP13: 2115299.1 | AQ13: 2683594.8 | AR13: 3273132.2 | AS13: 3740885.9 | AT13: 4106241.5 | AU13: 4546380.4
A14: Cost of External Borrowings | B14: 4470222 | C14: 0 | D14: 0 | E14: 0 | F14: 0 | G14: 0 | H14: 0 | I14: 0 | J14: 0 | K14: 0 | L14: 6009362 | M14: 0 | N14: 0 | O14: 0 | P14: 0 | Q14: 0 | R14: 0 | S14: 0 | T14: 0 | U14: 0 | V14: 0 | W14: 0 | X14: 0 | Z14: 0 | AA14: 0 | AB14: 0 | AC14: 0 | AD14: 0 | AE14: 0 | AF14: 0 | AG14: 0 | AH14: 0 | AI14: 0 | AJ14: 0 | AK14: 0 | AL14: 0 | AM14: 0 | AN14: 0 | AO14: 0 | AP14: 0 | AQ14: 0 | AR14: 0 | AS14: 0 | AT14: 0 | AU14: 0
A15: Dividend Expenses | C15: 0 | D15: 0 | E15: 0 | F15: 0 | G15: 0 | H15: 0 | I15: 0 | J15: 0 | K15: 0 | M15: 0 | N15: 0 | O15: 0 | P15: 0 | Q15: 0 | R15: 0 | S15: 0 | T15: 0 | U15: 0 | V15: 0 | W15: 0 | X15: 0 | Z15: 0 | AA15: 0 | AB15: 0 | AC15: 0 | AD15: 0 | AE15: 0 | AF15: 0 | AG15: 0 | AH15: 0 | AI15: 0 | AJ15: 0 | AK15: 41700000 | AM15: 0 | AN15: 0 | AO15: 0 | AP15: 0 | AQ15: 0 | AR15: 0 | AS15: 0 | AT15: 0 | AU15: 0
A16: Other Financial Expense | C16: 0 | D16: 0 | E16: 0 | F16: 0 | G16: 0 | H16: 0 | I16: 0 | J16: 0 | K16: 0 | M16: 131880 | N16: 355097 | O16: 483052 | P16: 966071 | Q16: 2870704 | R16: 1210280 | S16: 1329291 | T16: 1395628 | U16: 1463518 | V16: 1520148 | W16: 1552760 | X16: 8271534 | Z16: 91980 | AA16: 261800 | AB16: 565737 | AC16: 648754 | AD16: 755094 | AE16: 810190 | AF16: 854372 | AG16: 917266 | AH16: 986906 | AI16: 1078317 | AJ16: 1230924 | AK16: 8306584 | AM16: 86958 | AN16: 130395 | AO16: 236870.5 | AP16: 301710.5 | AQ16: 383898.5 | AR16: 555561.35 | AS16: 591927.45 | AT16: 694663.95 | AU16: 751474.1
A17: Fees & Commision Expense | C17: 0 | D17: 0 | E17: 0 | F17: 0 | G17: 0 | H17: 0 | I17: 0 | J17: 0 | K17: 0 | M17: 26466.2 | N17: 68453.19 | O17: 111250.19 | P17: 151273.24 | Q17: 186207.2 | R17: 210440.17 | S17: 262942.98 | T17: 303011.98 | U17: 335003.98 | V17: 365373.98 | W17: 386287.98 | X17: 415075.99 | Z17: 27099.56 | AA17: 53942.56 | AB17: 95512.56 | AC17: 132076.56 | AD17: 166215.06 | AE17: 201955.06 | AF17: 228689.06 | AG17: 256573.06 | AH17: 283353.06 | AI17: 304714.06 | AJ17: 330109.06 | AK17: 356935.06 | AM17: 26972 | AN17: 63671 | AO17: 97616 | AP17: 133744 | AQ17: 166081.35 | AR17: 192861.35 | AS17: 192861.35 | AT17: 192861.35 | AU17: 286061.75
A18: Other Expenses | C18: 0 | D18: 0 | E18: 0 | F18: 0 | G18: 0 | H18: 0 | I18: 0 | J18: 0 | K18: 0 | M18: 0 | N18: 0 | O18: 0 | P18: 0 | Q18: 0 | R18: 0 | S18: 0 | T18: 0 | U18: 0 | V18: 0 | W18: 0 | X18: 0 | Z18: 0 | AA18: 0 | AB18: 0 | AC18: 0 | AD18: 0 | AE18: 0 | AF18: 0 | AG18: 0 | AH18: 0 | AI18: 0 | AJ18: 0 | AK18: 0 | AM18: 0 | AN18: 0 | AO18: 0 | AP18: 0 | AQ18: 0 | AR18: 0 | AS18: 0 | AT18: 0 | AU18: 0
A19: Net Financial Income | B19: =B3-B12 -> 60606977 | C19: =C3-C12 -> 12558632 | D19: =D3-D12 -> 26194051 | E19: =E3-E12 -> 33914034 | F19: =F3-F12 -> 41610450 | G19: =G3-G12 -> 49064147 | H19: =H3-H12 -> 73374050 | I19: =I3-I12 -> 83005489 | ... AU19: =AU3-AU12 -> 72040359
A20: Allowance for Loan Loss | B20: =B21-B22 -> 8663385.1 | C20: =C21-C22 -> 0 | D20: =D21-D22 -> 0 | E20: =E21-E22 -> 0 | F20: =F21-F22 -> 0 | G20: =G21-G22 -> 0 | H20: =H21-H22 -> 0 | I20: =I21-I22 -> 0 | ... AU20: =AU21-AU22 -> 0
A21: Provision for Loan Losses | B21: 8663385.1 | C21: 0 | D21: 0 | E21: 0 | F21: 0 | G21: 0 | H21: 0 | I21: 0 | J21: 0 | K21: 0 | L21: 7452358.1 | M21: 0 | N21: 0 | O21: 0 | P21: 0 | Q21: 0 | R21: 0 | S21: 0 | T21: 0 | U21: 0 | V21: 0 | W21: 0 | X21: 0 | Y21: 0 | Z21: 0 | AA21: 0 | AB21: 0 | AC21: 0 | AD21: 0 | AE21: 0 | AF21: 0 | AG21: 0 | AH21: 0 | AI21: 0 | AJ21: 0 | AK21: 0 | AL21: 236620 | AM21: 0 | AN21: 0 | AO21: 0 | AP21: 0 | AQ21: 0 | AR21: 0 | AS21: 0 | AT21: 0 | AU21: 0
A22: Value of Loans Recovered | C22: 0 | D22: 0 | E22: 0 | F22: 0 | G22: 0 | H22: 0 | I22: 0 | J22: 0 | K22: 0 | M22: 0 | N22: 0 | O22: 0 | P22: 0 | Q22: 0 | R22: 0 | S22: 0 | T22: 0 | U22: 0 | V22: 0 | W22: 0 | X22: 0 | Z22: 0 | AA22: 0 | AB22: 0 | AC22: 0 | AD22: 0 | AE22: 0 | AF22: 0 | AG22: 0 | AH22: 0 | AI22: 0 | AJ22: 0 | AK22: 0 | AM22: 0 | AN22: 0 | AO22: 0 | AP22: 0 | AQ22: 0 | AR22: 0 | AS22: 0 | AT22: 0 | AU22: 0
A23: Operating Expeses | B23: =SUM(B24:B28) -> 35085771 | C23: =SUM(C24:C28) -> 4984381.4 | D23: =SUM(D24:D28) -> 11914000 | E23: =SUM(E24:E28) -> 16787404 | F23: =SUM(F24:F28) -> 19791445 | G23: =SUM(G24:G28) -> 23674921 | H23: =SUM(H24:H28) -> 35116361 | I23: =SUM(I24:I28) -> 38375896 | ... AU23: =SUM(AU24:AU28) -> 33651434
A24: Personel Expenses | B24: 16521475 | C24: 1737585.4 | D24: 3466463 | E24: 6954219.8 | F24: 8727232 | G24: 10475187 | H24: 15979365 | I24: 17699475 | J24: 19422668 | K24: 21504192 | L24: 15472331 | M24: 1419138 | N24: 2786172 | O24: 4409173 | P24: 5741483 | Q24: 7076239 | R24: 8469272 | S24: 11691139 | T24: 13135137 | U24: 14524182 | V24: 16086302 | W24: 17655804 | X24: 21811979 | Y24: 21818016 | Z24: 1554504 | AA24: 3123651 | AB24: 4960538 | AC24: 6496777 | AD24: 8072862 | AE24: 9663433 | AF24: 11303892 | AG24: 12808755 | AH24: 14577505 | AI24: 16206438 | AJ24: 17551359 | AK24: 21136116 | AL24: 21138710 | AM24: 1553728 | AN24: 3142478 | AO24: 5044761 | AP24: 6510558 | AQ24: 8307629 | AR24: 9796180 | AS24: 11363378 | AT24: 12911179 | AU24: 14485459
A25: Governance Expenses | B25: 2991144 | C25: 330605 | D25: 1101032 | E25: 1175042 | F25: 1252637 | G25: 1477567 | H25: 1960502 | I25: 2075932 | J25: 2203217 | K25: 2498907 | L25: 2827400 | M25: 181780 | N25: 666540 | O25: 1644680 | P25: 2090790 | Q25: 2339840 | R25: 2721060 | S25: 3090290 | T25: 3524490 | U25: 3732580 | V25: 4237410 | W25: 4760370 | X25: 5147480 | Y25: 5147480 | Z25: 525510 | AA25: 1799300 | AB25: 3143690 | AC25: 3643820 | AD25: 4155980 | AE25: 4821640 | AF25: 5580700 | AG25: 6079360 | AH25: 6394820 | AI25: 6607090 | AJ25: 6715840 | AK25: 7323260 | AL25: 6623260 | AM25: 562050 | AN25: 1247750 | AO25: 2637500 | AP25: 3022180 | AQ25: 3249470 | AR25: 3904460 | AS25: 4265770 | AT25: 5237820 | AU25: 5533830
A26: Marketing Expenses | C26: 129565 | D26: 642394 | E26: 843169 | F26: 1007639 | G26: 1027519 | H26: 1518323 | I26: 1670863 | J26: 1854278 | K26: 2062618 | M26: 61950 | N26: 112500 | O26: 193160 | P26: 286580 | Q26: 410400 | R26: 493600 | S26: 524700 | T26: 615900 | U26: 668670 | V26: 707170 | W26: 793350 | X26: 842800 | Y26: 662710 | Z26: 36000 | AA26: 92020 | AB26: 114020 | AC26: 131640 | AD26: 280004 | AE26: 344724 | AF26: 399444 | AG26: 522604 | AH26: 682404 | AI26: 735604 | AJ26: 764004 | AK26: 823004 | AL26: 601564 | AM26: 53100 | AN26: 104200 | AO26: 168900 | AP26: 214820 | AQ26: 587560 | AR26: 730880 | AS26: 756680 | AT26: 773680 | AU26: 819980
A27: Depreciation and Amortization | B27: 1519419.1 | C27: 138128 | D27: 414384 | E27: 528924 | F27: 661155 | G27: 793386 | H27: 1190079 | I27: 1322310 | J27: 1454541 | K27: 1586772 | L27: 1707778.4 | M27: 0 | N27: 0 | O27: 0 | P27: 0 | Q27: 0 | R27: 0 | S27: 0 | T27: 0 | U27: 0 | V27: 0 | W27: 0 | X27: 0 | Y27: =2614259.25+154236.4 -> 2768495.6 | Z27: 0 | AA27: 0 | AB27: 0 | AC27: 0 | AD27: 0 | AE27: 0 | AF27: 0 | AG27: 0 | AH27: 0 | AI27: 0 | AJ27: 0 | AK27: 0 | AL27: =2424033.05+154236.5 -> 2578269.5 | AM27: 0 | AN27: 0 | AO27: 0 | AP27: 0 | AQ27: 0 | AR27: 0 | AS27: 0 | AT27: 0 | AU27: 0
A28: Administrative Expenses | B28: 14053733 | C28: 2648498 | D28: 6289727 | E28: 7286049 | F28: 8142781.6 | G28: 9901262.6 | H28: 14468092 | I28: 15607316 | J28: 17023013 | K28: 20159602 | L28: 15261465 | M28: 583667 | N28: 2765111.9 | O28: 4736903.1 | P28: 4853713.6 | Q28: 5593663 | R28: 6417073.5 | S28: 6831794.5 | T28: 7844327.4 | U28: 8678803.9 | V28: 11000740 | W28: 12375351 | X28: 14266757 | Y28: =25104844.7-Y26 -> 24442135 | Z28: 1165336.5 | AA28: 4506090.9 | AB28: 5302623 | AC28: 6430173.8 | AD28: 8816714.8 | AE28: 10774098 | AF28: 11463912 | AG28: 14665850 | AH28: 16020899 | AI28: 17351035 | AJ28: 18845284 | AK28: 13423994 | AL28: =24191301.9-AL26 -> 23589738 | AM28: 1324050 | AN28: 5212606 | AO28: 6716487 | AP28: 7111095 | AQ28: 8888584 | AR28: 10233056 | AS28: 11841198 | AT28: 12221764 | AU28: 12812165
A29: Net Operating Income | B29: =B19-B20-B23 -> 16857820 | C29: =C19-C20-C23 -> 7574250.8 | D29: =D19-D20-D23 -> 14280051 | E29: =E19-E20-E23 -> 17126631 | F29: =F19-F20-F23 -> 21819006 | G29: =G19-G20-G23 -> 25389226 | H29: =H19-H20-H23 -> 38257689 | I29: =I19-I20-I23 -> 44629593 | ... AU29: =AU19-AU20-AU23 -> 38388925
A30: Net Non operating Income/Expense | B30: =B31-B32 -> 0 | C30: =C31-C32 -> 0 | D30: =D31-D32 -> 0 | E30: =E31-E32 -> 0 | F30: =F31-F32 -> 0 | G30: =G31-G32 -> 0 | H30: =H31-H32 -> 0 | I30: =I31-I32 -> 0 | ... AR30: =AR31-AR32 -> 0
A31: Non Operating Income | C31: 0 | D31: 0 | E31: 0 | F31: 0 | G31: 0 | H31: 0 | I31: 0 | J31: 0 | K31: 0 | M31: 0 | N31: 0 | O31: 0 | P31: 0 | Q31: 0 | R31: 0 | S31: 0 | T31: 0 | U31: 0 | V31: 0 | W31: 0 | X31: 0 | Z31: 0 | AA31: 0 | AB31: 0 | AC31: 0 | AD31: 0 | AE31: 0 | AF31: 0 | AG31: 0 | AH31: 0 | AL31: 1301958 | AM31: 0 | AN31: 0 | AO31: 0 | AP31: 0 | AQ31: 0 | AR31: 0 | AS31: 0 | AT31: 0 | AU31: 0
A32: Non Operating Expense | C32: 0 | D32: 0 | E32: 0 | F32: 0 | G32: 0 | H32: 0 | I32: 0 | J32: 0 | K32: 0 | M32: 0 | N32: 0 | O32: 0 | P32: 0 | Q32: 0 | R32: 0 | S32: 0 | T32: 0 | U32: 0 | V32: 0 | W32: 0 | X32: 0 | Z32: 0 | AA32: 0 | AB32: 0 | AC32: 0 | AD32: 0 | AE32: 0 | AF32: 0 | AG32: 0 | AH32: 0 | AM32: 0 | AN32: 0 | AO32: 0 | AP32: 0 | AQ32: 0 | AR32: 0 | AS32: 0 | AT32: 0 | AU32: 0
A33: Net Income(Before Tax & Donations) | B33: =B29+B30 -> 16857820 | C33: =C29+C30 -> 7574250.8 | D33: =D29+D30 -> 14280051 | E33: =E29+E30 -> 17126631 | F33: =F29+F30 -> 21819006 | G33: =G29+G30 -> 25389226 | H33: =H29+H30 -> 38257689 | I33: =I29+I30 -> 44629593 | ... AU33: =AU29+AU30 -> 38388925
A34: Taxes | C34: 0 | D34: 0 | E34: 271967 | F34: 150000 | G34: 300000 | H34: 450000 | I34: 450000 | J34: 450000 | K34: 600000 | P34: 0 | Q34: 0 | R34: 0 | S34: 0 | T34: 0 | U34: 140500 | V34: 153500 | W34: 171500 | X34: 186500 | Y34: 2500000 | AF34: 0 | AG34: 0 | AH34: 0 | AL34: 706224 | AM34: 0 | AN34: 0 | AO34: 0 | AP34: 0 | AQ34: 0 | AR34: 0 | AS34: 0 | AT34: 0 | AU34: 0
A35: Net Income(After Tax Before Donations) | B35: =B33-B34 -> 16857820 | C35: =C33-C34 -> 7574250.8 | D35: =D33-D34 -> 14280051 | E35: =E33-E34 -> 16854664 | F35: =F33-F34 -> 21669006 | G35: =G33-G34 -> 25089226 | H35: =H33-H34 -> 37807689 | I35: =I33-I34 -> 44179593 | ... AU35: =AU33-AU34 -> 38388925
A36: Donations | C36: 0 | D36: 0 | E36: 0 | F36: 0 | G36: 0 | H36: 0 | I36: 0 | J36: 0 | K36: 0 | M36: 13000 | N36: 22500 | O36: 33500 | P36: 37500 | Q36: 37500 | R36: 63500 | S36: 90500 | T36: 120500 | Z36: 32000 | AA36: 54000 | AB36: 54000 | AC36: 62000 | AD36: 89500 | AE36: 122500 | AF36: 152620 | AG36: 161620 | AH36: 180620 | AI36: 202620 | AJ36: 212620 | AK36: 215620 | AM36: 14000 | AN36: 26000 | AO36: 54000 | AP36: 83000 | AQ36: 127000 | AR36: 173000 | AS36: 191000 | AT36: 220120 | AU36: 247120
A37: Net Income/(After Tax & Donations) | B37: =B35-B36 -> 16857820 | C37: =C35-C36 -> 7574250.8 | D37: =D35-D36 -> 14280051 | E37: =E35-E36 -> 16854664 | F37: =F35-F36 -> 21669006 | G37: =G35-G36 -> 25089226 | H37: =H35-H36 -> 37807689 | I37: =I35-I36 -> 44179593 | ... AU37: =AU35-AU36 -> 38141805
A39: Total Expenses | B39: =B12+B23 -> 70966475 | C39: =C12+C23 -> 5286852.1 | D39: =D12+D23 -> 12655170 | E39: =E12+E23 -> 17788895 | F39: =F12+F23 -> 20865255 | G39: =G12+G23 -> 25028141 | H39: =H12+H23 -> 36877363 | I39: =I12+I23 -> 40139418 | ... AP39: =AP12+AP23 -> 19409407

Sheet Financials
A1: PTIMETIME
A2: Year | B2: 2012 Audited | C2: 2019 Audited | D2: 43831 | E2: 43891 | F2: 43922 | G2: 43952 | H2: 43983 | I2: 44075 | J2: 44105 | K2: 44136 | L2: 44166 | M2: Audited 2020 | N2: 44197 | O2: 44228 | P2: 44256 | Q2: 44287 | R2: 44317 | S2: 44348 | T2: 44378 | U2: 44409 | V2: 44440 | W2: 44470 | X2: 44501 | Y2: 44531 | Z2: Audited 2021 | AA2: 44562 | AB2: 44593 | AC2: 44621 | AD2: 44652 | AE2: 44682 | AF2: 44713 | AG2: 44743 | AH2: 44774 | AI2: 44805 | AJ2: 44835 | AK2: 44866 | AL2: 44896 | AM2: Audit 2022 | AN2: 44927 | AO2: 44958 | AP2: 44986 | AQ2: 45017 | AR2: 45047 | AS2: 45078 | AT2: 45108 | AU2: 45139 | AV2: 45170 | AW2: 45200 | AX2: 45231 | AY2: 45261
A3: Membership | M3: 3462 | Z3: 4013 | AM3: 4324
A4: Total Assets | B4: ='Evolutive SFP'!B26 -> 616749916 | C4: ='Evolutive SFP'!B26 -> 616749916 | D4: ='Evolutive SFP'!C26 -> 7.6180704e+08 | E4: ='Evolutive SFP'!D26 -> 7.6615477e+08 | F4: ='Evolutive SFP'!E26 -> 7.5549346e+08 | G4: ='Evolutive SFP'!F26 -> 7.5578154e+08 | H4: ='Evolutive SFP'!G26 -> 7.5259093e+08 | I4: ='Evolutive SFP'!H26 -> 7.5366684e+08 | J4: ='Evolutive SFP'!I26 -> 7.5672257e+08 | ... AY4: ='Evolutive SFP'!AX26 -> 0
A5: Total Deposits | B5: ='Evolutive SFP'!B30 -> 574156047 | C5: ='Evolutive SFP'!B30 -> 574156047 | D5: ='Evolutive SFP'!C30 -> 5.6774807e+08 | E5: ='Evolutive SFP'!D30 -> 582138061 | F5: ='Evolutive SFP'!E30 -> 5.9450076e+08 | G5: ='Evolutive SFP'!F30 -> 5.9384504e+08 | H5: ='Evolutive SFP'!G30 -> 5.9183523e+08 | I5: ='Evolutive SFP'!H30 -> 6.0997234e+08 | J5: ='Evolutive SFP'!I30 -> 6.1168659e+08 | ... AY5: ='Evolutive SFP'!AX30 -> 0
A6: Deposits-Members(BOSA) | B6: ='Evolutive SFP'!B29 -> 418806431 | C6: ='Evolutive SFP'!B29 -> 418806431 | D6: ='Evolutive SFP'!C29 -> 4.2198244e+08 | E6: ='Evolutive SFP'!D29 -> 427325266 | F6: ='Evolutive SFP'!E29 -> 4.2916071e+08 | G6: ='Evolutive SFP'!F29 -> 4.3220893e+08 | H6: ='Evolutive SFP'!G29 -> 4.3426279e+08 | I6: ='Evolutive SFP'!H29 -> 4.4005123e+08 | J6: ='Evolutive SFP'!I29 -> 4.4155717e+08 | ... AY6: ='Evolutive SFP'!AX29 -> 0
A7: Deposits-Customers(FOSA) | B7: =('Evolutive SFP'!B27+'Evolutive SFP'!B28) -> 155349616 | C7: ='Evolutive SFP'!B27 -> 127986727 | D7: ='Evolutive SFP'!C27 -> 97743215 | E7: ='Evolutive SFP'!D27 -> 103735571 | F7: ='Evolutive SFP'!E27 -> 1.130541e+08 | G7: ='Evolutive SFP'!F27 -> 1.0809158e+08 | H7: ='Evolutive SFP'!G27 -> 1.0286644e+08 | I7: ='Evolutive SFP'!H27 -> 1.1367251e+08 | J7: ='Evolutive SFP'!I27 -> 1.1411871e+08 | ... AY7: ='Evolutive SFP'!AX27 -> 0
A8: External Borrowing | B8: ='Evolutive SFP'!B36 -> 30000000 | C8: ='Evolutive SFP'!B36 -> 30000000 | D8: ='Evolutive SFP'!C36 -> 26040073 | E8: ='Evolutive SFP'!D36 -> 20587500 | F8: ='Evolutive SFP'!E36 -> 19480080 | G8: ='Evolutive SFP'!F36 -> 16342580 | H8: ='Evolutive SFP'!G36 -> 13205080 | I8: ='Evolutive SFP'!H36 -> 3792579.8 | J8: ='Evolutive SFP'!I36 -> 2197660.8 | ... AY8: ='Evolutive SFP'!AX36 -> 0
A10: Share capital and Reserves
A11: Core Capital | B11: =B14-B22-B25 -> 1.0901772e+08 | C11: =C14-C22 -> 1.1823935e+08 | D11: =D14-D22 -> 1.0884299e+08 | E11: =E14-E22 -> 1.0890701e+08 | F11: =F14-F22 -> 1.1940696e+08 | G11: =G14-G22 -> 1.1938169e+08 | H11: =H14-H22 -> 1.1924695e+08 | I11: =I14-I22 -> 84538672 | J11: =J14-J22 -> 84539172 | ... Y11: =Y14-Y22 -> 1.8225903e+08 | Z11: =Z14-Z27 -> 1.3123846e+08 | AA11: =AA14-AA27 -> 1.2954533e+08 | AB11: =AB14-AB27 -> 1.2889079e+08 | AC11: =AC14-AC27 -> 1.3411186e+08 | AD11: =AD14-AD27 -> 1.3983113e+08 | AE11: =AE14-AE27 -> 1.4440618e+08 | AF11: =AF14-AF27 -> 1.4714125e+08 | AG11: =AG14-AG27 -> 1.474561e+08 | ... AY11: =AY14-AY27 -> 25
A12: Institutional Capital | B12: =B11-B15 -> 60253029 | C12: =C11-C15 -> 69474660 | D12: =D11-D15 -> 60065805 | E12: =E11-E15 -> 60135724 | F12: =F11-F15 -> 70635675 | G12: =G11-G15 -> 70610406 | H12: =H11-H15 -> 70475662 | I12: =I11-I15 -> 35107171 | ... AY12: =AY11-AY15 -> 25
A14: Total Capital | B14: =B15+B16+B17+B18+B19+B20+B21 -> 1.1823935e+08 | C14: =C15+C16+C17+C18+C19+C20+C21 -> 1.1823935e+08 | D14: =D15+D16+D17+D18+D19+D20+D21 -> 1.0884299e+08 | E14: =E15+E16+E17+E18+E19+E20+E21 -> 1.0890701e+08 | F14: =F15+F16+F17+F18+F19+F20+F21 -> 1.1940696e+08 | G14: =G15+G16+G17+G18+G19+G20+G21 -> 1.1938169e+08 | H14: =H15+H16+H17+H18+H19+H20+H21 -> 1.1924695e+08 | I14: =I15+I16+I17+I18+I19+I20+I21 -> 84538672 | ... AY14: =AY15+AY16+AY17+AY18+AY19+AY20+AY21 -> 25
A15: Members Share Capital | B15: ='Evolutive SFP'!B38 -> 48764688 | C15: ='Evolutive SFP'!B38 -> 48764688 | D15: ='Evolutive SFP'!C38 -> 48777188 | E15: ='Evolutive SFP'!D38 -> 48771288 | F15: ='Evolutive SFP'!E38 -> 48771288 | G15: ='Evolutive SFP'!F38 -> 48771288 | H15: ='Evolutive SFP'!G38 -> 48771288 | I15: ='Evolutive SFP'!H38 -> 49431500 | J15: ='Evolutive SFP'!I38 -> 49432000 | ... AY15: ='Evolutive SFP'!AX38 -> 0
A16: Entrance Fees
A17: Retained Earnings | B17: ='Evolutive SFP'!B40 -> 30492146 | C17: ='Evolutive SFP'!B40 -> 30492146 | D17: ='Evolutive SFP'!C40 -> 30942146 | E17: ='Evolutive SFP'!D40 -> 30942146 | F17: ='Evolutive SFP'!E40 -> 38134753 | G17: ='Evolutive SFP'!F40 -> 38134753 | H17: ='Evolutive SFP'!G40 -> 38134753 | I17: ='Evolutive SFP'!H40 -> 21503348 | J17: ='Evolutive SFP'!I40 -> 21503348 | ... AY17: ='Evolutive SFP'!AX40 -> 0
A18: Appropriation Account | B18: ='Evolutive SFP'!B41 -> 7642607.3 | C18: ='Evolutive SFP'!B41 -> 7642607.3 | D18: ='Evolutive SFP'!C41 -> 855316.06 | E18: ='Evolutive SFP'!D41 -> 925234.67 | F18: ='Evolutive SFP'!E41 -> 1161015.3 | G18: ='Evolutive SFP'!F41 -> 1135746.2 | H18: ='Evolutive SFP'!G41 -> 1001002.5 | I18: ='Evolutive SFP'!H41 -> 0 | J18: ='Evolutive SFP'!I41 -> 0 | ... AY18: ='Evolutive SFP'!AX41 -> 0
A19: Statutory Reserves | B19: ='Evolutive SFP'!B42 -> 13603823 | C19: ='Evolutive SFP'!B42 -> 13603823 | D19: ='Evolutive SFP'!C42 -> 10532259 | E19: ='Evolutive SFP'!D42 -> 10532259 | F19: ='Evolutive SFP'!E42 -> 13603823 | G19: ='Evolutive SFP'!F42 -> 13603823 | H19: ='Evolutive SFP'!G42 -> 13603823 | I19: ='Evolutive SFP'!H42 -> 0 | J19: ='Evolutive SFP'!I42 -> 0 | ... AY19: ='Evolutive SFP'!AX42 -> 0
A20: Capital Reserves | B20: =('Evolutive SFP'!B43) -> 17736084 | C20: ='Evolutive SFP'!B43 -> 17736084 | D20: ='Evolutive SFP'!C43 -> 17736084 | E20: ='Evolutive SFP'!D43 -> 17736084 | F20: ='Evolutive SFP'!E43 -> 17736084 | G20: ='Evolutive SFP'!F43 -> 17736084 | H20: ='Evolutive SFP'!G43 -> 17736084 | I20: ='Evolutive SFP'!H43 -> 13603823 | J20: ='Evolutive SFP'!I43 -> 13603823 | ... AY20: ='Evolutive SFP'!AX43 -> 0
A21: Supplementary Capital & reserves | B21: =B22+B23 -> 0 | C21: =C22+C23 -> 0 | D21: =D22+D23 -> 0 | E21: =E22+E23 -> 0 | F21: =F22+F23 -> 0 | G21: =G22+G23 -> 0 | H21: =H22+H23 -> 0 | I21: =I22+I23 -> 0 | ... Y21: =Y22+Y23 -> 0 | Z21: 0 | AA21: 1 | AB21: 2 | AC21: 3 | AD21: 4 | AE21: 5 | AF21: 6 | AG21: 7 | AH21: 8 | AI21: 9 | AJ21: 10 | AK21: 11 | AL21: 12 | AM21: 13 | AN21: 14 | AO21: 15 | AP21: 16 | AQ21: 17 | AR21: 18 | AS21: 19 | AT21: 20 | AU21: 21 | AV21: 22 | AW21: 23 | AX21: 24 | AY21: 25
A22: Proposed Dividends | B22: ='Evolutive SFP'!B45 -> 0 | C22: ='Evolutive SFP'!B45 -> 0 | D22: ='Evolutive SFP'!C45 -> 0 | E22: ='Evolutive SFP'!D45 -> 0 | F22: ='Evolutive SFP'!E45 -> 0 | G22: ='Evolutive SFP'!F45 -> 0 | H22: ='Evolutive SFP'!G45 -> 0 | I22: ='Evolutive SFP'!H45 -> 0 | J22: ='Evolutive SFP'!I45 -> 0 | ... AY22: ='Evolutive SFP'!AX45 -> 0
A23: Risk Mgt Fund
A25: Investments | B25: =B26+B27+B28 -> 9221631 | C25: =C26+C27+C28 -> 9221631 | D25: =D26+D27+D28 -> 57779478 | E25: =E26+E27+E28 -> 58489478 | F25: =F26+F27+F28 -> 59744505 | G25: =G26+G27+G28 -> 60099478 | H25: =H26+H27+H28 -> 60454478 | I25: =I26+I27+I28 -> 61519478 | ... AY25: =AY26+AY27+AY28 -> 0
A26: Shares in Kusco,CIC,Coop Bank | B26: ='Evolutive SFP'!B12 -> 0 | C26: ='Evolutive SFP'!B11 -> 9221631 | D26: ='Evolutive SFP'!C11 -> 48557847 | E26: ='Evolutive SFP'!D11 -> 49267847 | F26: ='Evolutive SFP'!E11 -> 50522874 | G26: ='Evolutive SFP'!F11 -> 50877847 | H26: ='Evolutive SFP'!G11 -> 51232847 | I26: ='Evolutive SFP'!H11 -> 52297847 | J26: ='Evolutive SFP'!I11 -> 53552847 | ... AY26: ='Evolutive SFP'!AX11 -> 0
A27: Equity Investments (at cost) | B27: ='Evolutive SFP'!B10 -> 0 | C27: ='Evolutive SFP'!B12 -> 0 | D27: ='Evolutive SFP'!C12 -> 9221631 | E27: ='Evolutive SFP'!D12 -> 9221631 | F27: ='Evolutive SFP'!E12 -> 9221631 | G27: ='Evolutive SFP'!F12 -> 9221631 | H27: ='Evolutive SFP'!G12 -> 9221631 | I27: ='Evolutive SFP'!H12 -> 9221631.3 | J27: ='Evolutive SFP'!I12 -> 9221631.3 | ... AY27: ='Evolutive SFP'!AX12 -> 0
A28: Deposits in KUSCCO CFP | B28: ='Evolutive SFP'!B11 -> 9221631
A30: Net Loans & Advances | B30: ='Evolutive SFP'!B13 -> 360423402 | C30: ='Evolutive SFP'!B13 -> 360423402 | D30: ='Evolutive SFP'!C13 -> 3.5757131e+08 | E30: ='Evolutive SFP'!D13 -> 3.4700111e+08 | F30: ='Evolutive SFP'!E13 -> 340745739 | G30: ='Evolutive SFP'!F13 -> 331981703 | H30: ='Evolutive SFP'!G13 -> 324174103 | I30: ='Evolutive SFP'!H13 -> 3.2941099e+08 | J30: ='Evolutive SFP'!I13 -> 3.361167e+08 | ... AY30: ='Evolutive SFP'!AX13 -> 0
A31: Gross Loans & advances | B31: ='Evolutive SFP'!B14 -> 369086787 | C31: ='Evolutive SFP'!B14 -> 369086787 | D31: ='Evolutive SFP'!C14 -> 366682836 | E31: ='Evolutive SFP'!D14 -> 3.5626197e+08 | F31: ='Evolutive SFP'!E14 -> 350006594 | G31: ='Evolutive SFP'!F14 -> 341242558 | H31: ='Evolutive SFP'!G14 -> 333434958 | I31: ='Evolutive SFP'!H14 -> 3.496496e+08 | J31: ='Evolutive SFP'!I14 -> 3.5635532e+08 | ... AY31: ='Evolutive SFP'!AX14 -> 0
A32: Allowance for loan losses | B32: ='Evolutive SFP'!B15 -> 8663385 | C32: ='Evolutive SFP'!B15 -> 8663385 | D32: ='Evolutive SFP'!C15 -> 9111524.9 | E32: ='Evolutive SFP'!D15 -> 9260855 | F32: ='Evolutive SFP'!E15 -> 9260855 | G32: ='Evolutive SFP'!F15 -> 9260855 | H32: ='Evolutive SFP'!G15 -> 9260855 | I32: ='Evolutive SFP'!H15 -> 20238613 | J32: ='Evolutive SFP'!I15 -> 20238613 | ... AY32: ='Evolutive SFP'!AX15 -> 0
A34: Non-Earning Assets | B34: ='Evolutive SFP'!B20+'Evolutive SFP'!B7 -> 71554902 | C34: ='Evolutive SFP'!B7+'Evolutive SFP'!B16+'Evolutive SFP'!B20 -> 71554902 | D34: ='Evolutive SFP'!C7+'Evolutive SFP'!C16+'Evolutive SFP'!C20 -> 2.3070485e+08 | E34: ='Evolutive SFP'!D7+'Evolutive SFP'!D16+'Evolutive SFP'!D20 -> 2.3527879e+08 | F34: ='Evolutive SFP'!E7+'Evolutive SFP'!E16+'Evolutive SFP'!E20 -> 2.3709362e+08 | G34: ='Evolutive SFP'!F7+'Evolutive SFP'!F16+'Evolutive SFP'!F20 -> 2.3769879e+08 | H34: ='Evolutive SFP'!G7+'Evolutive SFP'!G16+'Evolutive SFP'!G20 -> 2.1925861e+08 | I34: ='Evolutive SFP'!H7+'Evolutive SFP'!H16+'Evolutive SFP'!H20 -> 2.335207e+08 | J34: ='Evolutive SFP'!I7+'Evolutive SFP'!I16+'Evolutive SFP'!I20 -> 2.344482e+08 | ... AY34: ='Evolutive SFP'!AX7+'Evolutive SFP'!AX16+'Evolutive SFP'!AX20 -> 0
A35: Property and Equipment | B35: ='Evolutive SFP'!B22 -> 23963774 | C35: ='Evolutive SFP'!B22 -> 23963774 | D35: ='Evolutive SFP'!C22 -> 22863775 | E35: ='Evolutive SFP'!D22 -> 22863775 | F35: ='Evolutive SFP'!E22 -> 22863775 | G35: ='Evolutive SFP'!F22 -> 22863775 | H35: ='Evolutive SFP'!G22 -> 22863775 | I35: ='Evolutive SFP'!H22 -> 23946128 | J35: ='Evolutive SFP'!I22 -> 24674503 | ... AY35: ='Evolutive SFP'!AX22 -> 0
A37: Turnover | B37: =B38+B39+B40+B41 -> #REF! | C37: =C38+C39+C40+C41 -> 96487681 | D37: =D38+D39+D40+D41 -> 12861103 | E37: =E38+E39+E40+E41 -> 26935221 | F37: =F38+F39+F40+F41 -> 34915525 | G37: =G38+G39+G40+G41 -> 42684260 | H37: =H38+H39+H40+H41 -> 50417367 | I37: =I38+I39+I40+I41 -> 75135052 | ... AY37: =AY38+AY39+AY40+AY41 -> 0
A38: Loan Interest | B38: ='Evolutitve SCI'!#REF! -> #REF! | C38: ='Evolutitve SCI'!B5 -> 77566990 | D38: ='Evolutitve SCI'!C5 -> 6732613.4 | E38: ='Evolutitve SCI'!D5 -> 19015406 | F38: ='Evolutitve SCI'!E5 -> 24439884 | G38: ='Evolutitve SCI'!F5 -> 30141958 | H38: ='Evolutitve SCI'!G5 -> 35979618 | I38: ='Evolutitve SCI'!H5 -> 53936455 | J38: ='Evolutitve SCI'!I5 -> 60560876 | ... AY38: ='Evolutitve SCI'!AX5 -> 0
A39: Income from investments | B39: ='Evolutitve SCI'!#REF! -> #REF! | C39: ='Evolutitve SCI'!B7 -> 18920691 | D39: ='Evolutitve SCI'!C7 -> 5025383.4 | E39: ='Evolutitve SCI'!D7 -> 5622692.2 | F39: ='Evolutitve SCI'!E7 -> 7863496.3 | G39: ='Evolutitve SCI'!F7 -> 9732204.7 | H39: ='Evolutitve SCI'!G7 -> 11050546 | I39: ='Evolutitve SCI'!H7 -> 15778460 | J39: ='Evolutitve SCI'!I7 -> 17741687 | ... AY39: ='Evolutitve SCI'!AX7 -> 0
A40: Fees & Commissions | B40: ='Evolutitve SCI'!#REF! -> #REF! | C40: ='Evolutitve SCI'!B6 -> 0 | D40: ='Evolutitve SCI'!C6 -> 1103106.1 | E40: ='Evolutitve SCI'!D6 -> 2297122.6 | F40: ='Evolutitve SCI'!E6 -> 2612145.2 | G40: ='Evolutitve SCI'!F6 -> 2810097.7 | H40: ='Evolutitve SCI'!G6 -> 3387203.7 | I40: ='Evolutitve SCI'!H6 -> 5420137.4 | J40: ='Evolutitve SCI'!I6 -> 6466447.1 | ... AY40: ='Evolutitve SCI'!AX6 -> 0
A41: Average yield on loans
A43: Financial and Operating costs | B43: =SUM(B44:B47) -> #REF! | C43: =SUM(C44:C47) -> 70966475 | D43: =SUM(D44:D47) -> 5286852.1 | E43: =SUM(E44:E47) -> 12655170 | F43: =SUM(F44:F47) -> 17788895 | G43: =SUM(G44:G47) -> 20865255 | H43: =SUM(H44:H47) -> 25028141 | I43: =SUM(I44:I47) -> 36877363 | ... AY43: =SUM(AY44:AY47) -> 0
A44: Interest expense on deposits | B44: ='Evolutitve SCI'!#REF!+'Evolutitve SCI'!#REF! -> #REF! | C44: ='Evolutitve SCI'!B13+'Evolutitve SCI'!B16 -> 31410482 | D44: ='Evolutitve SCI'!C13+'Evolutitve SCI'!C16 -> 302470.65 | E44: ='Evolutitve SCI'!D13+'Evolutitve SCI'!D16 -> 741170 | F44: ='Evolutitve SCI'!E13+'Evolutitve SCI'!E16 -> 1001490.8 | G44: ='Evolutitve SCI'!F13+'Evolutitve SCI'!F16 -> 1073810.1 | H44: ='Evolutitve SCI'!G13+'Evolutitve SCI'!G16 -> 1353220.2 | I44: ='Evolutitve SCI'!H13+'Evolutitve SCI'!H16 -> 1761001.9 | J44: ='Evolutitve SCI'!I13+'Evolutitve SCI'!I16 -> 1763521.9 | ... AY44: ='Evolutitve SCI'!AX13+'Evolutitve SCI'!AX16 -> 0
A45: Dividend expense on share capital | B45: ='Evolutitve SCI'!#REF! -> #REF! | C45: ='Evolutitve SCI'!B15 -> 0 | D45: ='Evolutitve SCI'!C15 -> 0 | E45: ='Evolutitve SCI'!D15 -> 0 | F45: ='Evolutitve SCI'!E15 -> 0 | G45: ='Evolutitve SCI'!F15 -> 0 | H45: ='Evolutitve SCI'!G15 -> 0 | I45: ='Evolutitve SCI'!H15 -> 0 | J45: ='Evolutitve SCI'!I15 -> 0 | ... AY45: ='Evolutitve SCI'!AX15 -> 0
A46: Interest expense on borrowed funds | B46: ='Evolutitve SCI'!#REF! -> #REF! | C46: ='Evolutitve SCI'!B14 -> 4470222 | D46: ='Evolutitve SCI'!C14 -> 0 | E46: ='Evolutitve SCI'!D14 -> 0 | F46: ='Evolutitve SCI'!E14 -> 0 | G46: ='Evolutitve SCI'!F14 -> 0 | H46: ='Evolutitve SCI'!G14 -> 0 | I46: ='Evolutitve SCI'!H14 -> 0 | J46: ='Evolutitve SCI'!I14 -> 0 | ... AY46: ='Evolutitve SCI'!AX14 -> 0
A47: Opperating expenses | B47: ='Evolutitve SCI'!#REF! -> #REF! | C47: ='Evolutitve SCI'!B23 -> 35085771 | D47: ='Evolutitve SCI'!C23 -> 4984381.4 | E47: ='Evolutitve SCI'!D23 -> 11914000 | F47: ='Evolutitve SCI'!E23 -> 16787404 | G47: ='Evolutitve SCI'!F23 -> 19791445 | H47: ='Evolutitve SCI'!G23 -> 23674921 | I47: ='Evolutitve SCI'!H23 -> 35116361 | J47: ='Evolutitve SCI'!I23 -> 38375896 | ... AY47: ='Evolutitve SCI'!AX23 -> 0

Sheet CAELS
A1: PRIMETIME
D2: 2019 Audited | E2: 43831 | F2: 43891 | G2: 43922 | H2: 43952 | I2: 43983 | J2: 44075 | K2: 44105 | L2: 44136 | M2: 44166 | N2: Audited 2020 | O2: 44197 | P2: 44228 | Q2: 44256 | R2: 44287 | S2: 44317 | T2: 44348 | U2: 44378 | V2: 44409 | W2: 44440 | X2: 44470 | Y2: 44501 | Z2: 44531 | AA2: Audited 2021 | AB2: 44562 | AC2: 44593 | AD2: 44621 | AE2: 44652 | AF2: 44682 | AG2: 44713 | AH2: 44743 | AI2: 44774 | AJ2: 44805 | AK2: 44835 | AL2: 44866 | AM2: 44896 | AN2: Audit 2022 | AO2: 44927 | AP2: 44958 | AQ2: 44986 | AR2: 45017 | AS2: 45047 | AT2: 45078 | AU2: 45108 | AV2: 45139 | AW2: 45170 | AX2: 45200 | AY2: 45231 | AZ2: 45261
A3: CAPITAL ADEQUACY | B3: Core Capital | C3: 10 M | D3: =(('Evolutive SFP'!B38+'Evolutive SFP'!B39+'Evolutive SFP'!B40+'Evolutive SFP'!B41+'Evolutive SFP'!B42+'Evolutive SFP'!B43)-'Evolutive SFP'!B12)/1000000 -> 118.23935 | E3: =(('Evolutive SFP'!C38+'Evolutive SFP'!C39+'Evolutive SFP'!C40+'Evolutive SFP'!C41+'Evolutive SFP'!C42+'Evolutive SFP'!C43)-'Evolutive SFP'!C12)/1000000 -> 99.621362 | F3: =(('Evolutive SFP'!D38+'Evolutive SFP'!D39+'Evolutive SFP'!D40+'Evolutive SFP'!D41+'Evolutive SFP'!D42+'Evolutive SFP'!D43)-'Evolutive SFP'!D12)/1000000 -> 99.685381 | G3: =(('Evolutive SFP'!E38+'Evolutive SFP'!E39+'Evolutive SFP'!E40+'Evolutive SFP'!E41+'Evolutive SFP'!E42+'Evolutive SFP'!E43)-'Evolutive SFP'!E12)/1000000 -> 110.18533 | H3: =(('Evolutive SFP'!F38+'Evolutive SFP'!F39+'Evolutive SFP'!F40+'Evolutive SFP'!F41+'Evolutive SFP'!F42+'Evolutive SFP'!F43)-'Evolutive SFP'!F12)/1000000 -> 110.16006 | I3: =(('Evolutive SFP'!G38+'Evolutive SFP'!G39+'Evolutive SFP'!G40+'Evolutive SFP'!G41+'Evolutive SFP'!G42+'Evolutive SFP'!G43)-'Evolutive SFP'!G12)/1000000 -> 110.02532 | J3: =(('Evolutive SFP'!H38+'Evolutive SFP'!H39+'Evolutive SFP'!H40+'Evolutive SFP'!H41+'Evolutive SFP'!H42+'Evolutive SFP'!H43)-'Evolutive SFP'!H12)/1000000 -> 75.31704 | K3: =(('Evolutive SFP'!I38+'Evolutive SFP'!I39+'Evolutive SFP'!I40+'Evolutive SFP'!I41+'Evolutive SFP'!I42+'Evolutive SFP'!I43)-'Evolutive SFP'!I12)/1000000 -> 75.31754 | ... AZ3: =(('Evolutive SFP'!AX38+'Evolutive SFP'!AX39+'Evolutive SFP'!AX40+'Evolutive SFP'!AX41+'Evolutive SFP'!AX42+'Evolutive SFP'!AX43)-'Evolutive SFP'!AX12)/1000000 -> 0
B4: CCA | C4: Min 10% | D4: =D3/(('Evolutive SFP'!B26)/1000000) -> 0.1917136 | E4: =E3/(('Evolutive SFP'!C26)/1000000) -> 0.13076981 | F4: =F3/(('Evolutive SFP'!D26)/1000000) -> 0.13011128 | G4: =G3/(('Evolutive SFP'!E26)/1000000) -> 0.14584551 | H4: =H3/(('Evolutive SFP'!F26)/1000000) -> 0.14575649 | I4: =I3/(('Evolutive SFP'!G26)/1000000) -> 0.14619538 | J4: =J3/(('Evolutive SFP'!H26)/1000000) -> 0.09993413 | K4: =K3/(('Evolutive SFP'!I26)/1000000) -> 0.099531246 | ... AZ4: =AZ3/(('Evolutive SFP'!AX26)/1000000) -> #DIV/0!
