Workbook

Sheet Evolutitve SCI
B2: 2010 Audited | C2: 2020 Audited | D2: 44197 | E2: 44229 | F2: 44258 | G2: 44290 | H2: 44321 | I2: 44353 | J2: 44384 | K2: 44416 | L2: 44448 | M2: 44479 | N2: 44511 | O2: 44542 | P2: Audited 2021 | Q2: 44562 | R2: 44593 | S2: 44621 | T2: 44652 | U2: 44682 | V2: 44713 | W2: 44743 | X2: 44774 | Y2: 44805 | Z2: 44835 | AA2: 44866 | AB2: 44896 | AC2: Audited 2022 | AD2: 44949 | AE2: 44980 | AF2: 45008 | AG2: 45039 | AH2: 45069 | AI2: 45100 | AJ2: 45130 | AK2: 45161 | AL2: 45192 | AM2: 45222 | AN2: 45253 | AO2: 45283
A3: Financial Income | B3: =B4+B7 -> 14599.248 | C3: =C4+C7 -> 118584595 | D3: =D4+D7 -> 10079332 | E3: =E4+E7 -> 20545692 | F3: =F4+F7 -> 33311767 | G3: =G4+G7 -> 47098671 | H3: =H4+H7 -> 59410884 | I3: =I4+I7 -> 73036293 | ... AO3: =AO4+AO7 -> 0
A4: Financial Income From Loans Portfolio | B4: =SUM(B5:B6) -> 12855.806 | C4: =SUM(C5:C6) -> 88458375 | D4: =SUM(D5:D6) -> 8099005 | E4: =SUM(E5:E6) -> 15832497 | F4: =SUM(F5:F6) -> 24875910 | G4: =SUM(G5:G6) -> 34583604 | H4: =SUM(H5:H6) -> 44665750 | I4: =SUM(I5:I6) -> 55806894 | ... AO4: =SUM(AO5:AO6) -> 0
A5: Interest from Loans Portfolio | B5: 11945.435 | C5: 88458375 | D5: 8099005 | E5: 15832497 | F5: 24875910 | G5: 34583604 | H5: 44665750 | I5: 55806894 | J5: 69071138 | K5: 80411931 | L5: 92232153 | M5: 103945112 | N5: 114740008 | O5: 126726553 | P5: 126726553 | Q5: 10562905 | R5: 22627633 | S5: 36086795 | T5: 51827462 | U5: 64176506 | V5: 76832128 | W5: 88985276 | X5: 103062264 | Y5: 115658570 | Z5: 129443405 | AA5: 142266251 | AB5: 155095951 | AC5: 155095951 | AD5: 13625273 | AE5: 25931024 | AF5: 39351953 | AG5: 52289788 | AH5: 66108386 | AI5: 78795356 | AJ5: 91844866 | AK5: 105795895
A6: Fees&Commision on Loan Portfolio | B6: 910.371 | D6: 0 | E6: 0 | F6: 0 | G6: 0 | H6: 0 | I6: 0 | J6: 0 | K6: 0 | L6: 0 | M6: 0 | N6: 0 | O6: 0 | Q6: 0 | R6: 0 | S6: 0 | T6: 0 | U6: 0 | V6: 0 | W6: 0 | X6: 0 | Y6: 0 | Z6: 0 | AA6: 0 | AB6: 0 | AD6: 0 | AE6: 0 | AF6: 0 | AG6: 0 | AH6: 0 | AI6: 0 | AJ6: 0 | AK6: 0
A7: Financial Income from Investments | B7: =SUM(B8:B11) -> 1743.4416 | C7: =SUM(C8:C11) -> 30126220 | D7: =SUM(D8:D11) -> 1980327 | E7: =SUM(E8:E11) -> 4713195 | F7: =SUM(F8:F11) -> 8435857 | G7: =SUM(G8:G11) -> 12515067 | H7: =SUM(H8:H11) -> 14745134 | I7: =SUM(I8:I11) -> 17229399 | ... AO7: =SUM(AO8:AO11) -> 0
A8: Government Securities | C8: - | D8: 0 | E8: 0 | F8: 0 | G8: 0 | H8: 0 | I8: 0 | J8: 0 | K8: 0 | L8: 0 | M8: 0 | N8: 0 | O8: 0 | Q8: 0 | R8: 0 | S8: 0 | T8: 0 | U8: 0 | V8: 0 | W8: 0 | X8: 0 | Y8: 0 | Z8: 0 | AA8: 0 | AB8: 0 | AD8: 0 | AE8: 0 | AF8: 0 | AG8: 0 | AH8: 0 | AI8: 0 | AJ8: 0 | AK8: 0
A9: Deposits with Banks & other Financial Institutions | C9: 1966450 | D9: 0 | E9: 0 | F9: 0 | G9: 0 | H9: 0 | I9: 0 | J9: 0 | K9: 0 | L9: 0 | M9: 0 | N9: 0 | O9: 0 | P9: 1950937 | Q9: 0 | R9: 0 | S9: 0 | T9: 0 | U9: 0 | V9: 0 | W9: 0 | X9: 0 | Y9: 0 | Z9: 0 | AA9: 0 | AB9: 0 | AC9: 1870115 | AD9: 0 | AE9: 0 | AF9: 0 | AG9: 0 | AH9: 0 | AI9: 0 | AJ9: 0 | AK9: 0
A10: Other Investments | C10: - | D10: 0 | E10: 0 | F10: 0 | G10: 0 | H10: 0 | I10: 0 | J10: 0 | K10: 0 | L10: 0 | M10: 0 | N10: 0 | O10: 0 | Q10: 0 | R10: 0 | S10: 0 | T10: 0 | U10: 0 | V10: 0 | W10: 0 | X10: 0 | Y10: 0 | Z10: 0 | AA10: 0 | AB10: 0 | AD10: 0 | AE10: 0 | AF10: 0 | AG10: 0 | AH10: 0 | AI10: 0 | AJ10: 0 | AK10: 0
A11: Other Operating Income | B11: 1743.4416 | C11: 28159770 | D11: 1980327 | E11: 4713195 | F11: 8435857 | G11: 12515067 | H11: 14745134 | I11: 17229399 | J11: 20466689 | K11: 23188437 | L11: 25668575 | M11: 28312182 | N11: 30508945 | O11: 33788242 | P11: =31380556+15049+441700 -> 31837305 | Q11: 2310707 | R11: 4056977 | S11: 9430516 | T11: 12896000 | U11: 15634480 | V11: 19342262 | W11: 21377006 | X11: 24834371 | Y11: 27512745 | Z11: 29988393 | AA11: 32180733 | AB11: 35234684 | AC11: =32951820+403400+9350 -> 33364570 | AD11: 2695055 | AE11: 5183034 | AF11: 12381014 | AG11: 12956592 | AH11: 15790270 | AI11: 19381815 | AJ11: 26178140 | AK11: 29951489
A12: Financial Expenses | B12: =SUM(B13:B18) -> 549.0847 | C12: =SUM(C13:C18) -> 58726389 | D12: =SUM(D13:D18) -> 2061192 | E12: =SUM(E13:E18) -> 5180036 | F12: =SUM(F13:F18) -> 9173589 | G12: =SUM(G13:G18) -> 12244352 | H12: =SUM(H13:H18) -> 18286396 | I12: =SUM(I13:I18) -> 27280369 | ... AO12: =SUM(AO13:AO18) -> 0
A13: Interest Expense on Deposits | B13: 185.36 | C13: 41798147 | D13: 1000000 | E13: 2000000 | F13: 5000000 | G13: 7000000 | H13: 12000000 | I13: 20000000 | J13: 30000000 | K13: 37000000 | L13: 44000000 | M13: 50000000 | N13: 55000000 | O13: 60000000 | P13: 58000000 | Q13: 2000000 | R13: 4000000 | S13: 6000000 | T13: 8000000 | U13: 16000000 | V13: 26000000 | W13: 40600000 | X13: 46400000 | Y13: 52200000 | Z13: 58000000 | AA13: 63800000 | AB13: 66000000 | AC13: 61000000 | AD13: 5000000 | AE13: 6000000 | AF13: 15000000 | AG13: 20000000 | AH13: 25000000 | AI13: 30000000 | AJ13: 35000000 | AK13: 40000000
A14: Cost of External Borrowings | B14: 363.7247 | C14: 14829925 | D14: 895320 | E14: 1757401 | F14: 2495757 | G14: 3274296 | H14: 3993847 | I14: 4694532 | J14: 5340633 | K14: 5965364 | L14: 6549268 | M14: 7661777 | N14: 8715033 | O14: 11710144 | P14: =10035652+1674492 -> 11710144 | Q14: 1104110 | R14: 2666590 | S14: 4099890 | T14: 5611953 | U14: 7022687 | V14: 8416847 | W14: 9733978 | X14: 11032713 | Y14: 12283175 | Z14: 13466263 | AA14: 13822260 | AB14: 17641219 | AC14: =12430511+5210708 -> 17641219 | AD14: 1679272 | AE14: 3161201 | AF14: 4587268 | AG14: 6135786 | AH14: 7584957 | AI14: 9032944 | AJ14: 10163081 | AK14: 11477801
A15: Dividend Expenses | C15: 0 | D15: 0 | E15: 0 | F15: 0 | G15: 0 | H15: 0 | I15: 0 | J15: 0 | K15: 0 | L15: 0 | M15: 0 | N15: 0 | O15: 0 | Q15: 0 | R15: 0 | S15: 0 | T15: 0 | U15: 0 | V15: 0 | W15: 0 | X15: 0 | Y15: 0 | Z15: 0 | AA15: 0 | AB15: 0 | AD15: 0 | AE15: 0 | AF15: 0 | AG15: 0 | AH15: 0 | AI15: 0 | AJ15: 0 | AK15: 0
A16: Other Financial Expense | C16: - | D16: 43217 | E16: 43217 | F16: 125058 | G16: 174164 | H16: 251698 | I16: 286873 | J16: 758844 | K16: 991550 | L16: 1032378 | M16: 1032378 | N16: 1032378 | O16: 1032378 | P16: =42294824-P17-P14-P21 -> 16272909 | Q16: 1000000 | R16: 2000000 | S16: 3000000 | T16: 4000000 | U16: 720344 | V16: 0 | W16: 0 | X16: 0 | Y16: 0 | Z16: 0 | AA16: 0 | AB16: 0 | AC16: =43131530-AC14-AC17-AC21 -> 23468517 | AD16: 0 | AE16: 4000000 | AF16: 6000000 | AG16: 8000000 | AH16: 10000000 | AI16: 12000000 | AJ16: 14000000 | AK16: 16000000
A17: Fees & Commision Expense | C17: 2098317 | D17: 26285 | E17: 66379 | F17: 104485 | G17: 115559 | H17: 137611 | I17: 156048 | J17: 953938 | K17: 962655 | L17: 1023182 | M17: 1061810 | N17: 1655487 | O17: 1700843 | P17: 1710767 | Q17: 558528 | R17: 583352 | S17: 616466 | T17: 650818 | U17: 650818 | V17: 747403 | W17: 2776014 | X17: 1910739 | Y17: 1943893 | Z17: 1960993 | AA17: 2008300 | AB17: 1565202 | AC17: 1548311 | AD17: 43611 | AE17: 1911232 | AF17: 1773395 | AG17: 1469538 | AH17: 1715339 | AI17: 285063 | AJ17: 302066 | AK17: 302066
A18: Other Expenses | C18: - | D18: 96370 | E18: 1313039 | F18: 1448289 | G18: 1680333 | H18: 1903240 | I18: 2142916 | J18: 2391215 | K18: 2662308 | L18: 2844347 | M18: 3126306 | N18: 3623895 | O18: 13250455 | Q18: 117874 | R18: 1829234 | S18: 2209659 | T18: 2341788 | U18: 2682888 | V18: 3112451 | W18: 3224444 | X18: 3616521 | Y18: 3803109 | Z18: 4155506 | AA18: 5663747 | AB18: 5489512 | AD18: 2433451 | AE18: 439616 | AF18: 649607 | AG18: 979290 | AH18: 1176901 | AI18: 3227984 | AJ18: 3907443 | AK18: 4146547
A19: Net Financial Income | B19: =B3-B12 -> 14050.163 | C19: =C3-C12 -> 59858206 | D19: =D3-D12 -> 8018140 | E19: =E3-E12 -> 15365656 | F19: =F3-F12 -> 24138178 | G19: =G3-G12 -> 34854319 | H19: =H3-H12 -> 41124488 | I19: =I3-I12 -> 45755924 | ... AO19: =AO3-AO12 -> 0
A20: Allowance for Loan Loss | B20: =B21-B22 -> 0 | C20: =C21-C22 -> 13181219 | D20: =D21-D22 -> 1000000 | E20: =E21-E22 -> 2000000 | F20: =F21-F22 -> 3000000 | G20: =G21-G22 -> 4000000 | H20: =H21-H22 -> 5000000 | I20: =I21-I22 -> 6000000 | ... AO20: =AO21-AO22 -> 0
A21: Provision for Loan Losses | C21: 13181219 | D21: 1000000 | E21: 2000000 | F21: 3000000 | G21: 4000000 | H21: 5000000 | I21: 6000000 | J21: 7000000 | K21: 8000000 | L21: 9000000 | M21: 10000000 | N21: 12000000 | O21: 12401004 | P21: 12601004 | Q21: 1000000 | R21: 2000000 | S21: 3000000 | T21: 3000000 | U21: 8000000 | V21: 9000000 | W21: 10000000 | X21: 11000000 | Y21: 10269557 | Z21: 10574633 | AA21: 11574633 | AB21: 15473483 | AC21: 473483 | AD21: 0 | AE21: 2125830 | AF21: 0 | AG21: 0 | AH21: 0 | AI21: 0 | AJ21: 1079623 | AK21: 1390912
A22: Value of Loans Recovered | D22: 0 | E22: 0 | F22: 0 | G22: 0 | H22: 0 | I22: 0 | J22: 0 | K22: 0 | L22: 0 | M22: 0 | N22: 0 | O22: 0 | Q22: 0 | R22: 0 | S22: 0 | T22: 0 | U22: 0 | V22: 0 | W22: 0 | X22: 0 | Y22: 0 | Z22: 0 | AA22: 0 | AB22: 0 | AD22: 0 | AE22: 0 | AF22: 0 | AG22: 0 | AH22: 0 | AI22: 0 | AJ22: 0 | AK22: 0
A23: Operating Expeses | B23: =SUM(B24:B28) -> 11019.38 | C23: =SUM(C24:C28) -> 41765573 | D23: =SUM(D24:D28) -> 2725789 | E23: =SUM(E24:E28) -> 8588399 | F23: =SUM(F24:F28) -> 11513740 | G23: =SUM(G24:G28) -> 14779697 | H23: =SUM(H24:H28) -> 17742988 | I23: =SUM(I24:I28) -> 22111423 | ... AO23: =SUM(AO24:AO28) -> 0
A24: Personel Expenses | B24: 3512.444 | C24: 21003549 | D24: 1347309 | E24: 3092017 | F24: 4755430 | G24: 6116773 | H24: 7695779 | I24: 9487565 | J24: 12335468 | K24: 13847231 | L24: 15270288 | M24: 17324377 | N24: 19319770 | O24: 17429683 | P24: 19109783 | Q24: 1420310 | R24: 2785854 | S24: 4584477 | T24: 6075761 | U24: 8358265 | V24: 9746132 | W24: 11128619 | X24: 12528250 | Y24: 14091316 | Z24: 15477583 | AA24: 16911038 | AB24: 18758205 | AC24: 18298205 | AD24: 2748133 | AE24: 5977144 | AF24: 7367535 | AG24: 9243562 | AH24: 11677886 | AI24: 13113768 | AJ24: 14710022 | AK24: 16269502
A25: Governance Expenses | B25: 401.873 | C25: 4104017 | D25: 118460 | E25: 275660 | F25: 1258260 | G25: 1547760 | H25: 1838060 | I25: 2249360 | J25: 2543160 | K25: 2703060 | L25: 2871160 | M25: 2990060 | N25: 3205560 | O25: 3591060 | P25: =4459275-P26 -> 3591060 | Q25: 224500 | R25: 1640080 | S25: 3501090 | T25: 3636490 | U25: 3847660 | V25: 3979700 | W25: 4173590 | X25: 4355299 | Y25: 4749779 | Z25: 4912739 | AA25: 5063039 | AB25: 5638729 | AC25: =6850019-AC26 -> 5278729 | AD25: 542670 | AE25: 939920 | AF25: 3046150 | AG25: 3269670 | AH25: 3563240 | AI25: 4199160 | AJ25: 4646610 | AK25: 4820110
A26: Marketing Expenses | B26: 919.3528 | D26: 28900 | E26: 57600 | F26: 227200 | G26: 250100 | H26: 277650 | I26: 320700 | J26: 386500 | K26: 524840 | L26: 560020 | M26: 805800 | N26: 858320 | O26: 868215 | P26: 868215 | Q26: 68500 | R26: 280700 | S26: 505000 | T26: 581500 | U26: 688400 | V26: 849310 | W26: 977510 | X26: 1110510 | Y26: 1175280 | Z26: 1319330 | AA26: 1425440 | AB26: 1571290 | AC26: 1571290 | AD26: 53050 | AE26: 389735 | AF26: 662855 | AG26: 1099705 | AH26: 1297005 | AI26: 1411055 | AJ26: 1559305 | AK26: 1698205
A27: Depreciation and Amortization | B27: 1276.981 | C27: 2525292 | D27: 214525 | E27: 412197 | F27: 614510 | G27: 980289 | H27: 1294557 | I27: 1561172 | J27: 1940083 | K27: 2217038 | L27: 2493508 | M27: 2770565 | N27: 3273377 | O27: 3594135 | P27: 3594135 | Q27: 221703 | R27: 387117 | S27: 609426 | T27: 969136 | U27: 1210670 | V27: 1487826 | W27: 1738915 | X27: 1987332 | Y27: 2235748 | Z27: 2484165 | AA27: 2558622 | AB27: 3465247 | AC27: 3465248 | AD27: 229554 | AE27: 459108 | AF27: 730564 | AG27: 975503 | AH27: 1258742 | AI27: 1477036 | AJ27: 1723209 | AK27: 2215555
A28: Administrative Expenses | B28: 4908.7291 | C28: 14132715 | D28: 1016595 | E28: 4750925 | F28: 4658340 | G28: 5884775 | H28: 6636942 | I28: 8492626 | J28: 9461535 | K28: 10946397 | L28: 12515358 | M28: 13380691 | N28: 15975190 | O28: 19400679 | P28: =17863179-142600 -> 17720579 | Q28: 1721829 | R28: 5674610 | S28: 7081516 | T28: 9279700 | U28: 7714250 | V28: 10491694 | W28: 11547184 | X28: 13045695 | Y28: 16414496 | Z28: 18451612 | AA28: 21757070 | AB28: 20557818 | AC28: =20682918-AC36 -> 20557818 | AD28: 1967935 | AE28: 4709928 | AF28: 7314289 | AG28: 10708493 | AH28: 11988478 | AI28: 15385750 | AJ28: 16932276 | AK28: 17809547
A29: Net Operating Income | B29: =B19-B20-B23 -> 3030.7829 | C29: =C19-C20-C23 -> 4911414 | D29: =D19-D20-D23 -> 4292351 | E29: =E19-E20-E23 -> 4777257 | F29: =F19-F20-F23 -> 9624438 | G29: =G19-G20-G23 -> 16074622 | H29: =H19-H20-H23 -> 18381500 | I29: =I19-I20-I23 -> 17644501 | ... AO29: =AO19-AO20-AO23 -> 0
A30: Net Non operating Income/Expense | B30: =B31-B32 -> 0 | C30: 0 | D30: =D31-D32 -> 0 | E30: =E31-E32 -> 0 | F30: =F31-F32 -> 0 | G30: =G31-G32 -> 0 | H30: =H31-H32 -> 0 | I30: =I31-I32 -> 0 | J30: =J31-J32 -> 0 | K30: =K31-K32 -> 0 | ... AO30: =AO31-AO32 -> 0
A31: Non Operating Income | C31: - | D31: 0 | E31: 0 | F31: 0 | G31: 0 | H31: 0 | I31: 0 | J31: 0 | K31: 0 | L31: 0 | M31: 0 | N31: 0 | O31: 0 | P31: 441700 | Q31: 0 | R31: 0 | S31: 0 | T31: 0 | U31: 0 | V31: 0 | W31: 0 | X31: 0 | Y31: 0 | Z31: 0 | AA31: 0 | AB31: 0 | AD31: 0 | AE31: 0 | AF31: 0 | AG31: 0 | AH31: 0 | AI31: 0 | AJ31: 0 | AK31: 0
A32: Non Operating Expense | C32: - | D32: 0 | E32: 0 | F32: 0 | G32: 0 | H32: 0 | I32: 0 | J32: 0 | K32: 0 | L32: 0 | M32: 0 | N32: 0 | O32: 2529357 | Q32: 0 | R32: 0 | S32: 0 | T32: 0 | U32: 0 | V32: 0 | W32: 0 | X32: 0 | Y32: 0 | Z32: 0 | AA32: 0 | AB32: 0 | AD32: 0 | AE32: 0 | AF32: 0 | AG32: 0 | AH32: 0 | AI32: 0 | AJ32: 0 | AK32: 0
A33: Net Income(Before Tax & Donations) | B33: =B29+B30 -> 3030.7829 | C33: =C29+C30 -> 4911414 | D33: =D29+D30 -> 4292351 | E33: =E29+E30 -> 4777257 | F33: =F29+F30 -> 9624438 | G33: =G29+G30 -> 16074622 | H33: =H29+H30 -> 18381500 | I33: =I29+I30 -> 17644501 | ... AO33: =AO29+AO30 -> 0
A34: Taxes | B34: 20 | C34: 2147442 | D34: 237867 | E34: 248779 | F34: 396897 | G34: 301068 | H34: 312518 | I34: 343574 | J34: 0 | K34: 0 | L34: 0 | M34: 0 | N34: 0 | O34: 4546814 | P34: 4546814 | Q34: 300000 | R34: 0 | S34: 0 | T34: 0 | U34: 0 | V34: 0 | W34: 0 | X34: 0 | Y34: 0 | Z34: 0 | AA34: 0 | AB34: 369209 | AC34: 167995 | AD34: 0 | AE34: 0 | AF34: 0 | AG34: 0 | AH34: 0 | AI34: 0 | AJ34: 0 | AK34: 0
A35: Net Income(After Tax Before Donations) | B35: =B33-B34 -> 3010.7829 | C35: =C33-C34 -> 2763972 | D35: =D33-D34 -> 4054484 | E35: =E33-E34 -> 4528478 | F35: =F33-F34 -> 9227541 | G35: =G33-G34 -> 15773554 | H35: =H33-H34 -> 18068982 | I35: =I33-I34 -> 17300927 | ... AO35: =AO33-AO34 -> 0
A36: Donations | D36: 0 | E36: 30000 | F36: 40000 | G36: 40000 | H36: 55000 | I36: 55000 | J36: 60000 | K36: 75600 | L36: 80600 | M36: 100600 | N36: 125600 | O36: 142600 | P36: 142600 | Q36: 5000 | R36: 17000 | S36: 17000 | T36: 22000 | U36: 32000 | V36: 99100 | W36: 104100 | X36: 114100 | Y36: 114100 | Z36: 114100 | AA36: 125100 | AB36: 125100 | AC36: 125100 | AD36: 5000 | AE36: 10000 | AF36: 20000 | AG36: 25000 | AH36: 30000 | AI36: 35000 | AJ36: 40000 | AK36: 40000
A37: Net Income/(After Tax & Donations) | B37: =B35-B36 -> 3010.7829 | C37: =C35-C36 -> 2763972 | D37: =D35-D36 -> 4054484 | E37: =E35-E36 -> 4498478 | F37: =F35-F36 -> 9187541 | G37: =G35-G36 -> 15733554 | H37: =H35-H36 -> 18013982 | I37: =I35-I36 -> 17245927 | ... AO37: =AO35-AO36 -> 0
A39: Total Expenses | B39: =B12+B23 -> 11568.465 | C39: =C12+C23 -> 100491962 | D39: =D12+D23 -> 4786981 | E39: =E12+E23 -> 13768435 | F39: =F12+F23 -> 20687329 | G39: =G12+G23 -> 27024049 | H39: =H12+H23 -> 36029384 | I39: =I12+I23 -> 49391792 | ... AC39: =AC12+AC23 -> 152829337
J41: =J39-I39 -> 16719584 | K41: =K39-J39 -> 11709067 | L41: =L39-K39 -> 11339066 | M41: =M39-L39 -> 10994255 | N41: =N39-M39 -> 12505246 | O41: =O39-N39 -> 19918582 | P41: =P39-O39 -> 0 | Q41: =Q39-#REF! -> #REF! | R41: =R39-Q39 -> 13410183 | S41: =S39-R39 -> 10359987 | T41: =T39-S39 -> 8939622 | U41: =U39-T39 -> 7748836 | V41: =V39-U39 -> 15935381 | W41: =W39-V39 -> 21068891 | X41: =X39-W39 -> 10086805 | Y41: =Y39-X39 -> 12909737 | ... AC41: =AC39-AB39 -> 12142115

Sheet Evolutive SFP
B3: 2010 Audited | C3: 2020 Audited | D3: 44197 | E3: 44228 | F3: 44256 | G3: 44287 | H3: 44317 | I3: 44348 | J3: 44378 | K3: 44409 | L3: 44440 | M3: 44470 | N3: 44501 | O3: 44531 | P3: Audited 2021 | Q3: 44562 | R3: 44593 | S3: 44621 | T3: 44652 | U3: 44682 | V3: 44713 | W3: 44743 | X3: 44774 | Y3: 44805 | Z3: 44835 | AA3: 44866 | AB3: 44896 | AC3: Audited 2022 | AD3: 44949 | AE3: 44980 | AF3: 45008 | AG3: 45039 | AH3: 45069 | AI3: 45100 | AJ3: 45130 | AK3: 45161 | AL3: 45192 | AM3: 45222 | AN3: 45253 | AO3: 45283
A4: Cash & cash Equivalent | B4: =SUM(B5:B6) -> 19363224 | C4: =SUM(C5:C6) -> 128614953 | D4: =SUM(D5:D6) -> 127864143 | E4: =SUM(E5:E6) -> 118444272 | F4: =SUM(F5:F6) -> 66778450 | G4: =SUM(G5:G6) -> 84467545 | H4: =SUM(H5:H6) -> 57536247 | I4: =SUM(I5:I6) -> 91149655 | ... AO4: =SUM(AO5:AO6) -> 0
A5: Cash In Hand | B5: 19363224 | C5: 2686350 | D5: 7676670 | E5: 3831445 | F5: 9591338 | G5: 7447272 | H5: 11787193 | I5: 8116471 | J5: 3739371 | K5: 8236628 | L5: 5833562 | M5: 7284269 | N5: 12026502 | O5: 6042390 | P5: 6042390 | Q5: 8077430 | R5: 15642655 | S5: 7579113 | T5: 9088953 | U5: 4470470 | V5: 18933536 | W5: 16029828 | X5: 8626488 | Y5: 12619194 | Z5: 10905309 | AA5: 10106374 | AB5: 6106691 | AC5: =6106691+503949 -> 6610640 | AD5: 6715372 | AE5: 14362099 | AF5: 16564967 | AG5: 6130094 | AH5: 18514179 | AI5: 5358200 | AJ5: 16214537 | AK5: 6860818
A6: Cash at Bank | C6: 125928603 | D6: 120187473 | E6: 114612827 | F6: 57187112 | G6: 77020273 | H6: 45749054 | I6: 83033184 | J6: 64077460 | K6: 65415309 | L6: 84409762 | M6: 105270649 | N6: 113060898 | O6: 166559775 | P6: =111228428+55000000+331347 -> 166559775 | Q6: 141208488 | R6: 180766446 | S6: 147393822 | T6: 79584873 | U6: 86966429 | V6: 121609782 | W6: 88231678 | X6: 103747342 | Y6: 97181948 | Z6: 106049805 | AA6: 114367673 | AB6: 173572282 | AC6: =111502512+60000000 -> 171502512 | AD6: 159820476 | AE6: 154861826 | AF6: 131734240 | AG6: 124930044 | AH6: 114940252 | AI6: 136949595 | AJ6: 156953733 | AK6: 161520014
A7: Prepayment and Sundry | B7: 13400392 | C7: 89293794 | D7: 22972619 | E7: 20716662 | F7: 103616312 | G7: 88797119 | H7: 114427077 | I7: 68135442 | J7: 101961296 | K7: 103920108 | L7: 111267825 | M7: 95122533 | N7: 84007973 | O7: 66515095 | P7: =66515095-12000000 -> 54515095 | Q7: 123539280 | R7: 87030760 | S7: 90586804 | T7: 40411890 | U7: 32184925 | V7: 534685 | W7: 32591960 | X7: 31389019 | Y7: 30167754 | Z7: 32383451 | AA7: 33371063 | AB7: 30366824 | AC7: =30571824 -> 30571824 | AD7: 32978963 | AE7: 35216654 | AF7: 33200037 | AG7: 42908470 | AH7: 34808055 | AI7: 28932530 | AJ7: 40713806 | AK7: 41145922
A8: Financial Investment | B8: =SUM(B9:B13) -> 472260 | C8: =SUM(C9:C13) -> 48158789 | D8: =SUM(D9:D13) -> 51742253 | E8: =SUM(E9:E13) -> 80400025 | F8: =SUM(F9:F13) -> 80400025 | G8: =SUM(G9:G13) -> 80400025 | H8: =SUM(H9:H13) -> 80556471 | I8: =SUM(I9:I13) -> 80556471 | ... AO8: =SUM(AO9:AO13) -> 0
A9: Government Securities - Treasury Bills/bonds, | C9: 0 | D9: 0 | E9: 0 | F9: 0 | G9: 0 | H9: 0 | I9: 0 | J9: 0 | K9: 0 | L9: 0 | M9: 0 | N9: 0 | O9: 0 | Q9: 0 | R9: 0 | S9: 0 | T9: 0 | U9: 0 | V9: 0 | W9: 0 | X9: 0 | Y9: 0 | Z9: 0 | AA9: 0 | AB9: 0 | AD9: 0 | AE9: 0 | AF9: 0 | AG9: 0 | AH9: 0 | AI9: 0 | AJ9: 0 | AK9: 0
A10: Other Securities - Commercial papers/Bonds | C10: 0 | D10: 0 | E10: 0 | F10: 0 | G10: 0 | H10: 0 | I10: 0 | J10: 0 | K10: 0 | L10: 0 | M10: 0 | N10: 0 | O10: 0 | Q10: 0 | R10: 0 | S10: 0 | T10: 0 | U10: 0 | V10: 0 | W10: 0 | X10: 0 | Y10: 0 | Z10: 0 | AA10: 0 | AB10: 0 | AD10: 0 | AE10: 0 | AF10: 0 | AG10: 0 | AH10: 0 | AI10: 0 | AJ10: 0 | AK10: 0
A11: Balances in NACCOS (E.g Jungu Kuu, ESS, Savings,Money Market, CFP) | C11: 45647269 | D11: 31991236 | E11: 31991236 | F11: 31991236 | G11: 31991236 | H11: 32147682 | I11: 32147682 | J11: 32147682 | K11: 32147682 | L11: 32147682 | M11: 32373682 | N11: 32599681 | O11: 34119292 | P11: 34119292 | Q11: 34359442 | R11: 34585442 | S11: 34811442 | T11: 35483697 | U11: 35709697 | V11: 35935697 | W11: 36161697 | X11: 36489030 | Y11: 36715030 | Z11: 36941030 | AA11: 37167030 | AB11: 37835432 | AC11: 39401254 | AD11: 38061432 | AE11: 38287432 | AF11: 38513432 | AG11: 38739432 | AH11: 38965432 | AI11: 39381283 | AJ11: 39813015 | AK11: 40039015
A12: Equity Investments in NACCOs(Shares in- CIC, KUSCCO, COOP BANK,CAK, KERUSSU) | P12: =12139125+5757349+25913328+2087467 -> 45897269 | AC12: =12139126+6007349+25913328+2087467 -> 46147270 | AD12: 48658789 | AE12: 48658789 | AF12: 48658789 | AG12: 48658789 | AH12: 48658789 | AI12: 48658789 | AJ12: 48658789 | AK12: 48658789
A13: Equity Investments in companies - shares/stocks | B13: 472260 | C13: 2511520 | D13: 19751017 | E13: 48408789 | F13: 48408789 | G13: 48408789 | H13: 48408789 | I13: 48408789 | J13: 48408789 | K13: 48408789 | L13: 48408789 | M13: 48408789 | N13: 48408789 | O13: 48408789 | P13: =2511520 -> 2511520 | Q13: 48408789 | R13: 48408789 | S13: 48658789 | T13: 48658789 | U13: 48658789 | V13: 48658789 | W13: 48658789 | X13: 48658789 | Y13: 48658789 | Z13: 48658789 | AA13: 48658789 | AB13: 48658789 | AC13: 2511520
A14: Net Loan Portfolio | B14: =B15-B16 -> 112905266 | C14: =C15-C16 -> 945191720 | D14: =D15-D16 -> 949574103 | E14: =E15-E16 -> 945974458 | F14: =F15-F16 -> 945527615 | G14: =G15-G16 -> 945103539 | H14: =H15-H16 -> 944515624 | I14: =I15-I16 -> 964550729 | ... AO14: =AO15-AO16 -> 0
A15: Gross Loan Portfolio | B15: 112905266 | C15: 994788305 | D15: 1000170688 | E15: 997571043 | F15: 998124200 | G15: 998700124 | H15: 999112209 | I15: 1020147314 | J15: 1023417329 | K15: 1024214400 | L15: 1058417904 | M15: 1058417904 | N15: 1065218794 | O15: 1089345186 | P15: 1099345186 | Q15: 1065218794 | R15: 1068748915 | S15: 1081740012 | T15: 752122230 | U15: 762735725 | V15: 753318303 | W15: 758057271 | X15: 770490393 | Y15: 771992553 | Z15: 771916311 | AA15: 769859428 | AB15: 778820671 | AC15: 778820671 | AD15: 797611909 | AE15: 799587538 | AF15: 791436543 | AG15: 795572569 | AH15: 800003088 | AI15: 804016813 | AJ15: 800870142 | AK15: 825108150
A16: Allowance For Loan Loss | C16: 49596585 | D16: 50596585 | E16: 51596585 | F16: 52596585 | G16: 53596585 | H16: 54596585 | I16: 55596585 | J16: 56596585 | K16: 57596585 | L16: 58596585 | M16: 59596585 | N16: 61596585 | O16: 61997589 | P16: 62197589 | Q16: 63197589 | R16: 64197589 | S16: 65197589 | T16: 53066286 | U16: 40162289 | V16: 37793271 | W16: 38478743 | X16: 37720603 | Y16: 38431846 | Z16: 37736923 | AA16: 36725966 | AB16: 37635773 | AC16: 37635771 | AD16: 38884135 | AE16: 39761885 | AF16: 35760457 | AG16: 37294472 | AH16: 37461770 | AI16: 37285746 | AJ16: 38715396 | AK16: 39093914
A17: Accounts Recievables | B17: =SUM(B18:B20) -> 0 | C17: =SUM(C18:C20) -> 0 | D17: =SUM(D18:D20) -> 0 | E17: =SUM(E18:E20) -> 0 | F17: =SUM(F18:F20) -> 0 | G17: =SUM(G18:G20) -> 0 | H17: =SUM(H18:H20) -> 0 | I17: =SUM(I18:I20) -> 0 | ... AO17: =SUM(AO18:AO20) -> 0
A18: Tax Recoverable | C18: 0 | D18: 0 | E18: 0 | F18: 0 | G18: 0 | H18: 0 | I18: 0 | J18: 0 | K18: 0 | L18: 0 | M18: 0 | N18: 0 | O18: 0 | Q18: 0 | R18: 0 | S18: 0 | T18: 0 | U18: 0 | V18: 0 | W18: 0 | X18: 0 | Y18: 0 | Z18: 0 | AA18: 0 | AB18: 0 | AD18: 0 | AE18: 0 | AF18: 0 | AG18: 0 | AH18: 0 | AI18: 0 | AJ18: 0 | AK18: 0
A19: Deffered Tax Assets | C19: 0 | D19: 0 | E19: 0 | F19: 0 | G19: 0 | H19: 0 | I19: 0 | J19: 0 | K19: 0 | L19: 0 | M19: 0 | N19: 0 | O19: 0 | Q19: 0 | R19: 0 | S19: 0 | T19: 0 | U19: 0 | V19: 0 | W19: 0 | X19: 0 | Y19: 0 | Z19: 0 | AA19: 0 | AB19: 0 | AD19: 0 | AE19: 0 | AF19: 0 | AG19: 0 | AH19: 0 | AI19: 0 | AJ19: 0 | AK19: 0
A20: Retirement Benefit Assets | C20: 0 | D20: 0 | E20: 0 | F20: 0 | G20: 0 | H20: 0 | I20: 0 | J20: 0 | K20: 0 | L20: 0 | M20: 0 | N20: 0 | O20: 0 | Q20: 0 | R20: 0 | S20: 0 | T20: 0 | U20: 0 | V20: 0 | W20: 0 | X20: 0 | Y20: 0 | Z20: 0 | AA20: 0 | AB20: 0 | AD20: 0 | AE20: 0 | AF20: 0 | AG20: 0 | AH20: 0 | AI20: 0 | AJ20: 0 | AK20: 0
A21: Property&Equipments&Other Assets | B21: =SUM(B22:B26) -> 4874587 | C21: =SUM(C22:C26) -> 25718556 | D21: =SUM(D22:D26) -> 23155004 | E21: =SUM(E22:E26) -> 23515693 | F21: =SUM(F22:F26) -> 23581880 | G21: =SUM(G22:G26) -> 24303315 | H21: =SUM(H22:H26) -> 24819659 | I21: =SUM(I22:I26) -> 28489669 | ... AO21: =SUM(AO22:AO26) -> 0
A22: Investment Properties | D22: 3851000 | E22: 3851000 | F22: 3851000 | G22: 3851000 | H22: 3851000 | I22: 3851000 | J22: 3851000 | K22: 3851000 | L22: 3851000 | M22: 3851000 | N22: 3851000 | O22: 3851000 | Q22: 3851000 | R22: 3851000 | S22: 3851000 | T22: 4851000 | U22: 4851000 | V22: 4851000 | W22: 4851000 | X22: 4851000 | Y22: 4851000 | Z22: 4851000 | AA22: 4851000 | AB22: 4851000 | AD22: 4851000 | AE22: 4851000 | AF22: 4851000 | AG22: 4851000 | AH22: 4851000 | AI22: 4851000 | AJ22: 4851000 | AK22: 4851000
A23: Property and Equipment | B23: 4123114 | C23: 22098514 | D23: 18083810 | E23: 17937047 | F23: 18054199 | G23: 18826000 | H23: 18824438 | I23: 22477624 | J23: 18901572 | K23: 18696523 | L23: 18940393 | M23: 18733901 | N23: 18711770 | O23: 18484754 | P23: 22335754 | Q23: 17256614 | R23: 18600463 | S23: 22994217 | T23: 22983810 | U23: 22784839 | V23: 22585868 | W23: 22386897 | X23: 22187926 | Y23: 22013955 | Z23: 21814984 | AA23: 21905973 | AB23: 21048793 | AC23: 25899792 | AD23: 20853838 | AE23: 20658883 | AF23: 21216919 | AG23: 21038961 | AH23: 21302932 | AI23: 21338119 | AJ23: 21124927 | AK23: 21124927
A24: Prepaid Lease Rentals | B24: 0 | C24: 0 | D24: 0 | E24: 0 | F24: 0 | G24: 0 | H24: 0 | I24: 0 | J24: 0 | K24: 0 | L24: 0 | M24: 0 | N24: 0 | O24: 0 | Q24: 0 | R24: 0 | S24: 0 | T24: 205000 | U24: 205000 | V24: 205000 | W24: 0 | X24: 0 | Y24: 0 | Z24: 0 | AA24: 0 | AB24: 205000 | AD24: 205000 | AE24: 205000 | AF24: 205000 | AG24: 205000 | AH24: 0 | AI24: 0 | AJ24: 0 | AK24: 0
A25: Intangible Assets | B25: 751473 | C25: 1829376 | D25: 1220194 | E25: 1727646 | F25: 1676681 | G25: 1626315 | H25: 2144221 | I25: 2161045 | J25: 2039540 | K25: 1967634 | L25: 1907794 | M25: 1837229 | N25: 1766664 | O25: 1742522 | P25: 1742522 | Q25: 1698959 | R25: 1655396 | S25: 1611833 | T25: 1569270 | U25: 1566007 | V25: 1487822 | W25: 1435704 | X25: 1386258 | Y25: 1336813 | Z25: 1287367 | AA25: 1237921 | AB25: 1188476 | AC25: 1188475 | AD25: 1153877 | AE25: 1119278 | AF25: 1089536 | AG25: 1056555 | AH25: 1023576 | AI25: 990595 | AJ25: 957614 | AK25: 957614
A26: Other Assets | C26: 1790666 | D26: 0 | E26: 0 | F26: 0 | G26: 0 | H26: 0 | I26: 0 | J26: 0 | K26: 0 | L26: 0 | M26: 0 | N26: 0 | O26: 1790666 | P26: 1790666 | Q26: 0 | R26: 0 | S26: 0 | T26: 418788148 | U26: 404232984 | V26: 402878958 | W26: 411407226 | X26: 398891285 | Y26: 404408813 | Z26: 405398731 | AA26: 403374085 | AB26: 400771712 | AC26: 395771710 | AD26: 393588686 | AE26: 396896059 | AF26: 388525810 | AG26: 384754056 | AH26: 385078134 | AI26: 380859359 | AJ26: 377652365 | AK26: 375652365
A27: Total Assets | B27: =B21+B17+B14+B8+B7+B4 -> 151015729 | C27: =C21+C17+C14+C8+C7+C4 -> 1236977812 | D27: =D21+D17+D14+D8+D7+D4 -> 1175308122 | E27: =E21+E17+E14+E8+E7+E4 -> 1189051110 | F27: =F21+F17+F14+F8+F7+F4 -> 1219904282 | G27: =G21+G17+G14+G8+G7+G4 -> 1223071543 | H27: =H21+H17+H14+H8+H7+H4 -> 1221855078 | I27: =I21+I17+I14+I8+I7+I4 -> 1232881966 | ... AO27: =AO21+AO17+AO14+AO8+AO7+AO4 -> 0
A28: Savings and Deposits | B28: 8112861 | C28: 196597486 | D28: 160094607 | E28: 144474108 | F28: 165646387 | G28: 155276718 | H28: 144478780 | I28: 146250517 | J28: 152918909 | K28: 149269584 | L28: 145882062 | M28: 147305327 | N28: 155412239 | O28: 148467369 | P28: 184968757 | Q28: 149428757 | R28: 159822084 | S28: 189938230 | T28: 155584657 | U28: 148675981 | V28: 152995040 | W28: 151349612 | X28: 154851879 | Y28: 151477016 | Z28: 152988067 | AA28: 152119545 | AB28: 159702332 | AC28: 202098796 | AD28: 158213177 | AE28: 157480121 | AF28: 169957870 | AG28: 154024015 | AH28: 146668825 | AI28: 142176533 | AJ28: 172023155 | AK28: 182424131
A29: Short Terrm Deposits | B29: 8350444 | C29: 22744581 | D29: 27240666 | E29: 28980670 | F29: 31005770 | G29: 34844770 | H29: 36440611 | I29: 38825897 | J29: 36476526 | K29: 39644265 | L29: 40738819 | M29: 37281819 | N29: 34110327 | O29: 38432727 | P29: 38432727 | Q29: 36705237 | R29: 40412232 | S29: 39467005 | T29: 41096817 | U29: 44584817 | V29: 47714517 | W29: 49804418 | X29: 49666417 | Y29: 48013888 | Z29: 47171661 | AA29: 46054150 | AB29: 43583125 | AC29: 43583126 | AD29: 46097781 | AE29: 47319049 | AF29: 51294232 | AG29: 54835511 | AH29: 54422221 | AI29: 54570722 | AJ29: 55469442 | AK29: 55176774
A30: Non Withdrawable Deposits | B30: 112140909 | C30: 648119220 | D30: 653027408 | E30: 657560984 | F30: 658237631 | G30: 663672071 | H30: 667297041 | I30: 672478023 | J30: 671289225 | K30: 674145345 | L30: 677288785 | M30: 677014567 | N30: 681062853 | O30: 688606121 | P30: 688580171 | Q30: 693913233 | R30: 699331954 | S30: 703419370 | T30: 707120558 | U30: 711700029 | V30: 711246774 | W30: 711177383 | X30: 710435343 | Y30: 713581190 | Z30: 716857531 | AA30: 720983998 | AB30: 726994123 | AC30: 727001223 | AD30: 729441854 | AE30: 735032641 | AF30: 738093934 | AG30: 742920489 | AH30: 747616909 | AI30: 751271783 | AJ30: 746110350 | AK30: 747558830
A31: Total Deposit Liabilities | B31: =SUM(B28:B30) -> 128604214 | C31: =SUM(C28:C30) -> 867461287 | D31: =SUM(D28:D30) -> 840362681 | E31: =SUM(E28:E30) -> 831015762 | F31: =SUM(F28:F30) -> 854889788 | G31: =SUM(G28:G30) -> 853793559 | H31: =SUM(H28:H30) -> 848216432 | I31: =SUM(I28:I30) -> 857554437 | ... AO31: =SUM(AO28:AO30) -> 0
A32: Tax Payable | B32: 27231 | C32: 2147442 | D32: 237867 | E32: 248779 | F32: 396897 | G32: 301068 | H32: 312518 | I32: 343574 | J32: 0 | K32: 0 | L32: 0 | M32: 0 | N32: 0 | O32: 2947779 | P32: 2947779 | Q32: 300000 | R32: 0 | S32: 0 | T32: 0 | U32: 0 | V32: 0 | W32: 0 | X32: 0 | Y32: 0 | Z32: 0 | AA32: 0 | AB32: 1731947 | AC32: 2057169 | AD32: 0 | AE32: 0 | AF32: 0 | AG32: 0 | AH32: 0 | AI32: 0 | AJ32: 0 | AK32: 0
A33: Dividends Payable | B33: 3618123 | C33: 40280000 | D33: 1000000 | E33: 2000000 | F33: 5000000 | G33: 7000000 | H33: 12000000 | I33: 20000000 | J33: 30000000 | K33: 37000000 | L33: 44000000 | M33: 50000000 | N33: 55000000 | O33: 60000000 | P33: 58000000 | Q33: 2000000 | R33: 4000000 | S33: 6000000 | T33: 8000000 | U33: 16000000 | V33: 26000000 | W33: 40600000 | X33: 46400000 | Y33: 52200000 | Z33: 58000000 | AA33: 63800000 | AB33: 66000000 | AC33: 61000000 | AD33: 66000000 | AE33: 67000000 | AF33: 20361698 | AG33: 22460124 | AH33: 25000000 | AI33: 30000000 | AJ33: 35000000 | AK33: 40000000
A34: Deferred Tax Liability | C34: 0 | D34: 0 | E34: 0 | F34: 0 | G34: 0 | H34: 0 | I34: 0 | J34: 0 | K34: 0 | L34: 0 | M34: 0 | N34: 0 | O34: 0 | Q34: 0 | R34: 0 | S34: 0 | T34: 0 | U34: 0 | V34: 0 | W34: 0 | X34: 0 | Y34: 0 | Z34: 0 | AA34: 0 | AB34: 0 | AD34: 0 | AE34: 0 | AF34: 0 | AG34: 0 | AH34: 0 | AI34: 0 | AJ34: 0 | AK34: 0
A35: Retirement Benefits Liabilty | D35: 0 | E35: 0 | F35: 0 | G35: 0 | H35: 0 | I35: 0 | J35: 0 | K35: 0 | L35: 0 | M35: 0 | N35: 0 | O35: 0 | Q35: 0 | R35: 0 | S35: 0 | T35: 0 | U35: 0 | V35: 0 | W35: 0 | X35: 0 | Y35: 0 | Z35: 0 | AA35: 0 | AB35: 0 | AD35: 0 | AE35: 0 | AF35: 0 | AG35: 0 | AH35: 0 | AI35: 0 | AJ35: 0 | AK35: 0
A36: Other Liabilities | B36: 1214920 | C36: 1662567 | D36: 35647251 | E36: 33391294 | F36: 36018635 | G36: 35078954 | H36: 36224122 | I36: 33981112 | J36: 34508937 | K36: 35115761 | L36: 35455529 | M36: 39521305 | N36: 38355000 | O36: 39589774 | P36: =2754336+360000 -> 3114336 | Q36: 101366275 | R36: 98856737 | S36: 40685202 | T36: 46232258 | U36: 42153455 | V36: 38704100 | W36: 46433542 | X36: 43221390 | Y36: 42630921 | Z36: 43103540 | AA36: 43861370 | AB36: 45021948 | AC36: =820000+1731947 -> 2551947 | AD36: 46175731 | AE36: 48627384 | AF36: 46610040 | AG36: 48964308 | AH36: 47417317 | AI36: 49458537 | AJ36: 52426619 | AK36: 52438404
A37: External Borrowings | B37: 2291669 | C37: 86676534 | D37: 82942020 | E37: 78518799 | F37: 74852133 | G37: 71185467 | H37: 66760355 | I37: 63093688 | J37: 59427022 | K37: 55000013 | L37: 101333347 | M37: 96277793 | N37: 91184333 | O37: 145741122 | P37: 145741122 | Q37: 142364405 | R37: 138101668 | S37: 133841034 | T37: 129863219 | U37: 125572404 | V37: 121264026 | W37: 114161192 | X37: 109818728 | Y37: 105458661 | Z37: 101088594 | AA37: 96692814 | AB37: 138434460 | AC37: 138434460 | AD37: 133712944 | AE37: 128984534 | AF37: 124293770 | AG37: 119528144 | AH37: 114743280 | AI37: 109953977 | AJ37: 105130154 | AK37: 100316438
A38: Total Liabilities | B38: =SUM(B31:B37) -> 135756157 | C38: =SUM(C31:C37) -> 998227830 | D38: =SUM(D31:D37) -> 960189819 | E38: =SUM(E31:E37) -> 945174634 | F38: =SUM(F31:F37) -> 971157453 | G38: =SUM(G31:G37) -> 967359048 | H38: =SUM(H31:H37) -> 963513427 | I38: =SUM(I31:I37) -> 974972811 | ... AO38: =SUM(AO31:AO37) -> 0
A39: Share Capital | B39: 10494697 | C39: 89412126 | D39: 89754772 | E39: 90040142 | F39: 90221432 | G39: 90641085 | H39: 90989813 | I39: 91325372 | J39: 91622528 | K39: 92044339 | L39: 92591109 | M39: 92961774 | N39: 93128535 | O39: 93531639 | P39: 93531639 | Q39: 93586416 | R39: 94151903 | S39: 94273046 | T39: 94633923 | U39: 95038260 | V39: 95442159 | W39: 95853606 | X39: 96212068 | Y39: 96665839 | Z39: 97149961 | AA39: 97328132 | AB39: 97671003 | AC39: 97671003 | AD39: 98127674 | AE39: 98548744 | AF39: 98813674 | AG39: 99188780 | AH39: 99563636 | AI39: 99964203 | AJ39: 100330070 | AK39: 100687987
A40: Capital Grants | B40: 340425 | C40: 0 | D40: 0 | E40: 0 | F40: 0 | G40: 0 | H40: 0 | I40: 0 | J40: 0 | K40: 0 | L40: 0 | M40: 0 | N40: 0 | O40: 0 | P40: 0 | Q40: 0 | R40: 0 | S40: 0 | T40: 0 | U40: 0 | V40: 0 | W40: 0 | X40: 0 | Y40: 0 | Z40: 0 | AA40: 0 | AB40: 0 | AD40: 0 | AE40: 0 | AF40: 0 | AG40: 0 | AH40: 0 | AI40: 0 | AJ40: 0 | AK40: 0
A41: Prior Year Retained Earnigs | B41: 351220 | C41: 60964231 | D41: 64270660 | E41: 63291409 | F41: 63291409 | G41: 63291409 | H41: 63291409 | I41: 63291409 | J41: 63291409 | K41: 63291409 | L41: 63291409 | M41: 63291409 | N41: 63291409 | O41: 69329545 | P41: =63291409-2279292-2129357-360000 -> 58522760 | Q41: 69369767 | R41: 69369767 | S41: 69369767 | T41: 69369767 | U41: 69369767 | V41: 69369767 | W41: 69369767 | X41: 69369767 | Y41: 69369767 | Z41: 69369767 | AA41: 69369767 | AB41: 91210399 | AC41: =68909767-5838174-820000 -> 62251593 | AD41: 90655591 | AE41: 90655591 | AF41: 90655591 | AG41: 90655591 | AH41: 90655591 | AI41: 90655591 | AJ41: 90655591 | AK41: 90655591
A42: Current Year Surplus | B42: 3541956 | C42: 2327178 | D42: 4054484 | E42: 4498478 | F42: 9187541 | G42: 15733554 | H42: 18013982 | I42: 17245927 | J42: 16366451 | K42: 17704325 | L42: 19960619 | M42: 22002930 | N42: 20464343 | O42: 0 | P42: =10646785 -> 10646785 | Q42: 3161258 | R42: 2820073 | S42: 8809930 | T42: 20554316 | U42: 22883004 | V42: 22243927 | W42: 14357928 | X42: 20795476 | Y42: 23890862 | Z42: 28514874 | AA42: 29737735 | AB42: 0 | AC42: 28567777 | AD42: 1617652 | AE42: 5720906 | AF42: 4581304 | AG42: 3399833 | AH42: 6606108 | AI42: 8009411 | AJ42: 13959371 | AK42: 19577139
...

Sheet Compliancereport Audited2021
A1: SMARTLIFE SACCO SOCIETY LIMITED
A2: PERFORMANCE AND COMPLIANCE REPORT AS AT : 31st December , 2021
B3: Prudential Standard | C3: Audited | D3: Returns | F3: Audited 2021 | G3: Aggregate for all Licensed Saccos
C4: 2020 | D4: 30th September , 2021 | E4: 31st December , 2021
A5: A. CAPITAL ADEQUACY
A6: Core Capital | B6: ≥10M | C6: =C33 -> 2.0758069e+08 | D6: =D33 -> 1.7484271e+08 | E6: =E33 -> 174010427 | F6: =F33 -> 222237053 | G6: =G33 -> 1.1717834e+11
A7: Core Capital/Total Assets | B7: ≥10% | C7: =C33/C29 -> 0.16781278 | D7: =D33/D29 -> 0.13381624 | E7: =E33/E29 -> 0.12656575 | F7: =F33/F29 -> 0.16190225 | G7: =G33/G29 -> 0.17065191
A8: Institutional Capital/Total Assets | B8: ≥8% | C8: =C34/C29 -> 0.09553006 | D8: =D34/D29 -> 0.06295144 | E8: =E34/E29 -> 0.058535908 | F8: =F34/F29 -> 0.093763377 | G8: =G34/G29 -> 0.10490582
A9: B. ASSET QUALITY
A10: NPL (Substandard+Doubtful+Loss) | B10: <5% | C10: =C35/C32 -> 0 | D10: =D35/D32 -> 0.020000001 | E10: =E35/E32 -> 0.017517802 | F10: =F35/F32 -> 0.046495215 | G10: =G35/G32 -> 0.08178734
A11: Non-Earning Assets | B11: <10% | C11: =C36/C29 -> 0.092978507 | D11: =D36/D29 -> 0.10111527 | E11: =E36/E29 -> 0.064394132 | F11: =F36/F29 -> 0.058560697 | G11: =G36/G29 -> 0.10019208
A12: Equity investments/Deposits | B12: <5% | C12: =C38/C31 -> 0.0028952531 | D12: =D38/D31 -> 0.05603455 | E12: =E38/E31 -> 0.055292342 | F12: =F38/F31 -> 0.002753915 | G12: =G38/G31 -> 0.02863476
A13: Equity investments/Core capital | B13: <40% | C13: =C38/C33 -> 0.012099006 | D13: =D38/D33 -> 0.2768705 | E13: =E38/E33 -> 0.27819476 | F13: =F38/F33 -> 0.011301086 | G13: =G38/G33 -> 0.11343868
A14: C. EARNINGS RATING
A15: Yield on Gross Loans | C15: =C48/C32 -> 0.088921808 | D15: =D48/D32 -> 0.087141528 | E15: =E48/E32 -> 0.11633278 | F15: =F48/F32 -> 0.11527458 | G15: =G48/G32 -> 0.158556
A16: Total Expense/Total Income | C16: =C49/C44 -> 0.35220066 | D16: =D49/D44 -> 0.75622526 | E16: =E49/E44 -> 0.84171025 | F16: =F49/F44 -> 0.82368588 | G16: =G49/G44 -> 0.71531043
A17: Net Income/Average Assets (ROA) | C17: =C50/C30 -> 0.051126501 | D17: =D50/D30 -> 0.015886054 | E17: =E50/E30 -> 0.006437902 | F17: =F50/F30 -> 0.0084980965 | G17: =G50/G30 -> 0.036318533
A18: Operating Expenses/Financial Income (OPEX) | C18: =C47/C44 -> 0.35220066 | D18: =D47/D44 -> 0.28592134 | E18: =E47/E44 -> 0.27962389 | F18: =F47/F44 -> 0.27885654 | G18: =G47/G44 -> 0.32493127
A19: D. LIQUIDITY
A20: Liquid Assets/Short-term Liabilities | B20: >15% | C20: =C40/C41 -> 0.31777559 | D20: =D40/D41 -> 0.33916319 | E20: =E40/E41 -> 0.59633626 | F20: =F40/F41 -> 0.75219846 | G20: =G40/G41 -> 0.70602321
A21: External Borrowing/Total Assets | B21: <25% | C21: =C42/C29 -> 0 | D21: =D42/D29 -> 0.077555693 | E21: =E42/E29 -> 0.10600419 | F21: =F42/F29 -> 0.10617409 | G21: =G42/G29 -> 0.034506714
A22: Liquid Assets/Total Assets | C22: =C40/C29 -> 0.079593966 | D22: =D40/D29 -> 0.06906792 | E22: =E40/E29 -> 0.12554146 | F22: =F40/F29 -> 0.12574267 | G22: =G40/G29 -> 0.13781953
A23: E. STRUCTURE/SENSITIVITY TO RISK
A24: Gross loans /Total Assets | B24: 70-80 | C24: =C32/C29 -> 0.80420869 | D24: =D32/D29 -> 0.81006239 | E24: =E32/E29 -> 0.79233063 | F24: =F32/F29 -> 0.80088564 | G24: =G32/G29 -> 0.74612895
A25: Gross loans/Deposits | B25: >100% | C25: =C32/C31 -> 1.1467812 | D25: =D32/D31 -> 1.2251488 | E25: =E32/E31 -> 1.2442461 | F25: =F32/F31 -> 1.2054466 | G25: =G32/G31 -> 1.1036595
A26: Financial Investments/Total Assets | C26: =C39/C31 -> 0.090283881 | D26: =D39/D31 -> 0.093246405 | E26: =E39/E31 -> 0.094263272 | F26: =F39/F31 -> 0.090493137 | G26: =G39/G31 -> 0.063826668
A27: Dividends+Interest on Deposits/Total Income | C27: =C46/C44 -> 0 | D27: =D46/D44 -> 0.37319532 | E27: =E46/E44 -> 0.37379732 | F27: =F46/F44 -> 0.36034582 | G27: =G46/G44 -> 0.32674991
A28: F. KEY FINANCIAL STATISTICS
A29: Total Assets | C29: 1236977812 | D29: 1306588126 | E29: 1374861880 | F29: ='[1]Evolutive SFP'!P27 -> 1372661880 | G29: 6.8665121e+11
A30: Average Assets | C30: 1202710145 | D30: 1237602419 | E30: 1.291947e+09 | F30: =('[1]Evolutive SFP'!C27+'[1]Evolutive SFP'!P27)/2 -> 1304819846 | G30: 6.5195014e+11
A31: Total Deposits | C31: 867461287 | D31: 863909666 | E31: 875506217 | F31: ='[1]Evolutive SFP'!P31 -> 911981655 | G31: 4.6421053e+11
A32: Gross Loans | C32: 994788305 | D32: 1058417904 | E32: 1089345186 | F32: ='[1]Evolutive SFP'!P15 -> 1099345186 | G32: 5.1233035e+11
A33: Core Capital | C33: 2.0758069e+08 | D33: 1.7484271e+08 | E33: 174010427 | F33: ='[1]Evolutive SFP'!P39+'[1]Evolutive SFP'!P41+'[1]Evolutive SFP'!P42+'[1]Evolutive SFP'!P43+'[1]Evolutive SFP'!P44-'[1]Evolutive SFP'!P13 -> 222237053 | G33: 1.1717834e+11
A34: Institutional Capital | C34: 1.1816856e+08 | D34: 82251604 | E34: 80478788 | F34: =[1]Financials!Q12 -> 128705414 | G34: 7.2033707e+10
A35: Non-performing Loans | C35: 0 | D35: 21168359 | E35: 19082933 | F35: ='[1]FORM 4'!D42+'[1]FORM 4'!D43+'[1]FORM 4'!D44 -> 51114291 | G35: 4.1902136e+10
A36: Non-Earning Assets | C36: 115012350 | D36: 132116012 | E36: 88533037 | F36: ='[1]Evolutive SFP'!P7+'[1]Evolutive SFP'!P17+'[1]Evolutive SFP'!P23+'[1]Evolutive SFP'!P24+'[1]Evolutive SFP'!P25+'[1]Evolutive SFP'!P26 -> 80384037 | G36: 6.8797012e+10
A37: Property and Equipment | C37: 23927890 | D37: 20848187 | E37: 20227276 | F37: ='[1]Evolutive SFP'!P23+'[1]Evolutive SFP'!P25 -> 24078276 | G37: 1.934763e+10
A38: Equity Investments | C38: 2511520 | D38: 48408789 | E38: 48408789 | F38: ='[1]Evolutive SFP'!P13 -> 2511520 | G38: 1.3292557e+10
A39: Financial Investments | C39: 78317772 | D39: 80556471 | E39: 82528081 | F39: ='[1]Evolutive SFP'!P8 -> 82528081 | G39: 2.9629011e+10
A40: Liquid Assets | C40: 98455970 | D40: 90243324 | E40: 172602165 | F40: ='[1]Evolutive SFP'!P4+'[1]Evolutive SFP'!P9+'[1]Evolutive SFP'!P10 -> 172602165 | G40: 9.463395e+10
...

Sheet Sheet1

Sheet FORM 4
D1: 44256
B2: CLASSIFICATION | C2: NO. OF A/Cs | D2: OUTSTANDING LOAN PORTFOLIO(Kshs) | E2: REQUIRED PROVISION | F2: REQUIRED PROVISION AMOUNT(Kshs)
B3: Performing | C3: 95 | D3: 896051883 | E3: 0.01 | F3: =D3*E3 -> 8960518.8
B4: Watch | C4: 3 | D4: 28296375 | E4: 0.05 | F4: =D4*E4 -> 1414818.8 | H4: NPL | I4: =D5+D6+D7 -> 18864250
B5: Substandard | C5: 1 | D5: 9432125 | E5: 0.25 | F5: =D5*E5 -> 2358031.2 | H5: PAR | I5: =I4/D8 -> 0.02
B6: Doubtful | C6: 0 | D6: 5659275 | E6: 0.5 | F6: =D6*E6 -> 2829637.5
B7: Loss | C7: 0 | D7: 3772850 | E7: 1 | F7: =D7*E7 -> 3772850
B8: subtotal | C8: =SUM(C3:C7) -> 99 | D8: =SUM(D3:D7) -> 943212508 | E8: =SUM(E3:E7) -> 1.81 | F8: =SUM(F3:F7) -> 19335856
D10: 44348
B11: CLASSIFICATION | C11: NO. OF A/Cs | D11: OUTSTANDING LOAN PORTFOLIO(Kshs) | E11: REQUIRED PROVISION | F11: REQUIRED PROVISION AMOUNT(Kshs)
B12: Performing | D12: 969139948 | E12: 0.01 | F12: =D12*E12 -> 9691399.5
B13: Watch | D13: 30604419 | E13: 0.05 | F13: =D13*E13 -> 1530221 | H13: NPL | I13: =D14+D15+D16 -> 20402945
B14: Substandard | D14: 10201473 | E14: 0.25 | F14: =D14*E14 -> 2550368.2 | H14: PAR | I14: =I13/D17 -> 0.019999999
B15: Doubtful | D15: 6120883 | E15: 0.5 | F15: =D15*E15 -> 3060441.5
B16: Loss | D16: 4080589 | E16: 1 | F16: =D16*E16 -> 4080589
B17: subtotal | C17: =SUM(C12:C16) -> 0 | D17: =SUM(D12:D16) -> 1020147312 | E17: 1.81 | F17: =SUM(F12:F16) -> 20913019
D19: 44440
B20: CLASSIFICATION | C20: NO. OF A/Cs | D20: OUTSTANDING LOAN PORTFOLIO(Kshs) | E20: REQUIRED PROVISION | F20: REQUIRED PROVISION AMOUNT(Kshs)
B21: Performing | C21: 95 | D21: 1005497008 | E21: 0.01 | F21: =D21*E21 -> 10054970
B22: Watch | C22: 3 | D22: 31752537 | E22: 0.05 | F22: =D22*E22 -> 1587626.9 | H22: NPL | I22: =D23+D24+D25 -> 21168359
B23: Substandard | C23: 1 | D23: 10584179 | E23: 0.25 | F23: =D23*E23 -> 2646044.8 | H23: PAR | I23: =I22/D26 -> 0.020000001
B24: Doubtful | C24: 0 | D24: 6350509 | E24: 0.5 | F24: =D24*E24 -> 3175254.5
B25: Loss | C25: 0 | D25: 4233671 | E25: 1 | F25: =D25*E25 -> 4233671
B26: subtotal | C26: =SUM(C21:C25) -> 99 | D26: =SUM(D21:D25) -> 1058417904 | E26: 1.81 | F26: =SUM(F21:F25) -> 21697567
D28: 44531
B29: CLASSIFICATION | C29: NO. OF A/Cs | D29: OUTSTANDING LOAN PORTFOLIO(Kshs) | E29: REQUIRED PROVISION | F29: REQUIRED PROVISION AMOUNT(Kshs)
B30: Performing | C30: 4961 | D30: 1043560612 | E30: 0.01 | F30: =D30*E30 -> 10435606
B31: Watch | C31: 157 | D31: 26701641 | E31: 0.05 | F31: =D31*E31 -> 1335082.1 | H31: NPL | I31: =D32+D33+D34 -> 19082933
B32: Substandard | C32: 25 | D32: 2486540 | E32: 0.25 | F32: =D32*E32 -> 621635 | H32: PAR | I32: =I31/D35 -> 0.017517802
B33: Doubtful | C33: 33 | D33: 5183552 | E33: 0.5 | F33: =D33*E33 -> 2591776
B34: Loss | C34: 321 | D34: 11412841 | E34: 1 | F34: =D34*E34 -> 11412841
B35: subtotal | C35: =SUM(C30:C34) -> 5497 | D35: =SUM(D30:D34) -> 1089345186 | E35: 1.81 | F35: =SUM(F30:F34) -> 26396940
D38: Audited 2021
B39: CLASSIFICATION | C39: NO. OF A/Cs | D39: OUTSTANDING LOAN PORTFOLIO(Kshs) | E39: REQUIRED PROVISION | F39: REQUIRED PROVISION AMOUNT(Kshs)
B40: Performing | C40: 4961 | D40: 10312387 | E40: 0.01 | F40: =D40*E40 -> 103123.87
B41: Watch | C41: 157 | D41: 770911 | E41: 0.05 | F41: =D41*E41 -> 38545.55
B42: Substandard | C42: 25 | D42: 2716646 | E42: 0.25 | F42: =D42*E42 -> 679161.5
B43: Doubtful | C43: 33 | D43: 4710165 | E43: 0.5 | F43: =D43*E43 -> 2355082.5
B44: Loss | C44: 321 | D44: 43687480 | E44: 1 | F44: =D44*E44 -> 43687480
B45: subtotal | C45: =SUM(C40:C44) -> 5497 | D45: =SUM(D40:D44) -> 62197589 | E45: 1.81 | F45: =SUM(F40:F44) -> 46863393
...

Sheet CAELS
A1: SMARTLIFE SACCO 2017 CAELS
D2: 2010 Audited | E2: 2020Audited | F2: 44198 | G2: 44230 | H2: 44259 | I2: 44291 | J2: 44322 | K2: 44354 | L2: 44385 | M2: 44417 | N2: 44449 | O2: 44480 | P2: 44512 | Q2: 44543 | R2: 2021 AUDITED | S2: 44576 | T2: 44608 | U2: 44637 | V2: 44669 | W2: 44700 | X2: 44732 | Y2: 44763 | Z2: 44795 | AA2: 44827 | AB2: 44858 | AC2: 44890 | AD2: 44921 | AE2: AUDITED2022 | AF2: 44952 | AG2: 44983 | AH2: 45011 | AI2: 45042 | AJ2: 45072 | AK2: 45103 | AL2: 45133 | AM2: 45164
A3: CAPITAL ADEQUACY | B3: Core Capital | C3: 10 M | D3: =(('Evolutive SFP'!B39+'Evolutive SFP'!B40+'Evolutive SFP'!B41+'Evolutive SFP'!B42+'Evolutive SFP'!B43+'Evolutive SFP'!B44)-'Evolutive SFP'!B10)/1000000 -> 15.259572 | E3: =(('Evolutive SFP'!C39+'Evolutive SFP'!C40+'Evolutive SFP'!C41+'Evolutive SFP'!C42+'Evolutive SFP'!C43+'Evolutive SFP'!C44)-'Evolutive SFP'!C10)/1000000 -> 210.09221 | F3: =(('Evolutive SFP'!D39+'Evolutive SFP'!D40+'Evolutive SFP'!D41+'Evolutive SFP'!D42+'Evolutive SFP'!D43+'Evolutive SFP'!D44)-'Evolutive SFP'!D10)/1000000 -> 215.1183 | G3: =(('Evolutive SFP'!E39+'Evolutive SFP'!E40+'Evolutive SFP'!E41+'Evolutive SFP'!E42+'Evolutive SFP'!E43+'Evolutive SFP'!E44)-'Evolutive SFP'!E10)/1000000 -> 215.2187 | H3: =(('Evolutive SFP'!F39+'Evolutive SFP'!F40+'Evolutive SFP'!F41+'Evolutive SFP'!F42+'Evolutive SFP'!F43+'Evolutive SFP'!F44)-'Evolutive SFP'!F10)/1000000 -> 220.08906 | I3: =(('Evolutive SFP'!G39+'Evolutive SFP'!G40+'Evolutive SFP'!G41+'Evolutive SFP'!G42+'Evolutive SFP'!G43+'Evolutive SFP'!G44)-'Evolutive SFP'!G10)/1000000 -> 227.05472 | J3: =(('Evolutive SFP'!H39+'Evolutive SFP'!H40+'Evolutive SFP'!H41+'Evolutive SFP'!H42+'Evolutive SFP'!H43+'Evolutive SFP'!H44)-'Evolutive SFP'!H10)/1000000 -> 229.68388 | K3: =(('Evolutive SFP'!I39+'Evolutive SFP'!I40+'Evolutive SFP'!I41+'Evolutive SFP'!I42+'Evolutive SFP'!I43+'Evolutive SFP'!I44)-'Evolutive SFP'!I10)/1000000 -> 229.25138 | ... AJ3: =(('Evolutive SFP'!AH39+'Evolutive SFP'!AH40+'Evolutive SFP'!AH41+'Evolutive SFP'!AH42+'Evolutive SFP'!AH43+'Evolutive SFP'!AH44)-'Evolutive SFP'!AH10)/1000000 -> 266.15734
B4: CCA | C4: Min 10% | D4: =D3/(('Evolutive SFP'!B27)/1000000) -> 0.10104624 | E4: =E3/(('Evolutive SFP'!C27)/1000000) -> 0.16984315 | F4: =F3/(('Evolutive SFP'!D27)/1000000) -> 0.18303141 | G4: =G3/(('Evolutive SFP'!E27)/1000000) -> 0.18100038 | H4: =H3/(('Evolutive SFP'!F27)/1000000) -> 0.18041502 | I4: =I3/(('Evolutive SFP'!G27)/1000000) -> 0.18564304 | J4: =J3/(('Evolutive SFP'!H27)/1000000) -> 0.18797964 | K4: =K3/(('Evolutive SFP'!I27)/1000000) -> 0.18594755 | ... AJ4: =AJ3/(('Evolutive SFP'!AH27)/1000000) -> 0.18603507
B5: CCD | C5: Min 8% | D5: =D3/('Evolutive SFP'!B31/1000000) -> 0.1186553 | E5: =E3/('Evolutive SFP'!C31/1000000) -> 0.24219203 | F5: =F3/('Evolutive SFP'!D31/1000000) -> 0.25598269 | G5: =G3/('Evolutive SFP'!E31/1000000) -> 0.2589827 | H5: =H3/('Evolutive SFP'!F31/1000000) -> 0.25744729 | I5: =I3/('Evolutive SFP'!G31/1000000) -> 0.26593633 | J5: =J3/('Evolutive SFP'!H31/1000000) -> 0.27078452 | K5: =K3/('Evolutive SFP'!I31/1000000) -> 0.26733158 | ... AJ5: =AJ3/('Evolutive SFP'!AH31/1000000) -> 0.28054718
B6: ICA | C6: Min 8% | D6: =((D3*1000000)-'Evolutive SFP'!B39)/'Evolutive SFP'!B27 -> 0.031552177 | E6: =((E3*1000000)-'Evolutive SFP'!C39)/'Evolutive SFP'!C27 -> 0.097560427 | F6: =((F3*1000000)-'Evolutive SFP'!D39)/'Evolutive SFP'!D27 -> 0.1066644 | G6: =((G3*1000000)-'Evolutive SFP'!E39)/'Evolutive SFP'!E27 -> 0.10527601 | H6: =((H3*1000000)-'Evolutive SFP'!F39)/'Evolutive SFP'!F27 -> 0.10645723 | I6: =((I3*1000000)-'Evolutive SFP'!G39)/'Evolutive SFP'!G27 -> 0.11153365 | J6: =((J3*1000000)-'Evolutive SFP'!H39)/'Evolutive SFP'!H27 -> 0.11351106 | K6: =((K3*1000000)-'Evolutive SFP'!I39)/'Evolutive SFP'!I27 -> 0.11187284 | ... AJ6: =((AJ3*1000000)-'Evolutive SFP'!AH39)/'Evolutive SFP'!AH27 -> 0.11644343
A7: ASSET QUALITY | B7: A/LNPL30 | H7: ='Evolutive SFP'!P312 -> 0 | N7: ='Evolutive SFP'!G16/('FORM 4'!E5+'FORM 4'!E6+'FORM 4'!E7) -> 30626620 | P7: ='Evolutive SFP'!N16/('FORM 4'!D14+'FORM 4'!D15+'FORM 4'!D16) -> 3.0190046 | Q7: ='Evolutive SFP'!O16/('FORM 4'!E14+'FORM 4'!E15+'FORM 4'!E16) -> 35427194 | R7: ='Evolutive SFP'!P16/('FORM 4'!F14+'FORM 4'!F15+'FORM 4'!F16) -> 6.4178134 | S7: ='Evolutive SFP'!Q16/('FORM 4'!G14+'FORM 4'!G15+'FORM 4'!G16) -> #DIV/0! | T7: ='Evolutive SFP'!R16/('FORM 4'!H14+'FORM 4'!H15+'FORM 4'!H16) -> #VALUE! | U7: ='Evolutive SFP'!S16/('FORM 4'!I14+'FORM 4'!I15+'FORM 4'!I16) -> 3.2598796e+09 | V7: ='Evolutive SFP'!T16/('FORM 4'!J14+'FORM 4'!J15+'FORM 4'!J16) -> #DIV/0! | W7: ='Evolutive SFP'!U16/('FORM 4'!K14+'FORM 4'!K15+'FORM 4'!K16) -> #DIV/0! | ... AJ7: ='Evolutive SFP'!AH16/('FORM 4'!X14+'FORM 4'!X15+'FORM 4'!X16) -> #DIV/0!
B8: NPL30 | H8: =('FORM 4'!D5+'FORM 4'!D6+'FORM 4'!D7) -> 18864250 | K8: =('FORM 4'!D14+'FORM 4'!D15+'FORM 4'!D16)/'Evolutive SFP'!I15 -> 0.019999999 | M8: =('FORM 4'!D5+'FORM 4'!D6+'FORM 4'!D7)/'Evolutive SFP'!K15 -> 0.018418263 | N8: =('FORM 4'!D23+'FORM 4'!D24+'FORM 4'!D25)/'Evolutive SFP'!L15 -> 0.020000001 | O8: =('FORM 4'!F5+'FORM 4'!F6+'FORM 4'!F7)/'Evolutive SFP'!M15 -> 0.0084659554 | P8: =('FORM 4'!G5+'FORM 4'!G6+'FORM 4'!G7)/'Evolutive SFP'!N15 -> 0 | Q8: =('FORM 4'!H5+'FORM 4'!H6+'FORM 4'!H7)/'Evolutive SFP'!O15 -> #VALUE! | R8: =('FORM 4'!I5+'FORM 4'!I6+'FORM 4'!I7)/'Evolutive SFP'!P15 -> 1.8192648e-11 | S8: =('FORM 4'!J5+'FORM 4'!J6+'FORM 4'!J7)/'Evolutive SFP'!Q15 -> 0 | T8: =('FORM 4'!K5+'FORM 4'!K6+'FORM 4'!K7)/'Evolutive SFP'!R15 -> 0 | U8: =('FORM 4'!L5+'FORM 4'!L6+'FORM 4'!L7)/'Evolutive SFP'!S15 -> 0 | V8: =('FORM 4'!M5+'FORM 4'!M6+'FORM 4'!M7)/'Evolutive SFP'!T15 -> 0 | ... AJ8: =('FORM 4'!AA5+'FORM 4'!AA6+'FORM 4'!AA7)/'Evolutive SFP'!AH15 -> 0
A9: EARNINGS | B9: ROA | E9: ='Evolutitve SCI'!C33/(('Evolutive SFP'!B27+'Evolutive SFP'!C27)/2) -> 0.0070769984 | F9: ='Evolutitve SCI'!D33/(('Evolutive SFP'!C27+'Evolutive SFP'!D27)/2) -> 0.0035587415 | G9: ='Evolutitve SCI'!E33/(('Evolutive SFP'!D27+'Evolutive SFP'!E27)/2) -> 0.0040410585 | H9: ='Evolutitve SCI'!F33/(('Evolutive SFP'!E27+'Evolutive SFP'!F27)/2) -> 0.007990549 | I9: ='Evolutitve SCI'!G33/(('Evolutive SFP'!F27+'Evolutive SFP'!G27)/2) -> 0.01315987 | J9: ='Evolutitve SCI'!H33/(('Evolutive SFP'!G27+'Evolutive SFP'!H27)/2) -> 0.015036443 | K9: ='Evolutitve SCI'!I33/(('Evolutive SFP'!H27+'Evolutive SFP'!I27)/2) -> 0.014375879 | L9: ='Evolutitve SCI'!J33/(('Evolutive SFP'!I27+'Evolutive SFP'!J27)/2) -> 0.013274815 | ... AJ9: ='Evolutitve SCI'!AH33/(('Evolutive SFP'!AG27+'Evolutive SFP'!AH27)/2) -> 0.0046370126
B10: Cost Income ratio | D10: ='Evolutitve SCI'!B23/'Evolutitve SCI'!B19 -> 0.78428841 | E10: ='Evolutitve SCI'!C23/'Evolutitve SCI'!C19 -> 0.69774181 | F10: ='Evolutitve SCI'!D23/'Evolutitve SCI'!D19 -> 0.33995278 | G10: ='Evolutitve SCI'!E23/'Evolutitve SCI'!E19 -> 0.55893474 | H10: ='Evolutitve SCI'!F23/'Evolutitve SCI'!F19 -> 0.47699292 | I10: ='Evolutitve SCI'!G23/'Evolutitve SCI'!G19 -> 0.42404205 | J10: ='Evolutitve SCI'!H23/'Evolutitve SCI'!H19 -> 0.43144581 | K10: ='Evolutitve SCI'!I23/'Evolutitve SCI'!I19 -> 0.48324722 | ... AJ10: ='Evolutitve SCI'!AH23/'Evolutitve SCI'!AH19 -> 0.81779676
B11: Operating Expense ratio | D11: =('Evolutitve SCI'!B23+'Evolutitve SCI'!B12)/(('Evolutive SFP'!B27+'Evolutive SFP'!C27)/2) -> 1.6669335e-05 | E11: =('Evolutitve SCI'!C23+'Evolutitve SCI'!C12)/(('Evolutive SFP'!C27+'Evolutive SFP'!D27)/2) -> 0.083316791 | F11: =('Evolutitve SCI'!D23+'Evolutitve SCI'!D12)/(('Evolutive SFP'!D27+'Evolutive SFP'!E27)/2) -> 0.004049284 | G11: =('Evolutitve SCI'!E23+'Evolutitve SCI'!E12)/(('Evolutive SFP'!E27+'Evolutive SFP'!F27)/2) -> 0.011431042 | H11: =('Evolutitve SCI'!F23+'Evolutitve SCI'!F12)/(('Evolutive SFP'!F27+'Evolutive SFP'!G27)/2) -> 0.016936172 | I11: =('Evolutitve SCI'!G23+'Evolutitve SCI'!G12)/(('Evolutive SFP'!G27+'Evolutive SFP'!H27)/2) -> 0.022106225 | J11: =('Evolutitve SCI'!H23+'Evolutitve SCI'!H12)/(('Evolutive SFP'!H27+'Evolutive SFP'!I27)/2) -> 0.029354985 | K11: =('Evolutitve SCI'!I23+'Evolutitve SCI'!I12)/(('Evolutive SFP'!I27+'Evolutive SFP'!J27)/2) -> 0.03991531 | ... AJ11: =('Evolutitve SCI'!AH23+'Evolutitve SCI'!AH12)/(('Evolutive SFP'!AH27+'Evolutive SFP'!AI27)/2) -> 0.052544175
A12: LIQUIDITY | B12: MIN LIQ ratio | C12: Min 15% | D12: =('Evolutive SFP'!B4)/('Evolutive SFP'!B28+'Evolutive SFP'!B29+'Evolutive SFP'!B32+'Evolutive SFP'!B33+'Evolutive SFP'!B34+'Evolutive SFP'!B35+'Evolutive SFP'!B36) -> 0.90806632 | E12: =('Evolutive SFP'!C4)/('Evolutive SFP'!C28+'Evolutive SFP'!C29+'Evolutive SFP'!C32+'Evolutive SFP'!C33+'Evolutive SFP'!C34+'Evolutive SFP'!C35+'Evolutive SFP'!C36) -> 0.48822814 | F12: =('Evolutive SFP'!D4)/('Evolutive SFP'!D28+'Evolutive SFP'!D29+'Evolutive SFP'!D32+'Evolutive SFP'!D33+'Evolutive SFP'!D34+'Evolutive SFP'!D35+'Evolutive SFP'!D36) -> 0.57026099 | G12: =('Evolutive SFP'!E4)/('Evolutive SFP'!E28+'Evolutive SFP'!E29+'Evolutive SFP'!E32+'Evolutive SFP'!E33+'Evolutive SFP'!E34+'Evolutive SFP'!E35+'Evolutive SFP'!E36) -> 0.56646193 | H12: =('Evolutive SFP'!F4)/('Evolutive SFP'!F28+'Evolutive SFP'!F29+'Evolutive SFP'!F32+'Evolutive SFP'!F33+'Evolutive SFP'!F34+'Evolutive SFP'!F35+'Evolutive SFP'!F36) -> 0.28050195 | I12: =('Evolutive SFP'!G4)/('Evolutive SFP'!G28+'Evolutive SFP'!G29+'Evolutive SFP'!G32+'Evolutive SFP'!G33+'Evolutive SFP'!G34+'Evolutive SFP'!G35+'Evolutive SFP'!G36) -> 0.36329891 | J12: =('Evolutive SFP'!H4)/('Evolutive SFP'!H28+'Evolutive SFP'!H29+'Evolutive SFP'!H32+'Evolutive SFP'!H33+'Evolutive SFP'!H34+'Evolutive SFP'!H35+'Evolutive SFP'!H36) -> 0.25075064 | K12: =('Evolutive SFP'!I4)/('Evolutive SFP'!I28+'Evolutive SFP'!I29+'Evolutive SFP'!I32+'Evolutive SFP'!I33+'Evolutive SFP'!I34+'Evolutive SFP'!I35+'Evolutive SFP'!I36) -> 0.38074033 | ... AJ12: =('Evolutive SFP'!AH4)/('Evolutive SFP'!AH28+'Evolutive SFP'!AH29+'Evolutive SFP'!AH32+'Evolutive SFP'!AH33+'Evolutive SFP'!AH34+'Evolutive SFP'!AH35+'Evolutive SFP'!AH36) -> 0.48793547
B13: T/LIQ ratio | D13: ='Evolutive SFP'!B4/('Evolutive SFP'!B31+'Evolutive SFP'!B36) -> 0.14915539 | E13: ='Evolutive SFP'!C4/('Evolutive SFP'!C31+'Evolutive SFP'!C36) -> 0.14798231 | F13: ='Evolutive SFP'!D4/('Evolutive SFP'!D31+'Evolutive SFP'!D36) -> 0.14596198 | G13: ='Evolutive SFP'!E4/('Evolutive SFP'!E31+'Evolutive SFP'!E36) -> 0.13702372 | H13: ='Evolutive SFP'!F4/('Evolutive SFP'!F31+'Evolutive SFP'!F36) -> 0.074955459 | I13: ='Evolutive SFP'!G4/('Evolutive SFP'!G31+'Evolutive SFP'!G36) -> 0.095027739 | J13: ='Evolutive SFP'!H4/('Evolutive SFP'!H31+'Evolutive SFP'!H36) -> 0.065053832 | K13: ='Evolutive SFP'!I4/('Evolutive SFP'!I31+'Evolutive SFP'!I36) -> 0.10223895 | ... AJ13: ='Evolutive SFP'!AH4/('Evolutive SFP'!AH31+'Evolutive SFP'!AH36) -> 0.13397354
B14: EB ratio | C14: Max 25% | D14: ='Evolutive SFP'!B37/'Evolutive SFP'!B27 -> 0.015175035 | E14: ='Evolutive SFP'!C37/'Evolutive SFP'!C27 -> 0.070071212 | F14: ='Evolutive SFP'!D37/'Evolutive SFP'!D27 -> 0.070570447 | G14: ='Evolutive SFP'!E37/'Evolutive SFP'!E27 -> 0.066034839 | H14: ='Evolutive SFP'!F37/'Evolutive SFP'!F27 -> 0.061359021 | I14: ='Evolutive SFP'!G37/'Evolutive SFP'!G27 -> 0.05820221 | J14: ='Evolutive SFP'!H37/'Evolutive SFP'!H27 -> 0.054638522 | K14: ='Evolutive SFP'!I37/'Evolutive SFP'!I27 -> 0.051175773 | ... AJ14: ='Evolutive SFP'!AH37/'Evolutive SFP'!AH27 -> 0.080201712
B15: LA to TA ratio | D15: ='Evolutive SFP'!B4/'Evolutive SFP'!B27 -> 0.12821992 | E15: ='Evolutive SFP'!C4/'Evolutive SFP'!C27 -> 0.10397515 | F15: ='Evolutive SFP'!D4/'Evolutive SFP'!D27 -> 0.10879202 | G15: ='Evolutive SFP'!E4/'Evolutive SFP'!E27 -> 0.099612431 | H15: ='Evolutive SFP'!F4/'Evolutive SFP'!F27 -> 0.054740729 | I15: ='Evolutive SFP'!G4/'Evolutive SFP'!G27 -> 0.069061819 | J15: ='Evolutive SFP'!H4/'Evolutive SFP'!H27 -> 0.047089256 | K15: ='Evolutive SFP'!I4/'Evolutive SFP'!I27 -> 0.073932183 | ... AJ15: ='Evolutive SFP'!AH4/'Evolutive SFP'!AH27 -> 0.093280181
A16: STRUCTURE | B16: NEA ratio | C16: Max 10% | D16: =('Evolutive SFP'!B7+'Evolutive SFP'!B21)/'Evolutive SFP'!B27 -> 0.12101375 | E16: =('Evolutive SFP'!C7+'Evolutive SFP'!C21)/'Evolutive SFP'!C27 -> 0.092978507 | F16: =('Evolutive SFP'!D7+'Evolutive SFP'!D21)/'Evolutive SFP'!D27 -> 0.03924726 | G16: =('Evolutive SFP'!E7+'Evolutive SFP'!E21)/'Evolutive SFP'!E27 -> 0.037199709 | H16: =('Evolutive SFP'!F7+'Evolutive SFP'!F21)/'Evolutive SFP'!F27 -> 0.10426899 | I16: =('Evolutive SFP'!G7+'Evolutive SFP'!G21)/'Evolutive SFP'!G27 -> 0.09247246 | J16: =('Evolutive SFP'!H7+'Evolutive SFP'!H21)/'Evolutive SFP'!H27 -> 0.11396338 | K16: =('Evolutive SFP'!I7+'Evolutive SFP'!I21)/'Evolutive SFP'!I27 -> 0.078373367 | ... AJ16: =('Evolutive SFP'!AH7+'Evolutive SFP'!AH21)/'Evolutive SFP'!AH27 -> 0.31248256
B17: LB ratio | C17: Max 5% | D17: ='Evolutive SFP'!B21/'Evolutive SFP'!B27 -> 0.032278671 | E17: ='Evolutive SFP'!C21/'Evolutive SFP'!C27 -> 0.020791445 | F17: ='Evolutive SFP'!D21/'Evolutive SFP'!D27 -> 0.01970122 | G17: ='Evolutive SFP'!E21/'Evolutive SFP'!E27 -> 0.019776856 | H17: ='Evolutive SFP'!F21/'Evolutive SFP'!F27 -> 0.019330926 | I17: ='Evolutive SFP'!G21/'Evolutive SFP'!G27 -> 0.019870722 | J17: ='Evolutive SFP'!H21/'Evolutive SFP'!H27 -> 0.020313096 | K17: ='Evolutive SFP'!I21/'Evolutive SFP'!I27 -> 0.023108189 | ... AJ17: ='Evolutive SFP'!AH21/'Evolutive SFP'!AH27 -> 0.2881529
B18: PI to Deposit ratio | C18: Max 5% | D18: ='Evolutive SFP'!B13/'Evolutive SFP'!B31 -> 0.0036721969 | E18: ='Evolutive SFP'!C13/'Evolutive SFP'!C31 -> 0.0028952531 | F18: ='Evolutive SFP'!D13/'Evolutive SFP'!D31 -> 0.023502968 | G18: ='Evolutive SFP'!E13/'Evolutive SFP'!E31 -> 0.058252552 | H18: ='Evolutive SFP'!F13/'Evolutive SFP'!F31 -> 0.056625766 | I18: ='Evolutive SFP'!G13/'Evolutive SFP'!G31 -> 0.056698471 | J18: ='Evolutive SFP'!H13/'Evolutive SFP'!H31 -> 0.05707127 | K18: ='Evolutive SFP'!I13/'Evolutive SFP'!I31 -> 0.056449815 | ... AJ18: ='Evolutive SFP'!AH13/'Evolutive SFP'!AH31 -> 0
B19: PI to CC ratio | C19: Max 40% | D19: ='Evolutive SFP'!B13/(CAELS!D3*1000000) -> 0.030948443 | E19: ='Evolutive SFP'!C13/(CAELS!E3*1000000) -> 0.01195437 | F19: ='Evolutive SFP'!D13/(CAELS!F3*1000000) -> 0.091814675 | G19: ='Evolutive SFP'!E13/(CAELS!G3*1000000) -> 0.22492835 | H19: ='Evolutive SFP'!F13/(CAELS!H3*1000000) -> 0.21995091 | I19: ='Evolutive SFP'!G13/(CAELS!I3*1000000) -> 0.21320318 | J19: ='Evolutive SFP'!H13/(CAELS!J3*1000000) -> 0.21076268 | K19: ='Evolutive SFP'!I13/(CAELS!K3*1000000) -> 0.21116029 | ... AJ19: ='Evolutive SFP'!AH13/(CAELS!AJ3*1000000) -> 0
B20: Gross loans/TA | D20: ='Evolutive SFP'!B15/'Evolutive SFP'!B27 -> 0.74763912 | E20: ='Evolutive SFP'!C15/'Evolutive SFP'!C27 -> 0.80420869 | F20: ='Evolutive SFP'!D15/'Evolutive SFP'!D27 -> 0.85098594 | G20: ='Evolutive SFP'!E15/'Evolutive SFP'!E27 -> 0.83896397 | H20: ='Evolutive SFP'!F15/'Evolutive SFP'!F27 -> 0.81819878 | I20: ='Evolutive SFP'!G15/'Evolutive SFP'!G27 -> 0.81655086 | J20: ='Evolutive SFP'!H15/'Evolutive SFP'!H27 -> 0.81770107 | K20: ='Evolutive SFP'!I15/'Evolutive SFP'!I27 -> 0.8274493 | ... AJ20: ='Evolutive SFP'!AH15/'Evolutive SFP'!AH27 -> 0.55917538
