Workbook
Name BALANCE1_LDA01: '[1]Financial Statements'!$E$112
Name BALANCE1_LDA12: '[1]Financial Statements'!$E$123
Name BALANCE2_LDA01: '[1]Financial Statements'!$F$112
Name BALANCE2_LDA12: '[1]Financial Statements'!$F$123
Name BALANCE3_LDA01: '[1]Financial Statements'!$G$112
Name BALANCE3_LDA12: '[1]Financial Statements'!$G$123
Name BALANCE4_LDA01: '[1]Financial Statements'!$H$112
Name BALANCE4_LDA12: '[1]Financial Statements'!$H$123
Name BALANCE5_LDA01: '[1]Financial Statements'!$I$112
Name BALANCE5_LDA12: '[1]Financial Statements'!$I$123
Name BALANCE6_LDA01: '[1]Financial Statements'!$J$112
Name BALANCE6_LDA12: '[1]Financial Statements'!$J$123
Name NotApplicable: #REF!
Name PEARLS1_LA002: '[1]Financial Statements'!$E$280
Name PEARLS1_LE008: '[1]Financial Statements'!$E$275
Name PEARLS1_LE009: '[1]Financial Statements'!$E$276
Name PEARLS1_LR001: '[1]Financial Statements'!$E$282
Name PEARLS1_LR005: '[1]Financial Statements'!$E$286
Name PEARLS1_LR006: '[1]Financial Statements'!$E$287
Name PEARLS1_LR007: '[1]Financial Statements'!$E$288
Name PEARLS1_LR009: '[1]Financial Statements'!$E$290
Name PEARLS1_LS001: '[1]Financial Statements'!$E$298
Name PEARLS1_LS005: '[1]Financial Statements'!$E$302
Name PEARLS1_LS011: '[1]Financial Statements'!$E$308
Name PEARLS2_LA002: '[1]Financial Statements'!$F$280
Name PEARLS2_LE008: '[1]Financial Statements'!$F$275
Name PEARLS2_LE009: '[1]Financial Statements'!$F$276
Name PEARLS2_LR001: '[1]Financial Statements'!$F$282
Name PEARLS2_LR005: '[1]Financial Statements'!$F$286
Name PEARLS2_LR006: '[1]Financial Statements'!$F$287
Name PEARLS2_LR007: '[1]Financial Statements'!$F$288
Name PEARLS2_LR009: '[1]Financial Statements'!$F$290
Name PEARLS2_LS001: '[1]Financial Statements'!$F$298
Name PEARLS2_LS005: '[1]Financial Statements'!$F$302
Name PEARLS2_LS010: '[1]Financial Statements'!$F$307
Name PEARLS2_LS011: '[1]Financial Statements'!$F$308
Name PEARLS3_LA002: '[1]Financial Statements'!$G$280
Name PEARLS3_LE008: '[1]Financial Statements'!$G$275
Name PEARLS3_LE009: '[1]Financial Statements'!$G$276
Name PEARLS3_LR001: '[1]Financial Statements'!$G$282
Name PEARLS3_LR005: '[1]Financial Statements'!$G$286
Name PEARLS3_LR006: '[1]Financial Statements'!$G$287
Name PEARLS3_LR007: '[1]Financial Statements'!$G$288
Name PEARLS3_LR009: '[1]Financial Statements'!$G$290
Name PEARLS3_LS001: '[1]Financial Statements'!$G$298
Name PEARLS3_LS005: '[1]Financial Statements'!$G$302
Name PEARLS3_LS010: '[1]Financial Statements'!$G$307
Name PEARLS3_LS011: '[1]Financial Statements'!$G$308
Name PEARLS4_LA002: '[1]Financial Statements'!$H$280
Name PEARLS4_LE008: '[1]Financial Statements'!$H$275
Name PEARLS4_LE009: '[1]Financial Statements'!$H$276
Name PEARLS4_LR001: '[1]Financial Statements'!$H$282
Name PEARLS4_LR005: '[1]Financial Statements'!$H$286
Name PEARLS4_LR006: '[1]Financial Statements'!$H$287
Name PEARLS4_LR007: '[1]Financial Statements'!$H$288
Name PEARLS4_LR009: '[1]Financial Statements'!$H$290
Name PEARLS4_LS001: '[1]Financial Statements'!$H$298
Name PEARLS4_LS005: '[1]Financial Statements'!$H$302
Name PEARLS4_LS010: '[1]Financial Statements'!$H$307
Name PEARLS4_LS011: '[1]Financial Statements'!$H$308

Sheet Trend
B1: SOTICO SACCO
B2: ASSETS | C2: Audit 2016 | D2: Audit 2017 | E2: Audit 2018 | F2: Audit 2019 | G2: 43831 | H2: 43862 | I2: 43891 | J2: 43922 | K2: 43952 | L2: 43983 | M2: 44013 | N2: 44044 | O2: 44075 | P2: 44105 | Q2: 44136 | R2: 44166 | S2: Audited 2020 | T2: 44217 | U2: 44248 | V2: 44276 | W2: 44307 | X2: 44337 | Y2: 44368 | Z2: 44398 | AA2: 44429 | AB2: 44460 | AC2: 44490 | AD2: 44521 | AE2: 44551 | AF2: audited 21 | AG2: 44582 | AH2: 44613 | AI2: 44641 | AJ2: 44672 | AK2: 44702 | AL2: 44733 | AM2: 44763 | AN2: 44794 | AO2: 44825 | AP2: 44855 | AQ2: 44886 | AR2: 44916 | AS2: Audited 2022 | AT2: 44927 | AU2: 44958 | AV2: 44986 | AW2: 45017 | AX2: 45047 | AY2: 45078 | AZ2: 45108 | BA2: 45139 | BB2: 45170 | BC2: 45200
B3: Cash and Cash Equivalent | C3: =C4+C5 -> 27227584 | D3: =D4+D5 -> 20473615 | E3: =E4+E5 -> 29501244 | F3: =F4+F5 -> 52141499 | G3: =G4+G5 -> 28844168 | H3: =H4+H5 -> 28253972 | I3: =I4+I5 -> 41920668 | J3: =J4+J5 -> 37566335 | ... BC3: =BC4+BC5 -> 0
B4: Cash in hand(both local and foreign notes and coins) | C4: 169124 | D4: 895020 | E4: 1271319 | F4: 3664875 | G4: 1795796 | H4: 2840851 | I4: 11998592 | J4: 2633772 | K4: 2443459 | L4: 1180714 | M4: 1859636 | N4: 1697909 | O4: 3188901 | P4: 1602048 | Q4: 279037 | R4: 648514 | S4: 631414 | T4: 1512742 | U4: 1735893 | V4: 4383087 | W4: 744029 | X4: 1864038 | Y4: 1410962 | Z4: 695173 | AA4: 577366 | AB4: 528792 | AC4: 733129 | AD4: 737157 | AE4: 1327867 | AF4: 1200917 | AG4: 1463496 | AH4: 397781 | AI4: 1935733 | AJ4: 1225532 | AK4: 292550 | AL4: 758099 | AM4: 1875881 | AN4: 2344131 | AO4: 2474530 | AP4: 2879290 | AQ4: 1345227 | AR4: 4462609 | AS4: 4328509 | AT4: 2535627 | AU4: 937581 | AV4: 1291167 | AW4: 656334 | AX4: 630848 | AY4: 1296450 | AZ4: 3799733
B5: Cash at bank:(placement with financial institutions) | C5: 27058460 | D5: 19578595 | E5: 28229925 | F5: =52141499-3664875 -> 48476624 | G5: 27048372 | H5: 25413121 | I5: 29922076 | J5: 34932563 | K5: 33397671 | L5: 33252214 | M5: 30648873 | N5: 28143498 | O5: 28705517 | P5: 25104929 | Q5: 30725664 | R5: 27038645 | S5: =27606849-S4 -> 26975435 | T5: 35633245 | U5: 32524837 | V5: 33033300 | W5: 34540914 | X5: 30026103 | Y5: 29131596 | Z5: 21076734 | AA5: 19527515 | AB5: 21883073 | AC5: 25014973 | AD5: 48735601 | AE5: 25612090 | AF5: 25645434 | AG5: 31826537 | AH5: 21620058 | AI5: 29450093 | AJ5: 16931651 | AK5: 16881830 | AL5: 24688130 | AM5: 25726686 | AN5: 21493412 | AO5: 23906817 | AP5: 25671312 | AQ5: 29994725 | AR5: 24165791 | AS5: =5505784+537250+17519568+15000+134100+588189 -> 24299891 | AT5: 25365880 | AU5: 24212389 | AV5: 15699303 | AW5: 20973910 | AX5: 21016722 | AY5: 25853378 | AZ5: 48236559
B7: Prepayments and Sundry Receivables | C7: 625108 | D7: 109588 | E7: 292674 | F7: 83945 | G7: 1374105.4 | H7: 1264313.4 | I7: 1198812.4 | J7: 1198812.4 | K7: 990479.02 | L7: 948812.35 | M7: 982916.35 | N7: 982916.35 | O7: 863394.35 | P7: 854931.35 | Q7: 112307.18 | R7: 661012.35 | S7: 81853 | T7: 752023.35 | U7: 690999.35 | V7: 682023.35 | W7: 682023.35 | X7: 397847.52 | Y7: 341012.35 | Z7: 284177.18 | AA7: 227342.02 | AB7: 170506.85 | AC7: 113671.68 | AD7: 56836.52 | AE7: 769726.5 | AF7: 912262 | AG7: 906229.18 | AH7: 500716.86 | AI7: 928158.75 | AJ7: 121349.35 | AK7: 106180.85 | AL7: 91012.35 | AM7: 75843.85 | AN7: 1.35 | AO7: 1.35 | AP7: 1.35 | AQ7: 1.35 | AR7: 667030.22 | AS7: 674602 | AT7: 731249.5 | AU7: 763289.5 | AV7: 0 | AW7: 640688.98 | AX7: 820328.67 | AY7: 657174.8 | AZ7: 951507.05
B9: Financial Investments | C9: =SUM(C10:C14) -> 40449810 | D9: =SUM(D10:D14) -> 49120055 | E9: =SUM(E10:E14) -> 49120055 | F9: =SUM(F10:F14) -> 49120055 | G9: =SUM(G10:G14) -> 49120055 | H9: =SUM(H10:H14) -> 49120055 | I9: =SUM(I10:I14) -> 49120055 | J9: =SUM(J10:J14) -> 49120055 | ... BC9: =SUM(BC10:BC14) -> 0
B10: Government Securities - Treasury Bills/bonds, | G10: 0 | H10: 0 | I10: 0 | J10: 0 | K10: 0 | L10: 0 | M10: 0 | N10: 0 | O10: 0 | P10: 0 | Q10: 0 | R10: 0 | S10: 0 | T10: 0 | U10: 0 | V10: 0 | W10: 0 | X10: 0 | Y10: 0 | Z10: 0 | AA10: 0 | AB10: 0 | AC10: 0 | AD10: 0 | AE10: 0 | AG10: 0 | AH10: 0 | AI10: 0 | AJ10: 0 | AK10: 0 | AL10: 0 | AM10: 0 | AN10: 0 | AO10: 0 | AP10: 0 | AQ10: 0 | AR10: 0 | AS10: 0 | AT10: 0 | AU10: 0 | AV10: 0 | AW10: 0 | AX10: 0 | AY10: 0 | AZ10: 0
B11: Other Securities - Commercial papers/Bonds | G11: 0 | H11: 0 | I11: 0 | J11: 0 | K11: 0 | L11: 0 | M11: 0 | N11: 0 | O11: 0 | P11: 0 | Q11: 0 | R11: 0 | S11: 0 | T11: 0 | U11: 0 | V11: 0 | W11: 0 | X11: 0 | Y11: 0 | Z11: 0 | AA11: 0 | AB11: 0 | AC11: 0 | AD11: 0 | AE11: 0 | AG11: 0 | AH11: 0 | AI11: 0 | AJ11: 0 | AK11: 0 | AL11: 0 | AM11: 0 | AN11: 0 | AO11: 0 | AP11: 0 | AQ11: 0 | AR11: 0 | AT11: 0 | AU11: 0 | AV11: 0 | AW11: 0 | AX11: 0 | AY11: 0 | AZ11: 0
B12: Balances with other SACCO Societies | G12: 0 | H12: 0 | I12: 0 | J12: 0 | K12: 0 | L12: 0 | M12: 0 | N12: 0 | AB12: 0 | AC12: 0 | AD12: 0 | AE12: 0 | AG12: 5151497.8 | AH12: 5151497.8 | AI12: 5151497.8 | AJ12: 5151497.8 | AK12: 5151497.8 | AL12: 5151497.8 | AM12: 5151497.8 | AN12: 5151497.8 | AO12: 5151497.8 | AP12: 5151497.8 | AQ12: 5151497.8 | AR12: 5151497.8 | AS12: =5051088+35280+65130 -> 5151498 | AT12: 5151497.8 | AU12: 5151497.8 | AV12: 5151497.8 | AW12: 5151497.8 | AX12: 5151497.8 | AY12: 5151497.8 | AZ12: 0
B13: Equity Investments in NACCOs(Shares in- CIC, KUSCCO, COOP BANK,CAK, KERUSSU) | C13: 40449810 | D13: 49120055 | E13: 49120055 | F13: 49120055 | G13: 49120055 | H13: 49120055 | I13: 49120055 | J13: 49120055 | K13: 49120055 | L13: 49120055 | M13: 49120055 | N13: 49120055 | O13: 49120055 | P13: 49120055 | Q13: 49120055 | R13: 49120055 | S13: 5151498 | T13: 49120055 | U13: 5151497.8 | V13: 5151497.8 | W13: 5151497.8 | X13: 5151497.8 | Y13: 5151497.8 | Z13: 5151497.8 | AA13: 5151497.8 | AB13: 5151497.8 | AC13: 5151497.8 | AD13: 5151497.8 | AE13: 5151497.8 | AF13: 5151498 | AG13: 0 | AH13: 0 | AI13: 0 | AJ13: 0 | AK13: 0 | AL13: 0 | AM13: 0 | AN13: 0 | AO13: 0 | AP13: 0 | AQ13: 0 | AR13: 0
B14: Investments in companies - shares/stocks | AQ14: 0 | AR14: 0 | AS14: 0 | AT14: 0 | AU14: 0 | AV14: 0 | AW14: 5151497.8
B16: Net Loan Portfolio | C16: =C17-C18 -> 108864930 | D16: =D17-D18 -> 112673981 | E16: =E17-E18 -> 118004126 | F16: =F17-F18 -> 126643002 | G16: =G17-G18 -> 144740267 | H16: =H17-H18 -> 139423704 | I16: =I17-I18 -> 138129985 | J16: =J17-J18 -> 133289652 | ... BC16: =BC17-BC18 -> 0
B17: Gross Loan Portfolio | C17: 112489704 | D17: 116513632 | E17: 121965745 | F17: 131804621 | G17: 149901886 | H17: 144585323 | I17: 143291604 | J17: 138451271 | K17: 139995318 | L17: 140220540 | M17: 1.4525861e+08 | N17: 150498478 | O17: 160536761 | P17: 166635163 | Q17: 170750046 | R17: 170698863 | S17: 1.7059549e+08 | T17: 178942254 | U17: 178656087 | V17: 174685518 | W17: 174679684 | X17: 173688465 | Y17: 171002891 | Z17: 189899417 | AA17: 187254428 | AB17: 183109082 | AC17: 183367220 | AD17: 178461929 | AE17: 181539412 | AF17: 181532478 | AG17: 178604455 | AH17: 174805092 | AI17: 171770087 | AJ17: 188776405 | AK17: 187498957 | AL17: 184227194 | AM17: 182534610 | AN17: 188451436 | AO17: 189307357 | AP17: 192071109 | AQ17: 187514511 | AR17: 191230019 | AS17: =188945414+2285196 -> 191230610 | AT17: 210078476 | AU17: 212498557 | AV17: 203656338 | AW17: 197965618 | AX17: 197327218 | AY17: 195353913 | AZ17: 187471588
B18: Allowance for Loan Loss | C18: 3624774 | D18: 3839651 | E18: 3961619 | F18: 5161619 | G18: 5161619 | H18: 5161619 | I18: 5161619 | J18: 5161619 | K18: 5494952.3 | L18: 5561619 | M18: 5661619 | N18: 5661619 | O18: 5661619 | P18: 5661619 | Q18: 5661619 | R18: 5661619 | S18: 5661619 | T18: 5661619 | U18: 5661619 | V18: 5661619 | W18: 5661619 | X18: 5661619 | Y18: 5661619 | Z18: 5661619 | AA18: 5661619 | AB18: 5661619 | AC18: 5661619 | AD18: 5661619 | AE18: 5961619 | AF18: 5961619 | AG18: 5961619 | AH18: 5961619 | AI18: 5961619 | AJ18: 5961619 | AK18: 5961619 | AL18: 5961619 | AM18: 5961619 | AN18: 5961619 | AO18: 5961619 | AP18: 5961619 | AQ18: 5961619 | AR18: 6261619 | AS18: 6261619 | AT18: 6261619 | AU18: 6261619 | AV18: 6261619 | AW18: 6261619 | AX18: 6261619 | AY18: 6411619 | AZ18: 6411619
AS19: 0
B20: Account Receivables | C20: =SUM(C21:C23) -> 0 | D20: =SUM(D21:D23) -> 0 | E20: =SUM(E21:E23) -> 0 | F20: =SUM(F21:F23) -> 24654 | G20: =SUM(G21:G23) -> 24654.37 | H20: =SUM(H21:H23) -> 24654.37 | I20: =SUM(I21:I23) -> 24654.37 | J20: =SUM(J21:J23) -> 24654.37 | ... AE20: =SUM(AE21:AE23) -> 0 | AF20: 0 | AG20: =SUM(AG21:AG23) -> 0 | AH20: =SUM(AH21:AH23) -> 0 | AI20: =SUM(AI21:AI23) -> 0 | AJ20: =SUM(AJ21:AJ23) -> 0 | AK20: =SUM(AK21:AK23) -> 0 | AL20: =SUM(AL21:AL23) -> 0 | AM20: =SUM(AM21:AM23) -> 0 | AN20: =SUM(AN21:AN23) -> 0 | ... BC20: =SUM(BC21:BC23) -> 0
B21: Tax Recoverable | G21: 0 | H21: 0 | I21: 0 | J21: 0 | K21: 0 | L21: 0 | N21: 0 | O21: 0 | P21: 0 | Q21: 0 | R21: 0 | S21: 0 | T21: 0 | U21: 0 | V21: 0 | W21: 0 | X21: 0 | Y21: 0 | Z21: 0 | AA21: 0 | AS21: 87423 | AT21: 0 | AU21: 0 | AV21: 0 | AW21: 0 | AX21: 0 | AY21: 0 | AZ21: 0
B22: Deferred Tax Assets | F22: 24654 | G22: 24654.37 | H22: 24654.37 | I22: 24654.37 | J22: 24654.37 | K22: 24654.37 | L22: 24654.37 | M22: 24654.365 | N22: 24654.37 | O22: 24654.37 | P22: 24654.37 | Q22: 24654.37 | R22: 24654.37 | S22: 24654.37 | T22: 24654.37 | U22: 0 | V22: 0 | W22: 0 | X22: 0 | Y22: 0 | Z22: 0 | AA22: 0 | AS22: 0 | AT22: 0 | AU22: 0 | AV22: 0 | AW22: 0 | AX22: 0 | AY22: 0 | AZ22: 0
B23: Retirement Benefit Assets | G23: 0 | H23: 0 | I23: 0 | J23: 0 | K23: 0 | L23: 0 | N23: 0 | O23: 0 | P23: 0 | Q23: 0 | R23: 0 | S23: 0 | T23: 0 | U23: 0 | V23: 0 | W23: 0 | X23: 0 | Y23: 0 | Z23: 0 | AA23: 0 | AS23: 0 | AT23: 0 | AU23: 0 | AV23: 0 | AW23: 0 | AX23: 0 | AY23: 0 | AZ23: 0
B25: Property and Equipment and Other Assets | C25: =SUM(C26:C30) -> 12988708 | D25: =SUM(D26:D30) -> 16405838 | E25: =SUM(E26:E30) -> 18915297 | F25: =SUM(F26:F30) -> 18369726 | G25: =SUM(G26:G30) -> 17066422 | H25: =SUM(H26:H30) -> 17019582 | I25: =SUM(I26:I30) -> 17004895 | J25: =SUM(J26:J30) -> 16944609 | ... BC25: =SUM(BC26:BC30) -> 0
B26: Investment Properties | F26: 4728302 | G26: 4038480 | H26: 4728302 | I26: 4728302 | J26: 4728302 | K26: 4728302 | L26: 4728302 | M26: 4728302 | N26: 4728302 | O26: 4728302 | P26: 4728302 | Q26: 4728302 | R26: 4728302 | T26: 4728302 | U26: 4728302 | V26: 4774302 | W26: 4781552 | X26: 4781552 | Y26: 4781552 | Z26: 4821552 | AA26: 4938552 | AB26: 6310511.4 | AC26: 5990211.4 | AD26: 5990211.4 | AE26: 5990211.4 | AG26: 5990211.4 | AH26: 5990211.4 | AI26: 5990211.4 | AJ26: 5990211.4 | AK26: 5990211.4 | AL26: 5990211.4 | AM26: 5990211.4 | AN26: 5990211.4 | AO26: 5990211.4 | AP26: 5990211.4 | AQ26: 5990211.4 | AR26: 5990211.4 | AT26: 5990211.4 | AU26: 5990211.4 | AV26: 5990211.4 | AW26: 5990211.4 | AX26: 5990211.4 | AY26: 5990211.4 | AZ26: 5990211
B27: Property and Equipment | C27: 10052178 | D27: 14045660 | E27: 16051260 | F27: =10646547+399391+117946+468108 -> 11631992 | G27: 12221216 | H27: 11505240 | I27: 11511238 | J27: 11445987 | K27: 11380736 | L27: 11357710 | M27: 11357710 | N27: 11225284 | O27: 11159071 | P27: 11092858 | Q27: 11038721 | R27: 10972366 | S27: 15634519 | T27: 10849265 | U27: 10865392 | V27: 10807179 | W27: 10748967 | X27: 10711265 | Y27: 10652826 | Z27: 10594388 | AA27: 10535950 | AB27: 10477512 | AC27: 10587505 | AD27: 10524818 | AE27: 10465663 | AF27: 16491564 | AG27: 10450124 | AH27: 10398896 | AI27: 10347668 | AJ27: 10296440 | AK27: 10245212 | AL27: 10193984 | AM27: 10157352 | AN27: 10105995 | AO27: 10054638 | AP27: 10003280 | AQ27: 11455428 | AR27: 9900566 | AS27: 15890778 | AT27: 9853417 | AU27: 9806268 | AV27: 9759119 | AW27: 9711970 | AX27: 9664821 | AY27: 9617672 | AZ27: 9570523
B28: Prepaid lease rentals | G28: 0 | H28: 0 | I28: 0 | J28: 0 | K28: 0 | L28: 0 | M28: 0 | N28: 0 | O28: 0 | P28: 0 | Q28: 0 | R28: 0 | T28: 0 | U28: 0 | V28: 0 | W28: 0 | X28: 0 | Y28: 0 | Z28: 0 | AA28: 0 | AB28: 0 | AC28: 0 | AD28: 0 | AE28: 0 | AG28: 0 | AH28: 0 | AI28: 0 | AJ28: 0 | AK28: 0 | AL28: 0 | AM28: 0 | AN28: 0 | AO28: 0 | AP28: 0 | AQ28: 0 | AR28: 0 | AT28: 0 | AU28: 0 | AV28: 0 | AW28: 0 | AX28: 0 | AY28: 0 | AZ28: 0
B29: intangible assets | C29: 254508 | D29: 178156.03 | E29: 1182015 | F29: 827410 | G29: 806725.58 | H29: 786040.31 | I29: 765355.04 | J29: 770319.77 | K29: 748922 | L29: 703299.23 | M29: 703299.23 | N29: 661928.68 | O29: 641243.41 | P29: 620558.14 | Q29: 599872.87 | R29: 579187.6 | S29: 645336 | T29: 579187.6 | U29: 613069.67 | V29: 596936.26 | W29: 580802.85 | X29: 564669.44 | Y29: 548536.02 | Z29: 532402.61 | AA29: 516269.2 | AB29: 500135.79 | AC29: 484002.37 | AD29: 467868.96 | AE29: 451735.55 | AF29: 484002 | AG29: 473919.2 | AH29: 463835.81 | AI29: 453752.42 | AJ29: 443669.04 | AK29: 433585.65 | AL29: 423502.26 | AM29: 413418.88 | AN29: 403335.49 | AO29: 393252.1 | AP29: 383168.71 | AQ29: 373085.33 | AR29: 363001.94 | AS29: 363001 | AT29: 355439.64 | AU29: 347877.1 | AV29: 340314.55 | AW29: 332752.01 | AX29: 325189.46 | AY29: 317626.92 | AZ29: 310064
B30: Other Assets | C30: 2682022 | D30: 2182022 | E30: 1682022 | F30: 1182022 | G30: 0 | H30: 0 | I30: 0 | J30: 0 | K30: 0 | L30: 0 | N30: 0 | O30: 0 | P30: 0 | Q30: 0 | R30: 0 | S30: 682022 | T30: 0 | U30: 0 | V30: 0 | W30: 0 | X30: 0 | Y30: 0 | Z30: 0 | AA30: 0 | AB30: 0 | AC30: 0 | AD30: 0 | AE30: 0 | AG30: 0 | AH30: 0 | AI30: 0 | AJ30: 0 | AK30: 0 | AL30: 0 | AM30: 0 | AN30: 0 | AO30: 0 | AP30: 0 | AQ30: 0 | AR30: 0 | AT30: 0 | AU30: 0 | AV30: 0 | AW30: 0 | AX30: 0 | AY30: 0 | AZ30: 0
B32: Total Assets | C32: =C3+C7+C9+C16+C20+C25 -> 190156140 | D32: =D3+D7+D9+D16+D20+D25 -> 1.9878308e+08 | E32: =E3+E7+E9+E16+E20+E25 -> 215833396 | F32: =F3+F7+F9+F16+F20+F25 -> 246382881 | G32: =G3+G7+G9+G16+G20+G25 -> 2.4116967e+08 | H32: =H3+H7+H9+H16+H20+H25 -> 2.3510628e+08 | I32: =I3+I7+I9+I16+I20+I25 -> 2.4739907e+08 | J32: =J3+J7+J9+J16+J20+J25 -> 2.3814412e+08 | ... AS32: =AS3+AS7+AS9+AS16+AS20+AS25 -> 235764693 | AT32: =AT3+#REF!+AT9+AT16+AT20+AT25 -> #REF! | AU32: =AU3+#REF!+AU9+AU16+AU20+AU25 -> #REF! | AV32: =AV3+#REF!+AV9+AV16+AV20+AV25 -> #REF! | AW32: =AW3+#REF!+AW9+AW16+AW20+AW25 -> #REF! | AX32: =AX3+#REF!+AX9+AX16+AX20+AX25 -> #REF! | AY32: =AY3+#REF!+AY9+AY16+AY20+AY25 -> #REF! | AZ32: =AZ3+#REF!+AZ9+AZ16+AZ20+AZ25 -> #REF! | BA32: =BA3+BA7+BA9+BA16+BA20+BA25 -> 0 | BB32: =BB3+BB7+BB9+BB16+BB20+BB25 -> 0 | BC32: =BC3+BC7+BC9+BC16+BC20+BC25 -> 0
B34: LIABILITIES
B35: Savings Deposits - Withdrawable deposits - FOSA) | C35: 8225206 | D35: 7582824 | E35: 12295782 | F35: =2750359+13768541 -> 16518900 | G35: 10725594 | H35: 9323076 | I35: 9323076 | J35: 9323076 | K35: 12848608 | L35: 12332975 | M35: 12332975 | N35: 11041856 | O35: 12509093 | P35: 11318113 | Q35: 16644640 | R35: 14908062 | S35: 14908062 | T35: 14174609 | U35: 14174609 | V35: 24128229 | W35: 12983252 | X35: 13708126 | Y35: 12824131 | Z35: 16101738 | AA35: 16384201 | AB35: 12302073 | AC35: 11240594 | AD35: 11011255 | AE35: 11261843 | AF35: 10866395 | AG35: 11477157 | AH35: 13578330 | AI35: 15269225 | AJ35: 16288304 | AK35: 14249401 | AL35: 14249401 | AM35: 11203778 | AN35: 12634700 | AO35: 12403805 | AP35: 13252408 | AQ35: 12393395 | AR35: 11231947 | AS35: 11188730
B36: Short Term Deposits (e.g Fixed deposits, special savings) | C36: 1506728 | D36: 972987 | G36: 2210643 | H36: 2214951 | I36: 1961671 | J36: 2086980 | K36: 2963541 | L36: 3022835 | M36: 3143066.1 | N36: 3724149 | O36: 3597590 | P36: 3604241 | Q36: 3744423 | R36: 3455423 | S36: 3455423 | T36: 3329227 | U36: 3219756 | V36: 3058071 | W36: 3498168 | X36: 2686474 | Y36: 2616111 | Z36: 2045376 | AA36: 2359674 | AB36: 2037786 | AC36: 2560064 | AD36: 2649900 | AE36: 3329981 | AF36: 3732181 | AG36: 3629057 | AH36: 3297345 | AI36: 4706910 | AJ36: 3317899 | AK36: 3491565 | AL36: 3197394 | AM36: 3544007 | AN36: 3602829 | AO36: 3768963 | AP36: 3565751 | AQ36: 3984635 | AR36: 3956965 | AS36: =981250+2975715 -> 3956965
B37: Non withdrawable deposits (BOSA member deposits) | C37: 93532161 | D37: 98991963 | E37: 109828204 | F37: 116729770 | G37: 117465834 | H37: 118247917 | I37: 119559661 | J37: 120700906 | K37: 122212542 | L37: 124213870 | M37: 1.2626295e+08 | N37: 128279307 | O37: 130016226 | P37: 131724520 | Q37: 133734795 | R37: 135994936 | S37: 135994936 | T37: 136653263 | U37: 137537284 | V37: 139195096 | W37: 140475752 | X37: 141528870 | Y37: 141453588 | Z37: 142098601 | AA37: 142486180 | AB37: 143168702 | AC37: 143994254 | AD37: 143554875 | AE37: 146927870 | AF37: 146924536 | AG37: 147221478 | AH37: 148468081 | AI37: 150105966 | AJ37: 151905118 | AK37: 152648620 | AL37: 152865832 | AM37: 153860576 | AN37: 154727604 | AO37: 155462672 | AP37: 158029895 | AQ37: 156535062 | AR37: 157906218 | AS37: 157906218
B38: Total Deposit Liabilities | C38: =SUM(C35:C37) -> 103264095 | D38: =SUM(D35:D37) -> 107547774 | E38: =SUM(E35:E37) -> 122123986 | F38: =SUM(F35:F37) -> 133248670 | G38: =SUM(G35:G37) -> 130402071 | H38: =SUM(H35:H37) -> 129785944 | I38: =SUM(I35:I37) -> 130844408 | J38: =SUM(J35:J37) -> 132110962 | ... AE38: =SUM(AE35:AE37) -> 161519694 | AF38: 161523112 | AG38: =SUM(AG35:AG37) -> 162327692 | AH38: =SUM(AH35:AH37) -> 165343756 | AI38: =SUM(AI35:AI37) -> 170082101 | AJ38: =SUM(AJ35:AJ37) -> 171511321 | AK38: =SUM(AK35:AK37) -> 170389586 | AL38: =SUM(AL35:AL37) -> 170312627 | AM38: =SUM(AM35:AM37) -> 168608361 | AN38: =SUM(AN35:AN37) -> 170965133 | ... BC38: =SUM(BC35:BC37) -> 0
B40: Accounts Payable Other Liabilities | C40: =SUM(C41:C46) -> 25491076 | D40: =SUM(D41:D46) -> 19847333 | E40: =SUM(E41:E46) -> 21277512 | F40: =SUM(F41:F46) -> 39923867 | G40: =SUM(G41:G46) -> 36157376 | H40: =SUM(H42:H46) -> 31404626 | I40: =SUM(I42:I46) -> 42591870 | J40: =SUM(J42:J46) -> 32154417 | K40: =SUM(K42:K46) -> 24771760 | L40: =SUM(L42:L46) -> 21188898 | M40: =SUM(M42:M46) -> 21177452 | N40: =SUM(N42:N46) -> 21688671 | O40: =SUM(O42:O46) -> 29589025 | ... S40: =SUM(S42:S46) -> 26166271 | T40: =T41+T42+T43+T44+T45+T46 -> 44792538 | U40: =U41+U42+U43+U44+U45+U46 -> 40229835 | V40: =V41+V42+V43+V44+V45+V46 -> 27648444 | W40: =W41+W42+W43+W44+W45+W46 -> 31182796 | X40: =X41+X42+X43+X44+X45+X46 -> 25544616 | Y40: =Y41+Y42+Y43+Y44+Y45+Y46 -> 22264807 | Z40: =Z41+Z42+Z43+Z44+Z45+Z46 -> 29286390 | AA40: =AA41+AA42+AA43+AA44+AA45+AA46 -> 23802904 | ... AE40: =AE41+AE42+AE43+AE44+AE45+AE46 -> 26401893 | AF40: 28558245 | AG40: =AG41+AG42+AG43+AG44+AG45+AG46 -> 30937410 | AH40: =AH41+AH42+AH43+AH44+AH45+AH46 -> 12178724 | AI40: =AI41+AI42+AI43+AI44+AI45+AI46 -> 13403851 | AJ40: =AJ41+AJ42+AJ43+AJ44+AJ45+AJ46 -> 15127650 | AK40: =AK41+AK42+AK43+AK44+AK45+AK46 -> 13514942 | AL40: =AL41+AL42+AL43+AL44+AL45+AL46 -> 18119376 | AM40: =AM41+AM42+AM43+AM44+AM45+AM46 -> 19692739 | AN40: =AN41+AN42+AN43+AN44+AN45+AN46 -> 18673318 | ... BC40: =BC41+BC42+BC43+BC44+BC45+BC46 -> 0
B41: Tax Payable | C41: 46171 | D41: 45756 | E41: 66991 | F41: 0 | G41: 0 | H41: 0 | I41: 0 | J41: 0 | K41: 0 | L41: 0 | N41: 0 | O41: 0 | P41: 0 | Q41: 0 | R41: 0 | S41: 0 | T41: 0 | U41: 3057048 | V41: 3117312 | W41: 789464 | X41: 536064 | Y41: 84408 | Z41: 145703 | AA41: 207313 | AB41: 264868 | AC41: 309927 | AD41: 380294 | AE41: 351837 | AF41: 33481 | AG41: 315592 | AH41: 537672 | AI41: 430774 | AJ41: 318125 | AK41: 395314 | AL41: 315771 | AM41: 376319 | AN41: 423512 | AO41: 247907 | AP41: 297130 | AQ41: 407657 | AR41: 204879 | AS41: 0
B42: Dividends Payable | C42: 10618031 | D42: 11160836 | E42: 12285140 | F42: 13018317 | G42: 12813817 | H42: 14813817 | I42: 14940262 | J42: 3800755 | K42: 8514761 | L42: 9214331 | M42: 10014331 | N42: 11013741 | O42: 12013281 | P42: 13013281 | Q42: 13763281 | R42: 13598769 | S42: 13598769 | T42: 16178541 | U42: 1445817 | V42: 743561 | W42: 9068 | X42: 9068 | Y42: 9068 | Z42: 8468 | AA42: 4388 | AB42: 3528 | AC42: 3528 | AD42: 2248 | AE42: 2248 | AF42: 16669637 | AG42: 1639429 | AH42: 2681850 | AI42: 2510683 | AJ42: 3806545 | AK42: 5097204 | AL42: 10199543 | AM42: 10906945 | AN42: 11613057 | AO42: 12963710 | AP42: 14494561 | AQ42: 15661993 | AR42: 15799109 | AS42: 15284564
B43: Deferred Tax Liability | G43: 0 | H43: 0 | I43: 0 | J43: 0 | K43: 0 | L43: 0 | M43: 0 | N43: 0 | O43: 0 | P43: 0 | Q43: 0 | R43: 0 | S43: 0 | T43: 0 | U43: 0 | V43: 0 | W43: 0 | X43: 0 | Y43: 0 | Z43: 0 | AA43: 0 | AB43: 0 | AC43: 0 | AD43: 0 | AE43: 0 | AG43: 0 | AH43: 0 | AI43: 0 | AJ43: 0 | AK43: 0 | AL43: 0 | AM43: 0 | AN43: 0 | AO43: 0 | AP43: 0 | AQ43: 0 | AR43: 0
B44: Retirement Benefits Liability | E44: 1578142 | F44: 1841591 | G44: 0 | H44: 0 | I44: 0 | J44: 0 | K44: 0 | L44: 0 | M44: 0 | N44: 0 | O44: 0 | P44: 0 | Q44: 0 | R44: 0 | S44: 0 | T44: 0 | U44: 0 | V44: 0 | W44: 0 | X44: 0 | Y44: 0 | Z44: 0 | AA44: 0 | AB44: 0 | AC44: 0 | AD44: 0 | AE44: 0 | AG44: 2452000 | AH44: 2452000 | AI44: 2505789 | AJ44: 2532684 | AK44: 2559579 | AL44: 2586474 | AM44: 2613368 | AN44: 2640263 | AO44: 2667158 | AP44: 2694052 | AQ44: 2747842 | AR44: 2747842
B45: Other Liabilities | C45: 7826874 | D45: 8640741 | E45: 7347239 | F45: 13063959 | G45: 15424764 | H45: 12760343 | I45: 15651608 | J45: 20474711 | K45: 12539722 | L45: 11974567 | M45: 11163121 | N45: 10674930 | O45: 9575744 | P45: 10618644 | Q45: 11947976 | R45: 12567502 | S45: 12567502 | T45: 16613997 | U45: 27868011 | V45: 11787571 | W45: 18384264 | X45: 17170443 | Y45: 18128591 | Z45: 17132219 | AA45: 15676682 | AB45: 19189083 | AC45: 23016791 | AD45: 44481633 | AE45: 23543552 | AF45: 9350871 | AG45: 26530389 | AH45: 6507202 | AI45: 7956605 | AJ45: 8470296 | AK45: 5462845 | AL45: 5017588 | AM45: 5796107 | AN45: 3996486 | AO45: 5265131 | AP45: 5367323 | AQ45: 5090725 | AR45: 4600070 | AS45: =4893878+2747842 -> 7641720
B46: External Borrowings | C46: 7000000 | F46: 12000000 | G46: 7918795 | H46: 3830466 | I46: 12000000 | J46: 7878951 | K46: 3717277 | L46: 0 | M46: 0 | N46: 0 | O46: 8000000 | P46: 5270648 | Q46: 2544373 | R46: 0 | S46: 0 | T46: 12000000 | U46: 7858959 | V46: 12000000 | W46: 12000000 | X46: 7829041 | Y46: 4042740 | Z46: 12000000 | AA46: 7914521 | AB46: 8000000 | AC46: 8000000 | AD46: 5227909 | AE46: 2504256 | AF46: 2504256 | AG46: 0 | AH46: 0 | AI46: 0 | AJ46: 0 | AK46: 0 | AL46: 0 | AM46: 0 | AN46: 0 | AO46: 0 | AP46: 0 | AQ46: 0 | AR46: 0 | AS46: 0
B47: Total Liabilities | C47: =C38+C40 -> 128755171 | D47: =D38+D40 -> 127395107 | E47: =E38+E40 -> 143401498 | F47: =F38+F40 -> 173172537 | G47: =G38+G40 -> 166559447 | H47: =H38+H40 -> 161190570 | I47: =I38+I40 -> 173436278 | J47: =J38+J40 -> 164265379 | ... AE47: =AE38+AE40 -> 187921587 | AF47: 190081357 | AG47: =AG38+AG40 -> 193265102 | AH47: =AH38+AH40 -> 177522480 | AI47: =AI38+AI40 -> 183485952 | AJ47: =AJ38+AJ40 -> 186638971 | AK47: =AK38+AK40 -> 183904528 | AL47: =AL38+AL40 -> 188432003 | AM47: =AM38+AM40 -> 188301100 | AN47: =AN38+AN40 -> 189638451 | ... BC47: =BC38+BC40 -> 0
...

Sheet Financials
B2: Sotico Sacco
A3: 1 | B3: Year | C3: Audit 2016 | D3: Audit 2017 | E3: Audit 2018 | F3: Audit 2019 | G3: 43831 | H3: 43862 | I3: 43891 | J3: 43922 | K3: 43952 | L3: 43983 | M3: 44013 | N3: 44044 | O3: 44075 | P3: 44105 | Q3: 44136 | R3: 44166 | S3: Audit 20 | T3: 44217 | U3: 44228 | V3: 44256 | W3: 44287 | X3: 44317 | Y3: 44348 | Z3: 44378 | AA3: 44409 | AB3: 44440 | AC3: 44470 | AD3: 44501 | AE3: 44531 | AF3: Audited 2021 | AG3: 44562 | AH3: 44593 | AI3: 44621 | AJ3: 44652 | AK3: 44682 | AL3: 44713 | AM3: 44743 | AN3: 44774 | AO3: 44805 | AP3: 44835 | AQ3: 44866 | AR3: 44896 | AS3: audited 22 | AT3: 44958 | AU3: 44986 | AV3: 45017 | AW3: 45047 | AX3: 45078 | AY3: 45108 | AZ3: 45139 | BA3: 45170 | BB3: 45200
B4: Membership | D4: 5832 | E4: 6054 | F4: 6290 | R4: 6599 | S4: 6600 | T4: 6601 | U4: 6602 | V4: 6603 | W4: 6604 | X4: 6605 | Y4: 6606 | Z4: 6607 | AA4: 6608 | AB4: 6609 | AC4: 6610 | AD4: 6611 | AE4: 6612 | AF4: 6613 | AG4: 6614 | AH4: 6615 | AI4: 6616 | AJ4: 6617 | AK4: 6618 | AL4: 6619 | AM4: 6620 | AN4: 6621 | AO4: 6622 | AP4: 6623 | AQ4: 6624 | AR4: 6625 | AS4: 6626 | AT4: 6627 | AU4: 6628 | AV4: 6629 | AW4: 6630 | AX4: 6631 | AY4: 6632 | AZ4: 6633
A5: 2 | B5: Total Assets | C5: =Trend!C32 -> 190156140 | D5: =Trend!D32 -> 1.9878308e+08 | E5: =Trend!E32 -> 215833396 | F5: =Trend!F32 -> 246382881 | G5: =Trend!G32 -> 2.4116967e+08 | H5: =Trend!H32 -> 2.3510628e+08 | I5: =Trend!I32 -> 2.4739907e+08 | J5: =Trend!J32 -> 2.3814412e+08 | ... AZ5: =Trend!AZ32 -> #REF!
A6: 3 | B6: Total Deposits | C6: =Trend!C38 -> 103264095 | D6: =Trend!D38 -> 107547774 | E6: =Trend!E38 -> 122123986 | F6: =Trend!F38 -> 133248670 | G6: =Trend!G38 -> 130402071 | H6: =Trend!H38 -> 129785944 | I6: =Trend!I38 -> 130844408 | J6: =Trend!J38 -> 132110962 | ... AZ6: =Trend!AZ38 -> 0
A7: 3.1 | B7: Deposits-Members(BOSA) | C7: =Trend!C37 -> 93532161 | D7: =Trend!D37 -> 98991963 | E7: =Trend!E37 -> 109828204 | F7: =Trend!F37 -> 116729770 | G7: =Trend!G37 -> 117465834 | H7: =Trend!H37 -> 118247917 | I7: =Trend!I37 -> 119559661 | J7: =Trend!J37 -> 120700906 | ... AZ7: =Trend!AZ37 -> 0
A8: 3.2 | B8: Deposits-Customers(FOSA) | C8: =Trend!C35+Trend!C36 -> 9731934 | D8: =Trend!D35+Trend!D36 -> 8555811 | E8: =Trend!E35+Trend!E36 -> 12295782 | F8: =Trend!F35+Trend!F36 -> 16518900 | G8: =Trend!G35+Trend!G36 -> 12936237 | H8: =Trend!H35+Trend!H36 -> 11538027 | I8: =Trend!I35+Trend!I36 -> 11284747 | J8: =Trend!J35+Trend!J36 -> 11410056 | ... AZ8: =Trend!AZ35+Trend!AZ36 -> 0
A9: 4 | B9: External Borrowing | C9: =Trend!C46 -> 7000000 | D9: =Trend!D46 -> 0 | E9: =Trend!E46 -> 0 | F9: =Trend!F46 -> 12000000 | G9: =Trend!G46 -> 7918795 | H9: =Trend!H46 -> 3830466 | I9: =Trend!I46 -> 12000000 | J9: =Trend!J46 -> 7878951 | ... AZ9: =Trend!AZ46 -> 0
A10: 4.1 | B10: Short term Liabilities | C10: =Trend!C41+Trend!C42+Trend!C43+Trend!C45 -> 18491076 | D10: =Trend!D41+Trend!D42+Trend!D43+Trend!D45 -> 19847333 | E10: =Trend!E41+Trend!E42+Trend!E43+Trend!E45 -> 19699370 | F10: =Trend!F41+Trend!F42+Trend!F43+Trend!F45 -> 26082276 | G10: =Trend!G41+Trend!G42+Trend!G43+Trend!G45 -> 28238581 | H10: =Trend!H41+Trend!H42+Trend!H43+Trend!H45 -> 27574160 | I10: =Trend!I41+Trend!I42+Trend!I43+Trend!I45 -> 30591870 | J10: =Trend!J41+Trend!J42+Trend!J43+Trend!J45 -> 24275466 | ... AZ10: =Trend!AZ41+Trend!AZ42+Trend!AZ43+Trend!AZ45 -> 0
A11: 5 | B11: Share capital and Reserves
A12: 5.1 | B12: Core Capital | C12: =C14 -> 24822209 | D12: =D14 -> 34314785 | E12: =E14 -> 35358713 | F12: =F14 -> 36137160 | G12: =G14 -> 37537040 | H12: =H14 -> 36642527 | I12: =I14 -> 36589607 | J12: =J14 -> 36405554 | ... AZ12: =AZ14 -> 0
A13: 5.2 | B13: Institutional Capital | C13: =C12-C15 -> 14729609 | D13: =D12-D15 -> 23743385 | E13: =E12-E15 -> 24380513 | F13: =F12-F15 -> 24732360 | G13: =G12-G15 -> 26132240 | H13: =H12-H15 -> 25237727 | I13: =I12-I15 -> 25040807 | J13: =J12-J15 -> 24856754 | ... AZ13: =AZ12-AZ15 -> 0
A14: 5.3 | B14: Total Capital | C14: =SUM(C15:C19) -> 24822209 | D14: =SUM(D15:D19) -> 34314785 | E14: =SUM(E15:E19) -> 35358713 | F14: =SUM(F15:F19) -> 36137160 | G14: =SUM(G15:G19) -> 37537040 | H14: =SUM(H15:H19) -> 36642527 | I14: =SUM(I15:I19) -> 36589607 | J14: =SUM(J15:J19) -> 36405554 | ... AZ14: =SUM(AZ15:AZ19) -> 0
A15: 5.3.1 | B15: Members Share Capital | C15: =Trend!C50 -> 10092600 | D15: =Trend!D50 -> 10571400 | E15: =Trend!E50 -> 10978200 | F15: =Trend!F50 -> 11404800 | G15: =Trend!G50 -> 11404800 | H15: =Trend!H50 -> 11404800 | I15: =Trend!I50 -> 11548800 | J15: =Trend!J50 -> 11548800 | ... AZ15: =Trend!AZ50 -> 0
A16: 5.3.3 | B16: Retained Earnings | C16: =Trend!C53 -> 1279011 | D16: =Trend!D53 -> 1697046.7 | E16: =Trend!E53 -> 1946285 | F16: =Trend!F53 -> 1958695 | G16: =Trend!G53 -> 3353455 | H16: =Trend!H53 -> 2464062 | I16: =Trend!I53 -> 2267142 | J16: =Trend!J53 -> 2083089 | ... AZ16: =Trend!AZ53 -> 0
A17: 5.3.5 | B17: Statutory Reserves | C17: =Trend!C58 -> 4468256 | D17: =Trend!D58 -> 4888175 | E17: =Trend!E58 -> 5276065 | F17: =Trend!F58 -> 5615502 | G17: =Trend!G58 -> 5620622 | H17: =Trend!H58 -> 5615502 | I17: =Trend!I58 -> 5615502 | J17: =Trend!J58 -> 5615502 | ... AZ17: =Trend!AZ58 -> 0
A18: 5.3.6 | B18: Capital Reserve | C18: =Trend!C59 -> 8982342 | D18: =Trend!D59 -> 17158163 | E18: =Trend!E59 -> 17158163 | F18: =Trend!F59 -> 17158163 | G18: =Trend!G59 -> 17158163 | H18: =Trend!H59 -> 17158163 | I18: =Trend!I59 -> 17158163 | J18: =Trend!J59 -> 17158163 | ... AZ18: =Trend!AZ59 -> 0
A19: `nbnmn | B19: Supplementary Capital & reserves
A20: a | B20: Proposed Dividends | C20: =Trend!C82+Trend!C84 -> 9449807 | D20: =Trend!D82+Trend!D84 -> 9899196 | E20: =Trend!E82+Trend!E84 -> 11083861 | F20: =Trend!F82+Trend!F84 -> 11740414 | G20: =Trend!G82+Trend!G84 -> 0 | H20: =Trend!H82+Trend!H84 -> 2200000 | I20: =Trend!I82+Trend!I84 -> 2600000 | J20: =Trend!J82+Trend!J84 -> 4200000 | ... AZ20: =Trend!AZ82+Trend!AZ84 -> 0
A21: 6 | B21: Investments | C21: =C23 -> 40449810 | D21: =D23 -> 49120055 | E21: =E23 -> 49120055 | F21: =F23 -> 49120055 | G21: =G23 -> 49120055 | H21: =H23 -> 49120055 | I21: =I23 -> 49120055 | J21: =J23 -> 49120055 | K21: =K23+K22 -> 49120055 | L21: =L23+L22 -> 49120055 | M21: =M23+M22 -> 49120055 | N21: =N23+N22 -> 49120055 | O21: =O23+O22 -> 49120055 | P21: =P23+P22 -> 49120055 | Q21: =Q23+Q22 -> 49120055 | R21: =R23+R22 -> 49120055 | ... AZ21: =AZ23+AZ22 -> 0
A22: 6.1 | B22: Investments in Coop bank, CIC, Kuscco, Kerussu & Codic | C22: =Trend!C12 -> 0 | D22: =Trend!D12 -> 0 | E22: =Trend!E12 -> 0 | F22: =Trend!F12 -> 0 | G22: =Trend!G12 -> 0 | H22: =Trend!H12 -> 0 | I22: =Trend!I12 -> 0 | J22: =Trend!J12 -> 0 | ... AR22: =Trend!AR12 -> 5151497.8 | AS22: =Trend!#REF! -> #REF! | AT22: =Trend!AT12 -> 5151497.8 | AU22: =Trend!AU12 -> 5151497.8 | AV22: =Trend!AV12 -> 5151497.8 | AW22: =Trend!AW12 -> 5151497.8 | AX22: =Trend!AX12 -> 5151497.8 | AY22: =Trend!AY12 -> 5151497.8 | AZ22: =Trend!AZ12 -> 0
A23: 6.2 | B23: Equity Investments (at cost) | C23: =Trend!C13 -> 40449810 | D23: =Trend!D13 -> 49120055 | E23: =Trend!E13 -> 49120055 | F23: =Trend!F13 -> 49120055 | G23: =Trend!G13 -> 49120055 | H23: =Trend!H13 -> 49120055 | I23: =Trend!I13 -> 49120055 | J23: =Trend!J13 -> 49120055 | ... AR23: =Trend!AR13 -> 0 | AS23: =Trend!AS12 -> 5151498 | AT23: =Trend!AT13 -> 0 | AU23: =Trend!AU13 -> 0 | AV23: =Trend!AV13 -> 0 | AW23: =Trend!AW13 -> 0 | AX23: =Trend!AX13 -> 0 | AY23: =Trend!AY13 -> 0 | AZ23: =Trend!AZ13 -> 0
A24: 6.3 | B24: Deposits in KUSCCO CFP
A25: 7 | B25: Net Loans & advances | C25: =C26-C27 -> 108864930 | D25: =D26-D27 -> 112673981 | E25: =E26-E27 -> 118004126 | F25: =F26-F27 -> 126643002 | G25: =G26-G27 -> 144740267 | H25: =H26-H27 -> 139423704 | I25: =I26-I27 -> 138129985 | J25: =J26-J27 -> 133289652 | ... AZ25: =AZ26-AZ27 -> 181059969
A26: 7.1 | B26: Gross Loans & advances | C26: =Trend!C17 -> 112489704 | D26: =Trend!D17 -> 116513632 | E26: =Trend!E17 -> 121965745 | F26: =Trend!F17 -> 131804621 | G26: =Trend!G17 -> 149901886 | H26: =Trend!H17 -> 144585323 | I26: =Trend!I17 -> 143291604 | J26: =Trend!J17 -> 138451271 | ... AZ26: =Trend!AZ17 -> 187471588
A27: 7.3 | B27: Allowance for loan losses | C27: =Trend!C18 -> 3624774 | D27: =Trend!D18 -> 3839651 | E27: =Trend!E18 -> 3961619 | F27: =Trend!F18 -> 5161619 | G27: =Trend!G18 -> 5161619 | H27: =Trend!H18 -> 5161619 | I27: =Trend!I18 -> 5161619 | J27: =Trend!J18 -> 5161619 | ... AZ27: =Trend!AZ18 -> 6411619
A28: 7.4 | B28: Non Performing Loans (A/L NPL30 | C28: -4 | D28: -3 | E28: -2 | F28: -1 | G28: 0 | H28: 0 | I28: 0 | J28: 0 | K28: 10 | M28: 24 | N28: 25 | O28: 26 | P28: 27 | Q28: 28 | R28: 29 | S28: 30 | T28: 31 | U28: 32 | V28: 33 | W28: 34 | X28: 35 | Y28: 36 | Z28: 37 | AA28: 38 | AB28: 39 | AC28: 40 | AD28: 41 | AE28: 42 | AF28: 43 | AG28: 44 | AH28: 45 | AI28: 46 | AJ28: 47 | AK28: 48 | AL28: 49 | AM28: 50 | AN28: 51 | AO28: 52 | AP28: 53 | AQ28: 54 | AR28: 55 | AS28: 56 | AT28: 57 | AU28: 58 | AV28: 59 | AW28: 60 | AX28: 61 | AY28: 62 | AZ28: 63
A29: 7.5666667 | B29: Non Performing Loans NPL30 | L29: 19839389
A30: 7.7166667 | B30: Required loan loss provision
A31: 7.8666667 | B31: Cash and Cash equipments | C31: =Trend!C3 -> 27227584 | D31: =Trend!D3 -> 20473615 | E31: =Trend!E3 -> 29501244 | F31: =Trend!F3 -> 52141499 | G31: =Trend!G3 -> 28844168 | H31: =Trend!H3 -> 28253972 | I31: =Trend!I3 -> 41920668 | J31: =Trend!J3 -> 37566335 | ... AZ31: =Trend!AZ3 -> 52036292
A32: 8 | B32: Non-Earning Assets | C32: =Trend!C7+Trend!C25 -> 13613816 | D32: =Trend!D7+Trend!D25 -> 16515426 | E32: =Trend!E7+Trend!E25 -> 19207971 | F32: =Trend!F7+Trend!F25 -> 18453671 | G32: =Trend!G7+Trend!G25 -> 18440527 | H32: =Trend!H7+Trend!H25 -> 18283896 | I32: =Trend!I7+Trend!I25 -> 18203707 | J32: =Trend!J7+Trend!J25 -> 18143421 | ... AS32: =Trend!AS7+Trend!AS25 -> 16928381 | AT32: =Trend!#REF!+Trend!AT25 -> #REF! | AU32: =Trend!#REF!+Trend!AU25 -> #REF! | AV32: =Trend!#REF!+Trend!AV25 -> #REF! | AW32: =Trend!#REF!+Trend!AW25 -> #REF! | AX32: =Trend!#REF!+Trend!AX25 -> #REF! | AY32: =Trend!#REF!+Trend!AY25 -> #REF! | AZ32: =Trend!#REF!+Trend!AZ25 -> #REF!
A33: 8.1 | B33: Property and Equipment | C33: =Trend!C27 -> 10052178 | D33: =Trend!D27 -> 14045660 | E33: =Trend!E27 -> 16051260 | F33: =Trend!F27 -> 11631992 | G33: =Trend!G27 -> 12221216 | H33: =Trend!H27 -> 11505240 | I33: =Trend!I27 -> 11511238 | J33: =Trend!J27 -> 11445987 | ... AZ33: =Trend!AZ27 -> 9570523
A34: 8.2 | B34: Land and Building | C34: 12999996 | D34: 12999997 | E34: 12999998 | F34: 12999999 | G34: 13000000 | H34: 13000002 | I34: 13000015 | J34: 13000021 | K34: 13000041 | L34: 13000054 | M34: 13000055 | N34: 13000056 | O34: 13000057 | P34: 13000058 | Q34: 13000059 | R34: 13000060 | S34: 13000060 | T34: 13000061 | U34: 13000062 | V34: 13000063 | W34: 13000064 | X34: 13000065 | Y34: 13000066 | Z34: 13000067 | AA34: 13000068 | AB34: 13000069 | AC34: 13000070 | AD34: 13000071 | AE34: 13000072 | AF34: 13000073 | AG34: 13000074 | AH34: 13000075 | AI34: 13000076 | AJ34: 13000077 | AK34: 13000078 | AL34: 13000079 | AM34: 13000080 | AN34: 13000081 | AO34: 13000082 | AP34: 13000083 | AQ34: 13000084 | AR34: 13000085 | AS34: 13000086 | AT34: 13000087 | AU34: 13000088 | AV34: 13000089 | AW34: 13000090 | AX34: 13000091 | AY34: 13000092 | AZ34: 13000093
A35: 9 | B35: Turnover | C35: =C36+C37+C38 -> 27127521 | D35: =D36+D37+D38 -> 27376695 | E35: =E36+E37+E38 -> 28491876 | F35: =F36+F37+F38 -> 30436001 | G35: =G36+G37+G38 -> 2318955.6 | H35: =H36+H37+H38 -> 4953370.5 | I35: =I36+I37+I38 -> 7211467.8 | J35: =J36+J37+J38 -> 9740396.4 | ... AZ35: =AZ36+AZ37+AZ38 -> 0
A36: 9.1 | B36: Loan Interest | C36: =Trend!C74 -> 18352026 | D36: =Trend!D74 -> 18322301 | E36: =Trend!E74 -> 18131997 | F36: =Trend!F74 -> 18377030 | G36: =Trend!G74 -> 1756233.8 | H36: =Trend!H74 -> 3494619.5 | I36: =Trend!I74 -> 5151232.2 | J36: =Trend!J74 -> 6814814 | ... AZ36: =Trend!AZ74 -> 0
B37: Income from investments | C37: =Trend!C76 -> 6136255 | D37: =Trend!D76 -> 6802219 | E37: =Trend!E76 -> 6612283 | F37: =Trend!F76 -> 12058971 | G37: =Trend!G76 -> 288948.04 | H37: =Trend!H76 -> 639294.26 | I37: =Trend!I76 -> 1059967.4 | J37: =Trend!J76 -> 1612656.6 | ... AZ37: =Trend!AZ76 -> 0
A38: 9.2 | B38: Fees & Commissions | C38: =Trend!C75 -> 2639240 | D38: =Trend!D75 -> 2252175 | E38: =Trend!E75 -> 3747596 | F38: =Trend!F75 -> 0 | G38: =Trend!G75 -> 273773.8 | H38: =Trend!H75 -> 819456.7 | I38: =Trend!I75 -> 1000268.2 | J38: =Trend!J75 -> 1312925.7 | ... AZ38: =Trend!AZ75 -> 0
B39: Average yield on loans | C39: =C36/C26 -> 0.16314405 | D39: =D36/D26 -> 0.15725457 | E39: =E36/E26 -> 0.14866467 | F39: =F36/F26 -> 0.1394263 | G39: =G36/G26 -> 0.011715889 | H39: =H36/H26 -> 0.024169947 | I39: =I36/I26 -> 0.035949295 | J39: =J36/J26 -> 0.049221751 | ... AZ39: =AZ36/AZ26 -> 0
A40: 10 | B40: Total Expenses (FinCosts + OpEx) | C40: =SUM(C41:C47) -> 29985207 | D40: =SUM(D41:D47) -> 30890339 | E40: =SUM(E41:E47) -> 32359574 | F40: =SUM(F41:F47) -> 35035493 | G40: =SUM(G41:G47) -> 1533035.8 | H40: =SUM(H41:H47) -> 3613385.2 | I40: =SUM(I41:I47) -> 6374557.4 | J40: =SUM(J41:J47) -> 8161207.5 | ... AZ40: =SUM(AZ41:AZ47) -> 0
A41: 10.1 | B41: Financial Exp. (Interest on deposits) | C41: =Trend!C93 -> 4472114 | D41: =Trend!D93 -> 5710996 | E41: =Trend!E93 -> 5971894 | F41: =Trend!F93 -> 6436772 | G41: =Trend!G93 -> 588360.4 | H41: =Trend!H93 -> 1165382.8 | I41: =Trend!I93 -> 1771537.7 | J41: =Trend!J93 -> 2345206.1 | ... AZ41: =Trend!AZ93 -> 0
...

Sheet Prudential Ratios
C1: Sotico Sacco Society
C2: Financial Performance
C3: FINANCIAL SOUNDNESS INDICATORS | D3: Prude. Std | E3: Ref. # | F3: Audit 16 | G3: Audit 17 | H3: Audit 18 | I3: Audit 19 | J3: 43831 | K3: 43862 | L3: 43891 | M3: 43922 | N3: 43952 | O3: 43983 | P3: 44013 | Q3: 44044 | R3: 44075 | S3: 44105 | T3: 44136 | U3: 44166 | V3: Audit 20 | W3: 44217 | X3: 44248 | Y3: 44276 | Z3: 44307 | AA3: 44337 | AB3: 44368 | AC3: 44398 | AD3: 44429 | AE3: 44460 | AF3: 44490 | AG3: 44521 | AH3: 44551 | AI3: Audited 2021 | AJ3: 44562 | AK3: 44593 | AL3: 44621 | AM3: 44652 | AN3: 44682 | AO3: 44713 | AP3: 44743 | AQ3: 44774 | AR3: 44805 | AS3: 44835 | AT3: 44866 | AU3: 44896 | AV3: audited 22
B4: 1 | C4: CAPITAL ADEQUACY REQUIREMENTS
B5: 1.1 | C5: Core capital | D5: ≥ Ksh.10M | E5: 9.a | F5: =Financials!C12/1000000 -> 24.822209 | G5: =Financials!D12/1000000 -> 34.314785 | H5: =Financials!E12/1000000 -> 35.358713 | I5: =Financials!F12/1000000 -> 36.13716 | J5: =Financials!G12/1000000 -> 37.53704 | K5: =Financials!H12/1000000 -> 36.642527 | L5: =Financials!I12/1000000 -> 36.589607 | M5: =Financials!J12/1000000 -> 36.405554 | ... AV5: =Financials!AS12/1000000 -> 37.690995
B6: 1.2 | C6: Core capital /Total Assets | D6: ≥ 10% | E6: 9.b | F6: =Financials!C12/Financials!C5 -> 0.13053593 | G6: =Financials!D12/Financials!D5 -> 0.17262428 | H6: =Financials!E12/Financials!E5 -> 0.16382411 | I6: =Financials!F12/Financials!F5 -> 0.14667074 | J6: =Financials!G12/Financials!G5 -> 0.15564577 | K6: =Financials!H12/Financials!H5 -> 0.15585516 | L6: =Financials!I12/Financials!I5 -> 0.14789711 | M6: =Financials!J12/Financials!J5 -> 0.15287194 | ... AV6: =Financials!AS12/Financials!AS5 -> 0.159867
B7: 1.3 | C7: Core capital /Total Deposits | D7: ≥ 8% | E7: 9.d | F7: =Financials!C12/Financials!C6 -> 0.24037599 | G7: =Financials!D12/Financials!D6 -> 0.3190655 | H7: =Financials!E12/Financials!E6 -> 0.28953127 | I7: =Financials!F12/Financials!F6 -> 0.27120091 | J7: =Financials!G12/Financials!G6 -> 0.28785616 | K7: =Financials!H12/Financials!H6 -> 0.28233047 | L7: =Financials!I12/Financials!I6 -> 0.27964212 | M7: =Financials!J12/Financials!J6 -> 0.275568 | ... AV7: =Financials!AS12/Financials!AS6 -> 0.21780167
B8: 1.4 | C8: Share Capital/Total Assets | D8: ≤2% | E8: 9.c | F8: =Financials!C15/Financials!C5 -> 0.053075331 | G8: =Financials!D15/Financials!D5 -> 0.053180583 | H8: =Financials!E15/Financials!E5 -> 0.050864232 | I8: =Financials!F15/Financials!F5 -> 0.04628893 | J8: =Financials!G15/Financials!G5 -> 0.047289528 | K8: =Financials!H15/Financials!H5 -> 0.048509125 | L8: =Financials!I15/Financials!I5 -> 0.046680855 | M8: =Financials!J15/Financials!J5 -> 0.048495004 | ... AV8: =Financials!AS15/Financials!AS5 -> 0.072291087
B9: 1.5 | C9: Institutional Capital/Total Assets | D9: ≥ 8% | E9: 9.c | F9: =Financials!C13/Financials!C5 -> 0.077460602 | G9: =Financials!D13/Financials!D5 -> 0.11944369 | H9: =Financials!E13/Financials!E5 -> 0.11295987 | I9: =Financials!F13/Financials!F5 -> 0.10038181 | J9: =Financials!G13/Financials!G5 -> 0.10835625 | K9: =Financials!H13/Financials!H5 -> 0.10734603 | L9: =Financials!I13/Financials!I5 -> 0.10121625 | M9: =Financials!J13/Financials!J5 -> 0.10437694 | ... AV9: =Financials!AS13/Financials!AS5 -> 0.087575916
B10: 2 | C10: ASSET MIX AND QUALITY
B11: 2.1 | C11: Non Earning Assets
B12: 2.1.1 | C12: Non earning Assets/Total assets | D12: ≤ 10% | E12: 48.1 | F12: =Financials!C32/Financials!C5 -> 0.071592829 | G12: =Financials!D32/Financials!D5 -> 0.083082656 | H12: =Financials!E32/Financials!E5 -> 0.088994434 | I12: =Financials!F32/Financials!F5 -> 0.074898349 | J12: =Financials!G32/Financials!G5 -> 0.076462877 | K12: =Financials!H32/Financials!H5 -> 0.07776864 | L12: =Financials!I32/Financials!I5 -> 0.073580339 | M12: =Financials!J32/Financials!J5 -> 0.076186728 | ... AV12: =Financials!AS32/Financials!AS5 -> 0.071802019
B13: 2.1.2 | C13: Property and Equipment/Total Assets | D13: ≤ 5% | E13: 48.1 | F13: =Financials!C33/Financials!C5 -> 0.052862758 | G13: =Financials!D33/Financials!D5 -> 0.070658228 | H13: =Financials!E33/Financials!E5 -> 0.074368751 | I13: =Financials!F33/Financials!F5 -> 0.04721104 | J13: =Financials!G33/Financials!G5 -> 0.050674763 | K13: =Financials!H33/Financials!H5 -> 0.048936336 | L13: =Financials!I33/Financials!I5 -> 0.046529027 | M13: =Financials!J33/Financials!J5 -> 0.048063278 | ... AV13: =Financials!AS33/Financials!AS5 -> 0.067401008
B14: 2.1.3 | C14: Non Performing loans/Gross Loans | D14: ≤ 6% | E14: 41 | F14: =Financials!C28/Financials!C26 -> -3.555881e-08 | G14: =Financials!D28/Financials!D26 -> -2.574806e-08 | H14: =Financials!E28/Financials!E26 -> -1.6398047e-08 | I14: =Financials!F28/Financials!F26 -> -7.5869874e-09 | J14: =Financials!G28/Financials!G26 -> 0 | K14: =Financials!H28/Financials!H26 -> 0 | L14: =Financials!I28/Financials!I26 -> 0 | M14: =Financials!J28/Financials!J26 -> 0 | N14: =Financials!K28/Financials!K26 -> 7.143096e-08 | O14: =Financials!L29/Financials!L26 -> 0.14148704 | P14: =Financials!M29/Financials!M26 -> 0 | Q14: =Financials!N29/Financials!N26 -> 0 | R14: =Financials!O29/Financials!O26 -> 0 | S14: =Financials!P29/Financials!P26 -> 0 | T14: =Financials!Q29/Financials!Q26 -> 0 | U14: =Financials!R29/Financials!R26 -> 0 | V14: =Financials!S29/Financials!S26 -> 0 | ... AV14: =Financials!AS29/Financials!AS26 -> 0
B15: 2.2 | C15: Earning Assets
B16: 2.2.1 | C16: Equities & Investments/Deposits | D16: ≤ 5% | E16: 48.4 | F16: =Financials!C21/Financials!C6 -> 0.39171224 | G16: =Financials!D21/Financials!D6 -> 0.45672777 | H16: =Financials!E21/Financials!E6 -> 0.40221464 | I16: =Financials!F21/Financials!F6 -> 0.36863449 | J16: =Financials!G21/Financials!G6 -> 0.37668155 | K16: =Financials!H21/Financials!H6 -> 0.37846976 | L16: =Financials!I21/Financials!I6 -> 0.37540813 | M16: =Financials!J21/Financials!J6 -> 0.37180908 | ... AV16: =Financials!AS21/Financials!AS6 -> #REF!
B17: 2.2.2 | C17: Equities & Investments/Core Capital | D17: ≤ 40% | E17: 48.4 | F17: =Financials!C21/Financials!C12 -> 1.6295814 | G17: =Financials!D21/Financials!D12 -> 1.4314546 | H17: =Financials!E21/Financials!E12 -> 1.3891924 | I17: =Financials!F21/Financials!F12 -> 1.3592672 | J17: =Financials!G21/Financials!G12 -> 1.3085756 | K17: =Financials!H21/Financials!H12 -> 1.3405204 | L17: =Financials!I21/Financials!I12 -> 1.3424592 | M17: =Financials!J21/Financials!J12 -> 1.3492462 | ... AV17: =Financials!AS21/Financials!AS12 -> #REF!
B18: 2.2.3 | C18: Net Loans & advances /Total assets | D18: NPR | F18: =Financials!C25/Financials!C5 -> 0.57250284 | G18: =Financials!D25/Financials!D5 -> 0.56681878 | H18: =Financials!E25/Financials!E5 -> 0.5467371 | I18: =Financials!F25/Financials!F5 -> 0.51400893 | J18: =Financials!G25/Financials!G5 -> 0.60015949 | K18: =Financials!H25/Financials!H5 -> 0.59302416 | L18: =Financials!I25/Financials!I5 -> 0.55832864 | M18: =Financials!J25/Financials!J5 -> 0.55970164 | ... AV18: =Financials!AS25/Financials!AS5 -> 0.78454916
B19: 3 | C19: FUNDING MIX
B20: 3.1 | C20: Total Deposits/Total Assets | D20: NPR | F20: =Financials!C6/Financials!C5 -> 0.54304896 | G20: =Financials!D6/Financials!D5 -> 0.54103083 | H20: =Financials!E6/Financials!E5 -> 0.56582525 | I20: =Financials!F6/Financials!F5 -> 0.54081951 | J20: =Financials!G6/Financials!G5 -> 0.54070676 | K20: =Financials!H6/Financials!H5 -> 0.55203095 | L20: =Financials!I6/Financials!I5 -> 0.52887995 | M20: =Financials!J6/Financials!J5 -> 0.55475215 | ... AV20: =Financials!AS6/Financials!AS5 -> 0.73400267
B21: 3.1.1 | C21: BOSA Deposits/Total Assets | D21: NPR | F21: =Financials!C7/Financials!C5 -> 0.49187032 | G21: =Financials!D7/Financials!D5 -> 0.49798989 | H21: =Financials!E7/Financials!E5 -> 0.5088564 | I21: =Financials!F7/Financials!F5 -> 0.47377387 | J21: =Financials!G7/Financials!G5 -> 0.48706719 | K21: =Financials!H7/Financials!H5 -> 0.50295516 | L21: =Financials!I7/Financials!I5 -> 0.48326641 | M21: =Financials!J7/Financials!J5 -> 0.50683975 | ... AV21: =Financials!AS7/Financials!AS5 -> 0.66976194
B22: 3.1.2 | C22: FOSA Deposits/Total Assets | D22: NPR | F22: =Financials!C8/Financials!C5 -> 0.051178647 | G22: =Financials!D8/Financials!D5 -> 0.043040943 | H22: =Financials!E8/Financials!E5 -> 0.056968858 | I22: =Financials!F8/Financials!F5 -> 0.067045648 | J22: =Financials!G8/Financials!G5 -> 0.053639568 | K22: =Financials!H8/Financials!H5 -> 0.049075792 | L22: =Financials!I8/Financials!I5 -> 0.045613539 | M22: =Financials!J8/Financials!J5 -> 0.047912399 | ... AV22: =Financials!AS8/Financials!AS5 -> 0.064240726
B23: 3.2 | C23: External Borrowing/Total assets | D23: ≤ 25% | E23: 35.1 | F23: =Financials!C9/Financials!C5 -> 0.036811854 | G23: =Financials!D9/Financials!D5 -> 0 | H23: =Financials!E9/Financials!E5 -> 0 | I23: =Financials!F9/Financials!F5 -> 0.048704683 | J23: =Financials!G9/Financials!G5 -> 0.032834954 | K23: =Financials!H9/Financials!H5 -> 0.016292487 | L23: =Financials!I9/Financials!I5 -> 0.048504629 | M23: =Financials!J9/Financials!J5 -> 0.033084802 | ... AV23: =Financials!AS9/Financials!AS5 -> 0
B24: 4 | C24: GROWTH RATIOS
B25: 4.1 | C25: Total Assets | D25: NPR | G25: =Financials!D5/Financials!C5-1 -> 0.045367649 | H25: =Financials!E5/Financials!D5-1 -> 0.085773494 | I25: =Financials!F5/Financials!E5-1 -> 0.14154197 | J25: =Financials!G5/Financials!F5-1 -> -0.021158979 | K25: =Financials!H5/Financials!G5-1 -> -0.025141595 | L25: =Financials!I5/Financials!H5-1 -> 0.052286094 | M25: =Financials!J5/Financials!I5-1 -> -0.037409003 | N25: =Financials!K5/Financials!J5-1 -> -0.0033990913 | ... AV25: =Financials!AS5/Financials!AR5-1 -> 0.0004055919
B26: 4.2 | C26: Total Deposits | D26: NPR | G26: =Financials!D6/Financials!C6-1 -> 0.041482754 | H26: =Financials!E6/Financials!D6-1 -> 0.13553244 | I26: =Financials!F6/Financials!E6-1 -> 0.091093358 | J26: =Financials!G6/Financials!F6-1 -> -0.021363058 | K26: =Financials!H6/Financials!G6-1 -> -0.0047248253 | L26: =Financials!I6/Financials!H6-1 -> 0.0081554594 | M26: =Financials!J6/Financials!I6-1 -> 0.0096798481 | N26: =Financials!K6/Financials!J6-1 -> 0.044763348 | ... AV26: =Financials!AS6/Financials!AR6-1 -> -0.00024967196
B27: 4.2.1 | C27: FOSA Deposits | D27: NPR | G27: =Financials!D8/Financials!C8-1 -> -0.12085193 | H27: =Financials!E8/Financials!D8-1 -> 0.43712642 | I27: =Financials!F8/Financials!E8-1 -> 0.34346071 | J27: =Financials!G8/Financials!F8-1 -> -0.21688266 | K27: =Financials!H8/Financials!G8-1 -> -0.10808475 | L27: =Financials!I8/Financials!H8-1 -> -0.02195176 | M27: =Financials!J8/Financials!I8-1 -> 0.011104281 | N27: =Financials!K8/Financials!J8-1 -> 0.38580819 | ... AV27: =Financials!AS8/Financials!AR8-1 -> -0.0028452993
B28: 4.2.2 | C28: BOSA Deposits | D28: NPR | G28: =Financials!D7/Financials!C7-1 -> 0.058373526 | H28: =Financials!E7/Financials!D7-1 -> 0.10946587 | I28: =Financials!F7/Financials!E7-1 -> 0.062839651 | J28: =Financials!G7/Financials!F7-1 -> 0.0063057093 | K28: =Financials!H7/Financials!G7-1 -> 0.0066579615 | L28: =Financials!I7/Financials!H7-1 -> 0.011093168 | M28: =Financials!J7/Financials!I7-1 -> 0.0095454018 | N28: =Financials!K7/Financials!J7-1 -> 0.012523817 | ... AV28: =Financials!AS7/Financials!AR7-1 -> 0
B29: 4.3 | C29: Net Loans & advances | D29: NPR | G29: =Financials!D25/Financials!C25-1 -> 0.034988779 | H29: =Financials!E25/Financials!D25-1 -> 0.047305908 | I29: =Financials!F25/Financials!E25-1 -> 0.073208254 | J29: =Financials!G25/Financials!F25-1 -> 0.14289984 | K29: =Financials!H25/Financials!G25-1 -> -0.036731748 | L29: =Financials!I25/Financials!H25-1 -> -0.0092790463 | M29: =Financials!J25/Financials!I25-1 -> -0.03504187 | N29: =Financials!K25/Financials!J25-1 -> 0.0090833283 | ... AV29: =Financials!AS25/Financials!AR25-1 -> 3.1951404e-06
B30: 4.4 | C30: Core capital | D30: NPR | G30: =Financials!D12/Financials!C12-1 -> 0.38242268 | H30: =Financials!E12/Financials!D12-1 -> 0.030422113 | I30: =Financials!F12/Financials!E12-1 -> 0.022015705 | J30: =Financials!G12/Financials!F12-1 -> 0.038737964 | K30: =Financials!H12/Financials!G12-1 -> -0.023830142 | L30: =Financials!I12/Financials!H12-1 -> -0.0014442235 | M30: =Financials!J12/Financials!I12-1 -> -0.0050301989 | N30: =Financials!K12/Financials!J12-1 -> 0.015367298 | ... AV30: =Financials!AS12/Financials!AR12-1 -> 0.0046187788
B31: 4.5 | C31: Total Gross Income | D31: NPR | G31: =Financials!D35/Financials!C35-1 -> 0.0091852846 | H31: =Financials!E35/Financials!D35-1 -> 0.040734683 | I31: =Financials!F35/Financials!E35-1 -> 0.068234363 | J31: =Financials!G35/Financials!F35-1 -> -0.92380879 | K31: =Financials!H35/Financials!G35-1 -> 1.136035 | L31: =Financials!I35/Financials!H35-1 -> 0.45587088 | M31: =Financials!J35/Financials!I35-1 -> 0.35068152 | N31: =Financials!K35/Financials!J35-1 -> 0.72325588 | ... AV31: =Financials!AS35/Financials!AR35-1 -> #DIV/0!
B32: 4.6 | C32: Membership | D32: NPR | G32: =Financials!D3/Financials!#REF!-1 -> #VALUE! | H32: =Financials!E3/Financials!#REF!-1 -> #VALUE! | I32: =Financials!F3/Financials!#REF!-1 -> #VALUE! | J32: =Financials!G3/Financials!#REF!-1 -> #REF! | K32: =Financials!H3/Financials!#REF!-1 -> #REF! | L32: =Financials!I3/Financials!#REF!-1 -> #REF! | M32: =Financials!J3/Financials!#REF!-1 -> #REF! | N32: =Financials!K3/Financials!#REF!-1 -> #REF! | ... AV32: =Financials!AS3/Financials!#REF!-1 -> #VALUE!
B33: 5 | C33: Efficiency Ratios
B34: 5.1 | C34: FinCost-Deposits/Average Deposits | D34: NPR | G34: =Financials!D41/((Financials!D6+Financials!C6)/2) -> 0.054180972 | H34: =Financials!E41/((Financials!E6+Financials!D6)/2) -> 0.052003729 | I34: =Financials!F41/((Financials!F6+Financials!E6)/2) -> 0.050410816 | J34: =Financials!G41/((Financials!G6+Financials!F6)/2) -> 0.0044631803 | K34: =Financials!H41/((Financials!H6+Financials!G6)/2) -> 0.0089580052 | L34: =Financials!I41/((Financials!I6+Financials!H6)/2) -> 0.013594255 | M34: =Financials!J41/((Financials!J6+Financials!I6)/2) -> 0.017837294 | N34: =Financials!K41/((Financials!K6+Financials!J6)/2) -> 0.022307311 | ... AV34: =Financials!AS41/((Financials!AS6+Financials!AR6)/2) -> 0.042571694
B35: 5.2 | C35: FinCost-Shares/Average Share capital | D35: NPR | G35: =Financials!D42/((Financials!D15+Financials!C15)/2) -> 0.95811034 | H35: =Financials!E42/((Financials!E15+Financials!D15)/2) -> 1.0286837 | I35: =Financials!F42/((Financials!F15+Financials!E15)/2) -> 1.0490474 | J35: =Financials!G42/((Financials!G15+Financials!F15)/2) -> 0 | K35: =Financials!H42/((Financials!H15+Financials!G15)/2) -> 0.017536476 | L35: =Financials!I42/((Financials!I15+Financials!H15)/2) -> 0.026139691 | M35: =Financials!J42/((Financials!J15+Financials!I15)/2) -> 0.034635633 | N35: =Financials!K42/((Financials!K15+Financials!J15)/2) -> 0.043073 | ... AV35: =Financials!AS42/((Financials!AS15+Financials!AR15)/2) -> 0
B36: 5.3 | C36: FinCost-Ext Loans/Average Ext Loans | D36: NPR | G36: =Financials!D43/((Financials!D9+Financials!C9)/2) -> 0.14446314 | H36: =Financials!E43/((Financials!E9+Financials!D9)/2) -> #DIV/0! | I36: =Financials!F43/((Financials!F9+Financials!E9)/2) -> 0.21638667 | J36: =Financials!G43/((Financials!G9+Financials!F9)/2) -> 0 | K36: =Financials!H43/((Financials!H9+Financials!G9)/2) -> 0 | L36: =Financials!I43/((Financials!I9+Financials!H9)/2) -> 0.073778373 | M36: =Financials!J43/((Financials!J9+Financials!I9)/2) -> 0.0587529 | N36: =Financials!K43/((Financials!K9+Financials!J9)/2) -> 0.10071775 | ... AV36: =Financials!AS43/((Financials!AS9+Financials!AR9)/2) -> #DIV/0!
B37: 5.4 | C37: OpEx/Average Total Assets | D37: NPR | G37: =(Financials!D45+Financials!D46)/((Financials!D5+Financials!C5)/2) -> 0.074368176 | H37: =(Financials!E45+Financials!E46)/((Financials!E5+Financials!D5)/2) -> 0.068526452 | I37: =(Financials!F45+Financials!F46)/((Financials!F5+Financials!E5)/2) -> 0.05827478 | J37: =(Financials!G45+Financials!G46)/((Financials!G5+Financials!F5)/2) -> 0.0036502133 | K37: =(Financials!H45+Financials!H46)/((Financials!H5+Financials!G5)/2) -> 0.0090610511 | L37: =(Financials!I45+Financials!I46)/((Financials!I5+Financials!H5)/2) -> 0.014911013 | M37: =(Financials!J45+Financials!J46)/((Financials!J5+Financials!I5)/2) -> 0.019272994 | N37: =(Financials!K45+Financials!K46)/((Financials!K5+Financials!J5)/2) -> 0.02647621 | ... AV37: =(Financials!AS45+Financials!AS46)/((Financials!AS5+Financials!AR5)/2) -> 0.068991214
B38: 5.5 | C38: Avge yield on Net loans | D38: NPR | G38: =Financials!D36/((Financials!D25+Financials!C25)/2) -> 0.16540933 | H38: =Financials!E36/((Financials!E25+Financials!D25)/2) -> 0.15720605 | I38: =Financials!F36/((Financials!F25+Financials!E25)/2) -> 0.15023295 | J38: =Financials!G36/((Financials!G25+Financials!F25)/2) -> 0.01294283 | K38: =Financials!H36/((Financials!H25+Financials!G25)/2) -> 0.024595796 | L38: =Financials!I36/((Financials!I25+Financials!H25)/2) -> 0.037118816 | M38: =Financials!J36/((Financials!J25+Financials!I25)/2) -> 0.050216072 | N38: =Financials!K36/((Financials!K25+Financials!J25)/2) -> 0.064592427 | ... AV38: =Financials!AS36/((Financials!AS25+Financials!AR25)/2) -> 0.13472299
B39: 6 | C39: Liquidity Ratio
B40: 6.1 | C40: Liquid Assets - ST Liabilities/ Deposits | D40: ≥15% | E40: 13.2 | F40: =Financials!C10/Financials!C6 -> 0.17906588 | G40: =Financials!D10/Financials!D6 -> 0.18454434 | H40: =Financials!E10/Financials!E6 -> 0.16130631 | I40: =Financials!F10/Financials!F6 -> 0.19574136 | J40: =Financials!G10/Financials!G6 -> 0.2165501 | K40: =Financials!H10/Financials!H6 -> 0.21245875 | L40: =Financials!I10/Financials!I6 -> 0.23380342 | M40: =Financials!J10/Financials!J6 -> 0.18375058 | N40: =Financials!K10/Financials!K6 -> 0.15254142 | O40: =Financials!L48/(Financials!L10+Financials!L6) -> 0.2141903 | P40: =Financials!M48/(Financials!M10+Financials!M6) -> 0.19954099 | Q40: =Financials!N48/(Financials!N10+Financials!N6) -> 0.18114906 | R40: =Financials!O48/(Financials!O10+Financials!O6) -> 0.19017381 | S40: =Financials!P48/(Financials!P10+Financials!P6) -> 0.15684265 | T40: =Financials!Q48/(Financials!Q10+Financials!Q6) -> 0.17240627 | U40: =Financials!R48/(Financials!R10+Financials!R6) -> 0.15337048 | V40: =Financials!S48/(Financials!S10+Financials!S6) -> 0.15292561 | ... AV40: =Financials!AS48/(Financials!AS10+Financials!AS6) -> #REF!
...

Sheet Sheet1
B2: Description | C2: Audited 2016 | D2: Audited 2017 | E2: Audited 2018 | F2: Audited 2019 | G2: 43891 | H2: 43983 | I2: 44075 | J2: 44166 | K2: 44197 | L2: 44228 | M2: 44256 | N2: 44287 | O2: 44317 | P2: 44348 | Q2: 44378 | R2: 44409 | S2: 44440 | T2: 44470 | U2: 44501 | V2: 44531
B3: Total Assets | C3: 190156140 | D3: 1.9878308e+08 | E3: 215833396 | F3: 246382881 | G3: 2.4739907e+08 | H3: 2.3597468e+08 | I3: 2.5330628e+08 | J3: 2.5880998e+08 | K3: 2.6176359e+08 | L3: 2.6692002e+08 | M3: 2.7207645e+08 | N3: 2.7723288e+08 | O3: 2.8238932e+08 | P3: 2.8754575e+08 | Q3: 2.920728e+08
B4: FOSA Deposits | C4: 8225206 | D4: 7582824 | E4: 12295782 | F4: 16518900 | G4: 9323076 | H4: 12332975 | I4: 12509093 | J4: 14908062 | K4: 16501070 | L4: 18194178 | M4: 19887286 | N4: 21580393 | O4: 23273501 | P4: 24966608 | Q4: 26631116
B5: BOSA Deposits | C5: 93532161 | D5: 98991963 | E5: 109828204 | F5: 116729770 | G5: 119559661 | H5: 124213870 | I5: 130016226 | J5: 135994936 | K5: 1.4122322e+08 | L5: 1.4673404e+08 | M5: 1.5224485e+08 | N5: 1.5775567e+08 | O5: 1.6326649e+08 | P5: 168777309 | Q5: 1.742074e+08
B6: Gross Loans | C6: 112489704 | D6: 116513632 | E6: 121965745 | F6: 1.3180462e+08 | G6: 143291604 | H6: 140220540 | I6: 160536761 | J6: 170698863 | K6: 1.7932144e+08 | L6: 1.8957524e+08 | M6: 1.9982904e+08 | N6: 2.1008284e+08 | O6: 2.2033664e+08 | P6: 2.3059044e+08 | Q6: 2.4037818e+08
B7: Core Capital | C7: 24822209 | D7: 34314785 | E7: 35358713 | F7: 36137160 | G7: 36589607 | H7: 37542920 | I7: 39621162 | J7: 39672352 | K7: 41188129 | L7: 42320777 | M7: 43453424 | N7: 44586072 | O7: 45718719 | P7: 46851367 | Q7: 48093480
B8: Institutional Capital | C8: 14729609 | D8: 23743385 | E8: 24380513 | F8: 24732360 | G8: 25040807 | H8: 25597201 | I8: 26409923 | J8: 25214184 | K8: 25898742 | L8: 26032028 | M8: 26165313 | N8: 26298599 | O8: 26431884 | P8: 26565170 | Q8: 26855962
B9: Non-Earning Assets | C9: 13613816 | D9: 16515426 | E9: 19207971 | F9: 18478326 | G9: 18203707 | H9: 17738124 | I9: 12688363 | J9: 12237220 | K9: 9479548.2 | L9: 7184626 | M9: 4889703.9 | N9: 2594781.7 | O9: 299859.53 | P9: -1995062.6 | Q9: -4422199.1
