Workbook

Sheet sofp
A1: TRANS-NATIONAL TIMES SACCO
B2: Audited 2019 | C2: 43831 | D2: 43862 | E2: 43891 | F2: 43922 | G2: 43952 | H2: 43983 | I2: 44044 | J2: 44075 | K2: 44105 | L2: 44136 | M2: 44166 | N2: AUDITED 2020 | O2: 44197 | P2: 44228 | Q2: 44256 | R2: 44287 | S2: 44317 | T2: 44348 | U2: 44378 | V2: 44409 | W2: 44440 | X2: 44470 | Y2: 44501 | Z2: 44531 | AA2: AUDITED 2021 | AB2: 44583 | AC2: 44614 | AD2: 22-Mrch | AE2: 22-Aprl | AF2: 44703 | AG2: 44734 | AH2: 44764 | AI2: 44774 | AJ2: 44805 | AK2: 44835 | AL2: 44866 | AM2: 44896 | AN2: AUDITED 2022
A3: Cash & cash Equivalent | B3: =SUM(B4:B5) -> 126161088 | C3: =SUM(C4:C5) -> 1.1746108e+08 | D3: =SUM(D4:D5) -> 1.0266458e+08 | E3: =SUM(E4:E5) -> 1.8121047e+08 | F3: =SUM(F4:F5) -> 1.7031862e+08 | G3: =SUM(G4:G5) -> 1.4838293e+08 | H3: =SUM(H4:H5) -> 1.3151115e+08 | I3: =SUM(I4:I5) -> 1.4864861e+08 | ... AN3: =SUM(AN4:AN5) -> 150386392
A4: Cash In Hand | B4: 12288424 | C4: 7830148.5 | D4: 8392768.5 | E4: 4791553.8 | F4: 9428812.3 | G4: 11985501 | H4: 14752659 | I4: 15369652 | J4: 19989118 | K4: 20143334 | L4: 3101637.6 | M4: 7133780.5 | N4: 7133781 | O4: 4119245.5 | P4: 5593030.5 | Q4: 6141837.5 | R4: 8780073.5 | S4: 10159656 | T4: 14999424 | U4: 18411838 | V4: 11785614 | W4: 16597534 | X4: 15306004 | AA4: 10038378 | AB4: 24014388 | AC4: 31587818 | AD4: 37510452 | AE4: 23259438 | AF4: 10914362 | AG4: 13784310 | AH4: 17729876 | AI4: 8852330.5 | AJ4: 14239776 | AK4: 14941164 | AL4: 6909526.6 | AM4: 4786482.6 | AN4: 4786483
A5: Cash at Bank | B5: =49850364+64022300 -> 113872664 | C5: 1.0963093e+08 | D5: 94271812 | E5: 1.7641892e+08 | F5: 1.6088981e+08 | G5: 1.3639743e+08 | H5: 1.1675849e+08 | I5: 1.3327896e+08 | J5: 3.5438439e+08 | K5: 1.981758e+08 | L5: 1.8643774e+08 | M5: 1.3550198e+08 | N5: =76274817+71269389 -> 147544206 | O5: 1.2229977e+08 | P5: 83550376 | Q5: 1.2580654e+08 | R5: 1.5746534e+08 | S5: 1.1756499e+08 | T5: 1.1186801e+08 | U5: 1.086303e+08 | V5: 1.2710652e+08 | W5: 1.1413142e+08 | X5: 96749792 | AA5: =89424927+66344537 -> 155769464 | AB5: 1.3507707e+08 | AC5: 82565921 | AD5: 1.3103099e+08 | AE5: 1.2682993e+08 | AF5: 1.4845228e+08 | AG5: 1.1818268e+08 | AH5: 1.3375209e+08 | AI5: 1.1641657e+08 | AJ5: 1.0245533e+08 | AK5: 1.1372852e+08 | AL5: 1.0286836e+08 | AM5: 1.1213698e+08 | AN5: =27382778+118217131 -> 145599909
A6: Prepayment and Sundry | B6: 353238578 | N6: 443341212 | O6: 0 | P6: 0 | Q6: 0 | R6: 0 | S6: 0 | T6: 0 | U6: 0 | V6: 0 | W6: 0 | X6: 0 | AA6: 394493297 | AB6: 0 | AC6: 0 | AD6: 0 | AE6: 0 | AF6: 0 | AG6: 0 | AH6: 0
A7: Financial Investment | B7: =B8+B9+B10+B11 -> 218554560 | C7: =C8+C9+C10+C11 -> 2.1855456e+08 | D7: =D8+D9+D10+D11 -> 2.2208662e+08 | E7: =E8+E9+E10+E11 -> 2.2208662e+08 | F7: =F8+F9+F10+F11 -> 2.2648662e+08 | G7: =G8+G9+G10+G11 -> 2.2922247e+08 | H7: =H8+H9+H10+H11 -> 2.3030247e+08 | I7: =I8+I9+I10+I11 -> 2.3480247e+08 | ... AN7: =AN8+AN9+AN10+AN11 -> 488614494
A8: Government Security | O8: 0 | P8: 0 | Q8: 0 | R8: 0 | S8: 0 | T8: 0 | U8: 0 | V8: 0 | W8: 0 | X8: 0 | AB8: 0 | AC8: 0 | AD8: 0 | AE8: 0 | AF8: 0 | AG8: 0 | AH8: 0 | AI8: 0 | AJ8: 0 | AK8: 0 | AL8: 0 | AM8: 0
A9: Other Securities | O9: 0 | P9: 0 | Q9: 0 | R9: 0 | S9: 0 | T9: 0 | U9: 0 | V9: 0 | W9: 0 | X9: 0 | AB9: 0 | AC9: 0 | AD9: 0 | AE9: 0 | AF9: 0 | AG9: 0 | AH9: 0 | AI9: 0 | AJ9: 0 | AK9: 0 | AL9: 0 | AM9: 0
A10: Balances with Other Saccos | B10: =218554560-24000 -> 218530560 | C10: 2.1855456e+08 | D10: 2.2208662e+08 | E10: 2.2208662e+08 | F10: 2.2648662e+08 | G10: 2.2922247e+08 | H10: 2.3030247e+08 | I10: 2.3480247e+08 | J10: 2.3700247e+08 | K10: 2.3720247e+08 | L10: 2.3740247e+08 | M10: 2.8517466e+08 | N10: =1007862+8658965+41347233+119631235+114505363 -> 285150658 | O10: 2.8817466e+08 | P10: 2.9117466e+08 | Q10: 2.9117466e+08 | R10: 2.9117466e+08 | S10: 3.2367201e+08 | T10: 3.2483146e+08 | U10: 3.2857146e+08 | V10: 3.3043125e+08 | W10: 3.3617125e+08 | X10: 3.4291125e+08 | AA10: =437931242-AA11 -> 437907242 | AB10: 3.595152e+08 | AC10: 3.402552e+08 | AD10: 3.834552e+08 | AE10: 3.8365526e+08 | AF10: 3.9104526e+08 | AG10: 4.5543526e+08 | AH10: 4.5863526e+08 | AI10: 4.627187e+08 | AJ10: 4.627187e+08 | AK10: 4.646587e+08 | AL10: 4.658587e+08 | AM10: 4.6861449e+08 | AN10: 488614494
A11: Investment In Companies | B11: 24000 | N11: 24000 | O11: 0 | P11: 0 | Q11: 0 | R11: 0 | S11: 0 | T11: 0 | U11: 0 | V11: 0 | W11: 0 | X11: 0 | AA11: 24000 | AB11: 0 | AC11: 0 | AD11: 0 | AE11: 0 | AF11: 0 | AG11: 0 | AH11: 0 | AI11: 0 | AJ11: 0 | AK11: 0 | AL11: 0 | AM11: 0
A12: Net Loan Portfolio | B12: =B13-B14 -> 854944397 | C12: =C13-C14 -> 8.6182725e+08 | D12: =D13-D14 -> 8.7474837e+08 | E12: =E13-E14 -> 8.3730951e+08 | F12: =F13-F14 -> 8.1189392e+08 | G12: =G13-G14 -> 7.9388107e+08 | H12: =H13-H14 -> 8.3302891e+08 | I12: =I13-I14 -> 8.5497448e+08 | ... AN12: =AN13-AN14 -> 1027056145
A13: Gross Loan Portfolio | B13: 905898148 | C13: 9.0874961e+08 | D13: 9.2167073e+08 | E13: 8.8573187e+08 | F13: 8.6031628e+08 | G13: 8.4330343e+08 | H13: 8.8295127e+08 | I13: 9.0589684e+08 | J13: 9.0290715e+08 | K13: 9.4804975e+08 | L13: 9.7197199e+08 | M13: 1.0145305e+09 | N13: 1014523454 | O13: 1.0046262e+09 | P13: 1.0226448e+09 | Q13: 9.9445367e+08 | R13: 1.0083379e+09 | S13: 9.8936991e+08 | T13: 995045043 | U13: 1.0302148e+09 | V13: 1.019429e+09 | W13: 1.0190062e+09 | X13: 1.0354669e+09 | AA13: 1040330186 | AB13: 1.0280197e+09 | AC13: 1.0350988e+09 | AD13: 1.0277955e+09 | AE13: 1.0253364e+09 | AF13: 1.0230091e+09 | AG13: 1.0409134e+09 | AH13: 1.0407835e+09 | AI13: 1.0382876e+09 | AJ13: 1.0312393e+09 | AK13: 1.0220122e+09 | AL13: 1.0136316e+09 | AM13: 1.0174618e+09 | AN13: 1066045543
A14: Allowance For Loan Loss | B14: 50953751 | C14: 46922358 | D14: 46922358 | E14: 48422358 | F14: 48422358 | G14: 49422358 | H14: 49922358 | I14: 50922358 | J14: 51422358 | K14: 51922358 | L14: 52422358 | M14: 52922358 | N14: 42738346 | O14: 48738346 | P14: 48738346 | Q14: 42738346 | R14: 44738346 | S14: 44738346 | T14: 45738346 | U14: 45738346 | V14: 46738346 | W14: 46738346 | X14: 46738346 | AA14: 42738346 | AB14: 48738346 | AC14: 48738346 | AD14: 48738346 | AE14: 48738346 | AF14: 48738346 | AG14: 42738346 | AH14: 42738346 | AI14: 42738346 | AJ14: 42738346 | AK14: 42738346 | AL14: 42738346 | AM14: 42738346 | AN14: 38989398
A15: Accounts Recievables | B15: =SUM(B16:B18) -> 298746 | C15: =SUM(C16:C18) -> 0 | D15: =SUM(D16:D18) -> 0 | E15: =SUM(E16:E18) -> 0 | F15: =SUM(F16:F18) -> 0 | G15: =SUM(G16:G18) -> 0 | H15: =SUM(H16:H18) -> 0 | I15: =SUM(I16:I18) -> 0 | ... AN15: =SUM(AN16:AN18) -> 0
A16: Tax Recoverable | B16: 298746 | O16: 0 | P16: 0 | Q16: 0 | R16: 0 | S16: 0 | T16: 0 | U16: 0 | V16: 0 | W16: 0 | X16: 0 | AB16: 1.0280197e+09 | AC16: 1.0350988e+09 | AD16: 1.0277955e+09 | AE16: 1.0253364e+09 | AF16: 1.0230091e+09 | AG16: 1.0409134e+09 | AH16: 1.0407835e+09
A17: Deffered Tax Assets | O17: 0 | P17: 0 | Q17: 0 | R17: 0 | S17: 0 | T17: 0 | U17: 0 | V17: 0 | W17: 0 | X17: 0 | AB17: 48738346 | AC17: 48738346 | AD17: 48738346 | AE17: 48738346 | AF17: 48738346 | AG17: 42738346 | AH17: 42738346
A18: Retirement Benefit Assets | O18: 0 | P18: 0 | Q18: 0 | R18: 0 | S18: 0 | T18: 0 | U18: 0 | V18: 0 | W18: 0 | X18: 0 | AB18: 0 | AC18: 0 | AD18: 0 | AE18: 0 | AF18: 0 | AG18: 0 | AH18: 0
A19: Property&Equipments&Other Assets | B19: =SUM(B20:B24) -> 49545258 | C19: =SUM(C20:C24) -> 4.1135568e+08 | D19: =SUM(D20:D24) -> 4.211053e+08 | E19: =SUM(E20:E24) -> 4.2658826e+08 | F19: =SUM(F20:F24) -> 430759398 | G19: =SUM(G20:G24) -> 4.3013963e+08 | H19: =SUM(H20:H24) -> 4.403869e+08 | I19: =SUM(I20:I24) -> 4.3386527e+08 | ... AN19: =SUM(AN20:AN24) -> 543719646
A20: Investment Properties | O20: 0 | P20: 0 | Q20: 0 | R20: 0 | S20: 0 | T20: 0 | U20: 0 | V20: 0 | W20: 0 | X20: 0 | AB20: 0 | AC20: 0 | AD20: 0 | AE20: 0 | AF20: 0 | AG20: 0 | AH20: 0 | AI20: 0 | AJ20: 0 | AK20: 0 | AL20: 0 | AM20: 0
A21: Property and Equipment | B21: 45628545 | C21: 51693626 | D21: 54745071 | E21: 54289591 | F21: 55428321 | G21: 55467768 | H21: 55324242 | I21: 54805889 | J21: 54797492 | K21: 55013766 | L21: 59869475 | M21: 60793691 | N21: 60793690 | O21: 61218441 | P21: 62714699 | Q21: 62842969 | R21: 61477875 | S21: 61601875 | T21: 61523554 | U21: 63950454 | V21: 63808151 | W21: 64810751 | X21: 65423751 | AA21: 68828038 | AB21: 71462051 | AC21: 73342611 | AD21: 76311759 | AE21: 81680209 | AF21: 89972379 | AG21: 93115774 | AH21: 95079234 | AI21: 97272794 | AJ21: 98892489 | AK21: 1.0238595e+08 | AL21: 1.0450982e+08 | AM21: 1.0721007e+08 | AN21: 112903194
A22: Prepaid Lease Rentals | B22: 3916713 | C22: 3916713.3 | D22: 3916713.3 | E22: 3905159 | F22: 3905159 | G22: 3897456.1 | H22: 3893604.7 | I22: 3885901.9 | J22: 3882050.4 | K22: 3878199 | L22: 3874347.6 | M22: 3870496.1 | N22: 3870496 | O22: 3870496.1 | P22: 3870496.1 | Q22: 3870496.1 | R22: 3855090.4 | S22: 3855090.4 | T22: 3847387.5 | U22: 3847387.5 | V22: 3831981.8 | W22: 3831981.8 | X22: 3831981.8 | AA22: 3816576 | AB22: 3816576.1 | AC22: 3816576.1 | AD22: 3816576.1 | AE22: 3816576.1 | AF22: 3816576.1 | AG22: 3816576.1 | AH22: 3816576.1 | AI22: 3816576.1 | AJ22: 3816576.1 | AK22: 3943576.1 | AL22: 3943576.1 | AM22: 3943576.1 | AN22: 3943576
A23: Intangible Assets | C23: 0 | D23: 0 | E23: 31800 | F23: 45800 | G23: 45800 | H23: 485800 | I23: 2485800 | J23: 2485800 | K23: 2485800 | L23: 3162800 | M23: 3162800 | N23: 3162800 | O23: 3162800 | P23: 3162800 | Q23: 3562800 | R23: 2605333.9 | S23: 2605333.9 | T23: 2126600.9 | U23: 2126600.9 | V23: 1947867.8 | W23: 1947867.8 | X23: 1947867.8 | AA23: 2490402 | AB23: 2490401.8 | AC23: 2490401.8 | AD23: 3148271.8 | AE23: 3148271.8 | AF23: 4148271.8 | AG23: 4148271.8 | AH23: 4148271.8 | AI23: 4148271.8 | AJ23: 4148271.8 | AK23: 4148271.8 | AL23: 4236921.8 | AM23: 4389721.8 | AN23: 4389722
A24: Other Assets | C24: 3.5574534e+08 | D24: 3.6244351e+08 | E24: 3.6836171e+08 | F24: 3.7138012e+08 | G24: 3.7072861e+08 | H24: 3.8068325e+08 | I24: 3.7268768e+08 | J24: 3.7457846e+08 | K24: 3.8597152e+08 | L24: 3.8517821e+08 | M24: 3.862036e+08 | O24: 4.7199559e+08 | P24: 4.7407772e+08 | Q24: 4.7767633e+08 | R24: 4.5630411e+08 | S24: 4.5774332e+08 | T24: 4.4291254e+08 | U24: 4.3676195e+08 | V24: 4.4401176e+08 | W24: 4.5883915e+08 | X24: 4.6318962e+08 | AB24: 4.8319809e+08 | AC24: 5.0022187e+08 | AD24: 4.8440447e+08 | AE24: 4.8067373e+08 | AF24: 4.7878733e+08 | AG24: 4.781637e+08 | AH24: 4.8059862e+08 | AI24: 4.8079013e+08 | AJ24: 4.804988e+08 | AK24: 4.8076309e+08 | AL24: 5.1871546e+08 | AM24: 4.5152004e+08 | AN24: 422483154
A25: Total Assets | B25: =B19+B15+B12+B7+B6+B3 -> 1602742627 | C25: =C19+C15+C12+C7+C6+C3 -> 1.6091986e+09 | D25: =D19+D15+D12+D7+D6+D3 -> 1.6206049e+09 | E25: =E19+E15+E12+E7+E6+E3 -> 1.6671949e+09 | F25: =F19+F15+F12+F7+F6+F3 -> 1.6394586e+09 | G25: =G19+G15+G12+G7+G6+G3 -> 1.6016261e+09 | H25: =H19+H15+H12+H7+H6+H3 -> 1.6352294e+09 | I25: =I19+I15+I12+I7+I6+I3 -> 1.6722908e+09 | ... AN25: =AN19+AN15+AN12+AN7+AN6+AN3 -> 2209776677
A26: Savings and Deposits | B26: 142712717 | C26: 1.3358996e+08 | D26: 1.0113247e+08 | E26: 1.1856103e+08 | F26: 1.6190843e+08 | G26: 1.2317275e+08 | H26: 1.200673e+08 | I26: 1.3012642e+08 | J26: 1.3480754e+08 | K26: 1.4362961e+08 | L26: 1.3657087e+08 | M26: 1.6515884e+08 | N26: 165118842 | O26: 1.3060704e+08 | P26: 1.2950436e+08 | Q26: 1.3031237e+08 | R26: 1.3981643e+08 | S26: 1.3840429e+08 | T26: 1.2944395e+08 | U26: 1.6063684e+08 | V26: 1.5539765e+08 | W26: 1.5414217e+08 | X26: 1.5396492e+08 | AA26: 141490550 | AB26: 1.3764594e+08 | AC26: 1.158245e+08 | AD26: 1.4145135e+08 | AE26: 1.2601287e+08 | AF26: 1.4530816e+08 | AG26: 1.4038221e+08 | AH26: 1.4975588e+08 | AI26: 1.3505852e+08 | AJ26: 1.3020226e+08 | AK26: 1.2711603e+08 | AL26: 1.3071242e+08 | AM26: 1.2462844e+08 | AN26: 106571848
A27: Short Terrm Deposits | B27: 95822078 | C27: 99391727 | D27: 1.082532e+08 | E27: 1.0977023e+08 | F27: 1.0910548e+08 | G27: 115051476 | H27: 1.2127869e+08 | I27: 1.239691e+08 | J27: 1.2267034e+08 | K27: 1.2242491e+08 | L27: 1.2525082e+08 | M27: 1.2586019e+08 | N27: 125860190 | O27: 1.2696493e+08 | P27: 1.2576079e+08 | Q27: 1.2886155e+08 | R27: 126253283 | S27: 134453258 | T27: 135872308 | U27: 153917147 | V27: 150522311 | W27: 154057538 | X27: 1.5702546e+08 | AA27: 165342484 | AB27: 1.689584e+08 | AC27: 1.6909244e+08 | AD27: 1.7492139e+08 | AE27: 1.7796385e+08 | AF27: 1.8438149e+08 | AG27: 1.8512196e+08 | AH27: 2.0108971e+08 | AI27: 2.0087517e+08 | AJ27: 2.0366698e+08 | AK27: 2.0907924e+08 | AL27: 2.1723341e+08 | AM27: 2.0422631e+08 | AN27: 212226310
A28: Non Withdrawable Deposits | B28: 785401586 | C28: 7.9060446e+08 | D28: 7.9722785e+08 | E28: 8.0612753e+08 | F28: 8.2275054e+08 | G28: 8.2820634e+08 | H28: 8.3542453e+08 | I28: 8.4217551e+08 | J28: 8.3681196e+08 | K28: 8.4384723e+08 | L28: 8.505418e+08 | M28: 8.5752864e+08 | N28: 857529636 | O28: 8.6101725e+08 | P28: 8.675791e+08 | Q28: 8.7195407e+08 | R28: 8.8025066e+08 | S28: 8.969788e+08 | T28: 9.0547179e+08 | U28: 9.0983607e+08 | V28: 9.0814631e+08 | W28: 9.1856855e+08 | X28: 9.2396185e+08 | AA28: 935167554 | AB28: 9.4364627e+08 | AC28: 9.4958197e+08 | AD28: 9.6318604e+08 | AE28: 9.7790257e+08 | AF28: 9.9617827e+08 | AG28: 1.0087073e+09 | AH28: 1.017166e+09 | AI28: 1.0198723e+09 | AJ28: 1.0172475e+09 | AK28: 1.019017e+09 | AL28: 1.021758e+09 | AM28: 1.0243564e+09 | AN28: 1013699515
A29: Total Deposit Liabilities | B29: =SUM(B26:B28) -> 1023936381 | C29: =SUM(C26:C28) -> 1.0235862e+09 | D29: =SUM(D26:D28) -> 1.0066135e+09 | E29: =SUM(E26:E28) -> 1.0344588e+09 | F29: =SUM(F26:F28) -> 1.0937644e+09 | G29: =SUM(G26:G28) -> 1.0664306e+09 | H29: =SUM(H26:H28) -> 1.0767705e+09 | I29: =SUM(I26:I28) -> 1.096271e+09 | ... AN29: =SUM(AN26:AN28) -> 1332497673
A30: Tax Payable | C30: 2463815 | D30: 1509690.3 | E30: 1820917.1 | F30: 1491240.3 | G30: 1888908.1 | H30: 1747554.3 | I30: 1806251 | J30: 1741919.7 | K30: 1763163.5 | L30: 716644.92 | M30: 326624.1 | O30: 642502.38 | P30: 215202.67 | Q30: 727315.09 | R30: 686131.88 | S30: 5272807.1 | T30: 5222782.7 | U30: 4088084.1 | V30: 3706637.1 | W30: 3496526.9 | X30: 3120087.3 | AA30: -678121 | AB30: 1183908.4 | AC30: -19462.97 | AD30: 519912.79 | AE30: -3515387 | AF30: 2335029.2 | AG30: 2349022.4 | AH30: 2958692.9 | AI30: 3318660.9 | AJ30: 2913512 | AK30: -2415960.7 | AL30: -2097787.6 | AM30: -4244436.8
A31: Dividends Payable | B31: 84014461 | C31: 0 | D31: 0 | E31: 0 | F31: 0 | G31: 0 | H31: 0 | I31: 0 | J31: 0 | K31: 0 | L31: 0 | M31: 0 | N31: 77330992 | O31: 0 | P31: 0 | Q31: 0 | R31: 0 | S31: 0 | T31: 0 | U31: 0 | V31: 0 | W31: 0 | X31: 0 | AA31: 122958829 | AB31: 0 | AC31: 0 | AD31: 0 | AE31: 0 | AF31: 0 | AG31: 0 | AH31: 0 | AI31: 0 | AJ31: 0 | AK31: 0 | AL31: 0 | AM31: 0
A32: Deferred Tax Liability | B32: 5817765 | C32: 5817765 | D32: 5817765 | E32: 5817765 | F32: 5817765 | G32: 5817765 | H32: 5817765 | I32: 5817765 | J32: 5817765 | K32: 5817765 | L32: 5817765 | M32: 5817765 | N32: 5817765 | O32: 5817765 | P32: 5817765 | Q32: 5817765 | R32: 5817765 | S32: 5817765 | T32: 5817765 | U32: 5817765 | V32: 5817765 | W32: 5817765 | X32: 5817765 | AA32: 5817765 | AB32: 5817765 | AC32: 5817765 | AD32: 5817765 | AE32: 5817765 | AF32: 5817765 | AG32: 5817765 | AH32: 5817765 | AI32: 5817765 | AJ32: 5817765 | AK32: 5817765 | AL32: 5817765 | AM32: 5817765 | AN32: 5817765
A33: Retirement Benefits Liabilty | C33: 12811166 | D33: 12811166 | E33: 13336718 | F33: 13336718 | G33: 13687086 | H33: 13862270 | I33: 14212638 | J33: 14212638 | K33: 14387822 | L33: 14563006 | M33: 14738190 | O33: 14738190 | P33: 14738190 | Q33: 14738190 | R33: 15438926 | S33: 15438926 | T33: 15789294 | U33: 15789294 | V33: 16139662 | W33: 10239662 | X33: 9788717.8 | AA33: 2119096 | AB33: 139464.02 | AC33: -70535.98 | AD33: -870535.98 | AE33: -1170536 | AF33: -2020536 | AG33: -2652536 | AH33: -2076616 | AI33: -3376616 | AJ33: -4776616 | AK33: -3751416.4 | AL33: -3533467.9 | AM33: -3783467.9
A34: Other Liabilities | B34: 12811166 | C34: 88213932 | D34: 86332728 | E34: 85162658 | F34: 17652305 | G34: 13897490 | H34: 7825791.4 | I34: 6715539.2 | J34: 9129413.7 | K34: 12791619 | L34: 6511614.5 | M34: 30517876 | N34: 14738190 | O34: 1.0562227e+08 | P34: 88833554 | Q34: 82665727 | R34: 81584680 | S34: 33141038 | T34: 29328113 | U34: 18841638 | V34: 25687258 | W34: 23231859 | X34: 22966869 | AB34: 20814807 | AC34: 1.3210488e+08 | AD34: 1.3406209e+08 | AE34: 1.0948556e+08 | AF34: 8773753.6 | AG34: -28610347 | AH34: -53203830 | AI34: -28769851 | AJ34: -36897809 | AK34: -40330364 | AL34: -49538598 | AM34: -1.0214591e+08 | AN34: 60292558
A35: External Borrowings | B35: 137071101 | C35: 1.3311744e+08 | D35: 1.7107631e+08 | E35: 1.7107631e+08 | F35: 1.3753741e+08 | G35: 1.2992613e+08 | H35: 1.4525584e+08 | I35: 1.5903364e+08 | J35: 3.8143212e+08 | K35: 2.5624878e+08 | L35: 2.5624878e+08 | M35: 2.5819774e+08 | N35: 289699512 | O35: 277866179 | P35: 2.7106887e+08 | Q35: 2.7106887e+08 | R35: 2.8197283e+08 | S35: 2.8384638e+08 | T35: 2.6874432e+08 | U35: 2.5691099e+08 | V35: 2.6604257e+08 | W35: 2.5368732e+08 | X35: 2.5155201e+08 | AA35: 261813600 | AB35: 3.2216551e+08 | AC35: 3.2134854e+08 | AD35: 3.085152e+08 | AE35: 3.1752265e+08 | AF35: 3.912921e+08 | AG35: 3.7689488e+08 | AH35: 3.9187255e+08 | AI35: 3.5798788e+08 | AJ35: 3.5798788e+08 | AK35: 3.5269622e+08 | AL35: 3.4740455e+08 | AM35: 3.4211288e+08 | AN35: 342112881
A36: Total Liabilities | B36: =SUM(B29:B35) -> 1263650874 | C36: =SUM(C29:C35) -> 1.2660103e+09 | D36: =SUM(D29:D35) -> 1.2841612e+09 | E36: =SUM(E29:E35) -> 1.3116732e+09 | F36: =SUM(F29:F35) -> 1.2695999e+09 | G36: =SUM(G29:G35) -> 1.2316479e+09 | H36: =SUM(H29:H35) -> 1.2512797e+09 | I36: =SUM(I29:I35) -> 1.2838569e+09 | ... AN36: =SUM(AN29:AN35) -> 1740720877
A37: Share Capital | B37: 94040516 | C37: 96375374 | D37: 99026286 | E37: 1.0159799e+08 | F37: 1.0369588e+08 | G37: 1.0591767e+08 | H37: 1.0815539e+08 | I37: 1.1266596e+08 | J37: 1.1480718e+08 | K37: 1.17099e+08 | L37: 1.19163e+08 | M37: 1.2112037e+08 | N37: 121120367 | O37: 1.2370364e+08 | P37: 1.2570105e+08 | Q37: 1.2821325e+08 | R37: 1.3036721e+08 | S37: 1.3214984e+08 | T37: 1.3471771e+08 | U37: 1.3705512e+08 | V37: 1.3913992e+08 | W37: 1.4132706e+08 | X37: 1.4367808e+08 | AA37: 148054368 | AB37: 1.4856041e+08 | AC37: 1.4869928e+08 | AD37: 1.4929312e+08 | AE37: 1.4922417e+08 | AF37: 1.5057846e+08 | AG37: 1.5139444e+08 | AH37: 1.5135603e+08 | AI37: 1.5201269e+08 | AJ37: 1.52395e+08 | AK37: 1.5273261e+08 | AL37: 1.531093e+08 | AM37: 1.5337047e+08 | AN37: 153370471
A38: Capital Grants | C38: 0 | D38: 0 | E38: 0 | F38: 0 | G38: 0 | H38: 0 | I38: 0 | J38: 0 | K38: 0 | L38: 0 | M38: 0 | O38: 0 | P38: 0 | Q38: 0 | R38: 0 | S38: 0 | T38: 0 | U38: 0 | V38: 0 | W38: 0 | X38: 0 | AB38: 0 | AC38: 0 | AD38: 0 | AE38: 0 | AF38: 0 | AG38: 0 | AH38: 0 | AI38: 0 | AJ38: 0 | AK38: 0 | AL38: 0 | AM38: 0
A39: Prior Year Retained Earnigs | B39: 76444433 | C39: 75728252 | D39: 75728252 | E39: 75728215 | F39: 75728252 | G39: 75728252 | H39: 75728696 | I39: 75728696 | J39: 75728696 | K39: 75728696 | L39: 75728696 | M39: 75728696 | N39: 74728696 | O39: 96421479 | P39: 96421479 | Q39: 1.0922148e+08 | R39: 1.0922148e+08 | S39: 1.0922148e+08 | T39: 1.0922148e+08 | U39: 1.0922148e+08 | V39: 1.0922148e+08 | W39: 1.0922148e+08 | X39: 1.0922148e+08 | AB39: 1.4242632e+08 | AC39: 8104132.9 | AD39: 48104133 | AE39: 48104133 | AF39: 45504133 | AG39: 1.3742205e+08 | AH39: 1.3742205e+08 | AI39: 1.3742205e+08 | AJ39: 1.3742205e+08 | AK39: 1.3742205e+08 | AL39: 1.3742205e+08 | AM39: 1.3742205e+08 | AN39: 126395535
A40: Current Year Surplus | C40: 4874335.4 | D40: -4521185.8 | E40: 11985150 | F40: 24224212 | G40: 22121897 | H40: 33855267 | I40: 33828986 | J40: 35234668 | K40: 39049351 | L40: 41252982 | M40: 22243840 | N40: =92322924-N39 -> 17594228 | O40: 1117242.3 | P40: 6199533.6 | Q40: 13000040 | R40: 7642331.3 | S40: 898922.75 | T40: 5575826 | U40: 8451719.7 | V40: 9581941 | W40: 28597534 | X40: 30781216 | AB40: 1285976.7 | AC40: 3947050.3 | AD40: 7524026.4 | AE40: 6103515.2 | AF40: 7048248.1 | AG40: 21784625 | AH40: 23436514 | AI40: 23135718 | AJ40: 23082006 | AK40: 40249539 | AL40: 53437644 | AM40: 79367888 | AN40: =-20359837+29691591-2000000-5938318+3748948-16871187 -> -11728803
...

Sheet soci
B2: Audited 2019 | C2: 43831 | D2: 43862 | E2: 43891 | F2: 43922 | G2: 43952 | H2: 43983 | I2: 44044 | J2: 44075 | K2: 44105 | L2: 44136 | M2: 44166 | N2: AUDITED 2020 | O2: 44197 | P2: 44228 | Q2: 44256 | R2: 44287 | S2: 44317 | T2: 44348 | U2: 44378 | V2: 44409 | W2: 44440 | X2: 44470 | Y2: 44501 | Z2: 44531 | AA2: AUDITED 2021 | AB2: 44562 | AC2: 44593 | AD2: 44621 | AE2: 44652 | AF2: 44682 | AG2: 44713 | AH2: 44743 | AI2: 44774 | AJ2: 44805 | AK2: 44835 | AL2: 44866 | AM2: 44896 | AN2: Audited 2022
A3: Financial Income | B3: =B7+B4 -> 256532840 | C3: =C7+C4 -> 16521722 | D3: =D7+D4 -> 19232980 | E3: =E7+E4 -> 50088742 | F3: =F7+F4 -> 78736160 | G3: =G7+G4 -> 94240710 | H3: =H7+H4 -> 1.1527639e+08 | I3: =I7+I4 -> 1.5103701e+08 | ... AN3: =AN7+AN4 -> 354693313
A4: Financial Income From Loans Portfolio | B4: =B5+B6 -> 233834351 | C4: =C5+C6 -> 16521722 | D4: =D5+D6 -> 18732732 | E4: =E5+E6 -> 49588493 | F4: =F5+F6 -> 66811705 | G4: =G5+G6 -> 81786939 | H4: =H5+H6 -> 1.0183527e+08 | I4: =I5+I6 -> 1.3758886e+08 | ... AN4: =AN5+AN6 -> 316481623
A5: Interest from Loans Portfolio | B5: 176875846 | C5: 13021470 | D5: 13138377 | E5: 41284261 | F5: 57630156 | G5: 71135398 | H5: 85709724 | I5: 1.1447714e+08 | J5: 1.2865374e+08 | K5: 1.4328807e+08 | L5: 1.584202e+08 | M5: 1.7378698e+08 | N5: 184786981 | O5: 15277940 | P5: 30405576 | Q5: 46168620 | R5: 61940773 | S5: 77623182 | T5: 93410913 | U5: 1.0924128e+08 | V5: 1.2660975e+08 | W5: 1.4567543e+08 | X5: 1.6602146e+08 | AA5: 217212003 | AB5: 18467275 | AC5: 35781411 | AD5: 56795977 | AE5: 75114251 | AF5: 94824393 | AG5: 1.1625177e+08 | AH5: 1.3568376e+08 | AI5: 1.5532127e+08 | AJ5: 1.7410113e+08 | AK5: 1.9264607e+08 | AL5: 2.0980331e+08 | AM5: 2.301771e+08 | AN5: 228517048
A6: Fees&Commision on Loan Portfolio | B6: 56958505 | C6: 3500252.2 | D6: 5594354.9 | E6: 8304232.4 | F6: 9181548.5 | G6: 10651541 | H6: 16125550 | I6: 23111719 | J6: 25597123 | K6: 30149351 | L6: 33496935 | M6: 38626067 | N6: 52901050 | O6: 1931950.8 | P6: 4147290.7 | Q6: 7400584.5 | R6: 10838469 | S6: 12878955 | T6: 17320987 | U6: 24596743 | V6: 25743615 | W6: 25801995 | X6: 25858380 | AA6: 87931702 | AB6: 42840 | AC6: 76618 | AD6: 141593 | AE6: 121316 | AF6: 180326 | AG6: 233642.8 | AH6: 283412.77 | AI6: 337592.8 | AJ6: 388517.8 | AK6: 426947.8 | AL6: 468947.8 | AM6: 584596.8 | AN6: 87964575
A7: Financial Income from Investments | B7: =SUM(B8:B11) -> 22698489 | C7: =SUM(C8:C11) -> 0 | D7: =SUM(D8:D11) -> 500248.06 | E7: =SUM(E8:E11) -> 500248.06 | F7: =SUM(F8:F11) -> 11924455 | G7: =SUM(G8:G11) -> 12453771 | H7: =SUM(H8:H11) -> 13441115 | I7: =SUM(I8:I11) -> 13448154 | ... AN7: =SUM(AN8:AN11) -> 38211690
A8: Government Securities | O8: 0 | P8: 0 | Q8: 0 | R8: 0 | S8: 0 | T8: 0 | U8: 0 | V8: 0 | W8: 0 | X8: 0 | AB8: 0 | AC8: 0 | AD8: 0 | AE8: 0 | AF8: 0 | AG8: 0 | AH8: 0 | AI8: 0 | AJ8: 0 | AK8: 0 | AL8: 0 | AM8: 0
A9: Deposits with Banks & other Financial Institutions | C9: 0 | D9: 500248.06 | E9: 500248.06 | F9: 500248.06 | G9: 1029563.9 | H9: 1029563.9 | I9: 1036602.7 | J9: 1036818.6 | K9: 1037028.7 | L9: 1037028.7 | M9: 2207259.8 | O9: 0 | P9: 0 | Q9: 630.95 | R9: 630.95 | S9: 1272655.6 | T9: 1272655.6 | U9: 1272655.6 | V9: 1973003.8 | W9: 2090600.8 | X9: 2090600.8 | AB9: 844023.3 | AC9: 846751.13 | AD9: 846751.13 | AE9: 846751.13 | AF9: 846751.13 | AG9: 846751.13 | AH9: 846751.13 | AI9: 2690181.8 | AJ9: 2690181.8 | AK9: 2690181.8 | AL9: 2690181.8 | AM9: 9714279.9 | AN9: 9714280
A10: Other Investments | B10: 1908295 | C10: 0 | D10: 0 | E10: 0 | F10: 11424207 | G10: 11424207 | H10: 12411551 | I10: 12411551 | J10: 12411551 | K10: 12411551 | L10: 12411551 | M10: 12434444 | N10: 2207260 | O10: 0 | P10: 0 | Q10: 1224844 | R10: 0 | S10: 0 | T10: 0 | U10: 0 | V10: 0 | W10: 11078589 | X10: 11078589 | AA10: 2980594 | AB10: 0 | AC10: 0 | AD10: 0 | AE10: 0 | AF10: 0 | AG10: 12320734 | AH10: 12320734 | AI10: 12320734 | AJ10: 12320734 | AK10: 12320734 | AL10: 12320734 | AM10: 25562640
A11: Other Operating Income | B11: 20790194 | N11: 18657068 | O11: 1426995.4 | P11: 2481556.4 | Q11: 4685962 | R11: 5653067.5 | S11: 9236922.4 | T11: 10694691 | U11: 12738494 | V11: 14405857 | W11: 15874429 | X11: 17291920 | AA11: 14506454 | AB11: 1377155.4 | AC11: 2219919 | AD11: 4314562.6 | AE11: 5632011.4 | AF11: 9935844.8 | AG11: 11441874 | AH11: 13010713 | AI11: 14261311 | AJ11: 15722628 | AK11: 18249355 | AL11: 22799365 | AM11: 24154693 | AN11: 28497410
A12: Financial Expenses | B12: =SUM(B13:B18) -> 101755189 | C12: =SUM(C13:C18) -> 2688407.8 | D12: =SUM(D13:D18) -> 5882553.4 | E12: =SUM(E13:E18) -> 6998482.4 | F12: =SUM(F13:F18) -> 8955782 | G12: =SUM(G13:G18) -> 13593452 | H12: =SUM(H13:H18) -> 15855271 | I12: =SUM(I13:I18) -> 33456692 | ... AN12: =SUM(AN13:AN18) -> 144784771
A13: Interest Expense on Deposits | B13: 94088686 | C13: 2178181.8 | D13: 3769858.5 | E13: 4884587.5 | F13: 6671582.6 | G13: 9038281.2 | H13: 10426468 | I13: 14501672 | J13: 16244063 | K13: 18234359 | L13: 21375177 | M13: 49398693 | O13: 1771464 | P13: 4489755.2 | Q13: 6138432.1 | R13: 8085970.9 | S13: 10257560 | T13: 12461773 | U13: 14261396 | V13: 16929300 | W13: 18765101 | X13: 21070514 | AA13: 155744738 | AB13: 2952714.6 | AC13: 5736443.2 | AD13: 8447156.8 | AE13: 11284316 | AF13: 14212255 | AG13: 16936377 | AH13: 20785704 | AI13: 23609104 | AJ13: 26479358 | AK13: 30504972 | AL13: 33970806 | AM13: 38811488 | AN13: =99669373 -> 99669373
A14: Cost of External Borrowings | B14: 7666503 | C14: 510226 | D14: 2112695 | E14: 2113895 | F14: 2284199.4 | G14: 4555171.1 | H14: 5428802.7 | I14: 18955021 | J14: 22934455 | K14: 25481070 | L14: 25575391 | M14: 28965607 | O14: 210900 | P14: 3967142.6 | Q14: 4099423.1 | R14: 4509186.9 | S14: 18048389 | T14: 18193202 | U14: 18354956 | V14: 19635122 | W14: 19573196 | X14: 23268179 | AB14: 49821.61 | AC14: 473732.52 | AD14: 596180.33 | AE14: 597380.3 | AF14: 1054421.4 | AG14: 1065201.9 | AH14: 1067001.9 | AI14: 6470986 | AJ14: 7170056.8 | AK14: 7393495.8 | AL14: 7701309 | AM14: 7891195 | AN14: =1185665+22284140 -> 23469805
A15: Dividend Expenses | O15: 0 | P15: 0 | Q15: 0 | R15: 0 | S15: 0 | T15: 0 | U15: 0 | V15: 0 | W15: 0 | X15: 0 | AB15: 0 | AC15: 0 | AD15: 0 | AE15: 0 | AF15: 0 | AG15: 0 | AH15: 0 | AI15: 0 | AJ15: 0 | AK15: 0 | AL15: 0 | AM15: 0 | AN15: 21645593
A16: Other Financial Expense | O16: 0 | P16: 0 | Q16: 0 | R16: 0 | S16: 0 | T16: 0 | U16: 0 | V16: 0 | W16: 0 | X16: 0 | AB16: 0 | AC16: 0 | AD16: 0 | AE16: 0 | AF16: 0 | AG16: 0 | AH16: 0 | AI16: 0 | AJ16: 0 | AK16: 0 | AL16: 0 | AM16: 0
A17: Fees & Commision Expense | O17: 0 | P17: 0 | Q17: 0 | R17: 0 | S17: 0 | T17: 0 | U17: 0 | V17: 0 | W17: 0 | X17: 0 | AB17: 0 | AC17: 0 | AD17: 0 | AE17: 0 | AF17: 0 | AG17: 0 | AH17: 0 | AI17: 0 | AJ17: 0 | AK17: 0 | AL17: 0 | AM17: 0
A18: Other Expenses | O18: 0 | P18: 0 | Q18: 0 | R18: 0 | S18: 0 | T18: 0 | U18: 0 | V18: 0 | W18: 0 | X18: 0 | AA18: 20000000 | AB18: 0 | AC18: 0 | AD18: 0 | AE18: 0 | AF18: 0 | AG18: 0 | AH18: 0 | AI18: 0 | AJ18: 0 | AK18: 0 | AL18: 0 | AM18: 0
A19: Net Financial Income | B19: =B3-B12 -> 154777651 | C19: =C3-C12 -> 13833314 | D19: =D3-D12 -> 13350426 | E19: =E3-E12 -> 43090259 | F19: =F3-F12 -> 69780378 | G19: =G3-G12 -> 80647257 | H19: =H3-H12 -> 99421119 | I19: =I3-I12 -> 1.1758032e+08 | ... AN19: =AN3-AN12 -> 209908542
A20: Allowance for Loan Loss | O20: 0 | P20: 0 | Q20: 0 | R20: 2000000 | S20: 2000000 | T20: 3000000 | U20: 3000000 | V20: 4000000 | W20: 4000000 | X20: 4000000
A21: Provision for Loan Losses | C21: 0 | D21: 0 | E21: 1500000 | F21: 1500000 | G21: 2500000 | H21: 3000000 | I21: 4000000 | J21: 4500000 | K21: 5000000 | L21: 5500000 | M21: 6000000 | O21: 0 | P21: 0 | Q21: 0 | R21: 0 | S21: 0 | T21: 0 | U21: 0 | V21: 0 | W21: 0 | X21: 0
A22: Value of Loans Recovered | C22: 0 | D22: 0 | E22: 0 | F22: 0 | G22: 0 | H22: 0 | I22: 0 | J22: 0 | K22: 0 | L22: 0 | M22: 0
A23: Operating Expeses | B23: =SUM(B24:B28) -> 131684611 | C23: =SUM(C24:C28) -> 10713803 | D23: =SUM(D24:D28) -> 20884864 | E23: =SUM(E24:E28) -> 35154365 | F23: =SUM(F24:F28) -> 52089970 | G23: =SUM(G24:G28) -> 65679527 | H23: =SUM(H24:H28) -> 73177337 | I23: =SUM(I24:I28) -> 94148543 | ... N23: =SUM(N24:N28) -> 132194359 | W23: =SUM(W24:W28) -> 1.2958521e+08 | X23: =SUM(X24:X28) -> 1.4322104e+08 | Y23: =SUM(Y24:Y28) -> 0 | Z23: =SUM(Z24:Z28) -> 0 | AA23: =SUM(AA24:AA28) -> 130007972 | AB23: =SUM(AB24:AB28) -> 16442781 | AC23: 0 | AD23: =SUM(AD24:AD28) -> 45531520 | AE23: =SUM(AE24:AE28) -> 63729118 | AF23: =SUM(AF24:AF28) -> 83472390 | AG23: =SUM(AG24:AG28) -> 1.0130856e+08 | AH23: =SUM(AH24:AH28) -> 1.1685615e+08 | AI23: =SUM(AI24:AI28) -> 1.3171528e+08 | AJ23: =SUM(AJ24:AJ28) -> 1.476213e+08 | AK23: =SUM(AK24:AK28) -> 1.4731481e+08 | ... AN23: =SUM(AN24:AN28) -> 178494606
A24: Personel Expenses | B24: 40327405 | C24: 5889327.3 | D24: 6356284.3 | E24: 12907465 | F24: 13589965 | G24: 19914668 | H24: 23035276 | I24: 29314222 | J24: 32221232 | K24: 36018304 | L24: 39375460 | M24: 39880468 | N24: 40880468 | O24: 5815004.2 | P24: 6171338.2 | Q24: 12541620 | R24: 16389911 | S24: 19904475 | T24: 26249222 | U24: 33457917 | V24: 37784509 | W24: 38490199 | X24: 42482699 | AA24: 52446080 | AB24: 2672570.1 | AC24: 6728014 | AD24: 12155228 | AE24: 17029662 | AF24: 22329585 | AG24: 27191188 | AH24: 32531458 | AI24: 36874386 | AJ24: 41819298 | AK24: 49553164 | AL24: 53740233 | AM24: 54086277 | AN24: 54086277
A25: Governance Expenses | B25: 23705306 | C25: 1871302 | D25: 7334202 | E25: 8040547 | F25: 8957397 | G25: 8660397 | H25: 9048970 | I25: 9921306 | J25: 10359179 | K25: 12233179 | L25: 13509982 | M25: 16984122 | N25: 18184122 | O25: 2890805 | P25: 4029405 | Q25: 5316878 | R25: 9350888 | S25: 10127054 | T25: 11951404 | U25: 14196818 | V25: 15701143 | W25: 19298303 | X25: 19967703 | AA25: 19367933 | AB25: 3591100 | AC25: 6001770 | AD25: 8612440 | AE25: 15681160 | AF25: 18480060 | AG25: 22371190 | AH25: 23674550 | AI25: 24637950 | AJ25: 28534410 | AK25: 26257310 | AL25: 24781060 | AM25: 28084460 | AN25: 26084460
A26: Marketing Expenses | B26: 11075110 | C26: 878234 | D26: 2844964 | E26: 5530745 | F26: 7134162.6 | G26: 7781663.7 | H26: 8246128.2 | I26: 9316638.3 | J26: 10097098 | K26: 10665691 | L26: 12635857 | M26: 13615687 | N26: 12003487 | O26: 1942117 | P26: 2707533 | Q26: 3565433 | R26: 4434563 | S26: 5325633 | T26: 7125777 | U26: 7638075 | V26: 8623117 | W26: 9283563 | X26: 10792305 | AA26: =21081792-AA27 -> 14983074 | AB26: 3754908 | AC26: 5868620 | AD26: 7286250 | AE26: 9093478 | AF26: 11477758 | AG26: 12831658 | AH26: 14473046 | AI26: 16655682 | AJ26: 18184570 | AK26: 18071240 | AL26: 21038934 | AM26: 23797460 | AN26: 11423660
A27: Depreciation and Amortization | B27: 8790687 | C27: 0 | D27: 0 | E27: 1536233.8 | F27: 1536233.8 | G27: 2560389.6 | H27: 3072467.6 | I27: 4096623.4 | J27: 4608701.4 | K27: 5120779.3 | L27: 5632857.2 | M27: 6144935.2 | N27: 6144935 | O27: 0 | P27: 0 | Q27: 0 | R27: 3005777.8 | S27: 3005777.8 | T27: 4508666.7 | U27: 4508666.7 | V27: 6019258.5 | W27: 6019258.5 | X27: 6019258.5 | AA27: 6098718 | AB27: 0 | AC27: 0 | AD27: 0 | AE27: 0 | AF27: 0 | AG27: 0 | AH27: 0 | AI27: 0 | AJ27: 0 | AK27: 0 | AL27: 0 | AM27: 0 | AN27: =14556874+2388929 -> 16945803
A28: Administrative Expenses | B28: 47786103 | C28: 2074940 | D28: 4349413.6 | E28: 7139373.6 | F28: 20872211 | G28: 26762408 | H28: 29774495 | I28: 41499753 | J28: 47492381 | K28: 52574986 | L28: 56349640 | M28: 61051780 | N28: =39981347+15000000 -> 54981347 | O28: 4889353.8 | P28: 9469715 | Q28: 14818815 | R28: 23014312 | S28: 31443905 | T28: 33633376 | U28: 43979622 | V28: 50457840 | W28: 56493888 | X28: 63959075 | AA28: 37112167 | AB28: 6424202.9 | AC28: 10169069 | AD28: 17477602 | AE28: 21924818 | AF28: 31184988 | AG28: 38914529 | AH28: 46177100 | AI28: 53547260 | AJ28: 59083019 | AK28: 53433100 | AL28: 52542086 | AM28: 56432201 | AN28: =40764184+1955189+165500+11309608+5173695+2009890-AN26+20000000 -> 69954406
A29: Net Operating Income | B29: =B19-B21-B23 -> 23093040 | C29: =C19-C21-C23 -> 3119511 | D29: =D19-D21-D23 -> -7534437.5 | E29: =E19-E21-E23 -> 6435894.5 | F29: =F19-F21-F23 -> 16190408 | G29: =G19-G21-G23 -> 12467731 | H29: =H19-H21-H23 -> 23243782 | I29: =I19-I21-I23 -> 19431779 | ... AN29: =AN19-AN21-AN23 -> 31413936
A30: Net Non operating Income/Expense | B30: =B29 -> 23093040 | C30: =C29 -> 3119511 | D30: =D29 -> -7534437.5 | E30: =E29 -> 6435894.5 | F30: =F29 -> 16190408 | G30: =G29 -> 12467731 | H30: =H29 -> 23243782 | I30: =I29 -> 19431779 | ... AN30: =AN29 -> 31413936
A31: Non Operating Income | O31: 0 | P31: 0 | Q31: 0 | R31: 0 | S31: 0 | T31: 0 | U31: 0 | V31: 0 | W31: 0 | X31: 0
A32: Non Operating Expense | O32: 0 | P32: 0 | Q32: 0 | R32: 0 | S32: 0 | T32: 0 | U32: 0 | V32: 0 | W32: 0 | X32: 0
A33: Net Income(Before Tax & Donations) | B33: =B30 -> 23093040 | C33: =C30 -> 3119511 | D33: =D30 -> -7534437.5 | E33: =E30 -> 6435894.5 | F33: =F30 -> 16190408 | G33: =G30 -> 12467731 | H33: =H30 -> 23243782 | I33: =I30 -> 19431779 | ... AN33: =AN30 -> 31413936
A34: Taxes | B34: 5613801 | L34: 3267225.9 | M34: 3267225.9 | O34: 0 | P34: 0 | Q34: 0 | R34: 0 | S34: 0 | T34: 0 | U34: 0 | V34: 0 | W34: 0 | X34: 0 | AA34: 3595387 | AB34: 0 | AC34: 0 | AD34: 0 | AE34: 0 | AF34: 0 | AG34: 0 | AH34: 0 | AI34: 0 | AJ34: 870469 | AK34: 870469 | AL34: 870469 | AM34: 1722344 | AN34: 1722344
A35: Net Income(After Tax Before Donations) | B35: =B33-B34 -> 17479239 | C35: =C33-C34 -> 3119511 | D35: =D33-D34 -> -7534437.5 | E35: =E33-E34 -> 6435894.5 | F35: =F33-F34 -> 16190408 | G35: =G33-G34 -> 12467731 | H35: =H33-H34 -> 23243782 | I35: =I33-I34 -> 19431779 | ... AN35: =AN33-AN34 -> 29691592
A36: Donations | O36: 0 | P36: 0 | Q36: 0 | R36: 0 | S36: 0 | T36: 0 | U36: 0 | V36: 0 | W36: 0 | X36: 0
A37: Net Income/(After Tax & Donations) | B37: =B35-B36 -> 17479239 | C37: =C35-C36 -> 3119511 | D37: =D35-D36 -> -7534437.5 | E37: =E35-E36 -> 6435894.5 | F37: =F35-F36 -> 16190408 | G37: =G35-G36 -> 12467731 | H37: =H35-H36 -> 23243782 | I37: =I35-I36 -> 19431779 | ... AN37: =AN35-AN36 -> 29691592

Sheet financials
B1: Audited 2019 | C1: 43831 | D1: 43862 | E1: 43891 | F1: 43922 | G1: 43952 | H1: 43983 | I1: 44044 | J1: 44075 | K1: 44105 | L1: 44136 | M1: 44166 | N1: AUDITED 2020 | O1: 44197 | P1: 44228 | Q1: 44256 | R1: 44287 | S1: 44317 | T1: 44348 | U1: 44378 | V1: 44409 | W1: 44440 | X1: 44470 | Y1: 44501 | Z1: 44531 | AA1: Audited 2021 | AB1: 44562 | AC1: 44593 | AD1: 44621 | AE1: 44652 | AF1: 44682 | AG1: 44713 | AH1: 44743 | AI1: 44774 | AJ1: 44805 | AK1: 44835 | AL1: 44866 | AM1: 44896 | AN1: Audited 2022
A2: Membership
A3: Total Assets | B3: =sofp!B25 -> 1602742627 | C3: =sofp!C25 -> 1.6091986e+09 | D3: =sofp!D25 -> 1.6206049e+09 | E3: =sofp!E25 -> 1.6671949e+09 | F3: =sofp!F25 -> 1.6394586e+09 | G3: =sofp!G25 -> 1.6016261e+09 | H3: =sofp!H25 -> 1.6352294e+09 | I3: =sofp!I25 -> 1.6722908e+09 | ... AN3: =sofp!AN25 -> 2209776677
A4: Total Deposits | B4: =sofp!B29 -> 1023936381 | C4: =sofp!C29 -> 1.0235862e+09 | D4: =sofp!D29 -> 1.0066135e+09 | E4: =sofp!E29 -> 1.0344588e+09 | F4: =sofp!F29 -> 1.0937644e+09 | G4: =sofp!G29 -> 1.0664306e+09 | H4: =sofp!H29 -> 1.0767705e+09 | I4: =sofp!I29 -> 1.096271e+09 | ... AN4: =sofp!AN29 -> 1332497673
A5: Deposits-Members(BOSA) | B5: =sofp!B28 -> 785401586 | C5: =sofp!C28 -> 7.9060446e+08 | D5: =sofp!D28 -> 7.9722785e+08 | E5: =sofp!E28 -> 8.0612753e+08 | F5: =sofp!F28 -> 8.2275054e+08 | G5: =sofp!G28 -> 8.2820634e+08 | H5: =sofp!H28 -> 8.3542453e+08 | I5: =sofp!I28 -> 8.4217551e+08 | ... AN5: =sofp!AN28 -> 1013699515
A6: Deposits-Customers(FOSA) | B6: =sofp!B26 + sofp!B28 -> 928114303 | C6: =sofp!C26 + sofp!C28 -> 9.2419443e+08 | D6: =sofp!D26 + sofp!D28 -> 8.9836032e+08 | E6: =sofp!E26 + sofp!E28 -> 9.2468856e+08 | F6: =sofp!F26 + sofp!F28 -> 984658965 | G6: =sofp!G26 + sofp!G28 -> 9.5137909e+08 | H6: =sofp!H26 + sofp!H28 -> 9.5549184e+08 | I6: =sofp!I26 + sofp!I28 -> 9.7230193e+08 | ... AN6: =sofp!AN26 + sofp!AN28 -> 1120271363
A7: External Borrowing | B7: =sofp!B35 -> 137071101 | C7: =sofp!C35 -> 1.3311744e+08 | D7: =sofp!D35 -> 1.7107631e+08 | E7: =sofp!E35 -> 1.7107631e+08 | F7: =sofp!F35 -> 1.3753741e+08 | G7: =sofp!G35 -> 1.2992613e+08 | H7: =sofp!H35 -> 1.4525584e+08 | I7: =sofp!I35 -> 1.5903364e+08 | ... AN7: =sofp!AN35 -> 342112881
A8: Short term liabilities | B8: =SUM(sofp!B30:B34) -> 102643392 | C8: =SUM(sofp!C30:C34) -> 1.0930668e+08 | D8: =SUM(sofp!D30:D34) -> 1.0647135e+08 | E8: =SUM(sofp!E30:E34) -> 1.0613806e+08 | F8: =SUM(sofp!F30:F34) -> 38298028 | G8: =SUM(sofp!G30:G34) -> 35291248 | H8: =SUM(sofp!H30:H34) -> 29253380 | I8: =SUM(sofp!I30:I34) -> 28552193 | ... AN8: =SUM(sofp!AN30:AN34) -> 66110323
A10: Share Capital and Reserves
A11: Core Capital | B11: =B14 -> 237956727 | C11: =C14 -> 2.3265076e+08 | D11: =D14 -> 225906148 | E11: =E14 -> 2.4498415e+08 | F11: =F14 -> 2.5932114e+08 | G11: =G14 -> 2.5944062e+08 | H11: =H14 -> 2.7341215e+08 | I11: =I14 -> 2.7789644e+08 | ... M11: =M14 -> 2.747657e+08 | N11: =N14-N24 -> 276149287 | O11: =O14-O24 -> 2.7691515e+08 | P11: =P14-P24 -> 2.8399486e+08 | Q11: =Q14-Q24 -> 3.0610756e+08 | R11: =R14-R24 -> 3.0290381e+08 | S11: =S14-S24 -> 2.9794304e+08 | T11: =T14-T24 -> 3.0518781e+08 | U11: =U14-U24 -> 3.1040112e+08 | ... AN11: =AN14-AN24 -> 341647076
A12: Institutional Capital | B12: =B11 - B15 -> 143916211 | C12: =C11 - C15 -> 1.3627538e+08 | D12: =D11 - D15 -> 1.2687986e+08 | E12: =E11 - E15 -> 1.4338616e+08 | F12: =F11 - F15 -> 1.5562526e+08 | G12: =G11 - G15 -> 1.5352294e+08 | H12: =H11 - H15 -> 1.6525676e+08 | I12: =I11 - I15 -> 1.6523048e+08 | ... M12: =M11 - M15 -> 1.5364533e+08 | N12: =sofp!N39+sofp!N40+sofp!N41+sofp!N42 -> 155052920 | O12: =sofp!O39+sofp!O40+sofp!O41+sofp!O42 -> 1.5321152e+08 | P12: =sofp!P39+sofp!P40+sofp!P41+sofp!P42 -> 1.5829381e+08 | Q12: =sofp!Q39+sofp!Q40+sofp!Q41+sofp!Q42 -> 1.7789431e+08 | R12: =sofp!R39+sofp!R40+sofp!R41+sofp!R42 -> 1.7253661e+08 | S12: =sofp!S39+sofp!S40+sofp!S41+sofp!S42 -> 1.657932e+08 | T12: =sofp!T39+sofp!T40+sofp!T41+sofp!T42 -> 1.704701e+08 | U12: =sofp!U39+sofp!U40+sofp!U41+sofp!U42 -> 1.7334599e+08 | ... AN12: =sofp!AN39+sofp!AN40+sofp!AN41+sofp!AN42 -> 188276605
A14: Total Capital | B14: =SUM(B15:B17) + B19 -> 237956727 | C14: =SUM(C15:C17) + C19 -> 2.3265076e+08 | D14: =SUM(D15:D17) + D19 -> 225906148 | E14: =SUM(E15:E17) + E19 -> 2.4498415e+08 | F14: =SUM(F15:F17) + F19 -> 2.5932114e+08 | G14: =SUM(G15:G17) + G19 -> 2.5944062e+08 | H14: =SUM(H15:H17) + H19 -> 2.7341215e+08 | I14: =SUM(I15:I17) + I19 -> 2.7789644e+08 | ... AN14: =SUM(AN15:AN17) + AN19 -> 341647076
A15: Members Share Capital | B15: =sofp!B37 -> 94040516 | C15: =sofp!C37 -> 96375374 | D15: =sofp!D37 -> 99026286 | E15: =sofp!E37 -> 1.0159799e+08 | F15: =sofp!F37 -> 1.0369588e+08 | G15: =sofp!G37 -> 1.0591767e+08 | H15: =sofp!H37 -> 1.0815539e+08 | I15: =sofp!I37 -> 1.1266596e+08 | ... AN15: =sofp!AN37 -> 153370471
A16: Retained Earnings | B16: =sofp!B39 + sofp!B40 -> 76444433 | C16: =sofp!C39 + sofp!C40 -> 80602587 | D16: =sofp!D39 + sofp!D40 -> 71207066 | E16: =sofp!E39 + sofp!E40 -> 87713365 | F16: =sofp!F39 + sofp!F40 -> 99952464 | G16: =sofp!G39 + sofp!G40 -> 97850149 | H16: =sofp!H39 + sofp!H40 -> 1.0958396e+08 | I16: =sofp!I39 + sofp!I40 -> 1.0955768e+08 | ... AN16: =sofp!AN39 + sofp!AN40 -> 114666732
A17: Statutory Reserves | B17: =sofp!B41 -> 36256597 | C17: =sofp!C41 -> 34616258 | D17: =sofp!D41 -> 34616258 | E17: =sofp!E41 -> 34616258 | F17: =sofp!F41 -> 34616258 | G17: =sofp!G41 -> 34616258 | H17: =sofp!H41 -> 34616258 | I17: =sofp!I41 -> 34616258 | ... AN17: =sofp!AN41 -> 48394692
A18: Supplementary Capital & Reserves
A19: Capital Reserves | B19: =sofp!B42 -> 31215181 | C19: =sofp!C42 -> 21056538 | D19: =sofp!D42 -> 21056538 | E19: =sofp!E42 -> 21056538 | F19: =sofp!F42 -> 21056538 | G19: =sofp!G42 -> 21056538 | H19: =sofp!H42 -> 21056538 | I19: =sofp!I42 -> 21056538 | ... AN19: =sofp!AN42 -> 25215181
A20: Proposed Dividends | B20: =sofp!B44 -> 0 | C20: =sofp!C44 -> 0 | D20: =sofp!D44 -> 0 | E20: =sofp!E44 -> 0 | F20: =sofp!F44 -> 0 | G20: =sofp!G44 -> 0 | H20: =sofp!H44 -> 0 | I20: =sofp!I44 -> 0 | ... AN20: =sofp!AN44 -> 16871187
A22: Investments | B22: =SUM(B23:B24) -> 218554560 | C22: =SUM(C23:C24) -> 2.1855456e+08 | D22: =SUM(D23:D24) -> 2.2208662e+08 | E22: =SUM(E23:E24) -> 2.2208662e+08 | F22: =SUM(F23:F24) -> 2.2648662e+08 | G22: =SUM(G23:G24) -> 2.2922247e+08 | H22: =SUM(H23:H24) -> 2.3030247e+08 | I22: =SUM(I23:I24) -> 2.3480247e+08 | ... AN22: =SUM(AN23:AN24) -> 488614494
A23: Investment in Coop Bank, Kuscco | B23: =sofp!B10 -> 218530560 | C23: =sofp!C10 -> 2.1855456e+08 | D23: =sofp!D10 -> 2.2208662e+08 | E23: =sofp!E10 -> 2.2208662e+08 | F23: =sofp!F10 -> 2.2648662e+08 | G23: =sofp!G10 -> 2.2922247e+08 | H23: =sofp!H10 -> 2.3030247e+08 | I23: =sofp!I10 -> 2.3480247e+08 | ... AN23: =sofp!AN10 -> 488614494
A24: Equity investments (at Cost) | B24: =sofp!B9 + sofp!B11 -> 24000 | C24: =sofp!C9 + sofp!C11 -> 0 | D24: =sofp!D9 + sofp!D11 -> 0 | E24: =sofp!E9 + sofp!E11 -> 0 | F24: =sofp!F9 + sofp!F11 -> 0 | G24: =sofp!G9 + sofp!G11 -> 0 | H24: =sofp!H9 + sofp!H11 -> 0 | I24: =sofp!I9 + sofp!I11 -> 0 | ... AN24: =sofp!AN9 + sofp!AN11 -> 0
A26: Net Loans & Advances | B26: =B27 - B28 -> 854944397 | C26: =C27 - C28 -> 8.6182725e+08 | D26: =D27 - D28 -> 8.7474837e+08 | E26: =E27 - E28 -> 8.3730951e+08 | F26: =F27 - F28 -> 8.1189392e+08 | G26: =G27 - G28 -> 7.9388107e+08 | H26: =H27 - H28 -> 8.3302891e+08 | I26: =I27 - I28 -> 8.5497448e+08 | ... AN26: =AN27 - AN28 -> 1027056145
A27: Gross Loans & Advances | B27: =sofp!B13 -> 905898148 | C27: =sofp!C13 -> 9.0874961e+08 | D27: =sofp!D13 -> 9.2167073e+08 | E27: =sofp!E13 -> 8.8573187e+08 | F27: =sofp!F13 -> 8.6031628e+08 | G27: =sofp!G13 -> 8.4330343e+08 | H27: =sofp!H13 -> 8.8295127e+08 | I27: =sofp!I13 -> 9.0589684e+08 | ... AN27: =sofp!AN13 -> 1066045543
A28: Allowance for loan loss | B28: =sofp!B14 -> 50953751 | C28: =sofp!C14 -> 46922358 | D28: =sofp!D14 -> 46922358 | E28: =sofp!E14 -> 48422358 | F28: =sofp!F14 -> 48422358 | G28: =sofp!G14 -> 49422358 | H28: =sofp!H14 -> 49922358 | I28: =sofp!I14 -> 50922358 | ... AN28: =sofp!AN14 -> 38989398
A30: Non-Performing loans
A31: Renegotiated loans
A32: Required Loan loss provision
A33: Cash and cash equivalents | B33: =sofp!B3 -> 126161088 | C33: =sofp!C3 -> 1.1746108e+08 | D33: =sofp!D3 -> 1.0266458e+08 | E33: =sofp!E3 -> 1.8121047e+08 | F33: =sofp!F3 -> 1.7031862e+08 | G33: =sofp!G3 -> 1.4838293e+08 | H33: =sofp!H3 -> 1.3151115e+08 | I33: =sofp!I3 -> 1.4864861e+08 | ... AN33: =sofp!AN3 -> 150386392
A35: Non-Earning Assets | B35: =sofp!B19 + sofp!B6 -> 402783836 | C35: =sofp!C19 + sofp!C6 -> 4.1135568e+08 | D35: =sofp!D19 + sofp!D6 -> 4.211053e+08 | E35: =sofp!E19 + sofp!E6 -> 4.2658826e+08 | F35: =sofp!F19 + sofp!F6 -> 430759398 | G35: =sofp!G19 + sofp!G6 -> 4.3013963e+08 | H35: =sofp!H19 + sofp!H6 -> 4.403869e+08 | I35: =sofp!I19 + sofp!I6 -> 4.3386527e+08 | ... AN35: =sofp!AN19 + sofp!AN6 -> 543719646
A36: Property and Equipment | B36: =sofp!B21 -> 45628545 | C36: =sofp!C21 -> 51693626 | D36: =sofp!D21 -> 54745071 | E36: =sofp!E21 -> 54289591 | F36: =sofp!F21 -> 55428321 | G36: =sofp!G21 -> 55467768 | H36: =sofp!H21 -> 55324242 | I36: =sofp!I21 -> 54805889 | ... AN36: =sofp!AN21 -> 112903194
A37: Land and Building
A39: Turnover | B39: =SUM(B40:B42) -> 256532840 | C39: =SUM(C40:C42) -> 16521722 | D39: =SUM(D40:D42) -> 19232980 | E39: =SUM(E40:E42) -> 50088742 | F39: =SUM(F40:F42) -> 78736160 | G39: =SUM(G40:G42) -> 94240710 | H39: =SUM(H40:H42) -> 1.1527639e+08 | I39: =SUM(I40:I42) -> 1.5103701e+08 | ... AN39: =SUM(AN40:AN42) -> 354693313
A40: Loan Interest | B40: =soci!B5 -> 176875846 | C40: =soci!C5 -> 13021470 | D40: =soci!D5 -> 13138377 | E40: =soci!E5 -> 41284261 | F40: =soci!F5 -> 57630156 | G40: =soci!G5 -> 71135398 | H40: =soci!H5 -> 85709724 | I40: =soci!I5 -> 1.1447714e+08 | ... AN40: =soci!AN5 -> 228517048
A41: Income from Investments | B41: =soci!B7 -> 22698489 | C41: =soci!C7 -> 0 | D41: =soci!D7 -> 500248.06 | E41: =soci!E7 -> 500248.06 | F41: =soci!F7 -> 11924455 | G41: =soci!G7 -> 12453771 | H41: =soci!H7 -> 13441115 | I41: =soci!I7 -> 13448154 | ... AN41: =soci!AN7 -> 38211690
A42: Fees & Commissions | B42: =soci!B6 -> 56958505 | C42: =soci!C6 -> 3500252.2 | D42: =soci!D6 -> 5594354.9 | E42: =soci!E6 -> 8304232.4 | F42: =soci!F6 -> 9181548.5 | G42: =soci!G6 -> 10651541 | H42: =soci!H6 -> 16125550 | I42: =soci!I6 -> 23111719 | ... AN42: =soci!AN6 -> 87964575
A43: Average yield on loans | B43: =B40/B27 -> 0.19524915 | C43: =C40/C27 -> 0.014328996 | D43: =D40/D27 -> 0.014254957 | E43: =E40/E27 -> 0.046610337 | F43: =F40/F27 -> 0.066987174 | G43: =G40/G27 -> 0.084353265 | H43: =H40/H27 -> 0.097071862 | I43: =I40/I27 -> 0.12636885 | ... AN43: =AN40/AN27 -> 0.21435955
A45: Financial and operating Costs
A46: Interest expense on deposits | B46: =soci!B13 + soci!B16 -> 94088686 | C46: =soci!C13 + soci!C16 -> 2178181.8 | D46: =soci!D13 + soci!D16 -> 3769858.5 | E46: =soci!E13 + soci!E16 -> 4884587.5 | F46: =soci!F13 + soci!F16 -> 6671582.6 | G46: =soci!G13 + soci!G16 -> 9038281.2 | H46: =soci!H13 + soci!H16 -> 10426468 | I46: =soci!I13 + soci!I16 -> 14501672 | ... AN46: =soci!AN13 + soci!AN16 -> 99669373
A47: Dividend expense on share capital | B47: =soci!B15 -> 0 | C47: =soci!C15 -> 0 | D47: =soci!D15 -> 0 | E47: =soci!E15 -> 0 | F47: =soci!F15 -> 0 | G47: =soci!G15 -> 0 | H47: =soci!H15 -> 0 | I47: =soci!I15 -> 0 | ... AN47: =soci!AN15 -> 21645593
A48: Interest expense on borrowed funds | B48: =soci!B14 -> 7666503 | C48: =soci!C14 -> 510226 | D48: =soci!D14 -> 2112695 | E48: =soci!E14 -> 2113895 | F48: =soci!F14 -> 2284199.4 | G48: =soci!G14 -> 4555171.1 | H48: =soci!H14 -> 5428802.7 | I48: =soci!I14 -> 18955021 | ... AN48: =soci!AN14 -> 23469805
...

Sheet caels
A1: TRANS-NATIONAL TIMES SACCO SOCIETY | C1: Audited 2019 | D1: 43831 | E1: 43862 | F1: 43891 | G1: 43922 | H1: 43952 | I1: 43983 | J1: 44044 | K1: 44075 | L1: 44105 | M1: 44136 | N1: 44166 | O1: Audited 2020 | P1: 44197 | Q1: 44228 | R1: 44256 | S1: 44287 | T1: 44317 | U1: 44348 | V1: 44378 | W1: 44409 | X1: 44440 | Y1: 44470 | Z1: 44501 | AA1: 44531 | AB1: Audited 2021 | AC1: 44562 | AD1: 44593 | AE1: 44621 | AF1: 44652 | AG1: 44682 | AH1: 44713 | AI1: 44743 | AJ1: 44774 | AK1: 44805 | AL1: 44835 | AM1: 44866 | AN1: 44896 | AO1: Audited 2022
A2: CAPITAL ADEQUACY
A3: Core Capital | B3: > Kshs. 10 Million | C3: =financials!B11 -> 237956727 | D3: =financials!C11 -> 2.3265076e+08 | E3: =financials!D11 -> 225906148 | F3: =financials!E11 -> 2.4498415e+08 | G3: =financials!F11 -> 2.5932114e+08 | H3: =financials!G11 -> 2.5944062e+08 | I3: =financials!H11 -> 2.7341215e+08 | J3: =financials!I11 -> 2.7789644e+08 | ... AO3: =financials!AN11 -> 341647076
A4: Core Capital to Total Assets | B4: Min. 10% | C4: =financials!B11 /financials!B3 -> 0.14846846 | D4: =financials!C11 /financials!C3 -> 0.14457554 | E4: =financials!D11 /financials!D3 -> 0.13939619 | F4: =financials!E11 /financials!E3 -> 0.14694392 | G4: =financials!F11 /financials!F3 -> 0.15817486 | H4: =financials!G11 /financials!G3 -> 0.16198576 | I4: =financials!H11 /financials!H3 -> 0.16720109 | J4: =financials!I11 /financials!I3 -> 0.1661771 | ... AO4: =financials!AN11 /financials!AN3 -> 0.15460706
A5: Core Capital to Total Deposits | B5: Min. 8% | C5: =financials!B11 /financials!B4 -> 0.23239405 | D5: =financials!C11 /financials!C4 -> 0.22728986 | E5: =financials!D11 /financials!D4 -> 0.22442193 | F5: =financials!E11 /financials!E4 -> 0.2368235 | G5: =financials!F11 /financials!F4 -> 0.23709048 | H5: =financials!G11 /financials!G4 -> 0.24327943 | I5: =financials!H11 /financials!H4 -> 0.25391868 | J5: =financials!I11 /financials!I4 -> 0.25349246 | ... AO5: =financials!AN11 /financials!AN4 -> 0.256396
A6: Institutional Capital to Total Assets | B6: Min 8% | C6: =financials!B12/sofp!B25 -> 0.089793713 | D6: =financials!C12/sofp!C25 -> 0.08468525 | E6: =financials!D12/sofp!D25 -> 0.07829167 | F6: =financials!E12/sofp!E25 -> 0.086004441 | G6: =financials!F12/sofp!F25 -> 0.09492479 | H6: =financials!G12/sofp!G25 -> 0.095854422 | I6: =financials!H12/sofp!H25 -> 0.10106029 | J6: =financials!I12/sofp!I25 -> 0.09880487 | ... AO6: =financials!AN12/sofp!AN25 -> 0.085201644
A7: ASSET QUALITY
A8: A/LNPL30
A9: NPL30
A10: EARNINGS
A11: ROA | C11: =soci!B33 /sofp!B25 -> 0.014408452 | D11: =soci!C33 /sofp!C25 -> 0.0019385495 | E11: =soci!D33 /sofp!D25 -> -0.0046491515 | F11: =soci!E33 /sofp!E25 -> 0.0038603133 | G11: =soci!F33 /sofp!F25 -> 0.0098754605 | H11: =soci!G33 /sofp!G25 -> 0.0077844202 | I11: =soci!H33 /sofp!H25 -> 0.014214386 | J11: =soci!I33 /sofp!I25 -> 0.011619856 | ... AO11: =soci!AN33 /sofp!AN25 -> 0.014215887
A12: Cost Income Ratio | C12: =soci!B23 /sofp!B19 -> 2.6578651 | D12: =soci!C23 /sofp!C19 -> 0.026045108 | E12: =soci!D23 /sofp!D19 -> 0.049595348 | F12: =soci!E23 /sofp!E19 -> 0.082408185 | G12: =soci!F23 /sofp!F19 -> 0.1209259 | H12: =soci!G23 /sofp!G19 -> 0.1526935 | I12: =soci!H23 /sofp!H19 -> 0.16616602 | J12: =soci!I23 /sofp!I19 -> 0.21699949 | ... AO12: =soci!AN23 /sofp!AN19 -> 0.32828427
A13: Operating Expense Ratio | C13: =(soci!B12 + soci!B23) / ((sofp!B25 + sofp!C25)/2) -> 0.14535746 | D13: =(soci!C12 + soci!C23) / ((sofp!C25 + sofp!D25)/2) -> 0.0082990878 | E13: =(soci!D12 + soci!D23) / ((sofp!D25 + sofp!E25)/2) -> 0.016282876 | F13: =(soci!E12 + soci!E23) / ((sofp!E25 + sofp!F25)/2) -> 0.025495776 | G13: =(soci!F12 + soci!F23) / ((sofp!F25 + sofp!G25)/2) -> 0.037669952 | H13: =(soci!G12 + soci!G23) / ((sofp!G25 + sofp!H25)/2) -> 0.048981475 | I13: =(soci!H12 + soci!H23) / ((sofp!H25 + sofp!I25)/2) -> 0.05383647 | J13: =(soci!I12 + soci!I23) / ((sofp!I25 + sofp!K25)/2) -> 0.073520373 | K13: =(soci!J12 + soci!J23) / ((sofp!J25 + sofp!L25)/2) -> 0.077873987 | L13: =(soci!K12 + soci!K23) / ((sofp!K25 + sofp!M25)/2) -> 0.088033321 | M13: =(soci!L12 + soci!L23) / ((sofp!L25 + sofp!N25)/2) -> 0.093757831 | N13: =(soci!M12 + soci!M23) / ((sofp!M25 + sofp!O25)/2) -> 0.1150938 | O13: =(soci!N12 + soci!N23) / ((sofp!N25 + sofp!P25)/2) -> 0.069196197 | P13: =(soci!O12 + soci!O23) / ((sofp!O25 + sofp!Q25)/2) -> 0.0010342266 | Q13: =(soci!P12 + soci!P23) / ((sofp!P25 + sofp!R25)/2) -> 0.0044008382 | ... AO13: =(soci!AN12 + soci!AN23) / ((sofp!AN25 + sofp!AP25)/2) -> 0.29259009
A14: LIQUIDITY
A15: Min Liquidity Ratio | B15: Min 15% | C15: =financials!B33/(financials!B8+financials!B6) -> 0.12239646 | D15: =financials!C33/(financials!C8+financials!C6) -> 0.11365356 | E15: =financials!D33/(financials!D8+financials!D6) -> 0.10217092 | F15: =financials!E33/(financials!E8+financials!E6) -> 0.17579141 | G15: =financials!F33/(financials!F8+financials!F6) -> 0.16649637 | H15: =financials!G33/(financials!G8+financials!G6) -> 0.15038754 | I15: =financials!H33/(financials!H8+financials!H6) -> 0.13354841 | J15: =financials!I33/(financials!I8+financials!I6) -> 0.14852175 | ... AO15: =financials!AN33/(financials!AN8+financials!AN6) -> 0.12676055
A16: T/LIQ Ratio | C16: =financials!B33/financials!B3 -> 0.07871575 | D16: =financials!C33/financials!C3 -> 0.072993525 | E16: =financials!D33/financials!D3 -> 0.063349545 | F16: =financials!E33/financials!E3 -> 0.10869184 | G16: =financials!F33/financials!F3 -> 0.10388712 | H16: =financials!G33/financials!G3 -> 0.092645173 | I16: =financials!H33/financials!H3 -> 0.080423671 | J16: =financials!I33/financials!I3 -> 0.088889209 | ... AO16: =financials!AN33/financials!AN3 -> 0.068055018
A17: External Borrowing to TA Ratio | B17: Max 25% | C17: =sofp!B35 / sofp!B25 -> 0.08552284 | D17: =sofp!C35 / sofp!C25 -> 0.082722818 | E17: =sofp!D35 / sofp!D25 -> 0.10556325 | F17: =sofp!E35 / sofp!E25 -> 0.10261327 | G17: =sofp!F35 / sofp!F25 -> 0.083891968 | H17: =sofp!G35 / sofp!G25 -> 0.081121385 | I17: =sofp!H35 / sofp!H25 -> 0.088829025 | J17: =sofp!I35 / sofp!I25 -> 0.095099272 | ... AO17: =sofp!AN35 / sofp!AN25 -> 0.15481785
A18: Liquid Assets to TA Ratio | C18: =financials!B33 / financials!B3 -> 0.07871575 | D18: =financials!C33 / financials!C3 -> 0.072993525 | E18: =financials!D33 / financials!D3 -> 0.063349545 | F18: =financials!E33 / financials!E3 -> 0.10869184 | G18: =financials!F33 / financials!F3 -> 0.10388712 | H18: =financials!G33 / financials!G3 -> 0.092645173 | I18: =financials!H33 / financials!H3 -> 0.080423671 | J18: =financials!I33 / financials!I3 -> 0.088889209 | ... AO18: =financials!AN33 / financials!AN3 -> 0.068055018
A19: STRUCTURE
A20: Non-Earning to TA Ratio | B20: Max 10% | C20: =financials!B35 / financials!B3 -> 0.25130912 | D20: =financials!C35 / financials!C3 -> 0.25562767 | E20: =financials!D35 / financials!D3 -> 0.25984452 | F20: =financials!E35 / financials!E3 -> 0.25587187 | G20: =financials!F35 / financials!F3 -> 0.26274491 | H20: =financials!G35 / financials!G3 -> 0.26856433 | I20: =financials!H35 / financials!H3 -> 0.26931199 | J20: =financials!I35 / financials!I3 -> 0.25944367 | ... AO20: =financials!AN35 / financials!AN3 -> 0.24605185
A21: LB Ratio | B21: Max 5% | C21: =financials!B36 / financials!B3 -> 0.028469041 | D21: =financials!C36 / financials!C3 -> 0.032123833 | E21: =financials!D36 / financials!D3 -> 0.033780641 | F21: =financials!E36 / financials!E3 -> 0.032563435 | G21: =financials!F36 / financials!F3 -> 0.033808919 | H21: =financials!G36 / financials!G3 -> 0.034632158 | I21: =financials!H36 / financials!H3 -> 0.033832709 | J21: =financials!I36 / financials!I3 -> 0.032772941 | ... AO21: =financials!AN36 / financials!AN3 -> 0.051092581
A22: Investments to Deposit Ratio | B22: Max 5% | C22: =financials!B22 / financials!B4 -> 0.21344545 | D22: =financials!C22 / financials!C4 -> 0.21351848 | E22: =financials!D22 / financials!D4 -> 0.22062749 | F22: =financials!E22 / financials!E4 -> 0.2146887 | G22: =financials!F22 / financials!F4 -> 0.20707074 | H22: =financials!G22 / financials!G4 -> 0.21494364 | I22: =financials!H22 / financials!H4 -> 0.21388259 | J22: =financials!I22 / financials!I4 -> 0.21418286 | ... AO22: =financials!AN22 / financials!AN4 -> 0.36669069
A23: Investments to Core Capital Ratio | B23: Max 40% | C23: =financials!B22 / C3 -> 0.91846346 | D23: =financials!C22 / D3 -> 0.93941048 | E23: =financials!D22 / E3 -> 0.9830924 | F23: =financials!E22 / F3 -> 0.90653462 | G23: =financials!F22 / G3 -> 0.87338279 | H23: =financials!G22 / H3 -> 0.88352574 | I23: =financials!H22 / I3 -> 0.84232711 | J23: =financials!I22 / J3 -> 0.84492795 | ... AO23: =financials!AN22 / AO3 -> 1.4301732
A24: Gross loans/TA | C24: =financials!B27 / financials!B3 -> 0.56521748 | D24: =financials!C27 / financials!C3 -> 0.56472186 | E24: =financials!D27 / financials!D3 -> 0.5687202 | F24: =financials!E27 / financials!E3 -> 0.53127075 | G24: =financials!F27 / financials!F3 -> 0.52475634 | H24: =financials!G27 / financials!G3 -> 0.52652952 | I24: =financials!H27 / financials!H3 -> 0.53995559 | J24: =financials!I27 / financials!I3 -> 0.5417101 | ... AO24: =financials!AN27 / financials!AN3 -> 0.4824223
A25: FUNDING MIX
A26: Total Deposits/Total Assets | C26: =financials!B4 / financials!B3 -> 0.63886513 | D26: =financials!C4 / financials!C3 -> 0.63608443 | E26: =financials!D4 / financials!D3 -> 0.62113445 | F26: =financials!E4 / financials!E3 -> 0.62047864 | G26: =financials!F4 / financials!F3 -> 0.6671498 | H26: =financials!G4 / financials!G3 -> 0.6658424 | I26: =financials!H4 / financials!H3 -> 0.65848285 | J26: =financials!I4 / financials!I3 -> 0.65555046 | ... AO26: =financials!AN4 / financials!AN3 -> 0.60300106
A27: BOSA Deposits/Total Assets | C27: =financials!B5 / financials!B3 -> 0.490036 | D27: =financials!C5 / financials!C3 -> 0.49130324 | E27: =financials!D5 / financials!D3 -> 0.49193228 | F27: =financials!E5 / financials!E3 -> 0.48352328 | G27: =financials!F5 / financials!F3 -> 0.50184284 | H27: =financials!G5 / financials!G3 -> 0.51710343 | I27: =financials!H5 / financials!H3 -> 0.51089133 | J27: =financials!I5 / financials!I3 -> 0.50360589 | ... AO27: =financials!AN5 / financials!AN3 -> 0.45873392
A28: FOSA Deposits/Total Assets | C28: =financials!B6 / financials!B3 -> 0.57907882 | D28: =financials!C6 / financials!C3 -> 0.57431969 | E28: =financials!D6 / financials!D3 -> 0.55433643 | F28: =financials!E6 / financials!E3 -> 0.55463737 | G28: =financials!F6 / financials!F3 -> 0.6006001 | H28: =financials!G6 / financials!G3 -> 0.59400823 | I28: =financials!H6 / financials!H3 -> 0.58431668 | J28: =financials!I6 / financials!I3 -> 0.58141916 | ... AO28: =financials!AN6 / financials!AN3 -> 0.50696135
A29: GROWTH RATIOS
A30: Total Assets | C30: =(financials!C3 / financials!B3) - 1 -> 0.0040280564 | D30: =(financials!D3 / financials!C3) - 1 -> 0.0070881878 | E30: =(financials!E3 / financials!D3) - 1 -> 0.028748521 | F30: =(financials!F3 / financials!E3) - 1 -> -0.01663651 | G30: =(financials!G3 / financials!F3) - 1 -> -0.023076189 | H30: =(financials!H3 / financials!G3) - 1 -> 0.020980761 | I30: =(financials!I3 / financials!H3) - 1 -> 0.02266434 | J30: =(financials!K3 / financials!I3) - 1 -> 0.07576879 | K30: =(financials!L3 / financials!J3) - 1 -> -0.052685145 | L30: =(financials!M3 / financials!K3) - 1 -> 0.02470865 | M30: =(financials!N3 / financials!L3) - 1 -> 0.069071096 | N30: =(financials!O3 / financials!M3) - 1 -> 0.036496652 | O30: =(financials!P3 / financials!N3) - 1 -> -0.012874789 | P30: =(financials!Q3 / financials!O3) - 1 -> 0.006312842 | Q30: =(financials!R3 / financials!P3) - 1 -> 0.024873856 | ... AO30: =(financials!AP3 / financials!AN3) - 1 -> -1
A31: Total Deposits | C31: =(financials!C4 / financials!B4) - 1 -> -0.0003420399 | D31: =(financials!D4 / financials!C4) - 1 -> -0.01658154 | E31: =(financials!E4 / financials!D4) - 1 -> 0.027662333 | F31: =(financials!F4 / financials!E4) - 1 -> 0.057330123 | G31: =(financials!G4 / financials!F4) - 1 -> -0.024990646 | H31: =(financials!H4 / financials!G4) - 1 -> 0.0096958601 | I31: =(financials!I4 / financials!H4) - 1 -> 0.018110167 | J31: =(financials!K4 / financials!I4) - 1 -> 0.01243372 | K31: =(financials!L4 / financials!J4) - 1 -> 0.016516323 | L31: =(financials!M4 / financials!K4) - 1 -> 0.034819224 | M31: =(financials!N4 / financials!L4) - 1 -> 0.032494038 | N31: =(financials!O4 / financials!M4) - 1 -> -0.026083763 | O31: =(financials!P4 / financials!N4) - 1 -> -0.022345859 | P31: =(financials!Q4 / financials!O4) - 1 -> 0.011209447 | Q31: =(financials!R4 / financials!P4) - 1 -> 0.020907725 | ... AO31: =(financials!AP4 / financials!AN4) - 1 -> -1
A32: BOSA Deposits | C32: =(financials!C5 / financials!B5) - 1 -> 0.0066244791 | D32: =(financials!D5 / financials!C5) - 1 -> 0.0083776271 | E32: =(financials!E5 / financials!D5) - 1 -> 0.011163279 | F32: =(financials!F5 / financials!E5) - 1 -> 0.020620819 | G32: =(financials!G5 / financials!F5) - 1 -> 0.0066311772 | H32: =(financials!H5 / financials!G5) - 1 -> 0.0087154496 | I32: =(financials!I5 / financials!H5) - 1 -> 0.0080808919 | J32: =(financials!K5 / financials!I5) - 1 -> 0.0019850038 | K32: =(financials!L5 / financials!J5) - 1 -> 0.016407319 | L32: =(financials!M5 / financials!K5) - 1 -> 0.01621313 | M32: =(financials!N5 / financials!L5) - 1 -> 0.00821575 | N32: =(financials!O5 / financials!M5) - 1 -> 0.0040682176 | O32: =(financials!P5 / financials!N5) - 1 -> 0.011719091 | P32: =(financials!Q5 / financials!O5) - 1 -> 0.012702204 | Q32: =(financials!R5 / financials!P5) - 1 -> 0.014605652 | ... AO32: =(financials!AP5 / financials!AN5) - 1 -> -1
