Workbook

Sheet Evolutive SFP
B3: 2010 Audited | C3: 2020 Audited | D3: 44197 | E3: 44228 | F3: 44256 | G3: 44287 | H3: 44317 | I3: 44348 | J3: 44378 | K3: 44409 | L3: 44440 | M3: 44470 | N3: 44501 | O3: 44531 | P3: Audited 2021 | Q3: 44562 | R3: 44593 | S3: 44621 | T3: 44652 | U3: 44682 | V3: 44713 | W3: 44743 | X3: 44774 | Y3: 44805 | Z3: 44835 | AA3: 44866 | AB3: 44896 | AC3: Audited 2022 | AD3: 44927 | AE3: 44958 | AF3: 44986 | AG3: 45017 | AH3: 45047 | AI3: 45078
A4: Cash & cash Equivalent | B4: =SUM(B5:B6) -> 19363224 | C4: =SUM(C5:C6) -> 80999768 | D4: =SUM(D5:D6) -> 77138716 | E4: =SUM(E5:E6) -> 73684628 | F4: =SUM(F5:F6) -> 74121415 | G4: =SUM(G5:G6) -> 71189444 | H4: =SUM(H5:H6) -> 70304355 | I4: =SUM(I5:I6) -> 71367924 | ... AI4: =SUM(AI5:AI6) -> 0
A5: Cash In Hand | B5: 19363224 | C5: 4035251 | D5: 3995970.5 | E5: 3766598.5 | F5: 9326300.6 | G5: 6523468.4 | H5: 6020580.6 | I5: 4661148.9 | J5: 4172915.1 | K5: 5899898 | L5: 4658033 | M5: 6059450 | N5: 8118262 | O5: 11625492 | P5: 10261482 | Q5: 10176526 | R5: 11570375 | S5: 4777669.3 | T5: 9598330.1 | U5: 9337814.5 | V5: 9646218 | W5: 6587404.5 | X5: 5381194.4 | Y5: 5547341 | Z5: 12800686 | AA5: 10878142 | AB5: 12090099 | AC5: 12090099 | AD5: 5598184.4 | AE5: 6939336.4 | AF5: 7836364.8 | AG5: 11271977 | AH5: 10975510
A6: Cash at Bank | C6: =80999768-C5 -> 76964517 | D6: 73142746 | E6: 69918030 | F6: 64795114 | G6: 64665975 | H6: 64283775 | I6: 66706775 | J6: 70796777 | K6: 68747673 | L6: 69847685 | M6: 76817871 | N6: 75811108 | O6: 72390306 | P6: =84096060-P5 -> 73834578 | Q6: 75499065 | R6: 78207876 | S6: 79393868 | T6: 69151232 | U6: 75944679 | V6: 72662792 | W6: 1.1045243e+08 | X6: 95160120 | Y6: 91045937 | Z6: 85844011 | AA6: 92890471 | AB6: 1.0171478e+08 | AC6: =114000530-AC5 -> 101910431 | AD6: 1.1005059e+08 | AE6: 1.0399697e+08 | AF6: 99499404 | AG6: 86380711 | AH6: 85059273
A7: Prepayment and Sundry | B7: 13400392 | C7: 2333374 | D7: 633118.27 | E7: 44413.73 | F7: 445154.27 | G7: 331738.27 | H7: 229721.27 | I7: 444301.27 | J7: 546243.27 | K7: 373441.27 | L7: 930490.27 | M7: 911843.27 | N7: 524693.27 | O7: 0 | P7: 1268268 | Q7: 786800.57 | R7: 462657.57 | S7: 558673.57 | T7: 399543.57 | U7: 334323.57 | V7: 1110531.6 | W7: 239495.37 | X7: 583688.37 | Y7: 0 | Z7: 1308291.4 | AA7: 307206.37 | AB7: 435016.37 | AC7: 1714134 | AD7: 986516.37 | AE7: 871836.37 | AF7: 0 | AG7: 710789.37 | AH7: 283876.51
A8: Financial Investment | B8: =SUM(B9:B13) -> 472260 | C8: =SUM(C9:C13) -> 3322320 | D8: =SUM(D9:D13) -> 4219411.4 | E8: =SUM(E9:E13) -> 3322320.4 | F8: =SUM(F9:F13) -> 3322320.4 | G8: =SUM(G9:G13) -> 3322320.4 | H8: =SUM(H9:H13) -> 3322320.4 | I8: =SUM(I9:I13) -> 3322320.4 | ... AI8: =SUM(AI9:AI13) -> 0
A9: Government Securities - Treasury Bills/bonds, | D9: 0 | E9: 0 | F9: 0 | G9: 0 | H9: 0 | I9: 0 | J9: 0 | K9: 0 | L9: 0 | M9: 0 | N9: 0 | O9: 0 | Q9: 0 | R9: 0 | S9: 0 | T9: 0 | U9: 0 | V9: 0 | W9: 0 | X9: 0 | Y9: 0 | Z9: 0 | AA9: 0 | AB9: 0 | AD9: 0 | AE9: 0 | AF9: 0 | AG9: 0 | AH9: 0
A10: Other Securities - Commercial papers/Bonds | D10: 0 | E10: 0 | F10: 0 | G10: 0 | H10: 0 | I10: 0 | J10: 0 | K10: 0 | L10: 0 | M10: 0 | N10: 0 | O10: 0 | Q10: 0 | R10: 0 | S10: 0 | T10: 0 | U10: 0 | V10: 0 | W10: 0 | X10: 0 | Y10: 0 | Z10: 0 | AA10: 0 | AB10: 0 | AD10: 0 | AE10: 0 | AF10: 0 | AG10: 0 | AH10: 0
A11: Balances in NACCOS (E.g Jungu Kuu, ESS, Savings,Money Market,Coop FD, CFP) | C11: =3322320-C13 -> 3167735 | D11: 0 | E11: 0 | F11: 0 | G11: 0 | H11: 0 | I11: 0 | J11: 0 | K11: 0 | L11: 0 | M11: 0 | N11: 0 | O11: 0 | Q11: 0 | R11: 0 | S11: 0 | T11: 0 | U11: 0 | V11: 0 | W11: 0 | X11: 0 | Y11: 0 | Z11: 0 | AA11: 0 | AB11: 0 | AD11: 0 | AE11: 0 | AF11: 0 | AG11: 0 | AH11: 0
A12: Equity Investments in NACCOs(Shares in- CIC, KUSCCO, COOP BANK,CAK, KERUSSU) | P12: =3460532-P13 -> 3297347 | AC12: =3460532-AC13 -> 3297347 | AD12: 3460532.4 | AE12: 3460532.4 | AF12: 3460532.4 | AG12: 3460532.4 | AH12: 3460532.4
A13: Equity Investments in companies - shares/stocks | B13: 472260 | C13: 154585 | D13: 4219411.4 | E13: 3322320.4 | F13: 3322320.4 | G13: 3322320.4 | H13: 3322320.4 | I13: 3322320.4 | J13: 3322320.4 | K13: 3322320.4 | L13: 3322320.4 | M13: 3322320 | N13: 3322320.4 | O13: 3322320.4 | P13: 163185 | Q13: 3322320.4 | R13: 3322320.4 | S13: 3322320.4 | T13: 3322320.4 | U13: 3322320.4 | V13: 3322320.4 | W13: 3322320.4 | X13: 3322320 | Y13: 3322320.4 | Z13: 3322320.4 | AA13: 3322320.4 | AB13: 3322320.4 | AC13: 163185
A14: Net Loan Portfolio | B14: =B15-B16 -> 112905266 | C14: =C15-C16 -> 94715902 | D14: =D15-D16 -> 99526768 | E14: =E15-E16 -> 1.0157231e+08 | F14: =F15-F16 -> 1.0014554e+08 | G14: =G15-G16 -> 1.0108718e+08 | H14: =H15-H16 -> 1.0268952e+08 | I14: =I15-I16 -> 1.0076412e+08 | ... AI14: =AI15-AI16 -> 0
A15: Gross Loan Portfolio | B15: 112905266 | C15: 117738087 | D15: 1.2341506e+08 | E15: 1.2614517e+08 | F15: 1.2572372e+08 | G15: 1.2647362e+08 | H15: 1.2571171e+08 | I15: 1.2592833e+08 | J15: 1.2270415e+08 | K15: 1.2228531e+08 | L15: 1.2298995e+08 | M15: 1.2060145e+08 | N15: 1.2367159e+08 | O15: 1.2297216e+08 | P15: 122972158 | Q15: 1.2169113e+08 | R15: 1.2135364e+08 | S15: 1.2743106e+08 | T15: 1.2994009e+08 | U15: 1.2848417e+08 | V15: 1.2840855e+08 | W15: 1.1615697e+08 | X15: 1.2939291e+08 | Y15: 1.3083972e+08 | Z15: 1.2950216e+08 | AA15: 128305935 | AB15: 1.2334043e+08 | AC15: 123584731 | AD15: 1.248453e+08 | AE15: 1.2811169e+08 | AF15: 1.3037113e+08 | AG15: 1.306111e+08 | AH15: 1.3063519e+08
A16: Allowance For Loan Loss | C16: 23022185 | D16: 23888296 | E16: 24572853 | F16: 25578182 | G16: 25386444 | H16: 23022185 | I16: 25164216 | J16: 25184107 | K16: 26026638 | L16: 25773596 | M16: 25381900 | N16: 25292796 | O16: 21966025 | P16: 21966025 | Q16: 21966025 | R16: 21966025 | S16: 24181711 | T16: 24174931 | U16: 23481600 | V16: 23472632 | W16: 22494308 | X16: 23135805 | Y16: 22759629 | Z16: 22766749 | AA16: 22547845 | AB16: 20829565 | AC16: 20874830 | AD16: 20834667 | AE16: 21275292 | AF16: 21566058 | AG16: 21739949 | AH16: 21518105
A17: Accounts Recievables | B17: =SUM(B18:B20) -> 0 | C17: =SUM(C18:C20) -> 0 | D17: =SUM(D18:D20) -> 0 | E17: =SUM(E18:E20) -> 0 | F17: =SUM(F18:F20) -> 0 | G17: =SUM(G18:G20) -> 0 | H17: =SUM(H18:H20) -> 0 | I17: =SUM(I18:I20) -> 0 | ... AI17: =SUM(AI18:AI20) -> 0
A18: Tax Recoverable | D18: 0 | E18: 0 | F18: 0 | G18: 0 | H18: 0 | I18: 0 | J18: 0 | K18: 0 | L18: 0 | M18: 0 | N18: 0 | O18: 0 | Q18: 0 | R18: 0 | S18: 0 | T18: 0 | U18: 0 | V18: 0 | W18: 0 | X18: 0 | Y18: 0 | Z18: 0 | AA18: 0 | AB18: 0 | AD18: 0 | AE18: 0 | AF18: 0 | AG18: 0 | AH18: 0
A19: Deffered Tax Assets | D19: 0 | E19: 0 | F19: 0 | G19: 0 | H19: 0 | I19: 0 | J19: 0 | K19: 0 | L19: 0 | M19: 0 | N19: 0 | O19: 0 | Q19: 0 | R19: 0 | S19: 0 | T19: 0 | U19: 0 | V19: 0 | W19: 0 | X19: 0 | Y19: 0 | Z19: 0 | AA19: 0 | AB19: 0 | AD19: 0 | AE19: 0 | AF19: 0 | AG19: 0 | AH19: 0
A20: Retirement Benefit Assets | D20: 0 | E20: 0 | F20: 0 | G20: 0 | H20: 0 | I20: 0 | J20: 0 | K20: 0 | L20: 0 | M20: 0 | N20: 0 | O20: 0 | Q20: 0 | R20: 0 | S20: 0 | T20: 0 | U20: 0 | V20: 0 | W20: 0 | X20: 0 | Y20: 0 | Z20: 0 | AA20: 0 | AB20: 0 | AD20: 0 | AE20: 0 | AF20: 0 | AG20: 0 | AH20: 0
A21: Property&Equipments&Other Assets | B21: =SUM(B22:B26) -> 4874587 | C21: =SUM(C22:C26) -> 14963299 | D21: =SUM(D22:D26) -> 15620229 | E21: =SUM(E22:E26) -> 16690034 | F21: =SUM(F22:F26) -> 16705739 | G21: =SUM(G22:G26) -> 16705180 | H21: =SUM(H22:H26) -> 16734039 | I21: =SUM(I22:I26) -> 15635767 | ... AI21: =SUM(AI22:AI26) -> 0
A22: Investment Properties | D22: 0 | E22: 0 | F22: 0 | G22: 0 | H22: 0 | I22: 0 | J22: 0 | K22: 0 | L22: 0 | M22: 0 | N22: 0 | O22: 0 | Q22: 0 | R22: 0 | S22: 0 | T22: 0 | U22: 0 | V22: 0 | W22: 0 | X22: 0 | Y22: 0 | Z22: 0 | AA22: 0 | AB22: 0 | AD22: 0 | AE22: 0 | AF22: 0 | AG22: 0 | AH22: 0
A23: Property and Equipment | B23: 4123114 | C23: 13159426 | D23: 13635196 | E23: 13635196 | F23: 13660301 | G23: 13666801 | H23: 13701801 | I23: 12851347 | J23: 12886347 | K23: 12953447 | L23: 12953447 | M23: 12963347 | N23: 12988547 | O23: 12135656 | P23: 12118019 | Q23: 12119458 | R23: 12119458 | S23: 12123882 | T23: 12124282 | U23: 12180282 | V23: 11499364 | W23: 11629864 | X23: 11474348 | Y23: 11961238 | Z23: 11961238 | AA23: 11961238 | AB23: 11482673 | AC23: 11476711 | AD23: 11478269 | AE23: 11478269 | AF23: 11477413 | AG23: 12373033 | AH23: 11859474
A24: Prepaid Lease Rentals | B24: 0 | D24: 0 | E24: 0 | F24: 0 | G24: 0 | H24: 0 | I24: 0 | J24: 0 | K24: 0 | L24: 0 | M24: 0 | N24: 0 | O24: 0 | Q24: 0 | R24: 0 | S24: 0 | T24: 0 | U24: 0 | V24: 0 | W24: 0 | X24: 0 | Y24: 0 | Z24: 0 | AA24: 0 | AB24: 0 | AD24: 0 | AE24: 0 | AF24: 0 | AG24: 0 | AH24: 0
A25: Intangible Assets | B25: 751473 | C25: 1803873 | D25: 1803872.4 | E25: 1803872.4 | F25: 1803872.4 | G25: 1803872.4 | H25: 1803872.4 | I25: 1503527.7 | J25: 1503527.7 | K25: 1503527.7 | L25: 1503527.7 | M25: 1503527.7 | N25: 1503527.7 | O25: 1203183 | P25: 1203183 | Q25: 1203183 | R25: 1203183 | S25: 1203183 | T25: 1203183 | U25: 1203183 | V25: 1002856 | W25: 1002856 | X25: 936080 | Y25: 936080.42 | Z25: 936080.42 | AA25: 936080.42 | AB25: 802523.03 | AC25: 802523 | AD25: 802523.87 | AE25: 802523.03 | AF25: 802523.03 | AG25: 802523.03 | AH25: 691172.96
A26: Other Assets | D26: 181160 | E26: 1250965 | F26: 1241565.6 | G26: 1234505.8 | H26: 1228365 | I26: 1280892.4 | J26: 1301965 | K26: 1291565 | L26: 1285625.9 | M26: 1274565 | N26: 967957.96 | O26: 1251165 | Q26: 1212565 | R26: 1200908.8 | S26: 1188765 | T26: 1175821 | U26: 1167138.6 | V26: 1255919.6 | W26: 1006868.7 | X26: 1265875.6 | Y26: 1358621.8 | Z26: 1363175.6 | AA26: 1342203.8 | AB26: 1254495.9 | AD26: 1208829.1 | AE26: 1199696 | AF26: 1182335.9 | AG26: 1183935.9 | AH26: 1165136.1
A27: Total Assets | B27: =B21+B17+B14+B8+B7+B4 -> 151015729 | C27: =C21+C17+C14+C8+C7+C4 -> 196334663 | D27: =D21+D17+D14+D8+D7+D4 -> 1.9713824e+08 | E27: =E21+E17+E14+E8+E7+E4 -> 1.9531371e+08 | F27: =F21+F17+F14+F8+F7+F4 -> 1.9474017e+08 | G27: =G21+G17+G14+G8+G7+G4 -> 1.9263586e+08 | H27: =H21+H17+H14+H8+H7+H4 -> 1.9327996e+08 | I27: =I21+I17+I14+I8+I7+I4 -> 1.9153443e+08 | ... AI27: =AI21+AI17+AI14+AI8+AI7+AI4 -> 0
A28: Savings and Deposits | B28: 8112861 | D28: 43388182 | E28: 41878809 | F28: 44019734 | G28: 42339315 | H28: 40289561 | I28: 40213381 | J28: 39423150 | K28: 37586802 | L28: 37772136 | M28: 40771718 | N28: 41579536 | O28: 40688748 | P28: 40687314 | Q28: 40668804 | R28: 42694972 | S28: 40260481 | T28: 41555416 | U28: 45199037 | V28: 42150626 | W28: 60483106 | X28: 55704378 | Y28: 52141570 | Z28: 52428644 | AA28: 53115331 | AB28: 59343782 | AC28: 59343782 | AD28: 60897812 | AE28: 55103067 | AF28: 54896465 | AG28: 49813962 | AH28: 47077439
A29: Short Terrm Deposits | B29: 8350444 | C29: 45172689 | D29: 0 | E29: 0 | F29: 0 | G29: 0 | H29: 0 | I29: 0 | J29: 0 | K29: 0 | L29: 0 | M29: 0 | N29: 0 | O29: 0 | Q29: 0 | R29: 0 | S29: 0 | T29: 0 | U29: 0 | V29: 0 | W29: 0 | X29: 0 | Y29: 0 | Z29: 0 | AA29: 0 | AB29: 0 | AD29: 0 | AE29: 0 | AF29: 0 | AG29: 0 | AH29: 0
A30: Non Withdrawable Deposits | B30: 112140909 | C30: 97747282 | D30: 98068546 | E30: 98848445 | F30: 99652558 | G30: 1.0010073e+08 | H30: 1.0079304e+08 | I30: 1.0131074e+08 | J30: 1.0204955e+08 | K30: 1.0284144e+08 | L30: 1.0298548e+08 | M30: 1.0403389e+08 | N30: 1.0598307e+08 | O30: 1.0382613e+08 | P30: 103826130 | Q30: 1.0423904e+08 | R30: 1.0530178e+08 | S30: 1.0642489e+08 | T30: 1.0641779e+08 | U30: 1.071894e+08 | V30: 107844184 | W30: 1.083984e+08 | X30: 1.0851814e+08 | Y30: 1.0894108e+08 | Z30: 1.0974554e+08 | AA30: 1.1058952e+08 | AB30: 1.1016692e+08 | AC30: 110164921 | AD30: 1.11064e+08 | AE30: 1.1176483e+08 | AF30: 1.1222131e+08 | AG30: 1.1214909e+08 | AH30: 1.1279939e+08
A31: Total Deposit Liabilities | B31: =SUM(B28:B30) -> 128604214 | C31: =SUM(C28:C30) -> 142919971 | D31: =SUM(D28:D30) -> 1.4145673e+08 | E31: =SUM(E28:E30) -> 1.4072725e+08 | F31: =SUM(F28:F30) -> 1.4367229e+08 | G31: =SUM(G28:G30) -> 1.4244005e+08 | H31: =SUM(H28:H30) -> 1.4108261e+08 | I31: =SUM(I28:I30) -> 1.4152412e+08 | ... AI31: =SUM(AI28:AI30) -> 0
A32: Tax Payable | B32: 27231 | C32: 331303 | D32: 331303 | E32: 331303 | F32: 331303 | G32: 331303 | H32: 0 | I32: 0 | J32: 0 | K32: 0 | L32: 0 | M32: 0 | N32: 200 | O32: 0 | P32: 47492 | Q32: 0 | R32: 0 | S32: 47492 | T32: 47492 | U32: 47492 | V32: 0 | W32: 0 | X32: 0 | Y32: 0 | Z32: 0 | AA32: 0 | AB32: 0 | AC32: 320845 | AD32: 0 | AE32: 320844.57 | AF32: 320844.57 | AG32: 1207.57 | AH32: 1207.57
A33: Dividends Payable | B33: 3618123 | C33: 4469416 | D33: 4469416 | E33: 4109416.8 | F33: 178005.53 | G33: 178005.53 | H33: 178005.53 | I33: 178005.53 | J33: 178005.53 | K33: 178005.53 | L33: 178005.53 | M33: 178005.53 | N33: 178005.53 | O33: 178005.53 | P33: 4982212 | Q33: 178005.53 | R33: 178005.53 | S33: 2725690.5 | T33: 239968.88 | U33: 238270.68 | V33: 238270.68 | W33: 234411.68 | X33: 195009.52 | Y33: 190317.68 | Z33: 184179.68 | AA33: 178733.68 | AB33: 178733.68 | AC33: 4492182 | AD33: 178733.68 | AE33: 4492181.4 | AF33: 529802.69 | AG33: 362474.69 | AH33: 222434.69
A34: Deferred Tax Liability | D34: 0 | E34: 0 | F34: 0 | G34: 0 | H34: 0 | I34: 0 | J34: 0 | K34: 0 | L34: 0 | M34: 0 | N34: 0 | O34: 0 | Q34: 0 | R34: 0 | S34: 0 | T34: 0 | U34: 0 | V34: 0 | W34: 0 | X34: 0 | Y34: 0 | Z34: 0 | AA34: 0 | AB34: 0 | AD34: 0 | AE34: 0 | AF34: 0 | AG34: 0 | AH34: 0
A35: Retirement Benefits Liabilty | D35: 0 | E35: 0 | F35: 0 | G35: 0 | H35: 0 | I35: 0 | J35: 0 | K35: 0 | L35: 0 | M35: 0 | N35: 0 | O35: 0 | Q35: 0 | R35: 0 | S35: 0 | T35: 0 | U35: 0 | V35: 0 | W35: 0 | X35: 0 | Y35: 0 | Z35: 0 | AA35: 0 | AB35: 0 | AD35: 0 | AE35: 0 | AF35: 0 | AG35: 0 | AH35: 0
A36: Other Liabilities | B36: 1214920 | C36: 3786965 | D36: 3553292.6 | E36: 4331685.6 | F36: 5115811.3 | G36: 2766231.6 | H36: 2183007.4 | I36: 2274820.4 | J36: 2360998.2 | K36: 2245091.8 | L36: 2262577.7 | M36: 2873146.9 | N36: 2835491.5 | O36: 3479721.9 | P36: 3897607 | Q36: 4250814 | R36: 4300142.7 | S36: 4402849.5 | T36: 3569501.6 | U36: 3392247.9 | V36: 3001895.8 | W36: 2588665.3 | X36: 2945164.6 | Y36: 2768203.4 | Z36: 2691983.5 | AA36: 3301131.6 | AB36: 4289497.7 | AC36: 4525108 | AD36: 3780541.6 | AE36: 4394962 | AF36: 5324401.7 | AG36: 2574064.7 | AH36: 2104728.3
A37: External Borrowings | B37: 2291669 | D37: 0 | E37: 0 | F37: 0 | G37: 0 | H37: 0 | I37: 0 | J37: 0 | K37: 0 | L37: 0 | M37: 0 | N37: 0 | O37: 0 | Q37: 0 | R37: 0 | S37: 0 | T37: 0 | U37: 0 | V37: 0 | W37: 0 | X37: 0 | Y37: 0 | Z37: 0 | AA37: 0 | AB37: 0 | AD37: 0 | AE37: 0 | AF37: 0 | AG37: 0 | AH37: 0
A38: Total Liabilities | B38: =SUM(B31:B37) -> 135756157 | C38: =SUM(C31:C37) -> 151507655 | D38: =SUM(D31:D37) -> 1.4981074e+08 | E38: =SUM(E31:E37) -> 1.4949966e+08 | F38: =SUM(F31:F37) -> 1.4929741e+08 | G38: =SUM(G31:G37) -> 1.4571559e+08 | H38: =SUM(H31:H37) -> 1.4344362e+08 | I38: =SUM(I31:I37) -> 1.4397694e+08 | ... AI38: =SUM(AI31:AI37) -> 0
A39: Share Capital | B39: 10494697 | C39: 20354392 | D39: 20409827 | E39: 20503312 | F39: 20818309 | G39: 21386718 | H39: 21646522 | I39: 21819583 | J39: 22004384 | K39: 22196119 | L39: 22378767 | M39: 22474919 | N39: 22686914 | O39: 22976846 | P39: 22976846 | Q39: 23140804 | R39: 23269757 | S39: 23443264 | T39: 23613532 | U39: 23856891 | V39: 24046291 | W39: 26611793 | X39: 26858915 | Y39: 27115705 | Z39: 27303776 | AA39: 27562238 | AB39: 27792649 | AC39: 27792649 | AD39: 28258881 | AE39: 28590364 | AF39: 28888314 | AG39: 29099240 | AH39: 29296147
A40: Capital Grants | B40: 340425 | D40: 0 | E40: 0 | F40: 0 | G40: 0 | H40: 0 | I40: 0 | J40: 0 | K40: 0 | L40: 0 | M40: 0 | N40: 0 | O40: 0 | Q40: 0 | R40: 0 | S40: 0 | T40: 0 | U40: 0 | V40: 0 | W40: 0 | X40: 0 | Y40: 0 | Z40: 0 | AA40: 0 | AB40: 0 | AD40: 0 | AE40: 0 | AF40: 0 | AG40: 0 | AH40: 0
A41: Prior Year Retained Earnigs | B41: 351220 | C41: 3557811 | D41: 15121447 | E41: 14903354 | F41: 14903354 | G41: 14903354 | H41: 14903354 | I41: 14903354 | J41: 14903354 | K41: 14903354 | L41: 14903354 | M41: 14903354 | N41: 14903354 | O41: 14903354 | P41: 14862025 | Q41: 21838346 | R41: 21838346 | S41: 18140371 | T41: 16019589 | U41: 16066589 | V41: 16063849 | W41: 16070380 | X41: 16063849 | Y41: 16063849 | Z41: 16016357 | AA41: 16016357 | AB41: 16016357 | AC41: 16015500 | AD41: 20349706 | AE41: 16006370 | AF41: 16006370 | AG41: 16006370 | AH41: 16006370
A42: Current Year Surplus | B42: 3541956 | C42: =14862025-C41 -> 11304214 | D42: 1999765.2 | E42: 796449.7 | F42: 110660.8 | G42: 1019263.6 | H42: 3675568.4 | I42: 1223616.2 | J42: 1519756.4 | K42: 788796.1 | L42: 1622544.4 | M42: 3226500.4 | N42: 3837707.9 | O42: 7270515.7 | P42: =4851449-970290-180000-250000-2297685 -> 1153474 | Q42: 118618.9 | R42: 280801.46 | S42: -208201.4 | T42: 695700.1 | U42: 1921498.5 | V42: 1509917.9 | W42: 2936258.1 | X42: 3514391 | Y42: 4450016 | Z42: 5319856.8 | AA42: 6051563.5 | AB42: 5243957.2 | AC42: =4001194+856-800239-180000-250000-2781799 -> -9988 | AD42: 2347310.3 | AE42: 3393614.9 | AF42: 3356802.4 | AG42: 3528907.5 | AH42: 3585005
...

Sheet Evolutitve SCI
B2: 2010 Audited | C2: 2020 Audited | D2: 44197 | E2: 44229 | F2: 44258 | G2: 44290 | H2: 44321 | I2: 44348 | J2: 44378 | K2: 44409 | L2: 44440 | M2: 44472 | N2: 44501 | O2: 44531 | P2: Audited 2021 | Q2: 44564 | R2: 44596 | S2: 44625 | T2: 44657 | U2: 44688 | V2: 44720 | W2: 44751 | X2: 44783 | Y2: 44815 | Z2: 44846 | AA2: 44878 | AB2: 44909 | AC2: Audited 2022 | AD2: 44927 | AE2: 44958 | AF2: 44986 | AG2: 45017 | AH2: 45047 | AI2: 45078 | AJ2: 45108 | AK2: 45139 | AL2: 45170 | AM2: 45200
A3: Financial Income | B3: =B4+B7 -> 14599.248 | C3: =C4+C7 -> 24912213 | D3: =D4+D7 -> 3346469.6 | E3: =E4+E7 -> 4855477.2 | F3: =F4+F7 -> 6639.17 | G3: =G4+G7 -> 8837677.4 | H3: =H4+H7 -> 10209983 | I3: =I4+I7 -> 12571337 | ... AM3: =AM4+AM7 -> 0
A4: Financial Income From Loans Portfolio | B4: =SUM(B5:B6) -> 12855.806 | C4: =SUM(C5:C6) -> 14548967 | D4: =SUM(D5:D6) -> 2222474.9 | E4: =SUM(E5:E6) -> 3827277.3 | F4: =SUM(F5:F6) -> 4832.3 | G4: =SUM(G5:G6) -> 5984742 | H4: =SUM(H5:H6) -> 6784203.7 | I4: =SUM(I5:I6) -> 8447529.5 | ... AM4: =SUM(AM5:AM6) -> 0
A5: Interest from Loans Portfolio | B5: 11945.435 | C5: 14548967 | D5: 2067244.9 | E5: 3579327.3 | F5: 4523.8 | G5: 5617072 | H5: 6370913.7 | I5: 7966759.5 | J5: 9001525.2 | K5: 9823827.3 | L5: 10936923 | M5: 12398964 | N5: 13806661 | O5: 16279831 | P5: 16279831 | Q5: 1287910.1 | R5: 2464378.9 | S5: 4375359.9 | T5: 6146687.3 | U5: 7291788.5 | V5: 8210233.7 | W5: 9625651.9 | X5: 11155163 | Y5: 12513316 | Z5: 13427122 | AA5: 14627894 | AB5: 15893299 | AC5: 16139597 | AD5: 2789027.5 | AE5: 4593922.7 | AF5: 5902480.8 | AG5: 6908719.2 | AH5: 8115358.9
A6: Fees&Commision on Loan Portfolio | B6: 910.371 | D6: 155230 | E6: 247950 | F6: 308.5 | G6: 367670 | H6: 413290 | I6: 480770 | J6: 527950 | K6: 577650 | L6: 638260 | M6: 714775 | N6: 829325 | O6: 958390 | P6: =121000+837390 -> 958390 | Q6: 73760 | R6: 134660 | S6: 278470 | T6: 380630 | U6: 445520 | V6: 503320 | W6: 561020 | X6: 769410 | Y6: 852830 | Z6: 895790 | AA6: 963720 | AB6: 1010645 | AC6: =118800+891845 -> 1010645 | AD6: 118955 | AE6: 218885 | AF6: 305495 | AG6: 355095 | AH6: 417511
A7: Financial Income from Investments | B7: =SUM(B8:B11) -> 1743.4416 | C7: =SUM(C8:C11) -> 10363246 | D7: =SUM(D8:D11) -> 1123994.7 | E7: =SUM(E8:E11) -> 1028199.9 | F7: =SUM(F8:F11) -> 1806.87 | G7: =SUM(G8:G11) -> 2852935.3 | H7: =SUM(H8:H11) -> 3425779.1 | I7: =SUM(I8:I11) -> 4123807.4 | ... AM7: =SUM(AM8:AM11) -> 0
A8: Government Securities | D8: 0 | E8: 0 | F8: 0 | G8: 0 | H8: 0 | I8: 0 | J8: 0 | K8: 0 | L8: 0 | M8: 0 | N8: 0 | O8: 0 | Q8: 0 | R8: 0 | S8: 0 | T8: 0 | U8: 0 | V8: 0 | W8: 0 | X8: 0 | Y8: 0 | Z8: 0 | AA8: 0 | AB8: 0 | AD8: 0 | AE8: 0 | AF8: 0 | AG8: 0 | AH8: 0
A9: Deposits with Banks & other Financial Institutions | C9: 3397666 | D9: 0 | E9: 0 | F9: 0 | G9: 0 | H9: 0 | I9: 0 | J9: 0 | K9: 0 | L9: 0 | M9: 0 | N9: 0 | O9: 0 | P9: 3595000 | Q9: 0 | R9: 0 | S9: 0 | T9: 0 | U9: 0 | V9: 0 | W9: 5142.59 | X9: 5142.59 | Y9: 5142.59 | Z9: 0 | AA9: 0 | AB9: 0 | AC9: 3717486 | AD9: 0 | AE9: 0 | AF9: 0 | AG9: 0 | AH9: 230063
A10: Other Investments | D10: 0 | E10: 0 | F10: 0 | G10: 368484.5 | H10: 370322.75 | I10: 370857.75 | J10: 370857.75 | K10: 370857.75 | L10: 370857.75 | M10: 374615.75 | N10: 374615.75 | O10: 374615.75 | Q10: 0 | R10: 0 | S10: 0 | T10: 2614 | U10: 2614 | V10: 357856 | W10: 357856 | X10: 357856 | Y10: 360919.75 | Z10: 360919.75 | AA10: 360919.75 | AB10: 424759.75 | AD10: 0 | AE10: 0 | AF10: 483609 | AG10: 483609 | AH10: 485978.3
A11: Other Operating Income | B11: 1743.4416 | C11: 6965580 | D11: 1123994.7 | E11: 1028199.9 | F11: 1806.87 | G11: 2484450.8 | H11: 3055456.4 | I11: 3752949.6 | J11: 4463511.7 | K11: 5137703.6 | L11: 5857306.3 | M11: 6632230.7 | N11: 7065068.5 | O11: 8192540.7 | P11: =7308424-P6 -> 6350034 | Q11: 413527.76 | R11: 1100703 | S11: 1557736.3 | T11: 2517989.7 | U11: 3343123 | V11: 4103460.2 | W11: 4810620.3 | X11: 5923126.3 | Y11: 6694253.5 | Z11: 7428873.2 | AA11: 7995224.6 | AB11: 10122078 | AC11: =8027184-AC6 -> 7016539 | AD11: 471477.07 | AE11: 866372.74 | AF11: 1251944.1 | AG11: 2160196.5 | AH11: 2526495.9
A12: Financial Expenses | B12: =SUM(B13:B18) -> 549.0847 | C12: =SUM(C13:C18) -> 1954946 | D12: =SUM(D13:D18) -> 45833.4 | E12: =SUM(E13:E18) -> 53043.4 | F12: =SUM(F13:F18) -> 257.5 | G12: =SUM(G13:G18) -> 281147.6 | H12: =SUM(H13:H18) -> 282552.2 | I12: =SUM(I13:I18) -> 311174.2 | ... AM12: =SUM(AM13:AM18) -> 0
A13: Interest Expense on Deposits | B13: 185.36 | C13: 1954946 | D13: 0 | E13: 0 | F13: 0 | G13: 0 | H13: 0 | I13: 0 | J13: 0 | K13: 0 | L13: 0 | M13: 0 | N13: 0 | O13: 0 | P13: 2076522 | Q13: 0 | R13: 0 | S13: 0 | T13: 0 | U13: 0 | V13: 0 | W13: 0 | X13: 0 | Y13: 0 | Z13: 0 | AA13: 0 | AB13: 0 | AC13: 1101649 | AD13: 0 | AE13: 0 | AF13: 0 | AG13: 0 | AH13: 0
A14: Cost of External Borrowings | B14: 363.7247 | D14: 0 | E14: 0 | F14: 0 | G14: 0 | H14: 0 | I14: 0 | J14: 0 | K14: 0 | L14: 0 | M14: 0 | N14: 0 | O14: 0 | Q14: 0 | R14: 0 | S14: 0 | T14: 0 | U14: 0 | V14: 0 | W14: 0 | X14: 0 | Y14: 0 | Z14: 0 | AA14: 0 | AB14: 0 | AD14: 0 | AE14: 0 | AF14: 0 | AG14: 0 | AH14: 0
A15: Dividend Expenses | D15: 0 | E15: 0 | F15: 0 | G15: 0 | H15: 0 | I15: 0 | J15: 0 | K15: 0 | L15: 0 | M15: 0 | N15: 0 | O15: 0 | Q15: 0 | R15: 0 | S15: 0 | T15: 0 | U15: 0 | V15: 0 | W15: 0 | X15: 0 | Y15: 0 | Z15: 0 | AA15: 0 | AB15: 0 | AD15: 0 | AE15: 0 | AF15: 0 | AG15: 0 | AH15: 0
A16: Other Financial Expense | D16: 0 | E16: 0 | F16: 0 | G16: 0 | H16: 0 | I16: 0 | J16: 0 | K16: 0 | L16: 0 | M16: 0 | N16: 0 | O16: 0 | P16: 182643 | Q16: 0 | R16: 0 | S16: 0 | T16: 0 | U16: 0 | V16: 0 | W16: 0 | X16: 0 | Y16: 0 | Z16: 0 | AA16: 0 | AB16: 0 | AC16: 213780 | AD16: 0 | AE16: 0 | AF16: 0 | AG16: 0 | AH16: 0
A17: Fees & Commision Expense | D17: 45833.4 | E17: 53043.4 | F17: 257.5 | G17: 281147.6 | H17: 282552.2 | I17: 311174.2 | J17: 327199.7 | K17: 331532.1 | L17: 345948 | M17: 354114.1 | N17: 417849.2 | O17: 434016.7 | Q17: 7360 | R17: 51660 | S17: 81802.1 | T17: 99013.8 | U17: 111644.6 | V17: 111644.6 | W17: 185085.5 | X17: 208645 | Y17: 239248.5 | Z17: 259386.2 | AA17: 279645.8 | AB17: 348980.4 | AD17: 35720 | AE17: 65228.3 | AF17: 65778.3 | AG17: 121915 | AH17: 147545.2
A18: Other Expenses | D18: 0 | E18: 0 | F18: 0 | G18: 0 | H18: 0 | I18: 0 | J18: 0 | K18: 0 | L18: 0 | M18: 0 | N18: 0 | O18: 0 | Q18: 0 | R18: 0 | S18: 0 | T18: 0 | U18: 0 | V18: 0 | W18: 0 | X18: 0 | Y18: 0 | Z18: 0 | AA18: 0 | AB18: 533533.4 | AC18: 533533 | AD18: 0 | AE18: 0 | AF18: 0 | AG18: 0 | AH18: 0
A19: Net Financial Income | B19: =B3-B12 -> 14050.163 | C19: =C3-C12 -> 22957267 | D19: =D3-D12 -> 3300636.2 | E19: =E3-E12 -> 4802433.8 | F19: =F3-F12 -> 6381.67 | G19: =G3-G12 -> 8556529.8 | H19: =H3-H12 -> 9927430.6 | I19: =I3-I12 -> 12260163 | ... AM19: =AM3-AM12 -> 0
A20: Allowance for Loan Loss | B20: =B21-B22 -> 0 | C20: =C21-C22 -> 712970 | D20: =D21-D22 -> 866110.6 | E20: =E21-E22 -> 1550668.6 | F20: =F21-F22 -> 0 | G20: =G21-G22 -> 2364259.2 | H20: =H21-H22 -> 1956021.8 | I20: =I21-I22 -> 2142031.4 | ... AM20: =AM21-AM22 -> 0
A21: Provision for Loan Losses | C21: 712970 | D21: 866110.6 | E21: 1550668.6 | F21: 0 | G21: 2364259.2 | H21: 1956021.8 | I21: 2142031.4 | J21: 2161922.5 | K21: 3004453.6 | L21: 2751411.3 | M21: 2359715 | N21: 2270611.4 | O21: -1056159.9 | Q21: 0 | R21: 1489093.9 | S21: 2215685.7 | T21: 2208906.2 | U21: 1515575.1 | V21: 1506607.5 | W21: 528282.7 | X21: 1169780.4 | Y21: 793604.4 | Z21: 800724.4 | AA21: 581820 | AB21: 0 | AC21: 0 | AD21: 0 | AE21: 400463 | AF21: 691228.9 | AG21: 865119.5 | AH21: 643275
A22: Value of Loans Recovered | D22: 0 | E22: 0 | F22: 0 | G22: 0 | H22: 0 | I22: 0 | J22: 0 | K22: 0 | L22: 0 | M22: 0 | N22: 0 | O22: 0 | Q22: 0 | R22: 0 | S22: 0 | T22: 0 | U22: 0 | V22: 0 | W22: 0 | X22: 0 | Y22: 0 | Z22: 0 | AA22: 0 | AB22: 0 | AC22: 0 | AD22: 0 | AE22: 0 | AF22: 0 | AG22: 0 | AH22: 0
A23: Operating Expeses | B23: =SUM(B24:B28) -> 11019.38 | C23: =SUM(C24:C28) -> 18075183 | D23: =SUM(D24:D28) -> 434760.35 | E23: =SUM(E24:E28) -> 2455315.5 | F23: =SUM(F24:F28) -> 595087.12 | G23: =SUM(G24:G28) -> 5005006.9 | H23: =SUM(H24:H28) -> 6083862.6 | I23: =SUM(I24:I28) -> 8558515.1 | ... AM23: =SUM(AM24:AM28) -> 0
A24: Personel Expenses | B24: 3512.444 | C24: 8022789 | D24: 48173 | E24: 1332960.4 | F24: 2064.8 | G24: 2732782.8 | H24: 3476048.8 | I24: 4185253.7 | J24: 4864209.7 | K24: 5565565.6 | L24: 6249851.6 | M24: 7002132.5 | N24: 7715009.5 | O24: 9075535.8 | P24: 9075536 | Q24: 725226 | R24: 1502435.9 | S24: 1611600 | T24: 3032756.4 | U24: 3756318.5 | V24: 4502580.6 | W24: 5289042.7 | X24: 5977948.8 | Y24: 7021615.8 | Z24: 7681884.9 | AA24: 8382421.6 | AB24: 9613066 | AC24: 9613066 | AD24: 625132.1 | AE24: 864412.1 | AF24: 2120981.6 | AG24: 2834167 | AH24: 3622442.1
A25: Governance Expenses | B25: 401.873 | C25: 3550465 | D25: 69820 | E25: 615843.94 | F25: 843.95 | G25: 1172859.5 | H25: 1241669.5 | I25: 1491930.4 | J25: 1812486.3 | K25: 1996316.3 | L25: 2134266 | M25: 2277604.6 | N25: 2674672.8 | O25: 3066223.7 | P25: =3524875-P26 -> 3029675 | Q25: 200085.17 | R25: 471976.05 | S25: 885891.93 | T25: 1034007.3 | U25: 1496013.2 | V25: 1883758.6 | W25: 2049084.1 | X25: 2166244.6 | Y25: 2334455.4 | Z25: 2544921 | AA25: 2903900.7 | AB25: 3576200.5 | AC25: =4379341-AC26 -> 3576201 | AD25: 191297.2 | AE25: 620297.2 | AF25: 1210487.7 | AG25: 1709848.8 | AH25: 1889717.6
A26: Marketing Expenses | B26: 919.3528 | D26: 0 | E26: 0 | F26: 11.9 | G26: 28130 | H26: 30130 | I26: 32430 | J26: 32830 | K26: 32830 | L26: 32830 | M26: 37530 | N26: 40130 | O26: 376380 | P26: 495200 | Q26: 0 | R26: 0 | S26: 0 | T26: 3340 | U26: 3340 | V26: 55440 | W26: 92640 | X26: 94940 | Y26: 94940 | Z26: 95440 | AA26: 141040 | AB26: 803140 | AC26: 803140 | AD26: 0 | AE26: 0 | AF26: 0 | AG26: 9100 | AH26: 10700
A27: Depreciation and Amortization | B27: 1276.981 | D27: 358.75 | E27: 0 | F27: 591372.2 | G27: 0 | H27: 0 | I27: 1144298.8 | J27: 1144298.8 | K27: 1144298.8 | L27: 1144298 | M27: 1144298.8 | N27: 1144298.8 | O27: 2297535.1 | Q27: 0 | R27: 0 | S27: 0 | T27: 0 | U27: 0 | V27: 881245 | W27: 881245 | X27: 1181136.1 | Y27: 1181136.1 | Z27: 1181136.1 | AA27: 1181136.1 | AB27: 1792658.6 | AC27: =1392855+400660 -> 1793515 | AD27: 0 | AE27: 0 | AF27: 856 | AG27: 856 | AH27: 624965.43
A28: Administrative Expenses | B28: 4908.7291 | C28: 6501929 | D28: 316408.6 | E28: 506511.2 | F28: 794.27 | G28: 1071234.6 | H28: 1336014.3 | I28: 1704602.3 | J28: 2165141.3 | K28: 2710486.3 | L28: 3010517.5 | M28: 3207010.3 | N28: 3463710.3 | O28: 3759650.3 | P28: =7025461-P16 -> 6842818 | Q28: 723907.8 | R28: 1393635.8 | S28: 1577295.8 | T28: 1893705.2 | U28: 2151163.6 | V28: 2516183.6 | W28: 3191160.6 | X28: 3690120.2 | Y28: 4023953.2 | Z28: 3989355.3 | AA28: 4178310.3 | AB28: 5211325.4 | AC28: =7606719-AC36-AC27-AC16 -> 5552874 | AD28: 180000 | AE28: 335265 | AF28: 497494 | AG28: 687806 | AH28: 1101856.6
A29: Net Operating Income | B29: =B19-B20-B23 -> 3030.7829 | C29: =C19-C20-C23 -> 4169114 | D29: =D19-D20-D23 -> 1999765.2 | E29: =E19-E20-E23 -> 796449.67 | F29: =F19-F20-F23 -> -588705.45 | G29: =G19-G20-G23 -> 1187263.6 | H29: =H19-H20-H23 -> 1887546.3 | I29: =I19-I20-I23 -> 1559616.2 | ... AN29: =AN19-AN20-AN23 -> 0
A30: Net Non operating Income/Expense | B30: =B31-B32 -> 0 | C30: =C31-C32 -> 0 | D30: =D31-D32 -> 0 | E30: =E31-E32 -> 0 | F30: =F31-F32 -> 26490 | G30: =G31-G32 -> 0 | H30: =H31-H32 -> 0 | I30: =I31-I32 -> 0 | ... AN30: =AN31-AN32 -> 0
A31: Non Operating Income | D31: 0 | E31: 0 | F31: 29190 | G31: 0 | H31: 0 | I31: 0 | J31: 0 | K31: 240 | L31: 240 | M31: 240 | N31: 240 | O31: 240 | Q31: 0 | R31: 0 | S31: 0 | T31: 0 | U31: 0 | V31: 0 | W31: 0 | X31: 0 | Y31: 0 | Z31: 0 | AA31: 0 | AB31: 0 | AD31: 0 | AE31: 100 | AF31: 100 | AG31: 100 | AH31: 100
A32: Non Operating Expense | D32: 0 | E32: 0 | F32: 2700 | G32: 0 | H32: 0 | I32: 0 | J32: 0 | K32: 0 | L32: 0 | M32: 0 | N32: 0 | O32: 0 | Q32: 0 | R32: 0 | S32: 0 | T32: 0 | U32: 0 | V32: 0 | W32: 0 | X32: 0 | Y32: 0 | Z32: 0 | AA32: 0 | AB32: 0 | AD32: 0 | AE32: 0 | AF32: 0 | AG32: 0 | AH32: 0
A33: Net Income(Before Tax & Donations) | B33: =B29+B30 -> 3030.7829 | C33: =C29+C30 -> 4169114 | D33: =D29+D30 -> 1999765.2 | E33: =E29+E30 -> 796449.67 | F33: =F29+F30 -> -562215.45 | G33: =G29+G30 -> 1187263.6 | H33: =H29+H30 -> 1887546.3 | I33: =I29+I30 -> 1559616.2 | ... AM33: =AM29+AM30 -> 0
A34: Taxes | B34: 20 | C34: 611603 | D34: 0 | E34: 0 | F34: 20000 | G34: 168000 | H34: 168000 | I34: 336000 | J34: 336000 | K34: 336000 | L34: 511920.8 | M34: 511920 | N34: 511920 | O34: 581920 | P34: 629412 | Q34: 0 | R34: 0 | S34: 47492 | T34: 80492 | U34: 127492 | V34: 207492 | W34: 207492 | X34: 207492 | Y34: 287492 | Z34: 240000 | AA34: 247920 | AB34: 327920 | AC34: 648765 | AD34: 0 | AE34: 0 | AF34: 0 | AG34: 150000 | AH34: 150000
A35: Net Income(After Tax Before Donations) | B35: =B33-B34 -> 3010.7829 | C35: =C33-C34 -> 3557511 | D35: =D33-D34 -> 1999765.2 | E35: =E33-E34 -> 796449.67 | F35: =F33-F34 -> -582215.45 | G35: =G33-G34 -> 1019263.6 | H35: =H33-H34 -> 1719546.3 | I35: =I33-I34 -> 1223616.2 | ... AM35: =AM33-AM34 -> 0
A36: Donations | D36: 0 | E36: 0 | F36: 0 | G36: 0 | H36: 0 | I36: 0 | J36: 0 | K36: 0 | L36: 0 | M36: 0 | N36: 0 | O36: 0 | Q36: 0 | R36: 0 | S36: 0 | T36: 0 | U36: 0 | V36: 0 | W36: 0 | X36: 0 | Y36: 0 | Z36: 0 | AA36: 0 | AB36: 0 | AC36: 46550 | AD36: 0 | AE36: 0 | AF36: 0 | AG36: 0 | AH36: 0
A37: Net Income/(After Tax & Donations) | B37: =B35-B36 -> 3010.7829 | C37: =C35-C36 -> 3557511 | D37: =D35-D36 -> 1999765.2 | E37: =E35-E36 -> 796449.67 | F37: =F35-F36 -> -582215.45 | G37: =G35-G36 -> 1019263.6 | H37: =H35-H36 -> 1719546.3 | I37: =I35-I36 -> 1223616.2 | ... AM37: =AM35-AM36 -> 0
A39: Total Expenses | B39: =B12+B23 -> 11568.465 | C39: =C12+C23 -> 20030129 | D39: =D12+D23 -> 480593.75 | E39: =E12+E23 -> 2508358.9 | F39: =F12+F23 -> 595344.62 | G39: =G12+G23 -> 5286154.5 | H39: =H12+H23 -> 6366414.8 | I39: =I12+I23 -> 8869689.3 | ... AM39: =AM12+AM23 -> 0

Sheet FORM 4
D1: 44256
B2: CLASSIFICATION | C2: NO. OF A/Cs | D2: OUTSTANDING LOAN PORTFOLIO(Kshs) | E2: REQUIRED PROVISION | F2: REQUIRED PROVISION AMOUNT(Kshs)
B3: Performing | C3: 873 | D3: 91882522 | E3: 0.01 | F3: =D3*E3 -> 918825.22
B4: Watch | C4: 43 | D4: 1343521.2 | E4: 0.05 | F4: =D4*E4 -> 67176.061 | H4: NPL | I4: =D5+D6+D7 -> 32492431
B5: Substandard | C5: 126 | D5: 7742521 | E5: 0.25 | F5: =D5*E5 -> 1935630.3 | H5: PAR | I5: =I4/D8 -> 0.25845391
B6: Doubtful | C6: 89 | D6: 4186717.8 | E6: 0.5 | F6: =D6*E6 -> 2093358.9
B7: Loss | C7: 385 | D7: 20563192 | E7: 1 | F7: =D7*E7 -> 20563192
B8: subtotal | C8: =SUM(C3:C7) -> 1516 | D8: =SUM(D3:D7) -> 1.2571847e+08 | E8: =SUM(E3:E7) -> 1.81 | F8: =SUM(F3:F7) -> 25578182
D10: 44348
B11: CLASSIFICATION | C11: NO. OF A/Cs | D11: OUTSTANDING LOAN PORTFOLIO(Kshs) | E11: REQUIRED PROVISION | F11: REQUIRED PROVISION AMOUNT(Kshs)
B12: Performing | C12: 894 | D12: 93520897 | E12: 0.01 | F12: =D12*E12 -> 935208.97
B13: Watch | C13: 31 | D13: 500814.14 | E13: 0.05 | F13: =D13*E13 -> 25040.707 | H13: NPL | I13: =D14+D15+D16 -> 31901373
B14: Substandard | C14: 140 | D14: 6989924 | E14: 0.25 | F14: =D14*E14 -> 1747481 | H14: PAR | I14: =I13/D17 -> 0.25334015
B15: Doubtful | C15: 89 | D15: 4909926 | E15: 0.5 | F15: =D15*E15 -> 2454963
B16: Loss | C16: 395 | D16: 20001523 | E16: 1 | F16: =D16*E16 -> 20001523
B17: subtotal | C17: =SUM(C12:C16) -> 1549 | D17: =SUM(D12:D16) -> 1.2592308e+08 | E17: 1.81 | F17: =SUM(F12:F16) -> 25164216
D19: 44440
B20: CLASSIFICATION | C20: NO. OF A/Cs | D20: OUTSTANDING LOAN PORTFOLIO(Kshs) | E20: REQUIRED PROVISION | F20: REQUIRED PROVISION AMOUNT(Kshs)
B21: Performing | C21: 913 | D21: 90842702 | E21: 0.01 | F21: =D21*E21 -> 908427.02
B22: Watch | C22: 40 | D22: 1213493.9 | E22: 0.05 | F22: =D22*E22 -> 60674.694 | H22: NPL | I22: =D23+D24+D25 -> 30927101
B23: Substandard | C23: 101 | D23: 4066892.9 | E23: 0.25 | F23: =D23*E23 -> 1016723.2 | H23: PAR | I23: =I22/D26 -> 0.25147399
B24: Doubtful | C24: 88 | D24: 6144873 | E24: 0.5 | F24: =D24*E24 -> 3072436.5
B25: Loss | C25: 411 | D25: 20715335 | E25: 1 | F25: =D25*E25 -> 20715335
B26: subtotal | C26: =SUM(C21:C25) -> 1553 | D26: =SUM(D21:D25) -> 1.229833e+08 | E26: 1.81 | F26: =SUM(F21:F25) -> 25773596
D28: 44531
B29: CLASSIFICATION | C29: NO. OF A/Cs | D29: OUTSTANDING LOAN PORTFOLIO(Kshs) | E29: REQUIRED PROVISION | F29: REQUIRED PROVISION AMOUNT(Kshs)
B30: Performing | C30: 854 | D30: 95533117 | E30: 0.01 | F30: =D30*E30 -> 955331.17
B31: Watch | C31: 52 | D31: 2068944.9 | E31: 0.05 | F31: =D31*E31 -> 103447.24 | H31: NPL | I31: =D32+D33+D34 -> 25363827
B32: Substandard | C32: 95 | D32: 3139897 | E32: 0.25 | F32: =D32*E32 -> 784974.25 | H32: PAR | I32: =I31/D35 -> 0.20626718
B33: Doubtful | C33: 71 | D33: 4203314 | E33: 0.5 | F33: =D33*E33 -> 2101657
B34: Loss | C34: 354 | D34: 18020616 | E34: 1 | F34: =D34*E34 -> 18020616
B35: subtotal | C35: =SUM(C30:C34) -> 1426 | D35: =SUM(D30:D34) -> 1.2296589e+08 | E35: 1.81 | F35: =SUM(F30:F34) -> 21966025
D38: Audited 2021
B39: CLASSIFICATION | C39: NO. OF A/Cs | D39: OUTSTANDING LOAN PORTFOLIO(Kshs) | E39: REQUIRED PROVISION | F39: REQUIRED PROVISION AMOUNT(Kshs)
B40: Performing | C40: 854 | D40: 95533117 | E40: 0.01 | F40: =D40*E40 -> 955331.17
B41: Watch | C41: 52 | D41: 2068945 | E41: 0.05 | F41: =D41*E41 -> 103447.25
B42: Substandard | C42: 95 | D42: 3139897 | E42: 0.25 | F42: =D42*E42 -> 784974.25
B43: Doubtful | C43: 71 | D43: 4203314 | E43: 0.5 | F43: =D43*E43 -> 2101657
B44: Loss | C44: 354 | D44: 18020616 | E44: 1 | F44: =D44*E44 -> 18020616
B45: subtotal | C45: =SUM(C40:C44) -> 1426 | D45: =SUM(D40:D44) -> 122965889 | E45: 1.81 | F45: =SUM(F40:F44) -> 21966026
...

Sheet CAELS
A1: TRANSCOUNTIES SACCO 2022 CAELS
D2: 2010 Audited | E2: 2020Audited | F2: 44198 | G2: 44230 | H2: 44259 | I2: 44291 | J2: 44322 | K2: 44354 | L2: 44385 | M2: 44417 | N2: 44449 | O2: 44480 | P2: 44512 | Q2: 44543 | R2: Audited 2021 | S2: 44590 | T2: 44595 | U2: 44651 | V2: 44652 | W2: 44683 | X2: 44715 | Y2: 44746 | Z2: 44778 | AA2: 44810 | AB2: 44841 | AC2: 44873 | AD2: 44904 | AE2: Audited 2022 | AF2: 44927 | AG2: 44958 | AH2: 44986 | AI2: 45017 | AJ2: 45047 | AK2: 45078 | AL2: 45108 | AM2: 45139 | AN2: 45170 | AO2: 45200 | AP2: 45231 | AQ2: 45261 | AR2: 45292
A3: CAPITAL ADEQUACY | B3: Core Capital | C3: 10 M | D3: =(('Evolutive SFP'!B39+'Evolutive SFP'!B40+'Evolutive SFP'!B41+'Evolutive SFP'!B42+'Evolutive SFP'!B43+'Evolutive SFP'!B44)-'Evolutive SFP'!B10)/1000000 -> 15.259572 | E3: =(('Evolutive SFP'!C39+'Evolutive SFP'!C40+'Evolutive SFP'!C41+'Evolutive SFP'!C42+'Evolutive SFP'!C43+'Evolutive SFP'!C44)-'Evolutive SFP'!C10)/1000000 -> 42.12668 | F3: =(('Evolutive SFP'!D39+'Evolutive SFP'!D40+'Evolutive SFP'!D41+'Evolutive SFP'!D42+'Evolutive SFP'!D43+'Evolutive SFP'!D44)-'Evolutive SFP'!D10)/1000000 -> 43.730082 | G3: =(('Evolutive SFP'!E39+'Evolutive SFP'!E40+'Evolutive SFP'!E41+'Evolutive SFP'!E42+'Evolutive SFP'!E43+'Evolutive SFP'!E44)-'Evolutive SFP'!E10)/1000000 -> 43.113721 | H3: =(('Evolutive SFP'!F39+'Evolutive SFP'!F40+'Evolutive SFP'!F41+'Evolutive SFP'!F42+'Evolutive SFP'!F43+'Evolutive SFP'!F44)-'Evolutive SFP'!F10)/1000000 -> 42.742429 | I3: =(('Evolutive SFP'!G39+'Evolutive SFP'!G40+'Evolutive SFP'!G41+'Evolutive SFP'!G42+'Evolutive SFP'!G43+'Evolutive SFP'!G44)-'Evolutive SFP'!G10)/1000000 -> 44.219941 | J3: =(('Evolutive SFP'!H39+'Evolutive SFP'!H40+'Evolutive SFP'!H41+'Evolutive SFP'!H42+'Evolutive SFP'!H43+'Evolutive SFP'!H44)-'Evolutive SFP'!H10)/1000000 -> 47.136049 | K3: =(('Evolutive SFP'!I39+'Evolutive SFP'!I40+'Evolutive SFP'!I41+'Evolutive SFP'!I42+'Evolutive SFP'!I43+'Evolutive SFP'!I44)-'Evolutive SFP'!I10)/1000000 -> 44.857158 | ... AY3: =(('Evolutive SFP'!AW39+'Evolutive SFP'!AW40+'Evolutive SFP'!AW41+'Evolutive SFP'!AW42+'Evolutive SFP'!AW43+'Evolutive SFP'!AW44)-'Evolutive SFP'!AW10)/1000000 -> 0
B4: CCA | C4: Min 10% | D4: =D3/(('Evolutive SFP'!B27)/1000000) -> 0.10104624 | E4: =E3/(('Evolutive SFP'!C27)/1000000) -> 0.21456568 | F4: =F3/(('Evolutive SFP'!D27)/1000000) -> 0.22182445 | G4: =G3/(('Evolutive SFP'!E27)/1000000) -> 0.22074088 | H4: =H3/(('Evolutive SFP'!F27)/1000000) -> 0.2194844 | I4: =I3/(('Evolutive SFP'!G27)/1000000) -> 0.22955197 | J4: =J3/(('Evolutive SFP'!H27)/1000000) -> 0.24387448 | K4: =K3/(('Evolutive SFP'!I27)/1000000) -> 0.23419893 | ... AY4: =AY3/(('Evolutive SFP'!AW27)/1000000) -> #DIV/0!
B5: CCD | C5: Min 8% | D5: =D3/('Evolutive SFP'!B31/1000000) -> 0.1186553 | E5: =E3/('Evolutive SFP'!C31/1000000) -> 0.29475713 | F5: =F3/('Evolutive SFP'!D31/1000000) -> 0.30914105 | G5: =G3/('Evolutive SFP'!E31/1000000) -> 0.30636369 | H5: =H3/('Evolutive SFP'!F31/1000000) -> 0.29749946 | I5: =I3/('Evolutive SFP'!G31/1000000) -> 0.31044598 | J5: =J3/('Evolutive SFP'!H31/1000000) -> 0.33410248 | K5: =K3/('Evolutive SFP'!I31/1000000) -> 0.31695769 | ... AY5: =AY3/('Evolutive SFP'!AW31/1000000) -> #DIV/0!
B6: ICA | C6: Min 8% | D6: =((D3*1000000)-'Evolutive SFP'!B39)/'Evolutive SFP'!B27 -> 0.031552177 | E6: =((E3*1000000)-'Evolutive SFP'!C39)/'Evolutive SFP'!C27 -> 0.11089375 | F6: =((F3*1000000)-'Evolutive SFP'!D39)/'Evolutive SFP'!D27 -> 0.11829392 | G6: =((G3*1000000)-'Evolutive SFP'!E39)/'Evolutive SFP'!E27 -> 0.11576458 | H6: =((H3*1000000)-'Evolutive SFP'!F39)/'Evolutive SFP'!F27 -> 0.11258139 | I6: =((I3*1000000)-'Evolutive SFP'!G39)/'Evolutive SFP'!G27 -> 0.11853049 | J6: =((J3*1000000)-'Evolutive SFP'!H39)/'Evolutive SFP'!H27 -> 0.13187879 | K6: =((K3*1000000)-'Evolutive SFP'!I39)/'Evolutive SFP'!I27 -> 0.12027903 | ... AY6: =((AY3*1000000)-'Evolutive SFP'!AW39)/'Evolutive SFP'!AW27 -> #DIV/0!
A7: ASSET QUALITY | B7: A/LNPL30
B8: NPL30 | R8: =('FORM 4'!D42+'FORM 4'!D43+'FORM 4'!D44)/'Evolutive SFP'!P15 -> 0.20625666 | U8: =('FORM 4'!D51+'FORM 4'!D52+'FORM 4'!D53)/'Evolutive SFP'!S15 -> 0.24271935 | X8: =('FORM 4'!D60+'FORM 4'!D61+'FORM 4'!D62)/'Evolutive SFP'!V15 -> 0.22916399 | AA8: =('FORM 4'!D69+'FORM 4'!D70+'FORM 4'!D71)/'Evolutive SFP'!Y15 -> 0.19994869 | AD8: =('FORM 4'!D78+'FORM 4'!D79+'FORM 4'!D80)/'Evolutive SFP'!AB15 -> 0.20087112 | AE8: =('FORM 4'!D88+'FORM 4'!D89+'FORM 4'!D90)/'Evolutive SFP'!AC15 -> 0.20047405
A9: EARNINGS | B9: ROA | E9: ='Evolutitve SCI'!C33/(('Evolutive SFP'!B27+'Evolutive SFP'!C27)/2) -> 0.024005236 | F9: ='Evolutitve SCI'!D33/(('Evolutive SFP'!C27+'Evolutive SFP'!D27)/2) -> 0.010164691 | G9: ='Evolutitve SCI'!E33/(('Evolutive SFP'!D27+'Evolutive SFP'!E27)/2) -> 0.0040588391 | H9: ='Evolutitve SCI'!F33/(('Evolutive SFP'!E27+'Evolutive SFP'!F27)/2) -> -0.0028827579 | I9: ='Evolutitve SCI'!G33/(('Evolutive SFP'!F27+'Evolutive SFP'!G27)/2) -> 0.0061297734 | J9: ='Evolutitve SCI'!H33/(('Evolutive SFP'!G27+'Evolutive SFP'!H27)/2) -> 0.0097821658 | K9: ='Evolutitve SCI'!I33/(('Evolutive SFP'!H27+'Evolutive SFP'!I27)/2) -> 0.0081058103 | L9: ='Evolutitve SCI'!J33/(('Evolutive SFP'!I27+'Evolutive SFP'!J27)/2) -> 0.0096758657 | ... AY9: ='Evolutitve SCI'!AW33/(('Evolutive SFP'!AV27+'Evolutive SFP'!AW27)/2) -> #DIV/0!
B10: Cost Income ratio | D10: ='Evolutitve SCI'!B23/'Evolutitve SCI'!B19 -> 0.78428841 | E10: ='Evolutitve SCI'!C23/'Evolutitve SCI'!C19 -> 0.78734037 | F10: ='Evolutitve SCI'!D23/'Evolutitve SCI'!D19 -> 0.13172017 | G10: ='Evolutitve SCI'!E23/'Evolutitve SCI'!E19 -> 0.51126484 | H10: ='Evolutitve SCI'!F23/'Evolutitve SCI'!F19 -> 93.249435 | I10: ='Evolutitve SCI'!G23/'Evolutitve SCI'!G19 -> 0.5849342 | J10: ='Evolutitve SCI'!H23/'Evolutitve SCI'!H19 -> 0.61283355 | K10: ='Evolutitve SCI'!I23/'Evolutitve SCI'!I19 -> 0.69807516 | ... AY10: ='Evolutitve SCI'!AW23/'Evolutitve SCI'!AW19 -> #DIV/0!
B11: Operating Expense ratio | D11: =('Evolutitve SCI'!B23+'Evolutitve SCI'!B12)/(('Evolutive SFP'!B27+'Evolutive SFP'!C27)/2) -> 6.6609769e-05 | E11: =('Evolutitve SCI'!C23+'Evolutitve SCI'!C12)/(('Evolutive SFP'!C27+'Evolutive SFP'!D27)/2) -> 0.10181199 | F11: =('Evolutitve SCI'!D23+'Evolutitve SCI'!D12)/(('Evolutive SFP'!D27+'Evolutive SFP'!E27)/2) -> 0.0024491852 | G11: =('Evolutitve SCI'!E23+'Evolutitve SCI'!E12)/(('Evolutive SFP'!E27+'Evolutive SFP'!F27)/2) -> 0.012861602 | H11: =('Evolutitve SCI'!F23+'Evolutitve SCI'!F12)/(('Evolutive SFP'!F27+'Evolutive SFP'!G27)/2) -> 0.0030737298 | I11: =('Evolutitve SCI'!G23+'Evolutitve SCI'!G12)/(('Evolutive SFP'!G27+'Evolutive SFP'!H27)/2) -> 0.027395376 | J11: =('Evolutitve SCI'!H23+'Evolutitve SCI'!H12)/(('Evolutive SFP'!H27+'Evolutive SFP'!I27)/2) -> 0.033088237 | K11: =('Evolutitve SCI'!I23+'Evolutitve SCI'!I12)/(('Evolutive SFP'!I27+'Evolutive SFP'!J27)/2) -> 0.046246331 | ... AY11: =('Evolutitve SCI'!AW23+'Evolutitve SCI'!AW12)/(('Evolutive SFP'!AW27+'Evolutive SFP'!AX27)/2) -> #DIV/0!
A12: LIQUIDITY | B12: MIN LIQ ratio | C12: Min 15% | D12: =('Evolutive SFP'!B4)/('Evolutive SFP'!B28+'Evolutive SFP'!B29+'Evolutive SFP'!B32+'Evolutive SFP'!B33+'Evolutive SFP'!B34+'Evolutive SFP'!B35+'Evolutive SFP'!B36) -> 0.90806632 | E12: =('Evolutive SFP'!C4)/('Evolutive SFP'!C28+'Evolutive SFP'!C29+'Evolutive SFP'!C32+'Evolutive SFP'!C33+'Evolutive SFP'!C34+'Evolutive SFP'!C35+'Evolutive SFP'!C36) -> 1.5066817 | F12: =('Evolutive SFP'!D4)/('Evolutive SFP'!D28+'Evolutive SFP'!D29+'Evolutive SFP'!D32+'Evolutive SFP'!D33+'Evolutive SFP'!D34+'Evolutive SFP'!D35+'Evolutive SFP'!D36) -> 1.4908281 | G12: =('Evolutive SFP'!E4)/('Evolutive SFP'!E28+'Evolutive SFP'!E29+'Evolutive SFP'!E32+'Evolutive SFP'!E33+'Evolutive SFP'!E34+'Evolutive SFP'!E35+'Evolutive SFP'!E36) -> 1.4547455 | H12: =('Evolutive SFP'!F4)/('Evolutive SFP'!F28+'Evolutive SFP'!F29+'Evolutive SFP'!F32+'Evolutive SFP'!F33+'Evolutive SFP'!F34+'Evolutive SFP'!F35+'Evolutive SFP'!F36) -> 1.4930332 | I12: =('Evolutive SFP'!G4)/('Evolutive SFP'!G28+'Evolutive SFP'!G29+'Evolutive SFP'!G32+'Evolutive SFP'!G33+'Evolutive SFP'!G34+'Evolutive SFP'!G35+'Evolutive SFP'!G36) -> 1.5606636 | J12: =('Evolutive SFP'!H4)/('Evolutive SFP'!H28+'Evolutive SFP'!H29+'Evolutive SFP'!H32+'Evolutive SFP'!H33+'Evolutive SFP'!H34+'Evolutive SFP'!H35+'Evolutive SFP'!H36) -> 1.64838 | K12: =('Evolutive SFP'!I4)/('Evolutive SFP'!I28+'Evolutive SFP'!I29+'Evolutive SFP'!I32+'Evolutive SFP'!I33+'Evolutive SFP'!I34+'Evolutive SFP'!I35+'Evolutive SFP'!I36) -> 1.6727037 | ... AY12: =('Evolutive SFP'!AW4)/('Evolutive SFP'!AW28+'Evolutive SFP'!AW29+'Evolutive SFP'!AW32+'Evolutive SFP'!AW33+'Evolutive SFP'!AW34+'Evolutive SFP'!AW35+'Evolutive SFP'!AW36) -> #DIV/0!
B13: T/LIQ ratio | D13: ='Evolutive SFP'!B4/('Evolutive SFP'!B31+'Evolutive SFP'!B36) -> 0.14915539 | E13: ='Evolutive SFP'!C4/('Evolutive SFP'!C31+'Evolutive SFP'!C36) -> 0.55211955 | F13: ='Evolutive SFP'!D4/('Evolutive SFP'!D31+'Evolutive SFP'!D36) -> 0.53195438 | G13: ='Evolutive SFP'!E4/('Evolutive SFP'!E31+'Evolutive SFP'!E36) -> 0.50796337 | H13: ='Evolutive SFP'!F4/('Evolutive SFP'!F31+'Evolutive SFP'!F36) -> 0.49816762 | I13: ='Evolutive SFP'!G4/('Evolutive SFP'!G31+'Evolutive SFP'!G36) -> 0.49026422 | J13: ='Evolutive SFP'!H4/('Evolutive SFP'!H31+'Evolutive SFP'!H36) -> 0.49072735 | K13: ='Evolutive SFP'!I4/('Evolutive SFP'!I31+'Evolutive SFP'!I36) -> 0.49630355 | ... AY13: ='Evolutive SFP'!AW4/('Evolutive SFP'!AW31+'Evolutive SFP'!AW36) -> #DIV/0!
B14: EB ratio | C14: Max 25% | D14: ='Evolutive SFP'!B37/'Evolutive SFP'!B27 -> 0.015175035 | E14: ='Evolutive SFP'!C37/'Evolutive SFP'!C27 -> 0 | F14: ='Evolutive SFP'!D37/'Evolutive SFP'!D27 -> 0 | G14: ='Evolutive SFP'!E37/'Evolutive SFP'!E27 -> 0 | H14: ='Evolutive SFP'!F37/'Evolutive SFP'!F27 -> 0 | I14: ='Evolutive SFP'!G37/'Evolutive SFP'!G27 -> 0 | J14: ='Evolutive SFP'!H37/'Evolutive SFP'!H27 -> 0 | K14: ='Evolutive SFP'!I37/'Evolutive SFP'!I27 -> 0 | ... AY14: ='Evolutive SFP'!AW37/'Evolutive SFP'!AW27 -> #DIV/0!
B15: LA to TA ratio | D15: ='Evolutive SFP'!B4/'Evolutive SFP'!B27 -> 0.12821992 | E15: ='Evolutive SFP'!C4/'Evolutive SFP'!C27 -> 0.41255969 | F15: ='Evolutive SFP'!D4/'Evolutive SFP'!D27 -> 0.3912925 | G15: ='Evolutive SFP'!E4/'Evolutive SFP'!E27 -> 0.37726296 | H15: ='Evolutive SFP'!F4/'Evolutive SFP'!F27 -> 0.38061698 | I15: ='Evolutive SFP'!G4/'Evolutive SFP'!G27 -> 0.36955447 | J15: ='Evolutive SFP'!H4/'Evolutive SFP'!H27 -> 0.36374364 | K15: ='Evolutive SFP'!I4/'Evolutive SFP'!I27 -> 0.37261146 | ... AY15: ='Evolutive SFP'!AW4/'Evolutive SFP'!AW27 -> #DIV/0!
A16: STRUCTURE | B16: NEA ratio | C16: Max 10% | D16: =('Evolutive SFP'!B7+'Evolutive SFP'!B21)/'Evolutive SFP'!B27 -> 0.12101375 | E16: =('Evolutive SFP'!C7+'Evolutive SFP'!C21)/'Evolutive SFP'!C27 -> 0.088097908 | F16: =('Evolutive SFP'!D7+'Evolutive SFP'!D21)/'Evolutive SFP'!D27 -> 0.082446444 | G16: =('Evolutive SFP'!E7+'Evolutive SFP'!E21)/'Evolutive SFP'!E27 -> 0.085679841 | H16: =('Evolutive SFP'!F7+'Evolutive SFP'!F21)/'Evolutive SFP'!F27 -> 0.088070652 | I16: =('Evolutive SFP'!G7+'Evolutive SFP'!G21)/'Evolutive SFP'!G27 -> 0.08844105 | J16: =('Evolutive SFP'!H7+'Evolutive SFP'!H21)/'Evolutive SFP'!H27 -> 0.087767818 | K16: =('Evolutive SFP'!I7+'Evolutive SFP'!I21)/'Evolutive SFP'!I27 -> 0.083953933 | ... AY16: =('Evolutive SFP'!AW7+'Evolutive SFP'!AW21)/'Evolutive SFP'!AW27 -> #DIV/0!
B17: LB ratio | C17: Max 5% | D17: ='Evolutive SFP'!B21/'Evolutive SFP'!B27 -> 0.032278671 | E17: ='Evolutive SFP'!C21/'Evolutive SFP'!C27 -> 0.076213231 | F17: ='Evolutive SFP'!D21/'Evolutive SFP'!D27 -> 0.079234899 | G17: ='Evolutive SFP'!E21/'Evolutive SFP'!E27 -> 0.085452444 | H17: ='Evolutive SFP'!F21/'Evolutive SFP'!F27 -> 0.085784763 | I17: ='Evolutive SFP'!G21/'Evolutive SFP'!G27 -> 0.08671895 | J17: ='Evolutive SFP'!H21/'Evolutive SFP'!H27 -> 0.086579276 | K17: ='Evolutive SFP'!I21/'Evolutive SFP'!I27 -> 0.081634239 | ... AY17: ='Evolutive SFP'!AW21/'Evolutive SFP'!AW27 -> #DIV/0!
B18: PI to Deposit ratio | C18: Max 5% | D18: ='Evolutive SFP'!B13/'Evolutive SFP'!B31 -> 0.0036721969 | E18: ='Evolutive SFP'!C13/'Evolutive SFP'!C31 -> 0.0010816193 | F18: ='Evolutive SFP'!D13/'Evolutive SFP'!D31 -> 0.029828283 | G18: ='Evolutive SFP'!E13/'Evolutive SFP'!E31 -> 0.023608223 | H18: ='Evolutive SFP'!F13/'Evolutive SFP'!F31 -> 0.023124295 | I18: ='Evolutive SFP'!G13/'Evolutive SFP'!G31 -> 0.023324342 | J18: ='Evolutive SFP'!H13/'Evolutive SFP'!H31 -> 0.02354876 | K18: ='Evolutive SFP'!I13/'Evolutive SFP'!I31 -> 0.023475295 | ... AY18: ='Evolutive SFP'!AW13/'Evolutive SFP'!AW31 -> #DIV/0!
B19: PI to CC ratio | C19: Max 40% | D19: ='Evolutive SFP'!B13/(CAELS!D3*1000000) -> 0.030948443 | E19: ='Evolutive SFP'!C13/(CAELS!E3*1000000) -> 0.0036695272 | F19: ='Evolutive SFP'!D13/(CAELS!F3*1000000) -> 0.096487616 | G19: ='Evolutive SFP'!E13/(CAELS!G3*1000000) -> 0.077059468 | H19: ='Evolutive SFP'!F13/(CAELS!H3*1000000) -> 0.077728863 | I19: ='Evolutive SFP'!G13/(CAELS!I3*1000000) -> 0.075131724 | J19: ='Evolutive SFP'!H13/(CAELS!J3*1000000) -> 0.070483642 | K19: ='Evolutive SFP'!I13/(CAELS!K3*1000000) -> 0.074064443 | ... AY19: ='Evolutive SFP'!AW13/(CAELS!AY3*1000000) -> #DIV/0!
B20: Gross loans/TA | D20: ='Evolutive SFP'!B15/'Evolutive SFP'!B27 -> 0.74763912 | E20: ='Evolutive SFP'!C15/'Evolutive SFP'!C27 -> 0.59968059 | F20: ='Evolutive SFP'!D15/'Evolutive SFP'!D27 -> 0.62603309 | G20: ='Evolutive SFP'!E15/'Evolutive SFP'!E27 -> 0.64585926 | H20: ='Evolutive SFP'!F15/'Evolutive SFP'!F27 -> 0.64559728 | I20: ='Evolutive SFP'!G15/'Evolutive SFP'!G27 -> 0.65654246 | J20: ='Evolutive SFP'!H15/'Evolutive SFP'!H27 -> 0.65041253 | K20: ='Evolutive SFP'!I15/'Evolutive SFP'!I27 -> 0.657471 | ... AY20: ='Evolutive SFP'!AW15/'Evolutive SFP'!AW27 -> #DIV/0!
A21: FUNDING MIX | B21: Total Deposits/Total Assets | D21: ='Evolutive SFP'!B31/'Evolutive SFP'!B27 -> 0.85159483 | E21: ='Evolutive SFP'!C31/'Evolutive SFP'!C27 -> 0.72794059 | F21: ='Evolutive SFP'!D31/'Evolutive SFP'!D27 -> 0.71755093 | G21: ='Evolutive SFP'!E31/'Evolutive SFP'!E27 -> 0.72051908 | H21: ='Evolutive SFP'!F31/'Evolutive SFP'!F27 -> 0.73776403 | I21: ='Evolutive SFP'!G31/'Evolutive SFP'!G27 -> 0.73942645 | J21: ='Evolutive SFP'!H31/'Evolutive SFP'!H27 -> 0.72993914 | K21: ='Evolutive SFP'!I31/'Evolutive SFP'!I27 -> 0.73889648 | ... AY21: ='Evolutive SFP'!AW31/'Evolutive SFP'!AW27 -> #DIV/0!
B22: BOSA Deposits/Total Assets | D22: ='Evolutive SFP'!B30/'Evolutive SFP'!B27 -> 0.74257768 | E22: ='Evolutive SFP'!C30/'Evolutive SFP'!C27 -> 0.49786054 | F22: ='Evolutive SFP'!D30/'Evolutive SFP'!D27 -> 0.49746079 | G22: ='Evolutive SFP'!E30/'Evolutive SFP'!E27 -> 0.5061009 | H22: ='Evolutive SFP'!F30/'Evolutive SFP'!F27 -> 0.51172061 | I22: ='Evolutive SFP'!G30/'Evolutive SFP'!G27 -> 0.51963707 | J22: ='Evolutive SFP'!H30/'Evolutive SFP'!H27 -> 0.52148731 | K22: ='Evolutive SFP'!I30/'Evolutive SFP'!I27 -> 0.52894269 | ... AY22: ='Evolutive SFP'!AW30/'Evolutive SFP'!AW27 -> #DIV/0!
B23: FOSA Deposits/Total Assets | D23: =('Evolutive SFP'!B28+'Evolutive SFP'!B29)/'Evolutive SFP'!B27 -> 0.10901715 | E23: =('Evolutive SFP'!C28+'Evolutive SFP'!C29)/'Evolutive SFP'!C27 -> 0.23008005 | F23: =('Evolutive SFP'!D28+'Evolutive SFP'!D29)/'Evolutive SFP'!D27 -> 0.22009013 | G23: =('Evolutive SFP'!E28+'Evolutive SFP'!E29)/'Evolutive SFP'!E27 -> 0.21441817 | H23: =('Evolutive SFP'!F28+'Evolutive SFP'!F29)/'Evolutive SFP'!F27 -> 0.22604342 | I23: =('Evolutive SFP'!G28+'Evolutive SFP'!G29)/'Evolutive SFP'!G27 -> 0.21978937 | J23: =('Evolutive SFP'!H28+'Evolutive SFP'!H29)/'Evolutive SFP'!H27 -> 0.20845183 | K23: =('Evolutive SFP'!I28+'Evolutive SFP'!I29)/'Evolutive SFP'!I27 -> 0.2099538 | ... AY23: =('Evolutive SFP'!AW28+'Evolutive SFP'!AW29)/'Evolutive SFP'!AW27 -> #DIV/0!
A24: GROWTH RATIOS | B24: Total Assets | D24: =(Financials!C4-Financials!B4)/Financials!B4 -> #VALUE! | E24: =(Financials!D4-Financials!C4)/Financials!C4 -> 0.30009413 | F24: =(Financials!E4-Financials!D4)/Financials!D4 -> 0.0040929075 | G24: =(Financials!F4-Financials!E4)/Financials!E4 -> -0.0092550939 | H24: =(Financials!G4-Financials!F4)/Financials!F4 -> -0.0029365037 | I24: =(Financials!H4-Financials!G4)/Financials!G4 -> -0.010805731 | J24: =(Financials!I4-Financials!H4)/Financials!H4 -> 0.0033435976 | K24: =(Financials!J4-Financials!I4)/Financials!I4 -> -0.0090310784 | ... AY24: =(Financials!AX4-Financials!AW4)/Financials!AW4 -> #DIV/0!
B25: Total Deposits | C25: =IF(CAELS!D16<6%,"1",IF) -> #NAME? | D25: =Financials!D5/Financials!C5-1 -> 0.11131639 | E25: =Financials!E5/Financials!D5-1 -> -0.010238193 | F25: =Financials!F5/Financials!E5-1 -> -0.0051568757 | G25: =Financials!G5/Financials!F5-1 -> 0.020927275 | H25: =Financials!H5/Financials!G5-1 -> -0.0085767565 | I25: =Financials!I5/Financials!H5-1 -> -0.0095299309 | J25: =Financials!J5/Financials!I5-1 -> 0.003129455 | K25: =Financials!K5/Financials!J5-1 -> -0.0003632884 | ... AY25: =Financials!AY5/Financials!AX5-1 -> #DIV/0!
B26: BOSA Deposits | D26: =Financials!D6/Financials!C6-1 -> -0.12835304 | E26: =Financials!E6/Financials!D6-1 -> 0.0032866834 | F26: =Financials!F6/Financials!E6-1 -> 0.0079525862 | G26: =Financials!G6/Financials!F6-1 -> 0.0081348105 | H26: =Financials!H6/Financials!G6-1 -> 0.0044973894 | I26: =Financials!I6/Financials!H6-1 -> 0.0069161326 | J26: =Financials!J6/Financials!I6-1 -> 0.0051361897 | K26: =Financials!K6/Financials!J6-1 -> 0.007292579 | ... AY26: =Financials!AY6/Financials!AX6-1 -> #DIV/0!
B27: FOSA Deposits | D27: =Financials!D7/Financials!C7-1 -> 1.7438409 | E27: =Financials!E7/Financials!D7-1 -> -0.039504104 | F27: =Financials!F7/Financials!E7-1 -> -0.03478766 | G27: =Financials!G7/Financials!F7-1 -> 0.051121906 | H27: =Financials!H7/Financials!G7-1 -> -0.038174212 | I27: =Financials!I7/Financials!H7-1 -> -0.04841254 | J27: =Financials!J7/Financials!I7-1 -> -0.0018908255 | K27: =Financials!K7/Financials!J7-1 -> -0.019650937 | ... AY27: =Financials!AY7/Financials!AX7-1 -> #DIV/0!
B28: Total Loans & advances | D28: =Financials!D31/Financials!C31-1 -> 0.042804213 | E28: =Financials!E31/Financials!D31-1 -> 0.048216994 | F28: =Financials!F31/Financials!E31-1 -> 0.022121316 | G28: =Financials!G31/Financials!F31-1 -> -0.0033409378 | H28: =Financials!H31/Financials!G31-1 -> 0.0059646513 | I28: =Financials!I31/Financials!H31-1 -> -0.0060243081 | J28: =Financials!J31/Financials!I31-1 -> 0.0017232122 | K28: =Financials!K31/Financials!J31-1 -> -0.02560335 | ... AY28: =Financials!AY31/Financials!AX31-1 -> #DIV/0!
B29: Core capital | D29: =Financials!D11/Financials!C11-1 -> 1.6860015 | E29: =Financials!E11/Financials!D11-1 -> 0.018201843 | F29: =Financials!F11/Financials!E11-1 -> 0.0071051593 | G29: =Financials!G11/Financials!F11-1 -> -0.0093309558 | H29: =Financials!H11/Financials!G11-1 -> 0.037481178 | I29: =Financials!I11/Financials!H11-1 -> 0.071302629 | J29: =Financials!J11/Financials!I11-1 -> -0.052013176 | K29: =Financials!K11/Financials!J11-1 -> 0.011579224 | ... AY29: =Financials!AY11/Financials!AX11-1 -> #DIV/0!
B30: Turnover | D30: =Financials!D37/Financials!C37-1 -> 1705.4039 | E30: =Financials!E37/Financials!D37-1 -> -0.86566952 | F30: =Financials!F37/Financials!E37-1 -> 0.45092525 | G30: =Financials!G37/Financials!F37-1 -> -0.99863264 | H30: =Financials!H37/Financials!G37-1 -> 1330.1419 | I30: =Financials!I37/Financials!H37-1 -> 0.15527897 | J30: =Financials!J37/Financials!I37-1 -> 0.23127895 | K30: =Financials!K37/Financials!J37-1 -> 0.14258687 | ... AY30: =Financials!AY37/Financials!AX37-1 -> #DIV/0!
B31: Membership
B32: Expenses | D32: ='Evolutitve SCI'!E39/'Evolutitve SCI'!B39-1 -> 215.8273 | E32: ='Evolutitve SCI'!F39/'Evolutitve SCI'!C39-1 -> -0.97027754 | F32: ='Evolutitve SCI'!G39/'Evolutitve SCI'!D39-1 -> 9.9992161 | G32: ='Evolutitve SCI'!H39/'Evolutitve SCI'!E39-1 -> 1.5380797 | H32: ='Evolutitve SCI'!I39/'Evolutitve SCI'!F39-1 -> 13.898412 | I32: ='Evolutitve SCI'!J39/'Evolutitve SCI'!G39-1 -> 0.95721969 | J32: ='Evolutitve SCI'!K39/'Evolutitve SCI'!H39-1 -> 0.85049661 | K32: ='Evolutitve SCI'!L39/'Evolutitve SCI'!I39-1 -> 0.45638823 | ... AY32: ='Evolutitve SCI'!AZ39/'Evolutitve SCI'!AW39-1 -> #DIV/0!
A33: Efficiency Ratios | B33: FinCost-Deposits/Avg Deposits
B34: FinCost-Shares/Avg Share capital
B35: FinCost-Ext Loans/Avg Ext Loans
B36: OpEx/Average Total Assets
B37: Opex/Turnover
B38: Avge yield on Net loans
B39: Avge yield on Gross loans
A41: ALL/Average Gross Loan portfolio

Sheet Financials
B1: SOLUTION Sacco Financial Performance
B2: Year | C2: 2010 Audited | D2: 2020 Audited | E2: 44197 | F2: 44229 | G2: 44258 | H2: 44290 | I2: 44321 | J2: 44353 | K2: 44384 | L2: 44416 | M2: 44448 | N2: 44479 | O2: 44511 | P2: 44542 | Q2: Audited 2021 | R2: 44582 | S2: 44614 | T2: 44643 | U2: 44675 | V2: 44706 | W2: 44738 | X2: 44769 | Y2: 44801 | Z2: 44833 | AA2: 44864 | AB2: 44868 | AC2: 44896 | AD2: Audited 2022 | AE2: 44564 | AF2: 44595 | AG2: 44623 | AH2: 44654 | AI2: 44684 | AJ2: 44715 | AK2: 44745 | AL2: 44776 | AM2: 44807 | AN2: 44837
A3: 1 | B3: Membership
A4: 2 | B4: Total Assets | C4: ='Evolutive SFP'!B27 -> 151015729 | D4: ='Evolutive SFP'!C27 -> 196334663 | E4: ='Evolutive SFP'!D27 -> 1.9713824e+08 | F4: ='Evolutive SFP'!E27 -> 1.9531371e+08 | G4: ='Evolutive SFP'!F27 -> 1.9474017e+08 | H4: ='Evolutive SFP'!G27 -> 1.9263586e+08 | I4: ='Evolutive SFP'!H27 -> 1.9327996e+08 | J4: ='Evolutive SFP'!I27 -> 1.9153443e+08 | ... AY4: ='Evolutive SFP'!AX27 -> 0
A5: 3 | B5: Total Deposits | C5: ='Evolutive SFP'!B31 -> 128604214 | D5: ='Evolutive SFP'!C31 -> 142919971 | E5: ='Evolutive SFP'!D31 -> 1.4145673e+08 | F5: ='Evolutive SFP'!E31 -> 1.4072725e+08 | G5: ='Evolutive SFP'!F31 -> 1.4367229e+08 | H5: ='Evolutive SFP'!G31 -> 1.4244005e+08 | I5: ='Evolutive SFP'!H31 -> 1.4108261e+08 | J5: ='Evolutive SFP'!I31 -> 1.4152412e+08 | ... AY5: ='Evolutive SFP'!AX31 -> 0
A6: 3.1 | B6: Deposits-Members(BOSA) | C6: ='Evolutive SFP'!B30 -> 112140909 | D6: ='Evolutive SFP'!C30 -> 97747282 | E6: ='Evolutive SFP'!D30 -> 98068546 | F6: ='Evolutive SFP'!E30 -> 98848445 | G6: ='Evolutive SFP'!F30 -> 99652558 | H6: ='Evolutive SFP'!G30 -> 1.0010073e+08 | I6: ='Evolutive SFP'!H30 -> 1.0079304e+08 | J6: ='Evolutive SFP'!I30 -> 1.0131074e+08 | ... AY6: ='Evolutive SFP'!AX30 -> 0
A7: 3.2 | B7: Deposits-Customers(FOSA) | C7: =('Evolutive SFP'!B28+'Evolutive SFP'!B29) -> 16463305 | D7: =('Evolutive SFP'!C28+'Evolutive SFP'!C29) -> 45172689 | E7: =('Evolutive SFP'!D28+'Evolutive SFP'!D29) -> 43388182 | F7: =('Evolutive SFP'!E28+'Evolutive SFP'!E29) -> 41878809 | G7: =('Evolutive SFP'!F28+'Evolutive SFP'!F29) -> 44019734 | H7: =('Evolutive SFP'!G28+'Evolutive SFP'!G29) -> 42339315 | I7: =('Evolutive SFP'!H28+'Evolutive SFP'!H29) -> 40289561 | J7: =('Evolutive SFP'!I28+'Evolutive SFP'!I29) -> 40213381 | ... AY7: =('Evolutive SFP'!AX28+'Evolutive SFP'!AX29) -> 0
A8: 4 | B8: External Borrowing | C8: ='Evolutive SFP'!B37 -> 2291669 | D8: ='Evolutive SFP'!C37 -> 0 | E8: ='Evolutive SFP'!D37 -> 0 | F8: ='Evolutive SFP'!E37 -> 0 | G8: ='Evolutive SFP'!F37 -> 0 | H8: ='Evolutive SFP'!G37 -> 0 | I8: ='Evolutive SFP'!H37 -> 0 | J8: ='Evolutive SFP'!I37 -> 0 | ... AY8: ='Evolutive SFP'!AX37 -> 0
A10: 5 | B10: Share capital and Reserves
A11: 5.1 | B11: Core Capital | C11: =C14-C22-C25 -> 14446887 | D11: =D14-D22-D25 -> 38804360 | E11: =E14-E22-E25 -> 39510671 | F11: =F14-F22-F25 -> 39791400 | G11: =G14-G22-G25 -> 39420109 | H11: =H14-H22-H25 -> 40897621 | I11: =I14-I22-I25 -> 43813729 | J11: =J14-J22-J25 -> 41534837 | ... AY11: =AY14-AY22-AY25 -> 0
A12: 5.2 | B12: Institutional Capital | C12: =C11-C15 -> 3952190 | D12: =D11-D15 -> 18449968 | E12: =E11-E15 -> 19100844 | F12: =F11-F15 -> 19288088 | G12: =G11-G15 -> 18601800 | H12: =H11-H15 -> 19510902 | I12: =I11-I15 -> 22167207 | J12: =J11-J15 -> 19715255 | ... AY12: =AY11-AY15 -> 0
A14: 5.3 | B14: Total Capital | C14: =C15+C16+C17+C18+C19+C20+C21 -> 14919147 | D14: =D15+D16+D17+D18+D19+D20+D21 -> 42126680 | E14: =E15+E16+E17+E18+E19+E20+E21 -> 43730082 | F14: =F15+F16+F17+F18+F19+F20+F21 -> 43113721 | G14: =G15+G16+G17+G18+G19+G20+G21 -> 42742429 | H14: =H15+H16+H17+H18+H19+H20+H21 -> 44219941 | I14: =I15+I16+I17+I18+I19+I20+I21 -> 47136049 | J14: =J15+J16+J17+J18+J19+J20+J21 -> 44857158 | ... AY14: =AY15+AY16+AY17+AY18+AY19+AY20+AY21 -> 0
A15: 5.3.1 | B15: Members Share Capital | C15: ='Evolutive SFP'!B39 -> 10494697 | D15: ='Evolutive SFP'!C39 -> 20354392 | E15: ='Evolutive SFP'!D39 -> 20409827 | F15: ='Evolutive SFP'!E39 -> 20503312 | G15: ='Evolutive SFP'!F39 -> 20818309 | H15: ='Evolutive SFP'!G39 -> 21386718 | I15: ='Evolutive SFP'!H39 -> 21646522 | J15: ='Evolutive SFP'!I39 -> 21819583 | ... AY15: ='Evolutive SFP'!AX39 -> 0
A16: 5.3.2 | B16: Entrance Fees
A17: 5.3.3 | B17: Retained Earnings | C17: ='Evolutive SFP'!B41 -> 351220 | D17: ='Evolutive SFP'!C41 -> 3557811 | E17: ='Evolutive SFP'!D41 -> 15121447 | F17: ='Evolutive SFP'!E41 -> 14903354 | G17: ='Evolutive SFP'!F41 -> 14903354 | H17: ='Evolutive SFP'!G41 -> 14903354 | I17: ='Evolutive SFP'!H41 -> 14903354 | J17: ='Evolutive SFP'!I41 -> 14903354 | ... AY17: ='Evolutive SFP'!AX41 -> 0
