Workbook
Name BALANCE1_LDA01: '[1]Financial Statements'!$E$112
Name BALANCE1_LDA12: '[1]Financial Statements'!$E$123
Name BALANCE2_ILF10: '[2]Financial Statements'!$F$61
Name BALANCE2_ILI10: '[2]Financial Statements'!$F$62
Name BALANCE2_ILP10: '[2]Financial Statements'!$F$63
Name BALANCE2_INI10: '[2]Financial Statements'!$F$65
Name BALANCE2_INI40: '[2]Financial Statements'!$F$66
Name BALANCE2_IO010: '[2]Financial Statements'!$F$68
Name BALANCE2_IQ006: '[2]Financial Statements'!$F$69
Name BALANCE2_IQ009: '[2]Financial Statements'!$F$70
Name BALANCE2_LDA01: '[1]Financial Statements'!$F$112
Name BALANCE2_LDA12: '[1]Financial Statements'!$F$123
Name BALANCE2_XO010: '[2]Financial Statements'!$F$247
Name BALANCE2_XO020: '[2]Financial Statements'!$F$248
Name BALANCE2_XO030: '[2]Financial Statements'!$F$249
Name BALANCE2_XO040: '[2]Financial Statements'!$F$250
Name BALANCE2_XO050: '[2]Financial Statements'!$F$251
Name BALANCE3_ILF10: '[2]Financial Statements'!$G$61
Name BALANCE3_ILI10: '[2]Financial Statements'!$G$62
Name BALANCE3_ILP10: '[2]Financial Statements'!$G$63
Name BALANCE3_INI10: '[2]Financial Statements'!$G$65
Name BALANCE3_INI40: '[2]Financial Statements'!$G$66
Name BALANCE3_IO010: '[2]Financial Statements'!$G$68
Name BALANCE3_IQ006: '[2]Financial Statements'!$G$69
Name BALANCE3_IQ009: '[2]Financial Statements'!$G$70
Name BALANCE3_LDA01: '[1]Financial Statements'!$G$112
Name BALANCE3_LDA12: '[1]Financial Statements'!$G$123
Name BALANCE3_XO010: '[2]Financial Statements'!$G$247
Name BALANCE3_XO020: '[2]Financial Statements'!$G$248
Name BALANCE3_XO030: '[2]Financial Statements'!$G$249
Name BALANCE3_XO040: '[2]Financial Statements'!$G$250
Name BALANCE3_XO050: '[2]Financial Statements'!$G$251
Name BALANCE4_ILF10: '[2]Financial Statements'!$H$61
Name BALANCE4_ILI10: '[2]Financial Statements'!$H$62
Name BALANCE4_ILP10: '[2]Financial Statements'!$H$63
Name BALANCE4_INI10: '[2]Financial Statements'!$H$65
Name BALANCE4_INI40: '[2]Financial Statements'!$H$66
Name BALANCE4_IO010: '[2]Financial Statements'!$H$68
Name BALANCE4_IQ006: '[2]Financial Statements'!$H$69
Name BALANCE4_IQ009: '[2]Financial Statements'!$H$70
Name BALANCE4_LDA01: '[1]Financial Statements'!$H$112
Name BALANCE4_LDA12: '[1]Financial Statements'!$H$123
Name BALANCE4_XO010: '[2]Financial Statements'!$H$247
Name BALANCE4_XO020: '[2]Financial Statements'!$H$248
Name BALANCE4_XO030: '[2]Financial Statements'!$H$249
Name BALANCE4_XO040: '[2]Financial Statements'!$H$250
Name BALANCE4_XO050: '[2]Financial Statements'!$H$251
Name BALANCE5_ILI10: '[2]Financial Statements'!$I$62
Name BALANCE5_ILP10: '[2]Financial Statements'!$I$63
Name BALANCE5_INI10: '[2]Financial Statements'!$I$65
Name BALANCE5_INI40: '[2]Financial Statements'!$I$66
Name BALANCE5_IO010: '[2]Financial Statements'!$I$68
Name BALANCE5_IQ006: '[2]Financial Statements'!$I$69
Name BALANCE5_IQ009: '[2]Financial Statements'!$I$70
Name BALANCE5_LDA01: '[1]Financial Statements'!$I$112
Name BALANCE5_LDA12: '[1]Financial Statements'!$I$123
Name BALANCE5_XO010: '[2]Financial Statements'!$I$247
Name BALANCE5_XO020: '[2]Financial Statements'!$I$248
Name BALANCE5_XO030: '[2]Financial Statements'!$I$249
Name BALANCE5_XO040: '[2]Financial Statements'!$I$250

Sheet Trend
CX1: =12575870-12590309 -> -14439
B2: Nyahururu Umoja(VICTAS) | AW2: =2624555-524911-608151-200000 -> 1291493
C3: Audited Accounts
B4: AUDITED STATEMENTS | C4: 2008 | D4: 2009 | E4: 2010 | F4: 2011 | G4: 2012 | H4: 41609 | I4: 2013 | J4: 41640 | K4: 41671 | L4: 41699 | M4: 41730 | N4: 41760 | O4: 41791 | P4: 41821 | Q4: 41852 | R4: 41883 | S4: 41913 | T4: 41944 | U4: 41974 | V4: Audited 2014 | W4: Jan-15 | X4: Feb-15 | Y4: Mar-15 | Z4: Apr-15 | AA4: 42125 | AB4: 42156 | AC4: 42186 | AD4: 42217 | AE4: 42248 | AF4: 42278 | AG4: 42309 | AH4: 42339 | AI4: 2015 | AJ4: 2015 Rev. | AK4: Jan-16 | AL4: Feb-16 | AM4: Mar-16 | AN4: Apr-16 | AO4: May-16 | AP4: Jun-16 | AQ4: Jul-16 | AR4: Aug-16 | AS4: Sept-16 | AT4: Oct-16 | AU4: Nov-16 | AV4: Dec-16 | AW4: Aud-2016 | AX4: Jan-2017 | AY4: Feb-2017 | AZ4: March-2017 | BA4: Apr-2017 | BB4: May-2017 | BC4: June-2017 | BD4: July-2017 | BE4: 42948 | BF4: 42979 | BG4: 43009 | BH4: 43040 | BI4: 43070 | BJ4: Audited 2017 | BK4: 43101 | BL4: 43132 | BM4: 43160 | BN4: 43191 | BO4: 43221 | BP4: 43252 | BQ4: 43282 | BR4: 43313 | BS4: 43344 | BT4: 43374 | BU4: 43405 | BV4: 43435 | BW4: Audited-2018 | BX4: 43466 | BY4: 43497 | BZ4: 43525 | CA4: 43556 | CB4: 43586 | CC4: 43617 | CD4: 43647 | CE4: 43678 | CF4: 43709 | CG4: 43739 | CH4: 43770 | CI4: 43800 | CJ4: Audited-2019 | CK4: 43831 | CL4: 43862 | CM4: 43891 | CN4: 43922 | CO4: 43952 | CP4: 43983 | CQ4: 44013 | CR4: 44044 | CS4: 44075 | CT4: 44105 | CU4: 44136 | CV4: 44166 | CW4: Audited 2020 | CX4: 44197 | CY4: 44228 | CZ4: 44256 | DA4: 44287 | DB4: 44317 | DC4: 44348 | DD4: 44378 | DE4: 44409 | DF4: 44440 | DG4: 44470 | DH4: 44501 | DI4: 44531 | DJ4: Audited-2021 | DK4: 44562 | DL4: 44593 | DM4: 44621 | DN4: 44652 | DO4: 44682 | DP4: 44713 | DQ4: 44743 | DR4: 44774 | DS4: 44805 | DT4: 44835 | DU4: 44866 | DV4: 44896 | DW4: Audited-22
B5: Cash and Cash Equivalent | C5: =SUM(C6:C7) -> 692551 | D5: =SUM(D6:D7) -> 2050924 | E5: =SUM(E6:E7) -> 1466652 | F5: =SUM(F6:F7) -> 6631870 | G5: =SUM(G6:G7) -> 8447670 | H5: =SUM(H6:H7) -> 15934406 | I5: =SUM(I6:I7) -> 16473429 | J5: =SUM(J6:J7) -> 32498030 | ... DW5: =SUM(DW6:DW7) -> 40136992
B6: Cash in Hand | C6: 692551 | D6: 2050924 | E6: 1466652 | F6: 6631870 | G6: 8447670 | H6: 2072524.5 | I6: 2008272 | J6: 3952137 | K6: 4296961.5 | L6: 1702028.5 | M6: 3522013.5 | N6: 3800938.5 | O6: 1500354 | P6: 3681214 | Q6: 2737510 | R6: 3491663 | S6: 2336673 | T6: 1558098.2 | U6: 1597927 | V6: 1137405 | W6: 915480 | X6: 3071335 | Y6: 3011475 | Z6: 3824566 | AA6: 3938097 | AB6: 2621397 | AC6: 3484317 | AD6: 1825373 | AE6: 1811887 | AF6: 1549902 | AG6: 2789695 | AH6: 3288082 | AI6: 2528402 | AJ6: 2528402 | AL6: 1917754 | AM6: 4252295 | AN6: 4894024 | AO6: 3938097 | AP6: 5868133 | AQ6: 3957008 | AR6: 2552472 | AS6: 3339979 | AU6: 2808257 | AV6: 3022983 | AW6: 7293918 | AZ6: 3171740 | BA6: 6947564 | BB6: 4190221 | BC6: 4580682.2 | BD6: 4758799 | BE6: 3573953 | BF6: 3754606 | BH6: 4123693 | BI6: 5045728 | BJ6: 7387734 | BK6: 11253203 | BL6: 6418620 | BM6: 2929877 | BN6: 5074804 | BO6: 3187375 | BP6: 7767560 | BQ6: 7479361 | BR6: 8108751 | BS6: 7368918 | BT6: 9037659 | BU6: 6226073 | BV6: 4946234 | BW6: 4946324 | BX6: 3045083 | BY6: 2887803 | BZ6: 7680216 | CA6: 9262974 | CB6: 9250689 | CC6: 7124091 | CD6: 6858434.7 | CE6: 3742037 | CF6: 3934900 | CG6: 9111685 | CH6: 9093178 | CI6: 1806997 | CJ6: 1806997 | CK6: 5344394 | CL6: 5530420 | CM6: 4429694 | CN6: 5733045 | CO6: 5974479 | CP6: 3318368 | CQ6: 4470588 | CR6: 5627555 | CS6: 7956958 | CT6: 7956958 | CU6: 2233374 | CV6: 3485128 | CW6: 3485128 | CX6: 6041142 | CY6: 9121646 | CZ6: 8051194 | DA6: 7809168 | DB6: 5914677 | DC6: 4669718 | DD6: 5312352 | DE6: 4928248 | DF6: 7093659 | DG6: 1490080 | DH6: 5745704 | DI6: 4919895 | DJ6: 4919895 | DK6: 4234521 | DL6: 3860966 | DM6: 3933959 | DN6: 3825177 | DO6: 3858834 | DP6: 6253686 | DQ6: 7644156 | DR6: 5409180 | DS6: 4838774 | DT6: 6457883 | DU6: 8296828 | DW6: 3263540
B7: Cash at Bank | H7: 13861882 | I7: =85465+10963752+3064382+196412+155146 -> 14465157 | J7: 28545893 | K7: 12210327 | L7: 13964050 | M7: 11023350 | N7: 12099886 | O7: 15362020 | P7: 14437685 | Q7: 13605351 | R7: 9964819.7 | S7: 9155059.7 | T7: 9222167.4 | U7: 6296735.6 | V7: =16001725-V6-2000000 -> 12864320 | W7: 9240642.4 | X7: 6454678 | Y7: 8711317.3 | Z7: 13393232 | AA7: 15148205 | AB7: 16521579 | AC7: 14371492 | AD7: 8317305.4 | AE7: 8786996.5 | AF7: 7835796 | AG7: 4737561.2 | AH7: 4978470.8 | AI7: =133232+4237489+234544+1012463+230000 -> 5847728 | AJ7: =133232+1012463+4237489+234544+230000 -> 5847728 | AL7: 3484212.8 | AM7: 2922878 | AN7: 4248744.8 | AO7: 15148205 | AP7: 4231632.7 | AQ7: 5836879.8 | AR7: 1712753.4 | AS7: -1311248.1 | AU7: 2310604.2 | AV7: 2434424.3 | AW7: =2189+1916833+378525+168977+7422938+263000+18308+18000000+967548 -> 29138318 | AZ7: 4326626.9 | BA7: 2547320 | BB7: 3964486 | BC7: 5716098 | BD7: 2119693 | BE7: 7161490.3 | BF7: 5839053 | BH7: 6670240.5 | BI7: 5936081 | BJ7: =2273464+227046+245650+135664+1446742+2629031+18798925+8000000+1178716+4000000 -> 38935238 | BK7: 0 | BL7: 9139966 | BM7: 7942942 | BN7: 9414188 | BO7: 11289222 | BP7: 8559990 | BQ7: 12044444 | BR7: 9614472 | BS7: 2916863 | BT7: 3731616 | BU7: 4439296 | BV7: 14296008 | BW7: =57724521-BW6 -> 52778197 | BX7: 13206079 | BY7: 3969436 | BZ7: 9162974 | CA7: 13916816 | CB7: 9658302 | CC7: 10016359 | CD7: 10422915 | CE7: 5322970 | CF7: 10665847 | CG7: 13827291 | CH7: 2839282.7 | CI7: 40604498 | CJ7: 44438914 | CK7: 4240600 | CL7: 32501434 | CM7: 11852066 | CN7: 8944813 | CO7: 20258340 | CP7: 8213449.9 | CQ7: 5904636.1 | CR7: 14145728 | CS7: 8449131.8 | CT7: 8449131.8 | CU7: 8493932.2 | CV7: 13539967 | CW7: =31495404.03-CW6 -> 28010276 | CX7: 12857710 | CY7: 22567860 | CZ7: 12888632 | DA7: 21065300 | DB7: 9029334.8 | DC7: 17089840 | DD7: 8799668.2 | DE7: 10807547 | DF7: 13976813 | DG7: 10562216 | DH7: 9126697 | DI7: 18760462 | DJ7: 26435090 | DK7: 8513746.5 | DL7: 12080379 | DM7: 19882721 | DN7: 7407976.3 | DO7: 5525372 | DP7: 10062639 | DQ7: 11951292 | DR7: 14136732 | DS7: 6092671.7 | DT7: 6327215.8 | DU7: 10155304 | DW7: =40136992-3263540 -> 36873452
B8: Prepayments and Sundry Receivables | C8: 67039 | D8: 42292 | E8: 49508 | F8: 37292 | G8: 85800 | H8: 818633.95 | I8: 85800 | J8: 1606266.4 | K8: 986486.48 | L8: 994092.07 | M8: 937436.37 | N8: 961317.76 | O8: 1101263.8 | P8: 1126434.9 | Q8: 1925528.4 | R8: 2391641.9 | S8: 2913196.8 | T8: 3372932.3 | U8: 906298 | V8: 85800 | W8: 1074825.1 | X8: 1271350.2 | Y8: 1520532.5 | Z8: 1567860.9 | AA8: 1895761.9 | AB8: 2047687.6 | AC8: 2833915.6 | AD8: 3127239.8 | AE8: 2086448.4 | AF8: 1606975.9 | AG8: 2211469 | AH8: 704228.1 | AI8: 85800 | AJ8: 85000 | AL8: 2380719.5 | AM8: 1727893.9 | AN8: 1572852.9 | AO8: 1895761.9 | AP8: 646861.27 | AQ8: 10577806 | AR8: 13238399 | AS8: 14276306 | AU8: 18407906 | AV8: 1429677.6 | AW8: 85800 | AZ8: 0 | BA8: 0 | BB8: 0 | BC8: 0 | BD8: 0 | BE8: 0 | BH8: 0 | BI8: 0 | BJ8: 115800 | BK8: 0 | BL8: 0 | BM8: 0 | BN8: 0 | BO8: 0 | BQ8: 0 | BR8: 0 | BS8: 0 | BT8: 0 | BU8: 0 | BV8: 0 | BW8: 2747143.4 | BX8: 0 | BZ8: 0 | CA8: 0 | CB8: 0 | CC8: 0 | CD8: 0 | CE8: 6681042 | CF8: 7153115.6 | CG8: 7441332 | CH8: 8098898.2 | CI8: 7527188.6 | CJ8: 7527188.6 | CK8: 7250638.6 | CL8: 8115570.8 | CM8: 7825760 | CN8: 11397977 | CO8: 12916310 | CP8: 11613890 | CQ8: 10266776 | CR8: 11024905 | CS8: 11818197 | CT8: 12692546 | CU8: 12210435 | CV8: 9885482.6 | CW8: 9671737.5 | CX8: 9671737.5 | CY8: 9671737.5 | CZ8: 9671737.5 | DA8: 9671737.5 | DB8: 9671737.5 | DC8: 9671737.5 | DD8: 9671737.5 | DE8: 9671737.5 | DF8: 9671737.5 | DG8: 9671737.5 | DH8: 9671737.5 | DI8: 9671737.5 | DJ8: 11288794 | DK8: 15891778 | DL8: 16326724 | DM8: 16663417 | DN8: 16773933 | DO8: 17404531 | DP8: 17848677 | DQ8: 18770995 | DR8: 19474740 | DS8: 19866306 | DT8: 19575118 | DU8: 20514287 | DW8: 15809279
B9: Financial Investments | C9: =SUM(C10:C13) -> 69500 | D9: =SUM(D10:D13) -> 149500 | E9: =SUM(E10:E13) -> 209500 | F9: =SUM(F10:F13) -> 219500 | G9: =SUM(G10:G13) -> 227500 | H9: =SUM(H10:H13) -> 4870491.9 | I9: =SUM(I10:I13) -> 1727686 | J9: =SUM(J10:J13) -> 9740983.7 | ... DW9: =SUM(DW10:DW13) -> 777172
B10: Government Securities | F10: 0 | G10: 0 | H10: 1500000 | I10: 1500000 | J10: 3000000 | K10: 1500000 | L10: 1500000 | M10: 1500000 | N10: 1500000 | O10: 1500000 | P10: 1500000 | Q10: 1500000 | R10: 1500000 | S10: 1500000 | T10: 1500000 | U10: 0 | AA10: 0 | AC10: 0 | AD10: 1500000 | AE10: 1500000 | AF10: 1500000 | AG10: 1500000 | AH10: 1500000 | AI10: 1500000 | AJ10: 1500000 | AL10: 1500000 | AM10: 1500000 | AN10: 1500000 | AP10: 1500000 | AQ10: 1500000 | AR10: 3000000 | AS10: 3000000 | AU10: 3000000 | AV10: 3000000 | AW10: 3000000 | AZ10: 3000000 | BA10: 0 | BB10: 0 | BC10: 0 | BD10: 0 | BE10: 0 | BH10: 0 | BI10: 0 | BK10: 0 | BL10: 0 | BM10: 0 | BN10: 0 | BO10: 0 | BP10: 0 | BQ10: 0 | BR10: 0 | BS10: 0 | BT10: 0 | BU10: 0 | BV10: 0 | BX10: 0 | BY10: 0 | BZ10: 0 | CA10: 0 | CX10: 0 | CY10: 0 | CZ10: 0 | DA10: 0 | DB10: 0 | DC10: 0 | DD10: 0 | DE10: 0 | DF10: 0 | DG10: 0 | DH10: 0 | DI10: 0 | DK10: 0 | DL10: 0 | DM10: 0 | DN10: 0 | DO10: 0 | DP10: 0 | DQ10: 0 | DR10: 0 | DS10: 0 | DT10: 0 | DU10: 0
B11: Other Securities | F11: 0 | H11: 0 | J11: 0 | K11: 0 | L11: 0 | M11: 0 | N11: 0 | O11: 0 | P11: 0 | Q11: 0 | R11: 0 | S11: 0 | T11: 0 | U11: 0 | AA11: 0 | AC11: 0 | AD11: 0 | AE11: 0 | AF11: 0 | AG11: 0 | AH11: 0 | AL11: 0 | AM11: 0 | AN11: 0 | AO11: 0 | AP11: 0 | AQ11: 0 | AR11: 0 | AS11: 0 | AU11: 156440 | AV11: 271415 | AZ11: 3995187.5 | BA11: 952860 | BB11: 783730 | BC11: 0 | BD11: 0 | BE11: 0 | BH11: 0 | BI11: 0 | BK11: 0 | BL11: 0 | BM11: 0 | BN11: 0 | BO11: 0 | BP11: 0 | BQ11: 0 | BR11: 0 | BS11: 0 | BT11: 0 | BU11: 0 | BV11: 0 | BX11: 0 | BY11: 0 | BZ11: 0 | CA11: 0 | CB11: 0 | CC11: 0 | CD11: 0 | CE11: 0 | CF11: 0 | CG11: 0 | CH11: 0 | CI11: 0 | CL11: 0 | CM11: 0 | CN11: 0 | CO11: 0 | CP11: 0 | CR11: 0 | CS11: 0 | CT11: 0 | CU11: 0 | CX11: 0 | CY11: 0 | CZ11: 0 | DA11: 0 | DB11: 0 | DC11: 0 | DD11: 0 | DE11: 0 | DF11: 0 | DG11: 0 | DH11: 0 | DI11: 0 | DK11: 0 | DL11: 0 | DM11: 0 | DN11: 0 | DO11: 0 | DP11: 0 | DQ11: 0 | DR11: 0 | DS11: 0 | DT11: 0 | DU11: 0
B12: Balances with other SACCO Societies | F12: 0 | H12: 3370491.9 | J12: 6740983.7 | K12: 3620491.9 | L12: 3620491.9 | M12: 3620491.9 | N12: 3620491.9 | O12: 3620491.9 | P12: 3728278.5 | Q12: 3840476.5 | R12: 3840476.5 | S12: 3840476.5 | T12: 3840476.5 | U12: 4093866.5 | W12: 4093866.5 | X12: 4093866.5 | Y12: 4093866.5 | Z12: 4218188.2 | AA12: 4218188.2 | AB12: 4218188.2 | AC12: 4218188.2 | AD12: 4218188.2 | AE12: 4218188.2 | AF12: 4218188.2 | AG12: 4538109.1 | AH12: 4750876.5 | AI12: =4540018+19000+10000+100500+148186 -> 4817704 | AJ12: =148186+19000+10000+100500+4540018 -> 4817704 | AL12: 4800876.5 | AM12: 4870876.5 | AN12: 4940876.5 | AO12: 4218188.2 | AP12: 4940876.5 | AQ12: 4940876.5 | AR12: 6869187.5 | AS12: 7190687.5 | AU12: 7442187.5 | AV12: 7995187.5 | AW12: =452749+19000+10000+50500 -> 532249 | AZ12: 647965 | BA12: 9499375 | BB12: 5001187.5 | BC12: 5001187 | BD12: 5504187.5 | BE12: 5755687 | BF12: 5805687 | BH12: 2016991 | BI12: 2066991 | BJ12: 579979 | BK12: 2116991 | BL12: 2216991.9 | BM12: 2216991 | BN12: 2266991 | BO12: 2316491 | BP12: 2316991 | BQ12: 2420636 | BR12: 2470636 | BS12: 2524664 | BT12: 2574664 | BU12: 3094664 | BV12: 2579415.5 | BW12: 580249 | BX12: 2684415 | BY12: 2789415 | BZ12: 3509664 | CA12: 4694661 | CB12: 3659664 | CC12: 3659664 | CD12: 3304415.5 | CE12: 3409415.5 | CF12: 3514415.5 | CG12: 3619415.5 | CH12: 3724415.5 | CI12: 3834415.5 | CJ12: 580249 | CK12: 3939415.5 | CL12: 4044415.5 | CM12: 4149415.5 | CN12: 4254415 | CO12: 4359415.5 | CP12: 36110000 | CQ12: 4579282.8 | CR12: 4702456 | CS12: 4912456 | CT12: 4912456 | CU12: 5017456.7 | CV12: 5122456.7 | CW12: ` | CX12: 5227456.7 | CY12: 5332456.7 | CZ12: 5465456 | DA12: 5596728.9 | DB12: 5702728.3 | DC12: 5806728.3 | DD12: 5911728.3 | DE12: 6016728.3 | DF12: 6121728.3 | DG12: 6121728.3 | DH12: 6121728.3 | DI12: 7441559.3 | DK12: 7578433.8 | DL12: 7578433.8 | DM12: 7578433.8 | DN12: 7578433.8 | DO12: 7878433.8 | DP12: 7978433.8 | DQ12: 8078433.8 | DR12: 8178433.8 | DS12: 8178433.8 | DT12: 8178433.8 | DU12: 8497858.9 | DW12: 777172
B13: Investments in companies | C13: 69500 | D13: 149500 | E13: 209500 | F13: 219500 | G13: 227500 | H13: 0 | I13: =148186+19000+10000+50500+0 -> 227686 | J13: 0 | K13: 0 | L13: 0 | M13: 0 | N13: 0 | O13: 0 | P13: 0 | Q13: 0 | R13: 0 | S13: 0 | T13: 0 | U13: 2000000 | V13: 2227686 | W13: 2000000 | X13: 2000000 | Y13: 2000000 | Z13: 2000000 | AA13: 4000000 | AB13: 4000000 | AC13: 6000000 | AD13: 15000000 | AE13: 15000000 | AF13: 20000000 | AG13: 20000000 | AH13: 17735502 | AI13: 17735502 | AJ13: 17735502 | AL13: 18317067 | AM13: 18317067 | AN13: 0 | AO13: 4000000 | AP13: 0 | AV13: 18000000 | AZ13: 22000000 | BA13: 50004500 | BB13: 25419228 | BC13: 26218898 | BD13: 26318898 | BE13: 26349210 | BF13: 26259891 | BH13: 30259891 | BI13: 28798926 | BK13: 29198925 | BL13: 25198926 | BM13: 25198926 | BN13: 22597206 | BO13: 23302925 | BP13: 19302925 | BQ13: 19409525 | BR13: 27909525 | BS13: 33909525 | BT13: 34909525 | BU13: 38909525 | BV13: 35902865 | BX13: 36425114 | BY13: 41523114 | BZ13: 41780134 | CA13: 34017661 | CB13: 32106659 | CC13: 30937631 | CD13: 32871249 | CE13: 32871249 | CF13: 28652834 | CG13: 25148757 | CH13: 30348756 | CK13: 30320249 | CL13: 10000000 | CM13: 25620249 | CN13: 29620249 | CO13: 20190068 | CP13: 4464415.5 | CQ13: 33618191 | CR13: 28535519 | CS13: 34397489 | CT13: 34397489 | CU13: 36281996 | CV13: 19356085 | CW13: 10580249 | CX13: 19976334 | CY13: 10580249 | CZ13: 11541267 | DA13: 11541267 | DB13: 18541267 | DC13: 18541267 | DD13: 20921017 | DE13: 21541267 | DF13: 21541267 | DG13: 20921018 | DH13: 16541267 | DI13: 10580249 | DJ13: 10777171 | DK13: 16829639 | DL13: 16829639 | DM13: 1829638.7 | DN13: 6829638.7 | DO13: 6829638.7 | DP13: 6829638.7 | DQ13: 6829638.7 | DR13: 6829638.7 | DS13: 10829639 | DT13: 10829639 | DU13: 10905982
B14: Net Loan Portfolio | C14: =C15-C16 -> 2617776 | D14: =D15-D16 -> 6440080 | E14: =E15-E16 -> 16654373 | F14: =F15-F16 -> 26721318 | G14: =G15-G16 -> 34118230 | H14: =H15-H16 -> 48217666 | I14: =I15-I16 -> 48346848 | J14: =J15-J16 -> 98776711 | ... DW14: =DW15-DW16 -> 340435332
B15: Gross Loan Portfolio | C15: 2617776 | D15: 6440080 | E15: 16654373 | F15: 26990740 | G15: 34462859 | H15: 48487088 | I15: =34462859+14368860 -> 48831719 | J15: 99315555 | K15: 51846750 | L15: 53088544 | M15: 56012665 | N15: 56324548 | O15: 57754398 | P15: 59518852 | Q15: 61912067 | R15: 66152643 | S15: 70188955 | T15: 70768398 | U15: 71533981 | V15: 72135405 | W15: 71223638 | X15: 72077931 | Y15: 70362672 | Z15: 71532583 | AA15: 71101461 | AB15: 74317436 | AC15: 75460453 | AD15: 77333983 | AE15: 80295247 | AF15: 78495691 | AG15: 82958722 | AH15: 85166104 | AI15: 89845305 | AJ15: 89845305 | AL15: 89104254 | AM15: 89091773 | AN15: 89091823 | AO15: 71101461 | AP15: 89113099 | AQ15: 98846724 | AR15: 1.0103769e+08 | AS15: 1.0592337e+08 | AU15: 1.0864998e+08 | AV15: 1.1197105e+08 | AW15: 110900703 | AZ15: 1.0803812e+08 | BA15: 2.3738046e+08 | BB15: 1.10904e+08 | BC15: 1.147742e+08 | BD15: 1.1999948e+08 | BE15: 1.20886e+08 | BF15: 120778872 | BH15: 1.2091617e+08 | BI15: 1.2118699e+08 | BJ15: 121040684 | BK15: 1.2296005e+08 | BL15: 129701372 | BM15: 1.3299163e+08 | BN15: 133743755 | BO15: 132448001 | BP15: 136981850 | BQ15: 137779559 | BR15: 135254054 | BS15: 136462545 | BT15: 134162150 | BU15: 138637075 | BV15: 1.3949406e+08 | BW15: 1.3949406e+08 | BX15: 144178769 | BY15: 145023448 | BZ15: 143765225 | CA15: 146169076 | CB15: 158767125 | CC15: 1.6390882e+08 | CD15: 1.6687668e+08 | CE15: 175053653 | CF15: 1.8200531e+08 | CG15: 1.8822493e+08 | CH15: 1.9554765e+08 | CI15: 1.9441609e+08 | CJ15: 1.9441609e+08 | CK15: =CK16+193554184 -> 204144493 | CL15: 2.0049904e+08 | CM15: 2.0078144e+08 | CN15: 200576944 | CO15: 1.9792202e+08 | CP15: 207508084 | CQ15: 2.1203643e+08 | CR15: 2.1480735e+08 | CS15: 220509733 | CT15: 220509733 | CU15: 2.3114986e+08 | CV15: 244834214 | CW15: 2.4487058e+08 | CX15: 2.5019748e+08 | CY15: 2.5662217e+08 | CZ15: 2.5883019e+08 | DA15: 2.5470893e+08 | DB15: 2.6641078e+08 | DC15: 2.7551335e+08 | DD15: 2.8723039e+08 | DE15: 2.9256186e+08 | DF15: 2.948748e+08 | DG15: 2.9649364e+08 | DH15: 3.0807217e+08 | DI15: 3.05658e+08 | DJ15: 305657997 | DK15: 3.0997454e+08 | DL15: 3.1480338e+08 | DM15: 3.1467198e+08 | DN15: 3.2540896e+08 | DO15: 3.2880795e+08 | DP15: 3.2967017e+08 | DQ15: 3.3173253e+08 | DR15: 3.3652744e+08 | DS15: 3.4683106e+08 | DT15: 3.5043062e+08 | DU15: 3.517363e+08 | DW15: 358511202
B16: Allowance for Loan Loss | F16: 269422 | G16: 344629 | H16: 269422 | I16: 484871 | J16: 538844 | K16: 269422 | L16: 269422 | M16: 269422 | N16: 269422 | O16: 269422 | P16: 269422 | Q16: 269422 | R16: 269422 | S16: 269422 | T16: 269422 | U16: 0 | V16: 1993646 | W16: 2400000 | X16: 2400000 | Y16: 2400000 | Z16: 2400000 | AA16: 2400000 | AB16: 2400000 | AC16: 2400000 | AD16: 2400000 | AE16: 2400000 | AF16: 2400000 | AG16: 2400000 | AH16: 2400000 | AI16: 124089 | AJ16: 1869557 | AL16: 2400000 | AM16: 2400000 | AN16: 2400000 | AO16: -2400000 | AP16: 2400000 | AQ16: 2400000 | AR16: 2400000 | AS16: 2400000 | AU16: 2400000 | AV16: 3292568 | AW16: 6590309 | AZ16: 3292568 | BA16: 6585136 | BB16: 3292568 | BC16: 6599370 | BD16: 6874356.8 | BE16: 7387204.2 | BF16: 6178186 | BH16: 5771304.2 | BI16: 5838260.9 | BJ16: 8590309 | BK16: 0 | BL16: 5921870 | BM16: 7256136 | BN16: 6949166 | BO16: 7183267 | BP16: 7556873 | BQ16: 8948946 | BR16: 8619319 | BS16: 7902398 | BT16: 7949409 | BU16: 8452644 | BV16: 9590309 | BX16: 9590309 | BY16: 9590309 | BZ16: 9590309 | CA16: 9590309 | CB16: 9590309 | CC16: 9590309 | CD16: 9576686 | CE16: 9576686 | CF16: 9576686 | CG16: 9576686 | CH16: 9576686 | CI16: 10590309 | CJ16: 10590309 | CK16: ='[3]balance sheet'!$D$22 -> 10590309 | CL16: ='[4]balance sheet'!$D$22 -> 10590309 | CM16: 10590309 | CN16: 10590309 | CO16: ='[4]balance sheet'!$D$22 -> 10590309 | CP16: 10576686 | CQ16: 10576686 | CR16: 10575870 | CS16: 10575870 | CT16: 10575870 | CU16: 10575870 | CV16: 12575870 | CW16: 12575870 | CX16: 12575870 | CY16: 12575870 | CZ16: 12575870 | DA16: 12575870 | DB16: 12575870 | DC16: 12575870 | DD16: 12075870 | DE16: 12075870 | DF16: 12075870 | DG16: 12075870 | DH16: 12075870 | DI16: 14575870 | DJ16: 14575870 | DK16: 12075870 | DL16: 14075870 | DM16: 14075870 | DN16: 14075870 | DO16: 14075870 | DP16: 14075870 | DQ16: 14075870 | DR16: 14575870 | DS16: 14575870 | DT16: 14575870 | DU16: 14575870 | DW16: 18075870
B17: Account Receivables | C17: =SUM(C18:C20) -> 0 | D17: =SUM(D18:D20) -> 0 | E17: =SUM(E18:E20) -> 0 | F17: =SUM(F18:F20) -> 0 | G17: =SUM(G18:G20) -> 0 | H17: =SUM(H18:H20) -> 0 | I17: =SUM(I18:I20) -> 0 | J17: =SUM(J18:J20) -> 0 | ... S17: =SUM(S18:S20) -> 0 | AA17: 0 | AB17: 0 | AC17: 0 | AZ17: 0 | BA17: 0 | BB17: 0 | BC17: 0 | BD17: 0 | BE17: 0 | BH17: 0 | BI17: 115800 | BK17: 0 | BL17: 0 | BM17: 0 | BN17: 0 | BO17: 0 | BP17: 0 | BQ17: 0 | BR17: 0 | BS17: 0 | BT17: 0 | BU17: 0 | BV17: 0 | BX17: 0 | BY17: 0 | BZ17: 0 | CA17: 0 | CB17: 0 | CC17: 0 | CD17: 0 | CE17: 0 | CF17: 0 | CG17: 0 | CH17: 0 | CI17: 0 | DS17: 0 | DT17: 0 | DU17: 0
B18: Tax Recoverable | G18: 0 | AA18: 0 | AB18: 0 | AC18: 0 | AZ18: 0 | BA18: 0 | BB18: 0 | BC18: 0 | BD18: 0 | BE18: 0 | BH18: 0 | BI18: 0 | BK18: 0 | BL18: 0 | BM18: 0 | BN18: 0 | BO18: 0 | BP18: 0 | BQ18: 0 | BR18: 0 | BS18: 0 | BT18: 0 | BU18: 0 | BV18: 0 | BX18: 0 | BY18: 0 | BZ18: 0 | CA18: 0 | CB18: 0 | CC18: 0 | CD18: 0 | CE18: 0 | CF18: 0 | CG18: 0 | CH18: 0 | CI18: 0 | CJ18: 0 | CK18: 0 | CL18: 0 | CM18: 0 | CN18: 0 | CO18: 0 | CP18: 0 | CR18: 0 | CS18: 0 | CT18: 0 | CU18: 0 | CV18: 0 | CW18: 0 | CX18: 0 | CY18: 0 | CZ18: 0 | DA18: 0 | DB18: 0 | DC18: 0 | DD18: 0 | DE18: 0 | DF18: 0 | DG18: 0 | DH18: 0 | DI18: 0 | DK18: 0 | DL18: 0 | DM18: 0 | DN18: 0 | DO18: 0 | DP18: 0 | DQ18: 0 | DR18: 0 | DS18: 0 | DT18: 0 | DU18: 0
B19: Deferred Tax Assets | G19: 0 | AA19: 0 | AB19: 0 | AC19: 0 | AZ19: 0 | BA19: 0 | BB19: 0 | BC19: 0 | BD19: 0 | BE19: 0 | BH19: 0 | BI19: 115800 | BK19: 0 | BL19: 0 | BM19: 0 | BN19: 0 | BO19: 0 | BP19: 0 | BQ19: 0 | BR19: 0 | BS19: 0 | BT19: 0 | BU19: 0 | BV19: 0 | BX19: 0 | BY19: 0 | BZ19: 0 | CA19: 0 | CB19: 0 | CC19: 0 | CD19: 0 | CE19: 0 | CF19: 0 | CG19: 0 | CH19: 0 | CI19: 0 | CJ19: 0 | CK19: 0 | CL19: 0 | CM19: 0 | CN19: 0 | CO19: 0 | CP19: 0 | CR19: 0 | CS19: 0 | CT19: 0 | CU19: 0 | CV19: 0 | CW19: 0 | CX19: 0 | CY19: 0 | CZ19: 0 | DA19: 0 | DB19: 0 | DC19: 0 | DD19: 0 | DE19: 0 | DF19: 0 | DG19: 0 | DH19: 0 | DI19: 0 | DK19: 0 | DL19: 0 | DM19: 0 | DN19: 0 | DO19: 0 | DP19: 0 | DQ19: 0 | DR19: 0 | DS19: 0 | DT19: 0 | DU19: 0
B20: Retirement Benefit Assets | G20: 0 | AA20: 0 | AB20: 0 | AC20: 0 | AZ20: 0 | BA20: 0 | BB20: 0 | BC20: 0 | BD20: 0 | BE20: 0 | BF20: 12194820 | BH20: 12934820 | BI20: 12943020 | BK20: 0 | BL20: 0 | BM20: 0 | BN20: 0 | BO20: 0 | BP20: 0 | BQ20: 0 | BR20: 0 | BS20: 0 | BT20: 0 | BU20: 0 | BV20: 0 | BX20: 0 | BY20: 0 | BZ20: 0 | CA20: 0 | CB20: 0 | CC20: 0 | CD20: 0 | CE20: 0 | CF20: 0 | CG20: 0 | CH20: 0 | CI20: 0 | CJ20: 0 | CK20: 0 | CL20: 0 | CM20: 0 | CN20: 0 | CO20: 0 | CP20: 0 | CR20: 0 | CS20: 0 | CT20: 0 | CU20: 0 | CV20: 0 | CW20: 0 | CX20: 0 | CY20: 0 | CZ20: 0 | DA20: 0 | DB20: 0 | DC20: 0 | DD20: 0 | DE20: 0 | DF20: 0 | DG20: 0 | DH20: 0 | DI20: 0 | DK20: 0 | DL20: 0 | DM20: 0 | DN20: 0 | DO20: 0 | DP20: 0 | DQ20: 0 | DR20: 0 | DS20: 0 | DT20: 0 | DU20: 0
B21: Property and Equipment and Other Assets | C21: =SUM(C22:C26) -> 28544 | D21: =SUM(D22:D26) -> 67851 | E21: =SUM(E22:E26) -> 635468 | F21: =SUM(F22:F26) -> 2039439 | G21: =SUM(G22:G26) -> 5403162 | H21: =SUM(H22:H26) -> 5517271 | I21: =SUM(I22:I26) -> 4750838 | J21: =SUM(J22:J26) -> 11034542 | ... DW21: =SUM(DW22:DW26) -> 17961747
B22: Investment Properties | F22: 0 | G22: 0 | H22: 0 | J22: 0 | K22: 0 | L22: 0 | M22: 0 | N22: 0 | O22: 0 | P22: 0 | Q22: 0 | R22: 0 | S22: 0 | T22: 0 | U22: 0 | AA22: 0 | AB22: 0 | AC22: 0 | AZ22: 0 | BA22: 0 | BB22: 0 | BC22: 0 | BD22: 0 | BE22: 0 | BH22: 0 | BI22: 0 | BK22: 0 | BL22: 0 | BM22: 0 | BN22: 0 | BO22: 0 | BP22: 0 | BQ22: 0 | BR22: 0 | BS22: 0 | BU22: 0 | BV22: 0 | BX22: 0 | BY22: 0 | BZ22: 0 | CA22: 0 | CG22: 18105795 | CL22: 0 | CM22: 0 | CN22: 0 | CO22: 0 | CP22: 620249 | CQ22: 620249 | CR22: 620249 | CS22: 620249 | CT22: 620249 | CU22: 620249 | CV22: 580249 | CX22: 0 | CY22: 0 | CZ22: 0 | DA22: 0 | DB22: 0 | DC22: 0 | DD22: 0 | DE22: 0 | DF22: 0 | DG22: 0 | DH22: 0 | DI22: 0 | DK22: 0 | DL22: 0 | DM22: 0 | DN22: 0 | DO22: 0 | DP22: 620249 | DQ22: 620249 | DR22: 620249 | DS22: 620249 | DT22: 620249 | DU22: 620249
B23: Property and Equipment | C23: 28544 | D23: 67851 | E23: 609253 | F23: 691887 | G23: 4364687 | H23: 5375271 | I23: 4109038 | J23: 10750542 | K23: 5385636 | L23: 5385921 | M23: 5385921 | N23: 5397921 | O23: 5397921 | P23: 5397921 | Q23: 5517646 | R23: 5517646 | S23: 5623836 | T23: 5648766 | U23: 5671916 | V23: 4161589 | W23: 5709813 | X23: 5710413 | Y23: 5710688 | Z23: 5766068 | AA23: 5789568 | AB23: 5794678 | AC23: 5897898 | AD23: 5898098 | AE23: 5903168 | AF23: 6350418 | AG23: 6398798 | AH23: 6445228 | AI23: 4710275 | AJ23: 4710275 | AL23: 6517848 | AM23: 6538198 | AN23: 6547478 | AO23: 5789568 | AP23: 6707718 | AQ23: 6834418 | AR23: 6900800 | AS23: 6958800 | AU23: 7476357 | AV23: 7487007 | AW23: 5040538 | AZ23: 11040351 | BA23: 22128162 | BB23: 11080881 | BC23: 11423155 | BD23: 11287581 | BE23: 11365081 | BF23: 11792846 | BH23: 12512496 | BI23: 12513496 | BJ23: 9322504 | BK23: 12546470 | BL23: 12560046 | BM23: 12734146 | BN23: 12734146 | BO23: 13044888 | BP23: 13103178 | BQ23: 13125688 | BR23: 13195688 | BS23: 13201553 | BT23: 13201503 | BU23: 15977003 | BV23: 14409716 | BW23: 7872296.5 | BX23: 9244217 | BY23: 9244217 | BZ23: 9244217 | CA23: 23082854 | CB23: 17283839 | CC23: 19647299 | CD23: 19647299 | CE23: 17412276 | CF23: 17514216 | CG23: 0 | CH23: 18105795 | CI23: 9082567.9 | CJ23: 9656041.9 | CK23: 18272342 | CL23: 18272342 | CM23: 18272342 | CN23: 16423411 | CO23: 18650308 | CP23: 19012158 | CQ23: 19012158 | CR23: 19012158 | CS23: 19012158 | CT23: 19012158 | CU23: 16129752 | CV23: 10887952 | CW23: 10887952 | CX23: 19125047 | CY23: 19125047 | CZ23: 19125047 | DA23: 19125047 | DB23: 19466087 | DC23: 19466087 | DD23: 19721987 | DE23: 19721987 | DF23: 19721987 | DG23: 19735180 | DH23: 19735180 | DI23: 10208042 | DJ23: 10470169 | DK23: 10208042 | DL23: 10470169 | DM23: 10470169 | DN23: 10470169 | DO23: 10470169 | DP23: 12041267 | DQ23: 12041267 | DR23: 12273365 | DS23: 12273365 | DT23: 12403665 | DU23: 12403665 | DW23: 11312245
B24: Prepaid lease rentals | E24: 26215 | F24: 947552 | H24: 0 | J24: 0 | K24: 0 | L24: 0 | M24: 0 | N24: 0 | O24: 0 | P24: 0 | Q24: 0 | R24: 0 | S24: 0 | T24: 0 | U24: 0 | AA24: 0 | AB24: 0 | AC24: 0 | AD24: 0 | AE24: 0 | AF24: 0 | AG24: 0 | AH24: 0 | AL24: 0 | AM24: 0 | AN24: 0 | AO24: 0 | AP24: 0 | AQ24: 0 | AR24: 0 | AS24: 0 | AU24: 0 | AV24: 0 | AZ24: 0 | BA24: 0 | BB24: 0 | BC24: 0 | BD24: 0 | BE24: 0 | BH24: 0 | BI24: 0 | BK24: 0 | BL24: 0 | BM24: 0 | BN24: 0 | BO24: 0 | BP24: 0 | BQ24: 0 | BR24: 0 | BS24: 0 | BT24: 0 | BU24: 0 | BV24: 0 | BX24: 0 | BY24: 0 | BZ24: 0 | CA24: 0 | CK24: 0 | CL24: 0 | CM24: 0 | CN24: 0 | CO24: 0 | CP24: 0 | CQ24: 0 | CR24: 0 | CS24: 0 | CT24: 0 | CU24: 0 | CX24: 0 | CY24: 0 | CZ24: 0 | DA24: 0 | DB24: 0 | DC24: 0 | DD24: 0 | DE24: 0 | DF24: 0 | DG24: 0 | DH24: 0 | DI24: 0 | DK24: 0 | DL24: 0 | DM24: 0 | DN24: 0 | DO24: 0 | DP24: 0 | DQ24: 0 | DR24: 0 | DS24: 0 | DT24: 0 | DU24: 0
B25: Intangible Assets | F25: 0 | G25: 490000 | H25: 142000 | I25: 343000 | J25: 284000 | K25: 142000 | L25: 142000 | M25: 142000 | N25: 142000 | O25: 142000 | P25: 142000 | Q25: 142000 | R25: 142000 | S25: 142000 | T25: 142000 | U25: 142000 | V25: 273000 | W25: 142000 | X25: 142000 | Y25: 142000 | Z25: 142000 | AA25: 142000 | AB25: 142000 | AC25: 142000 | AD25: 142000 | AE25: 142000 | AF25: 142000 | AG25: 142000 | AH25: 142000 | AI25: 191100 | AJ25: 191100 | AL25: 142000 | AM25: 142000 | AN25: 142000 | AO25: 142000 | AP25: 142000 | AQ25: 142000 | AR25: 142000 | AS25: 142000 | AU25: 142000 | AV25: 142000 | AW25: 133770 | AZ25: 142000 | BA25: 284000 | BB25: 142000 | BC25: 142000 | BD25: 201000 | BE25: 201000 | BF25: 201000 | BH25: 201000 | BI25: 201000 | BJ25: 93639 | BK25: 201000 | BL25: 201000 | BM25: 201000 | BN25: 201000 | BO25: 201000 | BP25: 201000 | BQ25: 201000 | BR25: 201000 | BS25: 201000 | BT25: 201000 | BU25: 201000 | BV25: 201000 | BW25: 4323488 | BX25: 5936000 | BY25: 5936000 | BZ25: 5936000 | CA25: 5936000 | CB25: 5536000 | CC25: 5936000 | CD25: 5936000 | CE25: 5978500 | CF25: 5978500 | CG25: 5978500 | CH25: 5978500 | CI25: 4323488 | CJ25: 4650553 | CK25: 4565553 | CL25: 4565553 | CM25: 4565553 | CN25: 6021000 | CO25: 4565553 | CP25: 6021000 | CQ25: 6021000 | CR25: 6021000 | CS25: 6395076.1 | CT25: 6395076.1 | CU25: 6395076.1 | CV25: 4783235.9 | CW25: 4783235.9 | CX25: 6609738 | CY25: 6609738 | CZ25: 6609738 | DA25: 6609738 | DB25: 6609738 | DC25: 6609738 | DD25: 6703675.2 | DE25: 6703675.2 | DF25: 6703675.2 | DG25: 6703675.2 | DH25: 6703675.2 | DI25: 5304912.3 | DJ25: 5304912 | DK25: 5304912.3 | DL25: 5304912.3 | DM25: 5304912.3 | DN25: 6004912.3 | DO25: 6004912.3 | DP25: 6704412.3 | DQ25: 6609738.2 | DR25: 6609738.2 | DS25: 6609738.2 | DT25: 6609738.2 | DU25: 6609738.2 | DW25: 6383993
B26: Other Assets | F26: 400000 | G26: 548475 | H26: 0 | I26: 298800 | J26: 0 | K26: 0 | L26: 0 | M26: 0 | N26: 0 | O26: 0 | P26: 0 | Q26: 0 | R26: 0 | S26: 0 | T26: 0 | U26: 0 | V26: 398800 | AA26: 0 | AB26: 0 | AC26: 0 | AI26: =398800+309647 -> 708447 | AJ26: 398800 | AM26: 93900 | AN26: 148400 | AP26: 148400 | AQ26: 148400 | AR26: 148400 | AS26: 148400 | AU26: 173274 | AV26: 173274 | AW26: 398800 | AZ26: 173274 | BA26: 400548 | BB26: 200274 | BC26: 26745740 | BD26: 200274 | BE26: 200974 | BF26: 200974 | BH26: 221324 | BI26: 228524 | BJ26: 398800 | BK26: 228524 | BL26: 233024 | BM26: 233024 | BN26: 233024 | BO26: 233024 | BP26: 233024 | BQ26: 233024 | BR26: 233024 | BS26: 233024 | BT26: 233024 | BU26: 233024 | BV26: 233024 | BW26: 398800 | BX26: 233024 | BY26: 233024 | BZ26: 233024 | CA26: 233024 | CB26: 233024 | CC26: 233024 | CD26: 233024 | CE26: 233024 | CF26: 233024 | CG26: 233024 | CH26: 233024 | CJ26: 398800 | CK26: ='[4]balance sheet'!$D$14 -> 398800 | CL26: ='[4]balance sheet'!$D$14 -> 398800 | CM26: 398800 | CN26: 233024 | CO26: ='[4]balance sheet'!$D$14 -> 398800 | CP26: ='[4]balance sheet'!$D$14 -> 398800 | CQ26: ='[4]balance sheet'!$D$14 -> 398800 | CR26: ='[4]balance sheet'!$D$14 -> 398800 | CS26: 283308 | CT26: 283308 | CU26: 283308 | CV26: 283308 | CW26: 283308 | CX26: 283308 | CY26: 283308 | CZ26: 283308 | DA26: 283308 | DB26: 283308 | DC26: 283308 | DD26: 233024 | DE26: 233024 | DF26: 233024 | DG26: 233024 | DH26: 233024 | DI26: 283009 | DJ26: 283009 | DK26: 233024 | DL26: 233024 | DM26: 233024 | DN26: 233024 | DO26: 233024 | DP26: 233024 | DQ26: 233024 | DR26: 233024 | DS26: 233024 | DT26: 233024 | DU26: 233024 | DW26: 265509
B27: Total Assets | C27: =C5+C8+C9+C14+C17+C21 -> 3475410 | D27: =D5+D8+D9+D14+D17+D21 -> 8750647 | E27: =E5+E8+E9+E14+E17+E21 -> 19015501 | F27: =F5+F8+F9+F14+F17+F21 -> 35649419 | G27: =G5+G8+G9+G14+G17+G21 -> 48282362 | H27: =H5+H8+H9+H14+H17+H21 -> 75358469 | I27: =I5+I8+I9+I14+I17+I21 -> 71384601 | J27: =J5+J8+J9+J14+J17+J21 -> 1.5365653e+08 | ... DW27: =DW5+DW8+DW9+DW14+DW17+DW21 -> 415120522
B28: Savings Deposits | C28: 97922 | D28: 531852 | E28: 1324050 | F28: 2594007 | G28: 8012418 | H28: 1189925 | I28: 11468318 | J28: 2349166 | K28: 1377625.3 | L28: 1278331.3 | M28: 1328033.3 | N28: 1329475.3 | O28: 1518621.8 | P28: 2012881.1 | Q28: 2302081.1 | R28: 1783425.1 | S28: 2105182.1 | T28: 2012095.1 | U28: 1983098.5 | V28: 17644747 | W28: 2198601 | X28: 1844070.5 | Y28: 2343143.5 | Z28: 2214796.5 | AA28: 3183600.5 | AB28: 1848801.5 | AC28: 2550142.5 | AD28: 3045696.5 | AE28: 3176476.5 | AF28: 2945999.5 | AG28: 3315428.5 | AH28: 3139236.5 | AI28: 31883601 | AJ28: 29828486 | AL28: 4912377.5 | AM28: 4912377.5 | AN28: 4912377.5 | AO28: 3183600.5 | AP28: 4912377.5 | AQ28: 4912377.5 | AR28: 4912377.5 | AS28: 4912377.5 | AU28: 4912377.5 | AV28: 29192642 | AW28: 30360370 | AZ28: -29198403 | BA28: -64185018 | BB28: 33494205 | BC28: 25201033 | BD28: 23344433 | BE28: 25309217 | BF28: 25532401 | BH28: 26278985 | BI28: 22442805 | BJ28: 28384296 | BK28: 9580252 | BL28: 28082298 | BM28: 28008192 | BN28: 28859163 | BO28: 25848317 | BP28: 27772412 | BQ28: 27420646 | BR28: 27389852 | BS28: 26153082 | BT28: 24495777 | BU28: 27357755 | BV28: 26798754 | BW28: 26798753 | BX28: 30867006 | BY28: 25344162 | BZ28: 30618493 | CA28: 26162355 | CB28: 32755176 | CC28: 33545089 | CD28: 33829353 | CE28: 33520751 | CF28: 36163642 | CG28: 34149048 | CH28: 34248882 | CI28: 30780081 | CJ28: 36226840 | CK28: 35092536 | CL28: 35675590 | CM28: 34961927 | CN28: 36238363 | CO28: 35279535 | CP28: 40183834 | CQ28: 35234293 | CR28: 36706312 | CS28: 37542853 | CT28: 37542853 | CU28: 37406573 | CV28: 30684412 | CW28: 42490601 | CX28: 40356510 | CY28: 44126736 | CZ28: 44833373 | DA28: 44757038 | DB28: 43973474 | DC28: 45969818 | DD28: 47515134 | DE28: 48225265 | DF28: 54158548 | DG28: 44673424 | DH28: 46899778 | DI28: 43754701 | DJ28: 53205532 | DK28: 47784080 | DL28: 46326760 | DM28: 47641337 | DN28: 51852990 | DO28: 46366800 | DP28: 46819844 | DQ28: 46161312 | DR28: 46858158 | DS28: 44492963 | DT28: 46474692 | DU28: 47956549 | DW28: 42297148
B29: Short Term Deposits | F29: 0 | G29: 0 | H29: 1013916 | J29: 2030127 | K29: 1016211 | L29: 1016211 | M29: 1016211 | N29: 1016211 | O29: 1016211 | P29: 1016211 | Q29: 1016211 | R29: 1016211 | S29: 1016211 | T29: 1016211 | U29: 1016211 | W29: 1016211 | X29: 1016211 | Y29: 1016211 | Z29: 1016211 | AA29: 1016211 | AB29: 1016211 | AC29: 1016211 | AD29: 1016211 | AE29: 1016211 | AF29: 1016211 | AG29: 1016211 | AH29: 1016211 | AL29: 1016211 | AM29: 1016211 | AN29: 1016211 | AO29: 1016211 | AP29: 1016211 | AQ29: 1016211 | AR29: 1016211 | AS29: 1016211 | AU29: 1016211 | AV29: 1159711 | AZ29: -1475411 | BA29: 3605506 | BB29: 1782753 | BC29: 3148622 | BD29: 8668392.7 | BE29: 9277616.8 | BF29: 9862176.3 | BH29: 7066568.6 | BI29: 9132841.2 | BK29: 24370316 | BL29: 9395007 | BM29: 10169515 | BN29: 8778393 | BO29: 7731382 | BP29: 7631577 | BQ29: 8317507 | BR29: 10195866 | BS29: 10234420 | BT29: 9926187 | BU29: 9191558 | BV29: 0 | BX29: 8600445 | BY29: 8176402 | BZ29: 9164766 | CA29: 9164766 | CB29: 10717396 | CC29: 11124406 | CD29: 10098770 | CE29: 10279538 | CF29: 11160511 | CG29: 11377844 | CH29: 11248874 | CI29: 5037258.6 | CK29: 10582010 | CL29: 10863676 | CM29: 11904692 | CN29: 12897686 | CO29: 12194355 | CP29: 14785157 | CQ29: 14184351 | CR29: 14835886 | CS29: 15177331 | CT29: 15177331 | CU29: 14977595 | CV29: 11806189 | CX29: 14977223 | CY29: 14874509 | CZ29: 15219389 | DA29: 14921329 | DB29: 15617402 | DC29: 15532941 | DD29: 16514934 | DE29: 14574735 | DF29: 14527331 | DG29: 17544251 | DH29: 18873175 | DI29: 8790669.6 | DK29: 12549488 | DL29: 9442322.9 | DM29: 12515784 | DN29: 7610901.4 | DO29: 8428823.2 | DP29: 13122261 | DQ29: 13735453 | DR29: 10632718 | DS29: 10933569 | DT29: 11827028 | DU29: 11884327 | DW29: 16839455
B30: Non withdrawable Deposits | C30: 2181426 | D30: 5388952 | E30: 7001000 | F30: 14533589 | G30: 21381443 | H30: 43845984 | I30: 32277459 | J30: 89972427 | K30: 46620951 | L30: 49122630 | M30: 50342190 | N30: 50954933 | O30: 52579322 | P30: 54490771 | Q30: 55824059 | R30: 57102659 | S30: 59031894 | T30: 58627230 | U30: 59062799 | V30: 44483332 | W30: 60320341 | X30: 59372074 | Y30: 62934368 | Z30: 65395641 | AA30: 67369388 | AB30: 70695032 | AC30: 69971662 | AD30: 72391511 | AE30: 75061343 | AF30: 77676333 | AG30: 79274547 | AH30: 79342488 | AI30: 61929319 | AJ30: 61929319 | AL30: 82076780 | AM30: 82076780 | AN30: 82089980 | AO30: 67369388 | AP30: 82103180 | AQ30: 81999260 | AR30: 82007260 | AS30: 82020260 | AU30: 82034260 | AV30: 77417125 | AW30: 81840305 | AZ30: -83429354 | BA30: -1.845848e+08 | BB30: 91498367 | BC30: 91694235 | BD30: 93266976 | BE30: 95468682 | BF30: 93033255 | BH30: 94525854 | BI30: 92858060 | BJ30: 92858059 | BK30: 96054149 | BL30: 96140020 | BM30: 98721123 | BN30: 100460695 | BO30: 101546557 | BP30: 102510413 | BQ30: 103917025 | BR30: 106196242 | BS30: 107388717 | BT30: 109324774 | BU30: 109324774 | BV30: 111455182 | BW30: 1.1145518e+08 | BX30: 113743409 | BY30: 114087828 | BZ30: 116889196 | CA30: 119824972 | CB30: 123846171 | CC30: 126507301 | CD30: 130121236 | CE30: 1.3331167e+08 | CF30: 1.3696544e+08 | CG30: 1.3896911e+08 | CH30: 1.4111165e+08 | CI30: 35817340 | CJ30: 1.3914883e+08 | CK30: 1.433023e+08 | CL30: 1.465425e+08 | CM30: 149802524 | CN30: 152117541 | CO30: 1.5393335e+08 | CP30: 1.5629047e+08 | CQ30: 1.5882949e+08 | CR30: 161473507 | CS30: 1.6634508e+08 | CT30: 1.6634508e+08 | CU30: 1.6900733e+08 | CV30: 1.7075954e+08 | CW30: 1.7075954e+08 | CX30: 1.7421812e+08 | CY30: 1.77314e+08 | CZ30: 1.8102102e+08 | DA30: 1.8265193e+08 | DB30: 1.8597832e+08 | DC30: 1.8844333e+08 | DD30: 1.918884e+08 | DE30: 1.9481076e+08 | DF30: 1.9720545e+08 | DG30: 1.9800797e+08 | DH30: 2.014376e+08 | DI30: 1.9872373e+08 | DJ30: 198723727 | DK30: 1.9876393e+08 | DL30: 2.0261319e+08 | DM30: 2.0705445e+08 | DN30: 2.0941105e+08 | DO30: 2.12208e+08 | DP30: 2.1481892e+08 | DQ30: 217682182 | DR30: 2.1984675e+08 | DS30: 2.2445341e+08 | DT30: 2.2629534e+08 | DU30: 2.29864e+08 | DW30: 226107824
B31: Total Deposit Liabilities | C31: =SUM(C28:C30) -> 2279348 | D31: =SUM(D28:D30) -> 5920804 | E31: =SUM(E28:E30) -> 8325050 | F31: =SUM(F28:F30) -> 17127596 | G31: =SUM(G28:G30) -> 29393861 | H31: =SUM(H28:H30) -> 46049825 | I31: =SUM(I28:I30) -> 43745777 | J31: =SUM(J28:J30) -> 94351720 | ... DW31: =SUM(DW28:DW30) -> 285244427
B32: Accounts Payable Other Liabilities | C32: =SUM(C33:C38) -> 756201 | D32: =SUM(D33:D38) -> 2092982 | E32: =SUM(E33:E38) -> 1853609 | F32: =SUM(F33:F38) -> 6664957 | G32: =SUM(G33:G38) -> 2958353 | H32: =SUM(H33:H38) -> 4033865 | I32: =SUM(I33:I38) -> 7334465 | J32: =SUM(J33:J38) -> 8185123.3 | ... DW32: =SUM(DW33:DW38) -> 32358567
B33: Tax Payable | F33: 7092 | G33: 5134 | H33: 0 | J33: 0 | K33: 0 | L33: 0 | M33: 0 | N33: 0 | O33: 0 | P33: 0 | Q33: 0 | R33: 0 | S33: 0 | T33: 0 | U33: 0 | V33: 4862 | AA33: 0 | AB33: 0 | AC33: 0 | AH33: 0 | AI33: 3866 | AJ33: 3866 | AW33: 305555 | AZ33: 0 | BA33: 0 | BB33: 0 | BC33: 0 | BD33: 0 | BE33: 0 | BF33: 0 | BH33: 0 | BI33: 0 | BJ33: 302193.2 | BK33: 302193 | BL33: 302193 | BM33: 0 | BN33: 0 | BO33: 0 | BP33: 0 | BQ33: 0 | BR33: 0 | BS33: 0 | BT33: 0 | BU33: 0 | BV33: 218211 | BW33: 218211.94 | BX33: 0 | BY33: 0 | BZ33: 0 | CA33: 0 | CJ33: 381333.67 | CK33: 381333.67 | CL33: 381333.67 | CM33: 381333.67 | CN33: 381333.67 | CU33: 0 | CV33: 368496.03 | CW33: 368496.03 | CX33: 368496.03 | CY33: 368496.03 | CZ33: 0 | DA33: 0 | DB33: 0 | DC33: 0 | DD33: 44702.03 | DE33: 47336.4 | DF33: 62669.58 | DG33: 70668.44 | DH33: 52908.43 | DI33: 726933.25 | DJ33: 726933 | DK33: 726933.25 | DL33: 726933.25 | DM33: 819744.25 | DN33: 0 | DO33: 0 | DP33: 0 | DQ33: 0 | DR33: 0 | DS33: 0 | DT33: 0 | DU33: 0 | DW33: 322500
B34: Dividends Payable | C34: 255924 | D34: 457806 | E34: 1138470 | F34: 1380040 | H34: 0 | I34: =719039+2565961 -> 3285000 | J34: 377 | K34: 10103 | L34: 23996 | M34: 26089 | N34: -3201704 | O34: -3201409 | P34: -3201221 | Q34: -3201221 | R34: -3200427 | S34: -3193581.5 | T34: -3195198 | U34: 0 | V34: =160000+3113833+617260 -> 3891093 | W34: 14127.3 | X34: 13712.5 | Y34: 4380 | Z34: 4380 | AA34: 2981 | AB34: 1657 | AC34: 517 | AD34: 763 | AE34: -1284.5 | AF34: -1284.5 | AG34: -1284.5 | AH34: -2486 | AI34: =4954346+200000+1011357 -> 6165703 | AJ34: =4954346+200000+1011357 -> 6165703 | AL34: -2485 | AM34: -2485 | AN34: -2485 | AO34: 2981 | AP34: -2485 | AQ34: -894.5 | AR34: -1226 | AS34: -1226 | AU34: 55215 | AW34: 608151 | AZ34: -1539 | BA34: -2700 | BB34: 1350 | BC34: 4839 | BD34: 0 | BE34: 0 | BF34: 0 | BH34: 0 | BI34: 0 | BJ34: 2525539 | BK34: 2525539 | BL34: 0 | BM34: 0 | BN34: 0 | BO34: 0 | BP34: 0 | BQ34: 0 | BR34: 0 | BS34: 0 | BT34: 0 | BU34: 0 | BV34: 2719777 | BW34: 2719777.6 | BX34: 0 | BY34: 0 | BZ34: 0 | CA34: 0 | CB34: 0 | CC34: 0 | CD34: 0 | CE34: 0 | CF34: 0 | CG34: 0 | CH34: 0 | CI34: 0 | CJ34: 11521824 | CK34: 11521824 | CL34: 11521824 | CM34: 177375.54 | CN34: 177375.54 | CO34: 0 | CP34: 0 | CR34: 0 | CS34: 0 | CT34: 0 | CU34: 0 | CV34: 0 | CW34: 15546768 | CX34: 15546768 | CY34: 15546768 | CZ34: 1316555.6 | DA34: 0 | DB34: 0 | DC34: 0 | DD34: 0 | DE34: 0 | DF34: 0 | DG34: 0 | DH34: 0 | DI34: 20450419 | DJ34: 20052971 | DK34: 20450419 | DL34: 20450419 | DM34: 0 | DN34: 0 | DO34: 0 | DP34: 0 | DQ34: 0 | DR34: 0 | DS34: 0 | DT34: 0 | DU34: 0 | DW34: 24345394
B35: Deferred Tax Liability | C35: 6107 | D35: 7900 | E35: 9000 | F35: 555360 | G35: 33850 | H35: 0 | J35: 0 | K35: 0 | L35: 0 | M35: 0 | N35: 0 | O35: 0 | P35: 0 | Q35: 0 | R35: 0 | S35: 0 | T35: 0 | U35: 0 | AA35: 0 | AB35: 0 | AC35: 0 | AD35: 0 | AE35: 0 | AF35: 0 | AG35: 0 | AH35: 0 | AL35: 0 | AM35: 0 | AN35: 0 | AO35: 0 | AP35: 0 | AQ35: 0 | AR35: 0 | AS35: 0 | AU35: 0 | AZ35: 0 | BA35: 0 | BB35: 0 | BC35: 0 | BD35: 0 | BE35: 0 | BF35: 0 | BH35: 0 | BI35: 0 | BK35: 0 | BL35: 0 | BM35: 0 | BN35: 0 | BO35: 0 | BP35: 0 | BQ35: 0 | BR35: 0 | BS35: 0 | BT35: 0 | BU35: 0 | BV35: 0 | BX35: 0 | BY35: 0 | BZ35: 0 | CA35: 0 | CB35: 0 | CC35: 0 | CD35: 0 | CE35: 0 | CF35: 0 | CG35: 0 | CH35: 0 | CI35: 0 | CO35: 0 | CP35: 0 | CR35: 0 | CS35: 0 | CT35: 0 | CU35: 0 | CX35: 0 | CY35: 0 | CZ35: 0 | DA35: 0 | DB35: 0 | DC35: 0 | DD35: 0 | DE35: 0 | DF35: 0 | DG35: 0 | DH35: 0 | DI35: 0 | DK35: 0 | DL35: 0 | DM35: 0 | DN35: 0 | DO35: 0 | DP35: 0 | DQ35: 0 | DR35: 0
B36: Retirement Benefits Liability | F36: 0 | G36: 0 | H36: 0 | J36: 0 | K36: 0 | L36: 0 | M36: 0 | N36: 0 | O36: 0 | P36: 0 | Q36: 0 | R36: 0 | S36: 0 | T36: 0 | U36: 0 | AA36: 0 | AB36: 0 | AC36: 0 | AD36: 0 | AE36: 0 | AF36: 0 | AG36: 0 | AH36: 0 | AL36: 0 | AM36: 0 | AN36: 0 | AO36: 0 | AP36: 0 | AQ36: 0 | AR36: -133500 | AS36: -133500 | AU36: -133500 | AZ36: 0 | BA36: 0 | BB36: 0 | BC36: 0 | BD36: 0 | BE36: 0 | BF36: 0 | BH36: 0 | BI36: 0 | BK36: 0 | BL36: 0 | BM36: 0 | BN36: 0 | BO36: 0 | BP36: 0 | BQ36: 0 | BR36: 0 | BS36: 0 | BT36: 0 | BU36: 0 | BV36: 0 | BX36: 0 | BY36: 0 | BZ36: 0 | CA36: 0 | CB36: 0 | CC36: 0 | CD36: 0 | CE36: 0 | CF36: 0 | CG36: 0 | CH36: 0 | CI36: 0 | CM36: 0 | CO36: 0 | CP36: 0 | CR36: 0 | CS36: 0 | CT36: 0 | CU36: 0 | CV36: 403800 | CX36: 403800 | CY36: 403800 | CZ36: 403800 | DA36: 253800 | DB36: 253800 | DC36: 253800 | DD36: 253800 | DE36: 253800 | DF36: 253800 | DG36: 253800 | DH36: 253800 | DI36: 373800 | DK36: 373800 | DL36: 373800 | DM36: 373800 | DN36: 216800 | DO36: 216800 | DP36: 216800 | DQ36: 216800 | DR36: 216800 | DS36: 216800 | DT36: 216800 | DU36: 216800
B37: Other Liabilities | C37: 494170 | D37: 627276 | E37: 706139 | F37: 1851747 | G37: 2359159 | H37: 0 | I37: 15600 | J37: 117016.35 | K37: 224978.16 | L37: 384080.62 | M37: 513229.93 | N37: 605517.59 | O37: 718155.76 | P37: 822150.09 | Q37: 925848.2 | R37: 1064791.7 | S37: 1199169.6 | T37: 1332083.5 | U37: 25987 | V37: =325156-956+328084 -> 652284 | W37: 152926.97 | X37: 271513.04 | Y37: 564591.85 | Z37: 710727.24 | AA37: 844251.81 | AB37: 810566.63 | AC37: 1065084.7 | AD37: 1167995.9 | AE37: 1293415.7 | AF37: 227377.15 | AG37: 362579.85 | AH37: 500215.28 | AI37: =362413 -> 362413 | AJ37: =362413 -> 362413 | AL37: 274890.46 | AM37: 232621.46 | AN37: 569943.98 | AO37: 844251.81 | AP37: 896396.4 | AQ37: 1373975.2 | AR37: 1531072.4 | AS37: 1736787.2 | AU37: 1979005.9 | AV37: 63416329 | AW37: =5434834+200000+63649 -> 5698483 | AZ37: -64079015 | BA37: -1.2848413e+08 | BB37: 5729157 | BC37: 30460891 | BD37: 3501403 | BE37: 0 | BF37: 0 | BH37: 0 | BI37: 0 | BJ37: =300000+39600+6911689 -> 7251289 | BK37: 7283122 | BL37: 7283122 | BM37: 0 | BN37: 0 | BO37: 0 | BP37: 0 | BQ37: 0 | BR37: 0 | BS37: 0 | BT37: 0 | BU37: 0 | BV37: 2049850 | BW37: =500000+1549850+9040189.61+9590309 -> 20680349 | BX37: 0 | BY37: 2116369 | BZ37: 2276468 | CA37: 2076468 | CB37: 1771961 | CC37: 1771961 | CD37: 1795603 | CE37: 1796615 | CF37: 1829767.9 | CG37: 1840835.5 | CH37: 1764496.1 | CI37: 1722240 | CJ37: =300000+1813240 -> 2113240 | CK37: 2374278.6 | CL37: 1839218.2 | CM37: 1850661.2 | CN37: 1736618 | CO37: 1730259 | CP37: 1820433 | CQ37: 1884155 | CR37: 1754651 | CS37: 1849421.6 | CT37: 1809947.4 | CU37: 1747750.4 | CV37: 2222863.2 | CW37: 2441055.3 | CX37: 2037255.3 | CY37: 1660932.5 | CZ37: 2106973.5 | DA37: 2468343.5 | DB37: 2086577.4 | DC37: 1382770.4 | DD37: 1402311.6 | DE37: 1463850.4 | DF37: 1463850.4 | DG37: 1339358.2 | DH37: 1395192.5 | DI37: 2062185 | DJ37: 2469034 | DK37: 1865648.1 | DL37: 2035223.5 | DM37: 1757168.2 | DN37: 1756141.7 | DO37: 1756141.7 | DP37: 1685208.4 | DQ37: 1543337.3 | DR37: 1553728.5 | DS37: 1481577.4 | DT37: 1463267.6 | DU37: 1426262.9 | DW37: 1845338
B38: External Borrowings | D38: 1000000 | F38: 2870718 | G38: 560210 | H38: 4033865 | I38: 4033865 | J38: 8067730 | K38: 3884335 | L38: 3884335 | M38: 3724529 | N38: 3724529 | O38: 3724529 | P38: 3365209 | Q38: 3250954 | R38: 3250954 | S38: 3250954 | T38: 3250954 | U38: 2262103 | V38: 2073269 | W38: 2262103 | X38: 2262103 | Y38: 2262103 | Z38: 1896774 | AA38: 1896774 | AB38: 1896774 | AC38: 1896774 | AD38: 1896774 | AE38: 1896774 | AF38: 1896774 | AG38: 776826 | AH38: 0 | AO38: 1896774 | AZ38: 0 | BA38: 0 | BB38: 0 | BC38: 0 | BD38: 0 | BE38: 0 | BF38: 0 | BH38: 0 | BI38: 0 | BK38: 0 | BL38: 0 | BP38: 0 | BT38: 0 | BU38: 5500000 | BV38: 5347222 | BW38: 5347222 | BX38: 5347222 | BY38: 5041666 | BZ38: 4888888 | CA38: 4736110 | CB38: 4583332 | CC38: 4430500 | CD38: 4268269 | CE38: 4067710 | CF38: 3852835 | CG38: 13701781 | CH38: 13532843 | CJ38: 13317968 | CK38: 12256156 | CL38: 12084076 | CM38: 11869201 | CN38: 10935639 | CO38: 10781446 | CP38: 10626229 | CQ38: 9564417 | CR38: 9369317 | CS38: 8969554 | CT38: 9184429 | CU38: 7930131 | CV38: 7752577 | CW38: 7752577 | CX38: 6674015 | CY38: 6492640 | CZ38: 6313114.7 | DA38: 5251302.7 | DB38: 5040426.9 | DC38: 14825552 | DD38: 13487615 | DE38: 12781740 | DF38: 12075865 | DG38: 11228928 | DH38: 10543180 | DI38: 12162420 | DJ38: 12092325 | DK38: 10681516 | DL38: 10681516 | DM38: 7182065.3 | DN38: 6691065.3 | DO38: 7318252.3 | DP38: 7012352.3 | DQ38: 6661352.3 | DR38: 6607372 | DS38: 6607372 | DT38: 5627372 | DU38: 5602949 | DW38: 5845335
B39: Total Liabilities | C39: =C32+C31 -> 3035549 | D39: =D32+D31 -> 8013786 | E39: =E32+E31 -> 10178659 | F39: =F32+F31 -> 23792553 | G39: =G32+G31 -> 32352214 | H39: =H32+H31 -> 50083690 | I39: =I32+I31 -> 51080242 | J39: =J32+J31 -> 1.0253684e+08 | ... DW39: =DW32+DW31 -> 317602994
B40: Share Capital | C40: 358000 | D40: 618000 | E40: 7470000 | F40: 10188316 | G40: 13099989 | H40: 16896221 | I40: 15978641 | J40: 33927742 | K40: 17383213 | L40: 17974930 | M40: 18032037 | N40: 18444575 | O40: 18585194 | P40: 19175829 | Q40: 18691824 | R40: 18921949 | S40: 19717783 | T40: 20111540 | U40: 19718355 | V40: 18898149 | W40: 20128307 | X40: 21027549 | Y40: 21308409 | Z40: 23736308 | AA40: 24389735 | AB40: 25091160 | AC40: 26050349 | AD40: 26849736 | AE40: 27104749 | AF40: 26346064 | AG40: 27544270 | AH40: 27907588 | AI40: 21766249 | AJ40: 21766249 | AL40: 35545041 | AM40: 35304832 | AN40: 36720050 | AO40: 24389735 | AP40: 46118892 | AQ40: 49332736 | AR40: 53888952 | AS40: 57802515 | AU40: 60964425 | AV40: 31786378 | AW40: 23368005 | AZ40: -32128988 | BA40: -64836010 | BB40: 24212302 | BC40: 24338933 | BD40: 24484113 | BE40: 24627428 | BF40: 24808583 | BG40: 0 | BH40: 25137577 | BI40: 25255387 | BJ40: 25255387 | BK40: 25332452 | BL40: 25488292 | BM40: 25892885 | BN40: 26065897 | BO40: 26305008 | BP40: 26514691 | BQ40: 27608561 | BR40: 28155319 | BS40: 28590761 | BT40: 28850953 | BU40: 29309422 | BV40: 29583093 | BW40: 29583093 | BX40: 29760294 | BY40: 29914576 | BZ40: 30548189 | CA40: 30655114 | CB40: 30821674 | CC40: 30945348 | CD40: 31105148 | CE40: 31242651 | CF40: 31416532 | CG40: 31574245 | CH40: 31850792 | CI40: 31984937 | CJ40: 31984937 | CK40: 32177150 | CL40: 32428751 | CM40: 32816015 | CN40: 32990257 | CO40: 33158170 | CP40: 33451675 | CQ40: 33844749 | CR40: 34213651 | CS40: 34987929 | CT40: 34582419 | CU40: 35649779 | CV40: 35996598 | CW40: 35996598 | CX40: 36244310 | CY40: 36616409 | CZ40: 37617520 | DA40: 38070246 | DB40: 38388355 | DC40: 39005546 | DD40: 39438880 | DE40: 39852688 | DF40: 40195569 | DG40: 40528805 | DH40: 40976875 | DI40: 41367362 | DJ40: 41367361 | DK40: 41875544 | DL40: 42391440 | DM40: 46886541 | DN40: 47847277 | DO40: 48264409 | DP40: 49922679 | DQ40: 50966752 | DR40: 51420469 | DS40: 51980328 | DT40: 52440976 | DU40: 52867806 | DW40: 53313338
...

Sheet Financials
B2: NYAHURURU UMOJA (VICTAS)
B3: Year | C3: 2008 | D3: 2009 | E3: 2010 | F3: 2011 | G3: 2012 | H3: 41609 | I3: 2013 | J3: 41640 | K3: 41671 | L3: 41699 | M3: 41730 | N3: 41760 | O3: 41791 | P3: 41821 | Q3: 41852 | R3: 41883 | S3: 41913 | T3: 41944 | U3: 41974 | V3: 2014 | W3: Jan-15 | X3: Feb-15 | Y3: Mar-15 | Z3: Apr-15 | AA3: 42125 | AB3: 42156 | AC3: 42186 | AD3: 42217 | AE3: 42248 | AF3: 42278 | AG3: 42309 | AH3: 42339 | AI3: 2015 | AJ3: 2015 Rev. | AK3: 42385 | AL3: 42416 | AM3: 42445 | AN3: 42476 | AO3: 42506 | AP3: 42537 | AQ3: Jul-16 | AR3: Aug-16 | AS3: Sept-16 | AT3: Oct-16 | AU3: Nov-16 | AV3: Dec-16 | AW3: Aud-16 | AX3: Jan-2017 | AY3: Feb-2017 | AZ3: Mar-2017 | BA3: Apr-2017 | BB3: 42856 | BC3: 42887 | BD3: 42917 | BE3: 42948 | BF3: 42979 | BG3: 43009 | BH3: 43040 | BI3: 43070 | BJ3: Aud-17 | BK3: 43101 | BL3: 43132 | BM3: 43160 | BN3: 43191 | BO3: 43221 | BP3: 43252 | BQ3: 43282 | BR3: 43313 | BS3: 43344 | BT3: 43374 | BU3: 43405 | BV3: 43435 | BW3: Audited 2018 | BX3: 43466 | BY3: 43497 | BZ3: 43525 | CA3: 43556 | CB3: 43586 | CC3: 43617 | CD3: 43647 | CE3: 43678 | CF3: 43709 | CG3: 43739 | CH3: 43770 | CI3: 43800 | CJ3: Audited-2019 | CK3: 43831 | CL3: 43862 | CM3: 43891 | CN3: 43922 | CO3: 43952 | CP3: 43983 | CQ3: 44013 | CR3: 44044 | CS3: 44075 | CT3: 44105 | CU3: 44136 | CV3: 44166 | CW3: Audited 2021 | CX3: 44197 | CY3: 44228 | CZ3: 44256 | DA3: 44287 | DB3: 44317 | DC3: 44348 | DD3: 44378 | DE3: 44409 | DF3: 44440 | DG3: 44470 | DH3: 44501 | DI3: 44531 | DJ3: Audited-2021 | DK3: 44562 | DL3: 44593 | DM3: 44621 | DN3: 44652 | DO3: 44682 | DP3: 44713 | DQ3: 44743 | DR3: 44774 | DS3: 44805 | DT3: 44835 | DU3: 44866 | DV3: 44896 | DW3: Audited 2022
A4: 1 | B4: Membership | C4: 179 | D4: 309 | E4: 697 | F4: 882 | G4: 1128 | I4: 1310
A5: 2 | B5: Total Assets | C5: =Trend!C27 -> 3475410 | D5: =Trend!D27 -> 8750647 | E5: =Trend!E27 -> 19015501 | F5: =Trend!F27 -> 35649419 | G5: =Trend!G27 -> 48282362 | H5: =Trend!H27 -> 75358469 | I5: =Trend!I27 -> 71384601 | J5: =Trend!J27 -> 1.5365653e+08 | ... DW5: =Trend!DW27 -> 415120522
A6: 3 | B6: Total Deposits | C6: =Trend!C31 -> 2279348 | D6: =Trend!D31 -> 5920804 | E6: =Trend!E31 -> 8325050 | F6: =Trend!F31 -> 17127596 | G6: =Trend!G31 -> 29393861 | H6: =Trend!H31 -> 46049825 | I6: =Trend!I31 -> 43745777 | J6: =Trend!J31 -> 94351720 | ... DW6: =Trend!DW31 -> 285244427
A7: 3.1 | B7: Deposits-Members(BOSA) | C7: =Trend!C30 -> 2181426 | D7: =Trend!D30 -> 5388952 | E7: =Trend!E30 -> 7001000 | F7: =Trend!F30 -> 14533589 | G7: =Trend!G30 -> 21381443 | H7: =Trend!H30 -> 43845984 | I7: =Trend!I30 -> 32277459 | J7: =Trend!J30 -> 89972427 | ... DR7: =Trend!DR30 -> 2.1984675e+08 | DS7: =Trend!DS29 -> 10933569 | DT7: =Trend!DT29 -> 11827028 | DU7: =Trend!DU29 -> 11884327 | DV7: =Trend!DV30 -> 0 | DW7: =Trend!DW30 -> 226107824
A8: 3.2 | B8: Deposits-Customers(FOSA) | C8: =Trend!C28 -> 97922 | D8: =Trend!D28 -> 531852 | E8: =Trend!E28 -> 1324050 | F8: =Trend!F28 -> 2594007 | G8: =Trend!G28 -> 8012418 | H8: =Trend!H28 -> 1189925 | I8: =Trend!I28 -> 11468318 | J8: =Trend!J28 -> 2349166 | ... DR8: =Trend!DR28 -> 46858158 | DS8: =Trend!DS27 -> 4.0179739e+08 | DT8: =Trend!DT27 -> 4.0708972e+08 | DU8: =Trend!DU27 -> 4.1539737e+08 | DV8: =Trend!DV28 -> 0 | DW8: =Trend!DW28 -> 42297148
A9: 4 | B9: External Borrowing | C9: =Trend!C38 -> 0 | D9: =Trend!D38 -> 1000000 | E9: =Trend!E38 -> 0 | F9: =Trend!F38 -> 2870718 | G9: =Trend!G38 -> 560210 | H9: =Trend!H38 -> 4033865 | I9: =Trend!I38 -> 4033865 | J9: =Trend!J38 -> 8067730 | ... DW9: =Trend!DW38 -> 5845335
A10: 4.1 | B10: Short term Liabilities | C10: =Trend!C33+Trend!C34+Trend!C35+Trend!C37 -> 756201 | D10: =Trend!D33+Trend!D34+Trend!D35+Trend!D37 -> 1092982 | E10: =Trend!E33+Trend!E34+Trend!E35+Trend!E37 -> 1853609 | F10: =Trend!F33+Trend!F34+Trend!F35+Trend!F37 -> 3794239 | G10: =Trend!G33+Trend!G34+Trend!G35+Trend!G37 -> 2398143 | H10: =Trend!H33+Trend!H34+Trend!H35+Trend!H37 -> 0 | I10: =Trend!I33+Trend!I34+Trend!I35+Trend!I37 -> 3300600 | J10: =Trend!J33+Trend!J34+Trend!J35+Trend!J37 -> 117393.35 | ... DR10: =Trend!DR33+Trend!DR34+Trend!DR35+Trend!DR37 -> 1553728.5 | DS10: =Trend!DS33+Trend!DS34+Trend!DS36+Trend!DS38 -> 6824172 | DT10: =Trend!DT33+Trend!DT34+Trend!DT36+Trend!DT38 -> 5844172 | DU10: =Trend!DU33+Trend!DU34+Trend!DU36+Trend!DU38 -> 5819749 | DV10: =Trend!DV33+Trend!DV34+Trend!DV35+Trend!DV37 -> 0 | DW10: =Trend!DW33+Trend!DW34+Trend!DW35+Trend!DW37 -> 26513232
A12: 5 | B12: Share capital and Reserves
A13: 5.1 | B13: Core Capital | C13: =C16 -> 439861 | D13: =D16 -> 736861 | E13: =E16 -> 8453756 | F13: =F16 -> 11449334 | G13: =G16 -> 15452148 | H13: =H16 -> 25274778 | I13: =I16 -> 19725079 | J13: =J16 -> 51119689 | ... DW13: =DW16 -> 97517528
A14: 5.2 | B14: Institutional Capital | C14: =C13-C17 -> 81861 | D14: =D13-D17 -> 118861 | E14: =E13-E17 -> 983756 | F14: =F13-F17 -> 1261018 | G14: =G13-G17 -> 2352159 | H14: =H13-H17 -> 8378557.1 | I14: =I13-I17 -> 3746438 | J14: =J13-J17 -> 17191947 | ... DW14: =DW13-DW17 -> 44204190
A16: 5.3 | B16: Total Capital | C16: =SUM(C17:C20) -> 439861 | D16: =SUM(D17:D20) -> 736861 | E16: =SUM(E17:E20) -> 8453756 | F16: =SUM(F17:F20) -> 11449334 | G16: =SUM(G17:G20) -> 15452148 | H16: =SUM(H17:H20) -> 25274778 | I16: =SUM(I17:I20) -> 19725079 | J16: =SUM(J17:J20) -> 51119689 | ... DW16: =SUM(DW17:DW20) -> 97517528
A17: 5.3.1 | B17: Members Share Capital | C17: =Trend!C40 -> 358000 | D17: =Trend!D40 -> 618000 | E17: =Trend!E40 -> 7470000 | F17: =Trend!F40 -> 10188316 | G17: =Trend!G40 -> 13099989 | H17: =Trend!H40 -> 16896221 | I17: =Trend!I40 -> 15978641 | J17: =Trend!J40 -> 33927742 | ... CK17: =Trend!CK40 -> 32177150 | CL17: =Trend!#REF! -> #REF! | CM17: =Trend!CM40 -> 32816015 | CN17: =Trend!CN40 -> 32990257 | CO17: =Trend!CO40 -> 33158170 | CP17: =Trend!CP40 -> 33451675 | CQ17: =Trend!CQ40 -> 33844749 | CR17: =Trend!CR40 -> 34213651 | CS17: =Trend!CS40 -> 34987929 | CT17: =Trend!CT40 -> 34582419 | ... DW17: =Trend!DW40 -> 53313338
A18: 5.3.3 | B18: Retained Earnings | C18: =Trend!C42 -> 24089 | D18: =Trend!D42 -> 46089 | E18: =Trend!E42 -> 88005 | F18: =Trend!F42 -> 211308 | G18: =Trend!G42 -> 325421 | H18: =Trend!H42 -> 5055549.1 | I18: =Trend!I42 -> 394020 | J18: =Trend!J42 -> 10499631 | ... DW18: =Trend!DW42 -> 17077729
A19: 5.3.5 | B19: Statutory Reserves | C19: =Trend!C46 -> 19772 | D19: =Trend!D46 -> 34772 | E19: =Trend!E46 -> 57751 | F19: =Trend!F46 -> 211710 | G19: =Trend!G46 -> 359738 | H19: =Trend!H46 -> 359738 | I19: =Trend!I46 -> 589148 | J19: =Trend!J46 -> 719476 | ... DW19: =Trend!DW46 -> 11130433
A20: 5.3.6 | B20: Capital Reserve | C20: =Trend!C47 -> 38000 | D20: =Trend!D47 -> 38000 | E20: =Trend!E47 -> 838000 | F20: =Trend!F47 -> 838000 | G20: =Trend!G47 -> 1667000 | H20: =Trend!H47 -> 2963270 | I20: =Trend!I47 -> 2763270 | J20: =Trend!J47 -> 5972840 | ... DW20: =Trend!DW47 -> 15996028
A21: 5.3.7 | B21: Supplementary Capital & reserves
A22: a | B22: Proposed Dividends | C22: =Trend!C68+Trend!C69 -> 0 | D22: =Trend!D68+Trend!D69 -> 0 | E22: =Trend!E68+Trend!E69 -> 1138470 | F22: =Trend!F68+Trend!F69 -> 1388148 | G22: =Trend!G68+Trend!G69 -> 1753935 | H22: =Trend!H68+Trend!H69 -> 0 | I22: =Trend!I68+Trend!I69 -> 2958639 | J22: =Trend!J68+Trend!J69 -> 0 | ... DW22: =Trend!DW68+Trend!DW69 -> 20925037
A23: b
A25: 6 | B25: Investments | C25: =SUM(C26:C27) -> 69500 | D25: =SUM(D26:D27) -> 149500 | E25: =SUM(E26:E27) -> 209500 | F25: =SUM(F26:F27) -> 219500 | G25: =SUM(G26:G27) -> 227500 | H25: =SUM(H26:H27) -> 3370491.9 | I25: =SUM(I26:I27) -> 227686 | J25: =SUM(J26:J27) -> 6740983.7 | ... DW25: =SUM(DW26:DW27) -> 17961747
A26: 6.1 | B26: Investments in Coop bank, CIC, Kuscco, Kerussu & Codic | C26: =Trend!C12 -> 0 | D26: =Trend!D12 -> 0 | E26: =Trend!E12 -> 0 | F26: =Trend!F12 -> 0 | G26: =Trend!G12 -> 0 | H26: =Trend!H12 -> 3370491.9 | I26: =Trend!I12 -> 0 | J26: =Trend!J12 -> 6740983.7 | ... CL26: =Trend!CL12 -> 4044415.5 | CM26: =Trend!#REF! -> #REF! | CN26: =Trend!CN12 -> 4254415 | CO26: =Trend!CO12 -> 4359415.5 | CP26: =Trend!CP12 -> 36110000 | CQ26: =Trend!CQ12 -> 4579282.8 | CR26: =Trend!CR12 -> 4702456 | CS26: =Trend!CS12 -> 4912456 | CT26: =Trend!CT12 -> 4912456 | CU26: =Trend!CU12 -> 5017456.7 | CV26: =Trend!CV12 -> 5122456.7 | CW26: =Trend!CW22 -> 0 | CX26: =Trend!CX22 -> 0 | CY26: =Trend!CY22 -> 0 | CZ26: =Trend!CZ22 -> 0 | DA26: =Trend!DA22 -> 0 | DB26: =Trend!DB22 -> 0 | DC26: =Trend!DC22 -> 0 | DD26: =Trend!DD22 -> 0 | ... DR26: =Trend!DR22 -> 620249 | DS26: =Trend!DS21 -> 19736376 | DT26: =Trend!DT21 -> 19866676 | DU26: =Trend!DU21 -> 19866676 | DV26: =Trend!DV21 -> 0 | DW26: =Trend!DW21 -> 17961747
A27: 6.2 | B27: Equity Investments (at cost) | C27: =Trend!C13 -> 69500 | D27: =Trend!D13 -> 149500 | E27: =Trend!E13 -> 209500 | F27: =Trend!F13 -> 219500 | G27: =Trend!G13 -> 227500 | H27: =Trend!H13 -> 0 | I27: =Trend!I13 -> 227686 | J27: =Trend!J13 -> 0 | ... CL27: =Trend!CL13 -> 10000000 | CM27: =Trend!CM12 -> 4149415.5 | CN27: =Trend!CN13 -> 29620249 | CO27: =Trend!CO13 -> 20190068 | CP27: =Trend!CP13 -> 4464415.5 | CQ27: =Trend!CQ13 -> 33618191 | CR27: =Trend!CR13 -> 28535519 | CS27: =Trend!CS13 -> 34397489 | CT27: =Trend!CT13 -> 34397489 | CU27: =Trend!CU13 -> 36281996 | ... DW27: =Trend!DW13 -> 0
A28: 6.3 | B28: Deposits in KUSCCO CFP
DQ29: =DM30-DP30 -> -14998186
A30: 7 | B30: Net Loans & advances | C30: =C31-C32 -> 2617776 | D30: =D31-D32 -> 6440080 | E30: =E31-E32 -> 16654373 | F30: =F31-F32 -> 26721318 | G30: =G31-G32 -> 34118230 | H30: =H31-H32 -> 48217666 | I30: =I31-I32 -> 48346848 | J30: =J31-J32 -> 98776711 | ... DW30: =DW31-DW32 -> 340435332
