Workbook

Sheet Evolutive SFP
A1: VISION AFRIKA SACCO SOCIETY
A2: STATEMENT OF FINANCIAL POSITION
B4: 2010 Audited | C4: 2020 Audited | D4: 44197 | E4: 44228 | F4: 44256 | G4: 44287 | H4: 44317 | I4: 44348 | J4: 44378 | K4: 44409 | L4: 44440 | M4: 44470 | N4: 44501 | O4: 44531 | P4: Audited 2021 | Q4: 44562 | R4: 44593 | S4: 44621 | T4: 44652 | U4: 44682 | V4: 44713 | W4: 44743 | X4: 44774 | Y4: 44805 | Z4: 44835 | AA4: 44866 | AB4: 44896 | AC4: Audited 2022 | AD4: 44927 | AE4: 44958 | AF4: 44986 | AG4: 45017 | AH4: 45047 | AI4: 45078 | AJ4: 45108 | AK4: 45139 | AL4: 45170 | AM4: 45200 | AN4: 45231 | AO4: 45261
A5: Cash & cash Equivalent | B5: =SUM(B6:B7) -> 19363224 | C5: =SUM(C6:C7) -> 41042857 | D5: =SUM(D6:D7) -> 37653030 | E5: =SUM(E6:E7) -> 40331467 | F5: =SUM(F6:F7) -> 42428391 | G5: =SUM(G6:G7) -> 36908358 | H5: =SUM(H6:H7) -> 37389306 | I5: =SUM(I6:I7) -> 43190648 | ... AO5: =SUM(AO6:AO7) -> 0
A6: Cash In Hand | B6: 19363224 | C6: 4486304 | D6: 6539440.4 | E6: 6831671.7 | F6: 4628652.7 | G6: 6736877.9 | H6: 5755519.9 | I6: 8084214.9 | J6: 6026309.6 | K6: 7506456.3 | L6: 15609696 | M6: 14737970 | N6: 9516716.2 | O6: 6158859.3 | P6: =3166713+3645751 -> 6812464 | Q6: 9558617.3 | R6: 8004432.9 | S6: 11655949 | T6: 8057600 | U6: 8099999 | V6: 9211486 | W6: 6054440 | X6: 8421004 | Y6: 8353753 | Z6: 7075617 | AA6: 6145176 | AB6: 8114904.6 | AC6: =5502578+1210609 -> 6713187 | AD6: 7142399 | AE6: 5878269.2 | AF6: 6838644.2 | AG6: 8569787.2 | AH6: 6132963.3 | AI6: 7942223.3 | AJ6: 9001345.3
A7: Cash at Bank | C7: 36556553 | D7: 31113590 | E7: 33499795 | F7: 37799738 | G7: 30171480 | H7: 31633786 | I7: 35106433 | J7: 23140555 | K7: 19936906 | L7: 39973860 | M7: 39519351 | N7: 40555205 | O7: 38049583 | P7: =44208443-P6 -> 37395979 | Q7: 42552323 | R7: 54168737 | S7: 40734690 | T7: 20177710 | U7: 32578728 | V7: 63969514 | W7: 60465367 | X7: 57736438 | Y7: 66693925 | Z7: 54931655 | AA7: 34201113 | AB7: 32100734 | AC7: =40162115-AC6 -> 33448928 | AD7: 31197297 | AE7: 38489392 | AF7: 34791527 | AG7: 37600835 | AH7: 18866969 | AI7: 18621695 | AJ7: 22284456
A8: Prepayment and Sundry | B8: 13400392 | C8: 7478512 | D8: 0 | E8: 0 | F8: 0 | G8: 0 | H8: 0 | I8: 0 | J8: 0 | K8: 0 | L8: 0 | M8: 0 | N8: 0 | O8: 0 | P8: =5148885+3084618 -> 8233503 | Q8: 0 | R8: 0 | S8: 0 | T8: 0 | U8: 0 | V8: 0 | W8: 0 | X8: 0 | Y8: 0 | Z8: 0 | AA8: 0 | AB8: 0 | AC8: 13311946 | AD8: 0 | AE8: 0 | AF8: 0 | AG8: 0 | AH8: 0 | AI8: 0 | AJ8: 0
A9: Financial Investment | B9: =SUM(B10:B14) -> 472260 | C9: =SUM(C10:C14) -> 293021 | D9: =SUM(D10:D14) -> 293020.64 | E9: =SUM(E10:E14) -> 293020.64 | F9: =SUM(F10:F14) -> 293020.64 | G9: =SUM(G10:G14) -> 293020.64 | H9: =SUM(H10:H14) -> 293020.64 | I9: =SUM(I10:I14) -> 293020.64 | ... AO9: =SUM(AO10:AO14) -> 0
A10: Government Securities - Treasury Bills/bonds, | C10: 0 | D10: 0 | E10: 0 | F10: 0 | G10: 0 | H10: 0 | I10: 0 | J10: 0 | K10: 0 | L10: 0 | M10: 0 | N10: 0 | O10: 0 | Q10: 0 | R10: 0 | S10: 0 | T10: 0 | U10: 0 | V10: 0 | W10: 0 | X10: 0 | Y10: 0 | Z10: 0 | AA10: 0 | AB10: 0 | AC10: 0 | AD10: 0 | AE10: 0 | AF10: 0 | AG10: 0 | AH10: 0 | AI10: 0 | AJ10: 0
A11: Other Securities - Commercial papers/Bonds | C11: 0 | D11: 0 | E11: 0 | F11: 0 | G11: 0 | H11: 0 | I11: 0 | J11: 0 | K11: 0 | L11: 0 | M11: 0 | N11: 0 | O11: 0 | Q11: 0 | R11: 0 | S11: 0 | T11: 0 | U11: 0 | V11: 0 | W11: 0 | X11: 0 | Y11: 0 | Z11: 0 | AA11: 0 | AB11: 0 | AC11: 0 | AD11: 0 | AE11: 0 | AF11: 0 | AG11: 0 | AH11: 0 | AI11: 0 | AJ11: 0
A12: Balances in NACCOS (E.g Jungu Kuu, ESS, Savings,Money Market,Coop FD, CFP) | C12: 0 | D12: 0 | E12: 0 | F12: 0 | G12: 0 | H12: 0 | I12: 0 | J12: 0 | K12: 0 | L12: 0 | M12: 0 | N12: 0 | O12: 0 | Q12: 0 | R12: 0 | S12: 0 | T12: 0 | U12: 0 | V12: 0 | W12: 0 | X12: 0 | Y12: 0 | Z12: 0 | AA12: 0 | AB12: 0 | AC12: 0 | AD12: 0 | AE12: 0 | AF12: 0 | AG12: 0 | AH12: 0 | AI12: 0 | AJ12: 0
A13: Equity Investments in NACCOs(Shares in- CIC, KUSCCO, COOP BANK,CAK, KERUSSU) | C13: 0 | Z13: 0 | AA13: 0 | AB13: 0 | AC13: =67200+48900 -> 116100 | AD13: 293020.64 | AE13: 293020.64 | AF13: 351265.82 | AG13: 351265.82 | AH13: 351265.82 | AI13: 351265.82 | AJ13: 351265.82
A14: Equity Investments in companies - shares/stocks | B14: 472260 | C14: 293021 | D14: 293020.64 | E14: 293020.64 | F14: 293020.64 | G14: 293020.64 | H14: 293020.64 | I14: 293020.64 | J14: 293020.64 | K14: 293020.64 | L14: 293020.64 | M14: 293020.64 | N14: 293020.64 | O14: 293020.64 | P14: 293021 | Q14: 293020.64 | R14: 293020.64 | S14: 293020.64 | T14: 293020.64 | U14: 293020.64 | V14: 293020.64 | W14: 293020.64 | X14: 293020.64 | Y14: 293020.64 | Z14: 293020.64 | AA14: 293020.64 | AB14: 293020.64 | AC14: =222000+13166 -> 235166
A15: Net Loan Portfolio | B15: =B16-B17 -> 112905266 | C15: =C16-C17 -> 361847211 | D15: =D16-D17 -> 3.5780519e+08 | E15: =E16-E17 -> 3.5845378e+08 | F15: =F16-F17 -> 3.6291313e+08 | G15: =G16-G17 -> 3.8098937e+08 | H15: =H16-H17 -> 3.8825293e+08 | I15: =I16-I17 -> 3.8992474e+08 | ... AO15: =AO16-AO17 -> 0
A16: Gross Loan Portfolio | B16: 112905266 | C16: 371165321 | D16: 3.6876144e+08 | E16: 3.7097772e+08 | F16: 3.7451242e+08 | G16: 3.9365943e+08 | H16: 4.0337954e+08 | I16: 4.0662377e+08 | J16: 4.2964704e+08 | K16: 4.3256573e+08 | L16: 4.3818131e+08 | M16: 4.4015733e+08 | N16: 4.5883137e+08 | O16: 4.7465035e+08 | P16: 478267747 | Q16: 4.7563906e+08 | R16: 4.8727969e+08 | S16: 4.9172564e+08 | T16: 5.1486799e+08 | U16: 5.377492e+08 | V16: 5.4483083e+08 | W16: 5.4597201e+08 | X16: 5.4324954e+08 | Y16: 5.5919435e+08 | Z16: 5.6944432e+08 | AA16: 6.2291781e+08 | AB16: 5.9687425e+08 | AC16: 596874250 | AD16: 5.968034e+08 | AE16: 5.9221317e+08 | AF16: 5.9843193e+08 | AG16: 6.0537741e+08 | AH16: 6.3778963e+08 | AI16: 6.4025769e+08 | AJ16: 6.4517445e+08
A17: Allowance For Loan Loss | C17: 9318110 | D17: 10956246 | E17: 12523937 | F17: 11599285 | G17: 12670063 | H17: 15126606 | I17: 16699024 | J17: 19508816 | K17: 18847990 | L17: 23192301 | M17: 19215559 | N17: 18829105 | O17: 14699101 | P17: 18455742 | Q17: 20174517 | R17: 24699380 | S17: 22084892 | T17: 28031415 | U17: 30176351 | V17: 32549239 | W17: 31908887 | X17: 29107263 | Y17: 33874121 | Z17: 32882590 | AA17: 40464551 | AB17: 18809013 | AC17: 18809013 | AD17: 23910266 | AE17: 30324594 | AF17: 25126682 | AG17: 31749425 | AH17: 32572039 | AI17: 38529252 | AJ17: 41399870
A18: Accounts Recievables | B18: =SUM(B19:B21) -> 0 | C18: =SUM(C19:C21) -> 0 | D18: =SUM(D19:D21) -> 0 | E18: =SUM(E19:E21) -> 0 | F18: =SUM(F19:F21) -> 0 | G18: =SUM(G19:G21) -> 0 | H18: =SUM(H19:H21) -> 0 | I18: =SUM(I19:I21) -> 0 | ... AO18: =SUM(AO19:AO21) -> 0
A19: Tax Recoverable | C19: 0 | D19: 0 | E19: 0 | F19: 0 | G19: 0 | H19: 0 | I19: 0 | J19: 0 | K19: 0 | L19: 0 | M19: 0 | N19: 0 | O19: 0 | Q19: 0 | R19: 0 | S19: 0 | T19: 0 | U19: 0 | V19: 0 | W19: 0 | X19: 0 | Y19: 0 | Z19: 0 | AA19: 0 | AB19: 0 | AC19: 0 | AD19: 0 | AE19: 0 | AF19: 0 | AG19: 0 | AH19: 0 | AI19: 0 | AJ19: 0
A20: Deffered Tax Assets | C20: 0 | D20: 0 | E20: 0 | F20: 0 | G20: 0 | H20: 0 | I20: 0 | J20: 0 | K20: 0 | L20: 0 | M20: 0 | N20: 0 | O20: 0 | Q20: 0 | R20: 0 | S20: 0 | T20: 0 | U20: 0 | V20: 0 | W20: 0 | X20: 0 | Y20: 0 | Z20: 0 | AA20: 0 | AB20: 0 | AC20: 0 | AD20: 0 | AE20: 0 | AF20: 0 | AG20: 0 | AH20: 0 | AI20: 0 | AJ20: 0
A21: Retirement Benefit Assets | C21: 0 | D21: 0 | E21: 0 | F21: 0 | G21: 0 | H21: 0 | I21: 0 | J21: 0 | K21: 0 | L21: 0 | M21: 0 | N21: 0 | O21: 0 | Q21: 0 | R21: 0 | S21: 0 | T21: 0 | U21: 0 | V21: 0 | W21: 0 | X21: 0 | Y21: 0 | Z21: 0 | AA21: 0 | AB21: 0 | AC21: 0 | AD21: 0 | AE21: 0 | AF21: 0 | AG21: 0 | AH21: 0 | AI21: 0 | AJ21: 0
A22: Property&Equipments&Other Assets | B22: =SUM(B23:B27) -> 4874587 | C22: =SUM(C23:C27) -> 14707861 | D22: =SUM(D23:D27) -> 27687116 | E22: =SUM(E23:E27) -> 26979015 | F22: =SUM(F23:F27) -> 34139566 | G22: =SUM(G23:G27) -> 33478223 | H22: =SUM(H23:H27) -> 33374581 | I22: =SUM(I23:I27) -> 33459013 | ... AO22: =SUM(AO23:AO27) -> 0
A23: Investment Properties | C23: 0 | D23: 0 | E23: 0 | F23: 0 | G23: 0 | H23: 0 | I23: 0 | J23: 0 | K23: 0 | L23: 0 | M23: 0 | N23: 0 | O23: 0 | Q23: 0 | R23: 0 | S23: 0 | T23: 0 | U23: 0 | V23: 0 | W23: 0 | X23: 0 | Y23: 0 | Z23: 0 | AA23: 0 | AB23: 0 | AC23: 0 | AD23: 0 | AE23: 0 | AF23: 0 | AG23: 0 | AH23: 0 | AI23: 0 | AJ23: 0
A24: Property and Equipment | B24: 4123114 | C24: 12039974 | D24: 12071336 | E24: 12791787 | F24: 12932891 | G24: 13132378 | H24: 13567985 | I24: 13797097 | J24: 13827902 | K24: 13800085 | L24: 14956940 | M24: 15307598 | N24: 15184616 | O24: 15298014 | P24: 15124222 | Q24: 15119684 | R24: 14921011 | S24: 14538513 | T24: 14402758 | U24: 15343975 | V24: 16026984 | W24: 15996644 | X24: 20323472 | Y24: 20103414 | Z24: 22423919 | AA24: 27638540 | AB24: 27897992 | AC24: 27896112 | AD24: 30247413 | AE24: 30616313 | AF24: 30662913 | AG24: 30385046 | AH24: 30230790 | AI24: 30119035 | AJ24: 30119468
A25: Prepaid Lease Rentals | B25: 0 | C25: 0 | D25: 605603.34 | E25: 495603.34 | F25: 770603.34 | G25: 660603.34 | H25: 605603.34 | I25: 550603.34 | J25: 495603.34 | K25: 440603.34 | L25: 732103.34 | M25: 677103.34 | N25: 622103.34 | O25: 567103.34 | Q25: 567103.34 | R25: 457103.34 | S25: 745853.34 | T25: 700703.34 | U25: 642953.34 | V25: 585203.34 | W25: 527453.34 | X25: 469703.34 | Y25: 772890.84 | Z25: 712253.34 | AA25: 651615.84 | AB25: 578378.34 | AC25: 0 | AD25: 517740.84 | AE25: 457103.34 | AF25: 457103.34 | AG25: 354103.34 | AH25: 457103.34 | AI25: 578378.34 | AJ25: 578378.34
A26: Intangible Assets | B26: 751473 | C26: 2667887 | D26: 2593619.8 | E26: 2521415.4 | F26: 2449210.9 | G26: 2380961.8 | H26: 2312768.3 | I26: 2396414.7 | J26: 2658026.9 | K26: 2751689.9 | L26: 2673101.4 | M26: 4246695.7 | N26: 4221023.4 | O26: 4155230.8 | P26: 4147680 | Q26: 4150029 | R26: 4038026.9 | S26: 3929135.6 | T26: 4393342.2 | U26: 4244655.4 | V26: 4083433.4 | W26: 3910024.3 | X26: 3753280.3 | Y26: 3596536.2 | Z26: 3379540.9 | AA26: 3231383 | AB26: 3522959 | AC26: 3515409 | AD26: 3425108.8 | AE26: 3491108.8 | AF26: 3535108.8 | AG26: 3535108.8 | AH26: 4337206.6 | AI26: 4239516.1 | AJ26: 4141875.6
A27: Other Assets | D27: 12416556 | E27: 11170210 | F27: 17986861 | G27: 17304280 | H27: 16888224 | I27: 16714898 | J27: 17955343 | K27: 20894366 | L27: 19257776 | M27: 17715579 | N27: 14231047 | O27: 11283601 | Q27: 14487323 | R27: 19924225 | S27: 22747867 | T27: 26337236 | U27: 26042001 | V27: 26453664 | W27: 28214826 | X27: 23239031 | Y27: 25816795 | Z27: 28762477 | AA27: 22936707 | AB27: 17804952 | AC27: 2675132 | AD27: 20182526 | AE27: 19372438 | AF27: 23032681 | AG27: 22864549 | AH27: 20584662 | AI27: 20923499 | AJ27: 20824168
A28: Total Assets | B28: =B22+B18+B15+B9+B8+B5 -> 151015729 | C28: =C22+C18+C15+C9+C8+C5 -> 425369462 | D28: =D22+D18+D15+D9+D8+D5 -> 4.2343836e+08 | E28: =E22+E18+E15+E9+E8+E5 -> 4.2605728e+08 | F28: =F22+F18+F15+F9+F8+F5 -> 4.3977411e+08 | G28: =G22+G18+G15+G9+G8+G5 -> 4.5166897e+08 | H28: =H22+H18+H15+H9+H8+H5 -> 4.5930984e+08 | I28: =I22+I18+I15+I9+I8+I5 -> 4.6686743e+08 | ... AO28: =AO22+AO18+AO15+AO9+AO8+AO5 -> 0
A29: Savings and Deposits | B29: 8112861 | C29: 69055366 | D29: 59103040 | E29: 58527832 | F29: 67730984 | G29: 73705286 | H29: 73751703 | I29: 75432870 | J29: 78081900 | K29: 74909437 | L29: 74105005 | M29: 69962704 | N29: 73079832 | O29: 80230784 | P29: 80230784 | Q29: 68440298 | R29: 88433353 | S29: 90023863 | T29: 89199124 | U29: 1.1206969e+08 | V29: 1.1185244e+08 | W29: 1.026842e+08 | X29: 99579654 | Y29: 1.1869714e+08 | Z29: 1.1154186e+08 | AA29: 1.3445803e+08 | AB29: 1.181484e+08 | AC29: 118148398 | AD29: 1.1021608e+08 | AE29: 1.0238197e+08 | AF29: 1.0815481e+08 | AG29: 1.0496368e+08 | AH29: 1.061593e+08 | AI29: 96970320 | AJ29: 1.0123825e+08
A30: Short Terrm Deposits | B30: 8350444 | C30: 1144590 | D30: 1147590 | E30: 1280990 | F30: 4623790 | G30: 4617840 | H30: 4634840 | I30: 4196000 | J30: 4736000 | K30: 4289000 | L30: 14689500 | M30: 14739500 | N30: 14739500 | O30: 14439500 | P30: 14439500 | Q30: 15309500 | R30: 15770000 | S30: 17719500 | T30: 15419500 | U30: 15469500 | V30: 15770000 | W30: 15770000 | X30: 15770000 | Y30: 15571900 | Z30: 16781900 | AA30: 17435474 | AB30: 7134574 | AC30: 7134574 | AD30: 7578764 | AE30: 6914974 | AF30: 7472184 | AG30: 8737939 | AH30: 8685939 | AI30: 9670139 | AJ30: 10424699
A31: Non Withdrawable Deposits | B31: 112140909 | C31: 228582666 | D31: 2.3527183e+08 | E31: 2.3895964e+08 | F31: 2.4660596e+08 | G31: 2.5082018e+08 | H31: 2.5667967e+08 | I31: 2.6235592e+08 | J31: 2.6521438e+08 | K31: 2.6976263e+08 | L31: 2.755323e+08 | M31: 2.8151789e+08 | N31: 2.8753569e+08 | O31: 2.8675886e+08 | P31: 286758860 | Q31: 2.9209457e+08 | R31: 2.9860918e+08 | S31: 3.0189103e+08 | T31: 3.0764944e+08 | U31: 3.1655863e+08 | V31: 3.1975261e+08 | W31: 3.2335375e+08 | X31: 3.1884835e+08 | Y31: 3.2244501e+08 | Z31: 3.2264543e+08 | AA31: 3.2831049e+08 | AB31: 3.212489e+08 | AC31: 321248900 | AD31: 3.2514337e+08 | AE31: 3.3152928e+08 | AF31: 3.3773217e+08 | AG31: 3.4956085e+08 | AH31: 3.5813603e+08 | AI31: 3.667259e+08 | AJ31: 3.6933998e+08
A32: Total Deposit Liabilities | B32: =SUM(B29:B31) -> 128604214 | C32: =SUM(C29:C31) -> 298782622 | D32: =SUM(D29:D31) -> 2.9552246e+08 | E32: =SUM(E29:E31) -> 2.9876846e+08 | F32: =SUM(F29:F31) -> 3.1896073e+08 | G32: =SUM(G29:G31) -> 3.2914331e+08 | H32: =SUM(H29:H31) -> 3.3506622e+08 | I32: =SUM(I29:I31) -> 3.4198479e+08 | ... AO32: =SUM(AO29:AO31) -> 0
A33: Tax Payable | B33: 27231 | C33: 72990 | D33: 0 | E33: 239364.49 | F33: 745907.18 | G33: 0 | H33: 0 | I33: 0 | J33: 0 | K33: 0 | L33: 0 | M33: 0 | N33: 0 | O33: 0 | P33: 349240 | Q33: 0 | R33: 0 | S33: 684137.02 | T33: 0 | U33: 0 | V33: 0 | W33: 0 | X33: 0 | Y33: 0 | Z33: 0 | AA33: 0 | AB33: 0 | AC33: 26501 | AD33: 0 | AE33: 52058.52 | AF33: 0 | AG33: 0 | AH33: 0 | AI33: 0 | AJ33: 0
A34: Dividends Payable | B34: 3618123 | C34: 11693602 | D34: 0 | E34: 5979035 | F34: 0 | G34: 0 | H34: 0 | I34: 0 | J34: 0 | K34: 0 | L34: 0 | M34: 0 | N34: 0 | O34: 0 | P34: 6948872 | Q34: 0 | R34: 0 | S34: 0 | T34: 0 | U34: 0 | V34: 0 | W34: 0 | X34: 0 | Y34: 0 | Z34: 0 | AA34: 0 | AB34: 0 | AC34: =9796905+6424978+150000+300000 -> 16671883 | AD34: 0 | AE34: 16671883 | AF34: 0 | AG34: 0 | AH34: 0 | AI34: 0 | AJ34: 0
A35: Deferred Tax Liability | C35: 0 | D35: 0 | E35: 0 | F35: 0 | G35: 0 | H35: 0 | I35: 0 | J35: 0 | K35: 0 | L35: 0 | M35: 0 | N35: 0 | O35: 0 | Q35: 0 | R35: 0 | S35: 0 | T35: 0 | U35: 0 | V35: 0 | W35: 0 | X35: 0 | Y35: 0 | Z35: 0 | AA35: 0 | AB35: 0 | AC35: 0 | AD35: 0 | AE35: 0 | AF35: 0 | AG35: 0 | AH35: 0 | AI35: 0 | AJ35: 0
A36: Retirement Benefits Liabilty | C36: 0 | D36: 0 | E36: 0 | F36: 0 | G36: 0 | H36: 0 | I36: 0 | J36: 0 | K36: 0 | L36: 0 | M36: 0 | N36: 0 | O36: 0 | Q36: 0 | R36: 0 | S36: 0 | T36: 0 | U36: 0 | V36: 0 | W36: 0 | X36: 0 | Y36: 0 | Z36: 0 | AA36: 0 | AB36: 0 | AC36: 0 | AD36: 0 | AE36: 0 | AF36: 0 | AG36: 0 | AH36: 0 | AI36: 0 | AJ36: 0
A37: Other Liabilities | B37: 1214920 | C37: 2671734 | D37: 1910516.3 | E37: 5386420.4 | F37: 1121640.4 | G37: 2465966.5 | H37: 2799191.9 | I37: 2630116.1 | J37: 2671333.6 | K37: 2342959.6 | L37: 2080306.4 | M37: 3354723.1 | N37: 2872430.4 | O37: 2565483.7 | P37: =15868792-P34 -> 8919920 | Q37: 2757005.9 | R37: 15828130 | S37: 3159439.4 | T37: 2808070.6 | U37: 2581088.7 | V37: 2212016 | W37: 2244297.8 | X37: 2227011.6 | Y37: 2130719.1 | Z37: 5443522.5 | AA37: 1047344.2 | AB37: 19796066 | AC37: 2828941 | AD37: 1924437.5 | AE37: 4398731.5 | AF37: 7928723.9 | AG37: 7299706 | AH37: 6361637.9 | AI37: 7744072.8 | AJ37: 8381856.9
A38: External Borrowings | B38: 2291669 | C38: 20000000 | D38: 20000000 | E38: 18888889 | F38: 17777778 | G38: 16666667 | H38: 15555556 | I38: 14444445 | J38: 13333333 | K38: 12222222 | L38: 26111111 | M38: 25485061 | N38: 23055556 | O38: 21527778 | P38: 21527778 | Q38: 35000000 | R38: 33055556 | S38: 31527778 | T38: 29155685 | U38: 27211240 | V38: 60000000 | W38: 58333333 | X38: 56666667 | Y38: 55000000 | Z38: 53333333 | AA38: 51666667 | AB38: 55000000 | AC38: 55000000 | AD38: 52608554 | AE38: 50941887 | AF38: 49583333 | AG38: 47777778 | AH38: 45972222 | AI38: 44695037 | AJ38: 42889481
A39: Total Liabilities | B39: =SUM(B32:B38) -> 135756157 | C39: =SUM(C32:C38) -> 333220948 | D39: =SUM(D32:D38) -> 3.1743298e+08 | E39: =SUM(E32:E38) -> 3.2926217e+08 | F39: =SUM(F32:F38) -> 3.3860606e+08 | G39: =SUM(G32:G38) -> 3.4827594e+08 | H39: =SUM(H32:H38) -> 3.5342096e+08 | I39: =SUM(I32:I38) -> 3.5905935e+08 | ... AO39: =SUM(AO32:AO38) -> 0
A40: Share Capital | B40: 10494697 | C40: 59790352 | D40: 60736993 | E40: 61600928 | F40: 62567055 | G40: 63496077 | H40: 64270079 | I40: 65053548 | J40: 65842783 | K40: 66573786 | L40: 67367373 | M40: 68090921 | N40: 68765442 | O40: 69488716 | P40: 69488716 | Q40: 70390869 | R40: 71331021 | S40: 72167810 | T40: 72992741 | U40: 73864351 | V40: 75380676 | W40: 77387881 | X40: 79198842 | Y40: 81250715 | Z40: 82383953 | AA40: 84713128 | AB40: 91472479 | AC40: 91472479 | AD40: 96380289 | AE40: 97466683 | AF40: 1.0492334e+08 | AG40: 1.0650311e+08 | AH40: 1.0743761e+08 | AI40: 1.0834524e+08 | AJ40: 1.0964473e+08
A41: Capital Grants | B41: 340425 | C41: 0 | D41: 0 | E41: 0 | F41: 0 | G41: 0 | H41: 0 | I41: 0 | J41: 0 | K41: 0 | L41: 0 | M41: 0 | N41: 0 | O41: 0 | Q41: 0 | R41: 0 | S41: 0 | T41: 0 | U41: 0 | V41: 0 | W41: 0 | X41: 0 | Y41: 0 | Z41: 0 | AA41: 0 | AB41: 0 | AC41: 0 | AD41: 0 | AE41: 0 | AF41: 0 | AG41: 0 | AH41: 0 | AI41: 0 | AJ41: 0
...

Sheet Evolutitve SCI
A1: VISION AFRIKA SACCO SOCIETY | E1: KIPSIGIS EDIS SACCO SOCIETY | G1: KIPSIGIS EDIS SACCO SOCIETY | I1: KIPSIGIS EDIS SACCO SOCIETY | K1: KIPSIGIS EDIS SACCO SOCIETY | M1: KIPSIGIS EDIS SACCO SOCIETY
A2: STATEMENT OF COMPREHENSIVE INCOME | C2: STATEMENT OF COMPREHENSIVE INCOME | E2: STATEMENT OF COMPREHENSIVE INCOME | G2: STATEMENT OF COMPREHENSIVE INCOME | I2: STATEMENT OF COMPREHENSIVE INCOME | K2: STATEMENT OF COMPREHENSIVE INCOME | M2: STATEMENT OF COMPREHENSIVE INCOME
B3: 2010 Audited | C3: 2020 Audited | D3: 44197 | E3: 44229 | F3: 44258 | G3: 44290 | H3: 44321 | I3: 44353 | J3: 44384 | K3: 44416 | L3: 44448 | M3: 44479 | N3: 44511 | O3: 44542 | P3: Audited 2021 | Q3: 44562 | R3: 44593 | S3: 44621 | T3: 44652 | U3: 44682 | V3: 44713 | W3: 44743 | X3: 44774 | Y3: 44805 | Z3: 44835 | AA3: 44866 | AB3: 44896 | AC3: Audited 2022 | AD3: 44927 | AE3: 44958 | AF3: 44986 | AG3: 45017 | AH3: 45047 | AI3: 45078 | AJ3: 45108 | AK3: 45139 | AL3: 45170 | AM3: 45200
A4: Financial Income | B4: =B5+B8 -> 14599.248 | C4: =C5+C8 -> 63720140 | D4: =D5+D8 -> 5713089.2 | E4: =E5+E8 -> 11297674 | F4: =F5+F8 -> 17949436 | G4: =G5+G8 -> 24917688 | H4: =H5+H8 -> 32298739 | I4: =I5+I8 -> 39038421 | ... AM4: =AM5+AM8 -> 0
A5: Financial Income From Loans Portfolio | B5: =SUM(B6:B7) -> 12855.806 | C5: =SUM(C6:C7) -> 48012555 | D5: =SUM(D6:D7) -> 5376032.7 | E5: =SUM(E6:E7) -> 10488008 | F5: =SUM(F6:F7) -> 16410048 | G5: =SUM(G6:G7) -> 22960662 | H5: =SUM(H6:H7) -> 29910160 | I5: =SUM(I6:I7) -> 36036409 | ... AM5: =SUM(AM6:AM7) -> 0
A6: Interest from Loans Portfolio | B6: 11945.435 | C6: 48012555 | D6: 4725458.3 | E6: 9735649 | F6: 14569971 | G6: 19912041 | H6: 24447913 | I6: 29715252 | J6: 36572235 | K6: 46196163 | L6: 52031591 | M6: 58995130 | N6: 65345449 | O6: 72838980 | P6: 74695913 | Q6: 6753021.6 | R6: 13938188 | S6: 21197140 | T6: 28757621 | U6: 37147371 | V6: 40650736 | W6: 51708004 | X6: 59293384 | Y6: 67016784 | Z6: 75720995 | AA6: 84174371 | AB6: 92866686 | AC6: 96450196 | AD6: 8072358.7 | AE6: 15846573 | AF6: 23806368 | AG6: 76494150 | AH6: 95908526 | AI6: 48352305 | AJ6: 56793892
A7: Fees&Commision on Loan Portfolio | B7: 910.371 | C7: 0 | D7: 650574.4 | E7: 752358.9 | F7: 1840077.8 | G7: 3048620.9 | H7: 5462246.4 | I7: 6321157 | J7: 7288347.2 | K7: 3997112.1 | L7: 5393206.9 | M7: 5483850.7 | N7: 7008109.2 | O7: 8496687 | Q7: 973119 | R7: 1430190.6 | S7: 3044885.5 | T7: 3835907.8 | U7: 4607124.1 | V7: 10052257 | W7: 5928262.2 | X7: 7935312.6 | Y7: 9189501.5 | Z7: 10556551 | AA7: 13503540 | AB7: 14350660 | AC7: =194783+1812929 -> 2007712 | AD7: 1068389.2 | AE7: 750961.7 | AF7: 2187285.7 | AG7: 0 | AH7: 0 | AI7: 4947294.8 | AJ7: 6055915.1
A8: Financial Income from Investments | B8: =SUM(B9:B12) -> 1743.4416 | C8: =SUM(C9:C12) -> 15707585 | D8: =SUM(D9:D12) -> 337056.54 | E8: =SUM(E9:E12) -> 809666.04 | F8: =SUM(F9:F12) -> 1539387.3 | G8: =SUM(G9:G12) -> 1957026.3 | H8: =SUM(H9:H12) -> 2388579.1 | I8: =SUM(I9:I12) -> 3002011.9 | ... AM8: =SUM(AM9:AM12) -> 0
A9: Government Securities | C9: 0 | D9: 0 | E9: 0 | F9: 0 | G9: 0 | H9: 0 | I9: 0 | J9: 0 | K9: 0 | L9: 0 | M9: 0 | N9: 0 | O9: 0 | Q9: 0 | R9: 0 | S9: 0 | T9: 0 | U9: 0 | V9: 0 | W9: 0 | X9: 0 | Y9: 0 | AD9: 0 | AE9: 0 | AF9: 0 | AG9: 0 | AH9: 0 | AI9: 0 | AJ9: 0
A10: Deposits with Banks & other Financial Institutions | C10: 0 | D10: 0 | E10: 0 | F10: 0 | G10: 0 | H10: 0 | I10: 0 | J10: 0 | K10: 0 | L10: 0 | M10: 0 | N10: 0 | O10: 0 | Q10: 0 | R10: 0 | S10: 0 | T10: 0 | U10: 0 | V10: 0 | W10: 0 | X10: 0 | Y10: 0 | AD10: 0 | AE10: 0 | AF10: 0 | AG10: 0 | AH10: 0 | AI10: 0 | AJ10: 0
A11: Other Investments | C11: 0 | D11: 0 | E11: 0 | F11: 0 | G11: 0 | H11: 0 | I11: 0 | J11: 0 | K11: 0 | L11: 0 | M11: 0 | N11: 0 | O11: 0 | P11: 37150 | Q11: 0 | R11: 0 | S11: 0 | T11: 0 | U11: 0 | V11: 0 | W11: 0 | X11: 0 | Y11: 0 | AC11: 79335 | AD11: 0 | AE11: 0 | AF11: 0 | AG11: 0 | AH11: 0 | AI11: 0 | AJ11: 0
A12: Other Operating Income | B12: 1743.4416 | C12: 15707585 | D12: 337056.54 | E12: 809666.04 | F12: 1539387.3 | G12: 1957026.3 | H12: 2388579.1 | I12: 3002011.9 | J12: 3587199.5 | K12: 4164659.1 | L12: 4480850.4 | M12: 4912494.4 | N12: 5881196 | O12: 5648078 | P12: 12250681 | Q12: 379301.34 | R12: 911463.54 | S12: 1628232.2 | T12: 2154791.9 | U12: 3136874.3 | V12: 3651981.5 | W12: 5332224.9 | X12: 4702308.3 | Y12: 5482715.7 | Z12: 6218759.3 | AA12: 6980894.9 | AB12: 7483729.5 | AC12: =15679820-AC7 -> 13672108 | AD12: 663643.4 | AE12: 1266842.5 | AF12: 2351890.7 | AG12: 0 | AH12: 0 | AI12: 4801186.8 | AJ12: 5677664.2
A13: Financial Expenses | B13: =SUM(B14:B19) -> 549.0847 | C13: =SUM(C14:C19) -> 13181407 | D13: =SUM(D14:D19) -> 137390.4 | E13: =SUM(E14:E19) -> 854259.22 | F13: =SUM(F14:F19) -> 1154061.3 | G13: =SUM(G14:G19) -> 1425488.2 | H13: =SUM(H14:H19) -> 1739119.4 | I13: =SUM(I14:I19) -> 1948867.5 | ... AM13: =SUM(AM14:AM19) -> 0
A14: Interest Expense on Deposits | B14: 185.36 | C14: 5714567 | D14: 0 | E14: 35887.33 | F14: 36374.67 | G14: 36374.67 | H14: 138934 | I14: 146882.2 | J14: 186882.2 | K14: 187782.2 | L14: 212782.2 | M14: 212782.2 | N14: 212782.2 | O14: 500607.82 | P14: 6235785 | Q14: 35825 | R14: 199025 | S14: 468288 | T14: 574307.1 | U14: 574307.1 | V14: 849993.4 | W14: 875883.81 | X14: 875883.81 | Y14: 1243439.6 | Z14: 1309895.9 | AA14: 1322602.8 | AB14: 1613584.9 | AC14: 8038563 | AD14: 76168.78 | AE14: 124234.33 | AF14: 127307.07 | AG14: 551114.05 | AH14: 726913.35 | AI14: 415025.64 | AJ14: 540242.5
A15: Cost of External Borrowings | B15: 363.7247 | C15: 610000 | D15: 0 | E15: 277808.22 | F15: 466179.61 | G15: 662465.75 | H15: 840547.94 | I15: 1012298.4 | J15: 1166636.3 | K15: 1313850.9 | L15: 1448797.7 | M15: 1988797.7 | N15: 2049220.1 | O15: 2845567.1 | P15: 2845567 | Q15: 871171.46 | R15: 1268294.8 | S15: 1452510.9 | T15: 1930463.7 | U15: 2242107.5 | V15: 3642855.5 | W15: 4454910.3 | X15: 5098974.2 | Y15: 5619887.9 | Z15: 6207633.7 | AA15: 6515574.2 | AB15: 7248222.7 | AC15: 7248223 | AD15: 368438.4 | AE15: 902091.38 | AF15: 2079477.2 | AG15: 11918988 | AH15: 15655737 | AI15: 3831018.4 | AJ15: 4375973.2
A16: Dividend Expenses | C16: 0 | D16: 0 | E16: 0 | F16: 0 | G16: 0 | H16: 0 | I16: 0 | J16: 0 | K16: 0 | L16: 0 | M16: 0 | N16: 0 | O16: 0 | Q16: 0 | R16: 0 | S16: 0 | T16: 0 | U16: 0 | V16: 0 | W16: 0 | X16: 0 | Y16: 0 | Z16: 0 | AA16: 0 | AD16: 0 | AE16: 0 | AF16: 0 | AG16: 0 | AH16: 0 | AI16: 0 | AJ16: 0
A17: Other Financial Expense | C17: 5727793 | D17: 53290.4 | E17: 406463.67 | F17: 466407.04 | G17: 500587.81 | H17: 533577.41 | I17: 563626.87 | J17: 670799.47 | K17: 708885.78 | L17: 815120.67 | M17: 917306.27 | N17: 1518236.1 | O17: 1278030.2 | P17: =3496741-P15 -> 651174 | Q17: 103832.2 | R17: 709472.88 | S17: 391688.68 | T17: 554340.02 | U17: 801939.02 | V17: 882541.62 | W17: 1563370.6 | X17: 2241000.2 | Y17: 2770414.2 | Z17: 3396726.8 | AA17: 4201973.8 | AB17: 5277075.2 | AC17: =12372744-AC15-AC18 -> 5120521 | AD17: 364280.64 | AE17: 678017.23 | AF17: 963895.23 | AG17: 214045.76 | AH17: 343509.03 | AI17: 2127638.5 | AJ17: 2461434
A18: Fees & Commision Expense | C18: 0 | D18: 84100 | E18: 134100 | F18: 185100 | G18: 226060 | H18: 226060 | I18: 226060 | J18: 226060 | K18: 261060 | L18: 261060 | M18: 280060 | N18: 318060 | O18: 332100 | Q18: 330000 | R18: 318100 | S18: 420005 | T18: 942875 | U18: 1012875 | V18: 1012875 | W18: 1049875 | X18: 1052875 | Y18: 1112875 | Z18: 1112875 | AA18: 1120875 | AB18: 1440170 | AC18: 4000 | AD18: 290000 | AE18: 677000 | AF18: 727000 | AG18: 0 | AH18: 0 | AI18: 1729501 | AJ18: 2084606
A19: Other Expenses | C19: 1129047 | D19: 0 | E19: 0 | F19: 0 | G19: 0 | H19: 0 | I19: 0 | J19: 0 | K19: 0 | L19: 0 | M19: 0 | N19: 0 | O19: 0 | Q19: 0 | R19: 0 | S19: 0 | T19: 0 | U19: 0 | V19: 0 | W19: 0 | X19: 0 | Y19: 0 | AD19: 0 | AE19: 0 | AF19: 0 | AG19: 0 | AH19: 0 | AI19: 0 | AJ19: 0
A20: Net Financial Income | B20: =B4-B13 -> 14050.163 | C20: =C4-C13 -> 50538733 | D20: =D4-D13 -> 5575698.8 | E20: =E4-E13 -> 10443415 | F20: =F4-F13 -> 16795374 | G20: =G4-G13 -> 23492200 | H20: =H4-H13 -> 30559619 | I20: =I4-I13 -> 37089553 | ... AM20: =AM4-AM13 -> 0
A21: Allowance for Loan Loss | B21: =B22-B23 -> 0 | C21: 9350985 | D21: =D22-D23 -> 10948246 | E21: =E22-E23 -> 3187876.6 | F21: =F22-F23 -> 2217279.8 | G21: =G22-G23 -> 3881831.5 | H21: =H22-H23 -> 6307639 | I21: =I22-I23 -> 8280057.1 | J21: =J22-J23 -> 11089848 | K21: =K22-K23 -> 10170035 | ... AM21: =AM22-AM23 -> 0
A22: Provision for Loan Losses | C22: 9350985 | D22: 10948246 | E22: 3187876.6 | F22: 2217279.8 | G22: 3881831.5 | H22: 6307639 | I22: 8280057.1 | J22: 11089848 | K22: 10170035 | L22: 14514347 | M22: 14578128 | N22: 14191673 | O22: 10978635 | P22: 14735275 | Q22: 16454051 | R22: 6217539.2 | S22: 3405286.4 | T22: 9956127.3 | U22: 12051063 | V22: 14340326 | W22: 13698125 | X22: 10851036 | Y22: 14483881 | Z22: 13492350 | AA22: 21025723 | AB22: 9905345.4 | AC22: 9905345 | AD22: 14986598 | AE22: 10447236 | AF22: 2751947.8 | AG22: 3186924.2 | AH22: 3660730.5 | AI22: 19219607 | AJ22: 24635232
A23: Value of Loans Recovered | C23: 0 | D23: 0 | E23: 0 | F23: 0 | G23: 0 | H23: 0 | I23: 0 | J23: 0 | K23: 0 | L23: 0 | M23: 0 | N23: 0 | O23: 0 | Q23: 0 | R23: 0 | S23: 0 | T23: 0 | U23: 0 | V23: 0 | W23: 0 | X23: 0 | Y23: 0 | AD23: 0 | AE23: 0 | AF23: 0 | AG23: 0 | AH23: 0 | AI23: 0 | AJ23: 0
A24: Operating Expeses | B24: =SUM(B25:B29) -> 11019.38 | C24: =SUM(C25:C29) -> 27366529 | D24: =SUM(D25:D29) -> 2443286.7 | E24: =SUM(E25:E29) -> 6468759.5 | F24: =SUM(F25:F29) -> 10384507 | G24: =SUM(G25:G29) -> 14120823 | H24: =SUM(H25:H29) -> 17040590 | I24: =SUM(I25:I29) -> 20462375 | ... AM24: =SUM(AM25:AM29) -> 0
A25: Personel Expenses | B25: 3512.444 | C25: 13868938 | D25: 1128257 | E25: 2823502 | F25: 4075096 | G25: 5793896 | H25: 7147788 | I25: 8667439 | J25: 10146889 | K25: 11428379 | L25: 12812925 | M25: 14196676 | N25: 15733117 | O25: 17615738 | P25: 18282763 | Q25: 1839430.8 | R25: 3954644.9 | S25: 5364365.6 | T25: 7745960.6 | U25: 9562930.8 | V25: 11309562 | W25: 13115147 | X25: 14775826 | Y25: 16436322 | Z25: 18070280 | AA25: 19651862 | AB25: 21676875 | AC25: 23734705 | AD25: 1732054.5 | AE25: 5121632.1 | AF25: 6939508.4 | AG25: 16100374 | AH25: 20929264 | AI25: 12729471 | AJ25: 14721200
A26: Governance Expenses | B26: 401.873 | C26: 2306230 | D26: 233128 | E26: 405139 | F26: 1134137 | G26: 1249854 | H26: 1538354 | I26: 1775007 | J26: 1924045 | K26: 1982457 | L26: 2368957 | M26: 2540983 | N26: 3281856 | O26: 3689226 | P26: 3689226 | Q26: 89194 | R26: 1136297.6 | S26: 2389485.4 | T26: 2717615.4 | U26: 3066099.3 | V26: 3395616.8 | W26: 4083583 | X26: 4481083.2 | Y26: 4747564.4 | Z26: 5204880.6 | AA26: 5833981.8 | AB26: 6232563 | AC26: 7261203 | AD26: 544089.78 | AE26: 751428.56 | AF26: 1862376.3 | AG26: 6773065 | AH26: 7449404.5 | AI26: 3108886.3 | AJ26: 3442156.3
A27: Marketing Expenses | B27: 919.3528 | C27: 2978074 | D27: 164380 | E27: 797118 | F27: 1146721 | G27: 1376971 | H27: 1579241 | I27: 1903041 | J27: 2399816 | K27: 2651856 | L27: 3012443 | M27: 3429579 | N27: 3798659 | O27: 4859953 | P27: 4859953 | Q27: 261870 | R27: 1180120 | S27: 1747330 | T27: 2089856 | U27: 2695666 | V27: 3322706 | W27: 4261439 | X27: 4505189 | Y27: 5294844 | Z27: 5732435 | AA27: 6695064 | AB27: 7698722 | AC27: 6670082 | AD27: 369800 | AE27: 803760 | AF27: 1670130 | AG27: 6597123.5 | AH27: 7876326 | AI27: 4474485 | AJ27: 4799530
A28: Depreciation and Amortization | B28: 1276.981 | C28: 2525875 | D28: 198753.72 | E28: 412331.1 | F28: 607431.33 | G28: 512767.84 | H28: 996879.89 | I28: 1198921.8 | J28: 1407854.5 | K28: 1617758.1 | L28: 1843391.8 | M28: 2065815.9 | N28: 2296720.4 | O28: 2514865.5 | P28: =17432483-P22 -> 2697208 | Q28: 331531.22 | R28: 656306.32 | S28: 962483.8 | T28: 1250532.2 | U28: 1591001.9 | V28: 1952615.1 | W28: 2352364.2 | X28: 2732280.4 | Y28: 3109082.1 | Z28: 3543072.7 | AA28: 3905214.8 | AB28: 3714836.8 | AC28: =2332715+1382422 -> 3715137 | AD28: 285929.49 | AE28: 285929.49 | AF28: 285929.49 | AG28: 1763209.6 | AH28: 2204011.7 | AI28: 1714174.8 | AJ28: 1999522.2
A29: Administrative Expenses | B29: 4908.7291 | C29: 5687412 | D29: 718768 | E29: 2030669.4 | F29: 3421121.8 | G29: 5187334.1 | H29: 5778326.8 | I29: 6917965.8 | J29: 7981106.2 | K29: 9202441.2 | L29: 10431320 | M29: 11923370 | N29: 13287192 | O29: 14653799 | P29: 15113622 | Q29: 1312310 | R29: 2829054 | S29: 5355199.8 | T29: 6210465.5 | U29: 7428301.5 | V29: 8907330.9 | W29: 10960958 | X29: 12427756 | Y29: 14214216 | Z29: 15614547 | AA29: 17664856 | AB29: 19694523 | AC29: 19229417 | AD29: 2042982.3 | AE29: 3887303.3 | AF29: 7203582.8 | AG29: 23997134 | AH29: 30274758 | AI29: 11843172 | AJ29: 13628639
A30: Net Operating Income | B30: =B20-B21-B24 -> 3030.7829 | C30: =C20-C21-C24 -> 13821219 | D30: =D20-D21-D24 -> -7815834.2 | E30: =E20-E21-E24 -> 786778.62 | F30: =F20-F21-F24 -> 4193587.4 | G30: =G20-G21-G24 -> 5489545.3 | H30: =H20-H21-H24 -> 7211390.7 | I30: =I20-I21-I24 -> 8347121.8 | ... AM30: =AM20-AM21-AM24 -> 0
A31: Net Non operating Income/Expense | B31: =B32-B33 -> 0 | C31: 0 | D31: =D32-D33 -> 0 | E31: =E32-E33 -> 0 | F31: =F32-F33 -> 0 | G31: =G32-G33 -> 0 | H31: =H32-H33 -> 0 | I31: =I32-I33 -> 0 | J31: =J32-J33 -> 0 | K31: =K32-K33 -> 0 | ... AM31: =AM32-AM33 -> 0
A32: Non Operating Income | C32: 0 | D32: 0 | E32: 0 | F32: 0 | G32: 0 | H32: 0 | I32: 0 | J32: 0 | K32: 0 | L32: 0 | M32: 0 | N32: 0 | O32: 0 | Q32: 0 | R32: 0 | S32: 0 | T32: 0 | U32: 0 | V32: 0 | W32: 0 | X32: 0 | Y32: 0 | AD32: 0 | AE32: 0 | AF32: 0 | AG32: 0 | AH32: 0 | AI32: 0 | AJ32: 0
A33: Non Operating Expense | C33: 0 | D33: 0 | E33: 0 | F33: 0 | G33: 0 | H33: 0 | I33: 0 | J33: 0 | K33: 0 | L33: 0 | M33: 0 | N33: 0 | O33: 0 | Q33: 0 | R33: 0 | S33: 0 | T33: 0 | U33: 0 | V33: 0 | W33: 0 | X33: 0 | Y33: 0 | AD33: 0 | AE33: 0 | AF33: 0 | AG33: 0 | AH33: 0 | AI33: 0 | AJ33: 0
A34: Net Income(Before Tax & Donations) | B34: =B30+B31 -> 3030.7829 | C34: =C30+C31 -> 13821219 | D34: =D30+D31 -> -7815834.2 | E34: =E30+E31 -> 786778.62 | F34: =F30+F31 -> 4193587.4 | G34: =G30+G31 -> 5489545.3 | H34: =H30+H31 -> 7211390.7 | I34: =I30+I31 -> 8347121.8 | ... AM34: =AM30+AM31 -> 0
A35: Taxes | B35: 20 | C35: 72990 | D35: 0 | E35: 0 | F35: 0 | G35: 0 | H35: 0 | I35: 0 | J35: 0 | K35: 0 | L35: 0 | M35: 0 | N35: 0 | O35: 0 | P35: 756008 | Q35: 0 | R35: 0 | S35: 0 | T35: 0 | U35: 0 | V35: 0 | W35: 0 | X35: 0 | Y35: 0 | AC35: 784018 | AD35: 0 | AE35: 0 | AF35: 0 | AG35: 364891.8 | AH35: 490895.7 | AI35: 0 | AJ35: 0
A36: Net Income(After Tax Before Donations) | B36: =B34-B35 -> 3010.7829 | C36: =C34-C35 -> 13748229 | D36: =D34-D35 -> -7815834.2 | E36: =E34-E35 -> 786778.62 | F36: =F34-F35 -> 4193587.4 | G36: =G34-G35 -> 5489545.3 | H36: =H34-H35 -> 7211390.7 | I36: =I34-I35 -> 8347121.8 | ... AM36: =AM34-AM35 -> 0
A37: Donations | D37: 0 | E37: 0 | F37: 0 | G37: 0 | H37: 0 | I37: 0 | J37: 0 | K37: 0 | L37: 0 | M37: 0 | N37: 0 | O37: 0 | Q37: 0 | R37: 0 | S37: 0 | T37: 0 | U37: 0 | V37: 0 | W37: 0 | X37: 0 | Y37: 0 | AD37: 0 | AE37: 0 | AF37: 0 | AG37: 0 | AH37: 0 | AI37: 0 | AJ37: 0
A38: Net Income/(After Tax & Donations) | B38: =B36-B37 -> 3010.7829 | C38: =C36-C37 -> 13748229 | D38: =D36-D37 -> -7815834.2 | E38: =E36-E37 -> 786778.62 | F38: =F36-F37 -> 4193587.4 | G38: =G36-G37 -> 5489545.3 | H38: =H36-H37 -> 7211390.7 | I38: =I36-I37 -> 8347121.8 | ... AM38: =AM36-AM37 -> 0
A40: Total Expenses | B40: =B13+B24 -> 11568.465 | C40: =C13+C24 -> 40547936 | D40: =D13+D24 -> 2580677.1 | E40: =E13+E24 -> 7323018.8 | F40: =F13+F24 -> 11538568 | G40: =G13+G24 -> 15546311 | H40: =H13+H24 -> 18779709 | I40: =I13+I24 -> 22411242 | ... O40: =O13+O24 -> 48289887 | P40: =P13+P24+P35+P22 -> 69866581 | Q40: =Q13+Q24 -> 5175164.7 | R40: =R13+R24 -> 12251315 | S40: =S13+S24 -> 18551357 | T40: =T13+T24 -> 24016416 | U40: =U13+U24 -> 28975228 | V40: =V13+V24 -> 35276097 | W40: =W13+W24 -> 42717531 | X40: =X13+X24 -> 48190868 | ... AM40: =AM13+AM24 -> 0
J42: =J40-I40 -> 3698846.6 | K42: =K40-J40 -> 3244381.5 | L42: =L40-K40 -> 3852327.4 | M42: =M40-L40 -> 4348572.7 | N42: =N40-M40 -> 4940473 | O42: =O40-N40 -> 5794043.5 | P42: =P40-O40 -> 21576694 | Q42: =Q40-P40 -> -64691416 | ... AD42: =AD40-AC40 -> -74948107

Sheet Financials
B1: Vision Afrika Sacco Financial Performance
B2: Year | C2: 2010 Audited | D2: 2020 Audited | E2: 44197 | F2: 44229 | G2: 44258 | H2: 44290 | I2: 44321 | J2: 44353 | K2: 44384 | L2: 44416 | M2: 44448 | N2: 44479 | O2: 44511 | P2: 44542 | Q2: Audited 2021 | R2: 44562 | S2: 44593 | T2: 44621 | U2: 44652 | V2: 44682 | W2: 44713 | X2: 44743 | Y2: 44774 | Z2: 44805 | AA2: 44835 | AB2: 44866 | AC2: 44896 | AD2: Audited-2022 | AE2: 44927 | AF2: 44958 | AG2: 44986 | AH2: 45017 | AI2: 45047 | AJ2: 45078 | AK2: 45108 | AL2: 45139 | AM2: 45170 | AN2: 45200 | AO2: 45231 | AP2: 45261
A3: 1 | B3: Membership
A4: 2 | B4: Total Assets | C4: ='Evolutive SFP'!B28 -> 151015729 | D4: ='Evolutive SFP'!C28 -> 425369462 | E4: ='Evolutive SFP'!D28 -> 4.2343836e+08 | F4: ='Evolutive SFP'!E28 -> 4.2605728e+08 | G4: ='Evolutive SFP'!F28 -> 4.3977411e+08 | H4: ='Evolutive SFP'!G28 -> 4.5166897e+08 | I4: ='Evolutive SFP'!H28 -> 4.5930984e+08 | J4: ='Evolutive SFP'!I28 -> 4.6686743e+08 | ... AQ4: ='Evolutive SFP'!AP28 -> 0
A5: 3 | B5: Total Deposits | C5: ='Evolutive SFP'!B32 -> 128604214 | D5: ='Evolutive SFP'!C32 -> 298782622 | E5: ='Evolutive SFP'!D32 -> 2.9552246e+08 | F5: ='Evolutive SFP'!E32 -> 2.9876846e+08 | G5: ='Evolutive SFP'!F32 -> 3.1896073e+08 | H5: ='Evolutive SFP'!G32 -> 3.2914331e+08 | I5: ='Evolutive SFP'!H32 -> 3.3506622e+08 | J5: ='Evolutive SFP'!I32 -> 3.4198479e+08 | ... AQ5: ='Evolutive SFP'!AP32 -> 0
A6: 3.1 | B6: Deposits-Members(BOSA) | C6: ='Evolutive SFP'!B31 -> 112140909 | D6: ='Evolutive SFP'!C31 -> 228582666 | E6: ='Evolutive SFP'!D31 -> 2.3527183e+08 | F6: ='Evolutive SFP'!E31 -> 2.3895964e+08 | G6: ='Evolutive SFP'!F31 -> 2.4660596e+08 | H6: ='Evolutive SFP'!G31 -> 2.5082018e+08 | I6: ='Evolutive SFP'!H31 -> 2.5667967e+08 | J6: ='Evolutive SFP'!I31 -> 2.6235592e+08 | ... AQ6: ='Evolutive SFP'!AP31 -> 0
A7: 3.2 | B7: Deposits-Customers(FOSA) | C7: =('Evolutive SFP'!B29+'Evolutive SFP'!B30) -> 16463305 | D7: =('Evolutive SFP'!C29+'Evolutive SFP'!C30) -> 70199956 | E7: =('Evolutive SFP'!D29+'Evolutive SFP'!D30) -> 60250630 | F7: =('Evolutive SFP'!E29+'Evolutive SFP'!E30) -> 59808822 | G7: =('Evolutive SFP'!F29+'Evolutive SFP'!F30) -> 72354774 | H7: =('Evolutive SFP'!G29+'Evolutive SFP'!G30) -> 78323126 | I7: =('Evolutive SFP'!H29+'Evolutive SFP'!H30) -> 78386543 | J7: =('Evolutive SFP'!I29+'Evolutive SFP'!I30) -> 79628870 | ... AQ7: =('Evolutive SFP'!AP29+'Evolutive SFP'!AP30) -> 0
A8: 4 | B8: External Borrowing | C8: ='Evolutive SFP'!B38 -> 2291669 | D8: ='Evolutive SFP'!C38 -> 20000000 | E8: ='Evolutive SFP'!D38 -> 20000000 | F8: ='Evolutive SFP'!E38 -> 18888889 | G8: ='Evolutive SFP'!F38 -> 17777778 | H8: ='Evolutive SFP'!G38 -> 16666667 | I8: ='Evolutive SFP'!H38 -> 15555556 | J8: ='Evolutive SFP'!I38 -> 14444445 | ... AQ8: ='Evolutive SFP'!AP38 -> 0
A10: 5 | B10: Share capital and Reserves
A11: 5.1 | B11: Core Capital | C11: =C14-C22-C25 -> 14446887 | D11: =D14-D22-D25 -> 91853472 | E11: =E14-E22-E25 -> 1.0571034e+08 | F11: =F14-F22-F25 -> 96500071 | G11: =G14-G22-G25 -> 1.0087301e+08 | H11: =H14-H22-H25 -> 1.0309799e+08 | I11: =I14-I22-I25 -> 1.0559383e+08 | J11: =J14-J22 -> 1.0780605e+08 | K11: =K14-K22 -> 1.1049601e+08 | L11: =L14-L22 -> 1.158126e+08 | M11: =M14-M22 -> 1.1596526e+08 | N11: =N14-N22 -> 1.1837719e+08 | O11: =O14-O22 -> 1.2334097e+08 | P11: =P14-P22 -> 1.3023223e+08 | Q11: =Q14-Q22 -> 112641898 | ... AQ11: =AQ14-AQ22 -> 0
A12: 5.2 | B12: Institutional Capital | C12: =C11-C15 -> 3952190 | D12: =D11-D15 -> 32063120 | E12: =E11-E15 -> 44973345 | F12: =F11-F15 -> 34899143 | G12: =G11-G15 -> 38305952 | H12: =H11-H15 -> 39601910 | I12: =I11-I15 -> 41323755 | J12: =J11-J15 -> 42752507 | ... AQ12: =AQ11-AQ15 -> 0
A14: 5.3 | B14: Total Capital | C14: =C15+C16+C17+C18+C19+C20+C21 -> 14919147 | D14: =D15+D16+D17+D18+D19+D20+D21 -> 92146493 | E14: =E15+E16+E17+E18+E19+E20+E21 -> 1.0600336e+08 | F14: =F15+F16+F17+F18+F19+F20+F21 -> 96793091 | G14: =G15+G16+G17+G18+G19+G20+G21 -> 1.0116603e+08 | H14: =H15+H16+H17+H18+H19+H20+H21 -> 1.0339101e+08 | I14: =I15+I16+I17+I18+I19+I20+I21 -> 1.0588685e+08 | J14: =J15+J16+J17+J18+J19+J20+J21 -> 1.0780605e+08 | ... AQ14: =AQ15+AQ16+AQ17+AQ18+AQ19+AQ20+AQ21 -> 0
A15: 5.3.1 | B15: Members Share Capital | C15: ='Evolutive SFP'!B40 -> 10494697 | D15: ='Evolutive SFP'!C40 -> 59790352 | E15: ='Evolutive SFP'!D40 -> 60736993 | F15: ='Evolutive SFP'!E40 -> 61600928 | G15: ='Evolutive SFP'!F40 -> 62567055 | H15: ='Evolutive SFP'!G40 -> 63496077 | I15: ='Evolutive SFP'!H40 -> 64270079 | J15: ='Evolutive SFP'!I40 -> 65053548 | ... AQ15: ='Evolutive SFP'!AP40 -> 0
A16: 5.3.2 | B16: Entrance Fees
A17: 5.3.3 | B17: Retained Earnings | C17: ='Evolutive SFP'!B42 -> 351220 | D17: ='Evolutive SFP'!C42 -> 19788651 | E17: ='Evolutive SFP'!D42 -> 19788651 | F17: ='Evolutive SFP'!E42 -> 26472293 | G17: ='Evolutive SFP'!F42 -> 26472293 | H17: ='Evolutive SFP'!G42 -> 26472293 | I17: ='Evolutive SFP'!H42 -> 26472293 | J17: ='Evolutive SFP'!I42 -> 26472293 | ... AQ17: ='Evolutive SFP'!AP42 -> 0
A18: 5.3.4 | B18: Appropriation Account | C18: ='Evolutive SFP'!B43 -> 3541956 | D18: ='Evolutive SFP'!C43 -> 5045847 | E18: ='Evolutive SFP'!D43 -> -7815834.3 | F18: ='Evolutive SFP'!E43 -> 786778.6 | G18: ='Evolutive SFP'!F43 -> 4193587.3 | H18: ='Evolutive SFP'!G43 -> 5489545.3 | I18: ='Evolutive SFP'!H43 -> 7211390.7 | J18: ='Evolutive SFP'!I43 -> 8347121.8 | ... AQ18: ='Evolutive SFP'!AP43 -> 0
A19: 5.3.5 | B19: Statutory Reserves | C19: ='Evolutive SFP'!B44 -> 531274 | D19: ='Evolutive SFP'!C44 -> 7521643 | E19: ='Evolutive SFP'!D44 -> 4765423 | F19: ='Evolutive SFP'!E44 -> 7933092 | G19: ='Evolutive SFP'!F44 -> 7933092 | H19: ='Evolutive SFP'!G44 -> 7933092 | I19: ='Evolutive SFP'!H44 -> 7933092 | J19: ='Evolutive SFP'!I44 -> 7933092 | ... AQ19: ='Evolutive SFP'!AP44 -> 0
A20: 5.3.6 | B20: Capital Reserves | C20: =('Evolutive SFP'!B45) -> 0 | D20: =('Evolutive SFP'!C45) -> 0 | E20: =('Evolutive SFP'!D45) -> 28528126 | F20: =('Evolutive SFP'!E45) -> 0 | G20: =('Evolutive SFP'!F45) -> 0 | H20: =('Evolutive SFP'!G45) -> 0 | I20: =('Evolutive SFP'!H45) -> 0 | J20: =('Evolutive SFP'!I45) -> 0 | ... AQ20: =('Evolutive SFP'!AP45) -> 0
A21: 5.3.7 | B21: Supplementary Capital & reserves | C21: =C22+C23 -> 0 | D21: =D22+D23 -> 0 | E21: =E22+E23 -> 0 | F21: =F22+F23 -> 0 | G21: =G22+G23 -> 0 | H21: =H22+H23 -> 0 | I21: =I22+I23 -> 0 | J21: =J22+J23 -> 0 | ... AQ21: =AQ22+AQ23 -> 0
A22: a | B22: Proposed Dividends | C22: ='Evolutive SFP'!B47 -> 0 | D22: ='Evolutive SFP'!C47 -> 0 | E22: ='Evolutive SFP'!D47 -> 0 | F22: ='Evolutive SFP'!E47 -> 0 | G22: ='Evolutive SFP'!F47 -> 0 | H22: ='Evolutive SFP'!G47 -> 0 | I22: ='Evolutive SFP'!H47 -> 0 | J22: ='Evolutive SFP'!I47 -> 0 | ... AQ22: ='Evolutive SFP'!AP47 -> 0
A23: b | B23: Risk Mgt Fund
A25: 6 | B25: Investments | C25: =C26+C27+C28 -> 472260 | D25: =D26+D27+D28 -> 293021 | E25: =E26+E27+E28 -> 293020.64 | F25: =F26+F27+F28 -> 293020.64 | G25: =G26+G27+G28 -> 293020.64 | H25: =H26+H27+H28 -> 293020.64 | I25: =I26+I27+I28 -> 293020.64 | J25: =J26+J27+J28 -> 293020.64 | ... AQ25: =AQ26+AQ27+AQ28 -> 0
A26: 6.1 | B26: Shares in Kusco,CIC,Coop Bank | C26: ='Evolutive SFP'!B14 -> 472260 | D26: ='Evolutive SFP'!C14 -> 293021 | E26: ='Evolutive SFP'!D14 -> 293020.64 | F26: ='Evolutive SFP'!E14 -> 293020.64 | G26: ='Evolutive SFP'!F14 -> 293020.64 | H26: ='Evolutive SFP'!G14 -> 293020.64 | I26: ='Evolutive SFP'!H14 -> 293020.64 | J26: ='Evolutive SFP'!I14 -> 293020.64 | ... AQ26: ='Evolutive SFP'!AP14 -> 0
A27: 6.2 | B27: Equity Investments (at cost) | C27: ='Evolutive SFP'!B11 -> 0 | D27: ='Evolutive SFP'!C11 -> 0 | E27: ='Evolutive SFP'!D11 -> 0 | F27: ='Evolutive SFP'!E11 -> 0 | G27: ='Evolutive SFP'!F11 -> 0 | H27: ='Evolutive SFP'!G11 -> 0 | I27: ='Evolutive SFP'!H11 -> 0 | J27: ='Evolutive SFP'!I11 -> 0 | ... AQ27: ='Evolutive SFP'!AP11 -> 0
A28: 6.3 | B28: Deposits in KUSCCO CFP | C28: ='Evolutive SFP'!B12 -> 0 | D28: ='Evolutive SFP'!C12 -> 0 | E28: ='Evolutive SFP'!D12 -> 0 | F28: ='Evolutive SFP'!E12 -> 0 | G28: ='Evolutive SFP'!F12 -> 0 | H28: ='Evolutive SFP'!G12 -> 0 | I28: ='Evolutive SFP'!H12 -> 0 | J28: ='Evolutive SFP'!I12 -> 0 | ... AQ28: ='Evolutive SFP'!AP12 -> 0
A30: 7 | B30: Net Loans & Advances | C30: ='Evolutive SFP'!B15 -> 112905266 | D30: ='Evolutive SFP'!C15 -> 361847211 | E30: ='Evolutive SFP'!D15 -> 3.5780519e+08 | F30: ='Evolutive SFP'!E15 -> 3.5845378e+08 | G30: ='Evolutive SFP'!F15 -> 3.6291313e+08 | H30: ='Evolutive SFP'!G15 -> 3.8098937e+08 | I30: ='Evolutive SFP'!H15 -> 3.8825293e+08 | J30: ='Evolutive SFP'!I15 -> 3.8992474e+08 | ... AQ30: ='Evolutive SFP'!AP15 -> 0
A31: 7.1 | B31: Gross Loans & advances | C31: ='Evolutive SFP'!B16 -> 112905266 | D31: ='Evolutive SFP'!C16 -> 371165321 | E31: ='Evolutive SFP'!D16 -> 3.6876144e+08 | F31: ='Evolutive SFP'!E16 -> 3.7097772e+08 | G31: ='Evolutive SFP'!F16 -> 3.7451242e+08 | H31: ='Evolutive SFP'!G16 -> 3.9365943e+08 | I31: ='Evolutive SFP'!H16 -> 4.0337954e+08 | J31: ='Evolutive SFP'!I16 -> 4.0662377e+08 | ... AQ31: ='Evolutive SFP'!AP16 -> 0
A32: 7.2 | B32: Allowance for loan losses | C32: ='Evolutive SFP'!B17 -> 0 | D32: ='Evolutive SFP'!C17 -> 9318110 | E32: ='Evolutive SFP'!D17 -> 10956246 | F32: ='Evolutive SFP'!E17 -> 12523937 | G32: ='Evolutive SFP'!F17 -> 11599285 | H32: ='Evolutive SFP'!G17 -> 12670063 | I32: ='Evolutive SFP'!H17 -> 15126606 | J32: ='Evolutive SFP'!I17 -> 16699024 | ... AQ32: ='Evolutive SFP'!AP17 -> 0
A34: 8 | B34: Non-Earning Assets | C34: ='Evolutive SFP'!B22+'Evolutive SFP'!B8 -> 18274979 | D34: ='Evolutive SFP'!C22+'Evolutive SFP'!C8 -> 22186373 | E34: ='Evolutive SFP'!D22+'Evolutive SFP'!D8 -> 27687116 | F34: ='Evolutive SFP'!E22+'Evolutive SFP'!E8 -> 26979015 | G34: ='Evolutive SFP'!F22+'Evolutive SFP'!F8 -> 34139566 | H34: ='Evolutive SFP'!G22+'Evolutive SFP'!G8 -> 33478223 | I34: ='Evolutive SFP'!H22+'Evolutive SFP'!H8 -> 33374581 | J34: ='Evolutive SFP'!I22+'Evolutive SFP'!I8 -> 33459013 | ... AQ34: ='Evolutive SFP'!AP22+'Evolutive SFP'!AP8 -> 0
A35: 8.1 | B35: Property and Equipment | C35: ='Evolutive SFP'!B24 -> 4123114 | D35: ='Evolutive SFP'!C24 -> 12039974 | E35: ='Evolutive SFP'!D24 -> 12071336 | F35: ='Evolutive SFP'!E24 -> 12791787 | G35: ='Evolutive SFP'!F24 -> 12932891 | H35: ='Evolutive SFP'!G24 -> 13132378 | I35: ='Evolutive SFP'!H24 -> 13567985 | J35: ='Evolutive SFP'!I24 -> 13797097 | ... AQ35: ='Evolutive SFP'!AP24 -> 0
A37: 9 | B37: Turnover | C37: =C38+C39+C40+C41 -> 14599.248 | D37: =D38+D39+D40+D41 -> 63720140 | E37: =E38+E39+E40+E41 -> 5713089.2 | F37: =F38+F39+F40+F41 -> 11297674 | G37: =G38+G39+G40+G41 -> 17949436 | H37: =H38+H39+H40+H41 -> 24917688 | I37: =I38+I39+I40+I41 -> 32298739 | J37: =J38+J39+J40+J41 -> 39038421 | ... AQ37: =AQ38+AQ39+AQ40+AQ41 -> 0
A38: 9.1 | B38: Loan Interest | C38: ='Evolutitve SCI'!B6 -> 11945.435 | D38: ='Evolutitve SCI'!C6 -> 48012555 | E38: ='Evolutitve SCI'!D6 -> 4725458.3 | F38: ='Evolutitve SCI'!E6 -> 9735649 | G38: ='Evolutitve SCI'!F6 -> 14569971 | H38: ='Evolutitve SCI'!G6 -> 19912041 | I38: ='Evolutitve SCI'!H6 -> 24447913 | J38: ='Evolutitve SCI'!I6 -> 29715252 | ... AD38: ='Evolutitve SCI'!AC6 -> 96450196 | AE38: ='Evolutitve SCI'!AF6 -> 23806368 | AF38: ='Evolutitve SCI'!AG6 -> 76494150 | AG38: ='Evolutitve SCI'!AH6 -> 95908526 | AH38: ='Evolutitve SCI'!AI6 -> 48352305 | AI38: ='Evolutitve SCI'!AJ6 -> 56793892 | AJ38: ='Evolutitve SCI'!AK6 -> 0 | AK38: ='Evolutitve SCI'!AL6 -> 0 | AL38: ='Evolutitve SCI'!AM6 -> 0 | ... AQ38: ='Evolutitve SCI'!AR6 -> 0
A39: 9.2 | B39: Income from investments | C39: ='Evolutitve SCI'!B8 -> 1743.4416 | D39: ='Evolutitve SCI'!C8 -> 15707585 | E39: ='Evolutitve SCI'!D8 -> 337056.54 | F39: ='Evolutitve SCI'!E8 -> 809666.04 | G39: ='Evolutitve SCI'!F8 -> 1539387.3 | H39: ='Evolutitve SCI'!G8 -> 1957026.3 | I39: ='Evolutitve SCI'!H8 -> 2388579.1 | J39: ='Evolutitve SCI'!I8 -> 3002011.9 | ... AD39: ='Evolutitve SCI'!AC8 -> 13751443 | AE39: ='Evolutitve SCI'!AF8 -> 2351890.7 | AF39: ='Evolutitve SCI'!AG8 -> 0 | AG39: ='Evolutitve SCI'!AH8 -> 0 | AH39: ='Evolutitve SCI'!AI8 -> 4801186.8 | AI39: ='Evolutitve SCI'!AJ8 -> 5677664.2 | AJ39: ='Evolutitve SCI'!AK8 -> 0 | AK39: ='Evolutitve SCI'!AL8 -> 0 | AL39: ='Evolutitve SCI'!AM8 -> 0 | ... AQ39: ='Evolutitve SCI'!AR8 -> 0
A40: 9.3 | B40: Fees & Commissions | C40: ='Evolutitve SCI'!B7 -> 910.371 | D40: ='Evolutitve SCI'!C7 -> 0 | E40: ='Evolutitve SCI'!D7 -> 650574.4 | F40: ='Evolutitve SCI'!E7 -> 752358.9 | G40: ='Evolutitve SCI'!F7 -> 1840077.8 | H40: ='Evolutitve SCI'!G7 -> 3048620.9 | I40: ='Evolutitve SCI'!H7 -> 5462246.4 | J40: ='Evolutitve SCI'!I7 -> 6321157 | ... AD40: ='Evolutitve SCI'!AC7 -> 2007712 | AE40: ='Evolutitve SCI'!AF7 -> 2187285.7 | AF40: ='Evolutitve SCI'!AG7 -> 0 | AG40: ='Evolutitve SCI'!AH7 -> 0 | AH40: ='Evolutitve SCI'!AI7 -> 4947294.8 | AI40: ='Evolutitve SCI'!AJ7 -> 6055915.1 | AJ40: ='Evolutitve SCI'!AK7 -> 0 | AK40: ='Evolutitve SCI'!AL7 -> 0 | AL40: ='Evolutitve SCI'!AM7 -> 0 | ... AQ40: ='Evolutitve SCI'!AR7 -> 0
A41: 9.4 | B41: Average yield on loans
A43: 10 | B43: Financial and Operating costs | C43: =SUM(C44:C47) -> 11568.465 | D43: =SUM(D44:D47) -> 39418889 | E43: =SUM(E44:E47) -> 2496577.1 | F43: =SUM(F44:F47) -> 7188918.8 | G43: =SUM(G44:G47) -> 11353468 | H43: =SUM(H44:H47) -> 15320251 | I43: =SUM(I44:I47) -> 18553649 | J43: =SUM(J44:J47) -> 22185182 | ... AQ43: =SUM(AQ44:AQ47) -> 0
A44: 10.1 | B44: Interest expense on deposits | C44: ='Evolutitve SCI'!B14+'Evolutitve SCI'!B17 -> 185.36 | D44: ='Evolutitve SCI'!C14+'Evolutitve SCI'!C17 -> 11442360 | E44: ='Evolutitve SCI'!D14+'Evolutitve SCI'!D17 -> 53290.4 | F44: ='Evolutitve SCI'!E14+'Evolutitve SCI'!E17 -> 442351 | G44: ='Evolutitve SCI'!F14+'Evolutitve SCI'!F17 -> 502781.71 | H44: ='Evolutitve SCI'!G14+'Evolutitve SCI'!G17 -> 536962.48 | I44: ='Evolutitve SCI'!H14+'Evolutitve SCI'!H17 -> 672511.41 | J44: ='Evolutitve SCI'!I14+'Evolutitve SCI'!I17 -> 710509.07 | ... AD44: ='Evolutitve SCI'!AC14+'Evolutitve SCI'!AC17 -> 13159084 | AE44: ='Evolutitve SCI'!AF14+'Evolutitve SCI'!AF17 -> 1091202.3 | AF44: ='Evolutitve SCI'!AG14+'Evolutitve SCI'!AG17 -> 765159.81 | AG44: ='Evolutitve SCI'!AH14+'Evolutitve SCI'!AH17 -> 1070422.4 | AH44: ='Evolutitve SCI'!AI14+'Evolutitve SCI'!AI17 -> 2542664.1 | AI44: ='Evolutitve SCI'!AJ14+'Evolutitve SCI'!AJ17 -> 3001676.5 | AJ44: ='Evolutitve SCI'!AK14+'Evolutitve SCI'!AK17 -> 0 | AK44: ='Evolutitve SCI'!AL14+'Evolutitve SCI'!AL17 -> 0 | AL44: ='Evolutitve SCI'!AM14+'Evolutitve SCI'!AM17 -> 0 | ... AQ44: ='Evolutitve SCI'!AR14+'Evolutitve SCI'!AR17 -> 0
A45: 10.2 | B45: Dividend expense on share capital | C45: ='Evolutitve SCI'!B16 -> 0 | D45: ='Evolutitve SCI'!C16 -> 0 | E45: ='Evolutitve SCI'!D16 -> 0 | F45: ='Evolutitve SCI'!E16 -> 0 | G45: ='Evolutitve SCI'!F16 -> 0 | H45: ='Evolutitve SCI'!G16 -> 0 | I45: ='Evolutitve SCI'!H16 -> 0 | J45: ='Evolutitve SCI'!I16 -> 0 | ... AD45: ='Evolutitve SCI'!AC16 -> 0 | AE45: ='Evolutitve SCI'!AF16 -> 0 | AF45: ='Evolutitve SCI'!AG16 -> 0 | AG45: ='Evolutitve SCI'!AH16 -> 0 | AH45: ='Evolutitve SCI'!AI16 -> 0 | AI45: ='Evolutitve SCI'!AJ16 -> 0 | AJ45: ='Evolutitve SCI'!AK16 -> 0 | AK45: ='Evolutitve SCI'!AL16 -> 0 | AL45: ='Evolutitve SCI'!AM16 -> 0 | ... AQ45: ='Evolutitve SCI'!AR16 -> 0
A46: 10.3 | B46: Interest expense on borrowed funds | C46: ='Evolutitve SCI'!B15 -> 363.7247 | D46: ='Evolutitve SCI'!C15 -> 610000 | E46: ='Evolutitve SCI'!D15 -> 0 | F46: ='Evolutitve SCI'!E15 -> 277808.22 | G46: ='Evolutitve SCI'!F15 -> 466179.61 | H46: ='Evolutitve SCI'!G15 -> 662465.75 | I46: ='Evolutitve SCI'!H15 -> 840547.94 | J46: ='Evolutitve SCI'!I15 -> 1012298.4 | ... AD46: ='Evolutitve SCI'!AC15 -> 7248223 | AE46: ='Evolutitve SCI'!AF15 -> 2079477.2 | AF46: ='Evolutitve SCI'!AG15 -> 11918988 | AG46: ='Evolutitve SCI'!AH15 -> 15655737 | AH46: ='Evolutitve SCI'!AI15 -> 3831018.4 | AI46: ='Evolutitve SCI'!AJ15 -> 4375973.2 | AJ46: ='Evolutitve SCI'!AK15 -> 0 | AK46: ='Evolutitve SCI'!AL15 -> 0 | AL46: ='Evolutitve SCI'!AM15 -> 0 | ... AQ46: ='Evolutitve SCI'!AR15 -> 0
A47: 10.4 | B47: Opperating expenses | C47: ='Evolutitve SCI'!B24 -> 11019.38 | D47: ='Evolutitve SCI'!C24 -> 27366529 | E47: ='Evolutitve SCI'!D24 -> 2443286.7 | F47: ='Evolutitve SCI'!E24 -> 6468759.5 | G47: ='Evolutitve SCI'!F24 -> 10384507 | H47: ='Evolutitve SCI'!G24 -> 14120823 | I47: ='Evolutitve SCI'!H24 -> 17040590 | J47: ='Evolutitve SCI'!I24 -> 20462375 | ... AD47: ='Evolutitve SCI'!AC24 -> 60610544 | AE47: ='Evolutitve SCI'!AF24 -> 17961527 | AF47: ='Evolutitve SCI'!AG24 -> 55230906 | AG47: ='Evolutitve SCI'!AH24 -> 68733764 | AH47: ='Evolutitve SCI'!AI24 -> 33870188 | AI47: ='Evolutitve SCI'!AJ24 -> 38591047 | AJ47: ='Evolutitve SCI'!AK24 -> 0 | AK47: ='Evolutitve SCI'!AL24 -> 0 | AL47: ='Evolutitve SCI'!AM24 -> 0 | ... AQ47: ='Evolutitve SCI'!AR24 -> 0

Sheet  FORM 4-2021
D1: 44256
B2: CLASSIFICATION | C2: NO. OF A/Cs | D2: OUTSTANDING LOAN PORTFOLIO(Kshs) | E2: REQUIRED PROVISION | F2: REQUIRED PROVISION AMOUNT(Kshs)
B3: Performing | C3: 1133 | D3: 2.5107245e+08 | E3: 0.01 | F3: =D3*E3 -> 2510724.5
B4: Watch | C4: 56 | D4: 11599862 | E4: 0.05 | F4: =D4*E4 -> 579993.08 | H4: NPL | I4: =D5+D6+D7 -> 4859452.5
B5: Substandard | C5: 10 | D5: 2211244 | E5: 0.25 | F5: =D5*E5 -> 552810.99 | H5: PAR | I5: =I4/D8 -> 0.018164021
B6: Doubtful | C6: 9 | D6: 2539012.2 | E6: 0.5 | F6: =D6*E6 -> 1269506.1
B7: Loss | C7: 1 | D7: 109196.3 | E7: 1 | F7: =D7*E7 -> 109196.3
B8: subtotal | C8: =SUM(C3:C7) -> 1209 | D8: =SUM(D3:D7) -> 2.6753177e+08 | E8: =SUM(E3:E7) -> 1.81 | F8: =SUM(F3:F7) -> 5022231
D10: 44348
B11: CLASSIFICATION | C11: NO. OF A/Cs | D11: OUTSTANDING LOAN PORTFOLIO(Kshs) | E11: REQUIRED PROVISION | F11: REQUIRED PROVISION AMOUNT(Kshs)
B12: Performing | C12: 1033 | D12: 2.9519095e+08 | E12: 0.01 | F12: =D12*E12 -> 2951909.5
B13: Watch | C13: 208 | D13: 49118366 | E13: 0.05 | F13: =D13*E13 -> 2455918.3
B14: Substandard | C14: 89 | D14: 22213074 | E14: 0.25 | F14: =D14*E14 -> 5553268.5 | H14: NPL | I14: =D14+D15+D16 -> 26147975
B15: Doubtful | C15: 5 | D15: 1266122.1 | E15: 0.5 | F15: =D15*E15 -> 633061.07 | H15: PAR | I15: =I14/D17 -> 0.070582968
B16: Loss | C16: 38 | D16: 2668778.9 | E16: 1 | F16: =D16*E16 -> 2668778.9
B17: subtotal | C17: =SUM(C12:C16) -> 1373 | D17: =SUM(D12:D16) -> 3.7045729e+08 | E17: 1.81 | F17: =SUM(F12:F16) -> 14262936
D19: 44440
B20: CLASSIFICATION | C20: NO. OF A/Cs | D20: OUTSTANDING LOAN PORTFOLIO(Kshs) | E20: REQUIRED PROVISION | F20: REQUIRED PROVISION AMOUNT(Kshs)
B21: Performing | C21: 1037 | D21: 3.0521995e+08 | E21: 0.01 | F21: =D21*E21 -> 3052199.5
B22: Watch | C22: 277 | D22: 54456279 | E22: 0.05 | F22: =D22*E22 -> 2722814 | H22: NPL | I22: =D23+D24+D25 -> 44340158
B23: Substandard | C23: 123 | D23: 38064282 | E23: 0.25 | F23: =D23*E23 -> 9516070.6 | H23: PAR | I23: =I22/D26 -> 0.10974842
B24: Doubtful | C24: 9 | D24: 2617613.7 | E24: 0.5 | F24: =D24*E24 -> 1308806.8
B25: Loss | C25: 66 | D25: 3658262 | E25: 1 | F25: =D25*E25 -> 3658262
B26: subtotal | C26: =SUM(C21:C25) -> 1512 | D26: =SUM(D21:D25) -> 4.0401638e+08 | E26: 1.81 | F26: =SUM(F21:F25) -> 20258153
D28: 44531
B29: CLASSIFICATION | C29: NO. OF A/Cs | D29: OUTSTANDING LOAN PORTFOLIO(Kshs) | E29: REQUIRED PROVISION | F29: REQUIRED PROVISION AMOUNT(Kshs)
B30: Performing | C30: 1133 | D30: 3.5646832e+08 | E30: 0.01 | F30: =D30*E30 -> 3564683.2
B31: Watch | C31: 268 | D31: 71989999 | E31: 0.05 | F31: =D31*E31 -> 3599500 | H31: NPL | I31: =D32+D33+D34 -> 16958386
B32: Substandard | C32: 44 | D32: 11907385 | E32: 0.25 | F32: =D32*E32 -> 2976846.2 | H32: PAR | I32: =I31/D35 -> 0.038073081
B33: Doubtful | C33: 8 | D33: 3874480 | E33: 0.5 | F33: =D33*E33 -> 1937240
B34: Loss | C34: 31 | D34: 1176521.4 | E34: 1 | F34: =D34*E34 -> 1176521.4
B35: subtotal | C35: =SUM(C30:C34) -> 1484 | D35: =SUM(D30:D34) -> 4.454167e+08 | E35: 1.81 | F35: =SUM(F30:F34) -> 13254791
D38: Audited 2021
B39: CLASSIFICATION | C39: NO. OF A/Cs | D39: OUTSTANDING LOAN PORTFOLIO(Kshs) | E39: REQUIRED PROVISION | F39: REQUIRED PROVISION AMOUNT(Kshs)
B40: Performing | D40: 382329955 | E40: 0.01 | F40: =D40*E40 -> 3823299.6
B41: Watch | D41: 75239582 | E41: 0.05 | F41: =D41*E41 -> 3761979.1
B42: Substandard | D42: 15253902 | E42: 0.25 | F42: =D42*E42 -> 3813475.5
B43: Doubtful | D43: 4215574 | E43: 0.5 | F43: =D43*E43 -> 2107787
B44: Loss | D44: 1228734 | E44: 1 | F44: =D44*E44 -> 1228734
B45: subtotal | C45: =SUM(C40:C44) -> 0 | D45: =D40+D41+D42+D43+D44 -> 478267747 | E45: 1.81 | F45: =SUM(F40:F44) -> 14735275

Sheet FORM 4-2022
A2: VISION AFRIKA SACCO SOCIETY LIMITED
A3: FORM 4
A4: RISK CLASSIFICATION
A6: 44621
A7: CLASSIFICATION | B7: NO. OF A/Cs | C7: OUTSTANDING LOAN PORTFOLIO(Kshs) | D7: REQUIRED PROVISION | E7: REQUIRED PROVISION AMOUNT(Kshs)
A8: Performing | B8: 1025 | C8: 3.6263438e+08 | D8: 0.01 | E8: =C8*D8 -> 3626343.8
A9: Watch | B9: 245 | C9: 72059288 | D9: 0.05 | E9: =C9*D9 -> 3602964.4
A10: Substandard | B10: 137 | C10: 17728963 | D10: 0.25 | E10: =C10*D10 -> 4432240.7
A11: Doubtful | B11: 16 | C11: 9528105.8 | D11: 0.5 | E11: =C11*D11 -> 4764052.9
A12: Loss | B12: 61 | C12: 3633253.1 | D12: 1 | E12: =C12*D12 -> 3633253.1
A13: subtotal | B13: =SUM(B8:B12) -> 1484 | C13: =SUM(C8:C12) -> 4.6558399e+08 | E13: =SUM(E8:E12) -> 20058855
A14: Reschedule/Renegotiated loans
A15: Performing | B15: 35 | C15: 17710295 | D15: 0.01 | E15: =C15*D15 -> 177102.95
A16: Watch | B16: 15 | C16: 5225787.7 | D16: 0.05 | E16: =C16*D16 -> 261289.38 | F16: =C10+C11+C12+C20 -> 57031974
A17: Substandard | B17: 6 | C17: 1930753.8 | D17: 0.25 | E17: =C17*D17 -> 482688.44 | F17: =(C10+C11+C12+C20)/C21 -> 0.11598332
A18: Doubtful | B18: 1 | C18: 339716.67 | D18: 0.5 | E18: =C18*D18 -> 169858.33
A19: Loss | B19: 2 | C19: 935098.54 | D19: 1 | E19: =C19*D19 -> 935098.54
A20: subtotal | B20: =SUM(B14:B19) -> 59 | C20: =SUM(C14:C19) -> 26141652 | E20: =SUM(E14:E19) -> 2026037.6
A21: GRAND TOTAL | B21: =B13+B20 -> 1543 | C21: =C13+C20 -> 4.9172564e+08 | E21: =E13+E20 -> 22084893
A24: 44713
A25: CLASSIFICATION | B25: NO. OF A/Cs | C25: OUTSTANDING LOAN PORTFOLIO(Kshs) | D25: REQUIRED PROVISION | E25: REQUIRED PROVISION AMOUNT(Kshs)
A26: Performing | B26: 1058 | C26: 3.6182684e+08 | D26: 0.01 | E26: =C26*D26 -> 3618268.4
A27: Watch | B27: 323 | C27: 1.0118516e+08 | D27: 0.05 | E27: =C27*D27 -> 5059257.8
A28: Substandard | B28: 215 | C28: 46834890 | D28: 0.25 | E28: =C28*D28 -> 11708723
A29: Doubtful | B29: 18 | C29: 5327601.8 | D29: 0.5 | E29: =C29*D29 -> 2663800.9
A30: Loss | B30: 104 | C30: 6408700.2 | D30: 1 | E30: =C30*D30 -> 6408700.2
A31: subtotal | B31: =SUM(B26:B30) -> 1718 | C31: =SUM(C26:C30) -> 5.2158319e+08 | E31: =SUM(E26:E30) -> 29458750
A32: Reschedule/Renegotiated loans | F32: =C28+C29+C30+C38 -> 81818832
A33: Performing | B33: 27 | C33: 12060426 | D33: 0.01 | E33: =C33*D33 -> 120604.26 | F33: =(C28+C29+C30+C38)/C39 -> 0.15017291
A34: Watch | B34: 9 | C34: 4818311.3 | D34: 0.05 | E34: =C34*D34 -> 240915.56
A35: Substandard | B35: 15 | C35: 4335597.9 | D35: 0.25 | E35: =C35*D35 -> 1083899.5
A36: Doubtful | B36: 2 | C36: 776469.44 | D36: 0.5 | E36: =C36*D36 -> 388234.72
A37: Loss | B37: 3 | C37: 1256835.2 | D37: 1 | E37: =C37*D37 -> 1256835.2
A38: subtotal | B38: =SUM(B32:B37) -> 56 | C38: =SUM(C32:C37) -> 23247640 | E38: =SUM(E32:E37) -> 3090489.2
A39: GRAND TOTAL | B39: =B31+B38 -> 1774 | C39: =C31+C38 -> 5.4483083e+08 | E39: =E31+E38 -> 32549239
A43: 44805
A44: CLASSIFICATION | B44: NO. OF A/Cs | C44: OUTSTANDING LOAN PORTFOLIO(Kshs) | D44: REQUIRED PROVISION | E44: REQUIRED PROVISION AMOUNT(Kshs)
A45: Performing | B45: 1264 | C45: 3.7999316e+08 | D45: 0.01 | E45: =C45*D45 -> 3799931.6
A46: Watch | B46: 325 | C46: 97671692 | D46: 0.05 | E46: =C46*D46 -> 4883584.6
A47: Substandard | B47: 225 | C47: 46643592 | D47: 0.25 | E47: =C47*D47 -> 11660898
...

Sheet compliance status audited 2022
A1: VISION AFRICA SACCO SOCIETY LIMITED
A2: PERFORMANCE AND COMPLIANCE REPORT AS AT : 31st December , 2021
B3: Prudential Standard | C3: Audited | D3: Returns | F3: Audited 2021 | H3: Aggregate for all Licensed Saccos
C4: 2020 | D4: 30th September , 2021 | E4: 31st December , 2021 | G4: Audited 2022
A5: A. CAPITAL ADEQUACY
A6: Core Capital | B6: ≥10M | C6: =C33 -> 91924493 | D6: =D33 -> 1.0857999e+08 | E6: =E33 -> 1.160816e+08 | F6: =F33 -> 112348877 | G6: =G33 -> 144680832 | H6: =H33 -> 1.1863726e+11
A7: Core Capital/Total Assets | B7: ≥10% | C7: =C33/C29 -> 0.21610506 | D7: =D33/D29 -> 0.21353606 | E7: =E33/E29 -> 0.21666851 | F7: =F33/F29 -> 0.21125402 | G7: =G33/G29 -> 0.21724592 | H7: =H33/H29 -> 0.17098641
A8: Institutional Capital/Total Assets | B8: ≥8% | C8: =C34/C29 -> 0.075544071 | D8: =D34/D29 -> 0.081049737 | E8: =E34/E29 -> 0.086966501 | F8: =F34/F29 -> 0.080591651 | G8: =G34/G29 -> 0.079895155 | H8: =H34/H29 -> 0.10520614
A9: B. ASSET QUALITY
A10: NPL (Substandard+Doubtful+Loss) | B10: <5% | C10: =C35/C32 -> 0 | D10: =D35/D32 -> 0.17916119 | E10: =E35/E32 -> 0.097318012 | F10: =F35/F32 -> 0.043277453 | G10: =G35/G32 -> 0.041384015 | H10: =H35/H32 -> 0.081282559
A11: Non-Earning Assets | B11: <10% | C11: =C36/C29 -> 0.052157889 | D11: =D36/D29 -> 0.073984253 | E11: =E36/E29 -> 0.058429417 | F11: =F36/F29 -> 0.051719498 | G11: =G36/G29 -> 0.071171502 | H11: =H36/H29 -> 0.098107352
A12: Equity investments/Deposits | B12: <5% | C12: =C38/C31 -> 0.0007430151 | D12: =D38/D31 -> 0.00080427967 | E12: =E38/E31 -> 0.00076821775 | F12: =F38/F31 -> 0.0007682187 | G12: =G38/G31 -> 0.00052664998 | H12: =H38/H31 -> 0.028360463
A13: Equity investments/Core capital | B13: <40% | C13: =C38/C33 -> 0.0024150256 | D13: =D38/D33 -> 0.0026986615 | E13: =E38/E33 -> 0.0025242644 | F13: =F38/F33 -> 0.0026081347 | G13: =G38/G33 -> 0.0016254123 | H13: =H38/H33 -> 0.11226744
A14: C. EARNINGS RATING
A15: Yield on Gross Loans | C15: =C48/C32 -> 0.12935625 | D15: =D48/D32 -> 0.1310526 | E15: =E48/E32 -> 0.17135912 | F15: =F48/F32 -> 0.15618012 | G15: =G48/G32 -> 0.16495586 | H15: =H48/H32 -> 0.15911073
A16: Total Expense/Total Income | C16: =C49/C44 -> 0.65406295 | D16: =D49/D44 -> 0.53640982 | E16: =E49/E44 -> 0.5551599 | F16: =F49/F44 -> 0.80321423 | G16: =G49/G44 -> 0.72205971 | H16: =H49/H44 -> 0.71152696
A17: Net Income/Average Assets (ROA) | C17: =C50/C30 -> 0.037059571 | D17: =D50/D30 -> 0.03220745 | E17: =E50/E30 -> 0.057723814 | F17: =F50/F30 -> 0.035765507 | G17: =G50/G30 -> 0.034226422 | H17: =H50/H30 -> 0.037337841
