Workbook

Sheet CAELS
A1: WANANCHI SACCO CAELS
D2: 2010 Audited | E2: 2017Audited | F2: 43102 | G2: 43132 | H2: 43162 | I2: 43192 | J2: 43222 | K2: 43253 | L2: 43283 | M2: 43314 | N2: 43345 | O2: 43375 | P2: 43406 | Q2: 43436 | R2: Audited 2018 | S2: 43469 | T2: 43501 | U2: 43530 | V2: 43562 | W2: 43593 | X2: 43625 | Y2: 43656 | Z2: 43688 | AA2: 43720 | AB2: 43751 | AC2: 43783 | AD2: 43814 | AE2: AUDITED 2019 | AF2: 43847 | AG2: 43879 | AH2: 43909 | AI2: 43941 | AJ2: 43972 | AK2: 44004 | AL2: 44066 | AM2: 44098 | AN2: 44129 | AO2: 44161 | AP2: 44192 | AQ2: AUDITED 2020 | AR2: 44197 | AS2: 44228 | AT2: 44256 | AU2: 44287 | AV2: 44317 | AW2: 44348 | AX2: 44378 | AY2: 44409 | AZ2: 44440 | BA2: 44470 | BB2: 44501 | BC2: 44531 | BD2: Audited 2021 | BE2: 44562 | BF2: 44593 | BG2: 44621 | BH2: 44652 | BI2: 44682 | BJ2: 44713 | BK2: 44743 | BL2: 44774 | BM2: 44805 | BN2: 44835 | BO2: 44866 | BP2: 44896 | BQ2: Audited 2022
A3: CAPITAL ADEQUACY | B3: Core Capital | C3: 10 M | D3: =(('Evolutive SFP'!B39+'Evolutive SFP'!B40+'Evolutive SFP'!B41+'Evolutive SFP'!B42+'Evolutive SFP'!B43+'Evolutive SFP'!B44)-'Evolutive SFP'!B10)/1000000 -> 15.259572 | E3: =(('Evolutive SFP'!C39+'Evolutive SFP'!C40+'Evolutive SFP'!C41+'Evolutive SFP'!C42+'Evolutive SFP'!C43+'Evolutive SFP'!C44)-'Evolutive SFP'!C10)/1000000 -> 251.79176 | F3: =(('Evolutive SFP'!D39+'Evolutive SFP'!D40+'Evolutive SFP'!D41+'Evolutive SFP'!D42+'Evolutive SFP'!D43+'Evolutive SFP'!D44)-'Evolutive SFP'!D7)/1000000 -> 170.66799 | G3: =(('Evolutive SFP'!E39+'Evolutive SFP'!E40+'Evolutive SFP'!E41+'Evolutive SFP'!E42+'Evolutive SFP'!E43+'Evolutive SFP'!E44)-'Evolutive SFP'!E10)/1000000 -> 221.85869 | H3: =(('Evolutive SFP'!F39+'Evolutive SFP'!F40+'Evolutive SFP'!F41+'Evolutive SFP'!F42+'Evolutive SFP'!F43+'Evolutive SFP'!F44)-'Evolutive SFP'!F10)/1000000 -> 223.40524 | I3: =(('Evolutive SFP'!G39+'Evolutive SFP'!G40+'Evolutive SFP'!G41+'Evolutive SFP'!G42+'Evolutive SFP'!G43+'Evolutive SFP'!G44)-'Evolutive SFP'!G10)/1000000 -> 222.62504 | J3: =(('Evolutive SFP'!H39+'Evolutive SFP'!H40+'Evolutive SFP'!H41+'Evolutive SFP'!H42+'Evolutive SFP'!H43+'Evolutive SFP'!H44)-'Evolutive SFP'!H10)/1000000 -> 221.56982 | K3: =(('Evolutive SFP'!I39+'Evolutive SFP'!I40+'Evolutive SFP'!I41+'Evolutive SFP'!I42+'Evolutive SFP'!I43+'Evolutive SFP'!I44)-'Evolutive SFP'!I10)/1000000 -> 222.46421 | L3: =(('Evolutive SFP'!J39+'Evolutive SFP'!J40+'Evolutive SFP'!J41+'Evolutive SFP'!J42+'Evolutive SFP'!J43+'Evolutive SFP'!J44)-'Evolutive SFP'!J10)/1000000 -> 223.2454 | M3: =(('Evolutive SFP'!K39+'Evolutive SFP'!K40+'Evolutive SFP'!K41+'Evolutive SFP'!K42+'Evolutive SFP'!K43+'Evolutive SFP'!K44)-'Evolutive SFP'!K10)/1000000 -> 229.84013 | N3: =(('Evolutive SFP'!L39+'Evolutive SFP'!L40+'Evolutive SFP'!L41+'Evolutive SFP'!L42+'Evolutive SFP'!L43+'Evolutive SFP'!L44)-'Evolutive SFP'!L10)/1000000 -> 230.21143 | ... BJ3: =(('Evolutive SFP'!BH39+'Evolutive SFP'!BH40+'Evolutive SFP'!BH41+'Evolutive SFP'!BH42+'Evolutive SFP'!BH43+'Evolutive SFP'!BH44)-'Evolutive SFP'!BH10)/1000000 -> 340.57863 | BK3: =(('Evolutive SFP'!BI41+'Evolutive SFP'!BI42+'Evolutive SFP'!BI43+'Evolutive SFP'!BI44+'Evolutive SFP'!BI45+'Evolutive SFP'!BI46)-'Evolutive SFP'!BI10)/1000000 -> 171.55244 | BL3: =(('Evolutive SFP'!BJ39+'Evolutive SFP'!BJ40+'Evolutive SFP'!BJ41+'Evolutive SFP'!BJ42+'Evolutive SFP'!BJ43+'Evolutive SFP'!BJ44)-'Evolutive SFP'!BJ10)/1000000 -> 347.66961 | BM3: =(('Evolutive SFP'!BK41+'Evolutive SFP'!BK42+'Evolutive SFP'!BK43+'Evolutive SFP'!BK44+'Evolutive SFP'!BK45+'Evolutive SFP'!BK46)-'Evolutive SFP'!BK10)/1000000 -> 172.30637 | BN3: =(('Evolutive SFP'!BL39+'Evolutive SFP'!BL40+'Evolutive SFP'!BL41+'Evolutive SFP'!BL42+'Evolutive SFP'!BL43+'Evolutive SFP'!BL44)-'Evolutive SFP'!BL10)/1000000 -> 352.73593 | BO3: =(('Evolutive SFP'!BM41+'Evolutive SFP'!BM42+'Evolutive SFP'!BM43+'Evolutive SFP'!BM44+'Evolutive SFP'!BM45+'Evolutive SFP'!BM46)-'Evolutive SFP'!BM10)/1000000 -> 176.60764 | BP3: =(('Evolutive SFP'!BN39+'Evolutive SFP'!BN40+'Evolutive SFP'!BN41+'Evolutive SFP'!BN42+'Evolutive SFP'!BN43+'Evolutive SFP'!BN44)-'Evolutive SFP'!BN10)/1000000 -> 349.91057 | BQ3: =(('Evolutive SFP'!BO41+'Evolutive SFP'!BO42+'Evolutive SFP'!BO43+'Evolutive SFP'!BO44+'Evolutive SFP'!BO45+'Evolutive SFP'!BO46)-'Evolutive SFP'!BO10)/1000000 -> 187.43404
B4: CCA | C4: Min 10% | D4: =D3/(('Evolutive SFP'!B27)/1000000) -> 0.10104624 | E4: =E3/(('Evolutive SFP'!C27)/1000000) -> 0.21922583 | F4: =F3/(('Evolutive SFP'!D27)/1000000) -> 0.15299794 | G4: =G3/(('Evolutive SFP'!E27)/1000000) -> 0.20215401 | H4: =H3/(('Evolutive SFP'!F27)/1000000) -> 0.20775171 | I4: =I3/(('Evolutive SFP'!G27)/1000000) -> 0.19567783 | J4: =J3/(('Evolutive SFP'!H27)/1000000) -> 0.19571582 | K4: =K3/(('Evolutive SFP'!I27)/1000000) -> 0.19453998 | ... BI4: =BI3/(('Evolutive SFP'!BG27)/1000000) -> 0.25102481 | BJ4: =Financials!BI11/Financials!BI4 -> 0.25092286 | BK4: =Financials!BJ11/Financials!BJ4 -> 0.21958432 | BL4: =Financials!BK11/Financials!BK4 -> 0.22862575 | BM4: =Financials!BL11/Financials!BL4 -> 0.23757125 | BN4: =Financials!BM11/Financials!BM4 -> 0.24281241 | BO4: =Financials!BN11/Financials!BN4 -> 0.24838093 | BP4: =Financials!BO11/Financials!BO4 -> 0.24620519 | BQ4: =Financials!BP11/Financials!BP4 -> 0.26574195
B5: CCD | C5: Min 8% | D5: =D3/('Evolutive SFP'!B31/1000000) -> 0.1186553 | E5: =E3/('Evolutive SFP'!C31/1000000) -> 0.29544775 | F5: =F3/('Evolutive SFP'!D31/1000000) -> 0.21047716 | G5: =G3/('Evolutive SFP'!E31/1000000) -> 0.27916029 | H5: =H3/('Evolutive SFP'!F31/1000000) -> 0.28572414 | I5: =I3/('Evolutive SFP'!G31/1000000) -> 0.27913395 | J5: =J3/('Evolutive SFP'!H31/1000000) -> 0.2814719 | K5: =K3/('Evolutive SFP'!I31/1000000) -> 0.27975309 | ... BQ5: =BQ3/('Evolutive SFP'!BO31/1000000) -> 0.20045901
B6: ICA | C6: Min 8% | D6: =((D3*1000000)-'Evolutive SFP'!B39)/'Evolutive SFP'!B27 -> 0.031552177 | E6: =((E3*1000000)-'Evolutive SFP'!C39)/'Evolutive SFP'!C27 -> 0.096753597 | F6: =((F3*1000000)-'Evolutive SFP'!D39)/'Evolutive SFP'!D27 -> 0.026368283 | G6: =((G3*1000000)-'Evolutive SFP'!E39)/'Evolutive SFP'!E27 -> 0.072949335 | H6: =((H3*1000000)-'Evolutive SFP'!F39)/'Evolutive SFP'!F27 -> 0.075317512 | I6: =((I3*1000000)-'Evolutive SFP'!G39)/'Evolutive SFP'!G27 -> 0.069989079 | J6: =((J3*1000000)-'Evolutive SFP'!H39)/'Evolutive SFP'!H27 -> 0.068829705 | K6: =((K3*1000000)-'Evolutive SFP'!I39)/'Evolutive SFP'!I27 -> 0.068401179 | ... BI6: =((BI3*1000000)-'Evolutive SFP'!BG39)/'Evolutive SFP'!BG27 -> 0.097383349 | BJ6: =Financials!BI12/Financials!BI4 -> 0.097377175 | BK6: =Financials!BJ12/Financials!BJ4 -> 0.08488405 | BL6: =Financials!BK12/Financials!BK4 -> 0.088293115 | BM6: =Financials!BL12/Financials!BL4 -> 0.091710134 | BN6: =Financials!BM12/Financials!BM4 -> 0.094757305 | BO6: =Financials!BN12/Financials!BN4 -> 0.097240244 | BP6: =Financials!BO12/Financials!BO4 -> 0.093434303 | BQ6: =Financials!BP12/Financials!BP4 -> 0.10851981
A7: ASSET QUALITY | B7: A/LNPL30
B8: NPL30 | H8: =('FORM 4'!D5+'FORM 4'!D6+'FORM 4'!D7)/'Evolutive SFP'!F15 -> 0.1787696 | K8: =('FORM 4'!D14+'FORM 4'!D15+'FORM 4'!D16)/'Evolutive SFP'!I15 -> 0.22772293 | N8: =('FORM 4'!D23+'FORM 4'!D24+'FORM 4'!D25)/'Evolutive SFP'!L15 -> 0.2237177 | O8: =('FORM 4'!F5+'FORM 4'!F6+'FORM 4'!F7)/'Evolutive SFP'!M15 -> 0.21153621 | P8: =('FORM 4'!G5+'FORM 4'!G6+'FORM 4'!G7)/'Evolutive SFP'!N15 -> 0 | Q8: =('FORM 4'!D32+'FORM 4'!D33+'FORM 4'!D34)/'Evolutive SFP'!O15 -> 0.24478584 | R8: 0.24 | S8: =('FORM 4'!F32+'FORM 4'!F33+'FORM 4'!F34)/'Evolutive SFP'!Q15 -> 0.20539278 | T8: =('FORM 4'!G32+'FORM 4'!G33+'FORM 4'!G34)/'Evolutive SFP'!R15 -> 0 | U8: =('FORM 4'!H32+'FORM 4'!H33+'FORM 4'!H34)/'Evolutive SFP'!S15 -> 0 | V8: =('FORM 4'!I32+'FORM 4'!I33+'FORM 4'!I34)/'Evolutive SFP'!T15 -> 0 | W8: =('FORM 4'!J32+'FORM 4'!J33+'FORM 4'!J34)/'Evolutive SFP'!U15 -> 0 | X8: =('FORM 4'!K32+'FORM 4'!K33+'FORM 4'!K34)/'Evolutive SFP'!V15 -> 0 | Y8: =('FORM 4'!L32+'FORM 4'!L33+'FORM 4'!L34)/'Evolutive SFP'!W15 -> 0 | Z8: =('FORM 4'!M32+'FORM 4'!M33+'FORM 4'!M34)/'Evolutive SFP'!X15 -> 0 | ... AD8: =('FORM 4'!Q32+'FORM 4'!Q33+'FORM 4'!Q34)/'Evolutive SFP'!AB15 -> 0 | AE8: 0.22 | AF8: =('FORM 4'!S32+'FORM 4'!S33+'FORM 4'!S34)/'Evolutive SFP'!AD15 -> 0 | AH8: =('FORM 4'!D99+'FORM 4'!D100+'FORM 4'!D101)/'Evolutive SFP'!AF15 -> 0.21548708 | AK8: =('FORM 4'!D108+'FORM 4'!D109+'FORM 4'!D110)/'Evolutive SFP'!AI15 -> 0.22964994 | AQ8: 0.31 | BD8: 0.32 | BP8: 0.33 | BQ8: 0.33
A9: EARNINGS | B9: ROA | E9: ='Evolutitve SCI'!C33/(('Evolutive SFP'!B27+'Evolutive SFP'!C27)/2) -> 0.019523279 | F9: ='Evolutitve SCI'!D33/(('Evolutive SFP'!C27+'Evolutive SFP'!D24)/2) -> 0.016250527 | G9: ='Evolutitve SCI'!E33/(('Evolutive SFP'!D24+'Evolutive SFP'!E27)/2) -> 0.011846915 | H9: ='Evolutitve SCI'!F33/(('Evolutive SFP'!E27+'Evolutive SFP'!F27)/2) -> 0.0068453599 | I9: ='Evolutitve SCI'!G33/(('Evolutive SFP'!F27+'Evolutive SFP'!G27)/2) -> 0.0054872561 | J9: ='Evolutitve SCI'!H33/(('Evolutive SFP'!G14+'Evolutive SFP'!H27)/2) -> 0.0034934452 | K9: ='Evolutitve SCI'!I33/(('Evolutive SFP'!H27+'Evolutive SFP'!I27)/2) -> 0.0040989427 | L9: ='Evolutitve SCI'!J33/(('Evolutive SFP'!I27+'Evolutive SFP'!J27)/2) -> 0.0043464169 | M9: ='Evolutitve SCI'!K33/(('Evolutive SFP'!J27+'Evolutive SFP'!K27)/2) -> 0.0097450994 | N9: ='Evolutitve SCI'!L33/(('Evolutive SFP'!K27+'Evolutive SFP'!L27)/2) -> 0.0092186265 | O9: ='Evolutitve SCI'!M33/(('Evolutive SFP'!L27+'Evolutive SFP'!M27)/2) -> 0.011066532 | P9: ='Evolutitve SCI'!N33/(('Evolutive SFP'!M27+'Evolutive SFP'!N27)/2) -> 0.011602885 | Q9: ='Evolutitve SCI'!O33/(('Evolutive SFP'!N27+'Evolutive SFP'!O27)/2) -> 0.018245322 | R9: ='Evolutitve SCI'!P33/(('Evolutive SFP'!O27+'Evolutive SFP'!P27)/2) -> 0.01805693 | ... AC9: ='Evolutitve SCI'!AA33/(('Evolutive SFP'!Z27+'Evolutive SFP'!AA27)/2) -> 0.0056100663 | AD9: ='Evolutitve SCI'!#REF!/(('Evolutive SFP'!AA27+'Evolutive SFP'!AB27)/2) -> #REF! | AE9: ='Evolutitve SCI'!AC33/(('Evolutive SFP'!AB27+'Evolutive SFP'!AC27)/2) -> 0.012295926 | AF9: ='Evolutitve SCI'!AD33/(('Evolutive SFP'!AC27+'Evolutive SFP'!AD27)/2) -> 0.00330105 | AG9: ='Evolutitve SCI'!AE33/(('Evolutive SFP'!AD27+'Evolutive SFP'!AE27)/2) -> 0.0023987892 | AH9: ='Evolutitve SCI'!AF33/(('Evolutive SFP'!AE27+'Evolutive SFP'!AF27)/2) -> 0.0016206315 | AI9: ='Evolutitve SCI'!AG33/(('Evolutive SFP'!AF27+'Evolutive SFP'!AG27)/2) -> 0.0031755642 | AJ9: ='Evolutitve SCI'!AH33/(('Evolutive SFP'!AG27+'Evolutive SFP'!AH27)/2) -> 0.0033762799 | AK9: ='Evolutitve SCI'!AI33/(('Evolutive SFP'!AH27+'Evolutive SFP'!AI27)/2) -> 0.0048861222 | AL9: ='Evolutitve SCI'!AJ33/(('Evolutive SFP'!AI27+'Evolutive SFP'!AJ27)/2) -> 0.0078607831 | ... BQ9: ='Evolutitve SCI'!BO33/(('Evolutive SFP'!BN27+'Evolutive SFP'!BO27)/2) -> 0.020747704
B10: Cost Income ratio | D10: ='Evolutitve SCI'!B23/'Evolutitve SCI'!B19 -> 0.78428841 | E10: ='Evolutitve SCI'!C23/'Evolutitve SCI'!C19 -> 0.81638811 | F10: ='Evolutitve SCI'!D23/'Evolutitve SCI'!D19 -> 0.43574848 | G10: ='Evolutitve SCI'!E23/'Evolutitve SCI'!E19 -> 0.64340473 | H10: ='Evolutitve SCI'!F23/'Evolutitve SCI'!F19 -> 0.69451785 | I10: ='Evolutitve SCI'!G23/'Evolutitve SCI'!G19 -> 0.7501933 | J10: ='Evolutitve SCI'!H23/'Evolutitve SCI'!H19 -> 0.7952059 | K10: ='Evolutitve SCI'!I23/'Evolutitve SCI'!I19 -> 0.80144187 | ... AC10: ='Evolutitve SCI'!AA23/'Evolutitve SCI'!AA19 -> 0.75898885 | AD10: ='Evolutitve SCI'!#REF!/'Evolutitve SCI'!#REF! -> #REF! | AE10: ='Evolutitve SCI'!AC23/'Evolutitve SCI'!AC19 -> 0.85016836 | AF10: ='Evolutitve SCI'!AD23/'Evolutitve SCI'!AD19 -> 0.66463853 | AG10: ='Evolutitve SCI'!AE23/'Evolutitve SCI'!AE19 -> 0.79162284 | AH10: ='Evolutitve SCI'!AF23/'Evolutitve SCI'!AF19 -> 0.83079923 | AI10: ='Evolutitve SCI'!AG23/'Evolutitve SCI'!AG19 -> 0.80132628 | AJ10: ='Evolutitve SCI'!AH23/'Evolutitve SCI'!AH19 -> 0.7997106 | AK10: ='Evolutitve SCI'!AI23/'Evolutitve SCI'!AI19 -> 0.78401721 | AL10: ='Evolutitve SCI'!AJ23/'Evolutitve SCI'!AJ19 -> 0.78597285 | ... BQ10: ='Evolutitve SCI'!BO23/'Evolutitve SCI'!BO19 -> 0.7310578
B11: Operating Expense ratio | D11: =('Evolutitve SCI'!B23+'Evolutitve SCI'!B12)/(('Evolutive SFP'!B27+'Evolutive SFP'!C27)/2) -> 1.780359e-05 | E11: =('Evolutitve SCI'!C23+'Evolutitve SCI'!C12)/(('Evolutive SFP'!C27+'Evolutive SFP'!D24)/2) -> 0.29111614 | F11: =('Evolutitve SCI'!D23+'Evolutitve SCI'!D12)/(('Evolutive SFP'!D24+'Evolutive SFP'!E27)/2) -> 0.017077852 | G11: =('Evolutitve SCI'!E23+'Evolutitve SCI'!E12)/(('Evolutive SFP'!E27+'Evolutive SFP'!F27)/2) -> 0.020493816 | H11: =('Evolutitve SCI'!F23+'Evolutitve SCI'!F12)/(('Evolutive SFP'!F27+'Evolutive SFP'!G14)/2) -> 0.039794797 | I11: =('Evolutitve SCI'!G23+'Evolutitve SCI'!G12)/(('Evolutive SFP'!G27+'Evolutive SFP'!H14)/2) -> 0.053209706 | J11: =('Evolutitve SCI'!H23+'Evolutitve SCI'!H12)/(('Evolutive SFP'!H27+'Evolutive SFP'!I27)/2) -> 0.055351703 | K11: =('Evolutitve SCI'!I23+'Evolutitve SCI'!I12)/(('Evolutive SFP'!I27+'Evolutive SFP'!J27)/2) -> 0.067396876 | L11: =('Evolutitve SCI'!J23+'Evolutitve SCI'!J12)/(('Evolutive SFP'!J27+'Evolutive SFP'!K27)/2) -> 0.079615125 | M11: =('Evolutitve SCI'!K23+'Evolutitve SCI'!K12)/(('Evolutive SFP'!K27+'Evolutive SFP'!L27)/2) -> 0.092267964 | N11: =('Evolutitve SCI'!L23+'Evolutitve SCI'!L12)/(('Evolutive SFP'!L27+'Evolutive SFP'!M27)/2) -> 0.090233951 | O11: =('Evolutitve SCI'!M23+'Evolutitve SCI'!M12)/(('Evolutive SFP'!M27+'Evolutive SFP'!N27)/2) -> 0.093664394 | P11: =('Evolutitve SCI'!N23+'Evolutitve SCI'!N12)/(('Evolutive SFP'!N27+'Evolutive SFP'!O27)/2) -> 0.11349845 | Q11: =('Evolutitve SCI'!O23+'Evolutitve SCI'!O12)/(('Evolutive SFP'!O27+'Evolutive SFP'!P27)/2) -> 0.12735612 | ... AC11: =('Evolutitve SCI'!AA23+'Evolutitve SCI'!AA12)/(('Evolutive SFP'!AA27+'Evolutive SFP'!AB27)/2) -> 0.056252928 | AD11: =('Evolutitve SCI'!#REF!+'Evolutitve SCI'!#REF!)/(('Evolutive SFP'!AB27+'Evolutive SFP'!AC27)/2) -> #REF! | AE11: =('Evolutitve SCI'!AC23+'Evolutitve SCI'!AC12)/(('Evolutive SFP'!AC27+'Evolutive SFP'!AD27)/2) -> 0.15343163 | AF11: =('Evolutitve SCI'!AD23+'Evolutitve SCI'!AD12)/(('Evolutive SFP'!AD27+'Evolutive SFP'!AE27)/2) -> 0.0090367067 | AG11: =('Evolutitve SCI'!AE23+'Evolutitve SCI'!AE12)/(('Evolutive SFP'!AE27+'Evolutive SFP'!AF27)/2) -> 0.022250112 | AH11: =('Evolutitve SCI'!AF23+'Evolutitve SCI'!AF12)/(('Evolutive SFP'!AF27+'Evolutive SFP'!AG27)/2) -> 0.033644018 | AI11: =('Evolutitve SCI'!AG23+'Evolutitve SCI'!AG12)/(('Evolutive SFP'!AG27+'Evolutive SFP'!AH27)/2) -> 0.042408299 | AJ11: =('Evolutitve SCI'!AH23+'Evolutitve SCI'!AH12)/(('Evolutive SFP'!AH27+'Evolutive SFP'!AI27)/2) -> 0.050973763 | AK11: =('Evolutitve SCI'!AI23+'Evolutitve SCI'!AI12)/(('Evolutive SFP'!AI27+'Evolutive SFP'!AJ27)/2) -> 0.040122255 | AL11: =('Evolutitve SCI'!AJ23+'Evolutitve SCI'!AJ12)/(('Evolutive SFP'!AJ27+'Evolutive SFP'!AK27)/2) -> 0.10770697 | ... AZ11: =('Evolutitve SCI'!AX23+'Evolutitve SCI'!AX12)/(('Evolutive SFP'!AX27+'Evolutive SFP'!AY27)/2) -> 0.090233211 | BA11: =('Evolutitve SCI'!AY23+'Evolutitve SCI'!AY12)/(('Evolutive SFP'!AY27+'Evolutive SFP'!AZ28)/2) -> 0.1422929 | BB11: =('Evolutitve SCI'!AZ23+'Evolutitve SCI'!AZ12)/(('Evolutive SFP'!AZ27+'Evolutive SFP'!BA28)/2) -> 0.15830138 | BC11: =('Evolutitve SCI'!BA23+'Evolutitve SCI'!BA12)/(('Evolutive SFP'!BA27+'Evolutive SFP'!BB28)/2) -> 0.18900127 | BD11: =('Evolutitve SCI'!BB23+'Evolutitve SCI'!BB12)/(('Evolutive SFP'!BB27+'Evolutive SFP'!BC28)/2) -> 0.17969284 | BE11: =('Evolutitve SCI'!BC23+'Evolutitve SCI'!BC12)/(('Evolutive SFP'!BC27+'Evolutive SFP'!BD28)/2) -> 0.016625781 | BF11: =('Evolutitve SCI'!BD23+'Evolutitve SCI'!BD12)/(('Evolutive SFP'!BD27+'Evolutive SFP'!BE28)/2) -> 0.032079427 | BG11: =('Evolutitve SCI'!BE23+'Evolutitve SCI'!BE12)/(('Evolutive SFP'!BE27+'Evolutive SFP'!BF28)/2) -> 0.052587723 | BH11: =('Evolutitve SCI'!BF23+'Evolutitve SCI'!BF12)/(('Evolutive SFP'!BF27+'Evolutive SFP'!BG28)/2) -> 0.067655172 | ... BQ11: =('Evolutitve SCI'!BO23+'Evolutitve SCI'!BO12)/(('Evolutive SFP'!BO27+'Evolutive SFP'!BP28)/2) -> 0.27192475
A12: LIQUIDITY | B12: MIN LIQ ratio | C12: Min 15% | D12: =('Evolutive SFP'!B4)/('Evolutive SFP'!B28+'Evolutive SFP'!B29+'Evolutive SFP'!B32+'Evolutive SFP'!B33+'Evolutive SFP'!B34+'Evolutive SFP'!B35+'Evolutive SFP'!B36) -> 0.90806632 | E12: =('Evolutive SFP'!C4)/('Evolutive SFP'!C28+'Evolutive SFP'!C29+'Evolutive SFP'!C32+'Evolutive SFP'!C33+'Evolutive SFP'!C34+'Evolutive SFP'!C35+'Evolutive SFP'!C36) -> 0.23568422 | F12: =('Evolutive SFP'!D4)/('Evolutive SFP'!D28+'Evolutive SFP'!D29+'Evolutive SFP'!D32+'Evolutive SFP'!D33+'Evolutive SFP'!D34+'Evolutive SFP'!D35+'Evolutive SFP'!D36) -> 0.39483664 | G12: =('Evolutive SFP'!E4)/('Evolutive SFP'!E28+'Evolutive SFP'!E29+'Evolutive SFP'!E32+'Evolutive SFP'!E33+'Evolutive SFP'!E34+'Evolutive SFP'!E35+'Evolutive SFP'!E36) -> 0.37670937 | H12: =('Evolutive SFP'!F4)/('Evolutive SFP'!F28+'Evolutive SFP'!F29+'Evolutive SFP'!F32+'Evolutive SFP'!F33+'Evolutive SFP'!F34+'Evolutive SFP'!F35+'Evolutive SFP'!F36) -> 0.33875077 | I12: =('Evolutive SFP'!G4)/('Evolutive SFP'!G28+'Evolutive SFP'!G29+'Evolutive SFP'!G32+'Evolutive SFP'!G33+'Evolutive SFP'!G34+'Evolutive SFP'!G35+'Evolutive SFP'!G36) -> 0.45616628 | J12: =('Evolutive SFP'!H4)/('Evolutive SFP'!H28+'Evolutive SFP'!H29+'Evolutive SFP'!H32+'Evolutive SFP'!H33+'Evolutive SFP'!H34+'Evolutive SFP'!H35+'Evolutive SFP'!H36) -> 0.44162502 | K12: =('Evolutive SFP'!I4)/('Evolutive SFP'!I28+'Evolutive SFP'!I29+'Evolutive SFP'!I32+'Evolutive SFP'!I33+'Evolutive SFP'!I34+'Evolutive SFP'!I35+'Evolutive SFP'!I36) -> 0.47501917 | ... BQ12: =('Evolutive SFP'!BO4)/('Evolutive SFP'!BO28+'Evolutive SFP'!BO29+'Evolutive SFP'!BO32+'Evolutive SFP'!BO33+'Evolutive SFP'!BO34+'Evolutive SFP'!BO35+'Evolutive SFP'!BO36) -> 0.67297791
B13: T/LIQ ratio | D13: ='Evolutive SFP'!B4/('Evolutive SFP'!B31+'Evolutive SFP'!B36) -> 0.14915539 | E13: ='Evolutive SFP'!C4/('Evolutive SFP'!C31+'Evolutive SFP'!C36) -> 0.16596351 | F13: ='Evolutive SFP'!D4/('Evolutive SFP'!D31+'Evolutive SFP'!D36) -> 0.26874622 | G13: ='Evolutive SFP'!E4/('Evolutive SFP'!E31+'Evolutive SFP'!E36) -> 0.25383825 | H13: ='Evolutive SFP'!F4/('Evolutive SFP'!F31+'Evolutive SFP'!F36) -> 0.22433373 | I13: ='Evolutive SFP'!G4/('Evolutive SFP'!G31+'Evolutive SFP'!G36) -> 0.30410681 | J13: ='Evolutive SFP'!H4/('Evolutive SFP'!H31+'Evolutive SFP'!H36) -> 0.29288262 | K13: ='Evolutive SFP'!I4/('Evolutive SFP'!I31+'Evolutive SFP'!I36) -> 0.31624407 | ... BQ13: ='Evolutive SFP'!BO4/('Evolutive SFP'!BO31+'Evolutive SFP'!BO36) -> 0.474224
B14: EB ratio | C14: Max 25% | D14: ='Evolutive SFP'!B37/'Evolutive SFP'!B27 -> 0.015175035 | E14: ='Evolutive SFP'!C37/'Evolutive SFP'!C27 -> 0 | F14: ='Evolutive SFP'!D37/'Evolutive SFP'!D24 -> 0 | G14: ='Evolutive SFP'!E37/'Evolutive SFP'!E27 -> 0 | H14: ='Evolutive SFP'!F37/'Evolutive SFP'!F27 -> 0 | I14: ='Evolutive SFP'!G37/'Evolutive SFP'!G27 -> 0.043947848 | J14: ='Evolutive SFP'!H37/'Evolutive SFP'!H27 -> 0.044165722 | K14: ='Evolutive SFP'!I37/'Evolutive SFP'!I27 -> 0.043723882 | L14: ='Evolutive SFP'!J37/'Evolutive SFP'!J27 -> 0.044141021 | M14: ='Evolutive SFP'!K37/'Evolutive SFP'!K27 -> 0.044531396 | N14: ='Evolutive SFP'!L37/'Evolutive SFP'!L27 -> 0.045006646 | ... BQ14: ='Evolutive SFP'!BO37/'Evolutive SFP'!BO27 -> 0
B15: LA to TA ratio | D15: ='Evolutive SFP'!B4/'Evolutive SFP'!B27 -> 0.12821992 | E15: ='Evolutive SFP'!C4/'Evolutive SFP'!C27 -> 0.12741401 | F15: ='Evolutive SFP'!D4/'Evolutive SFP'!D27 -> 0.20459469 | G15: ='Evolutive SFP'!E4/'Evolutive SFP'!E27 -> 0.19277982 | H15: ='Evolutive SFP'!F4/'Evolutive SFP'!F27 -> 0.16984218 | I15: ='Evolutive SFP'!G4/'Evolutive SFP'!G27 -> 0.22115387 | J15: ='Evolutive SFP'!H4/'Evolutive SFP'!H27 -> 0.21236898 | K15: ='Evolutive SFP'!I4/'Evolutive SFP'!I27 -> 0.22993072 | ... BQ15: ='Evolutive SFP'!BO4/'Evolutive SFP'!BO27 -> 0.33505028
A16: STRUCTURE | B16: NEA ratio | C16: Max 10% | D16: =('Evolutive SFP'!B7+'Evolutive SFP'!B21)/'Evolutive SFP'!B27 -> 0.12101375 | E16: =('Evolutive SFP'!C7+'Evolutive SFP'!C21)/'Evolutive SFP'!C27 -> 0.09430328 | F16: =('Evolutive SFP'!D7+'Evolutive SFP'!D21)/'Evolutive SFP'!D27 -> 0.14869319 | G16: =('Evolutive SFP'!E7+'Evolutive SFP'!E21)/'Evolutive SFP'!E27 -> 0.14867627 | H16: =('Evolutive SFP'!F7+'Evolutive SFP'!F21)/'Evolutive SFP'!F27 -> 0.15450319 | I16: =('Evolutive SFP'!G7+'Evolutive SFP'!G21)/'Evolutive SFP'!G27 -> 0.13952584 | J16: =('Evolutive SFP'!H7+'Evolutive SFP'!H21)/'Evolutive SFP'!H27 -> 0.14166077 | K16: =('Evolutive SFP'!I7+'Evolutive SFP'!I21)/'Evolutive SFP'!I27 -> 0.13016699 | ... BF16: =('Evolutive SFP'!BD7+'Evolutive SFP'!BD21)/'Evolutive SFP'!BD27 -> 0.20574079 | BG16: =Financials!BF34/Financials!BF4 -> 0.20942097 | BH16: =Financials!BG34/Financials!BG4 -> 0.20794077 | BI16: =Financials!BH34/Financials!BH4 -> 0.20923033 | BJ16: =Financials!BI34/Financials!BI4 -> 0.20853859 | BK16: =Financials!BJ34/Financials!BJ4 -> 0.23024493 | BL16: =Financials!BK34/Financials!BK4 -> 0.19593484 | BM16: =Financials!BL34/Financials!BL4 -> 0.19157008 | BN16: =Financials!BM34/Financials!BM4 -> 0.19516672 | ... BQ16: =Financials!BP34/Financials!BP4 -> 0.19381987
B17: LB ratio | C17: Max 5% | D17: ='Evolutive SFP'!B21/'Evolutive SFP'!B27 -> 0.032278671 | E17: ='Evolutive SFP'!C21/'Evolutive SFP'!C27 -> 0.064982853 | F17: ='Evolutive SFP'!D18/'Evolutive SFP'!D24 -> 0 | G17: ='Evolutive SFP'!E21/'Evolutive SFP'!E27 -> 0.094164143 | H17: ='Evolutive SFP'!F21/'Evolutive SFP'!F27 -> 0.095631993 | I17: ='Evolutive SFP'!G21/'Evolutive SFP'!G27 -> 0.088736275 | J17: ='Evolutive SFP'!H21/'Evolutive SFP'!H27 -> 0.091507825 | K17: ='Evolutive SFP'!I21/'Evolutive SFP'!I27 -> 0.082960813 | L17: ='Evolutive SFP'!J21/'Evolutive SFP'!J27 -> 0.091122476 | M17: ='Evolutive SFP'!K21/'Evolutive SFP'!K27 -> 0.084620753 | N17: ='Evolutive SFP'!L21/'Evolutive SFP'!L27 -> 0.084094025 | ... BQ17: ='Evolutive SFP'!BO21/'Evolutive SFP'!BO27 -> 0.092802982
B18: PI to Deposit ratio | C18: Max 5% | D18: ='Evolutive SFP'!B13/'Evolutive SFP'!B31 -> 0.0036721969 | E18: ='Evolutive SFP'!C13/'Evolutive SFP'!C31 -> 0.038661194 | F18: ='Evolutive SFP'!D9/'Evolutive SFP'!D31 -> 0 | G18: ='Evolutive SFP'!E13/'Evolutive SFP'!E31 -> 0.061511492 | H18: ='Evolutive SFP'!F13/'Evolutive SFP'!F31 -> 0.062585917 | I18: ='Evolutive SFP'!G13/'Evolutive SFP'!G31 -> 0.061419348 | J18: ='Evolutive SFP'!H13/'Evolutive SFP'!H31 -> 0.062292255 | K18: ='Evolutive SFP'!I13/'Evolutive SFP'!I31 -> 0.061725836 | L18: ='Evolutive SFP'!J13/'Evolutive SFP'!J31 -> 0.06237469 | M18: ='Evolutive SFP'!K13/'Evolutive SFP'!K31 -> 0.064340137 | N18: ='Evolutive SFP'!L13/'Evolutive SFP'!L31 -> 0.065547385 | ... BQ18: ='Evolutive SFP'!BO13/'Evolutive SFP'!BO31 -> 0.044706682
B19: PI to CC ratio | C19: Max 40% | D19: ='Evolutive SFP'!B13/(CAELS!D3*1000000) -> 0.030948443 | E19: ='Evolutive SFP'!C13/(CAELS!E3*1000000) -> 0.13085628 | F19: ='Evolutive SFP'!D9/(CAELS!F3*1000000) -> 0 | G19: ='Evolutive SFP'!E13/(CAELS!G3*1000000) -> 0.2203447 | H19: ='Evolutive SFP'!F13/(CAELS!H3*1000000) -> 0.21904315 | I19: ='Evolutive SFP'!G13/(CAELS!I3*1000000) -> 0.22003539 | J19: ='Evolutive SFP'!H13/(CAELS!J3*1000000) -> 0.22130897 | K19: ='Evolutive SFP'!I13/(CAELS!K3*1000000) -> 0.22064398 | L19: ='Evolutive SFP'!J13/(CAELS!L3*1000000) -> 0.22009586 | M19: ='Evolutive SFP'!K13/(CAELS!M3*1000000) -> 0.21486843 | N19: ='Evolutive SFP'!L13/(CAELS!N3*1000000) -> 0.21473907 | ... BQ19: ='Evolutive SFP'!BO13/(CAELS!BQ3*1000000) -> 0.22302156
B20: Gross loans/TA | D20: ='Evolutive SFP'!B15/'Evolutive SFP'!B27 -> 0.74763912 | E20: ='Evolutive SFP'!C15/'Evolutive SFP'!C27 -> 0.724849 | F20: ='Evolutive SFP'!D11/'Evolutive SFP'!D24 -> 0 | G20: ='Evolutive SFP'!E15/'Evolutive SFP'!E27 -> 0.7518191 | H20: ='Evolutive SFP'!F15/'Evolutive SFP'!F27 -> 0.77258742 | I20: ='Evolutive SFP'!G15/'Evolutive SFP'!G27 -> 0.73258269 | J20: ='Evolutive SFP'!H15/'Evolutive SFP'!H27 -> 0.74134655 | K20: ='Evolutive SFP'!I15/'Evolutive SFP'!I27 -> 0.73595915 | L20: ='Evolutive SFP'!J15/'Evolutive SFP'!J27 -> 0.73729101 | M20: ='Evolutive SFP'!K15/'Evolutive SFP'!K27 -> 0.74509989 | N20: ='Evolutive SFP'!L15/'Evolutive SFP'!L27 -> 0.75894859 | ... BQ20: ='Evolutive SFP'!BO15/'Evolutive SFP'!BO27 -> 0.58810719
A21: FUNDING MIX | B21: Total Deposits/Total Assets | D21: ='Evolutive SFP'!B31/'Evolutive SFP'!B27 -> 0.85159483 | E21: ='Evolutive SFP'!C31/'Evolutive SFP'!C27 -> 0.7420122 | F21: ='Evolutive SFP'!D31/'Evolutive SFP'!D27 -> 0.72690995 | G21: ='Evolutive SFP'!E31/'Evolutive SFP'!E27 -> 0.72415032 | H21: ='Evolutive SFP'!F31/'Evolutive SFP'!F27 -> 0.7271059 | I21: ='Evolutive SFP'!G31/'Evolutive SFP'!G27 -> 0.70101766 | J21: ='Evolutive SFP'!H31/'Evolutive SFP'!H27 -> 0.69532988 | K21: ='Evolutive SFP'!I31/'Evolutive SFP'!I27 -> 0.69539884 | ... BQ21: ='Evolutive SFP'!BO31/'Evolutive SFP'!BO27 -> 0.67707456
B22: BOSA Deposits/Total Assets | D22: ='Evolutive SFP'!B30/'Evolutive SFP'!B27 -> 0.74257768 | E22: ='Evolutive SFP'!C30/'Evolutive SFP'!C27 -> 0.23640553 | F22: ='Evolutive SFP'!D30/'Evolutive SFP'!D27 -> 0.24333689 | G22: ='Evolutive SFP'!E30/'Evolutive SFP'!E27 -> 0.24793522 | H22: ='Evolutive SFP'!F30/'Evolutive SFP'!F27 -> 0.25593211 | I22: ='Evolutive SFP'!G30/'Evolutive SFP'!G27 -> 0.24254153 | J22: ='Evolutive SFP'!H30/'Evolutive SFP'!H27 -> 0.24605095 | K22: ='Evolutive SFP'!I30/'Evolutive SFP'!I27 -> 0.24483627 | ... BQ22: ='Evolutive SFP'!BO30/'Evolutive SFP'!BO27 -> 0.23772344
B23: FOSA Deposits/Total Assets | D23: =('Evolutive SFP'!B28+'Evolutive SFP'!B29)/'Evolutive SFP'!B27 -> 0.10901715 | E23: =('Evolutive SFP'!C28+'Evolutive SFP'!C29)/'Evolutive SFP'!C27 -> 0.50560666 | F23: =('Evolutive SFP'!D28+'Evolutive SFP'!D29)/'Evolutive SFP'!D27 -> 0.48357306 | G23: =('Evolutive SFP'!E28+'Evolutive SFP'!E29)/'Evolutive SFP'!E27 -> 0.47621509 | H23: =('Evolutive SFP'!F28+'Evolutive SFP'!F29)/'Evolutive SFP'!F27 -> 0.47117378 | I23: =('Evolutive SFP'!G28+'Evolutive SFP'!G29)/'Evolutive SFP'!G27 -> 0.45847614 | J23: =('Evolutive SFP'!H28+'Evolutive SFP'!H29)/'Evolutive SFP'!H27 -> 0.44927893 | K23: =('Evolutive SFP'!I28+'Evolutive SFP'!I29)/'Evolutive SFP'!I27 -> 0.45056257 | ... BQ23: =('Evolutive SFP'!BO28+'Evolutive SFP'!BO29)/'Evolutive SFP'!BO27 -> 0.43935112
A24: GROWTH RATIOS | B24: Total Assets | D24: =(Financials!C4-Financials!B4)/Financials!B4 -> #VALUE! | E24: =(Financials!D4-Financials!C4)/Financials!C4 -> 6.605497 | F24: =(Financials!E4-Financials!D4)/Financials!D4 -> -0.99948283 | G24: =(Financials!F4-Financials!E4)/Financials!E4 -> 1846.5987 | H24: =(Financials!G4-Financials!F4)/Financials!F4 -> -0.020161115 | I24: =(Financials!H4-Financials!G4)/Financials!G4 -> -0.36915538 | J24: =(Financials!I4-Financials!H4)/Financials!H4 -> 0.66883544 | K24: =(Financials!J4-Financials!I4)/Financials!I4 -> 0.010105215 | ... BQ24: =(Financials!BP4-Financials!BO4)/Financials!BO4 -> -0.028312692
B25: Total Deposits | D25: =Financials!D5/Financials!C5-1 -> 5.6268269 | E25: =Financials!E5/Financials!D5-1 -> -0.048549295 | F25: =Financials!F5/Financials!E5-1 -> -0.019888031 | G25: =Financials!G5/Financials!F5-1 -> -0.016161957 | H25: =Financials!H5/Financials!G5-1 -> -1 | I25: =Financials!I5/Financials!H5-1 -> #DIV/0! | J25: =Financials!J5/Financials!I5-1 -> 0.010205396 | K25: =Financials!K5/Financials!J5-1 -> -0.0093944797 | ... BP25: =Financials!BP5/Financials!BO5-1 -> -1.086068e-07 | BQ25: =Financials!#REF!/Financials!BP5-1 -> #REF!
B26: BOSA Deposits | D26: =Financials!D6/Financials!C6-1 -> 1.4212707 | E26: =Financials!E6/Financials!D6-1 -> 3.1082711 | F26: =Financials!F6/Financials!E6-1 -> -0.75606967 | G26: =Financials!G6/Financials!F6-1 -> 0.011442563 | H26: =Financials!H6/Financials!G6-1 -> -1 | I26: =Financials!I6/Financials!H6-1 -> #DIV/0! | J26: =Financials!J6/Financials!I6-1 -> 0.005118623 | K26: =Financials!K6/Financials!J6-1 -> 0.0047158089 | ... BP26: =Financials!BP6/Financials!BO6-1 -> -1.5237698e-06 | BQ26: =Financials!#REF!/Financials!BP6-1 -> #REF!
B27: FOSA Deposits | D27: =Financials!D7/Financials!C7-1 -> 34.273256 | E27: =Financials!E7/Financials!D7-1 -> -0.91368177 | F27: =Financials!F7/Financials!E7-1 -> 9.4263457 | G27: =Financials!G7/Financials!F7-1 -> -0.030533893 | H27: =Financials!H7/Financials!G7-1 -> -0.69390436 | I27: =Financials!I7/Financials!H7-1 -> 2.2795459 | J27: =Financials!J7/Financials!I7-1 -> 0.012991205 | K27: =Financials!K7/Financials!J7-1 -> -0.017062028 | ... BP27: =Financials!BP7/Financials!BO7-1 -> 6.5710914e-07 | BQ27: =Financials!#REF!/Financials!BP7-1 -> #REF!
B28: Total Loans & advances | D28: =Financials!D31/Financials!C31-1 -> 6.3736603 | E28: =Financials!E31/Financials!D31-1 -> -1 | F28: =Financials!F31/Financials!E31-1 -> #DIV/0! | G28: =Financials!G31/Financials!F31-1 -> 0.0069060453 | H28: =Financials!H31/Financials!G31-1 -> #REF! | I28: =Financials!I31/Financials!H31-1 -> #REF! | J28: =Financials!J31/Financials!I31-1 -> 0.0027647299 | K28: =Financials!K31/Financials!J31-1 -> -0.0076575529 | ... BP28: =Financials!BP31/Financials!BO31-1 -> 0.00011810868 | BQ28: =Financials!#REF!/Financials!BP31-1 -> #REF!
B29: Core capital | D29: =Financials!D11/Financials!C11-1 -> 13.280228 | E29: =Financials!E11/Financials!D11-1 -> -0.40945348 | F29: =Financials!F11/Financials!E11-1 -> 0.41976202 | G29: =Financials!G11/Financials!F11-1 -> 0.0086519049 | H29: =Financials!H11/Financials!G11-1 -> #REF! | I29: =Financials!I11/Financials!H11-1 -> #REF! | J29: =Financials!J11/Financials!I11-1 -> 0.28939022 | K29: =Financials!K11/Financials!J11-1 -> 0.003511538 | ... BP29: =Financials!BP11/Financials!BO11-1 -> 0.04879215 | BQ29: =Financials!#REF!/Financials!BP11-1 -> #REF!
B30: Turnover | D30: =Financials!D37/Financials!C37-1 -> 13471.472 | E30: =Financials!E37/Financials!D37-1 -> -0.895099 | F30: =Financials!F37/Financials!E37-1 -> 0.63807394 | G30: =Financials!G37/Financials!F37-1 -> 0.45806631 | H30: =Financials!H37/Financials!G37-1 -> 0.28571648 | I30: =Financials!I37/Financials!H37-1 -> 0.21417251 | J30: =Financials!J37/Financials!I37-1 -> 0.2072454 | K30: =Financials!K37/Financials!J37-1 -> 0.14389035 | ... BP30: =Financials!BP37/Financials!BO37-1 -> -0.0067396463 | BQ30: =Financials!#REF!/Financials!BP37-1 -> #REF!
B31: Membership
B32: Expenses | D32: ='Evolutitve SCI'!E39/'Evolutitve SCI'!B39-1 -> 1923.6025 | E32: ='Evolutitve SCI'!F39/'Evolutitve SCI'!C39-1 -> -0.79138429 | F32: ='Evolutitve SCI'!G39/'Evolutitve SCI'!D39-1 -> 4.1641047 | G32: ='Evolutitve SCI'!H39/'Evolutitve SCI'!E39-1 -> 1.8287052 | H32: ='Evolutitve SCI'!I39/'Evolutitve SCI'!F39-1 -> 1.198247 | I32: ='Evolutitve SCI'!J39/'Evolutitve SCI'!G39-1 -> 0.85433457 | J32: ='Evolutitve SCI'!I39/'Evolutitve SCI'!H39-1 -> 0.21795055 | K32: ='Evolutitve SCI'!J39/'Evolutitve SCI'!I39-1 -> 0.17052673 | L32: ='Evolutitve SCI'!K39/'Evolutitve SCI'!J39-1 -> 0.14773104 | M32: ='Evolutitve SCI'!L39/'Evolutitve SCI'!K39-1 -> 0.13065045 | N32: ='Evolutitve SCI'!M39/'Evolutitve SCI'!L39-1 -> 0.13009803 | O32: ='Evolutitve SCI'!N39/'Evolutitve SCI'!M39-1 -> 0.12566265 | P32: ='Evolutitve SCI'!O39/'Evolutitve SCI'!N39-1 -> 0.094009932 | Q32: ='Evolutitve SCI'!P39/'Evolutitve SCI'!O39-1 -> 0.054741701 | ... BQ32: ='Evolutitve SCI'!BP39/'Evolutitve SCI'!BO39-1 -> -1
A33: Efficiency Ratios | B33: FinCost-Deposits/Avg Deposits | H33: =Financials!G44/('Evolutive SFP'!B30+'Evolutive SFP'!F30)/2 -> 0.001918652 | I33: =Financials!H44/('Evolutive SFP'!C30+'Evolutive SFP'!G30)/2 -> 0.0018961798 | K33: =Financials!J44/('Evolutive SFP'!F30+'Evolutive SFP'!I30)/2 -> 0.0072231137 | L33: =Financials!K44/('Evolutive SFP'!I30+'Evolutive SFP'!J30)/2 -> 0.0086356146 | M33: =Financials!L44/('Evolutive SFP'!J30+'Evolutive SFP'!K30)/2 -> 0.0099848309 | N33: =Financials!M44/('Evolutive SFP'!K30+'Evolutive SFP'!L30)/2 -> 0.011312134 | O33: =Financials!N44/('Evolutive SFP'!L30+'Evolutive SFP'!M30)/2 -> 0.013096251 | P33: =Financials!O44/('Evolutive SFP'!M30+'Evolutive SFP'!N30)/2 -> 0.015179056 | Q33: =Financials!P44/('Evolutive SFP'!N30+'Evolutive SFP'!O30)/2 -> 0.016170895 | R33: =Financials!Q44/('Evolutive SFP'!O30+'Evolutive SFP'!P30)/2 -> 0.027825701 | S33: =Financials!R44/('Evolutive SFP'!P30+'Evolutive SFP'!Q30)/2 -> 0.00064628865 | ... BJ33: =Financials!BI44/('Evolutive SFP'!BG30+'Evolutive SFP'!BH30)/2 -> 0.0083614385 | BK33: =Financials!BJ44/('Evolutive SFP'!BH30+'Evolutive SFP'!BI32)/2 -> 0.023442079 | BL33: =Financials!BK44/('Evolutive SFP'!BI32+'Evolutive SFP'!BJ30)/2 -> 0.025274853 | BM33: =Financials!BL44/('Evolutive SFP'!BJ30+'Evolutive SFP'!BK32)/2 -> 0.028346955 | BN33: =Financials!BM44/('Evolutive SFP'!BK32+'Evolutive SFP'!BL30)/2 -> 0.031831381 | BO33: =Financials!BN44/('Evolutive SFP'!BL30+'Evolutive SFP'!BM32)/2 -> 0.047204935 | BP33: =Financials!BO44/('Evolutive SFP'!BM32+'Evolutive SFP'!BN30)/2 -> 0.03782544 | BQ33: =Financials!BP44/('Evolutive SFP'!BN30+'Evolutive SFP'!BO32)/2 -> 0.036826532
B34: FinCost-Shares/Avg Share capital | H34: =Financials!G45/('Evolutive SFP'!B39+'Evolutive SFP'!F39)/2 -> 0 | I34: =Financials!H45/('Evolutive SFP'!C39+'Evolutive SFP'!G39)/2 -> 0 | K34: =Financials!J45/('Evolutive SFP'!F39+'Evolutive SFP'!I39)/2 -> 0 | L34: =Financials!K45/('Evolutive SFP'!I39+'Evolutive SFP'!J39)/2 -> 0 | M34: =Financials!L45/('Evolutive SFP'!J39+'Evolutive SFP'!K39)/2 -> 0 | N34: =Financials!M45/('Evolutive SFP'!K39+'Evolutive SFP'!L39)/2 -> 0 | O34: =Financials!N45/('Evolutive SFP'!L39+'Evolutive SFP'!M39)/2 -> 0 | P34: =Financials!O45/('Evolutive SFP'!M39+'Evolutive SFP'!N39)/2 -> 0 | Q34: =Financials!P45/('Evolutive SFP'!N39+'Evolutive SFP'!O39)/2 -> 0 | R34: =Financials!Q45/('Evolutive SFP'!O39+'Evolutive SFP'!P39)/2 -> 0 | S34: =Financials!R45/('Evolutive SFP'!P39+'Evolutive SFP'!Q39)/2 -> 0 | ... BJ34: =Financials!BI45/('Evolutive SFP'!BG39+'Evolutive SFP'!BH39)/2 -> 0 | BK34: =Financials!BJ45/('Evolutive SFP'!BH39+'Evolutive SFP'!BI41)/2 -> 0 | BL34: =Financials!BK45/('Evolutive SFP'!BI41+'Evolutive SFP'!BJ39)/2 -> 0 | BM34: =Financials!BL45/('Evolutive SFP'!BJ39+'Evolutive SFP'!BK41)/2 -> 0 | BN34: =Financials!BM45/('Evolutive SFP'!BK41+'Evolutive SFP'!BL39)/2 -> 0 | BO34: =Financials!BN45/('Evolutive SFP'!BL39+'Evolutive SFP'!BM41)/2 -> 0 | BP34: =Financials!BO45/('Evolutive SFP'!BM41+'Evolutive SFP'!BN39)/2 -> 0 | BQ34: =Financials!BP45/('Evolutive SFP'!BN39+'Evolutive SFP'!BO41)/2 -> 0
B35: FinCost-Ext Loans/Avg Ext Loans | H35: =Financials!G46/(Financials!F31+Financials!G31)/2 -> 0 | I35: =Financials!H46/(Financials!G31+Financials!H31)/2 -> #REF! | K35: =Financials!J46/(Financials!G31+Financials!J31)/2 -> 0.00053773974 | L35: =Financials!K46/(Financials!J31+Financials!K31)/2 -> 0.00068336881 | M35: =Financials!L46/(Financials!K31+Financials!L31)/2 -> 0.00085137383 | N35: =Financials!M46/(Financials!L31+Financials!M31)/2 -> 0.00099900602 | O35: =Financials!N46/(Financials!M31+Financials!N31)/2 -> 0.001269647 | P35: =Financials!O46/(Financials!N31+Financials!O31)/2 -> 0.0013721221 | Q35: =Financials!P46/(Financials!O31+Financials!P31)/2 -> 0.0013135457 | R35: =Financials!Q46/(Financials!P31+Financials!Q31)/2 -> 0.0012603678 | S35: =Financials!R46/(Financials!Q31+Financials!R31)/2 -> 0 | ... BQ35: =Financials!BP46/(Financials!BO31+Financials!BP31)/2 -> 0
B36: OpEx/Average Total Assets | H36: =Financials!G47/(Financials!F4+Financials!G4)/2 -> 0.0075258994 | I36: =Financials!H47/(Financials!G4+Financials!H4)/2 -> 0.012791236 | K36: =Financials!J47/(Financials!G4+Financials!J4)/2 -> 0.014703651 | L36: =Financials!K47/(Financials!J4+Financials!K4)/2 -> 0.016495376 | M36: =Financials!L47/(Financials!K4+Financials!L4)/2 -> 0.019080754 | N36: =Financials!M47/(Financials!L4+Financials!M4)/2 -> 0.021740142 | O36: =Financials!N47/(Financials!M4+Financials!N4)/2 -> 0.021199477 | P36: =Financials!O47/(Financials!N4+Financials!O4)/2 -> 0.021899079 | Q36: =Financials!P47/(Financials!O4+Financials!P4)/2 -> 0.025959423 | R36: =Financials!Q47/(Financials!P4+Financials!Q4)/2 -> 0.026582665 | S36: =Financials!R47/(Financials!Q4+Financials!R4)/2 -> 0.0019363483 | ... BQ36: =Financials!BP47/(Financials!BO4+Financials!BP4)/2 -> 0.028981539
B37: Opex/Turnover | H37: =Financials!G47/Financials!G37 -> 0.66365772 | I37: =Financials!H47/Financials!H37 -> 0.70809323 | K37: =Financials!J47/Financials!J37 -> 0.70258851 | L37: =Financials!K47/Financials!K37 -> 0.7068753 | M37: =Financials!L47/Financials!L37 -> 0.66520745 | N37: =Financials!M47/Financials!M37 -> 0.6740788 | O37: =Financials!N47/Financials!N37 -> 0.66156979 | P37: =Financials!O47/Financials!O37 -> 0.64670572 | Q37: =Financials!P47/Financials!P37 -> 0.63952507 | R37: =Financials!Q47/Financials!Q37 -> 0.64413081 | ... BQ37: =Financials!BP47/Financials!BP37 -> 0.6562216
B38: Avge yield on Net loans | H38: =Financials!G38/('Evolutive SFP'!F14+'Evolutive SFP'!B14)/2 -> 0.015666356 | I38: =Financials!H38/('Evolutive SFP'!G14+'Evolutive SFP'!C14)/2 -> 0.012112143 | K38: =Financials!J38/('Evolutive SFP'!I14+'Evolutive SFP'!F14)/2 -> 0.018228573 | L38: =Financials!K38/('Evolutive SFP'!J14+'Evolutive SFP'!I14)/2 -> 0.021347638 | M38: =Financials!L38/('Evolutive SFP'!K14+'Evolutive SFP'!J14)/2 -> 0.024622273 | N38: =Financials!M38/('Evolutive SFP'!L14+'Evolutive SFP'!K14)/2 -> 0.02776416 | O38: =Financials!N38/('Evolutive SFP'!M14+'Evolutive SFP'!L14)/2 -> 0.035265731 | P38: =Financials!O38/('Evolutive SFP'!N14+'Evolutive SFP'!M14)/2 -> 0.04290194 | Q38: =Financials!P38/('Evolutive SFP'!O14+'Evolutive SFP'!N14)/2 -> 0.04364573 | R38: =Financials!Q38/('Evolutive SFP'!P14+'Evolutive SFP'!O14)/2 -> 0.041150538 | S38: =Financials!R38/('Evolutive SFP'!Q14+'Evolutive SFP'!P14)/2 -> 0.002978629 | ... BJ38: =Financials!BI38/('Evolutive SFP'!BH14+'Evolutive SFP'!BG14)/2 -> 0.023515405 | BK38: =Financials!BJ38/('Evolutive SFP'!BI15+'Evolutive SFP'!BH14)/2 -> 0.025544955 | BL38: =Financials!BK38/('Evolutive SFP'!BJ14+'Evolutive SFP'!BI15)/2 -> 0.028762488 | BM38: =Financials!BL38/('Evolutive SFP'!BK15+'Evolutive SFP'!BJ14)/2 -> 0.031235918 | BN38: =Financials!BM38/('Evolutive SFP'!BL14+'Evolutive SFP'!BK15)/2 -> 0.033894335 | BO38: =Financials!BN38/('Evolutive SFP'!BM15+'Evolutive SFP'!BL14)/2 -> 0.036784238 | BP38: =Financials!BO38/('Evolutive SFP'!BN14+'Evolutive SFP'!BM15)/2 -> 0.010369618 | BQ38: =Financials!BP38/('Evolutive SFP'!BO15+'Evolutive SFP'!BN14)/2 -> 0
B39: Avge yield on Gross loans | H39: =Financials!G37/('Evolutive SFP'!F15+'Evolutive SFP'!B15)/2 -> 0.026109701 | I39: =Financials!H37/('Evolutive SFP'!G15+'Evolutive SFP'!C15)/2 -> 0.019015605 | K39: =Financials!J37/('Evolutive SFP'!I15+'Evolutive SFP'!F15)/2 -> 0.027766402 | L39: =Financials!K37/('Evolutive SFP'!J15+'Evolutive SFP'!I15)/2 -> 0.031679241 | M39: =Financials!L37/('Evolutive SFP'!K15+'Evolutive SFP'!J15)/2 -> 0.038700427 | N39: =Financials!M37/('Evolutive SFP'!L15+'Evolutive SFP'!K15)/2 -> 0.042888523 | O39: =Financials!N37/('Evolutive SFP'!M15+'Evolutive SFP'!L15)/2 -> 0.054359087 | P39: =Financials!O37/('Evolutive SFP'!N15+'Evolutive SFP'!M15)/2 -> 0.067586999 | Q39: =Financials!P37/('Evolutive SFP'!O15+'Evolutive SFP'!N15)/2 -> 0.0720488 | R39: =Financials!Q37/('Evolutive SFP'!P15+'Evolutive SFP'!O15)/2 -> 0.068526296 | S39: =Financials!R37/('Evolutive SFP'!Q15+'Evolutive SFP'!P15)/2 -> 0.0046236809 | ... BJ39: =Financials!BI37/('Evolutive SFP'!BH15+'Evolutive SFP'!BG15)/2 -> 0.036839894 | BK39: =Financials!BJ37/('Evolutive SFP'!BI16+'Evolutive SFP'!BH15)/2 -> 0.072094976 | BL39: =Financials!BK37/('Evolutive SFP'!BJ15+'Evolutive SFP'!BI16)/2 -> 0.082088566 | BM39: =Financials!BL37/('Evolutive SFP'!BK16+'Evolutive SFP'!BJ15)/2 -> 0.091173462 | BN39: =Financials!BM37/('Evolutive SFP'!BL15+'Evolutive SFP'!BK16)/2 -> 0.096696873 | BO39: =Financials!BN37/('Evolutive SFP'!BM16+'Evolutive SFP'!BL15)/2 -> 0.11138136 | BP39: =Financials!BO37/('Evolutive SFP'!BN15+'Evolutive SFP'!BM16)/2 -> 0.12168168 | BQ39: =Financials!BP37/('Evolutive SFP'!BO16+'Evolutive SFP'!BN15)/2 -> 0.12065093
A41: ALL/Average Gross Loan portfolio

Sheet Sheet1
B3: =6429931/0.01 -> 642993100
B4: =1159521/0.05 -> 23190420
B5: =4472345/0.25 -> 17889380
B6: =12240162/0.5 -> 24480324
B7: =139271396 -> 139271396
B8: =SUM(B3:B7) -> 847824620

Sheet Financials
B1: WANANCHI Sacco Financial Performance
B2: Year | C2: 2010 Audited | D2: 2017 Audited | E2: 43101 | F2: 43133 | G2: 43165 | H2: 43197 | I2: 43229 | J2: 43261 | K2: 43293 | L2: 43325 | M2: 43357 | N2: 43389 | O2: 43421 | P2: 43453 | Q2: Audited 2018 | R2: 43466 | S2: 43498 | T2: 43527 | U2: 43559 | V2: 43590 | W2: 43622 | X2: 43653 | Y2: 43685 | Z2: 43717 | AA2: 43748 | AB2: 43780 | AC2: 43811 | AD2: AUDITED 2019 | AE2: 43844 | AF2: 43876 | AG2: 43906 | AH2: 43938 | AI2: 43969 | AJ2: 44001 | AK2: 44063 | AL2: 44095 | AM2: 44126 | AN2: 44158 | AO2: 44189 | AP2: AUDITED2020 | AQ2: 44197 | AR2: 44228 | AS2: 44256 | AT2: 44287 | AU2: 44317 | AV2: 44348 | AW2: 44378 | AX2: 44409 | AY2: 44440 | AZ2: 44470 | BA2: 44501 | BB2: 44531 | BC2: Audited 2021 | BD2: 44562 | BE2: 44593 | BF2: 44621 | BG2: 44652 | BH2: 44682 | BI2: 44713 | BJ2: 44743 | BK2: 44774 | BL2: 44805 | BM2: 44835 | BN2: 44866 | BO2: 44896 | BP2: Audited 2022
A3: 1 | B3: Membership
A4: 2 | B4: Total Assets | C4: ='Evolutive SFP'!B27 -> 151015729 | D4: ='Evolutive SFP'!C27 -> 1148549670 | E4: ='Evolutive SFP'!D24 -> 594000 | F4: ='Evolutive SFP'!E27 -> 1.0974736e+09 | G4: ='Evolutive SFP'!F27 -> 1.0753473e+09 | H4: ='Evolutive SFP'!G14 -> 6.7837707e+08 | I4: ='Evolutive SFP'!H27 -> 1.1320997e+09 | J4: ='Evolutive SFP'!I27 -> 1.1435398e+09 | K4: ='Evolutive SFP'!J27 -> 1.1327332e+09 | L4: ='Evolutive SFP'!K27 -> 1.1228033e+09 | M4: ='Evolutive SFP'!L27 -> 1.110947e+09 | N4: ='Evolutive SFP'!M27 -> 1.4715746e+09 | O4: ='Evolutive SFP'!N27 -> 1.3400383e+09 | P4: ='Evolutive SFP'!O27 -> 1.2718126e+09 | ... BP4: ='Evolutive SFP'!BO27 -> 1380976781 | BQ4: ='Evolutive SFP'!BQ27 -> 0 | BR4: ='Evolutive SFP'!BR27 -> 0 | BS4: ='Evolutive SFP'!BS27 -> 0 | BT4: ='Evolutive SFP'!BT27 -> 0 | BU4: ='Evolutive SFP'!BU27 -> 0 | BV4: ='Evolutive SFP'!BV27 -> 0 | BW4: ='Evolutive SFP'!BW27 -> 0
A5: 3 | B5: Total Deposits | C5: ='Evolutive SFP'!B31 -> 128604214 | D5: ='Evolutive SFP'!C31 -> 852237862 | E5: ='Evolutive SFP'!D31 -> 8.1086231e+08 | F5: ='Evolutive SFP'!E31 -> 7.9473586e+08 | G5: ='Evolutive SFP'!F31 -> 7.8189137e+08 | H5: ='Evolutive SFP'!G19 -> 0 | I5: ='Evolutive SFP'!H31 -> 7.8718275e+08 | J5: ='Evolutive SFP'!I31 -> 7.9521626e+08 | K5: ='Evolutive SFP'!J31 -> 7.8774562e+08 | L5: ='Evolutive SFP'!K31 -> 7.6756735e+08 | M5: ='Evolutive SFP'!L31 -> 7.5419314e+08 | N5: ='Evolutive SFP'!M31 -> 1.1501802e+09 | O5: ='Evolutive SFP'!N31 -> 1.013712e+09 | P5: ='Evolutive SFP'!O31 -> 9.3133619e+08 | ... BP5: ='Evolutive SFP'!BO31 -> 935024252 | BQ5: ='Evolutive SFP'!BQ31 -> 0 | BR5: ='Evolutive SFP'!BR31 -> 0 | BS5: ='Evolutive SFP'!BS31 -> 0 | BT5: ='Evolutive SFP'!BT31 -> 0 | BU5: ='Evolutive SFP'!BU31 -> 0 | BV5: ='Evolutive SFP'!BV31 -> 0 | BW5: ='Evolutive SFP'!BW31 -> 0
A6: 3.1 | B6: Deposits-Members(BOSA) | C6: ='Evolutive SFP'!B30 -> 112140909 | D6: ='Evolutive SFP'!C30 -> 271523495 | E6: ='Evolutive SFP'!D27 -> 1.1154921e+09 | F6: ='Evolutive SFP'!E30 -> 2.7210236e+08 | G6: ='Evolutive SFP'!F30 -> 2.7521591e+08 | H6: ='Evolutive SFP'!G18 -> 0 | I6: ='Evolutive SFP'!H30 -> 2.7855421e+08 | J6: ='Evolutive SFP'!I30 -> 2.7998002e+08 | K6: ='Evolutive SFP'!J30 -> 2.8130035e+08 | L6: ='Evolutive SFP'!K30 -> 2.8198335e+08 | M6: ='Evolutive SFP'!L30 -> 2.8122165e+08 | N6: ='Evolutive SFP'!M30 -> 2.8199216e+08 | O6: ='Evolutive SFP'!N30 -> 2.8522983e+08 | P6: ='Evolutive SFP'!O30 -> 2.8553958e+08 | ... BP6: ='Evolutive SFP'!BO30 -> 328290550 | BQ6: ='Evolutive SFP'!BQ30 -> 0 | BR6: ='Evolutive SFP'!BR30 -> 0 | BS6: ='Evolutive SFP'!BS30 -> 0 | BT6: ='Evolutive SFP'!BT30 -> 0 | BU6: ='Evolutive SFP'!BU30 -> 0 | BV6: ='Evolutive SFP'!BV30 -> 0 | BW6: ='Evolutive SFP'!BW30 -> 0
A7: 3.2 | B7: Deposits-Customers(FOSA) | C7: =('Evolutive SFP'!B28+'Evolutive SFP'!B29) -> 16463305 | D7: =('Evolutive SFP'!C28+'Evolutive SFP'!C29) -> 580714367 | E7: =('Evolutive SFP'!D25+'Evolutive SFP'!D26) -> 50126239 | F7: =('Evolutive SFP'!E28+'Evolutive SFP'!E29) -> 5.226335e+08 | G7: =('Evolutive SFP'!F28+'Evolutive SFP'!F29) -> 5.0667546e+08 | H7: =('Evolutive SFP'!G16+'Evolutive SFP'!G17) -> 1.5509115e+08 | I7: =('Evolutive SFP'!H28+'Evolutive SFP'!H29) -> 5.0862854e+08 | J7: =('Evolutive SFP'!I28+'Evolutive SFP'!I29) -> 5.1523624e+08 | K7: =('Evolutive SFP'!J28+'Evolutive SFP'!J29) -> 5.0644526e+08 | L7: =('Evolutive SFP'!K28+'Evolutive SFP'!K29) -> 4.85584e+08 | M7: =('Evolutive SFP'!L28+'Evolutive SFP'!L29) -> 4.729715e+08 | N7: =('Evolutive SFP'!M28+'Evolutive SFP'!M29) -> 8.6818803e+08 | O7: =('Evolutive SFP'!N28+'Evolutive SFP'!N29) -> 7.284822e+08 | P7: =('Evolutive SFP'!O28+'Evolutive SFP'!O29) -> 6.4579662e+08 | ... BP7: =('Evolutive SFP'!BO28+'Evolutive SFP'!BO29) -> 606733702 | BQ7: =('Evolutive SFP'!BQ28+'Evolutive SFP'!BQ29) -> 0 | BR7: =('Evolutive SFP'!BR28+'Evolutive SFP'!BR29) -> 0 | BS7: =('Evolutive SFP'!BS28+'Evolutive SFP'!BS29) -> 0 | BT7: =('Evolutive SFP'!BT28+'Evolutive SFP'!BT29) -> 0 | BU7: =('Evolutive SFP'!BU28+'Evolutive SFP'!BU29) -> 0 | BV7: =('Evolutive SFP'!BV28+'Evolutive SFP'!BV29) -> 0 | BW7: =('Evolutive SFP'!BW28+'Evolutive SFP'!BW29) -> 0
A8: 4 | B8: External Borrowing | C8: ='Evolutive SFP'!B37 -> 2291669 | D8: ='Evolutive SFP'!C37 -> 0 | E8: ='Evolutive SFP'!D37 -> 0 | F8: ='Evolutive SFP'!E37 -> 0 | G8: ='Evolutive SFP'!F37 -> 0 | H8: ='Evolutive SFP'!G25 -> 5489439 | I8: ='Evolutive SFP'!H37 -> 50000000 | J8: ='Evolutive SFP'!I37 -> 50000000 | K8: ='Evolutive SFP'!J37 -> 50000000 | L8: ='Evolutive SFP'!K37 -> 50000000 | M8: ='Evolutive SFP'!L37 -> 50000000 | N8: ='Evolutive SFP'!M37 -> 0 | O8: ='Evolutive SFP'!N37 -> 0 | P8: ='Evolutive SFP'!O37 -> 0 | ... BP8: ='Evolutive SFP'!BO37 -> 0 | BQ8: ='Evolutive SFP'!BQ37 -> 0 | BR8: ='Evolutive SFP'!BR37 -> 0 | BS8: ='Evolutive SFP'!BS37 -> 0 | BT8: ='Evolutive SFP'!BT37 -> 0 | BU8: ='Evolutive SFP'!BU37 -> 0 | BV8: ='Evolutive SFP'!BV37 -> 0 | BW8: ='Evolutive SFP'!BW37 -> 0
A10: 5 | B10: Share capital and Reserves
A11: 5.1 | B11: Core Capital | C11: =C14-C22-C25 -> 14446887 | D11: =D14-D22-D25 -> 206304838 | E11: =E14-E22-E25 -> 1.2183261e+08 | F11: =F14-F22-F25 -> 1.7297331e+08 | G11: =G14-G22-G25 -> 1.7446985e+08 | H11: =H14-H22-H25 -> #REF! | I11: =I14-I22-I25 -> 1.7253443e+08 | J11: =J14-J22 -> 2.2246421e+08 | K11: =K14-K22 -> 2.232454e+08 | L11: =L14-L22 -> 2.2984013e+08 | M11: =M14-M22 -> 2.3021143e+08 | N11: =N14-N22 -> 2.4210544e+08 | O11: =O14-O22 -> 2.4536548e+08 | P11: =P14-P22 -> 2.5408282e+08 | Q11: =Q14-Q22 -> 248082819 | ... BW11: =BW14-BW22 -> 0
A12: 5.2 | B12: Institutional Capital | C12: =C11-C15 -> 3952190 | D12: =D11-D15 -> 65639391 | E12: =E11-E15 -> -19421777 | F12: =F11-F15 -> 31174581 | G12: =G11-G15 -> 32057095 | H12: =H11-H15 -> #REF! | I12: =I11-I15 -> 28886699 | J12: =J11-J15 -> 78219471 | ... BW12: =BW11-BW15 -> 0
A14: 5.3 | B14: Total Capital | C14: =C15+C16+C17+C18+C19+C20+C21 -> 14919147 | D14: =D15+D16+D17+D18+D19+D20+D21 -> 256104993 | E14: =E15+E16+E17+E18+E19+E20+E21 -> 2.2846032e+08 | F14: =F15+F16+F17+F18+F19+F20+F21 -> 2.2617193e+08 | G14: =G15+G16+G17+G18+G19+G20+G21 -> 2.2340524e+08 | H14: =H15+H16+H17+H18+H19+H20+H21 -> 2.331874e+09 | I14: =I15+I16+I17+I18+I19+I20+I21 -> 2.2156982e+08 | J14: =J15+J16+J17+J18+J19+J20+J21 -> 2.2246421e+08 | ... BW14: =BW15+BW16+BW17+BW18+BW19+BW20+BW21 -> 0
A15: 5.3.1 | B15: Members Share Capital | C15: ='Evolutive SFP'!B39 -> 10494697 | D15: ='Evolutive SFP'!C39 -> 140665447 | E15: ='Evolutive SFP'!D39 -> 1.4125438e+08 | F15: ='Evolutive SFP'!E39 -> 1.4179872e+08 | G15: ='Evolutive SFP'!F39 -> 1.4241276e+08 | H15: ='Evolutive SFP'!G27 -> 1.1377121e+09 | I15: ='Evolutive SFP'!H39 -> 1.4364773e+08 | J15: ='Evolutive SFP'!I39 -> 1.4424474e+08 | K15: ='Evolutive SFP'!J39 -> 1.4474297e+08 | L15: ='Evolutive SFP'!K39 -> 1.452943e+08 | M15: ='Evolutive SFP'!L39 -> 1.4635976e+08 | N15: ='Evolutive SFP'!M39 -> 1.5426005e+08 | O15: ='Evolutive SFP'!N39 -> 1.5549845e+08 | P15: ='Evolutive SFP'!O39 -> 1.5670017e+08 | ... BP15: ='Evolutive SFP'!BO39 -> 217120114 | BQ15: ='Evolutive SFP'!BQ39 -> 0 | BR15: ='Evolutive SFP'!BR39 -> 0 | BS15: ='Evolutive SFP'!BS39 -> 0 | BT15: ='Evolutive SFP'!BT39 -> 0 | BU15: ='Evolutive SFP'!BU39 -> 0 | BV15: ='Evolutive SFP'!BV39 -> 0 | BW15: ='Evolutive SFP'!BW39 -> 0
A16: 5.3.2 | B16: Entrance Fees
A17: 5.3.3 | B17: Retained Earnings | C17: ='Evolutive SFP'!B41 -> 351220 | D17: ='Evolutive SFP'!C41 -> 14978344 | E17: ='Evolutive SFP'!D41 -> 27664229 | F17: ='Evolutive SFP'!E41 -> 20813817 | G17: ='Evolutive SFP'!F41 -> 20813817 | H17: ='Evolutive SFP'!G29 -> 99792072 | I17: ='Evolutive SFP'!H41 -> 20813817 | J17: ='Evolutive SFP'!I41 -> 20813817 | K17: ='Evolutive SFP'!J41 -> 20813817 | L17: ='Evolutive SFP'!K41 -> 20813817 | M17: ='Evolutive SFP'!L41 -> 20813817 | N17: ='Evolutive SFP'!M41 -> 20813817 | O17: ='Evolutive SFP'!N41 -> 20813817 | P17: ='Evolutive SFP'!O41 -> 20813817 | ... BP17: ='Evolutive SFP'!BO41 -> 54209976 | BQ17: ='Evolutive SFP'!BQ41 -> 0 | BR17: ='Evolutive SFP'!BR41 -> 0 | BS17: ='Evolutive SFP'!BS41 -> 0 | BT17: ='Evolutive SFP'!BT41 -> 0 | BU17: ='Evolutive SFP'!BU41 -> 0 | BV17: ='Evolutive SFP'!BV41 -> 0 | BW17: ='Evolutive SFP'!BW41 -> 0
A18: 5.3.4 | B18: Appropriation Account | C18: ='Evolutive SFP'!B42 -> 3541956 | D18: ='Evolutive SFP'!C42 -> 5835476 | E18: ='Evolutive SFP'!D42 -> 9337095 | F18: ='Evolutive SFP'!E42 -> 6504356.7 | G18: ='Evolutive SFP'!F42 -> 7436870.6 | H18: ='Evolutive SFP'!G30 -> 2.7594244e+08 | I18: ='Evolutive SFP'!H42 -> 4366474.7 | J18: ='Evolutive SFP'!I42 -> 4663858 | K18: ='Evolutive SFP'!J42 -> 4946815.8 | L18: ='Evolutive SFP'!K42 -> 10990214 | M18: ='Evolutive SFP'!L42 -> 10296055 | N18: ='Evolutive SFP'!M42 -> 14289780 | O18: ='Evolutive SFP'!N42 -> 16311411 | P18: ='Evolutive SFP'!O42 -> 23827031 | ... BP18: ='Evolutive SFP'!BO42 -> 19201722 | BQ18: ='Evolutive SFP'!BQ42 -> 0 | BR18: ='Evolutive SFP'!BR42 -> 0 | BS18: ='Evolutive SFP'!BS42 -> 0 | BT18: ='Evolutive SFP'!BT42 -> 0 | BU18: ='Evolutive SFP'!BU42 -> 0 | BV18: ='Evolutive SFP'!BV42 -> 0 | BW18: ='Evolutive SFP'!BW42 -> 0
A19: 5.3.5 | B19: Statutory Reserves | C19: ='Evolutive SFP'!B43 -> 531274 | D19: ='Evolutive SFP'!C43 -> 31870722 | E19: ='Evolutive SFP'!D43 -> 29333544 | F19: ='Evolutive SFP'!E43 -> 31870722 | G19: ='Evolutive SFP'!F43 -> 31870722 | H19: ='Evolutive SFP'!G31 -> 7.9755631e+08 | I19: ='Evolutive SFP'!H43 -> 31870722 | J19: ='Evolutive SFP'!I43 -> 31870722 | K19: ='Evolutive SFP'!J43 -> 31870722 | L19: ='Evolutive SFP'!K43 -> 31870722 | M19: ='Evolutive SFP'!L43 -> 31870722 | N19: ='Evolutive SFP'!M43 -> 31870722 | O19: ='Evolutive SFP'!N43 -> 31870722 | P19: ='Evolutive SFP'!O43 -> 31870722 | ... BP19: ='Evolutive SFP'!BO43 -> 55580570 | BQ19: ='Evolutive SFP'!BQ43 -> 0 | BR19: ='Evolutive SFP'!BR43 -> 0 | BS19: ='Evolutive SFP'!BS43 -> 0 | BT19: ='Evolutive SFP'!BT43 -> 0 | BU19: ='Evolutive SFP'!BU43 -> 0 | BV19: ='Evolutive SFP'!BV43 -> 0 | BW19: ='Evolutive SFP'!BW43 -> 0
A20: 5.3.6 | B20: Capital Reserves | C20: =('Evolutive SFP'!B44) -> 0 | D20: =('Evolutive SFP'!C44) -> 58441770 | E20: =('Evolutive SFP'!D44) -> 20871074 | F20: =('Evolutive SFP'!E44) -> 20871074 | G20: =('Evolutive SFP'!F44) -> 20871074 | H20: =('Evolutive SFP'!G44) -> 20871074 | I20: =('Evolutive SFP'!H44) -> 20871074 | J20: =('Evolutive SFP'!I44) -> 20871074 | ... BP20: =('Evolutive SFP'!BO44) -> 20871074 | BQ20: =('Evolutive SFP'!BQ44) -> 0 | BR20: =('Evolutive SFP'!BR44) -> 0 | BS20: =('Evolutive SFP'!BS44) -> 0 | BT20: =('Evolutive SFP'!BT44) -> 0 | BU20: =('Evolutive SFP'!BU44) -> 0 | BV20: =('Evolutive SFP'!BV44) -> 0 | BW20: =('Evolutive SFP'!BW44) -> 0
A21: 5.3.7 | B21: Supplementary Capital & reserves | C21: =C22+C23 -> 0 | D21: =D22+D23 -> 4313234 | E21: =E22+E23 -> 0 | F21: =F22+F23 -> 4313234 | G21: =G22+G23 -> 0 | H21: =H22+H23 -> 0 | I21: =I22+I23 -> 0 | J21: =J22+J23 -> 0 | ... BW21: =BW22+BW23 -> 0
A22: a | B22: Proposed Dividends | C22: ='Evolutive SFP'!B46 -> 0 | D22: ='Evolutive SFP'!C46 -> 4313234 | E22: ='Evolutive SFP'!D46 -> 0 | F22: ='Evolutive SFP'!E46 -> 4313234 | G22: ='Evolutive SFP'!F46 -> 0 | H22: ='Evolutive SFP'!G46 -> 0 | I22: ='Evolutive SFP'!H46 -> 0 | J22: ='Evolutive SFP'!I46 -> 0 | ... BP22: ='Evolutive SFP'!BO46 -> 0 | BQ22: ='Evolutive SFP'!BQ46 -> 0 | BR22: ='Evolutive SFP'!BR46 -> 0 | BS22: ='Evolutive SFP'!BS46 -> 0 | BT22: ='Evolutive SFP'!BT46 -> 0 | BU22: ='Evolutive SFP'!BU46 -> 0 | BV22: ='Evolutive SFP'!BV46 -> 0 | BW22: ='Evolutive SFP'!BW46 -> 0
A23: b | B23: Risk Mgt Fund
A25: 6 | B25: Investments | C25: =C26+C27+C28 -> 472260 | D25: =D26+D27+D28 -> 45486921 | E25: =E26+E27+E28 -> 1.0662772e+08 | F25: =F26+F27+F28 -> 48885388 | G25: =G26+G27+G28 -> 48935388 | H25: =H26+H27+H28 -> #REF! | I25: =I26+I27+I28 -> 49035388 | J25: =J26+J27+J28 -> 49085388 | ... BW25: =BW26+BW27+BW28 -> 0
A26: 6.1 | B26: Shares in Kusco,CIC,Coop Bank | C26: ='Evolutive SFP'!B13 -> 472260 | D26: ='Evolutive SFP'!C13 -> 32948533 | E26: ='Evolutive SFP'!D9 -> 0 | F26: ='Evolutive SFP'!E13 -> 48885388 | G26: ='Evolutive SFP'!F13 -> 48935388 | H26: ='Evolutive SFP'!#REF! -> #REF! | I26: ='Evolutive SFP'!H13 -> 49035388 | J26: ='Evolutive SFP'!I13 -> 49085388 | K26: ='Evolutive SFP'!J13 -> 49135388 | L26: ='Evolutive SFP'!K13 -> 49385388 | M26: ='Evolutive SFP'!L13 -> 49435388 | N26: ='Evolutive SFP'!M13 -> 49485388 | O26: ='Evolutive SFP'!N13 -> 3.3953539e+08 | P26: ='Evolutive SFP'!O13 -> 3.8962744e+08 | ... BP26: ='Evolutive SFP'!BO13 -> 41801832 | BQ26: ='Evolutive SFP'!BQ13 -> 0 | BR26: ='Evolutive SFP'!BR13 -> 0 | BS26: ='Evolutive SFP'!BS13 -> 0 | BT26: ='Evolutive SFP'!BT13 -> 0 | BU26: ='Evolutive SFP'!BU13 -> 0 | BV26: ='Evolutive SFP'!BV13 -> 0 | BW26: ='Evolutive SFP'!BW13 -> 0
A27: 6.2 | B27: Equity Investments (at cost) | C27: ='Evolutive SFP'!B10 -> 0 | D27: ='Evolutive SFP'!C10 -> 0 | E27: ='Evolutive SFP'!D7 -> 57792330 | F27: ='Evolutive SFP'!E10 -> 0 | G27: ='Evolutive SFP'!F10 -> 0 | H27: ='Evolutive SFP'!#REF! -> #REF! | I27: ='Evolutive SFP'!H10 -> 0 | J27: ='Evolutive SFP'!I10 -> 0 | K27: ='Evolutive SFP'!J10 -> 0 | L27: ='Evolutive SFP'!K10 -> 0 | M27: ='Evolutive SFP'!L10 -> 0 | N27: ='Evolutive SFP'!M10 -> 0 | O27: ='Evolutive SFP'!N10 -> 0 | P27: ='Evolutive SFP'!O10 -> 0 | ... BP27: ='Evolutive SFP'!BO10 -> 0 | BQ27: ='Evolutive SFP'!BQ10 -> 0 | BR27: ='Evolutive SFP'!BR10 -> 0 | BS27: ='Evolutive SFP'!BS10 -> 0 | BT27: ='Evolutive SFP'!BT10 -> 0 | BU27: ='Evolutive SFP'!BU10 -> 0 | BV27: ='Evolutive SFP'!BV10 -> 0 | BW27: ='Evolutive SFP'!BW10 -> 0
A28: 6.3 | B28: Deposits in KUSCCO CFP | C28: ='Evolutive SFP'!B11 -> 0 | D28: ='Evolutive SFP'!C11 -> 12538388 | E28: ='Evolutive SFP'!D8 -> 48835388 | F28: ='Evolutive SFP'!E11 -> 0 | G28: ='Evolutive SFP'!F11 -> 0 | H28: ='Evolutive SFP'!#REF! -> #REF! | I28: ='Evolutive SFP'!H11 -> 0 | J28: ='Evolutive SFP'!I11 -> 0 | K28: ='Evolutive SFP'!J11 -> 0 | L28: ='Evolutive SFP'!K11 -> 0 | M28: ='Evolutive SFP'!L11 -> 0 | N28: ='Evolutive SFP'!M11 -> 0 | O28: ='Evolutive SFP'!N11 -> 0 | P28: ='Evolutive SFP'!O11 -> 0 | ... BP28: ='Evolutive SFP'!BO11 -> 0 | BQ28: ='Evolutive SFP'!BQ11 -> 0 | BR28: ='Evolutive SFP'!BR11 -> 0 | BS28: ='Evolutive SFP'!BS11 -> 0 | BT28: ='Evolutive SFP'!BT11 -> 0 | BU28: ='Evolutive SFP'!BU11 -> 0 | BV28: ='Evolutive SFP'!BV11 -> 0 | BW28: ='Evolutive SFP'!BW11 -> 0
A30: 7 | B30: Net Loans & Advances | C30: ='Evolutive SFP'!B14 -> 112905266 | D30: ='Evolutive SFP'!C14 -> 685110959 | E30: ='Evolutive SFP'!D10 -> 0 | F30: ='Evolutive SFP'!E14 -> 6.7384917e+08 | G30: ='Evolutive SFP'!F14 -> 6.77628e+08 | H30: ='Evolutive SFP'!#REF! -> #REF! | I30: ='Evolutive SFP'!H14 -> 6.8226734e+08 | J30: ='Evolutive SFP'!I14 -> 6.8266836e+08 | K30: ='Evolutive SFP'!J14 -> 6.7622378e+08 | L30: ='Evolutive SFP'!K14 -> 6.7381947e+08 | M30: ='Evolutive SFP'!L14 -> 6.7845115e+08 | N30: ='Evolutive SFP'!M14 -> 5.1260223e+08 | O30: ='Evolutive SFP'!N14 -> 5.5899658e+08 | P30: ='Evolutive SFP'!O14 -> 5.7846752e+08 | ... BP30: ='Evolutive SFP'!BO14 -> 598486828 | BQ30: ='Evolutive SFP'!BQ14 -> 0 | BR30: ='Evolutive SFP'!BR14 -> 0 | BS30: ='Evolutive SFP'!BS14 -> 0 | BT30: ='Evolutive SFP'!BT14 -> 0 | BU30: ='Evolutive SFP'!BU14 -> 0 | BV30: ='Evolutive SFP'!BV14 -> 0 | BW30: ='Evolutive SFP'!BW14 -> 0
A31: 7.1 | B31: Gross Loans & advances | C31: ='Evolutive SFP'!B15 -> 112905266 | D31: ='Evolutive SFP'!C15 -> 832525078 | E31: ='Evolutive SFP'!D11 -> 0 | F31: ='Evolutive SFP'!E15 -> 8.2510161e+08 | G31: ='Evolutive SFP'!F15 -> 8.307998e+08 | H31: ='Evolutive SFP'!#REF! -> #REF! | I31: ='Evolutive SFP'!H15 -> 8.3927821e+08 | J31: ='Evolutive SFP'!I15 -> 8.4159859e+08 | K31: ='Evolutive SFP'!J15 -> 8.35154e+08 | L31: ='Evolutive SFP'!K15 -> 8.3660065e+08 | M31: ='Evolutive SFP'!L15 -> 8.4315168e+08 | N31: ='Evolutive SFP'!M15 -> 6.7922211e+08 | O31: ='Evolutive SFP'!N15 -> 7.2945516e+08 | P31: ='Evolutive SFP'!O15 -> 7.4204087e+08 | ... BP31: ='Evolutive SFP'!BO15 -> 812162376 | BQ31: ='Evolutive SFP'!BQ15 -> 0 | BR31: ='Evolutive SFP'!BR15 -> 0 | BS31: ='Evolutive SFP'!BS15 -> 0 | BT31: ='Evolutive SFP'!BT15 -> 0 | BU31: ='Evolutive SFP'!BU15 -> 0 | BV31: ='Evolutive SFP'!BV15 -> 0 | BW31: ='Evolutive SFP'!BW15 -> 0
A32: 7.2 | B32: Allowance for loan losses | C32: ='Evolutive SFP'!B16 -> 0 | D32: ='Evolutive SFP'!C16 -> 147414119 | E32: ='Evolutive SFP'!D13 -> 48835388 | F32: ='Evolutive SFP'!E16 -> 1.5125245e+08 | G32: ='Evolutive SFP'!F16 -> 1.531718e+08 | H32: ='Evolutive SFP'!#REF! -> #REF! | I32: ='Evolutive SFP'!H16 -> 1.5701087e+08 | J32: ='Evolutive SFP'!I16 -> 1.5893023e+08 | K32: ='Evolutive SFP'!J16 -> 1.5893023e+08 | L32: ='Evolutive SFP'!K16 -> 1.6278118e+08 | M32: ='Evolutive SFP'!L16 -> 1.6470053e+08 | N32: ='Evolutive SFP'!M16 -> 1.6661988e+08 | O32: ='Evolutive SFP'!N16 -> 1.7045858e+08 | P32: ='Evolutive SFP'!O16 -> 1.6357335e+08 | ... BP32: ='Evolutive SFP'!BO16 -> 213675548 | BQ32: ='Evolutive SFP'!BQ16 -> 0 | BR32: ='Evolutive SFP'!BR16 -> 0 | BS32: ='Evolutive SFP'!BS16 -> 0 | BT32: ='Evolutive SFP'!BT16 -> 0 | BU32: ='Evolutive SFP'!BU16 -> 0 | BV32: ='Evolutive SFP'!BV16 -> 0 | BW32: ='Evolutive SFP'!BW16 -> 0
A34: 8 | B34: Non-Earning Assets | C34: ='Evolutive SFP'!B21+'Evolutive SFP'!B7 -> 18274979 | D34: ='Evolutive SFP'!C21+'Evolutive SFP'!C7 -> 108312001 | E34: ='Evolutive SFP'!D18+'Evolutive SFP'!D4 -> 2.2822376e+08 | F34: ='Evolutive SFP'!E21+'Evolutive SFP'!E7 -> 1.6316829e+08 | G34: ='Evolutive SFP'!F21+'Evolutive SFP'!F7 -> 1.6614459e+08 | H34: ='Evolutive SFP'!G8+'Evolutive SFP'!#REF! -> #REF! | I34: ='Evolutive SFP'!H21+'Evolutive SFP'!H7 -> 1.6037412e+08 | J34: ='Evolutive SFP'!I21+'Evolutive SFP'!I7 -> 1.4885113e+08 | K34: ='Evolutive SFP'!J21+'Evolutive SFP'!J7 -> 1.5144491e+08 | L34: ='Evolutive SFP'!K21+'Evolutive SFP'!K7 -> 1.4181593e+08 | M34: ='Evolutive SFP'!L21+'Evolutive SFP'!L7 -> 1.3883474e+08 | N34: ='Evolutive SFP'!M21+'Evolutive SFP'!M7 -> 2.7802686e+08 | O34: ='Evolutive SFP'!N21+'Evolutive SFP'!N7 -> 2.4161782e+08 | P34: ='Evolutive SFP'!O21+'Evolutive SFP'!O7 -> 1.4569539e+08 | ... BP34: ='Evolutive SFP'!BO21+'Evolutive SFP'!BO7 -> 267660740 | BQ34: =BP34/BP4 -> 0.19381987 | BR34: ='Evolutive SFP'!BR21+'Evolutive SFP'!BR7 -> 0 | BS34: ='Evolutive SFP'!BS21+'Evolutive SFP'!BS7 -> 0 | BT34: ='Evolutive SFP'!BT21+'Evolutive SFP'!BT7 -> 0 | BU34: ='Evolutive SFP'!BU21+'Evolutive SFP'!BU7 -> 0 | BV34: ='Evolutive SFP'!BV21+'Evolutive SFP'!BV7 -> 0 | BW34: ='Evolutive SFP'!BW21+'Evolutive SFP'!BW7 -> 0
