Workbook

Sheet Evolutive SFP
A2: Washa Sacco
B3: 2010 Audited | C3: 2020 Audited | D3: 44562 | E3: 44593 | F3: 44621 | G3: 44652 | H3: 44682 | I3: 44713 | J3: 44743 | K3: 44774 | L3: 44805 | M3: 44835 | N3: 44866 | O3: 44896 | P3: audited 2022
A4: Cash & cash Equivalent | B4: =SUM(B5:B6) -> 0 | C4: =SUM(C5:C6) -> 0 | D4: =SUM(D5:D6) -> 7.1078616e+08 | E4: =SUM(E5:E6) -> 4.8005591e+08 | F4: =SUM(F5:F6) -> 5.383918e+08 | G4: =SUM(G5:G6) -> 5.0840905e+08 | H4: =SUM(H5:H6) -> 5.1702137e+08 | I4: =SUM(I5:I6) -> 8.0524523e+08 | ... P4: =SUM(P5:P6) -> 469474880
A5: Cash In Hand | D5: 1.063018e+08 | E5: 63165349 | F5: 61720872 | G5: 68302499 | H5: 82293591 | I5: 79298037 | J5: 74301214 | K5: 54212456 | L5: 67267283 | M5: 46556978 | N5: 63179963 | O5: 91972825 | P5: 37278923
A6: Cash at Bank | D6: 6.0448435e+08 | E6: 4.1689056e+08 | F6: 4.7667093e+08 | G6: 4.4010655e+08 | H6: 4.3472778e+08 | I6: 7.2594719e+08 | J6: 3.7544934e+08 | K6: 4.6137572e+08 | L6: 4.4284249e+08 | M6: 4.5067234e+08 | N6: 3.0734485e+08 | O6: 3.7750106e+08 | P6: 432195957
A7: Prepayment and Sundry | E7: 1.5971448e+08 | F7: 3.3793969e+08 | G7: 1.9268712e+08 | H7: 1.6005053e+08 | I7: 1.8245847e+08 | J7: 4386941.2 | K7: 3.0381035e+08 | L7: 1.8807601e+08 | M7: 1.6409387e+08 | N7: 3.3451046e+08 | O7: 4.383495e+08 | P7: 335415092
A8: Financial Investment | B8: =SUM(B9:B13) -> 0 | C8: =SUM(C9:C13) -> 0 | D8: =SUM(D9:D13) -> 81856795 | E8: =SUM(E9:E13) -> 86044847 | F8: =SUM(F9:F13) -> 86544847 | G8: =SUM(G9:G13) -> 87044847 | H8: =SUM(H9:H13) -> 88744847 | I8: =SUM(I9:I13) -> 89340840 | ... P8: =SUM(P9:P13) -> 92444812
A9: Government Securities - Treasury Bills/bonds, | D9: 76528.9 | E9: 76528.9 | F9: 76528.9 | G9: 76528.9 | H9: 76528.9 | I9: 76528.9 | J9: 76528.9 | K9: 76528.9 | L9: 76528.9 | M9: 76528.9 | N9: 76528.9 | O9: 76528.9 | P9: 76529
A10: Other Securities - Commercial papers/Bonds | D10: 0 | E10: 0 | F10: 0 | G10: 0 | H10: 0 | I10: 0 | J10: 0 | K10: 0 | L10: 0 | M10: 0 | N10: 0 | O10: 0 | U10: =469474880-37278923 -> 432195957
A11: Balances in NACCOS (E.g Jungu Kuu, ESS, Savings,Money Market,Coop FD, CFP) | D11: 81780266 | E11: 85968318 | F11: 86468318 | G11: 86968318 | H11: 88668318 | I11: 89264311 | J11: 89764311 | K11: 90368283 | L11: 90868283 | M11: 91368283 | N11: 91868283 | O11: 92368283 | P11: 92368283
A12: Equity Investments in NACCOs(Shares in- CIC, KUSCCO, COOP BANK,CAK, KERUSSU) | D12: 0 | E12: 0 | F12: 0 | G12: 0 | H12: 0 | I12: 0 | J12: 0 | K12: 0 | L12: 0 | M12: 0 | N12: 0 | O12: 0
A13: Equity Investments in companies - shares/stocks
A14: Net Loan Portfolio | B14: =B15-B16 -> 0 | C14: =C15-C16 -> 0 | D14: =D15-D16 -> 7.2408237e+09 | E14: =E15-E16 -> 7.2954544e+09 | F14: =F15-F16 -> 7.518766e+09 | G14: =G15-G16 -> 7.6727679e+09 | H14: =H15-H16 -> 7.7516627e+09 | I14: =I15-I16 -> 7.8280875e+09 | ... P14: =P15-P16 -> 8571140428
A15: Gross Loan Portfolio | D15: 8.1467102e+09 | E15: 8.2208389e+09 | F15: 8.4863937e+09 | G15: 8.6038896e+09 | H15: 8.70156e+09 | I15: 8.7860762e+09 | J15: 8.9299537e+09 | K15: 9.1009253e+09 | L15: 9.3105319e+09 | M15: 9.3652804e+09 | N15: 9.5709146e+09 | O15: 9.7349153e+09 | P15: 9734915300
A16: Allowance For Loan Loss | D16: 9.0588651e+08 | E16: 9.253845e+08 | F16: 9.6762762e+08 | G16: 9.3112171e+08 | H16: 9.4989727e+08 | I16: 9.5798868e+08 | J16: 9.5663535e+08 | K16: 9.8667673e+08 | L16: 1.0105113e+09 | M16: 1.0305068e+09 | N16: 1.1655068e+09 | O16: 1.1637749e+09 | P16: 1163774872
A17: Accounts Recievables
A18: Tax Recoverable | D18: 0 | E18: 0 | F18: 0 | G18: 0 | H18: 0 | I18: 0 | J18: 0 | K18: 0 | L18: 0 | M18: 0 | N18: 0 | O18: 0
A19: Deffered Tax Assets | D19: 0 | E19: 0 | F19: 0 | G19: 0 | H19: 0 | I19: 0 | J19: 0 | K19: 0 | L19: 0 | M19: 0 | N19: 0 | O19: 0
A20: Retirement Benefit Assets | D20: 0 | E20: 0 | F20: 0 | G20: 0 | H20: 0 | I20: 0 | J20: 0 | K20: 0 | L20: 0 | M20: 0 | N20: 0 | O20: 0
A21: Property&Equipments&Other Assets | B21: =SUM(B22:B26) -> 0 | C21: =SUM(C22:C26) -> 0 | D21: =SUM(D22:D26) -> 1.7993041e+08 | E21: =SUM(E22:E26) -> 2.0498944e+08 | F21: =SUM(F22:F26) -> 2.0717052e+08 | G21: =SUM(G22:G26) -> 2.1555307e+08 | H21: =SUM(H22:H26) -> 2.4797764e+08 | I21: =SUM(I22:I26) -> 2.9012954e+08 | ... Q21: =SUM(Q22:Q26) -> 0
A22: Investment Properties | D22: 0 | E22: 0 | F22: 0 | G22: 0 | H22: 0 | I22: 0 | J22: 0 | K22: 0 | L22: 0 | M22: 0 | N22: 0 | O22: 0
A23: Property and Equipment | D23: 1.7576373e+08 | E23: 2.010753e+08 | F23: 2.0373183e+08 | G23: 2.1286282e+08 | H23: 2.4339467e+08 | I23: 2.854335e+08 | J23: 2.9322472e+08 | K23: 2.9453611e+08 | L23: 2.9409113e+08 | M23: 2.9402115e+08 | N23: 2.9724085e+08 | O23: 2.9377307e+08 | P23: =135428782+102144250+37304398+10681331+8214314 -> 293773075
A24: Prepaid Lease Rentals | D24: 0 | E24: 0 | F24: 0 | G24: 0 | H24: 0 | I24: 0 | J24: 0 | K24: 0 | L24: 0 | M24: 0 | N24: 0 | O24: 0 | T24: =295500805-1727731 -> 293773074
A25: Intangible Assets | D25: 1727730.8 | E25: 1151820.6 | F25: 575910.28 | G25: 0 | H25: 2063678.5 | I25: 2015686 | J25: 1967693.5 | K25: 1919700.9 | L25: 1871708.4 | M25: 1823715.9 | N25: 1775723.4 | O25: 1727730.9 | P25: 1727731
A26: Other Assets | D26: 2438948 | E26: 2762318.2 | F26: 2862780.6 | G26: 2690251 | H26: 2519296.4 | I26: 2680360.2 | J26: 44856601 | K26: 44641339 | L26: 20060370 | M26: 27904964 | N26: 29331049 | O26: 29334976 | P26: 26532634
A27: Total Assets | B27: =B21+B17+B14+B8+B7+B4 -> 0 | C27: =C21+C17+C14+C8+C7+C4 -> 0 | D27: =D21+D17+D14+D8+D7+D4 -> 8.213397e+09 | E27: =E21+E17+E14+E8+E7+E4 -> 8.2262591e+09 | F27: =F21+F17+F14+F8+F7+F4 -> 8.6888129e+09 | G27: =G21+G17+G14+G8+G7+G4 -> 8.676462e+09 | H27: =H21+H17+H14+H8+H7+H4 -> 8.7654571e+09 | I27: =I21+I17+I14+I8+I7+I4 -> 9.1952616e+09 | ... P27: =P21+P17+P14+P8+P7+P4 -> 9790508652
A28: Savings and Deposits | D28: 1.1633343e+09 | E28: 1.1128146e+09 | F28: 1098477431 | G28: 1.0668196e+09 | H28: 1.0730231e+09 | I28: 1.0825002e+09 | J28: 1.1106033e+09 | K28: 1.1159213e+09 | L28: 1.0828321e+09 | M28: 1.1256171e+09 | N28: 1.1863454e+09 | O28: 1.118202e+09 | P28: 1118202008 | T28: =P27-9790508651 -> 1
A29: Short Terrm Deposits | D29: 210396467 | E29: 230045882 | F29: 245452654 | G29: 242260285 | H29: 248562038 | I29: 295289738 | J29: 222728676 | K29: 224263557 | L29: 216785812 | M29: 223745510 | N29: 182520647 | O29: 234212902 | P29: 234212902
A30: Non Withdrawable Deposits | D30: 3.9622858e+09 | E30: 3.9404349e+09 | F30: 3.9877462e+09 | G30: 4.0274786e+09 | H30: 4.0712362e+09 | I30: 4.1240063e+09 | J30: 4.1884666e+09 | K30: 4.2332454e+09 | L30: 4.2771528e+09 | M30: 4337236817 | N30: 4.3859871e+09 | O30: 4.4221324e+09 | P30: 4422132439
A31: Total Deposit Liabilities | B31: =SUM(B28:B30) -> 0 | C31: =SUM(C28:C30) -> 0 | D31: =SUM(D28:D30) -> 5.3360166e+09 | E31: =SUM(E28:E30) -> 5.2832955e+09 | F31: =SUM(F28:F30) -> 5.3316763e+09 | G31: =SUM(G28:G30) -> 5.3365585e+09 | H31: =SUM(H28:H30) -> 5.3928213e+09 | I31: =SUM(I28:I30) -> 5.5017962e+09 | ... P31: =SUM(P28:P30) -> 5774547349
A32: Tax Payable | D32: 0 | E32: 0 | F32: 0 | G32: 0 | H32: 0 | I32: 0 | J32: 0 | K32: 0 | L32: 0 | M32: 0 | N32: 0 | O32: 0 | P32: 30567374
A33: Dividends Payable | D33: 524900000 | E33: 60600000 | F33: 111200000 | G33: 161500000 | H33: 209000000 | I33: 239300000 | J33: 309600000 | K33: 339900000 | L33: 500200000 | M33: 570500000 | N33: 583300000 | O33: 563300000 | P33: 573850000
A34: Deferred Tax Liability | D34: 71937016 | E34: 73893260 | F34: 75893260 | G34: 55184363 | H34: 57171513 | I34: 31242954 | J34: 33242954 | K34: 35234014 | L34: 30637763 | M34: 33714540 | N34: 39707030 | O34: 42117374 | P34: 38447563
A35: Retirement Benefits Liabilty | D35: 1063920 | E35: 1196910 | F35: 1329900 | G35: 1462890 | H35: 1606110 | I35: 586520 | J35: 641080 | K35: 726330 | L35: 2687280 | M35: 763880 | N35: 763880 | O35: 411326
A36: Other Liabilities | D36: 2.7746126e+08 | E36: 3.0844311e+08 | F36: 3.2283815e+08 | G36: 3.2413485e+08 | H36: 3.0237098e+08 | I36: 3.0964704e+08 | J36: 3.1725618e+08 | K36: 2.758155e+08 | L36: 2.8473559e+08 | M36: 2.9671484e+08 | N36: 2.5737925e+08 | O36: 2.8307013e+08 | P36: 208872348
A37: External Borrowings | D37: 0 | E37: 0 | F37: 0 | G37: 0 | H37: 0 | I37: 0 | J37: 0 | K37: 0 | L37: 0 | M37: 0 | N37: 0 | O37: 0
A38: Total Liabilities | B38: =SUM(B31:B37) -> 0 | C38: =SUM(C31:C37) -> 0 | D38: =SUM(D31:D37) -> 6.2113788e+09 | E38: =SUM(E31:E37) -> 5.7274287e+09 | F38: =SUM(F31:F37) -> 5.8429376e+09 | G38: =SUM(G31:G37) -> 5.8788406e+09 | H38: =SUM(H31:H37) -> 5.9629699e+09 | I38: =SUM(I31:I37) -> 6.0825727e+09 | ... P38: =SUM(P31:P37) -> 6626284634
A39: Share Capital | D39: 2.8802315e+08 | E39: 2.9009301e+08 | F39: 2.9126031e+08 | G39: 2.9291085e+08 | H39: 2.9451747e+08 | I39: 2.9528422e+08 | J39: 3.1281936e+08 | K39: 3.1368427e+08 | L39: 3.152255e+08 | M39: 3.1652504e+08 | N39: 3.1786335e+08 | O39: 3.1930081e+08 | P39: 319300807
A40: Capital Grants | D40: 0 | E40: 0 | F40: 0 | G40: 0 | H40: 0 | I40: 0 | J40: 0 | K40: 0 | L40: 0 | M40: 0 | N40: 0 | O40: 0
A41: Prior Year Retained Earnigs | D41: 5.8371373e+08 | E41: 5.8371373e+08 | F41: 5.8371373e+08 | G41: 5.8371373e+08 | H41: 5.8371373e+08 | I41: 5.8371373e+08 | J41: 5.8371373e+08 | K41: 5.8371373e+08 | L41: 5.8371373e+08 | M41: 5.8371373e+08 | N41: 5.2073694e+08 | O41: 4.519928e+08 | P41: 532285947
...

Sheet Evolutitve SCI
B2: 2010 Audited | C2: 2020 Audited | D2: 44562 | E2: 44593 | F2: 44621 | G2: 44652 | H2: 44682 | I2: 44713 | J2: 44743 | K2: 44774 | L2: 44805 | M2: 44835 | N2: 44866 | O2: 44896 | P2: audited 2022
A3: Financial Income | B3: =B4+B7 -> 0 | C3: =C4+C7 -> 0 | D3: =D4+D7 -> 1.3169117e+08 | E3: =E4+E7 -> 2.7560832e+08 | F3: =F4+F7 -> 4.1295895e+08 | G3: =G4+G7 -> 5.4806697e+08 | H3: =H4+H7 -> 6.6323576e+08 | I3: =I4+I7 -> 8.0828852e+08 | ... P3: =P4+P7 -> 1740269835
A4: Financial Income From Loans Portfolio | B4: =SUM(B5:B6) -> 0 | C4: =SUM(C5:C6) -> 0 | D4: =SUM(D5:D6) -> 1.3164192e+08 | E4: =SUM(E5:E6) -> 2.7545957e+08 | F4: =SUM(F5:F6) -> 4.127412e+08 | G4: =SUM(G5:G6) -> 5.4779172e+08 | H4: =SUM(H5:H6) -> 6.6288951e+08 | I4: =SUM(I5:I6) -> 8.0788927e+08 | ... P4: =SUM(P5:P6) -> 1614234972
A5: Interest from Loans Portfolio | D5: 1.2893192e+08 | E5: 2.6968467e+08 | F5: 4.0133362e+08 | G5: 5.3380706e+08 | H5: 6.4615031e+08 | I5: 7.8833408e+08 | J5: 8.9870506e+08 | K5: 1.0179117e+09 | L5: 1.1773818e+09 | M5: 1.3104477e+09 | N5: 1.4451481e+09 | O5: 1.5868748e+09 | P5: 1586970740
A6: Fees&Commision on Loan Portfolio | D6: 2710002.1 | E6: 5774899.5 | F6: 11407576 | G6: 13984661 | H6: 16739198 | I6: 19555188 | J6: 22287086 | K6: 26004290 | L6: 29160358 | M6: 31987719 | N6: 35050708 | O6: 42424134 | P6: 27264232
A7: Financial Income from Investments | B7: =SUM(B8:B11) -> 0 | C7: =SUM(C8:C11) -> 0 | D7: =SUM(D8:D11) -> 49250 | E7: =SUM(E8:E11) -> 148750 | F7: =SUM(F8:F11) -> 217750 | G7: =SUM(G8:G11) -> 275250 | H7: =SUM(H8:H11) -> 346250 | I7: =SUM(I8:I11) -> 399250 | ... P7: =SUM(P8:P11) -> 126034863
A8: Government Securities | D8: 0 | E8: 0 | F8: 0 | G8: 0 | H8: 0 | I8: 0 | J8: 0 | K8: 0 | L8: 0 | M8: 0 | N8: 0 | O8: 0
A9: Deposits with Banks & other Financial Institutions | D9: 0 | E9: 0 | F9: 0 | G9: 0 | H9: 0 | I9: 0 | J9: 0 | K9: 0 | L9: 0 | M9: 0 | N9: 0 | O9: 0
A10: Other Investments | D10: 49250 | E10: 148750 | F10: 217750 | G10: 275250 | H10: 346250 | I10: 399250 | J10: 455750 | K10: 488650 | L10: 569450 | M10: 644550 | N10: 692300 | O10: 773700 | P10: 126034863
A11: Other Operating Income
A12: Financial Expenses | B12: =SUM(B13:B18) -> 0 | C12: =SUM(C13:C18) -> 0 | D12: =SUM(D13:D18) -> 16287723 | E12: =SUM(E13:E18) -> 89210236 | F12: =SUM(F13:F18) -> 1.5282435e+08 | G12: =SUM(G13:G18) -> 2.194299e+08 | H12: =SUM(H13:H18) -> 2.8176028e+08 | I12: =SUM(I13:I18) -> 3.2591926e+08 | ... P12: =SUM(P13:P18) -> 549923210
A13: Interest Expense on Deposits | D13: 1078750.8 | E13: 63771490 | F13: 1.1486813e+08 | G13: 1.6573486e+08 | H13: 2.1526436e+08 | I13: 2.4634098e+08 | J13: 3.1896328e+08 | K13: 3.4992397e+08 | L13: 5.108175e+08 | M13: 5.8249025e+08 | N13: 5.960492e+08 | O13: 5.8730902e+08 | P13: 531164861
A14: Cost of External Borrowings | D14: 192161.35 | E14: 192161.35 | F14: 192161.35 | G14: 192161.35 | H14: 192161.35 | I14: 192161.35 | J14: 192161.35 | K14: 192161.35 | L14: 192161.35 | M14: 192161.35 | N14: 192161.35 | O14: 192161.35
A15: Dividend Expenses | D15: 0 | E15: 0 | F15: 0 | G15: 0 | H15: 0 | I15: 0 | J15: 0 | K15: 0 | L15: 0 | M15: 0 | N15: 0 | O15: 0
A16: Other Financial Expense | D16: 0 | E16: 0 | F16: 0 | G16: 0 | H16: 0 | I16: 0 | J16: 0 | K16: 0 | L16: 0 | M16: 0 | N16: 0 | O16: 0
A17: Fees & Commision Expense | D17: 16811 | E17: 246584.6 | F17: 264059.2 | G17: 3502873.2 | H17: 3803762.1 | I17: 4386119.1 | J17: 7417085.1 | K17: 7615676.1 | L17: 7629001.1 | M17: 15754126 | N17: 16112309 | O17: 18566188 | P17: 18758349
A18: Other Expenses | D18: 15000000 | E18: 25000000 | F18: 37500000 | G18: 50000000 | H18: 62500000 | I18: 75000000 | J18: 87500000 | K18: 100000000 | L18: 137000000 | M18: 190000000 | N18: 213000000 | O18: 215000000
A19: Net Financial Income | B19: =B3-B12 -> 0 | C19: =C3-C12 -> 0 | D19: =D3-D12 -> 1.1540345e+08 | E19: =E3-E12 -> 1.8639809e+08 | F19: =F3-F12 -> 2.601346e+08 | G19: =G3-G12 -> 3.2863707e+08 | H19: =H3-H12 -> 3.8147548e+08 | I19: =I3-I12 -> 4.8236925e+08 | ... P19: =P3-P12 -> 1190346625
A20: Allowance for Loan Loss | B20: =B21-B22 -> 0 | C20: =C21-C22 -> 0 | D20: =D21-D22 -> 15000000 | E20: =E21-E22 -> 34497982 | F20: =F21-F22 -> 76861564 | G20: =G21-G22 -> 76861564 | H20: =H21-H22 -> 91453795 | I20: =I21-I22 -> 1.0145379e+08 | ... P20: =P21-P22 -> 0
A21: Provision for Loan Losses | D21: 15000000 | E21: 34497982 | F21: 76861564 | G21: 76861564 | H21: 91453795 | I21: 1.0145379e+08 | J21: 1.0145379e+08 | K21: 1.3145379e+08 | L21: 1.5545379e+08 | M21: 1.7545379e+08 | N21: 2.1045379e+08 | O21: 2.1045379e+08
A22: Value of Loans Recovered | D22: 0 | E22: 0 | F22: 0 | G22: 0 | H22: 0 | I22: 0 | J22: 0 | K22: 0 | L22: 0 | M22: 0 | N22: 0 | O22: 0
A23: Operating Expeses | B23: =SUM(B24:B28) -> 0 | C23: =SUM(C24:C28) -> 0 | D23: =SUM(D24:D28) -> 41657631 | E23: =SUM(E24:E28) -> 82994718 | F23: =SUM(F24:F28) -> 1.1419933e+08 | G23: =SUM(G24:G28) -> 1.4093178e+08 | H23: =SUM(H24:H28) -> 1.4249081e+08 | I23: =SUM(I24:I28) -> 1.6743113e+08 | ... P23: =SUM(P24:P28) -> 535188521
A24: Personel Expenses | D24: 8744548.6 | E24: 16591972 | F24: 28439723 | G24: 37866177 | H24: 47042303 | I24: 56971771 | J24: 66139371 | K24: 75791291 | L24: 87297654 | M24: 96708196 | N24: 1.1000414e+08 | O24: 1.2904944e+08 | P24: 129049436
A25: Governance Expenses | D25: 9259601 | E25: 13069124 | F25: 15723044 | G25: 18323696 | H25: 19813523 | I25: 21210075 | J25: 22050075 | K25: 23014618 | L25: 23674618 | M25: 30943634 | N25: 38759089 | O25: 42931553 | P25: 42931553
A26: Marketing Expenses | D26: 4208495 | E26: 6668798 | F26: 8933219 | G26: 10832558 | H26: 13854589 | I26: 16619416 | J26: 21468563 | K26: 24749083 | L26: 27321135 | M26: 32232632 | N26: 37936132 | O26: 43308034 | P26: 43308034
A27: Depreciation and Amortization | D27: 5568336.3 | E27: 11270109 | F27: 18769525 | G27: 23716941 | H27: 3836973.2 | I27: 6307502.5 | J27: 7360737.8 | K27: 7769538.1 | L27: 8724728.3 | M27: 9999831.6 | N27: 12265727 | O27: 15640553 | P27: 226094348
A28: Administrative Expenses | D28: 13876650 | E28: 35394714 | F28: 42333822 | G28: 50192406 | H28: 57943422 | I28: 66322362 | J28: 73794728 | K28: 80936530 | L28: 89871397 | M28: 1.0862975e+08 | N28: 1.2052465e+08 | O28: 1.3380515e+08 | P28: 93805150
A29: Net Operating Income | B29: =B19-B20-B23 -> 0 | C29: =C19-C20-C23 -> 0 | D29: =D19-D20-D23 -> 58745818 | E29: =E19-E20-E23 -> 68905387 | F29: =F19-F20-F23 -> 69073701 | G29: =G19-G20-G23 -> 1.1084373e+08 | H29: =H19-H20-H23 -> 1.4753087e+08 | I29: =I19-I20-I23 -> 2.1348433e+08 | ... P29: =P19-P20-P23 -> 655158104
A30: Net Non operating Income/Expense | B30: =B31-B32 -> 0
A31: Non Operating Income
A32: Non Operating Expense
A33: Net Income(Before Tax & Donations) | B33: =B29+B30 -> 0 | C33: =C29+C30 -> 0 | D33: =D29+D30 -> 58745818 | E33: =E29+E30 -> 68905387 | F33: =F29+F30 -> 69073701 | G33: =G29+G30 -> 1.1084373e+08 | H33: =H29+H30 -> 1.4753087e+08 | I33: =I29+I30 -> 2.1348433e+08 | ... P33: =P29+P30 -> 655158104
A34: Taxes | B34: =B30+B31 -> 0 | P34: 40000000
A35: Net Income(After Tax Before Donations) | B35: =B33-B34 -> 0 | C35: =C33-C34 -> 0 | D35: =D33-D34 -> 58745818 | E35: =E33-E34 -> 68905387 | F35: =F33-F34 -> 69073701 | G35: =G33-G34 -> 1.1084373e+08 | H35: =H33-H34 -> 1.4753087e+08 | I35: =I33-I34 -> 2.1348433e+08 | ... P35: =P33-P34 -> 615158104
A36: Donations | C36: 0 | D36: 0 | E36: 0
A37: Net Income/(After Tax & Donations) | B37: =B35-B36 -> 0 | C37: =C35-C36 -> 0 | D37: =D35-D36 -> 58745818 | E37: =E35-E36 -> 68905387 | F37: =F35-F36 -> 69073701 | G37: =G35-G36 -> 1.1084373e+08 | H37: =H35-H36 -> 1.4753087e+08 | I37: =I35-I36 -> 2.1348433e+08 | ... P37: =P35-P36 -> 615158104
A39: Total Expenses | B39: =B12+B23 -> 0 | C39: =C12+C23 -> 0 | D39: =#REF!+#REF! -> #REF! | E39: =#REF!+#REF! -> #REF! | F39: =#REF!+#REF! -> #REF! | G39: =#REF!+#REF! -> #REF! | H39: =#REF!+#REF! -> #REF! | I39: =#REF!+#REF! -> #REF! | J39: =#REF!+#REF! -> #REF! | K39: =#REF!+#REF! -> #REF! | L39: =#REF!+#REF! -> #REF! | M39: =A12+A23 -> #VALUE! | N39: =B12+B23 -> 0 | O39: =C12+C23 -> 0
Q41: =Q39-P39 -> 0 | R41: =R39-Q39 -> 0

Sheet CAELS
A1: Winas SACCO 2021
D2: 44198 | E2: 44230 | F2: 44562 | G2: 44593 | H2: 44621 | I2: 44652 | J2: 44682 | K2: 44713 | L2: 44743 | M2: 44774 | N2: 44805 | O2: 44835 | P2: 44866 | Q2: 44896 | R2: audited 2022
A3: CAPITAL ADEQUACY | B3: Core Capital | C3: 10 M | D3: =(('Evolutive SFP'!#REF!+'Evolutive SFP'!#REF!+'Evolutive SFP'!#REF!+'Evolutive SFP'!#REF!+'Evolutive SFP'!#REF!+'Evolutive SFP'!#REF!)-'Evolutive SFP'!#REF!)/1000000 -> #REF! | E3: =(('Evolutive SFP'!#REF!+'Evolutive SFP'!#REF!+'Evolutive SFP'!#REF!+'Evolutive SFP'!#REF!+'Evolutive SFP'!#REF!+'Evolutive SFP'!#REF!)-'Evolutive SFP'!#REF!)/1000000 -> #REF! | F3: =(('Evolutive SFP'!D39+'Evolutive SFP'!D40+'Evolutive SFP'!D41+'Evolutive SFP'!D42+'Evolutive SFP'!D43+'Evolutive SFP'!D44)-'Evolutive SFP'!D10)/1000000 -> 2645.6851 | G3: =(('Evolutive SFP'!E39+'Evolutive SFP'!E40+'Evolutive SFP'!E41+'Evolutive SFP'!E42+'Evolutive SFP'!E43+'Evolutive SFP'!E44)-'Evolutive SFP'!E10)/1000000 -> 2677.0556 | H3: =(('Evolutive SFP'!F39+'Evolutive SFP'!F40+'Evolutive SFP'!F41+'Evolutive SFP'!F42+'Evolutive SFP'!F43+'Evolutive SFP'!F44)-'Evolutive SFP'!F10)/1000000 -> 2700.6227 | I3: =(('Evolutive SFP'!G39+'Evolutive SFP'!G40+'Evolutive SFP'!G41+'Evolutive SFP'!G42+'Evolutive SFP'!G43+'Evolutive SFP'!G44)-'Evolutive SFP'!G10)/1000000 -> 2764.9848 | J3: =(('Evolutive SFP'!H39+'Evolutive SFP'!H40+'Evolutive SFP'!H41+'Evolutive SFP'!H42+'Evolutive SFP'!H43+'Evolutive SFP'!H44)-'Evolutive SFP'!H10)/1000000 -> 2824.8952 | K3: =(('Evolutive SFP'!I39+'Evolutive SFP'!I40+'Evolutive SFP'!I41+'Evolutive SFP'!I42+'Evolutive SFP'!I43+'Evolutive SFP'!I44)-'Evolutive SFP'!I10)/1000000 -> 2913.5881 | L3: =(('Evolutive SFP'!J39+'Evolutive SFP'!J40+'Evolutive SFP'!J41+'Evolutive SFP'!J42+'Evolutive SFP'!J43+'Evolutive SFP'!J44)-'Evolutive SFP'!J10)/1000000 -> 2953.201 | M3: =(('Evolutive SFP'!K39+'Evolutive SFP'!K40+'Evolutive SFP'!K41+'Evolutive SFP'!K42+'Evolutive SFP'!K43+'Evolutive SFP'!K44)-'Evolutive SFP'!K10)/1000000 -> 3003.3193 | ... R3: =(('Evolutive SFP'!P39+'Evolutive SFP'!P40+'Evolutive SFP'!P41+'Evolutive SFP'!P42+'Evolutive SFP'!P43+'Evolutive SFP'!P44)-'Evolutive SFP'!P10)/1000000 -> 3143.1947
B4: CCA | C4: Min 10% | D4: =D3/(('Evolutive SFP'!#REF!)/1000000) -> #REF! | E4: =E3/(('Evolutive SFP'!#REF!)/1000000) -> #REF! | F4: =F3/(('Evolutive SFP'!D27)/1000000) -> 0.32211826 | G4: =G3/(('Evolutive SFP'!E27)/1000000) -> 0.32542806 | H4: =H3/(('Evolutive SFP'!F27)/1000000) -> 0.31081607 | I4: =I3/(('Evolutive SFP'!G27)/1000000) -> 0.31867653 | J4: =J3/(('Evolutive SFP'!H27)/1000000) -> 0.32227585 | K4: =K3/(('Evolutive SFP'!I27)/1000000) -> 0.31685755 | L4: =L3/(('Evolutive SFP'!J27)/1000000) -> 0.33341828 | M4: =M3/(('Evolutive SFP'!K27)/1000000) -> 0.32068966 | ... R4: =R3/(('Evolutive SFP'!P27)/1000000) -> 0.32104509
B5: CCD | C5: Min 8% | D5: =D3/('Evolutive SFP'!#REF!/1000000) -> #REF! | E5: =E3/('Evolutive SFP'!#REF!/1000000) -> #REF! | F5: =F3/('Evolutive SFP'!D31/1000000) -> 0.49581651 | G5: =G3/('Evolutive SFP'!E31/1000000) -> 0.50670185 | H5: =H3/('Evolutive SFP'!F31/1000000) -> 0.50652413 | I5: =I3/('Evolutive SFP'!G31/1000000) -> 0.51812134 | J5: =J3/('Evolutive SFP'!H31/1000000) -> 0.5238251 | K5: =K3/('Evolutive SFP'!I31/1000000) -> 0.52957034 | L5: =L3/('Evolutive SFP'!J31/1000000) -> 0.53482592 | M5: =M3/('Evolutive SFP'!K31/1000000) -> 0.53886371 | ... R5: =R3/('Evolutive SFP'!P31/1000000) -> 0.54431881
B6: ICA | C6: Min 8% | D6: =((D3*1000000)-'Evolutive SFP'!#REF!)/'Evolutive SFP'!#REF! -> #REF! | E6: =((E3*1000000)-'Evolutive SFP'!#REF!)/'Evolutive SFP'!#REF! -> #REF! | F6: =((F3*1000000)-'Evolutive SFP'!D39)/'Evolutive SFP'!D27 -> 0.28705077 | G6: =((G3*1000000)-'Evolutive SFP'!E39)/'Evolutive SFP'!E27 -> 0.2901638 | H6: =((H3*1000000)-'Evolutive SFP'!F39)/'Evolutive SFP'!F27 -> 0.27729477 | I6: =((I3*1000000)-'Evolutive SFP'!G39)/'Evolutive SFP'!G27 -> 0.28491728 | J6: =((J3*1000000)-'Evolutive SFP'!H39)/'Evolutive SFP'!H27 -> 0.28867607 | K6: =((K3*1000000)-'Evolutive SFP'!I39)/'Evolutive SFP'!I27 -> 0.2847449 | L6: =((L3*1000000)-'Evolutive SFP'!J39)/'Evolutive SFP'!J27 -> 0.29810078 | M6: =((M3*1000000)-'Evolutive SFP'!K39)/'Evolutive SFP'!K27 -> 0.28719496 | ... R6: =((R3*1000000)-'Evolutive SFP'!P39)/'Evolutive SFP'!P27 -> 0.28843179
A7: ASSET QUALITY | B7: A/LNPL30
B8: NPL30 | F8: =(2494410+2429401+5048799)/207093162 -> 0.048155187 | G8: =(2494410+2429401+5048799)/207093162 -> 0.048155187 | H8: =(2494410+2429401+5048799)/207093162 -> 0.048155187 | I8: =(2494410+2429401+5048799)/207093162 -> 0.048155187 | J8: =(2494410+2429401+5048799)/207093162 -> 0.048155187 | K8: =(2494410+2429401+5048799)/207093162 -> 0.048155187 | L8: =(2494410+2429401+5048799)/207093162 -> 0.048155187 | M8: =(2494410+2429401+5048799)/207093162 -> 0.048155187 | ... R8: =(2494410+2429401+5048799)/207093162 -> 0.048155187
A9: EARNINGS | B9: ROA | D9: ='Evolutitve SCI'!#REF!/(('Evolutive SFP'!C27+'Evolutive SFP'!#REF!)/2) -> #REF! | E9: ='Evolutitve SCI'!#REF!/(('Evolutive SFP'!#REF!+'Evolutive SFP'!#REF!)/2) -> #REF! | F9: ='Evolutitve SCI'!D33/(('Evolutive SFP'!#REF!+'Evolutive SFP'!D27)/2) -> #REF! | G9: ='Evolutitve SCI'!E33/(('Evolutive SFP'!D27+'Evolutive SFP'!E27)/2) -> 0.0083828259 | H9: ='Evolutitve SCI'!F33/(('Evolutive SFP'!E27+'Evolutive SFP'!F27)/2) -> 0.0081671188 | I9: ='Evolutitve SCI'!G33/(('Evolutive SFP'!F27+'Evolutive SFP'!G27)/2) -> 0.012766136 | J9: ='Evolutitve SCI'!H33/(('Evolutive SFP'!G27+'Evolutive SFP'!H27)/2) -> 0.016916817 | K9: ='Evolutitve SCI'!I33/(('Evolutive SFP'!H27+'Evolutive SFP'!I27)/2) -> 0.02377236 | L9: ='Evolutitve SCI'!J33/(('Evolutive SFP'!I27+'Evolutive SFP'!J27)/2) -> 0.02383125 | M9: ='Evolutitve SCI'!K33/(('Evolutive SFP'!J27+'Evolutive SFP'!K27)/2) -> 0.026665663 | N9: ='Evolutitve SCI'!L33/(('Evolutive SFP'!K27+'Evolutive SFP'!L27)/2) -> 0.01695541 | ... R9: ='Evolutitve SCI'!P33/(('Evolutive SFP'!O27+'Evolutive SFP'!P27)/2) -> 0.066558269
B10: Cost Income ratio | D10: ='Evolutitve SCI'!#REF!/'Evolutitve SCI'!#REF! -> #REF! | E10: ='Evolutitve SCI'!#REF!/'Evolutitve SCI'!#REF! -> #REF! | F10: ='Evolutitve SCI'!D23/'Evolutitve SCI'!D19 -> 0.36097388 | G10: ='Evolutitve SCI'!E23/'Evolutitve SCI'!E19 -> 0.4452552 | H10: ='Evolutitve SCI'!F23/'Evolutitve SCI'!F19 -> 0.43900094 | I10: ='Evolutitve SCI'!G23/'Evolutitve SCI'!G19 -> 0.42883713 | J10: ='Evolutitve SCI'!H23/'Evolutitve SCI'!H19 -> 0.37352548 | K10: ='Evolutitve SCI'!I23/'Evolutitve SCI'!I19 -> 0.34710157 | L10: ='Evolutitve SCI'!J23/'Evolutitve SCI'!J19 -> 0.3760795 | M10: ='Evolutitve SCI'!K23/'Evolutitve SCI'!K19 -> 0.36180482 | ... R10: ='Evolutitve SCI'!P23/'Evolutitve SCI'!P19 -> 0.44960729
B11: Operating Expense ratio | D11: =('Evolutitve SCI'!#REF!+'Evolutitve SCI'!#REF!)/(('Evolutive SFP'!#REF!+'Evolutive SFP'!#REF!)/2) -> #REF! | E11: =('Evolutitve SCI'!#REF!+'Evolutitve SCI'!#REF!)/(('Evolutive SFP'!#REF!+'Evolutive SFP'!#REF!)/2) -> #REF! | F11: =('Evolutitve SCI'!D23+'Evolutitve SCI'!D12)/(('Evolutive SFP'!D27+'Evolutive SFP'!#REF!)/2) -> #REF! | G11: =('Evolutitve SCI'!E23+'Evolutitve SCI'!E12)/(('Evolutive SFP'!E27+'Evolutive SFP'!#REF!)/2) -> #REF! | H11: =('Evolutitve SCI'!F23+'Evolutitve SCI'!F12)/(('Evolutive SFP'!F27+'Evolutive SFP'!#REF!)/2) -> #REF! | I11: =('Evolutitve SCI'!G23+'Evolutitve SCI'!G12)/(('Evolutive SFP'!G27+'Evolutive SFP'!#REF!)/2) -> #REF! | J11: =('Evolutitve SCI'!H23+'Evolutitve SCI'!H12)/(('Evolutive SFP'!H27+'Evolutive SFP'!#REF!)/2) -> #REF! | K11: =('Evolutitve SCI'!I23+'Evolutitve SCI'!I12)/(('Evolutive SFP'!I27+'Evolutive SFP'!#REF!)/2) -> #REF! | L11: =('Evolutitve SCI'!J23+'Evolutitve SCI'!J12)/(('Evolutive SFP'!J27+'Evolutive SFP'!#REF!)/2) -> #REF! | M11: =('Evolutitve SCI'!K23+'Evolutitve SCI'!K12)/(('Evolutive SFP'!K27+'Evolutive SFP'!#REF!)/2) -> #REF! | ... R11: =('Evolutitve SCI'!P23+'Evolutitve SCI'!P12)/(('Evolutive SFP'!P27+'Evolutive SFP'!#REF!)/2) -> #REF!
A12: LIQUIDITY | B12: MIN LIQ ratio | C12: Min 15% | D12: =('Evolutive SFP'!#REF!)/('Evolutive SFP'!#REF!+'Evolutive SFP'!#REF!+'Evolutive SFP'!#REF!+'Evolutive SFP'!#REF!+'Evolutive SFP'!#REF!+'Evolutive SFP'!#REF!+'Evolutive SFP'!#REF!) -> #REF! | E12: =('Evolutive SFP'!#REF!)/('Evolutive SFP'!#REF!+'Evolutive SFP'!#REF!+'Evolutive SFP'!#REF!+'Evolutive SFP'!#REF!+'Evolutive SFP'!#REF!+'Evolutive SFP'!#REF!+'Evolutive SFP'!#REF!) -> #REF! | F12: =('Evolutive SFP'!D4)/('Evolutive SFP'!D28+'Evolutive SFP'!D29+'Evolutive SFP'!D32+'Evolutive SFP'!D33+'Evolutive SFP'!D34+'Evolutive SFP'!D35+'Evolutive SFP'!D36) -> 0.31603236 | G12: =('Evolutive SFP'!E4)/('Evolutive SFP'!E28+'Evolutive SFP'!E29+'Evolutive SFP'!E32+'Evolutive SFP'!E33+'Evolutive SFP'!E34+'Evolutive SFP'!E35+'Evolutive SFP'!E36) -> 0.26863882 | H12: =('Evolutive SFP'!F4)/('Evolutive SFP'!F28+'Evolutive SFP'!F29+'Evolutive SFP'!F32+'Evolutive SFP'!F33+'Evolutive SFP'!F34+'Evolutive SFP'!F35+'Evolutive SFP'!F36) -> 0.29020823 | I12: =('Evolutive SFP'!G4)/('Evolutive SFP'!G28+'Evolutive SFP'!G29+'Evolutive SFP'!G32+'Evolutive SFP'!G33+'Evolutive SFP'!G34+'Evolutive SFP'!G35+'Evolutive SFP'!G36) -> 0.27461354 | J12: =('Evolutive SFP'!H4)/('Evolutive SFP'!H28+'Evolutive SFP'!H29+'Evolutive SFP'!H32+'Evolutive SFP'!H33+'Evolutive SFP'!H34+'Evolutive SFP'!H35+'Evolutive SFP'!H36) -> 0.27330558 | K12: =('Evolutive SFP'!I4)/('Evolutive SFP'!I28+'Evolutive SFP'!I29+'Evolutive SFP'!I32+'Evolutive SFP'!I33+'Evolutive SFP'!I34+'Evolutive SFP'!I35+'Evolutive SFP'!I36) -> 0.41114012 | L12: =('Evolutive SFP'!J4)/('Evolutive SFP'!J28+'Evolutive SFP'!J29+'Evolutive SFP'!J32+'Evolutive SFP'!J33+'Evolutive SFP'!J34+'Evolutive SFP'!J35+'Evolutive SFP'!J36) -> 0.22554376 | M12: =('Evolutive SFP'!K4)/('Evolutive SFP'!K28+'Evolutive SFP'!K29+'Evolutive SFP'!K32+'Evolutive SFP'!K33+'Evolutive SFP'!K34+'Evolutive SFP'!K35+'Evolutive SFP'!K36) -> 0.25884751 | ... R12: =('Evolutive SFP'!P4)/('Evolutive SFP'!P28+'Evolutive SFP'!P29+'Evolutive SFP'!P32+'Evolutive SFP'!P33+'Evolutive SFP'!P34+'Evolutive SFP'!P35+'Evolutive SFP'!P36) -> 0.21299567
B13: T/LIQ ratio | D13: ='Evolutive SFP'!#REF!/('Evolutive SFP'!#REF!+'Evolutive SFP'!#REF!) -> #REF! | E13: ='Evolutive SFP'!#REF!/('Evolutive SFP'!#REF!+'Evolutive SFP'!#REF!) -> #REF! | F13: ='Evolutive SFP'!D4/('Evolutive SFP'!D31+'Evolutive SFP'!D36) -> 0.12662135 | G13: ='Evolutive SFP'!E4/('Evolutive SFP'!E31+'Evolutive SFP'!E36) -> 0.085850922 | H13: ='Evolutive SFP'!F4/('Evolutive SFP'!F31+'Evolutive SFP'!F36) -> 0.095214507 | I13: ='Evolutive SFP'!G4/('Evolutive SFP'!G31+'Evolutive SFP'!G36) -> 0.089813919 | J13: ='Evolutive SFP'!H4/('Evolutive SFP'!H31+'Evolutive SFP'!H36) -> 0.090782075 | K13: ='Evolutive SFP'!I4/('Evolutive SFP'!I31+'Evolutive SFP'!I36) -> 0.13856201 | L13: ='Evolutive SFP'!J4/('Evolutive SFP'!J31+'Evolutive SFP'!J36) -> 0.077024547 | M13: ='Evolutive SFP'!K4/('Evolutive SFP'!K31+'Evolutive SFP'!K36) -> 0.088146096 | ... R13: ='Evolutive SFP'!P4/('Evolutive SFP'!P31+'Evolutive SFP'!P36) -> 0.078462636
B14: EB ratio | C14: Max 25% | D14: ='Evolutive SFP'!#REF!/'Evolutive SFP'!#REF! -> #REF! | E14: ='Evolutive SFP'!#REF!/'Evolutive SFP'!#REF! -> #REF! | F14: ='Evolutive SFP'!D37/'Evolutive SFP'!D27 -> 0 | G14: ='Evolutive SFP'!E37/'Evolutive SFP'!E27 -> 0 | H14: ='Evolutive SFP'!F37/'Evolutive SFP'!F27 -> 0 | I14: ='Evolutive SFP'!G37/'Evolutive SFP'!G27 -> 0 | J14: ='Evolutive SFP'!H37/'Evolutive SFP'!H27 -> 0 | K14: ='Evolutive SFP'!I37/'Evolutive SFP'!I27 -> 0 | L14: ='Evolutive SFP'!J37/'Evolutive SFP'!J27 -> 0 | M14: ='Evolutive SFP'!K37/'Evolutive SFP'!K27 -> 0 | ... R14: ='Evolutive SFP'!P37/'Evolutive SFP'!P27 -> 0
B15: LA to TA ratio | D15: ='Evolutive SFP'!#REF!/'Evolutive SFP'!#REF! -> #REF! | E15: ='Evolutive SFP'!#REF!/'Evolutive SFP'!#REF! -> #REF! | F15: ='Evolutive SFP'!D4/'Evolutive SFP'!D27 -> 0.086539851 | G15: ='Evolutive SFP'!E4/'Evolutive SFP'!E27 -> 0.058356527 | H15: ='Evolutive SFP'!F4/'Evolutive SFP'!F27 -> 0.061963793 | I15: ='Evolutive SFP'!G4/'Evolutive SFP'!G27 -> 0.058596355 | J15: ='Evolutive SFP'!H4/'Evolutive SFP'!H27 -> 0.05898396 | K15: ='Evolutive SFP'!I4/'Evolutive SFP'!I27 -> 0.087571758 | L15: ='Evolutive SFP'!J4/'Evolutive SFP'!J27 -> 0.050777125 | M15: ='Evolutive SFP'!K4/'Evolutive SFP'!K27 -> 0.055053686 | ... R15: ='Evolutive SFP'!P4/'Evolutive SFP'!P27 -> 0.047952042
A16: STRUCTURE | B16: NEA ratio | C16: Max 10% | D16: =('Evolutive SFP'!#REF!+'Evolutive SFP'!#REF!)/'Evolutive SFP'!#REF! -> #REF! | E16: =('Evolutive SFP'!#REF!+'Evolutive SFP'!#REF!)/'Evolutive SFP'!#REF! -> #REF! | F16: =('Evolutive SFP'!D7+'Evolutive SFP'!D21)/'Evolutive SFP'!D27 -> 0.021906942 | G16: =('Evolutive SFP'!E7+'Evolutive SFP'!E21)/'Evolutive SFP'!E27 -> 0.044334115 | H16: =('Evolutive SFP'!F7+'Evolutive SFP'!F21)/'Evolutive SFP'!F27 -> 0.062737018 | I16: =('Evolutive SFP'!G7+'Evolutive SFP'!G21)/'Evolutive SFP'!G27 -> 0.047051458 | J16: =('Evolutive SFP'!H7+'Evolutive SFP'!H21)/'Evolutive SFP'!H27 -> 0.04654956 | K16: =('Evolutive SFP'!I7+'Evolutive SFP'!I21)/'Evolutive SFP'!I27 -> 0.051394733 | L16: =('Evolutive SFP'!J7+'Evolutive SFP'!J21)/'Evolutive SFP'!J27 -> 0.03888704 | M16: =('Evolutive SFP'!K7+'Evolutive SFP'!K21)/'Evolutive SFP'!K27 -> 0.068862198 | ... R16: =('Evolutive SFP'!P7+'Evolutive SFP'!P21)/'Evolutive SFP'!P27 -> 0.067151622
B17: LB ratio | C17: Max 5% | D17: ='Evolutive SFP'!#REF!/'Evolutive SFP'!#REF! -> #REF! | E17: ='Evolutive SFP'!#REF!/'Evolutive SFP'!#REF! -> #REF! | F17: ='Evolutive SFP'!D21/'Evolutive SFP'!D27 -> 0.021906942 | G17: ='Evolutive SFP'!E21/'Evolutive SFP'!E27 -> 0.024918913 | H17: ='Evolutive SFP'!F21/'Evolutive SFP'!F27 -> 0.023843363 | I17: ='Evolutive SFP'!G21/'Evolutive SFP'!G27 -> 0.02484343 | J17: ='Evolutive SFP'!H21/'Evolutive SFP'!H27 -> 0.028290326 | K17: ='Evolutive SFP'!I21/'Evolutive SFP'!I27 -> 0.03155207 | L17: ='Evolutive SFP'!J21/'Evolutive SFP'!J27 -> 0.038391751 | M17: ='Evolutive SFP'!K21/'Evolutive SFP'!K27 -> 0.036421812 | ... R17: ='Evolutive SFP'!P21/'Evolutive SFP'!P27 -> 0.032892412
B18: PI to Deposit ratio | C18: Max 5% | D18: ='Evolutive SFP'!#REF!/'Evolutive SFP'!#REF! -> #REF! | E18: ='Evolutive SFP'!#REF!/'Evolutive SFP'!#REF! -> #REF! | F18: ='Evolutive SFP'!D41/'Evolutive SFP'!D31 -> 0.10939129 | G18: ='Evolutive SFP'!E41/'Evolutive SFP'!E31 -> 0.11048289 | H18: ='Evolutive SFP'!F41/'Evolutive SFP'!F31 -> 0.10948034 | I18: ='Evolutive SFP'!G41/'Evolutive SFP'!G31 -> 0.10938018 | J18: ='Evolutive SFP'!H41/'Evolutive SFP'!H31 -> 0.10823903 | K18: ='Evolutive SFP'!I41/'Evolutive SFP'!I31 -> 0.10609512 | L18: ='Evolutive SFP'!J41/'Evolutive SFP'!J31 -> 0.1057108 | M18: ='Evolutive SFP'!K41/'Evolutive SFP'!K31 -> 0.1047315 | ... R18: ='Evolutive SFP'!P41/'Evolutive SFP'!P31 -> 0.092177952
B19: PI to CC ratio | C19: Max 40% | D19: ='Evolutive SFP'!#REF!/(CAELS!D3*1000000) -> #REF! | E19: ='Evolutive SFP'!#REF!/(CAELS!E3*1000000) -> #REF! | F19: ='Evolutive SFP'!D41/(CAELS!F3*1000000) -> 0.22062857 | G19: ='Evolutive SFP'!E41/(CAELS!G3*1000000) -> 0.21804319 | H19: ='Evolutive SFP'!F41/(CAELS!H3*1000000) -> 0.21614042 | I19: ='Evolutive SFP'!G41/(CAELS!I3*1000000) -> 0.2111092 | J19: ='Evolutive SFP'!H41/(CAELS!J3*1000000) -> 0.206632 | K19: ='Evolutive SFP'!I41/(CAELS!K3*1000000) -> 0.20034188 | L19: ='Evolutive SFP'!J41/(CAELS!L3*1000000) -> 0.19765459 | M19: ='Evolutive SFP'!K41/(CAELS!M3*1000000) -> 0.1943562 | ... R19: ='Evolutive SFP'!P41/(CAELS!R3*1000000) -> 0.16934552
B20: Gross loans/TA | D20: ='Evolutive SFP'!#REF!/'Evolutive SFP'!#REF! -> #REF! | E20: ='Evolutive SFP'!#REF!/'Evolutive SFP'!#REF! -> #REF! | F20: ='Evolutive SFP'!D15/'Evolutive SFP'!D27 -> 0.99188072 | G20: ='Evolutive SFP'!E15/'Evolutive SFP'!E27 -> 0.99934111 | H20: ='Evolutive SFP'!F15/'Evolutive SFP'!F27 -> 0.97670346 | I20: ='Evolutive SFP'!G15/'Evolutive SFP'!G27 -> 0.99163572 | J20: ='Evolutive SFP'!H15/'Evolutive SFP'!H27 -> 0.99271035 | K20: ='Evolutive SFP'!I15/'Evolutive SFP'!I27 -> 0.95550041 | L20: ='Evolutive SFP'!J15/'Evolutive SFP'!J27 -> 1.0081975 | M20: ='Evolutive SFP'!K15/'Evolutive SFP'!K27 -> 0.97178234 | ... R20: ='Evolutive SFP'!P15/'Evolutive SFP'!P27 -> 0.99432171
A21: FUNDING MIX | B21: Total Deposits/Total Assets | D21: ='Evolutive SFP'!#REF!/'Evolutive SFP'!#REF! -> #REF! | E21: ='Evolutive SFP'!#REF!/'Evolutive SFP'!#REF! -> #REF! | F21: ='Evolutive SFP'!D31/'Evolutive SFP'!D27 -> 0.64967231 | G21: ='Evolutive SFP'!E31/'Evolutive SFP'!E27 -> 0.64224764 | H21: ='Evolutive SFP'!F31/'Evolutive SFP'!F27 -> 0.6136254 | I21: ='Evolutive SFP'!G31/'Evolutive SFP'!G27 -> 0.61506159 | J21: ='Evolutive SFP'!H31/'Evolutive SFP'!H27 -> 0.6152356 | K21: ='Evolutive SFP'!I31/'Evolutive SFP'!I27 -> 0.59832949 | L21: ='Evolutive SFP'!J31/'Evolutive SFP'!J27 -> 0.6234146 | M21: ='Evolutive SFP'!K31/'Evolutive SFP'!K27 -> 0.59512202 | ... R21: ='Evolutive SFP'!P31/'Evolutive SFP'!P27 -> 0.58981076
B22: BOSA Deposits/Total Assets | D22: ='Evolutive SFP'!#REF!/'Evolutive SFP'!#REF! -> #REF! | E22: ='Evolutive SFP'!#REF!/'Evolutive SFP'!#REF! -> #REF! | F22: ='Evolutive SFP'!D30/'Evolutive SFP'!D27 -> 0.48241743 | G22: ='Evolutive SFP'!E30/'Evolutive SFP'!E27 -> 0.47900691 | H22: ='Evolutive SFP'!F30/'Evolutive SFP'!F27 -> 0.45895179 | I22: ='Evolutive SFP'!G30/'Evolutive SFP'!G27 -> 0.46418444 | J22: ='Evolutive SFP'!H30/'Evolutive SFP'!H27 -> 0.46446365 | K22: ='Evolutive SFP'!I30/'Evolutive SFP'!I27 -> 0.44849254 | L22: ='Evolutive SFP'!J30/'Evolutive SFP'!J27 -> 0.47288056 | M22: ='Evolutive SFP'!K30/'Evolutive SFP'!K27 -> 0.45201921 | ... R22: ='Evolutive SFP'!P30/'Evolutive SFP'!P27 -> 0.45167545
B23: FOSA Deposits/Total Assets | D23: =('Evolutive SFP'!#REF!+'Evolutive SFP'!#REF!)/'Evolutive SFP'!#REF! -> #REF! | E23: =('Evolutive SFP'!#REF!+'Evolutive SFP'!#REF!)/'Evolutive SFP'!#REF! -> #REF! | F23: =('Evolutive SFP'!D28+'Evolutive SFP'!D29)/'Evolutive SFP'!D27 -> 0.16725488 | G23: =('Evolutive SFP'!E28+'Evolutive SFP'!E29)/'Evolutive SFP'!E27 -> 0.16324073 | H23: =('Evolutive SFP'!F28+'Evolutive SFP'!F29)/'Evolutive SFP'!F27 -> 0.15467361 | I23: =('Evolutive SFP'!G28+'Evolutive SFP'!G29)/'Evolutive SFP'!G27 -> 0.15087715 | J23: =('Evolutive SFP'!H28+'Evolutive SFP'!H29)/'Evolutive SFP'!H27 -> 0.15077195 | K23: =('Evolutive SFP'!I28+'Evolutive SFP'!I29)/'Evolutive SFP'!I27 -> 0.14983694 | L23: =('Evolutive SFP'!J28+'Evolutive SFP'!J29)/'Evolutive SFP'!J27 -> 0.15053404 | M23: =('Evolutive SFP'!K28+'Evolutive SFP'!K29)/'Evolutive SFP'!K27 -> 0.14310281 | ... R23: =('Evolutive SFP'!P28+'Evolutive SFP'!P29)/'Evolutive SFP'!P27 -> 0.13813531
A24: GROWTH RATIOS | B24: Total Assets | D24: =(Financials!#REF!-Financials!#REF!)/Financials!#REF! -> #REF! | E24: =(Financials!#REF!-Financials!#REF!)/Financials!#REF! -> #REF! | F24: =(Financials!C4-Financials!#REF!)/Financials!#REF! -> #REF! | G24: =(Financials!D4-Financials!C4)/Financials!C4 -> 0.0015659876 | H24: =(Financials!E4-Financials!D4)/Financials!D4 -> 0.056228935 | I24: =(Financials!F4-Financials!E4)/Financials!E4 -> -0.0014214703 | J24: =(Financials!G4-Financials!F4)/Financials!F4 -> 0.010257075 | K24: =(Financials!H4-Financials!G4)/Financials!G4 -> 0.049033893 | L24: =(Financials!I4-Financials!H4)/Financials!H4 -> -0.036748913 | M24: =(Financials!J4-Financials!I4)/Financials!I4 -> 0.057335838 | N24: =(Financials!K4-Financials!J4)/Financials!J4 -> 0.0042695644 | ... R24: =(Financials!O4-Financials!N4)/Financials!N4 -> -0.010684431
B25: Total Deposits | C25: =IF(CAELS!#REF!<6%,"1",_xludf.IF) -> #REF! | D25: =Financials!#REF!/Financials!#REF!-1 -> #REF! | E25: =Financials!#REF!/Financials!#REF!-1 -> #REF! | F25: =Financials!D5/Financials!C5-1 -> -0.0098802399 | G25: =Financials!E5/Financials!D5-1 -> 0.0091573211 | H25: =Financials!F5/Financials!E5-1 -> 0.00091569684 | I25: =Financials!G5/Financials!F5-1 -> 0.0105429 | J25: =Financials!H5/Financials!G5-1 -> 0.020207399 | K25: =Financials!I5/Financials!H5-1 -> 0.003635618 | L25: =Financials!J5/Financials!I5-1 -> 0.0093505144 | M25: =Financials!K5/Financials!J5-1 -> 0.00059935532 | ... R25: =Financials!P5/Financials!O5-1 -> -1
B26: BOSA Deposits | D26: =Financials!#REF!/Financials!#REF!-1 -> #REF! | E26: =Financials!#REF!/Financials!#REF!-1 -> #REF! | F26: =Financials!D6/Financials!C6-1 -> -0.005514724 | G26: =Financials!E6/Financials!D6-1 -> 0.012006611 | H26: =Financials!F6/Financials!E6-1 -> 0.0099636322 | I26: =Financials!G6/Financials!F6-1 -> 0.010864751 | J26: =Financials!H6/Financials!G6-1 -> 0.012961684 | K26: =Financials!I6/Financials!H6-1 -> 0.015630513 | L26: =Financials!J6/Financials!I6-1 -> 0.010690973 | M26: =Financials!K6/Financials!J6-1 -> 0.010372039 | ... R26: =Financials!P6/Financials!O6-1 -> -1
B27: FOSA Deposits | D27: =Financials!#REF!/Financials!#REF!-1 -> #REF! | E27: =Financials!#REF!/Financials!#REF!-1 -> #REF! | F27: =Financials!D7/Financials!C7-1 -> -0.022471806 | G27: =Financials!E7/Financials!D7-1 -> 0.00079648022 | H27: =Financials!F7/Financials!E7-1 -> -0.025931585 | I27: =Financials!G7/Financials!F7-1 -> 0.0095527014 | J27: =Financials!H7/Financials!G7-1 -> 0.042528333 | K27: =Financials!I7/Financials!H7-1 -> -0.032267551 | L27: =Financials!J7/Financials!I7-1 -> 0.0051396598 | M27: =Financials!K7/Financials!J7-1 -> -0.030269644 | ... R27: =Financials!P7/Financials!O7-1 -> -1
B28: Total Loans & advances | D28: =Financials!#REF!/Financials!#REF!-1 -> #REF! | E28: =Financials!#REF!/Financials!#REF!-1 -> #REF! | F28: =Financials!D31/Financials!C31-1 -> 0.0090992245 | G28: =Financials!E31/Financials!D31-1 -> 0.032302631 | H28: =Financials!F31/Financials!E31-1 -> 0.013845218 | I28: =Financials!G31/Financials!F31-1 -> 0.011351887 | J28: =Financials!H31/Financials!G31-1 -> 0.0097127646 | K28: =Financials!I31/Financials!H31-1 -> 0.01637563 | L28: =Financials!J31/Financials!I31-1 -> 0.019145852 | M28: =Financials!K31/Financials!J31-1 -> 0.023031344 | ... R28: =Financials!P31/Financials!O31-1 -> -1
B29: Core capital | D29: =Financials!#REF!/Financials!#REF!-1 -> #REF! | E29: =Financials!#REF!/Financials!#REF!-1 -> #REF! | F29: =Financials!D11/Financials!C11-1 -> #DIV/0! | G29: =Financials!E11/Financials!D11-1 -> 0.0089024927 | H29: =Financials!F11/Financials!E11-1 -> 0.024429355 | I29: =Financials!G11/Financials!F11-1 -> 0.021736366 | J29: =Financials!H11/Financials!G11-1 -> 0.032196495 | K29: =Financials!I11/Financials!H11-1 -> 0.013848601 | L29: =Financials!J11/Financials!I11-1 -> 0.01729193 | M29: =Financials!K11/Financials!J11-1 -> -0.013281302 | ... R29: =Financials!P11/Financials!O11-1 -> -1
B30: Turnover | D30: =Financials!#REF!/Financials!#REF!-1 -> #REF! | E30: =Financials!#REF!/Financials!#REF!-1 -> #REF! | F30: =Financials!D37/Financials!C37-1 -> 1.0928383 | G30: =Financials!E37/Financials!D37-1 -> 0.49835442 | H30: =Financials!F37/Financials!E37-1 -> 0.32717058 | I30: =Financials!G37/Financials!F37-1 -> 0.21013635 | J30: =Financials!H37/Financials!G37-1 -> 0.21870467 | K30: =Financials!I37/Financials!H37-1 -> 0.13999875 | L30: =Financials!J37/Financials!I37-1 -> 0.13343863 | M30: =Financials!K37/Financials!J37-1 -> 0.15578918 | ... R30: =Financials!P37/Financials!O37-1 -> -1
B31: Membership
B32: Expenses | D32: ='Evolutitve SCI'!F39/'Evolutitve SCI'!#REF!-1 -> #REF! | E32: ='Evolutitve SCI'!G39/'Evolutitve SCI'!D39-1 -> #REF! | F32: ='Evolutitve SCI'!Q39/'Evolutitve SCI'!P39-1 -> #DIV/0! | G32: ='Evolutitve SCI'!R39/'Evolutitve SCI'!Q39-1 -> #DIV/0! | H32: ='Evolutitve SCI'!S39/'Evolutitve SCI'!R39-1 -> #DIV/0! | I32: ='Evolutitve SCI'!T39/'Evolutitve SCI'!S39-1 -> #DIV/0! | J32: ='Evolutitve SCI'!U39/'Evolutitve SCI'!T39-1 -> #DIV/0! | K32: ='Evolutitve SCI'!V39/'Evolutitve SCI'!U39-1 -> #DIV/0! | L32: ='Evolutitve SCI'!W39/'Evolutitve SCI'!V39-1 -> #DIV/0! | M32: ='Evolutitve SCI'!X39/'Evolutitve SCI'!W39-1 -> #DIV/0! | ... R32: ='Evolutitve SCI'!AC39/'Evolutitve SCI'!AB39-1 -> #DIV/0!
A33: Efficiency Ratios | B33: FinCost-Deposits/Avg Deposits | F33: =Financials!C44/('Evolutive SFP'!#REF!+'Evolutive SFP'!D30)/2 -> #REF! | G33: =Financials!D44/('Evolutive SFP'!D30+'Evolutive SFP'!E30)/2 -> 0.0040347807 | H33: =Financials!E44/('Evolutive SFP'!E30+'Evolutive SFP'!F30)/2 -> 0.0072442928 | I33: =Financials!F44/('Evolutive SFP'!F30+'Evolutive SFP'!G30)/2 -> 0.010338753 | J33: =Financials!G44/('Evolutive SFP'!G30+'Evolutive SFP'!H30)/2 -> 0.013290032 | K33: =Financials!H44/('Evolutive SFP'!H30+'Evolutive SFP'!I30)/2 -> 0.015029512 | L33: =Financials!I44/('Evolutive SFP'!I30+'Evolutive SFP'!J30)/2 -> 0.019185824 | M33: =Financials!J44/('Evolutive SFP'!J30+'Evolutive SFP'!K30)/2 -> 0.020775109 | N33: =Financials!K44/('Evolutive SFP'!K30+'Evolutive SFP'!L30)/2 -> 0.030011375 | ... R33: =Financials!O44/('Evolutive SFP'!O30+'Evolutive SFP'!P30)/2 -> 0.030028774
B34: FinCost-Shares/Avg Share capital | F34: =Financials!C45/('Evolutive SFP'!#REF!+'Evolutive SFP'!D39)/2 -> #REF! | G34: =Financials!D45/('Evolutive SFP'!D39+'Evolutive SFP'!E39)/2 -> 0 | H34: =Financials!E45/('Evolutive SFP'!E39+'Evolutive SFP'!F39)/2 -> 0 | I34: =Financials!F45/('Evolutive SFP'!F39+'Evolutive SFP'!G39)/2 -> 0 | J34: =Financials!G45/('Evolutive SFP'!G39+'Evolutive SFP'!H39)/2 -> 0 | K34: =Financials!H45/('Evolutive SFP'!H39+'Evolutive SFP'!I39)/2 -> 0 | L34: =Financials!I45/('Evolutive SFP'!I39+'Evolutive SFP'!J39)/2 -> 0 | M34: =Financials!J45/('Evolutive SFP'!J39+'Evolutive SFP'!K39)/2 -> 0 | N34: =Financials!K45/('Evolutive SFP'!K39+'Evolutive SFP'!L39)/2 -> 0 | ... R34: =Financials!O45/('Evolutive SFP'!O39+'Evolutive SFP'!P39)/2 -> 0
B35: FinCost-Ext Loans/Avg Ext Loans | F35: =Financials!C46/(Financials!#REF!+Financials!C31)/2 -> #REF! | G35: =Financials!D46/(Financials!C31+Financials!D31)/2 -> 5.8701932e-06 | H35: =Financials!E46/(Financials!D31+Financials!E31)/2 -> 5.7508432e-06 | I35: =Financials!F46/(Financials!E31+Financials!F31)/2 -> 5.6219475e-06 | J35: =Financials!G46/(Financials!F31+Financials!G31)/2 -> 5.5520473e-06 | K35: =Financials!H46/(Financials!G31+Financials!H31)/2 -> 5.4942059e-06 | L35: =Financials!I46/(Financials!H31+Financials!I31)/2 -> 5.4233751e-06 | M35: =Financials!J46/(Financials!I31+Financials!J31)/2 -> 5.3286739e-06 | N35: =Financials!K46/(Financials!J31+Financials!K31)/2 -> 5.2185264e-06 | ... R35: =Financials!O46/(Financials!N31+Financials!O31)/2 -> 0
B36: OpEx/Average Total Assets | F36: =Financials!C47/(Financials!#REF!+Financials!C4)/2 -> #REF! | G36: =Financials!D47/(Financials!C4+Financials!D4)/2 -> 0.002524223 | H36: =Financials!E47/(Financials!D4+Financials!E4)/2 -> 0.0033756679 | I36: =Financials!F47/(Financials!E4+Financials!F4)/2 -> 0.004057862 | J36: =Financials!G47/(Financials!F4+Financials!G4)/2 -> 0.0040847228 | K36: =Financials!H47/(Financials!G4+Financials!H4)/2 -> 0.0046610364 | L36: =Financials!I47/(Financials!H4+Financials!I4)/2 -> 0.0052849284 | M36: =Financials!J47/(Financials!I4+Financials!J4)/2 -> 0.0058241365 | N36: =Financials!K47/(Financials!J4+Financials!K4)/2 -> 0.006310201 | ... R36: =Financials!O47/(Financials!N4+Financials!O4)/2 -> 0.013592605
B37: Opex/Turnover | F37: =Financials!C47/Financials!C37 -> 0.3163282 | G37: =Financials!D47/Financials!D37 -> 0.30113284 | H37: =Financials!E47/Financials!E37 -> 0.27653919 | I37: =Financials!F47/Financials!F37 -> 0.25714335 | J37: =Financials!G47/Financials!G37 -> 0.21484187 | K37: =Financials!H47/Financials!H37 -> 0.20714278 | L37: =Financials!I47/Financials!I37 -> 0.20708005 | M37: =Financials!J47/Financials!J37 -> 0.20323642 | ... R37: =Financials!O47/Financials!O37 -> 0.30753192
B38: Avge yield on Net loans | F38: =Financials!C38/('Evolutive SFP'!D14+'Evolutive SFP'!#REF!)/2 -> #REF! | G38: =Financials!D38/('Evolutive SFP'!E14+'Evolutive SFP'!D14)/2 -> 0.0092762629 | H38: =Financials!E38/('Evolutive SFP'!F14+'Evolutive SFP'!E14)/2 -> 0.013545553 | I38: =Financials!F38/('Evolutive SFP'!G14+'Evolutive SFP'!F14)/2 -> 0.017569228 | J38: =Financials!G38/('Evolutive SFP'!H14+'Evolutive SFP'!G14)/2 -> 0.020945678 | K38: =Financials!H38/('Evolutive SFP'!I14+'Evolutive SFP'!H14)/2 -> 0.025299959 | L38: =Financials!I38/('Evolutive SFP'!J14+'Evolutive SFP'!I14)/2 -> 0.028437503 | M38: =Financials!J38/('Evolutive SFP'!K14+'Evolutive SFP'!J14)/2 -> 0.031636596 | N38: =Financials!K38/('Evolutive SFP'!L14+'Evolutive SFP'!K14)/2 -> 0.035864582 | ... R38: =Financials!O38/('Evolutive SFP'!P14+'Evolutive SFP'!O14)/2 -> 0.046288203
B39: Avge yield on Gross loans | F39: =Financials!C37/('Evolutive SFP'!D15+'Evolutive SFP'!#REF!)/2 -> #REF! | G39: =Financials!D37/('Evolutive SFP'!E15+'Evolutive SFP'!D15)/2 -> 0.0084193523 | H39: =Financials!E37/('Evolutive SFP'!F15+'Evolutive SFP'!E15)/2 -> 0.012358688 | I39: =Financials!F37/('Evolutive SFP'!G15+'Evolutive SFP'!F15)/2 -> 0.016034461 | J39: =Financials!G37/('Evolutive SFP'!H15+'Evolutive SFP'!G15)/2 -> 0.019162627 | K39: =Financials!H37/('Evolutive SFP'!I15+'Evolutive SFP'!H15)/2 -> 0.023110285 | L39: =Financials!I37/('Evolutive SFP'!J15+'Evolutive SFP'!I15)/2 -> 0.026006049 | M39: =Financials!J37/('Evolutive SFP'!K15+'Evolutive SFP'!J15)/2 -> 0.028961557 | N39: =Financials!K37/('Evolutive SFP'!L15+'Evolutive SFP'!K15)/2 -> 0.032781533 | ... R39: =Financials!O37/('Evolutive SFP'!P15+'Evolutive SFP'!O15)/2 -> 0.044691448
A41: ALL/Average Gross Loan portfolio

Sheet Financials
B1: Washa Sacco Financial Performance
B2: Year | C2: 44562 | D2: 44593 | E2: 44621 | F2: 44652 | G2: 44682 | H2: 44713 | I2: 44743 | J2: 44774 | K2: 44805 | L2: 44835 | M2: 44866 | N2: 44896 | O2: audited 2022
A3: 1 | B3: Membership
A4: 2 | B4: Total Assets | C4: ='Evolutive SFP'!D27 -> 8.213397e+09 | D4: ='Evolutive SFP'!E27 -> 8.2262591e+09 | E4: ='Evolutive SFP'!F27 -> 8.6888129e+09 | F4: ='Evolutive SFP'!G27 -> 8.676462e+09 | G4: ='Evolutive SFP'!H27 -> 8.7654571e+09 | H4: ='Evolutive SFP'!I27 -> 9.1952616e+09 | I4: ='Evolutive SFP'!J27 -> 8.8573457e+09 | J4: ='Evolutive SFP'!K27 -> 9.3651891e+09 | ... O4: ='Evolutive SFP'!P27 -> 9790508652
A5: 3 | B5: Total Deposits | C5: ='Evolutive SFP'!D31 -> 5.3360166e+09 | D5: ='Evolutive SFP'!E31 -> 5.2832955e+09 | E5: ='Evolutive SFP'!F31 -> 5.3316763e+09 | F5: ='Evolutive SFP'!G31 -> 5.3365585e+09 | G5: ='Evolutive SFP'!H31 -> 5.3928213e+09 | H5: ='Evolutive SFP'!I31 -> 5.5017962e+09 | I5: ='Evolutive SFP'!J31 -> 5.5217986e+09 | J5: ='Evolutive SFP'!K31 -> 5.5734303e+09 | ... O5: ='Evolutive SFP'!P31 -> 5774547349
A6: 3.1 | B6: Deposits-Members(BOSA) | C6: ='Evolutive SFP'!D30 -> 3.9622858e+09 | D6: ='Evolutive SFP'!E30 -> 3.9404349e+09 | E6: ='Evolutive SFP'!F30 -> 3.9877462e+09 | F6: ='Evolutive SFP'!G30 -> 4.0274786e+09 | G6: ='Evolutive SFP'!H30 -> 4.0712362e+09 | H6: ='Evolutive SFP'!I30 -> 4.1240063e+09 | I6: ='Evolutive SFP'!J30 -> 4.1884666e+09 | J6: ='Evolutive SFP'!K30 -> 4.2332454e+09 | ... O6: ='Evolutive SFP'!P30 -> 4422132439
A7: 3.2 | B7: Deposits-Customers(FOSA) | C7: =('Evolutive SFP'!D28+'Evolutive SFP'!D29) -> 1.3737307e+09 | D7: =('Evolutive SFP'!E28+'Evolutive SFP'!E29) -> 1.3428605e+09 | E7: =('Evolutive SFP'!F28+'Evolutive SFP'!F29) -> 1343930085 | F7: =('Evolutive SFP'!G28+'Evolutive SFP'!G29) -> 1.3090798e+09 | G7: =('Evolutive SFP'!H28+'Evolutive SFP'!H29) -> 1.3215851e+09 | H7: =('Evolutive SFP'!I28+'Evolutive SFP'!I29) -> 1.3777899e+09 | I7: =('Evolutive SFP'!J28+'Evolutive SFP'!J29) -> 1.333332e+09 | J7: =('Evolutive SFP'!K28+'Evolutive SFP'!K29) -> 1.3401849e+09 | ... O7: =('Evolutive SFP'!P28+'Evolutive SFP'!P29) -> 1352414910
A8: 4 | B8: External Borrowing | C8: ='Evolutive SFP'!D37 -> 0 | D8: ='Evolutive SFP'!E37 -> 0 | E8: ='Evolutive SFP'!F37 -> 0 | F8: ='Evolutive SFP'!G37 -> 0 | G8: ='Evolutive SFP'!H37 -> 0 | H8: ='Evolutive SFP'!I37 -> 0 | I8: ='Evolutive SFP'!J37 -> 0 | J8: ='Evolutive SFP'!K37 -> 0 | ... O8: ='Evolutive SFP'!P37 -> 0
A10: 5 | B10: Share capital and Reserves
A11: 5.1 | B11: Core Capital | D11: =D14-D22-D25 -> 2.5910873e+09 | E11: =E14-E22-E25 -> 2.6141544e+09 | F11: =F14-F22-F25 -> 2.6780165e+09 | G11: =G14-G22-G25 -> 2.7362269e+09 | H11: =H14-H22-H25 -> 2.8243238e+09 | I11: =I14-I22-I25 -> 2.8634367e+09 | J11: =J14-J22-J25 -> 2.912951e+09 | K11: =K14-K22-K25 -> 2.8742633e+09 | ... O11: =O14-O22-O25 -> 3050826421
A12: 5.2 | B12: Institutional Capital | D12: =D11-D15 -> 2.3009943e+09 | E12: =E11-E15 -> 2.3228941e+09 | F12: =F11-F15 -> 2.3851057e+09 | G12: =G11-G15 -> 2.4417094e+09 | H12: =H11-H15 -> 2.5290395e+09 | I12: =I11-I15 -> 2.5506173e+09 | J12: =J11-J15 -> 2.5992668e+09 | K12: =K11-K15 -> 2.5590378e+09 | ... O12: =O11-O15 -> 2731525614
A14: 5.3 | B14: Total Capital | C14: =C15+C16+C17+C18+C19+C20+C21 -> 8.0475996e+08 | D14: =D15+D16+D17+D18+D19+D20+D21 -> 2.6770556e+09 | E14: =E15+E16+E17+E18+E19+E20+E21 -> 2.7006227e+09 | F14: =F15+F16+F17+F18+F19+F20+F21 -> 2.7649848e+09 | G14: =G15+G16+G17+G18+G19+G20+G21 -> 2.8248952e+09 | H14: =H15+H16+H17+H18+H19+H20+H21 -> 2.9135881e+09 | I14: =I15+I16+I17+I18+I19+I20+I21 -> 2.953201e+09 | J14: =J15+J16+J17+J18+J19+J20+J21 -> 3.0033193e+09 | ... O14: =O15+O16+O17+O18+O19+O20+O21 -> 3143194717
A15: 5.3.1 | B15: Members Share Capital | C15: ='Evolutive SFP'!D39 -> 2.8802315e+08 | D15: ='Evolutive SFP'!E39 -> 2.9009301e+08 | E15: ='Evolutive SFP'!F39 -> 2.9126031e+08 | F15: ='Evolutive SFP'!G39 -> 2.9291085e+08 | G15: ='Evolutive SFP'!H39 -> 2.9451747e+08 | H15: ='Evolutive SFP'!I39 -> 2.9528422e+08 | I15: ='Evolutive SFP'!J39 -> 3.1281936e+08 | J15: ='Evolutive SFP'!K39 -> 3.1368427e+08 | ... O15: ='Evolutive SFP'!P39 -> 319300807
A16: 5.3.2 | B16: Entrance Fees
A17: 5.3.3 | B17: Retained Earnings | C17: ='Evolutive SFP'!D41 -> 5.8371373e+08 | D17: ='Evolutive SFP'!E41 -> 5.8371373e+08 | E17: ='Evolutive SFP'!F41 -> 5.8371373e+08 | F17: ='Evolutive SFP'!G41 -> 5.8371373e+08 | G17: ='Evolutive SFP'!H41 -> 5.8371373e+08 | H17: ='Evolutive SFP'!I41 -> 5.8371373e+08 | I17: ='Evolutive SFP'!J41 -> 5.8371373e+08 | J17: ='Evolutive SFP'!K41 -> 5.8371373e+08 | ... O17: ='Evolutive SFP'!P41 -> 532285947
A18: 5.3.4 | B18: Appropriation Account | C18: ='Evolutive SFP'!D42 -> 69314543 | D18: ='Evolutive SFP'!E42 -> 88615150 | E18: ='Evolutive SFP'!F42 -> 98514978 | F18: ='Evolutive SFP'!G42 -> 1.4872655e+08 | G18: ='Evolutive SFP'!H42 -> 1.9453028e+08 | H18: ='Evolutive SFP'!I42 -> 2.6995644e+08 | I18: ='Evolutive SFP'!J42 -> 2.7944339e+08 | J18: ='Evolutive SFP'!K42 -> 3.1628764e+08 | ... O18: ='Evolutive SFP'!P42 -> 253848042
A19: 5.3.5 | B19: Statutory Reserves | C19: ='Evolutive SFP'!D43 -> 3.4766093e+08 | D19: ='Evolutive SFP'!E43 -> 3.4766093e+08 | E19: ='Evolutive SFP'!F43 -> 3.4766093e+08 | F19: ='Evolutive SFP'!G43 -> 3.4766093e+08 | G19: ='Evolutive SFP'!H43 -> 3.4766093e+08 | H19: ='Evolutive SFP'!I43 -> 3.4766093e+08 | I19: ='Evolutive SFP'!J43 -> 3.4766093e+08 | J19: ='Evolutive SFP'!K43 -> 3.4766093e+08 | ... O19: ='Evolutive SFP'!P43 -> 480787154
A20: 5.3.6 | B20: Capital Reserves | D20: =('Evolutive SFP'!E44) -> 1366972767 | E20: =('Evolutive SFP'!F44) -> 1379472767 | F20: =('Evolutive SFP'!G44) -> 1391972767 | G20: =('Evolutive SFP'!H44) -> 1404472767 | H20: =('Evolutive SFP'!I44) -> 1416972767 | I20: =('Evolutive SFP'!J44) -> 1.4295636e+09 | J20: =('Evolutive SFP'!K44) -> 1441972767 | K20: =('Evolutive SFP'!L44) -> 1478972767 | ... O20: =('Evolutive SFP'!P44) -> 1556972767
A21: 5.3.7 | B21: Supplementary Capital & reserves | C21: =C22+C23 -> -4.839524e+08 | D21: =D22+D23 -> 0 | E21: =E22+E23 -> 0 | F21: =F22+F23 -> 0 | G21: =G22+G23 -> 0 | H21: =H22+H23 -> 0 | I21: =I22+I23 -> 0 | J21: =J22+J23 -> 0 | ... O21: =O22+O23 -> 0
A22: a | B22: Proposed Dividends | C22: ='Evolutive SFP'!D46 -> -4.839524e+08 | D22: ='Evolutive SFP'!E46 -> 0 | E22: ='Evolutive SFP'!F46 -> 0 | F22: ='Evolutive SFP'!G46 -> 0 | G22: ='Evolutive SFP'!H46 -> 0 | H22: ='Evolutive SFP'!I46 -> 0 | I22: ='Evolutive SFP'!J46 -> 0 | J22: ='Evolutive SFP'!K46 -> 0 | ... O22: ='Evolutive SFP'!P46 -> 0
A23: b | B23: Risk Mgt Fund
A25: 6 | B25: Investments | D25: =D26+D27+D28 -> 85968320 | E25: =E26+E27+E28 -> 86468321 | F25: =F26+F27+F28 -> 86968322 | G25: =G26+G27+G28 -> 88668323 | H25: =H26+H27+H28 -> 89264317 | I25: =I26+I27+I28 -> 89764318 | J25: =J26+J27+J28 -> 90368291 | K25: =K26+K27+K28 -> 90868292 | ... O25: =O26+O27+O28 -> 92368296
A26: 6.1 | B26: Shares in Kusco,CIC,Coop Bank | D26: ='Evolutive SFP'!E11 -> 85968318 | E26: ='Evolutive SFP'!F11 -> 86468318 | F26: ='Evolutive SFP'!G11 -> 86968318 | G26: ='Evolutive SFP'!H11 -> 88668318 | H26: ='Evolutive SFP'!I11 -> 89264311 | I26: ='Evolutive SFP'!J11 -> 89764311 | J26: ='Evolutive SFP'!K11 -> 90368283 | K26: ='Evolutive SFP'!L11 -> 90868283 | ... O26: ='Evolutive SFP'!P11 -> 92368283
A27: 6.2 | B27: Equity Investments (at cost) | C27: ='Evolutive SFP'!D13 -> 0 | D27: ='Evolutive SFP'!E13 -> 0 | E27: ='Evolutive SFP'!F13 -> 0 | F27: ='Evolutive SFP'!G13 -> 0 | G27: ='Evolutive SFP'!H13 -> 0 | H27: ='Evolutive SFP'!I13 -> 0 | I27: ='Evolutive SFP'!J13 -> 0 | J27: ='Evolutive SFP'!K13 -> 0 | ... O27: ='Evolutive SFP'!P13 -> 0
A28: 6.3 | B28: Deposits in KUSCCO CFP | D28: 2 | E28: 3 | F28: 4 | G28: 5 | H28: 6 | I28: 7 | J28: 8 | K28: 9 | L28: 10 | M28: 11 | N28: 12 | O28: 13
A30: 7 | B30: Net Loans & Advances | C30: ='Evolutive SFP'!D14 -> 7.2408237e+09 | D30: ='Evolutive SFP'!E14 -> 7.2954544e+09 | E30: ='Evolutive SFP'!F14 -> 7.518766e+09 | F30: ='Evolutive SFP'!G14 -> 7.6727679e+09 | G30: ='Evolutive SFP'!H14 -> 7.7516627e+09 | H30: ='Evolutive SFP'!I14 -> 7.8280875e+09 | I30: ='Evolutive SFP'!J14 -> 7.9733184e+09 | J30: ='Evolutive SFP'!K14 -> 8.1142486e+09 | ... O30: ='Evolutive SFP'!P14 -> 8571140428
A31: 7.1 | B31: Gross Loans & advances | C31: ='Evolutive SFP'!D15 -> 8.1467102e+09 | D31: ='Evolutive SFP'!E15 -> 8.2208389e+09 | E31: ='Evolutive SFP'!F15 -> 8.4863937e+09 | F31: ='Evolutive SFP'!G15 -> 8.6038896e+09 | G31: ='Evolutive SFP'!H15 -> 8.70156e+09 | H31: ='Evolutive SFP'!I15 -> 8.7860762e+09 | I31: ='Evolutive SFP'!J15 -> 8.9299537e+09 | J31: ='Evolutive SFP'!K15 -> 9.1009253e+09 | ... O31: ='Evolutive SFP'!P15 -> 9734915300
A32: 7.2 | B32: Allowance for loan losses | C32: ='Evolutive SFP'!D16 -> 9.0588651e+08 | D32: ='Evolutive SFP'!E16 -> 9.253845e+08 | E32: ='Evolutive SFP'!F16 -> 9.6762762e+08 | F32: ='Evolutive SFP'!G16 -> 9.3112171e+08 | G32: ='Evolutive SFP'!H16 -> 9.4989727e+08 | H32: ='Evolutive SFP'!I16 -> 9.5798868e+08 | I32: ='Evolutive SFP'!J16 -> 9.5663535e+08 | J32: ='Evolutive SFP'!K16 -> 9.8667673e+08 | ... O32: ='Evolutive SFP'!P16 -> 1163774872
A34: 8 | B34: Non-Earning Assets | C34: ='Evolutive SFP'!D21+'Evolutive SFP'!D7 -> 1.7993041e+08 | D34: ='Evolutive SFP'!E21+'Evolutive SFP'!E7 -> 3.6470391e+08 | E34: ='Evolutive SFP'!F21+'Evolutive SFP'!F7 -> 5.4511021e+08 | F34: ='Evolutive SFP'!G21+'Evolutive SFP'!G7 -> 4.0824019e+08 | G34: ='Evolutive SFP'!H21+'Evolutive SFP'!H7 -> 4.0802817e+08 | H34: ='Evolutive SFP'!I21+'Evolutive SFP'!I7 -> 4.7258801e+08 | I34: ='Evolutive SFP'!J21+'Evolutive SFP'!J7 -> 3.4443596e+08 | J34: ='Evolutive SFP'!K21+'Evolutive SFP'!K7 -> 6.449075e+08 | ... O34: ='Evolutive SFP'!P21+'Evolutive SFP'!P7 -> 657448532
A35: 8.1 | B35: Property and Equipment | C35: ='Evolutive SFP'!D23 -> 1.7576373e+08 | D35: ='Evolutive SFP'!E23 -> 2.010753e+08 | E35: ='Evolutive SFP'!F23 -> 2.0373183e+08 | F35: ='Evolutive SFP'!G23 -> 2.1286282e+08 | G35: ='Evolutive SFP'!H23 -> 2.4339467e+08 | H35: ='Evolutive SFP'!I23 -> 2.854335e+08 | I35: ='Evolutive SFP'!J23 -> 2.9322472e+08 | J35: ='Evolutive SFP'!K23 -> 2.9453611e+08 | ... O35: ='Evolutive SFP'!P23 -> 293773075
A37: 9 | B37: Turnover | C37: =C38+C39+C40+C41 -> 1.3169117e+08 | D37: =D38+D39+D40+D41 -> 2.7560832e+08 | E37: =E38+E39+E40+E41 -> 4.1295895e+08 | F37: =F38+F39+F40+F41 -> 5.4806697e+08 | G37: =G38+G39+G40+G41 -> 6.6323576e+08 | H37: =H38+H39+H40+H41 -> 8.0828852e+08 | I37: =I38+I39+I40+I41 -> 9.214479e+08 | J37: =J38+J39+J40+J41 -> 1.0444046e+09 | ... O37: =O38+O39+O40+O41 -> 1740269835
A38: 9.1 | B38: Loan Interest | C38: ='Evolutitve SCI'!D5 -> 1.2893192e+08 | D38: ='Evolutitve SCI'!E5 -> 2.6968467e+08 | E38: ='Evolutitve SCI'!F5 -> 4.0133362e+08 | F38: ='Evolutitve SCI'!G5 -> 5.3380706e+08 | G38: ='Evolutitve SCI'!H5 -> 6.4615031e+08 | H38: ='Evolutitve SCI'!I5 -> 7.8833408e+08 | I38: ='Evolutitve SCI'!J5 -> 8.9870506e+08 | J38: ='Evolutitve SCI'!K5 -> 1.0179117e+09 | ... O38: ='Evolutitve SCI'!P5 -> 1586970740
A39: 9.2 | B39: Income from investments | C39: ='Evolutitve SCI'!D7 -> 49250 | D39: ='Evolutitve SCI'!E7 -> 148750 | E39: ='Evolutitve SCI'!F7 -> 217750 | F39: ='Evolutitve SCI'!G7 -> 275250 | G39: ='Evolutitve SCI'!H7 -> 346250 | H39: ='Evolutitve SCI'!I7 -> 399250 | I39: ='Evolutitve SCI'!J7 -> 455750 | J39: ='Evolutitve SCI'!K7 -> 488650 | ... O39: ='Evolutitve SCI'!P7 -> 126034863
A40: 9.3 | B40: Fees & Commissions | C40: ='Evolutitve SCI'!D6 -> 2710002.1 | D40: ='Evolutitve SCI'!E6 -> 5774899.5 | E40: ='Evolutitve SCI'!F6 -> 11407576 | F40: ='Evolutitve SCI'!G6 -> 13984661 | G40: ='Evolutitve SCI'!H6 -> 16739198 | H40: ='Evolutitve SCI'!I6 -> 19555188 | I40: ='Evolutitve SCI'!J6 -> 22287086 | J40: ='Evolutitve SCI'!K6 -> 26004290 | ... O40: ='Evolutitve SCI'!P6 -> 27264232
A41: 9.4 | B41: Average yield on loans
A43: 10 | B43: Financial and Operating costs | C43: =SUM(C44:C47) -> 42928543 | D43: =SUM(D44:D47) -> 1.4695837e+08 | E43: =SUM(E44:E47) -> 2.2925962e+08 | F43: =SUM(F44:F47) -> 3.068588e+08 | G43: =SUM(G44:G47) -> 3.5794733e+08 | H43: =SUM(H44:H47) -> 4.1396427e+08 | I43: =SUM(I44:I47) -> 5.0996892e+08 | J43: =SUM(J44:J47) -> 5.6237719e+08 | ... O43: =SUM(O44:O47) -> 1066353382
A44: 10.1 | B44: Interest expense on deposits | C44: ='Evolutitve SCI'!D13+'Evolutitve SCI'!D16 -> 1078750.8 | D44: ='Evolutitve SCI'!E13+'Evolutitve SCI'!E16 -> 63771490 | E44: ='Evolutitve SCI'!F13+'Evolutitve SCI'!F16 -> 1.1486813e+08 | F44: ='Evolutitve SCI'!G13+'Evolutitve SCI'!G16 -> 1.6573486e+08 | G44: ='Evolutitve SCI'!H13+'Evolutitve SCI'!H16 -> 2.1526436e+08 | H44: ='Evolutitve SCI'!I13+'Evolutitve SCI'!I16 -> 2.4634098e+08 | I44: ='Evolutitve SCI'!J13+'Evolutitve SCI'!J16 -> 3.1896328e+08 | J44: ='Evolutitve SCI'!K13+'Evolutitve SCI'!K16 -> 3.4992397e+08 | ... O44: ='Evolutitve SCI'!P13+'Evolutitve SCI'!P16 -> 531164861
A45: 10.2 | B45: Dividend expense on share capital | C45: ='Evolutitve SCI'!D15 -> 0 | D45: ='Evolutitve SCI'!E15 -> 0 | E45: ='Evolutitve SCI'!F15 -> 0 | F45: ='Evolutitve SCI'!G15 -> 0 | G45: ='Evolutitve SCI'!H15 -> 0 | H45: ='Evolutitve SCI'!I15 -> 0 | I45: ='Evolutitve SCI'!J15 -> 0 | J45: ='Evolutitve SCI'!K15 -> 0 | ... O45: ='Evolutitve SCI'!P15 -> 0
