Workbook

Sheet Balance Sheet
B1: ACUMEN SACCO SOCIETY | S1: =+X:X -> 0
B2: STATEMENT OF FINANCIAL POSITION
B3: FINANCIAL YEAR 2021 | C3: Aud-2019 | D3: Aud-2020 | E3: Jan | F3: Feb | G3: Mar | H3: Apr | I3: May | J3: Jun | K3: Jul | L3: Aug | M3: Sep | N3: Oct | O3: Nov | P3: Dec | Q3: Aud-21 | R3: 44583 | S3: 44614 | T3: 44642 | U3: 44673 | V3: 44703 | W3: 44734 | X3: 44764 | Y3: 44774 | Z3: 44805 | AA3: 44835 | AB3: 44866 | AC3: 44896 | AD3: audited 2022
A4: 1 | B4: Cash & Cash Equivalent | C4: =C5+C6 -> 10834463 | D4: =D5+D6 -> 60942575 | E4: =E5+E6 -> 17588525 | F4: =F5+F6 -> 17139918 | G4: =G5+G6 -> 16670331 | H4: =H5+H6 -> 20330141 | I4: =I5+I6 -> 21293872 | J4: =J5+J6 -> 24310141 | ... AD4: =AD5+AD6 -> 77254741
A5: 1.1 | B5: Cash in hand(both local and foreign notes and coins) | C5: 250946 | D5: 1162644 | E5: 0 | F5: 0 | G5: 0 | H5: 0 | I5: 0 | J5: 0 | K5: 0 | L5: 0 | M5: 1626211 | N5: 0 | O5: 0 | P5: 0 | Q5: 1177937 | R5: 0 | S5: 0 | T5: 0 | U5: 5403363 | V5: 8177749.9 | W5: 10487056 | X5: 8472651 | Y5: 12187787 | Z5: 17550823 | AA5: 21997216 | AB5: 15032041 | AC5: 1229050 | AD5: =1229050.75 -> 1229050.8
A6: 1.2 | B6: Cash at bank:(placement with financial institutions) | C6: =10834463-250946 -> 10583517 | D6: =60942575-1162644 -> 59779931 | E6: 17588525 | F6: 17139918 | G6: 16670331 | H6: 20330141 | I6: 21293872 | J6: 24310141 | K6: 10507164 | L6: 17769050 | M6: 11989163 | N6: 15706308 | O6: 13220603 | P6: 18872807 | Q6: =56687339-1177937 -> 55509402 | R6: 19988495 | S6: 15094316 | T6: 10091344 | U6: 38910895 | V6: 39201056 | W6: 39481190 | X6: 43776413 | Y6: 40093906 | Z6: 40497201 | AA6: 40797435 | AB6: 48023623 | AC6: 76033691 | AD6: =77254741-AD5 -> 76025690
A7: 2 | B7: Prepayments & Sundry Receivables | C7: 8620453 | D7: 11664214 | E7: 0 | F7: 0 | G7: 0 | H7: 0 | I7: 0 | J7: 0 | K7: 0 | L7: 0 | M7: 0 | N7: 0 | O7: 0 | P7: 0 | Q7: 6570298 | R7: 0 | S7: 0 | T7: 0 | U7: 0 | V7: 0 | W7: 0 | X7: 0 | Y7: 0 | Z7: 0 | AA7: 0 | AB7: 0 | AC7: 0 | AD7: 11282181 | AF7: =R14-AC14 -> -8289401.2
A8: 3 | B8: Financial Investments | C8: =SUM(C9:C12) -> 115855 | D8: =SUM(D9:D12) -> 115855 | E8: =SUM(E9:E12) -> 41747826 | F8: =SUM(F9:F12) -> 42026698 | G8: =SUM(G9:G12) -> 42341641 | H8: =SUM(H9:H12) -> 35634085 | I8: =SUM(I9:I12) -> 35905691 | J8: =SUM(J9:J12) -> 36173047 | ... AD8: =SUM(AD9:AD12) -> 115855
A9: 3.1 | B9: Government Securities - Treasury Bills/bonds, | D9: 0 | E9: 0 | F9: 0 | G9: 0 | H9: 0 | I9: 0 | J9: 0 | K9: 0 | L9: 0 | M9: 0 | N9: 0 | O9: 0 | P9: 0 | R9: 0 | S9: 0 | T9: 0 | U9: 0 | V9: 0 | W9: 0 | X9: 0 | Y9: 0 | Z9: 0 | AA9: 0 | AB9: 0 | AC9: 0
A10: 3.2 | B10: Other Securities - Commercial papers/Bonds | E10: 41631971 | F10: 41910843 | G10: 42225786 | H10: 35518230 | I10: 35789836 | J10: 36057192 | K10: 46393715 | L10: 36722409 | M10: 36984946 | N10: 37258688 | O10: 37528779 | P10: 37814532 | R10: 38101050 | S10: 38351386 | T10: 38633177 | U10: 0 | V10: 0 | W10: 0 | X10: 0 | Y10: 0 | Z10: 0 | AA10: 0 | AB10: 0 | AC10: 0
A11: 3.3a | B11: Balances with other SACCO Societies | D11: 0 | E11: 0 | F11: 0 | G11: 0 | H11: 0 | I11: 0 | J11: 0 | K11: 0 | L11: 0 | M11: 0 | N11: 0 | O11: 0 | P11: 0 | R11: 0 | S11: 0 | T11: 0 | U11: 0 | V11: 0 | W11: 0 | X11: 0 | Y11: 0 | Z11: 0 | AA11: 0 | AB11: 0 | AC11: 0
A12: 3.3b | B12: Investments in companies - shares/stocks | C12: 115855 | D12: 115855 | E12: 115855 | F12: 115855 | G12: 115855 | H12: 115855 | I12: 115855.18 | J12: 115855 | K12: 115855 | L12: 115855 | M12: 115855 | N12: 115855 | O12: 115855 | P12: 115855 | Q12: 115855 | R12: 115855 | S12: 115855 | T12: 115855 | U12: 115855 | V12: 115855 | W12: 115855 | X12: 115855 | Y12: 115855 | Z12: 115855 | AA12: 115855 | AB12: 115855 | AC12: 115855 | AD12: 115855
A13: 4 | B13: Net Loan Portfolio | C13: =C14-C15 -> 246137216 | D13: =D14-D15 -> 2.1688273e+08 | E13: =E14-E15 -> 2.2332317e+08 | F13: =F14-F15 -> 223644117 | G13: =G14-G15 -> 2.2853079e+08 | H13: =H14-H15 -> 2.3601268e+08 | I13: =I14-I15 -> 2.4549239e+08 | J13: =J14-J15 -> 2.4634833e+08 | ... AD13: =AD14-AD15 -> 3.0730254e+08
A14: 4.1 | B14: Gross Loan Portfolio | C14: 247597572 | D14: 2.3820198e+08 | E14: 2.4320502e+08 | F14: 238585005 | G14: 2.4437561e+08 | H14: 2.5338738e+08 | I14: 2.593564e+08 | J14: 2.607803e+08 | K14: 2.6816103e+08 | L14: 2.9282299e+08 | M14: 290247844 | N14: 2.9653408e+08 | O14: 3.0605257e+08 | P14: 312279513 | Q14: 312279513 | R14: 3.1414698e+08 | S14: 310947878 | T14: 3.1663468e+08 | U14: 319463452 | V14: 3.1110576e+08 | W14: 3.1236803e+08 | X14: 3.1435413e+08 | Y14: 323838439 | Z14: 321243675 | AA14: 314535806 | AB14: 3.2301206e+08 | AC14: 322436384 | AD14: 3.2243638e+08
A15: 4.2 | B15: Allowance for Loan Loss | C15: 1460356 | D15: 21319244 | E15: 19881849 | F15: 14940888 | G15: 15844821 | H15: 17374702 | I15: 13864013 | J15: 14431971 | K15: 16219556 | L15: 14873127 | M15: 14369299 | N15: 12887795 | O15: 13942448 | P15: 11418651 | Q15: 11418650 | R15: 13127959 | S15: 13690411 | T15: 13664300 | U15: 29186572 | V15: 14856216 | W15: 15454888 | X15: 17269384 | Y15: 17823058 | Z15: 18027045 | AA15: 17881657 | AB15: 17700548 | AC15: 15133841 | AD15: 15133841
A16: 5 | B16: Accounts Receivables | D16: 0 | E16: 0 | F16: 0 | G16: 0 | H16: 0 | I16: 0 | J16: 0 | K16: 0 | L16: 0 | M16: 0 | N16: 0 | O16: 0 | P16: 0 | R16: 0 | S16: 0 | T16: 0 | U16: 0 | V16: 0 | W16: 0 | X16: 0
A17: 5.1 | B17: Tax Recoverable | D17: 0 | E17: 0 | F17: 0 | G17: 0 | H17: 0 | I17: 0 | J17: 0 | K17: 0 | L17: 0 | M17: 0 | N17: 0 | O17: 0 | P17: 0 | R17: 0 | S17: 0 | T17: 0 | U17: 0 | V17: 0 | W17: 0 | X17: 0 | Y17: 0 | Z17: 0 | AA17: 0 | AB17: 0 | AC17: 0
A18: 5.2 | B18: Deferred Tax Assets | D18: 0 | E18: 0 | F18: 0 | G18: 0 | H18: 0 | I18: 0 | J18: 0 | K18: 0 | L18: 0 | M18: 0 | N18: 0 | O18: 0 | P18: 0 | R18: 0 | S18: 0 | T18: 0 | U18: 0 | V18: 0 | W18: 0 | X18: 0 | Y18: 0 | Z18: 0 | AA18: 0 | AB18: 0 | AC18: 0
A19: 5.3 | B19: Retirement Benefit Assets | D19: 0 | E19: 0 | F19: 0 | G19: 0 | H19: 0 | I19: 0 | J19: 0 | K19: 0 | L19: 0 | M19: 0 | N19: 0 | O19: 0 | P19: 0 | R19: 0 | S19: 0 | T19: 0 | U19: 0 | V19: 0 | W19: 0 | X19: 0 | Y19: 0 | Z19: 0 | AA19: 0 | AB19: 0 | AC19: 0
A20: 6 | B20: Property & Equipment & Other assets | C20: =SUM(C21:C25) -> 3663226 | D20: =SUM(D21:D25) -> 3806301.4 | E20: =SUM(E21:E25) -> 20811387 | F20: =SUM(F21:F25) -> 24558472 | G20: =SUM(G21:G25) -> 24787827 | H20: =SUM(H21:H25) -> 25944664 | I20: =SUM(I21:I25) -> 24321865 | J20: =SUM(J21:J25) -> 24580571 | ... AD20: =SUM(AD21:AD25) -> 7431862
A21: 6.1 | B21: Investment Properties | D21: 0 | E21: 0 | F21: 0 | G21: 0 | H21: 0 | I21: 0 | J21: 0 | K21: 0 | L21: 0 | M21: 0 | N21: 0 | O21: 0 | P21: 0 | R21: 0 | S21: 0 | T21: 0 | U21: 0 | V21: 0 | W21: 0 | X21: 0 | Y21: 0 | Z21: 0 | AA21: 0 | AB21: 0 | AC21: 0
A22: 6.2 | B22: Property & Equipment | C22: 3663226 | D22: 3806301.4 | E22: 3838301.4 | F22: 3788301.4 | G22: 3779212.4 | H22: 3729212.4 | I22: 4293012.4 | J22: 4396107.4 | K22: 4381107.4 | L22: 4331107.4 | M22: 4958707 | N22: 4627907.4 | O22: 4667107.4 | P22: 5202760 | Q22: 5202760 | R22: 5142759.1 | S22: 5082759.1 | T22: 8064559.1 | U22: 8004559 | V22: 7944559 | W22: 7884559.1 | X22: 7824559.5 | Y22: 7764559 | Z22: 7704559 | AA22: 8772945 | AB22: 7831355 | AC22: 7431862 | AD22: 7431862
A23: 6.3 | B23: Prepaid Lease rentals | D23: 0 | E23: 0 | F23: 0 | G23: 0 | H23: 0 | I23: 0 | J23: 0 | K23: 0 | L23: 0 | M23: 0 | N23: 0 | O23: 0 | P23: 0 | R23: 0 | S23: 0 | T23: 0 | U23: 0 | V23: 0 | W23: 0 | X23: 0 | Y23: 0 | Z23: 0 | AA23: 0 | AB23: 0 | AC23: 0
A24: 6.4 | B24: Intangible Assets | D24: 0 | E24: 0 | F24: 0 | G24: 0 | H24: 0 | I24: 0 | J24: 0 | K24: 0 | L24: 0 | M24: 0 | N24: 0 | O24: 0 | P24: 0 | R24: 0 | S24: 0 | T24: 0 | U24: 0 | V24: 0 | W24: 0 | X24: 0 | Y24: 0 | Z24: 0 | AA24: 0 | AB24: 0 | AC24: 0
A25: 6.5 | B25: Other Assets | E25: 16973085 | F25: 20770171 | G25: 21008615 | H25: 22215452 | I25: 20028852 | J25: 20184464 | K25: 19787100 | L25: 17161031 | M25: 17189666 | N25: 16082651 | O25: 16062718 | P25: 6570298 | R25: 7181487.2 | S25: 12513350 | T25: 14526708 | U25: 21401270 | V25: 22602714 | W25: 23668645 | X25: 24522300 | Y25: 22660501 | Z25: 22853190 | AA25: 24646422 | AB25: 22443909 | AC25: 11702763
B26: Total Assets | C26: =C4+C7+C8+C13+C16+C20 -> 269371213 | D26: =D4+D7+D8+D13+D16+D20 -> 2.9341168e+08 | E26: =E4+E7+E8+E13+E16+E20 -> 3.0347091e+08 | F26: =F4+F7+F8+F13+F16+F20 -> 3.0736921e+08 | G26: =G4+G7+G8+G13+G16+G20 -> 3.1233059e+08 | H26: =H4+H7+H8+H13+H16+H20 -> 3.1792157e+08 | I26: =I4+I7+I8+I13+I16+I20 -> 3.2701382e+08 | J26: =J4+J7+J8+J13+J16+J20 -> 3.3141209e+08 | ... AD26: =AD4+AD7+AD8+AD13+AD16+AD20 -> 4.0338718e+08
A27: 7 | B27: Savings Deposits - Withdrawable deposits - FOSA) | C27: 744248 | D27: 2276384.6 | E27: 4492765.1 | F27: 2389885 | G27: 3858157.5 | H27: 4039661.8 | I27: 6363453.3 | J27: 4705808.8 | K27: 4923281 | L27: 17554285 | M27: 6679865 | N27: 7769014.6 | O27: 7822799.3 | P27: 8866827.4 | Q27: 7898153 | R27: 8670232.6 | S27: 10412303 | T27: 10767730 | U27: 15840071 | V27: 12879740 | W27: 15726804 | X27: 13981586 | Y27: 14419401 | Z27: 12401261 | AA27: 11290164 | AB27: 11288607 | AC27: 8067834 | AD27: 8067834
A28: 8 | B28: Short Term Deposits (e.g Fixed deposits, special savings) | C28: 552646 | D28: 708204 | E28: 0 | F28: 0 | G28: 0 | H28: 0 | I28: 0 | J28: 0 | K28: 0 | L28: 0 | M28: 0 | N28: 0 | O28: 0 | P28: 0 | Q28: 968674 | R28: 0 | S28: 0 | T28: 0 | U28: 0 | V28: 0 | W28: 0 | X28: 0 | Y28: 0 | Z28: 0 | AA28: 0 | AB28: 0 | AC28: 0
A29: 9 | B29: Non withdrawable deposits (BOSA member deposits) | C29: 220316533 | D29: 254720687 | E29: 2.5960197e+08 | F29: 258890719 | G29: 2.6157253e+08 | H29: 2.6543749e+08 | I29: 2.6839572e+08 | J29: 2.7279089e+08 | K29: 2.740514e+08 | L29: 2.7775653e+08 | M29: 280167932 | N29: 2.83755e+08 | O29: 2.8751718e+08 | P29: 287470465 | Q29: 287470465 | R29: 2.90463e+08 | S29: 295733291 | T29: 2.990638e+08 | U29: 298957139 | V29: 2.9750593e+08 | W29: 2.9986164e+08 | X29: 3.0384757e+08 | Y29: 307627757 | Z29: 309862125 | AA29: 309283561 | AB29: 3.1290911e+08 | AC29: 312478374 | AD29: =311707089+771285 -> 312478374
B30: Total Deposit liabilities | C30: =SUM(C27:C29) -> 221613427 | D30: =SUM(D27:D29) -> 2.5770528e+08 | E30: =SUM(E27:E29) -> 2.6409473e+08 | F30: =SUM(F27:F29) -> 2.612806e+08 | G30: =SUM(G27:G29) -> 2.6543069e+08 | H30: =SUM(H27:H29) -> 2.6947715e+08 | I30: =SUM(I27:I29) -> 2.7475918e+08 | J30: =SUM(J27:J29) -> 2.774967e+08 | ... AD30: =SUM(AD27:AD29) -> 320546208
A31: 10 | B31: Accounts Payable & Other Liabilities | C31: =SUM(C32:C37) -> 14172704 | D31: =SUM(D32:D37) -> 413121 | E31: =SUM(E32:E37) -> 571369.87 | F31: =SUM(F32:F37) -> 713230 | G31: =SUM(G32:G37) -> 282026.23 | H31: =SUM(H32:H37) -> 563322.84 | I31: =SUM(I32:I37) -> 243979.34 | J31: =SUM(J32:J37) -> 216403.93 | ... AD31: =SUM(AD32:AD37) -> 19435937
A32: 10.1 | B32: Tax Payable | C32: 3610 | D32: 14602 | E32: 308444.97 | F32: 205807 | G32: 14602 | H32: 13002 | I32: 0 | J32: 0 | K32: 13002 | L32: 13002 | M32: 254150.97 | N32: 13002 | O32: 13002 | P32: 1046054 | Q32: 1046054 | R32: 1046054 | S32: 1046054 | T32: 1046054 | U32: 0 | V32: 0 | W32: 0 | X32: 0 | Y32: 0 | Z32: 0 | AA32: 0 | AB32: 0 | AC32: 968271 | AD32: 967553
A33: 10.2 | B33: Dividends Payable | C33: 2020210 | E33: 0 | F33: 0 | G33: 0 | H33: 0 | I33: 0 | J33: 0 | K33: 0 | L33: 0 | M33: 0 | N33: 0 | O33: 0 | P33: 17274788 | Q33: 2959259 | R33: 17274788 | S33: 0 | T33: 4196482.7 | U33: 3360862 | V33: 3100740 | W33: 2578741.7 | X33: 2400147.1 | Y33: 1999238 | Z33: 1931788 | AA33: 1903995 | AB33: 1792841.6 | AC33: 15104555 | AD33: 3070989
A34: 10.3 | B34: Deferred Tax Liability | D34: 0 | E34: 0 | F34: 0 | G34: 0 | H34: 0 | I34: 0 | J34: 0 | K34: 0 | L34: 0 | M34: 0 | N34: 0 | O34: 0 | P34: 0 | R34: 0 | S34: 0 | T34: 0 | U34: 0 | V34: 0 | W34: 0 | X34: 0 | Y34: 0 | Z34: 0 | AA34: 0 | AB34: 0 | AC34: 0
A35: 10.4 | B35: Retirement Benefits Liability | D35: 0 | E35: 0 | F35: 0 | G35: 0 | H35: 0 | K35: 0 | L35: 0 | M35: 0 | N35: 0 | O35: 0 | P35: 0 | R35: 0 | S35: 0 | T35: 0 | U35: 0 | V35: 0 | W35: 0 | X35: 0 | Y35: 0 | Z35: 0 | AA35: 0 | AB35: 0 | AC35: 0
A36: 10.5 | B36: Other Liabilities | C36: 538954 | D36: 398519 | E36: 262924.9 | F36: 507423 | G36: 267424.23 | H36: 550320.84 | I36: 243979.34 | J36: 216403.93 | K36: 216166.16 | L36: 375066.82 | M36: 174666 | N36: 410985.01 | O36: 327482.94 | P36: 1072234 | Q36: 1072234 | R36: 1100582.7 | S36: 3231474 | T36: 1486237.8 | U36: 817479 | V36: 3448748.6 | W36: 838537.69 | X36: 856633.75 | Y36: 902565 | Z36: 820578 | AA36: 868656 | AB36: 817488.96 | AC36: 715180 | AD36: =292840 -> 292840
A37: 10.6 | B37: External Borrowings | C37: 11609930 | D37: 0 | E37: 0 | F37: 0 | G37: 0 | H37: 0 | I37: 0 | J37: 0 | K37: 0 | L37: 0 | M37: 0 | N37: 0 | O37: 0 | P37: 0 | Q37: 14315529 | R37: 0 | S37: 0 | T37: 0 | U37: 0 | V37: 0 | W37: 0 | X37: 0 | Y37: 0 | Z37: 0 | AA37: 0 | AB37: 0 | AC37: 0 | AD37: 15104555
B38: Total Liabilities | C38: =C30+C31 -> 235786131 | D38: =D30+D31 -> 2.581184e+08 | E38: =E30+E31 -> 2.646661e+08 | F38: =F30+F31 -> 2.6199383e+08 | G38: =G30+G31 -> 2.6571271e+08 | H38: =H30+H31 -> 2.7004047e+08 | I38: =I30+I31 -> 2.7500316e+08 | J38: =J30+J31 -> 2.777131e+08 | ... AD38: =AD30+AD31 -> 339982145
A39: 11 | B39: Share Capital (Members share capital per Bylaws) | C39: =6148953+11127387 -> 17276340 | D39: 18970134 | E39: 19107910 | F39: 19227517 | G39: 19365263 | H39: 19441092 | I39: 19508987 | J39: 19592640 | K39: 19661192 | L39: 19754167 | M39: 19847365 | N39: 19953633 | O39: 20596317 | P39: 20674211 | Q39: 20674211 | R39: 20814762 | S39: 21048153 | T39: 21279380 | U39: 21411957 | V39: 21565458 | W39: 21736106 | X39: 21929376 | Y39: 22170725 | Z39: 22520199 | AA39: 22655976 | AB39: 23093488 | AC39: 29563201 | AD39: 29563201
A40: 12 | B40: Capital Grants | D40: 0 | E40: 0 | F40: 0 | G40: 0 | H40: 0 | I40: 0 | J40: 0 | K40: 0 | L40: 0 | M40: 0 | N40: 0 | O40: 0 | P40: 0 | R40: 0 | S40: 0 | T40: 0 | U40: 0 | V40: 0 | W40: 0 | X40: 0 | Y40: 0 | Z40: 0 | AA40: 0 | AB40: 0 | AC40: 0
...

Sheet Insider Lending
B2: Loan Type/Name | C2: Ref No | D2: Amount Granted | E2: Disbursement Date | F2: BOSA Deposits | G2: Security | H2: Repayment Commencement | I2: Repayment Period

Sheet Income Stat.
A1: ACUMEN SACCO SOCIETY
A2: STATEMENT OF COMPREHENSIVE INCOME
A3: FINANCIAL YEAR 2021 | C3: Aud-2019 | D3: Aud-2020 | E3: audited-21 | F3: Jan | G3: Feb | H3: Mar | I3: Apr | J3: May | K3: Jun | L3: Jul | M3: Aug | N3: Sep | O3: Oct | P3: Nov | Q3: Dec | R3: Aud-21 | S3: 44583 | T3: 44614 | U3: 44642 | V3: 44673 | W3: 44703 | X3: 44734 | Y3: 44764 | Z3: 44774 | AA3: 44805 | AB3: 44835 | AC3: 44866 | AD3: 44896 | AE3: Audited 2022
A4: 1 | B4: Financial Income | C4: =C5+C8 -> 32774205 | D4: =D5+D8 -> 34090071 | E4: 46322746 | F4: =F5+F8 -> 3418741.5 | G4: =G5+G8 -> 6535327 | H4: =H5+H8 -> 10453856 | I4: =I5+I8 -> 14017566 | J4: =J5+J8 -> 17535951 | K4: =K5+K8 -> 21401480 | L4: =L5+L8 -> 25456528 | M4: =M5+M8 -> 29896907 | ... AE4: =AE5+AE8 -> 50977192
A5: 2 | B5: Financial Income from Loans Portfolio | C5: =SUM(C6:C7) -> 26357606 | D5: =SUM(D6:D7) -> 29009435 | E5: 42777006 | F5: =SUM(F6:F7) -> 3117356.4 | G5: =SUM(G6:G7) -> 5871886 | H5: =SUM(H6:H7) -> 9414572.5 | I5: =SUM(I6:I7) -> 12623995 | J5: =SUM(J6:J7) -> 15812491 | K5: =SUM(K6:K7) -> 19224394 | L5: =SUM(L6:L7) -> 22878583 | M5: =SUM(M6:M7) -> 26904791 | ... AE5: =SUM(AE6:AE7) -> 50228228
A6: 2.1 | B6: Interest on Loan Portfolio | C6: 26357606 | D6: 29009435 | E6: 39662803 | F6: 2439265 | G6: 4918501 | H6: 7397029 | I6: 9889192 | J6: 12442331 | K6: 15103290 | L6: 17756062 | M6: 20447140 | N6: 23395937 | O6: 26305388 | P6: 29358663 | Q6: 39662803 | R6: 39662803 | S6: 3252538.1 | T6: 6475743.2 | U6: 9690395.7 | V6: 12962772 | W6: 16289805 | X6: 19550658 | Y6: 22731721 | Z6: 28916133 | AA6: 29183517 | AB6: 32454963 | AC6: 35699146 | AD6: 38924654 | AE6: 45542181
A7: 2.2 | B7: Fees & Commission on Loan Portfolio | E7: 3114203 | F7: 678091.4 | G7: 953385 | H7: 2017543.5 | I7: 2734803 | J7: 3370160.1 | K7: 4121103.8 | L7: 5122521.2 | M7: 6457651 | N7: 7418524 | O7: 7499864.5 | P7: 8289231.8 | Q7: 2302810 | R7: 3114203 | S7: 230977.6 | T7: 634903.9 | U7: 1160447.7 | V7: 1615548 | W7: 2562092.7 | X7: 1677069 | Y7: 2380353.3 | Z7: 837152 | AA7: 2540533 | AB7: 3951071 | AC7: 2960830.6 | AD7: 4096049 | AE7: =3799200+886847 -> 4686047
A8: 3 | B8: Financial Income from Investments in: | C8: =SUM(C9:C12) -> 6416599 | D8: =SUM(D9:D12) -> 5080636 | E8: 3545740 | F8: =SUM(F9:F12) -> 301385.13 | G8: =SUM(G9:G12) -> 663441 | H8: =SUM(H9:H12) -> 1039283.9 | I8: =SUM(I9:I12) -> 1393570.8 | J8: =SUM(J9:J12) -> 1723459.6 | K8: =SUM(K9:K12) -> 2177086.3 | L8: =SUM(L9:L12) -> 2577944.4 | M8: =SUM(M9:M12) -> 2992116.4 | ... AE8: =SUM(AE9:AE12) -> 748964
A9: 3.1 | B9: Government Securities | E9: 0 | F9: 0 | G9: 0 | H9: 0 | I9: 0 | J9: 0 | K9: 0 | L9: 0 | M9: 0 | N9: 0 | O9: 0 | P9: 0 | Q9: 0 | S9: 0 | T9: 0 | U9: 0 | V9: 0 | W9: 0 | X9: 0 | Y9: 0 | Z9: 0 | AA9: 0 | AB9: 0 | AC9: 0 | AD9: 0
A10: 3.2 | B10: Deposit with Banks and Other Financial Inst. | C10: 207434 | D10: 1879690 | E10: 3545740 | F10: 296185.13 | G10: 575057 | H10: 889999.89 | I10: 1182443.8 | J10: 1454049.8 | K10: 1721405.3 | L10: 2057928.7 | M10: 2386622.9 | N10: 2649160 | O10: 2922902.1 | P10: 3192993.1 | Q10: 3478746 | R10: 3545740 | S10: 286518.2 | T10: 573036.04 | U10: 854827.22 | V10: 1132545 | W10: 1422704.9 | X10: 1702828 | Y10: 1998062.4 | Z10: 2315555 | AA10: 2842210 | AB10: 2903228 | AC10: 3245270.4 | AD10: 3592454
A11: 3.3 | B11: Other Investments - dividend & Interest incomes from investments | E11: 0 | F11: 0 | G11: 0 | H11: 0 | I11: 0 | J11: 0 | K11: 0 | L11: 0 | M11: 0 | N11: 0 | O11: 0 | P11: 0 | Q11: 0 | S11: 0 | T11: 0 | U11: 0 | V11: 0 | W11: 0 | X11: 0 | Y11: 0 | Z11: 0 | AA11: 0 | AB11: 0 | AC11: 0 | AD11: 0
A12: 3.4 | B12: Other Operating Income- Salary processing fees, transaction fees, membership fees | C12: 6209165 | D12: 3200946 | E12: 0 | F12: 5200 | G12: 88384 | H12: 149284 | I12: 211127 | J12: 269409.8 | K12: 455680.97 | L12: 520015.75 | M12: 605493.5 | N12: 131618 | O12: 746224.7 | P12: 797327 | Q12: 878397 | S12: 52856.8 | T12: 172456 | U12: 317558.4 | V12: 423690 | W12: 507189.2 | X12: 598456 | Y12: 500334.8 | Z12: 834436 | AA12: 2155707 | AB12: 1153280.1 | AC12: 1143133.6 | AD12: 4315690 | AE12: =320330+428634 -> 748964
A13: 4 | B13: Financial Expense | C13: =C14+C15+C16+C17+C18+C19 -> 11783851 | D13: =D14+D15+D16+D17+D18+D19 -> 138384 | E13: 14507402 | F13: =F14+F15+F16+F17+F18+F19 -> 40564 | G13: =G14+G15+G16+G17+G18+G19 -> 46804 | H13: =H14+H15+H16+H17+H18+H19 -> 64376 | I13: =I14+I15+I16+I17+I18+I19 -> 83348 | J13: =J14+J15+J16+J17+J18+J19 -> 2023213 | K13: =K14+K15+K16+K17+K18+K19 -> 2037171 | L13: =L14+L15+L16+L17+L18+L19 -> 2149695 | M13: =M14+M15+M16+M17+M18+M19 -> 2163206 | ... AE13: =AE14+AE15+AE16+AE17+AE18+AE19 -> 15323702
A14: 4.2 | B14: Interest Expense on Deposits | C14: 11610005 | E14: 14315529 | F14: 0 | G14: 0 | H14: 0 | I14: 0 | J14: 0 | K14: 0 | L14: 0 | M14: 0 | N14: 0 | O14: 0 | P14: 0 | Q14: 14315529 | R14: 14315529 | S14: 0 | T14: 0 | U14: 0 | V14: 0 | W14: 0 | X14: 0 | Y14: 0 | Z14: 0 | AA14: 0 | AB14: 0 | AC14: 0 | AD14: 0 | AE14: 15104555
A15: 4.3 | B15: Cost of External Borrowings | E15: 0 | F15: 0 | G15: 0 | H15: 0 | I15: 0 | J15: 0 | K15: 0 | L15: 0 | M15: 0 | N15: 0 | O15: 0 | P15: 0 | Q15: 0 | S15: 0 | T15: 0 | U15: 0 | V15: 0 | W15: 0 | X15: 0 | Y15: 0 | Z15: 0 | AA15: 0 | AB15: 0 | AC15: 0 | AD15: 0
A16: 4.4 | B16: Dividend Expenses (on member shares) | E16: 0 | F16: 0 | G16: 0 | H16: 0 | I16: 0 | J16: 0 | K16: 0 | L16: 0 | M16: 0 | N16: 0 | O16: 0 | P16: 0 | Q16: 2959259 | S16: 0 | T16: 0 | U16: 0 | V16: 0 | W16: 0 | X16: 0 | Y16: 0 | Z16: 0 | AA16: 0 | AB16: 0 | AC16: 0 | AD16: 0
A17: 4.5 | B17: Other Financial Expense | C17: =124634+49212 -> 173846 | D17: =109986+28398 -> 138384 | E17: 191873 | F17: 0 | G17: 0 | H17: 0 | I17: 0 | J17: 1941025 | K17: 1907775 | L17: 1907775 | M17: 1907775 | N17: 2053442 | O17: 1907775 | P17: 1907775 | Q17: 191873 | R17: =140300+51573 -> 191873 | S17: 0 | T17: 0 | U17: 0 | V17: 356638 | W17: 5822594 | X17: 3989613.3 | Y17: 4167941.1 | Z17: 4183647 | AA17: 3834547 | AB17: 3549401.4 | AC17: 1084261.9 | AD17: 170803
A18: 4.6 | B18: Fees & Commission Expense | E18: 0 | F18: 0 | G18: 0 | H18: 0 | I18: 0 | J18: 0 | K18: 0 | L18: 0 | M18: 0 | N18: 0 | O18: 0 | P18: 0 | Q18: 0 | S18: 0 | T18: 0 | U18: 0 | V18: 0 | W18: 0 | X18: 0 | Y18: 0 | Z18: 0 | AA18: 0 | AB18: 0 | AC18: 749899.6 | AD18: 0
A19: 4.7 | B19: Other Expense | E19: 0 | F19: 40564 | G19: 46804 | H19: 64376 | I19: 83348 | J19: 82188 | K19: 129396 | L19: 241920 | M19: 255431 | N19: 0 | O19: 461887 | P19: 478651 | Q19: 0 | S19: 489622 | T19: 0 | U19: 527248 | V19: 0 | W19: 0 | X19: 0 | Y19: 0 | Z19: 0 | AA19: 0 | AB19: 0 | AC19: 493494 | AD19: 0 | AE19: 219147
A20: 5 | B20: Net Financial Income/(Loss) | C20: =C4-C13 -> 20990354 | D20: =D4-D13 -> 33951687 | E20: 31815344 | F20: =F4-F13 -> 3378177.5 | G20: =G4-G13 -> 6488523 | H20: =H4-H13 -> 10389480 | I20: =I4-I13 -> 13934218 | J20: =J4-J13 -> 15512738 | K20: =K4-K13 -> 19364309 | L20: =L4-L13 -> 23306833 | M20: =M4-M13 -> 27733701 | ... AE20: =AE4-AE13 -> 35653490
A21: 6 | B21: Allowance for Loan Loss | C21: =C22-C23 -> 1460356 | D21: =D22-D23 -> 19858888 | E21: -9900593 | F21: =F22-F23 -> 0 | G21: =G22-G23 -> 0 | H21: =H22-H23 -> 846134.5 | I21: =I22-I23 -> 2371292 | J21: =J22-J23 -> 2371292 | K21: =K22-K23 -> 2939249.8 | L21: =L22-L23 -> 4726834 | M21: =M22-M23 -> 4726834 | ... AE21: =AE22-AE23 -> 3715190
A22: 6.1 | B22: Provision for Loan Losses | C22: 1460356 | D22: 19858888 | E22: -9900593 | F22: 0 | G22: 0 | H22: 846134.5 | I22: 2371292 | J22: 2371292 | K22: 2939249.8 | L22: 4726834 | M22: 4726834 | N22: 4726834 | O22: 4726834 | P22: 5781487.1 | Q22: 0 | S22: 1708615.3 | T22: 2271067.3 | U22: 2271067.3 | V22: 12713718 | W22: 3458816.3 | X22: 4057488 | Y22: 5871985.1 | Z22: 6425659 | AA22: 6645635 | AB22: 6484258.8 | AC22: 6303149.9 | AD22: 3715190 | AE22: 3715190
A23: 6.2 | B23: Value of Loans Recovered | C23: 0 | E23: 0 | F23: 0 | G23: 0 | H23: 0 | I23: 0 | J23: 0 | K23: 0 | L23: 0 | M23: 0 | N23: 0 | O23: 0 | P23: 0 | Q23: 9900593 | R23: 9900593 | S23: 0 | T23: 0 | U23: 0 | V23: 0 | W23: 0 | X23: 0 | Y23: 0 | Z23: 0 | AA23: 0 | AB23: 0 | AC23: 0 | AD23: 0
A24: 7 | B24: Operating Expenses | C24: =SUM(C25:C29) -> 16012815 | D24: =SUM(D25:D29) -> 14056548 | E24: 20870409 | F24: =SUM(F25:F29) -> 1130303.3 | G24: =SUM(G25:G29) -> 3053257.3 | H24: =SUM(H25:H29) -> 4959956.9 | I24: =SUM(I25:I29) -> 5787799.1 | J24: =SUM(J25:J29) -> 6854095.2 | K24: =SUM(K25:K29) -> 8533034.1 | L24: =SUM(L25:L29) -> 10519944 | M24: =SUM(M25:M29) -> 11958350 | ... AE24: =SUM(AE25:AE29) -> 27091117
A25: 7.1 | B25: Personnel Expenses | C25: 6094358 | D25: 5780807 | E25: 7415081 | F25: 534186.3 | G25: 1087152.3 | H25: 1613513.8 | I25: 2121299 | J25: 2745514.5 | K25: 3610776 | L25: 4363428 | M25: 4957534.5 | N25: 5611894 | O25: 6269491.1 | P25: 6919453.1 | Q25: 7415081 | R25: 7415081 | S25: 680373 | T25: 1347425 | U25: 2074025 | V25: 2754365 | W25: 3437662.2 | X25: 4617963 | Y25: 5482490.5 | Z25: 6176528 | AA25: 6881824 | AB25: 7676130 | AC25: 8360402.5 | AD25: 8761936 | AE25: 8611936
A26: 7.2 | B26: Governance Expenses | C26: 3612674 | D26: 2626712 | E26: 3833821 | F26: 105048 | G26: 733690 | H26: 1612900.1 | I26: 1622476.1 | J26: 1799738.1 | K26: 2051732.1 | L26: 2745912.8 | M26: 3276754.8 | N26: 3500283 | O26: 3823875.8 | P26: 3991106.8 | Q26: 3833831 | R26: 3833831 | S26: 798834 | T26: 1652193 | U26: 1822115.6 | V26: 1957058 | W26: 2271195.6 | X26: 2429839.6 | Y26: 2829803.6 | Z26: 3082582 | AA26: 3238941 | AB26: 3501135 | AC26: 4695695 | AD26: 4833555 | AE26: 4548555
A27: 7.3 | B27: Marketing Expenses | C27: 959371 | D27: 427336 | E27: 1097736 | F27: 58713 | G27: 107332 | H27: 172044 | I27: 196954 | J27: 234374 | K27: 275884 | L27: 598554 | M27: 623719 | N27: 646529 | O27: 672311 | P27: 705977 | Q27: 1097736 | R27: 1097736 | S27: 605528.97 | T27: 639628.97 | U27: 795818.97 | V27: 825818 | W27: 979992.97 | X27: 1027353 | Y27: 1072053 | Z27: 1102502 | AA27: 1141152 | AB27: 1276483 | AC27: 1301984 | AD27: 1781611 | AE27: =1781611+245355 -> 2026966
A28: 7.4 | B28: Depreciation and Amortization Charges | C28: 541194 | D28: 543202 | E28: 716348.28 | F28: 50000 | G28: 100000 | H28: 150000 | I28: 200000 | J28: 250000 | K28: 300000 | L28: 350000 | M28: 400000 | N28: 450000 | O28: 500000 | P28: 550000 | Q28: 716348.28 | R28: 716348.28 | S28: 60000 | T28: 120000 | U28: 180000 | V28: 240000 | W28: 300000 | X28: 360000 | Y28: 420000 | Z28: 480000 | AA28: 540000 | AB28: 600000 | AC28: 1049576 | AD28: 1747808 | AE28: 1747808
A29: 7.5 | B29: Administrative Expenses | C29: =6305783-959371-541194 -> 4805218 | D29: =5649029-427336-543202 -> 4678491 | E29: 7807422.7 | F29: 382356 | G29: 1025083 | H29: 1411499 | I29: 1647070 | J29: 1824468.5 | K29: 2294642 | L29: 2462049 | M29: 2700341.7 | N29: 3057667 | O29: 3109230.7 | P29: 3408435.7 | Q29: 7807423 | R29: 7807423 | S29: 333561 | T29: 1070042 | U29: 845100 | V29: 1589429 | W29: 1853860.1 | X29: 2371323 | Y29: 2118177 | Z29: 2867249 | AA29: 3170755 | AB29: 3526657 | AC29: 3286351 | AD29: 9980625 | AE29: =13930626-1781611-245355-1747808.01 -> 10155852
A30: 8 | B30: Net Operating Income | C30: =C20-C21-C24 -> 3517183 | D30: =D20-D21-D24 -> 36251 | E30: 20845528 | F30: =F20-F21-F24 -> 2247874.2 | G30: =G20-G21-G24 -> 3435265.7 | H30: =H20-H21-H24 -> 4583389 | I30: =I20-I21-I24 -> 5775126.7 | J30: =J20-J21-J24 -> 6287350.5 | K30: =K20-K21-K24 -> 7892025.2 | L30: =L20-L21-L24 -> 8060054.8 | M30: =M20-M21-M24 -> 11048517 | ... AE30: =AE20-AE21-AE24 -> 4847183
A31: 9 | B31: Net Non- Operating Income/ (Expense) | C31: =C32-C33 -> 0 | D31: =D32-D33 -> 0 | E31: 0 | F31: =F32-F33 -> 0 | G31: =G32-G33 -> 0 | H31: =H32-H33 -> 0 | I31: =I32-I33 -> 0 | J31: =J32-J33 -> 0 | K31: =K32-K33 -> 0 | L31: =L32-L33 -> 0 | M31: =M32-M33 -> 0 | ... AE31: =AE32-AE33 -> 0
A32: 9.1 | B32: Non- Operating Income | E32: 0 | F32: 0 | G32: 0 | H32: 0 | I32: 0 | J32: 0 | K32: 0 | L32: 0 | M32: 0 | N32: 0 | O32: 0 | P32: 0 | Q32: 0 | S32: 0 | T32: 0 | U32: 0 | V32: 0 | W32: 0 | X32: 0 | Y32: 0 | Z32: 0 | AA32: 0 | AB32: 0 | AC32: 0 | AD32: 0
A33: 9.2 | B33: Non- Operating Expense | E33: 0 | F33: 0 | G33: 0 | H33: 0 | I33: 0 | J33: 0 | K33: 0 | L33: 0 | M33: 0 | N33: 0 | O33: 0 | P33: 0 | Q33: 0 | S33: 0 | T33: 0 | U33: 0 | V33: 0 | W33: 0 | X33: 0 | Y33: 0 | Z33: 0 | AA33: 0 | AB33: 0 | AC33: 0 | AD33: 0
A34: 10 | B34: Net Income (Before Taxes and Donations) | C34: =C30+C31 -> 3517183 | D34: =D30+D31 -> 36251 | E34: 20845528 | F34: =F30+F31 -> 2247874.2 | G34: =G30+G31 -> 3435265.7 | H34: =H30+H31 -> 4583389 | I34: =I30+I31 -> 5775126.7 | J34: =J30+J31 -> 6287350.5 | K34: =K30+K31 -> 7892025.2 | L34: =L30+L31 -> 8060054.8 | M34: =M30+M31 -> 11048517 | ... AE34: =AE30+AE31 -> 4847183
A35: 11 | B35: Taxes (Incomes taxes & Other payable to KRA) | E35: 1046054 | F35: 293843 | G35: 29208 | H35: 14604 | I35: 18949 | J35: 18949 | K35: 18948 | L35: 18948 | M35: 18948 | N35: 0 | O35: 18948 | P35: 18948 | Q35: 1046054 | R35: 1046054 | S35: 0 | T35: 0 | U35: 0 | V35: 0 | W35: 0 | X35: 0 | Y35: 0 | Z35: 0 | AA35: 0 | AB35: 0 | AC35: 0 | AD35: 968261 | AE35: 967553
A36: 12 | B36: Net Income (After Taxes before Donations) | C36: =C34-C35 -> 3517183 | D36: =D34-D35 -> 36251 | E36: 19799474 | F36: =F34-F35 -> 1954031.2 | G36: =G34-G35 -> 3406057.7 | H36: =H34-H35 -> 4568785 | I36: =I34-I35 -> 5756177.7 | J36: =J34-J35 -> 6268401.5 | K36: =K34-K35 -> 7873077.2 | L36: =L34-L35 -> 8041106.8 | M36: =M34-M35 -> 11029569 | ... AE36: =AE34-AE35 -> 3879630
A37: 13 | B37: Donations | E37: 0 | F37: 0 | G37: 0 | H37: 0 | I37: 0 | J37: 0 | K37: 0 | L37: 0 | M37: 0 | N37: 0 | O37: 0 | P37: 0 | Q37: 0 | S37: 0 | T37: 0 | U37: 0 | V37: 0 | W37: 0 | X37: 0 | Y37: 0 | Z37: 0 | AA37: 0 | AB37: 0 | AC37: 0 | AD37: 0
A38: 14 | B38: Net Income/(After Taxes and Donations) | C38: =C36-C37 -> 3517183 | D38: =D36-D37 -> 36251 | E38: 19799474 | F38: =F36-F37 -> 1954031.2 | G38: =G36-G37 -> 3406057.7 | H38: =H36-H37 -> 4568785 | I38: =I36-I37 -> 5756177.7 | J38: =J36-J37 -> 6268401.5 | K38: =K36-K37 -> 7873077.2 | L38: =L36-L37 -> 8041106.8 | M38: =M36-M37 -> 11029569 | ... AE38: =AE36-AE37 -> 3879630

Sheet Form 4
E2: 44256
C4: CLASSIFICATION | D4: NO. OF A/Cs | E4: OUTSTANDING LOAN PORTFOLIO(Kshs) | F4: REQUIRED PROVISION | G4: REQUIRED PROVISION AMOUNT(Kshs)
C5: Performing | E5: 1.7184866e+08 | F5: 0.01 | G5: =F5*E5 -> 1718486.6
C6: Watch | E6: 28919298 | F6: 0.05 | G6: =F6*E6 -> 1445964.9
C7: Substandard | E7: 17298338 | F7: 0.25 | G7: =F7*E7 -> 4324584.6
C8: Doubtful | E8: 6778093 | F8: 0.5 | G8: =F8*E8 -> 3389046.5
C9: Loss | E9: 3365364.3 | F9: 1 | G9: =F9*E9 -> 3365364.3
C10: subtotal
C12: Performing | F12: 0.01 | G12: -
C13: Watch | F13: 0.05 | G13: -
C14: Substandard | F14: 0.25 | G14: -
C15: Doubtful | F15: 0.5 | G15: -
C16: Loss | F16: 1 | G16: -
C17: subtotal | E17: =SUM(E5:E9) -> 2.2820975e+08 | G17: =SUM(G5:G9) -> 14243447
D21: NPL | E21: =E7+E8+E9 -> 27441796
D22: PAR | E22: =E21/E17 -> 0.12024813
E25: 44348
C27: CLASSIFICATION | D27: NO. OF A/Cs | E27: OUTSTANDING LOAN PORTFOLIO(Kshs) | F27: REQUIRED PROVISION | G27: REQUIRED PROVISION AMOUNT(Kshs)
C28: Performing | E28: 1.8085307e+08 | F28: 0.01 | G28: =F28*E28 -> 1808530.7
C29: Watch | E29: 31883985 | F29: 0.05 | G29: =F29*E29 -> 1594199.2
C30: Substandard | E30: 17598495 | F30: 0.25 | G30: =F30*E30 -> 4399623.7
C31: Doubtful | E31: 426649.69 | F31: 0.5 | G31: =F31*E31 -> 213324.85
C32: Loss | E32: 4644340.6 | F32: 1 | G32: =F32*E32 -> 4644340.6
C33: subtotal
C35: Performing | F35: 0.01 | G35: -
C36: Watch | F36: 0.05 | G36: -
C37: Substandard | F37: 0.25 | G37: -
C38: Doubtful | F38: 0.5 | G38: -
C39: Loss | F39: 1 | G39: -
C40: subtotal | E40: =SUM(E28:E32) -> 2.3540654e+08 | G40: =SUM(G28:G32) -> 12660019
D44: NPL | E44: =E30+E31+E32 -> 22669485
D45: PAR | E45: =E44/E40 -> 0.096299301
E47: 44734
C48: CLASSIFICATION | D48: NO. OF A/Cs | E48: OUTSTANDING LOAN PORTFOLIO(Kshs) | F48: REQUIRED PROVISION | G48: REQUIRED PROVISION AMOUNT(Kshs)
C49: Performing | D49: 554 | E49: 218517686 | F49: 0.01 | G49: =F49*E49 -> 2185176.9
C50: Watch | D50: 88 | E50: 70200018 | F50: 0.05 | G50: =F50*E50 -> 3510000.9
C51: Substandard | D51: 24 | E51: 7504880 | F51: 0.25 | G51: =F51*E51 -> 1876220
C52: Doubtful | D52: 8 | E52: 2427455 | F52: 0.5 | G52: =F52*E52 -> 1213727.5
C53: Loss | D53: 85 | E53: 5383483 | F53: 1 | G53: =F53*E53 -> 5383483
C54: subtotal
...

Sheet Financials
A1: ACUMEN SACCO KPI's
A3: Year/month | B3: Aud-2019 | C3: Aud-2020 | D3: Jan | E3: Feb | F3: Mar | G3: Apr | H3: May | I3: Jun | J3: Jul | K3: Aug | L3: Sep | M3: Oct | N3: Nov | O3: Dec | P3: Aud-21 | Q3: 44583 | R3: 44614 | S3: 44642 | T3: 44673 | U3: 44703 | V3: 44734 | W3: 44764 | X3: 44774 | Y3: 44805 | Z3: 44835 | AA3: 44866 | AB3: 44896 | AC3: Auditd 2022
A4: Membership
A5: Active | C5: 1241 | P5: 1530
A6: Dormant | C6: 443 | P6: 537
A7: Total Membership | C7: =SUM(C5:C6) -> 1684 | P7: =SUM(P5:P6) -> 2067
A8: Total Assets | B8: ='Balance Sheet'!C26 -> 269371213 | C8: ='Balance Sheet'!D26 -> 2.9341168e+08 | D8: ='Balance Sheet'!E26 -> 3.0347091e+08 | E8: ='Balance Sheet'!F26 -> 3.0736921e+08 | F8: ='Balance Sheet'!G26 -> 3.1233059e+08 | G8: ='Balance Sheet'!H26 -> 3.1792157e+08 | H8: ='Balance Sheet'!I26 -> 3.2701382e+08 | I8: ='Balance Sheet'!J26 -> 3.3141209e+08 | ... AD8: ='Balance Sheet'!AE26 -> 0
A9: Total Deposits | B9: =B10+B11 -> 221060781 | C9: =C10+C11 -> 2.5699707e+08 | D9: =D10+D11 -> 2.6409473e+08 | E9: =E10+E11 -> 2.612806e+08 | F9: =F10+F11 -> 2.6543069e+08 | G9: =G10+G11 -> 2.6947715e+08 | H9: =H10+H11 -> 2.7475918e+08 | I9: =I10+I11 -> 2.774967e+08 | ... AD9: =AD10+AD11 -> 0
A10: Deposits-Members(BOSA) | B10: ='Balance Sheet'!C29 -> 220316533 | C10: ='Balance Sheet'!D29 -> 254720687 | D10: ='Balance Sheet'!E29 -> 2.5960197e+08 | E10: ='Balance Sheet'!F29 -> 258890719 | F10: ='Balance Sheet'!G29 -> 2.6157253e+08 | G10: ='Balance Sheet'!H29 -> 2.6543749e+08 | H10: ='Balance Sheet'!I29 -> 2.6839572e+08 | I10: ='Balance Sheet'!J29 -> 2.7279089e+08 | ... AD10: ='Balance Sheet'!AE29 -> 0
A11: Deposits-Customers(FOSA) | B11: ='Balance Sheet'!C27 -> 744248 | C11: ='Balance Sheet'!D27 -> 2276384.6 | D11: ='Balance Sheet'!E27 -> 4492765.1 | E11: ='Balance Sheet'!F27 -> 2389885 | F11: ='Balance Sheet'!G27 -> 3858157.5 | G11: ='Balance Sheet'!H27 -> 4039661.8 | H11: ='Balance Sheet'!I27 -> 6363453.3 | I11: ='Balance Sheet'!J27 -> 4705808.8 | ... AD11: ='Balance Sheet'!AE27 -> 0
A12: Deposits-Term | B12: ='Balance Sheet'!C28 -> 552646 | C12: ='Balance Sheet'!D28 -> 708204 | D12: ='Balance Sheet'!E28 -> 0 | E12: ='Balance Sheet'!F28 -> 0 | F12: ='Balance Sheet'!G28 -> 0 | G12: ='Balance Sheet'!H28 -> 0 | H12: ='Balance Sheet'!I28 -> 0 | I12: ='Balance Sheet'!J28 -> 0 | ... AD12: ='Balance Sheet'!AE28 -> 0
A13: External Borrowing | B13: ='Balance Sheet'!C37 -> 11609930 | C13: ='Balance Sheet'!D37 -> 0 | D13: ='Balance Sheet'!E37 -> 0 | E13: ='Balance Sheet'!F37 -> 0 | F13: ='Balance Sheet'!G37 -> 0 | G13: ='Balance Sheet'!H37 -> 0 | H13: ='Balance Sheet'!I37 -> 0 | I13: ='Balance Sheet'!J37 -> 0 | ... AD13: ='Balance Sheet'!AE37 -> 0
A15: Share capital and Reserves
A16: Core Capital | B16: =B18-B31 -> 33585269 | C16: =C18-C31 -> 35288951 | D16: =D18-D31 -> 38804807 | E16: =E18-E31 -> 45375371 | F16: =F18-F31 -> 46617873 | G16: =G18-G31 -> 47881097 | H16: =H18-H31 -> 51997658 | I16: =I18-I31 -> 53685986 | ... AD16: =AD18-AD31 -> 0
A17: Institutional Capital | B17: =B16-B19 -> 16308929 | C17: =C16-C19 -> 16318817 | D17: =D16-D19 -> 19696897 | E17: =E16-E19 -> 26147854 | F17: =F16-F19 -> 27252610 | G17: =G16-G19 -> 28440005 | H17: =H16-H19 -> 32488671 | I17: =I16-I19 -> 34093346 | ... AD17: =AD16-AD19 -> 0
A18: Total Capital | B18: =B19+B20+B21+B22+B23+B24 -> 33585269 | C18: =C19+C20+C21+C22+C23+C24 -> 35288951 | D18: =D19+D20+D21+D22+D23+D24 -> 38804807 | E18: =E19+E20+E21+E22+E23+E24 -> 45375371 | F18: =F19+F20+F21+F22+F23+F24 -> 46617873 | G18: =G19+G20+G21+G22+G23+G24 -> 47881097 | H18: =H19+H20+H21+H22+H23+H24 -> 51997658 | I18: =I19+I20+I21+I22+I23+I24 -> 53685986 | ... AD18: =AD19+AD20+AD21+AD22+AD23+AD24 -> 0
A19: Members Share Capital | B19: ='Balance Sheet'!C39 -> 17276340 | C19: ='Balance Sheet'!D39 -> 18970134 | D19: ='Balance Sheet'!E39 -> 19107910 | E19: ='Balance Sheet'!F39 -> 19227517 | F19: ='Balance Sheet'!G39 -> 19365263 | G19: ='Balance Sheet'!H39 -> 19441092 | H19: ='Balance Sheet'!I39 -> 19508987 | I19: ='Balance Sheet'!J39 -> 19592640 | ... AD19: ='Balance Sheet'!AE39 -> 0
A20: Entrance Fees
A21: Retained Earnings | B21: ='Balance Sheet'!C41 -> 10527969 | C21: ='Balance Sheet'!D41 -> 10537857 | D21: ='Balance Sheet'!E41 -> 13911607 | E21: ='Balance Sheet'!F41 -> 20362564 | F21: ='Balance Sheet'!G41 -> 21467320 | G21: ='Balance Sheet'!H41 -> 22654715 | H21: ='Balance Sheet'!I41 -> 26703381 | I21: ='Balance Sheet'!J41 -> 28308056 | ... AD21: ='Balance Sheet'!AE41 -> 0
A22: Appropriation Account | B22: ='Balance Sheet'!C48 -> 0 | C22: ='Balance Sheet'!D48 -> 0 | D22: ='Balance Sheet'!E48 -> 0 | E22: ='Balance Sheet'!F48 -> 0 | F22: ='Balance Sheet'!G48 -> 0 | G22: ='Balance Sheet'!H48 -> 0 | H22: ='Balance Sheet'!I48 -> 0 | I22: ='Balance Sheet'!J48 -> 0 | ... AD22: ='Balance Sheet'!AE48 -> 0
A23: Statutory Reserves | B23: ='Balance Sheet'!C45 -> 5780960 | C23: ='Balance Sheet'!D45 -> 5780960 | D23: ='Balance Sheet'!E45 -> 5785290 | E23: ='Balance Sheet'!F45 -> 5785290 | F23: ='Balance Sheet'!G45 -> 5785290 | G23: ='Balance Sheet'!H45 -> 5785290 | H23: ='Balance Sheet'!I45 -> 5785290 | I23: ='Balance Sheet'!J45 -> 5785290 | ... AD23: ='Balance Sheet'!AE45 -> 0
A24: Capital Reserves | B24: ='Balance Sheet'!C46 -> 0 | C24: ='Balance Sheet'!D46 -> 0 | D24: ='Balance Sheet'!E46 -> 0 | E24: ='Balance Sheet'!F46 -> 0 | F24: ='Balance Sheet'!G46 -> 0 | G24: ='Balance Sheet'!H46 -> 0 | H24: ='Balance Sheet'!I46 -> 0 | I24: ='Balance Sheet'!J46 -> 0 | ... K24: ='Balance Sheet'!L46 -> 0 | L24: ='Balance Sheet'!M49 -> 0 | M24: ='Balance Sheet'!N49 -> 0 | N24: ='Balance Sheet'!O49 -> 0 | O24: ='Balance Sheet'!P49 -> 0 | P24: ='Balance Sheet'!Q47 -> 0 | Q24: ='Balance Sheet'!R46 -> 0 | R24: ='Balance Sheet'!S46 -> 0 | S24: ='Balance Sheet'!T46 -> 0 | T24: ='Balance Sheet'!U46 -> 0 | U24: ='Balance Sheet'!V46 -> 0 | V24: ='Balance Sheet'!W46 -> 0 | W24: ='Balance Sheet'!X49 -> 0 | X24: ='Balance Sheet'!Y49 -> 0 | Y24: ='Balance Sheet'!Z49 -> 0 | Z24: ='Balance Sheet'!AA49 -> 0 | AA24: ='Balance Sheet'!AB49 -> 0 | AB24: ='Balance Sheet'!AC49 -> 0 | AC24: ='Balance Sheet'!AD49 -> 0 | AD24: ='Balance Sheet'!AE49 -> 0
A25: Supplementary Capital & reserves
A26: Proposed Dividends
A27: Benevolent Fund
A28: Investments | B28: =B29+B30+B32 -> 115855 | C28: =C29+C30+C32 -> 115855 | D28: =D29+D30+D32 -> 83379797 | E28: =E29+E30+E32 -> 83937541 | F28: =F29+F30+F32 -> 84567427 | G28: =G29+G30+G32 -> 71152315 | H28: =H29+H30+H32 -> 71695527 | I28: =I29+I30+I32 -> 72230238 | ... AD28: =AD29+AD30+AD32 -> 0
A29: Govt bills | B29: ='Balance Sheet'!C8 -> 115855 | C29: ='Balance Sheet'!D8 -> 115855 | D29: ='Balance Sheet'!E8 -> 41747826 | E29: ='Balance Sheet'!F8 -> 42026698 | F29: ='Balance Sheet'!G8 -> 42341641 | G29: ='Balance Sheet'!H8 -> 35634085 | H29: ='Balance Sheet'!I8 -> 35905691 | I29: ='Balance Sheet'!J8 -> 36173047 | ... AD29: ='Balance Sheet'!AE8 -> 0
A30: Investments in naccos | B30: ='Balance Sheet'!C11 -> 0 | C30: ='Balance Sheet'!D11 -> 0 | D30: ='Balance Sheet'!E11 -> 0 | E30: ='Balance Sheet'!F11 -> 0 | F30: ='Balance Sheet'!G11 -> 0 | G30: ='Balance Sheet'!H11 -> 0 | H30: ='Balance Sheet'!I11 -> 0 | I30: ='Balance Sheet'!J11 -> 0 | ... AD30: ='Balance Sheet'!AE11 -> 0
A31: Equity Investments (at cost) | B31: ='Balance Sheet'!C9 -> 0 | C31: ='Balance Sheet'!D9 -> 0 | D31: ='Balance Sheet'!E9 -> 0 | E31: ='Balance Sheet'!F9 -> 0 | F31: ='Balance Sheet'!G9 -> 0 | G31: ='Balance Sheet'!H9 -> 0 | H31: ='Balance Sheet'!I9 -> 0 | I31: ='Balance Sheet'!J9 -> 0 | ... AD31: ='Balance Sheet'!AE9 -> 0
A32: Deposits in KUSCCO CFP | B32: ='Balance Sheet'!C10 -> 0 | C32: ='Balance Sheet'!D10 -> 0 | D32: ='Balance Sheet'!E10 -> 41631971 | E32: ='Balance Sheet'!F10 -> 41910843 | F32: ='Balance Sheet'!G10 -> 42225786 | G32: ='Balance Sheet'!H10 -> 35518230 | H32: ='Balance Sheet'!I10 -> 35789836 | I32: ='Balance Sheet'!J10 -> 36057192 | ... AD32: ='Balance Sheet'!AE10 -> 0
A33: Net Loans & Advances | B33: =B34-B35 -> 246137216 | C33: =C34-C35 -> 2.1688273e+08 | D33: =D34-D35 -> 2.2332317e+08 | E33: =E34-E35 -> 223644117 | F33: =F34-F35 -> 2.2853079e+08 | G33: =G34-G35 -> 2.3601268e+08 | H33: =H34-H35 -> 2.4549239e+08 | I33: =I34-I35 -> 2.4634833e+08 | ... AD33: =AD34-AD35 -> 0
A34: Gross Loans & advances | B34: ='Balance Sheet'!C14 -> 247597572 | C34: ='Balance Sheet'!D14 -> 2.3820198e+08 | D34: ='Balance Sheet'!E14 -> 2.4320502e+08 | E34: ='Balance Sheet'!F14 -> 238585005 | F34: ='Balance Sheet'!G14 -> 2.4437561e+08 | G34: ='Balance Sheet'!H14 -> 2.5338738e+08 | H34: ='Balance Sheet'!I14 -> 2.593564e+08 | I34: ='Balance Sheet'!J14 -> 2.607803e+08 | ... K34: ='Balance Sheet'!L14 -> 2.9282299e+08 | L34: ='Balance Sheet'!M13 -> 275878545 | M34: ='Balance Sheet'!N13 -> 2.8364628e+08 | N34: ='Balance Sheet'!O13 -> 2.9211013e+08 | O34: ='Balance Sheet'!P13 -> 300860862 | P34: ='Balance Sheet'!Q13 -> 300860863 | Q34: ='Balance Sheet'!R13 -> 3.0101902e+08 | R34: ='Balance Sheet'!S13 -> 2.9725747e+08 | S34: ='Balance Sheet'!T13 -> 302970378 | ... AD34: ='Balance Sheet'!AE13 -> 0
A35: Allowance for loan losses | B35: ='Balance Sheet'!C15 -> 1460356 | C35: ='Balance Sheet'!D15 -> 21319244 | D35: ='Balance Sheet'!E15 -> 19881849 | E35: ='Balance Sheet'!F15 -> 14940888 | F35: ='Balance Sheet'!G15 -> 15844821 | G35: ='Balance Sheet'!H15 -> 17374702 | H35: ='Balance Sheet'!I15 -> 13864013 | I35: ='Balance Sheet'!J15 -> 14431971 | ... AD35: ='Balance Sheet'!AE15 -> 0
A37: Non-Earning Assets | B37: ='Balance Sheet'!C6+'Balance Sheet'!C15+'Balance Sheet'!C19 -> 12043873 | C37: ='Balance Sheet'!D6+'Balance Sheet'!D15+'Balance Sheet'!D19 -> 81099175 | D37: ='Balance Sheet'!E6+'Balance Sheet'!E15+'Balance Sheet'!E19 -> 37470374 | E37: ='Balance Sheet'!F6+'Balance Sheet'!F15+'Balance Sheet'!F19 -> 32080806 | F37: ='Balance Sheet'!G6+'Balance Sheet'!G15+'Balance Sheet'!G19 -> 32515152 | G37: ='Balance Sheet'!H6+'Balance Sheet'!H15+'Balance Sheet'!H19 -> 37704843 | H37: ='Balance Sheet'!I6+'Balance Sheet'!I15+'Balance Sheet'!I19 -> 35157885 | I37: ='Balance Sheet'!J6+'Balance Sheet'!J15+'Balance Sheet'!J19 -> 38742112 | ... AD37: ='Balance Sheet'!AE6+'Balance Sheet'!AE15+'Balance Sheet'!AE19 -> 0
A38: Property and Equipment | B38: ='Balance Sheet'!C19 -> 0 | C38: ='Balance Sheet'!D19 -> 0 | D38: ='Balance Sheet'!E19 -> 0 | E38: ='Balance Sheet'!F19 -> 0 | F38: ='Balance Sheet'!G19 -> 0 | G38: ='Balance Sheet'!H19 -> 0 | H38: ='Balance Sheet'!I19 -> 0 | I38: ='Balance Sheet'!J19 -> 0 | ... AD38: ='Balance Sheet'!AE19 -> 0
Q39: =Q34-AB34 -> -6283519
A41: Turnover | B41: =B42+B44+B45 -> 32774205 | C41: =C42+C44+C45 -> 34090071 | D41: =D42+D44+D45 -> 3418741.5 | E41: =E42+E44+E45 -> 6535327 | F41: =F42+F44+F45 -> 10453856 | G41: =G42+G44+G45 -> 14017566 | H41: =H42+H44+H45 -> 17535951 | I41: =I42+I44+I45 -> 21401480 | ... AD41: =AD42+AD44+AD45 -> 0
A42: Loan Interest | B42: ='Income Stat.'!C6 -> 26357606 | C42: ='Income Stat.'!D6 -> 29009435 | D42: ='Income Stat.'!F6 -> 2439265 | E42: ='Income Stat.'!G6 -> 4918501 | F42: ='Income Stat.'!H6 -> 7397029 | G42: ='Income Stat.'!I6 -> 9889192 | H42: ='Income Stat.'!J6 -> 12442331 | I42: ='Income Stat.'!K6 -> 15103290 | J42: ='Income Stat.'!L6 -> 17756062 | K42: ='Income Stat.'!M6 -> 20447140 | ... AD42: ='Income Stat.'!AF6 -> 0
A43: Yield on loans | B43: ='Income Stat.'!C6/'Income Stat.'!C14 -> 2.2702493 | C43: ='Income Stat.'!D6/'Income Stat.'!D14 -> #DIV/0! | D43: ='Income Stat.'!F6/'Income Stat.'!F14 -> #DIV/0! | E43: ='Income Stat.'!G6/'Income Stat.'!G14 -> #DIV/0! | F43: ='Income Stat.'!H6/'Income Stat.'!H14 -> #DIV/0! | G43: ='Income Stat.'!I6/'Income Stat.'!I14 -> #DIV/0! | H43: ='Income Stat.'!J6/'Income Stat.'!J14 -> #DIV/0! | I43: ='Income Stat.'!K6/'Income Stat.'!K14 -> #DIV/0! | J43: ='Income Stat.'!L6/'Income Stat.'!L14 -> #DIV/0! | K43: ='Income Stat.'!M6/'Income Stat.'!M14 -> #DIV/0! | ... AD43: ='Income Stat.'!AF6/'Income Stat.'!AF14 -> #DIV/0!
A44: Income from investments | B44: ='Income Stat.'!C8 -> 6416599 | C44: ='Income Stat.'!D8 -> 5080636 | D44: ='Income Stat.'!F8 -> 301385.13 | E44: ='Income Stat.'!G8 -> 663441 | F44: ='Income Stat.'!H8 -> 1039283.9 | G44: ='Income Stat.'!I8 -> 1393570.8 | H44: ='Income Stat.'!J8 -> 1723459.6 | I44: ='Income Stat.'!K8 -> 2177086.3 | J44: ='Income Stat.'!L8 -> 2577944.4 | K44: ='Income Stat.'!M8 -> 2992116.4 | ... AD44: ='Income Stat.'!AF8 -> 0
...

Sheet CAEL
A1: ACUMEN SACCO CAELS 2021
C2: Regulatory Stds | D2: Aud-2019 | E2: Aud-2020 | F2: Jan | G2: Feb | H2: Mar | I2: Apr | J2: May | K2: Jun | L2: Aug | M2: Sep | N2: Oct | O2: Nov | P2: Dec | Q2: Aud-21 | R2: 44583 | S2: 44614 | T2: 44642 | U2: 44673 | V2: 44703 | W2: 44734 | X2: 44743 | Y2: 44774 | Z2: 44805 | AA2: 44835 | AB2: 44866 | AC2: 44896 | AD2: Audited 2022
A3: CAPITAL ADEQUACY | B3: Core Capital | C3: 10 M | D3: =Financials!B16 -> 33585269 | E3: =Financials!C16 -> 35288951 | F3: =Financials!D16 -> 38804807 | G3: =Financials!E16 -> 45375371 | H3: =Financials!F16 -> 46617873 | I3: =Financials!G16 -> 47881097 | J3: =Financials!H16 -> 51997658 | K3: =Financials!I16 -> 53685986 | L3: =Financials!K16 -> 58350435 | M3: =Financials!L16 -> 61466479 | N3: =Financials!M16 -> 65489689 | O3: =Financials!N16 -> 68024727 | P3: =Financials!O16 -> 53706746 | Q3: =Financials!P16 -> 53706746 | R3: =Financials!Q16 -> 52994015 | S3: =Financials!R16 -> 57992011 | ... AE3: =Financials!AD16 -> 0
B4: CCA | C4: 0.1 | D4: =Financials!B16/Financials!B8 -> 0.12468025 | E4: =Financials!C16/Financials!C8 -> 0.12027112 | F4: =Financials!D16/Financials!D8 -> 0.12786994 | G4: =Financials!E16/Financials!E8 -> 0.14762497 | H4: =Financials!F16/Financials!F8 -> 0.14925811 | I4: =Financials!G16/Financials!G8 -> 0.15060663 | J4: =Financials!H16/Financials!H8 -> 0.15900753 | K4: =Financials!I16/Financials!I8 -> 0.16199163 | L4: =Financials!K16/Financials!K8 -> 0.16480878 | M4: =Financials!L16/Financials!L8 -> 0.17625146 | N4: =Financials!M16/Financials!M8 -> 0.18321987 | O4: =Financials!N16/Financials!N8 -> 0.1870326 | P4: =Financials!O16/Financials!O8 -> 0.14537453 | Q4: =Financials!P16/Financials!P8 -> 0.14537453 | R4: =Financials!Q16/Financials!Q8 -> 0.14263007 | S4: =Financials!R16/Financials!R8 -> 0.15740942 | ... AD4: =Financials!AC16/Financials!AC8 -> 0.15718158
B5: CCD | C5: 0.08 | D5: =Financials!B16/Financials!B9 -> 0.15192776 | E5: =Financials!C16/Financials!C9 -> 0.13731266 | F5: =Financials!D16/Financials!D9 -> 0.14693518 | G5: =Financials!E16/Financials!E9 -> 0.17366529 | H5: =Financials!F16/Financials!F9 -> 0.17563106 | I5: =Financials!G16/Financials!G9 -> 0.17768148 | J5: =Financials!H16/Financials!H9 -> 0.18924812 | K5: =Financials!I16/Financials!I9 -> 0.19346531 | L5: =Financials!K16/Financials!K9 -> 0.1975899 | M5: =Financials!L16/Financials!L9 -> 0.21428256 | N5: =Financials!M16/Financials!M9 -> 0.22464595 | O5: =Financials!N16/Financials!N9 -> 0.23032685 | P5: =Financials!O16/Financials!O9 -> 0.18123519 | Q5: =Financials!P16/Financials!P9 -> 0.18182956 | R5: =Financials!Q16/Financials!Q9 -> 0.17715857 | S5: =Financials!R16/Financials!R9 -> 0.18942625 | ... AD5: =Financials!AC16/Financials!AC9 -> 0.19780311
B6: ICA | C6: 0.08 | D6: =(Financials!B18-Financials!B19)/Financials!B8 -> 0.060544439 | E6: =(Financials!C18-Financials!C19)/Financials!C8 -> 0.055617477 | F6: =(Financials!D18-Financials!D19)/Financials!D8 -> 0.064905388 | G6: =(Financials!E18-Financials!E19)/Financials!E8 -> 0.085069857 | H6: =(Financials!F18-Financials!F19)/Financials!F8 -> 0.087255657 | I6: =(Financials!G18-Financials!G19)/Financials!G8 -> 0.089456041 | J6: =(Financials!H18-Financials!H19)/Financials!H8 -> 0.099349536 | K6: =(Financials!I18-Financials!I19)/Financials!I8 -> 0.10287297 | L6: =(Financials!K18-Financials!K19)/Financials!K8 -> 0.10901382 | M6: =(Financials!L18-Financials!L19)/Financials!L8 -> 0.11934032 | N6: =(Financials!M18-Financials!M19)/Financials!M8 -> 0.12739578 | O6: =(Financials!N18-Financials!N19)/Financials!N8 -> 0.13040344 | P6: =(Financials!O18-Financials!O19)/Financials!O8 -> 0.089413147 | Q6: =(Financials!P18-Financials!P19)/Financials!P8 -> 0.089413147 | R6: =(Financials!Q18-Financials!Q19)/Financials!Q8 -> 0.086608444 | S6: =(Financials!R18-Financials!R19)/Financials!R8 -> 0.1002778 | ... AD6: =(Financials!AC18-Financials!AC19)/Financials!AC8 -> 0.083894175
A7: ASSET QUALITY | B7: A/LNPL30
B8: NPL30 | H8: ='Form 4'!E22 -> 0.12024813 | K8: ='Form 4'!E45 -> 0.096299301
B9: Non-earning Asset ratio | C9: Max 10% | D9: =('Balance Sheet'!C7+'Balance Sheet'!C20)/'Balance Sheet'!C26 -> 0.045601306 | E9: =('Balance Sheet'!D7+'Balance Sheet'!D20)/'Balance Sheet'!D26 -> 0.052726311 | F9: =('Balance Sheet'!E7+'Balance Sheet'!E20)/'Balance Sheet'!E26 -> 0.068577864 | G9: =('Balance Sheet'!F7+'Balance Sheet'!F20)/'Balance Sheet'!F26 -> 0.079898936 | H9: =('Balance Sheet'!G7+'Balance Sheet'!G20)/'Balance Sheet'!G26 -> 0.079364072 | I9: =('Balance Sheet'!H7+'Balance Sheet'!H20)/'Balance Sheet'!H26 -> 0.081607121 | J9: =('Balance Sheet'!I7+'Balance Sheet'!I20)/'Balance Sheet'!I26 -> 0.074375649 | K9: =('Balance Sheet'!J7+'Balance Sheet'!J20)/'Balance Sheet'!J26 -> 0.074169206 | L9: =('Balance Sheet'!L7+'Balance Sheet'!L20)/'Balance Sheet'!L26 -> 0.060703797 | M9: =('Balance Sheet'!M7+'Balance Sheet'!M20)/'Balance Sheet'!M26 -> 0.063509137 | N9: =('Balance Sheet'!N7+'Balance Sheet'!N20)/'Balance Sheet'!N26 -> 0.05794173 | O9: =('Balance Sheet'!O7+'Balance Sheet'!O20)/'Balance Sheet'!O26 -> 0.056996232 | P9: =('Balance Sheet'!P7+'Balance Sheet'!P20)/'Balance Sheet'!P26 -> 0.031867556 | Q9: =('Balance Sheet'!Q7+'Balance Sheet'!Q20)/'Balance Sheet'!Q26 -> 0.031867556 | R9: =('Balance Sheet'!R7+'Balance Sheet'!R20)/'Balance Sheet'!R26 -> 0.033169938 | S9: =('Balance Sheet'!S7+'Balance Sheet'!S20)/'Balance Sheet'!S26 -> 0.047761634 | ... AD9: =('Balance Sheet'!AD7+'Balance Sheet'!AD20)/'Balance Sheet'!AD26 -> 0.04639226
B10: Land and Building ratio | C10: Max 5% | D10: =('Balance Sheet'!C21+'Balance Sheet'!C22)/'Balance Sheet'!C26 -> 0.013599174 | E10: =('Balance Sheet'!D21+'Balance Sheet'!D22)/'Balance Sheet'!D26 -> 0.012972563 | F10: =('Balance Sheet'!E21+'Balance Sheet'!E22)/'Balance Sheet'!E26 -> 0.012648004 | G10: =('Balance Sheet'!F21+'Balance Sheet'!F22)/'Balance Sheet'!F26 -> 0.012324922 | H10: =('Balance Sheet'!G21+'Balance Sheet'!G22)/'Balance Sheet'!G26 -> 0.012100039 | I10: =('Balance Sheet'!H21+'Balance Sheet'!H22)/'Balance Sheet'!H26 -> 0.011729976 | J10: =('Balance Sheet'!I21+'Balance Sheet'!I22)/'Balance Sheet'!I26 -> 0.013127924 | K10: =('Balance Sheet'!J21+'Balance Sheet'!J22)/'Balance Sheet'!J26 -> 0.013264777 | L10: =('Balance Sheet'!L21+'Balance Sheet'!L22)/'Balance Sheet'!L26 -> 0.012233062 | M10: =('Balance Sheet'!M21+'Balance Sheet'!M22)/'Balance Sheet'!M26 -> 0.014218796 | N10: =('Balance Sheet'!N21+'Balance Sheet'!N22)/'Balance Sheet'!N26 -> 0.012947452 | O10: =('Balance Sheet'!O21+'Balance Sheet'!O22)/'Balance Sheet'!O26 -> 0.012832117 | P10: =('Balance Sheet'!P21+'Balance Sheet'!P22)/'Balance Sheet'!P26 -> 0.014082938 | Q10: =('Balance Sheet'!Q21+'Balance Sheet'!Q22)/'Balance Sheet'!Q26 -> 0.014082938 | R10: =('Balance Sheet'!R21+'Balance Sheet'!R22)/'Balance Sheet'!R26 -> 0.013841414 | S10: =('Balance Sheet'!S21+'Balance Sheet'!S22)/'Balance Sheet'!S26 -> 0.013796282 | ... AD10: =('Balance Sheet'!AD21+'Balance Sheet'!AD22)/'Balance Sheet'!AD26 -> 0.018423644
A11: EARNINGS | B11: Non-Government Investment to Deposit ratio | C11: Max 5% | D11: ='Balance Sheet'!C11/'Balance Sheet'!C29 -> 0 | E11: ='Balance Sheet'!D11/'Balance Sheet'!D29 -> 0 | F11: ='Balance Sheet'!E11/'Balance Sheet'!E29 -> 0 | G11: ='Balance Sheet'!F11/'Balance Sheet'!F29 -> 0 | H11: ='Balance Sheet'!G11/'Balance Sheet'!G29 -> 0 | I11: ='Balance Sheet'!H11/'Balance Sheet'!H29 -> 0 | J11: ='Balance Sheet'!I11/'Balance Sheet'!I29 -> 0 | K11: ='Balance Sheet'!J11/'Balance Sheet'!J29 -> 0 | L11: ='Balance Sheet'!L11/'Balance Sheet'!L29 -> 0 | M11: ='Balance Sheet'!M11/'Balance Sheet'!M29 -> 0 | N11: ='Balance Sheet'!N11/'Balance Sheet'!N29 -> 0 | O11: ='Balance Sheet'!O11/'Balance Sheet'!O29 -> 0 | P11: ='Balance Sheet'!P11/'Balance Sheet'!P29 -> 0 | Q11: ='Balance Sheet'!Q11/'Balance Sheet'!Q29 -> 0 | R11: ='Balance Sheet'!R11/'Balance Sheet'!R29 -> 0 | S11: ='Balance Sheet'!S11/'Balance Sheet'!S29 -> 0 | ... AD11: ='Balance Sheet'!AD11/'Balance Sheet'!AD29 -> 0
B12: Non-Government Investment to Core Capital ratio | C12: Max 40% | D12: ='Balance Sheet'!C11/Financials!B16 -> 0 | E12: ='Balance Sheet'!D11/Financials!C16 -> 0 | F12: ='Balance Sheet'!E11/Financials!D16 -> 0 | G12: ='Balance Sheet'!F11/Financials!E16 -> 0 | H12: ='Balance Sheet'!G11/Financials!F16 -> 0 | I12: ='Balance Sheet'!H11/Financials!G16 -> 0 | J12: ='Balance Sheet'!I11/Financials!H16 -> 0 | K12: ='Balance Sheet'!J11/Financials!I16 -> 0 | L12: ='Balance Sheet'!L11/Financials!K16 -> 0 | M12: ='Balance Sheet'!M11/Financials!L16 -> 0 | N12: ='Balance Sheet'!N11/Financials!M16 -> 0 | O12: ='Balance Sheet'!O11/Financials!N16 -> 0 | P12: ='Balance Sheet'!P11/Financials!O16 -> 0 | Q12: ='Balance Sheet'!Q11/Financials!P16 -> 0 | R12: ='Balance Sheet'!R11/Financials!Q16 -> 0 | S12: ='Balance Sheet'!S11/Financials!R16 -> 0 | ... AD12: ='Balance Sheet'!AD11/Financials!AC16 -> 0
B13: Gross loans/TA | D13: =Financials!B34/Financials!B8 -> 0.91916864 | E13: =Financials!C34/Financials!C8 -> 0.81183536 | F13: =Financials!D34/Financials!D8 -> 0.80141132 | G13: =Financials!E34/Financials!E8 -> 0.77621636 | H13: =Financials!F34/Financials!F8 -> 0.78242612 | I13: =Financials!G34/Financials!G8 -> 0.79701224 | J13: =Financials!H34/Financials!H8 -> 0.79310533 | K13: =Financials!I34/Financials!I8 -> 0.78687625 | L13: =Financials!K34/Financials!K8 -> 0.82706837 | M13: =Financials!L34/Financials!L8 -> 0.79106526 | N13: =Financials!M34/Financials!M8 -> 0.79355448 | O13: =Financials!N34/Financials!N8 -> 0.80315084 | P13: =Financials!O34/Financials!O8 -> 0.81437639 | Q13: =Financials!P34/Financials!P8 -> 0.81437639 | R13: =Financials!Q34/Financials!Q8 -> 0.81017387 | S13: =Financials!R34/Financials!R8 -> 0.80685466 | ... AD13: =Financials!AC34/Financials!AC8 -> 0.76180542
B14: ROA | D14: ='Income Stat.'!C38/Financials!B8 -> 0.013057011 | E14: ='Income Stat.'!D38/Financials!C8 -> 0.00012354996 | F14: ='Income Stat.'!F38/Financials!D8 -> 0.0064389408 | G14: ='Income Stat.'!G38/Financials!E8 -> 0.011081324 | H14: ='Income Stat.'!H38/Financials!F8 -> 0.014628042 | I14: ='Income Stat.'!I38/Financials!G8 -> 0.018105653 | J14: ='Income Stat.'!J38/Financials!H8 -> 0.019168614 | K14: ='Income Stat.'!K38/Financials!I8 -> 0.023756156 | L14: ='Income Stat.'!M38/Financials!K8 -> 0.031152636 | M14: ='Income Stat.'!N38/Financials!L8 -> 0.038849773 | N14: ='Income Stat.'!O38/Financials!M8 -> 0.044718358 | O14: ='Income Stat.'!P38/Financials!N8 -> 0.049150746 | P14: ='Income Stat.'!Q38/Financials!O8 -> 0.045583441 | Q14: ='Income Stat.'!R38/Financials!P8 -> 0.053593597 | R14: ='Income Stat.'!S38/Financials!Q8 -> -0.0022975281 | S14: ='Income Stat.'!T38/Financials!R8 -> 0.0020514434 | ... AD14: ='Income Stat.'!AE38/Financials!AC8 -> 0.0096176333
B15: Cost Income ratio | D15: ='Income Stat.'!C24/('Income Stat.'!C20-'Income Stat.'!C22) -> 0.81990869 | E15: ='Income Stat.'!D24/('Income Stat.'!D20-'Income Stat.'!D22) -> 0.99742769 | F15: ='Income Stat.'!F24/('Income Stat.'!F20-'Income Stat.'!F22) -> 0.33458967 | G15: ='Income Stat.'!G24/('Income Stat.'!G20-'Income Stat.'!G22) -> 0.47056276 | H15: ='Income Stat.'!H24/('Income Stat.'!H20-'Income Stat.'!H22) -> 0.51972935 | I15: ='Income Stat.'!I24/('Income Stat.'!I20-'Income Stat.'!I22) -> 0.50054798 | J15: ='Income Stat.'!J24/('Income Stat.'!J20-'Income Stat.'!J22) -> 0.52156325 | K15: ='Income Stat.'!K24/('Income Stat.'!K20-'Income Stat.'!K22) -> 0.51951314 | L15: ='Income Stat.'!M24/('Income Stat.'!M20-'Income Stat.'!M22) -> 0.51977307 | M15: ='Income Stat.'!N24/('Income Stat.'!N20-'Income Stat.'!N22) -> 0.4947377 | N15: ='Income Stat.'!O24/('Income Stat.'!O20-'Income Stat.'!O22) -> 0.4732031 | O15: ='Income Stat.'!P24/('Income Stat.'!P20-'Income Stat.'!P22) -> 0.46533708 | P15: ='Income Stat.'!Q24/('Income Stat.'!Q20-'Income Stat.'!Q22) -> 0.72325861 | Q15: ='Income Stat.'!R24/('Income Stat.'!R20-'Income Stat.'!R22) -> 0.65598597 | R15: ='Income Stat.'!S24/('Income Stat.'!S20-'Income Stat.'!S22) -> 1.5254311 | S15: ='Income Stat.'!T24/('Income Stat.'!T20-'Income Stat.'!T22) -> 0.86467805 | ... AD15: ='Income Stat.'!AE24/('Income Stat.'!AE20-'Income Stat.'!AE22) -> 0.84823291
B16: Operating Expense ratio | D16: ='Income Stat.'!C24/'Income Stat.'!C4 -> 0.48857981 | E16: ='Income Stat.'!D24/'Income Stat.'!D4 -> 0.41233554 | F16: ='Income Stat.'!F24/'Income Stat.'!F4 -> 0.3306197 | G16: ='Income Stat.'!G24/'Income Stat.'!G4 -> 0.46719274 | H16: ='Income Stat.'!H24/'Income Stat.'!H4 -> 0.47446194 | I16: ='Income Stat.'!I24/'Income Stat.'!I4 -> 0.41289616 | J16: ='Income Stat.'!J24/'Income Stat.'!J4 -> 0.39085963 | K16: ='Income Stat.'!K24/'Income Stat.'!K4 -> 0.39871234 | L16: ='Income Stat.'!M24/'Income Stat.'!M4 -> 0.39998619 | M16: ='Income Stat.'!N24/'Income Stat.'!N4 -> 0.39488848 | N16: ='Income Stat.'!O24/'Income Stat.'!O4 -> 0.38359298 | O16: ='Income Stat.'!P24/'Income Stat.'!P4 -> 0.37405476 | P16: ='Income Stat.'!Q24/'Income Stat.'!Q4 -> 0.45054356 | Q16: ='Income Stat.'!R24/'Income Stat.'!R4 -> 0.45054365 | R16: ='Income Stat.'!S24/'Income Stat.'!S4 -> 0.64827826 | S16: ='Income Stat.'!T24/'Income Stat.'!T4 -> 0.61471531 | ... AD16: ='Income Stat.'!AE24/'Income Stat.'!AE4 -> 0.53143604
A17: LIQUIDITY | B17: MIN LIQ ratio | C17: Min 15% | D17: ='Balance Sheet'!C4/'Balance Sheet'!C27 -> 14.557598 | E17: ='Balance Sheet'!D4/'Balance Sheet'!D27 -> 26.771652 | F17: ='Balance Sheet'!E4/'Balance Sheet'!E27 -> 3.9148552 | G17: ='Balance Sheet'!F4/'Balance Sheet'!F27 -> 7.1718589 | H17: ='Balance Sheet'!G4/'Balance Sheet'!G27 -> 4.320801 | I17: ='Balance Sheet'!H4/'Balance Sheet'!H27 -> 5.0326344 | J17: ='Balance Sheet'!I4/'Balance Sheet'!I27 -> 3.3462761 | K17: ='Balance Sheet'!J4/'Balance Sheet'!J27 -> 5.1659858 | L17: ='Balance Sheet'!L4/'Balance Sheet'!L27 -> 1.0122343 | M17: ='Balance Sheet'!M4/'Balance Sheet'!M27 -> 2.0382708 | N17: ='Balance Sheet'!N4/'Balance Sheet'!N27 -> 2.0216603 | O17: ='Balance Sheet'!O4/'Balance Sheet'!O27 -> 1.6900092 | P17: ='Balance Sheet'!P4/'Balance Sheet'!P27 -> 2.1284735 | Q17: ='Balance Sheet'!Q4/'Balance Sheet'!Q27 -> 7.1772906 | R17: ='Balance Sheet'!R4/'Balance Sheet'!R27 -> 2.3054162 | S17: ='Balance Sheet'!S4/'Balance Sheet'!S27 -> 1.4496616 | ... AD17: ='Balance Sheet'!AD4/'Balance Sheet'!AD27 -> 9.5756483
B18: Technical LIQ ratio | D18: ='Balance Sheet'!C4/'Balance Sheet'!C29 -> 0.049176804 | E18: ='Balance Sheet'!D4/'Balance Sheet'!D29 -> 0.23925255 | F18: ='Balance Sheet'!E4/'Balance Sheet'!E29 -> 0.067751892 | G18: ='Balance Sheet'!F4/'Balance Sheet'!F29 -> 0.066205223 | H18: ='Balance Sheet'!G4/'Balance Sheet'!G29 -> 0.063731199 | I18: ='Balance Sheet'!H4/'Balance Sheet'!H29 -> 0.076591069 | J18: ='Balance Sheet'!I4/'Balance Sheet'!I29 -> 0.079337597 | K18: ='Balance Sheet'!J4/'Balance Sheet'!J29 -> 0.089116396 | L18: ='Balance Sheet'!L4/'Balance Sheet'!L29 -> 0.063973472 | M18: ='Balance Sheet'!M4/'Balance Sheet'!M29 -> 0.048597189 | N18: ='Balance Sheet'!N4/'Balance Sheet'!N29 -> 0.055351653 | O18: ='Balance Sheet'!O4/'Balance Sheet'!O29 -> 0.045981957 | P18: ='Balance Sheet'!P4/'Balance Sheet'!P29 -> 0.06565129 | Q18: ='Balance Sheet'!Q4/'Balance Sheet'!Q29 -> 0.19719361 | R18: ='Balance Sheet'!R4/'Balance Sheet'!R29 -> 0.068815976 | S18: ='Balance Sheet'!S4/'Balance Sheet'!S29 -> 0.0510403 | ... AD18: ='Balance Sheet'!AD4/'Balance Sheet'!AD29 -> 0.24723228
B19: External Borrowing ratio | C19: Max 25% | D19: ='Balance Sheet'!C37/'Balance Sheet'!C26 -> 0.043100114 | E19: ='Balance Sheet'!D37/'Balance Sheet'!D26 -> 0 | F19: ='Balance Sheet'!E37/'Balance Sheet'!E26 -> 0 | G19: ='Balance Sheet'!F37/'Balance Sheet'!F26 -> 0 | H19: ='Balance Sheet'!G37/'Balance Sheet'!G26 -> 0 | I19: ='Balance Sheet'!H37/'Balance Sheet'!H26 -> 0 | J19: ='Balance Sheet'!I37/'Balance Sheet'!I26 -> 0 | K19: ='Balance Sheet'!J37/'Balance Sheet'!J26 -> 0 | L19: ='Balance Sheet'!L38/'Balance Sheet'!L26 -> 0.83519122 | M19: ='Balance Sheet'!M38/'Balance Sheet'!M26 -> 0.82374854 | N19: ='Balance Sheet'!N38/'Balance Sheet'!N26 -> 0.81678013 | O19: ='Balance Sheet'!O38/'Balance Sheet'!O26 -> 0.8129674 | P19: ='Balance Sheet'!P38/'Balance Sheet'!P26 -> 0.85462547 | Q19: ='Balance Sheet'!Q38/'Balance Sheet'!Q26 -> 0.85462547 | R19: ='Balance Sheet'!R38/'Balance Sheet'!R26 -> 0.85736993 | S19: ='Balance Sheet'!S38/'Balance Sheet'!S26 -> 0.84259058 | ... W19: ='Balance Sheet'!W38/'Balance Sheet'!W26 -> 0.84270331 | X19: ='Balance Sheet'!X39/'Balance Sheet'!X26 -> 0.057437337 | Y19: ='Balance Sheet'!Y38/'Balance Sheet'!Y26 -> 0.83569242 | Z19: ='Balance Sheet'!Z38/'Balance Sheet'!Z26 -> 0.82925243 | AA19: ='Balance Sheet'!AA38/'Balance Sheet'!AA26 -> 0.82279777 | AB19: ='Balance Sheet'!AB38/'Balance Sheet'!AB26 -> 0.81956426 | AC19: ='Balance Sheet'!AC38/'Balance Sheet'!AC26 -> 0.83536663 | AD19: ='Balance Sheet'!AD38/'Balance Sheet'!AD26 -> 0.84281841
