Workbook

Sheet Evolutive SFP
R1: ='Evolutitve SCI'!R5/'Evolutive SFP'!R14 -> 0.13803271 | S1: ='Evolutitve SCI'!S5/'Evolutive SFP'!S14 -> 0.02154924 | T1: ='Evolutitve SCI'!T5/'Evolutive SFP'!T14 -> 0.042696775 | U1: ='Evolutitve SCI'!U5/'Evolutive SFP'!U14 -> 0.046308651 | V1: ='Evolutitve SCI'!V5/'Evolutive SFP'!V14 -> 0.055089885 | W1: ='Evolutitve SCI'!W5/'Evolutive SFP'!W14 -> 0.050970278 | X1: ='Evolutitve SCI'!X5/'Evolutive SFP'!X14 -> 0.050939453 | Y1: ='Evolutitve SCI'!Y5/'Evolutive SFP'!Y14 -> 0.051560372 | Z1: -1115511.4
R2: =R5+R11 -> 18492812 | S2: =S5+S11 -> 10661536 | T2: =T5+T11 -> 12165835 | U2: =U5+U11 -> 12165835 | V2: =V5+V11 -> 8267864.4 | W2: =W5+W11 -> 8301101.9 | X2: =X5+X11 -> 5053192.3
B3: 2013 Audited | C3: Audited 2014 | D3: Audited 2015 | E3: Audited 2016 | F3: 42736 | G3: 42767 | H3: 42795 | I3: 42826 | J3: 42856 | K3: 42887 | L3: 42917 | M3: 42948 | N3: 42979 | O3: 43009 | P3: 43040 | Q3: 43070 | R3: Audited 2017 | S3: 43101 | T3: 43132 | U3: 43160 | V3: 43191 | W3: 43221 | X3: 43252 | Y3: 43282 | Z3: 43313 | AA3: 43344 | AB3: 43374 | AC3: 43405 | AD3: 43435 | AE3: Audited 2018 | AF3: 43466 | AG3: 43497 | AH3: 43525 | AI3: 43556 | AJ3: 43586 | AK3: 43617 | AL3: 43647 | AM3: 43678 | AN3: 43709 | AO3: 43739 | AP3: 43770 | AQ3: 43800 | AR3: Audited 2019 | AS3: 43831 | AT3: 43862 | AU3: 43891 | AV3: 43922 | AW3: 43952 | AX3: 43983 | AY3: 44013 | AZ3: 44044 | BA3: 44075 | BB3: 44105 | BC3: 44136 | BD3: 44166 | BE3: Audited 2020 | BF3: 44197 | BG3: 44228 | BH3: 44256 | BI3: 44287 | BJ3: 44317 | BK3: 44348 | BL3: 44378 | BM3: 44409 | BN3: 44440 | BO3: 44470 | BP3: 44501 | BQ3: 44531 | BR3: Audited 2021 | BS3: 44562 | BT3: 44593 | BU3: 44621 | BV3: 44652 | BW3: 44682 | BX3: 44713 | BY3: 44743 | BZ3: 44774 | CA3: 44805 | CB3: 44835 | CC3: 44866 | CD3: 44896 | CE3: Audited 2022 | CF3: Variances | CG3: Audited 2022 | CH3: 44927 | CI3: 44958 | CJ3: 44986 | CK3: 45017 | CL3: 45047 | CM3: 45078 | CN3: 45108
A4: Cash & cash Equivalent | B4: =SUM(B5:B6) -> 128444792 | C4: =SUM(C5:C6) -> 87766162 | D4: =SUM(D5:D6) -> 67219689 | E4: =SUM(E5:E6) -> 50284396 | F4: =SUM(F5:F6) -> 31944447 | G4: =SUM(G5:G6) -> 52742299 | H4: =SUM(H5:H6) -> 29959633 | I4: =SUM(I5:I6) -> 22009143 | ... CE4: =SUM(CE5:CE6) -> 18898344 | CF4: =CE4-CD4 -> -2402213 | CG4: =SUM(CG5:CG6) -> 18898344 | CH4: =SUM(CH5:CH6) -> 8787585.8 | CI4: =SUM(CI5:CI6) -> 4671734.2 | CJ4: =SUM(CJ5:CJ6) -> 5650814.7 | CK4: =SUM(CK5:CK6) -> 7733766.8 | CL4: =SUM(CL5:CL6) -> 5242336.9 | CM4: =SUM(CM5:CM6) -> 3685964.3 | CN4: =SUM(CN5:CN6) -> 4142581.5
A5: Cash In Hand | B5: 7138523 | C5: 11411572 | D5: 9130921 | E5: 5767269 | F5: 9147853 | G5: 8825525 | H5: 4413320 | I5: 6043135 | J5: 2550959 | K5: 1538242 | L5: 0 | M5: 0 | N5: 0 | O5: 0 | P5: 0 | Q5: 0 | R5: =589239+136650 -> 725889 | S5: 2839709 | T5: 4344008 | U5: 4344008 | V5: 446037 | W5: 423156 | X5: 1442019 | Y5: 1338199 | Z5: 4264850 | AA5: 3440169 | AB5: 4018646.5 | AC5: 15930450 | AD5: 6128522 | AE5: =31216703-AE6 -> 4894528 | AF5: 1374745.9 | AG5: 5255359.3 | AH5: 2259985.3 | AI5: 1871768.8 | AJ5: 8801131.8 | AK5: 3048258.8 | AL5: 2854110.8 | AM5: 2745621.8 | AN5: 2198232 | AS5: 1067632 | AT5: 52613 | AU5: 477763 | AV5: 475930.5 | AW5: 1235351.4 | AX5: 2923620 | AZ5: 1287257 | BA5: 1159857 | BB5: 2150360.4 | BC5: 1539417 | BD5: 16024918 | BE5: =15938710+26868+2750 -> 15968328 | BF5: 5564428.5 | BG5: 7884585.5 | BH5: 4412600.2 | BI5: 605236.75 | BJ5: 13379871 | BK5: 2451144.2 | BL5: 652865.05 | BM5: 2306736 | BN5: 3637257.4 | BO5: 4042833.8 | BP5: 3656920.9 | BQ5: 3062432.9 | BR5: =2742519+26868 -> 2769387 | BS5: 2610996.9 | BT5: 2350759.5 | BU5: 11381600 | BV5: 1932881.2 | BW5: 10354848 | BX5: 1331190.5 | BY5: 10335366 | BZ5: 2115160.4 | CA5: 3810781.8 | CB5: 7907868.8 | CC5: 2495612.1 | CD5: 1494432.6 | CE5: 744133 | CF5: =CE5-CD5 -> -750299.64 | CG5: 744133 | CH5: 1419181 | CI5: 3229669.6 | CJ5: 2380956.6 | CK5: 2176931.6 | CL5: 638254.6 | CM5: 1548752.6 | CN5: 1552888.6
A6: Cash at Bank | B6: 121306269 | C6: =81650213-5295623 -> 76354590 | D6: =63855087-5766319 -> 58088768 | E6: 44517127 | F6: 22796594 | G6: 43916774 | H6: 25546313 | I6: 15966008 | J6: 9971510 | K6: 3222102 | L6: 0 | M6: 0 | N6: 0 | O6: 0 | P6: 0 | Q6: 0 | R6: 31885175 | S6: 17133362 | T6: 9722175.1 | U6: 9722175.1 | V6: 2556306.3 | W6: 1792082.5 | X6: -418333.7 | Y6: -2453710.4 | Z6: 16273042 | AA6: 18050237 | AB6: 14658377 | AC6: 17529223 | AD6: -9634566.3 | AE6: 26322175 | AF6: -4462315.9 | AG6: 3883904.8 | AH6: 6027077.1 | AI6: -17411200 | AJ6: -17193122 | AK6: -14219783 | AL6: 10442462 | AM6: 8882118 | AN6: 10806090 | AS6: 6100792.8 | AT6: 5674541.6 | AU6: 24303562 | AV6: 20240496 | AW6: 20104363 | AX6: 21140554 | AZ6: 17556876 | BA6: 20597366 | BB6: 25231000 | BC6: 25062799 | BD6: 20625964 | BE6: =20690085 -> 20690085 | BF6: 14977517 | BG6: 17739254 | BH6: 17951706 | BI6: 15128451 | BJ6: 10625185 | BK6: 17696710 | BL6: 10413697 | BM6: 8975081.8 | BN6: 8029532.1 | BO6: 8372558.2 | BP6: 25652344 | BQ6: 16322664 | BR6: 24858953 | BS6: 15163240 | BT6: 19944641 | BU6: 11537229 | BV6: 4477692.1 | BW6: 10636232 | BX6: 11243092 | BY6: 14694832 | BZ6: 9844316.2 | CA6: 13508398 | CB6: 15030807 | CC6: 28946224 | CD6: 19806124 | CE6: 18154211 | CF6: =CE6-CD6 -> -1651913.4 | CG6: 18154211 | CH6: 7368404.8 | CI6: 1442064.6 | CJ6: 3269858.1 | CK6: 5556835.2 | CL6: 4604082.3 | CM6: 2137211.7 | CN6: 2589692.8
A7: Prepayment and Sundry | B7: 52413257 | C7: 41229631 | D7: 17661661 | E7: 24583094 | F7: 31308205 | G7: 23008112 | H7: 25592164 | I7: 25985706 | J7: 27688333 | K7: 26515797 | L7: 0 | M7: 0 | N7: 0 | O7: 0 | P7: 0 | Q7: 0 | R7: 22121089 | S7: 25508717 | T7: 19537047 | U7: 24008788 | V7: 34137255 | W7: 21858216 | X7: 43289021 | Y7: 0 | Z7: 0 | AA7: 0 | AB7: 0 | AC7: 0 | AD7: 0 | AE7: 26596843 | BE7: 6624843 | BF7: 0 | BG7: 0 | BH7: 0 | BI7: 0 | BJ7: 0 | BK7: 0 | BL7: 0 | BM7: 0 | BN7: 0 | BO7: 0 | BP7: 0 | BQ7: 0 | BR7: =1475908+115235871 -> 116711779 | BS7: 0 | BT7: 9478169 | BU7: 9555209.9 | BV7: 9299637 | BW7: 0 | BX7: 0 | BY7: 0 | BZ7: 0 | CA7: 0 | CB7: 0 | CC7: 0 | CD7: 0 | CE7: 10075490 | CF7: =CE7-CD7 -> 10075490 | CG7: 10075490 | CH7: 0 | CI7: 0 | CJ7: 0 | CK7: 0 | CL7: 0 | CM7: 0 | CN7: 0
A8: Financial Investment | B8: =SUM(B9:B12) -> 23235649 | C8: =SUM(C9:C12) -> 23582539 | D8: =SUM(D9:D12) -> 24253235 | E8: =SUM(E9:E12) -> 23630498 | F8: =SUM(F9:F12) -> 19804399 | G8: =SUM(G9:G12) -> 19804399 | H8: =SUM(H9:H12) -> 27179981 | I8: =SUM(I9:I12) -> 27179981 | ... CE8: =SUM(CE9:CE12) -> 14356941 | CF8: =CE8-CD8 -> -0.3 | CG8: =SUM(CG9:CG12) -> 14356941 | CH8: =SUM(CH9:CH12) -> 22744634 | CI8: =SUM(CI9:CI12) -> 22744634 | CJ8: =SUM(CJ9:CJ12) -> 22744634 | CK8: =SUM(CK9:CK12) -> 22744634 | CL8: =SUM(CL9:CL12) -> 22744634 | CM8: =SUM(CM9:CM12) -> 22764634 | CN8: =SUM(CN9:CN12) -> 22764634
A9: Government Security | C9: 0 | F9: 0 | G9: 0 | H9: 0 | I9: 0 | J9: 0 | K9: 0 | L9: 0 | M9: 0 | N9: 0 | O9: 0 | P9: 0 | Q9: 0 | X9: 0 | Y9: 0 | Z9: 0 | AA9: 0 | AB9: 0 | AC9: 0 | AD9: 0 | AE9: 0 | AF9: 0 | AG9: 0 | AH9: 0 | AI9: 0 | AJ9: 0 | AK9: 0 | AL9: 0 | AM9: 0 | AN9: 0 | AS9: 0 | AT9: 0 | AU9: 0 | AV9: 0 | AW9: 0 | AX9: 0 | AZ9: 0 | BA9: 0 | BB9: 0 | BC9: 0 | BD9: 0 | BF9: 0 | BG9: 0 | BH9: 0 | BI9: 0 | BJ9: 0 | BK9: 0 | BL9: 0 | BM9: 0 | BN9: 0 | BO9: 0 | BP9: 0 | BQ9: 0 | BS9: 0 | BT9: 0 | BU9: 0 | BV9: 0 | BW9: 0 | BX9: 0 | BY9: 0 | BZ9: 0 | CA9: 0 | CB9: 0 | CC9: 0 | CD9: 0 | CF9: =CE9-CD9 -> 0 | CH9: 0 | CI9: 0 | CJ9: 0 | CK9: 0 | CL9: 0 | CM9: 0 | CN9: 0
A10: Other Securities | C10: 0 | F10: 1317483.1 | G10: 1317483.1 | H10: 1317483.1 | I10: 1317483.1 | J10: 1317483.1 | K10: 1317483.1 | L10: 0 | M10: 0 | N10: 0 | O10: 0 | P10: 0 | Q10: 0 | X10: 0 | Y10: 24202.71 | Z10: 0 | AA10: 0 | AB10: 0 | AC10: 0 | AD10: 0 | AE10: 0 | AF10: 0 | AG10: 0 | AH10: 0 | AI10: 0 | AJ10: 0 | AK10: 0 | AL10: 0 | AM10: 0 | AN10: 0 | AS10: 0 | AT10: 0 | AU10: 0 | AV10: 0 | AW10: 0 | AX10: 0 | AZ10: 0 | BA10: 0 | BB10: 0 | BC10: 0 | BD10: 0 | BF10: 0 | BG10: 0 | BH10: 0 | BI10: 0 | BJ10: 0 | BK10: 0 | BL10: 0 | BM10: 0 | BN10: 0 | BO10: 0 | BP10: 0 | BQ10: 0 | BS10: 0 | BT10: 0 | BU10: 0 | BV10: 0 | BW10: 0 | BX10: 0 | BY10: 0 | BZ10: 0 | CA10: 0 | CB10: 0 | CC10: 0 | CD10: 0 | CF10: =CE10-CD10 -> 0 | CH10: 0 | CI10: 0 | CJ10: 0 | CK10: 0 | CL10: 0 | CM10: 0 | CN10: 0
A11: Balances with Other Saccos | B11: 5148733 | C11: 5295623 | D11: 5766319 | E11: 5143582 | F11: 0 | G11: 0 | H11: 7375581.5 | I11: 7375581.5 | J11: 7375581.5 | K11: 7375582 | L11: 0 | M11: 0 | N11: 0 | O11: 0 | P11: 0 | Q11: 0 | R11: =14155750+3611173 -> 17766923 | S11: 7821827.4 | T11: 7821827.4 | U11: 7821827.4 | V11: 7821827.4 | W11: 7877945.9 | X11: 3611173.3 | Y11: 3611173.3 | Z11: 0 | AA11: 0 | AB11: 0 | AC11: 0 | AD11: 0 | AE11: 0 | AF11: 7758945.9 | AG11: 7877945.9 | AH11: 0 | AI11: 0 | AJ11: 0 | AK11: 0 | AL11: 0 | AM11: 0 | AN11: 0 | AS11: 0 | AT11: 0 | AU11: 0 | AV11: 0 | AW11: 0 | AX11: 0 | AZ11: 0 | BA11: 0 | BB11: 0 | BC11: 0 | BD11: 0 | BF11: 0 | BG11: 0 | BH11: 0 | BI11: 0 | BJ11: 0 | BK11: 0 | BL11: 0 | BM11: 0 | BN11: 0 | BO11: 0 | BP11: 0 | BQ11: 0 | BS11: 0 | BT11: 0 | BU11: 0 | BV11: 0 | BW11: 0 | BX11: 0 | BY11: 0 | BZ11: 0 | CA11: 0 | CB11: 0 | CC11: 0 | CD11: 0 | CE11: 14356941 | CF11: =CE11-CD11 -> 14356941 | CG11: 14356941 | CH11: 0 | CI11: 0 | CJ11: 0 | CK11: 0 | CL11: 0 | CM11: 0 | CN11: 0
A12: Investment In Companies | B12: 18086916 | C12: =18236916+50000 -> 18286916 | D12: 18486916 | E12: 18486916 | F12: 18486916 | G12: 18486916 | H12: 18486916 | I12: 18486916 | J12: 18486916 | K12: 18486916 | L12: 0 | M12: 0 | N12: 0 | O12: 0 | P12: 0 | Q12: 0 | R12: =312100+37000+10000+492874 -> 851974 | S12: 18618897 | T12: 18618897 | U12: 18618897 | V12: 18618897 | W12: 18618897 | X12: 15007724 | Y12: 15007724 | Z12: 18618897 | AA12: 18618897 | AB12: 18618897 | AC12: 18618897 | AD12: 18618897 | AE12: 18618897 | AF12: 18644139 | AG12: 18618897 | AH12: 18618897 | AI12: 18618897 | AJ12: 18618897 | AK12: 18618897 | AL12: 18618897 | AM12: 18618897 | AN12: 18792655 | AS12: 18792655 | AT12: 18792655 | AU12: 14306941 | AV12: 14306941 | AW12: 14306941 | AX12: 14306941 | AZ12: 14306941 | BA12: 14306941 | BB12: 14306941 | BC12: 14306941 | BD12: 14306941 | BE12: 14306941 | BF12: 22517512 | BG12: 22517512 | BH12: 22517512 | BI12: 22517512 | BJ12: 22517512 | BK12: 22553300 | BL12: 22553300 | BM12: 22553300 | BN12: 22553300 | BO12: 22553300 | BP12: 22553300 | BQ12: 22553300 | BR12: 14306941 | BS12: 22553300 | BT12: 22553300 | BU12: 22553300 | BV12: 22553300 | BW12: 14356941 | BX12: 14356941 | BY12: 14356941 | BZ12: 14356941 | CA12: 14356941 | CB12: 14356941 | CC12: 14456941 | CD12: 14356941 | CF12: =CE12-CD12 -> -14356941 | CH12: 22744634 | CI12: 22744634 | CJ12: 22744634 | CK12: 22744634 | CL12: 22744634 | CM12: 22764634 | CN12: 22764634
A13: Net Loan Portfolio | B13: =B14-B15 -> 100772491 | C13: =C14-C15 -> 108738343 | D13: =D14-D15 -> 153940147 | E13: =E14-E15 -> 163589556 | F13: =F14-F15 -> 1.7133933e+08 | G13: =G14-G15 -> 1.7270349e+08 | H13: =H14-H15 -> 1.7451462e+08 | I13: =I14-I15 -> 1.6695465e+08 | ... CE13: =CE14-CE15 -> 43501127 | CF13: =CE13-CD13 -> 474179.98 | CG13: =CG14-CG15 -> 43501127 | CH13: =CH14-CH15 -> 1.1162795e+08 | CI13: =CI14-CI15 -> 48440087 | CJ13: =CJ14-CJ15 -> 50457085 | CK13: =CK14-CK15 -> 48821138 | CL13: =CL14-CL15 -> 47955121 | CM13: =CM14-CM15 -> 42380986 | CN13: =CN14-CN15 -> 55631257
A14: Gross Loan Portfolio | B14: 103051094 | C14: =103051094+225628493-216786901 -> 111892686 | D14: =153940147+3422873 -> 157363020 | E14: 167629119 | F14: 1.7958764e+08 | G14: 1.766828e+08 | H14: 1.7835008e+08 | I14: 170790111 | J14: 171339210 | K14: 1.718635e+08 | L14: 0 | M14: 0 | N14: 0 | O14: 0 | P14: 0 | Q14: 0 | R14: 1.3199861e+08 | S14: 1.5542763e+08 | T14: 1.6099855e+08 | U14: 1.6099855e+08 | V14: 1.4029934e+08 | W14: 1.5794637e+08 | X14: 1.6052017e+08 | Y14: 1.6053595e+08 | Z14: 1.5200309e+08 | AA14: 1.4614024e+08 | AB14: 1.3571907e+08 | AC14: 1.2630329e+08 | AD14: 1.1733634e+08 | AE14: 136448447 | AF14: 1.2861911e+08 | AG14: 1.3025927e+08 | AH14: 1.2193427e+08 | AI14: 1.2046881e+08 | AJ14: 1.1987045e+08 | AK14: 1.2090525e+08 | AL14: 1.2040948e+08 | AM14: 1.2249544e+08 | AN14: 1.2126987e+08 | AS14: 1.1984667e+08 | AT14: 9219483.9 | AU14: 12582696 | AV14: 12438189 | AW14: 11679979 | AX14: 12356350 | AZ14: 13642435 | BA14: 14076573 | BB14: 1.1637729e+08 | BC14: 1.163982e+08 | BD14: 1.0955832e+08 | BE14: =118974404+23565213-43872986 -> 98666631 | BF14: 1.0443983e+08 | BG14: 1.0291865e+08 | BH14: 1.0316208e+08 | BI14: 1.0513177e+08 | BJ14: 1.0460217e+08 | BK14: 1.0131827e+08 | BL14: 1.0828656e+08 | BM14: 1.0761066e+08 | BN14: 1.073874e+08 | BO14: 1.0770093e+08 | BP14: 1.0683059e+08 | BQ14: 1.0145116e+08 | BR14: 99799936 | BS14: 1.0184615e+08 | BT14: 1.0154812e+08 | BU14: 1.0697351e+08 | BV14: 1.1530025e+08 | BW14: 1.1462132e+08 | BX14: 1.1423782e+08 | BY14: 1.100773e+08 | BZ14: 1.125599e+08 | CA14: 1.1269283e+08 | CB14: 1.0625226e+08 | CC14: 1.0687569e+08 | CD14: 1.1143462e+08 | CE14: 111434614 | CF14: =CE14-CD14 -> -1.58 | CG14: 111434614 | CH14: 1.1162795e+08 | CI14: 1.127038e+08 | CJ14: 1.0881204e+08 | CK14: 1.0593719e+08 | CL14: 1.0725968e+08 | CM14: 1.0808258e+08 | CN14: 1.237537e+08
A15: Allowance For Loan Loss | B15: 2278603 | C15: 3154343 | D15: 3422873 | E15: 4039563 | F15: 8248306 | G15: 3979310.3 | H15: 3835462.4 | I15: 3835462.4 | J15: 3541834 | K15: 3607139.5 | L15: 0 | M15: 0 | N15: 0 | O15: 0 | P15: 0 | Q15: 0 | R15: 8346849 | S15: 9150264 | T15: 9759302 | U15: 13960467 | V15: 18801908 | W15: 40138586 | X15: 7576654 | Y15: 7576654 | Z15: 6945202 | AA15: 7576654 | AB15: 7576654 | AC15: 7576654 | AD15: 7576654 | AE15: 19152690 | AF15: 7576654 | AG15: 3422873 | AH15: 3422873 | AI15: 6945202 | AJ15: 6945202 | AK15: 6945202 | AL15: 6945202 | AM15: 6945202 | AN15: 6945202 | AS15: 1.1079151e+08 | AT15: 0 | AU15: 125826.96 | AV15: 124381.89 | AW15: 116799.8 | AX15: 123563.52 | AZ15: 136424.35 | BA15: 140765.73 | BB15: 1.0175735e+08 | BC15: 1.0175755e+08 | BD15: 98170179 | BE15: 98055147 | BF15: 96038619 | BG15: 1.0345375e+08 | BH15: 1.0216673e+08 | BI15: 1.0216673e+08 | BJ15: 1.0216673e+08 | BK15: 89788130 | BL15: 1.045009e+08 | BM15: 1.0646815e+08 | BN15: 1.0616673e+08 | BO15: 1.24684e+08 | BP15: 1.2335173e+08 | BQ15: 1.0216673e+08 | BR15: =78211545.57-19843602+12727643-191737.57 -> 70903849 | BS15: 1.0216673e+08 | BT15: 1.0216673e+08 | BU15: 1.0216673e+08 | BV15: 1.0216673e+08 | BW15: 77521848 | BX15: 81506090 | BY15: 80264280 | BZ15: 80264280 | CA15: 79027956 | CB15: 75274689 | CC15: 72859667 | CD15: 68407669 | CE15: 67933487 | CF15: =CE15-CD15 -> -474181.56 | CG15: 67933487 | CH15: 0 | CI15: 64263714 | CJ15: 58354957 | CK15: 57116051 | CL15: 59304557 | CM15: 65701593 | CN15: 68122439
A16: Accounts Recievables | B16: =SUM(B17:B19) -> 1014864 | C16: =SUM(C17:C19) -> 633214 | D16: =SUM(D17:D19) -> -1056148 | E16: =SUM(E17:E19) -> -1042683 | F16: =SUM(F17:F19) -> 0 | G16: =SUM(G17:G19) -> 0 | H16: =SUM(H17:H19) -> -1042683 | I16: =SUM(I17:I19) -> -1042683 | ... CE16: =SUM(CE17:CE19) -> 0 | CF16: =CE16-CD16 -> 0 | CG16: =SUM(CG17:CG19) -> 0 | CH16: =SUM(CH17:CH19) -> 7486538.1 | CI16: =SUM(CI17:CI19) -> 6842640 | CJ16: =SUM(CJ17:CJ19) -> 6842640 | CK16: =SUM(CK17:CK19) -> 6826640 | CL16: =SUM(CL17:CL19) -> 6826640 | CM16: =SUM(CM17:CM19) -> 10729369 | CN16: =SUM(CN17:CN19) -> 10721369
A17: Tax Recoverable | B17: 1014864 | C17: 633214 | D17: -1056148 | E17: -1042683 | F17: 0 | G17: 0 | H17: -1042683 | I17: -1042683 | J17: -1042683 | K17: -1042683 | L17: 0 | M17: 0 | N17: 0 | O17: 0 | P17: 0 | Q17: 0 | X17: 0 | Y17: 0 | Z17: 0 | AA17: 0 | AB17: 0 | AC17: 0 | AD17: 0 | AF17: 0 | AG17: 0 | AH17: 0 | AI17: 0 | AJ17: 0 | AK17: 0 | AL17: 0 | AM17: 0 | AN17: 0 | AS17: 0 | AT17: 0 | AU17: 0 | AV17: 0 | AW17: 0 | AX17: 0 | AZ17: 0 | BA17: 0 | BB17: 0 | BC17: 0 | BD17: 0 | BF17: 0 | BG17: 0 | BH17: 0 | BI17: 0 | BJ17: 0 | BK17: 0 | BL17: 0 | BM17: 0 | BN17: 0 | BO17: 0 | BP17: 0 | BQ17: 0 | BS17: 0 | BT17: 0 | BU17: 0 | BV17: 0 | BW17: 0 | CA17: 0 | CB17: 0 | CC17: 0 | CF17: =CE17-CD17 -> 0 | CH17: 0 | CI17: 0 | CJ17: 0 | CK17: 0 | CL17: 0 | CM17: 0 | CN17: 0
A18: Deffered Tax Assets | C18: 0 | F18: 0 | G18: 0 | H18: 0 | I18: 0 | J18: 0 | L18: 0 | M18: 0 | N18: 0 | O18: 0 | P18: 0 | Q18: 0 | X18: 0 | Y18: 0 | Z18: 0 | AA18: 0 | AB18: 0 | AC18: 0 | AD18: 0 | AF18: 0 | AG18: 0 | AH18: 0 | AI18: 0 | AJ18: 0 | AK18: 0 | AL18: 0 | AM18: 0 | AN18: 0 | AS18: 0 | AT18: 0 | AU18: 0 | AV18: 0 | AW18: 0 | AX18: 0 | AZ18: 0 | BA18: 0 | BB18: 0 | BC18: 0 | BD18: 0 | BF18: 0 | BG18: 0 | BH18: 0 | BI18: 0 | BJ18: 0 | BK18: 0 | BL18: 0 | BM18: 0 | BN18: 0 | BO18: 0 | BP18: 0 | BQ18: 0 | BS18: 0 | BT18: 0 | BU18: 0 | BV18: 0 | BW18: 0 | CA18: 0 | CB18: 0 | CC18: 0 | CF18: =CE18-CD18 -> 0 | CH18: 0 | CI18: 0 | CJ18: 0 | CK18: 0 | CL18: 0 | CM18: 0 | CN18: 0
A19: Retirement Benefit Assets | C19: 0 | F19: 0 | G19: 0 | H19: 0 | I19: 0 | L19: 0 | M19: 0 | N19: 0 | O19: 0 | P19: 0 | Q19: 0 | X19: 0 | Y19: 44295800 | Z19: 40950010 | AA19: 40616558 | AB19: 40953250 | AC19: 30430425 | AD19: 69650104 | AF19: 40251206 | AG19: 37086124 | AH19: 37638956 | AI19: 60639568 | AJ19: 55231656 | AK19: 53248170 | AL19: 43322133 | AM19: 46983140 | AN19: 47634678 | AS19: 34518708 | AT19: 1.3023026e+08 | AU19: 1.2274664e+08 | AV19: 1.2330664e+08 | AW19: 1.2668627e+08 | AX19: 1.3186282e+08 | AZ19: 1.2766503e+08 | BA19: 1.2641351e+08 | BB19: 1.2692238e+08 | BC19: 1.2573708e+08 | BD19: 1.25939e+08 | BF19: 14601812 | BG19: 13483515 | BH19: 13979889 | BI19: 13976590 | BJ19: 13977490 | BK19: 11552231 | BL19: 11578081 | BM19: 11610081 | BN19: 9393511.1 | BO19: 9388661.1 | BP19: 9380661.1 | BQ19: 9444799.1 | BR19: 0 | BS19: 9483199 | BT19: 0 | BU19: 0 | BV19: 0 | BW19: 0 | CA19: 24000 | CB19: 275435.67 | CC19: 275435.67 | CF19: =CE19-CD19 -> 0 | CH19: 7486538.1 | CI19: 6842640 | CJ19: 6842640 | CK19: 6826640 | CL19: 6826640 | CM19: 10729369 | CN19: 10721369
A20: Property&Equipments&Other Assets | B20: =SUM(B21:B25) -> 15008730 | C20: =SUM(C21:C25) -> 10355868 | D20: =SUM(D21:D25) -> 23445547 | E20: =SUM(E21:E25) -> 40139932 | F20: =SUM(F21:F25) -> 21382272 | G20: =SUM(G21:G25) -> 37531087 | H20: =SUM(H21:H25) -> 29989620 | I20: =SUM(I21:I25) -> 30668107 | ... CE20: =SUM(CE21:CE25) -> 132955259 | CF20: =CE20-CD20 -> 21909696 | CG20: =SUM(CG21:CG25) -> 132955259 | CH20: =SUM(CH21:CH25) -> 27115991 | CI20: =SUM(CI21:CI25) -> 95105675 | CJ20: =SUM(CJ21:CJ25) -> 85287674 | CK20: =SUM(CK21:CK25) -> 84736741 | CL20: =SUM(CL21:CL25) -> 87184328 | CM20: =SUM(CM21:CM25) -> 95715088 | CN20: =SUM(CN21:CN25) -> 83125110
A21: Investment Properties | C21: 0 | F21: 0 | G21: 0 | H21: 0 | I21: 0 | J21: 0 | K21: 0 | L21: 0 | M21: 0 | N21: 0 | O21: 0 | P21: 0 | Q21: 0 | S21: 0 | T21: 0 | U21: 0 | V21: 0 | W21: 0 | X21: 0 | Y21: 0 | Z21: 0 | AA21: 0 | AB21: 0 | AC21: 0 | AD21: 0 | AF21: 0 | AG21: 0 | AH21: 0 | AI21: 0 | AJ21: 0 | AK21: 0 | AL21: 0 | AM21: 0 | AN21: 0 | AS21: 0 | AT21: 0 | AU21: 0 | AV21: 0 | AW21: 0 | AX21: 0 | AZ21: 0 | BA21: 0 | BB21: 0 | BC21: 0 | BD21: 0 | BF21: 0 | BG21: 0 | BH21: 0 | BI21: 0 | BJ21: 0 | BK21: 0 | BL21: 0 | BM21: 0 | BN21: 0 | BO21: 0 | BP21: 0 | BQ21: 0 | BS21: 0 | BT21: 0 | BU21: 0 | BV21: 0 | BW21: 0 | BX21: 0 | BY21: 0 | BZ21: 0 | CA21: 0 | CB21: 0 | CC21: 0 | CD21: 0 | CF21: =CE21-CD21 -> 0 | CH21: 0 | CI21: 0 | CJ21: 0 | CK21: 0 | CL21: 0 | CM21: 0 | CN21: 0
A22: Property and Equipment | B22: 3110877 | C22: 4576955 | D22: 9907043 | E22: 14921476 | F22: 20113390 | G22: 14923330 | H22: 15050807 | I22: 14976884 | J22: 14902961 | K22: 15096038 | L22: 0 | M22: 0 | N22: 0 | O22: 0 | P22: 0 | Q22: 0 | R22: 15459762 | S22: 15405509 | T22: 15351256 | U22: 15351256 | V22: 15242751 | W22: 15188498 | X22: 4613176.9 | Y22: 4613176.9 | Z22: 4613176.9 | AA22: 4613176.9 | AB22: 4775576.9 | AC22: 4662176.9 | AD22: 4037546.9 | AE22: 14449570 | AF22: 4024046.9 | AG22: 4037546.9 | AH22: 4143213.9 | AI22: 2504641.9 | AJ22: 2507141.9 | AK22: 2509140.9 | AL22: 2509140.9 | AM22: 2509140.9 | AN22: 2509140.9 | AS22: 1834787.8 | AT22: 1834787.8 | AU22: 1848037.8 | AV22: 1848037.8 | AW22: 1860787.8 | AX22: 1860787.8 | AZ22: 1865287.8 | BA22: 1887287.8 | BB22: 1887287.8 | BC22: 1887287.8 | BD22: 1887287.8 | BE22: 14586623 | BF22: 16156930 | BG22: 16156930 | BH22: 16156930 | BI22: 16174640 | BJ22: 16307390 | BK22: 16330247 | BL22: 16579997 | BM22: 16886997 | BN22: 16886997 | BO22: 16886997 | BP22: 16927697 | BQ22: 16943047 | BR22: 14279292 | BS22: 16886997 | BT22: 17010547 | BU22: 17116807 | BV22: 17013247 | BW22: 14279292 | BX22: 13570536 | BY22: 12570536 | BZ22: 14968599 | CA22: 14968599 | CB22: 18763161 | CC22: 18763161 | CD22: 32319997 | CE22: 17192646 | CF22: =CE22-CD22 -> -15127351 | CG22: 17192646 | CH22: 14968599 | CI22: 27073991 | CJ22: 27073991 | CK22: 24197403 | CL22: 24197403 | CM22: 32331926 | CN22: 32331926
A23: Prepaid Lease Rentals | C23: 0 | F23: 0 | G23: 0 | H23: 0 | I23: 0 | J23: 0 | K23: 0 | L23: 0 | M23: 0 | N23: 0 | O23: 0 | P23: 0 | Q23: 0 | S23: 0 | T23: 0 | U23: 0 | V23: 0 | W23: 0 | X23: 0 | Y23: 0 | Z23: 0 | AA23: 0 | AB23: 0 | AC23: 0 | AD23: 0 | AF23: 0 | AG23: 0 | AH23: 0 | AI23: 0 | AJ23: 0 | AK23: 0 | AL23: 0 | AM23: 0 | AN23: 0 | AS23: 0 | AT23: 0 | AU23: 0 | AV23: 0 | AW23: 0 | AX23: 0 | AZ23: 0 | BA23: 0 | BB23: 0 | BC23: 0 | BD23: 0 | BF23: 1.1224273e+08 | BG23: 0 | BH23: 0 | BI23: 1.1067212e+08 | BJ23: 0 | BK23: 0 | BL23: 0 | BM23: 0 | BN23: 0 | BO23: 0 | BP23: 0 | BQ23: 0 | BS23: 0 | BT23: 0 | BU23: 0 | BV23: 0 | BW23: 0 | BX23: 0 | BY23: 0 | CA23: 0 | CB23: 0 | CC23: 0 | CD23: 0 | CF23: =CE23-CD23 -> 0 | CH23: 0 | CI23: 0 | CJ23: 0 | CK23: 0 | CL23: 0 | CM23: 0 | CN23: 0
A24: Intangible Assets | B24: 152185 | C24: 0 | E24: 2148552 | F24: 1268881.9 | G24: 2041124.4 | H24: 1987410.6 | I24: 2082286.8 | J24: 2024446 | K24: 1966604.2 | L24: 0 | M24: 0 | N24: 0 | O24: 0 | P24: 0 | Q24: 0 | R24: 1619556 | S24: 1655392.5 | T24: 1695881.4 | U24: 1695881.4 | V24: 1457600.8 | W24: 1417111.9 | X24: 4120044 | Y24: 4120044 | Z24: 4120044 | AA24: 4120044 | AB24: 4120044 | AC24: 4282444 | AD24: 4282444 | AE24: 4282444 | AF24: 4282444 | AG24: 4282444 | AH24: 4282444 | AI24: 5897348 | AJ24: 5897348 | AK24: 5897348 | AL24: 5897348 | AM24: 5897348 | AN24: 5897348 | AS24: 2142518.7 | AT24: 2142518.7 | AU24: 2142518.7 | AV24: 2142518.7 | AW24: 2142518.7 | AX24: 2404076.7 | AZ24: 2799001.7 | BA24: 2874351.7 | BB24: 2885676.7 | BC24: 2985676.7 | BD24: 2985676.7 | BE24: 2089974 | BF24: 1723461.8 | BG24: 1798461.8 | BH24: 1798461.8 | BI24: 1846661.8 | BJ24: 1846661.8 | BK24: 1846661.8 | BL24: 1846661.8 | BM24: 2118861.8 | BN24: 2118861.8 | BO24: 2118861.8 | BP24: 2158861.8 | BQ24: 2158861.8 | BR24: 1462982 | BS24: 2118861.8 | BT24: 2158861.8 | BU24: 2158861.8 | BV24: 2258861.8 | BW24: 1462982 | BX24: 7110806 | BY24: 9257455.6 | BZ24: 9257455.6 | CA24: 9257455.6 | CB24: 20958247 | CC24: 20958247 | CD24: 8778560.7 | CE24: 2526742 | CF24: =CE24-CD24 -> -6251818.7 | CG24: 2526742 | CH24: 2876587.4 | CI24: 2876587.4 | CJ24: 2876587.4 | CK24: 2876587.4 | CL24: 2876587.4 | CM24: 8778560.7 | CN24: 8778560.7
A25: Other Assets | B25: 11745668 | C25: 5778913 | D25: 13538504 | E25: 23069904 | F25: 0 | G25: 20566633 | H25: 12951403 | I25: 13608936 | J25: =488647+12452420 -> 12941067 | K25: 12838545 | L25: 0 | M25: 0 | N25: 0 | O25: 0 | P25: 0 | Q25: 0 | R25: =389280+25343078 -> 25732358 | S25: 25343078 | T25: 25343078 | U25: 25343078 | V25: 33779943 | W25: 33779943 | X25: 14270892 | Y25: 14270892 | Z25: 14270892 | AA25: 14270892 | AB25: 14270892 | AC25: 14270892 | AD25: 14270892 | AE25: =7753599+227275 -> 7980874 | AF25: 14270892 | AG25: 14270892 | AH25: 14270892 | AI25: 14270892 | AJ25: 14270892 | AK25: 14270892 | AL25: 14270892 | AM25: 14282892 | AN25: 14282892 | AS25: 12716827 | AT25: 12716827 | AU25: 12716827 | AV25: 12730527 | AW25: 12730527 | AX25: 12916527 | AZ25: 12916527 | BA25: 13007127 | BB25: 13007127 | BC25: 13007127 | BD25: 13007127 | BE25: 114835602 | BF25: 0 | BG25: 1.033849e+08 | BH25: 1.1454399e+08 | BI25: 0 | BJ25: 99932503 | BK25: 1.1321627e+08 | BL25: 1.1321627e+08 | BM25: 1.1321627e+08 | BN25: 1.1479619e+08 | BO25: 1.1321627e+08 | BP25: 1.1321627e+08 | BQ25: 1.101776e+08 | BS25: 1.1019373e+08 | BT25: 1.1363024e+08 | BU25: 1.1234745e+08 | BV25: 1.1436147e+08 | BW25: 1.1321627e+08 | BX25: 1.2852308e+08 | BY25: 1.1321627e+08 | BZ25: 1.206091e+08 | CA25: 1.0376415e+08 | CB25: 82311828 | CC25: 82311828 | CD25: 69947006 | CE25: 113235871 | CF25: =CE25-CD25 -> 43288865 | CG25: 113235871 | CH25: 9270804.2 | CI25: 65155097 | CJ25: 55337096 | CK25: 57662750 | CL25: 60110338 | CM25: 54604601 | CN25: 42014623
A26: Total Assets | B26: =B20+B16+B13+B8+B7+B4 -> 320889783 | C26: =C20+C16+C13+C8+C7+C4 -> 272305757 | D26: =D20+D16+D13+D8+D7+D4 -> 285464131 | E26: =E20+E16+E13+E8+E7+E4 -> 301184793 | F26: =F20+F16+F13+F8+F7+F4 -> 2.7577865e+08 | G26: =G20+G16+G13+G8+G7+G4 -> 3.0578939e+08 | H26: =H20+H16+H13+H8+H7+H4 -> 2.8619334e+08 | I26: =I20+I16+I13+I8+I7+I4 -> 2.717549e+08 | ... CE26: =CE20+CE16+CE13+CE8+CE7+CE4 -> 219787161 | CF26: =CE26-CD26 -> 30057152 | CG26: =CG20+CG16+CG13+CG8+CG7+CG4 -> 219787161 | CH26: =CH20+CH16+CH13+CH8+CH7+CH4 -> 1.7776269e+08 | CI26: =CI20+CI16+CI13+CI8+CI7+CI4 -> 1.7780477e+08 | CJ26: =CJ20+CJ16+CJ13+CJ8+CJ7+CJ4 -> 1.7098285e+08 | CK26: =CK20+CK16+CK13+CK8+CK7+CK4 -> 1.7086292e+08 | CL26: =CL20+CL16+CL13+CL8+CL7+CL4 -> 1.6995306e+08 | CM26: =CM20+CM16+CM13+CM8+CM7+CM4 -> 1.7527604e+08 | CN26: =CN20+CN16+CN13+CN8+CN7+CN4 -> 1.7638495e+08
A27: Savings and Deposits | B27: 57969061 | C27: =28636276+1891321+3132613 -> 33660210 | D27: =24367647-7748319 -> 16619328 | E27: 17947544 | F27: -6391944.5 | G27: 5076591 | H27: 4654413.1 | I27: 31282276 | J27: -4342846.4 | K27: -12144473 | L27: 0 | M27: 0 | N27: 0 | O27: 0 | P27: 0 | Q27: 0 | R27: =-31816265 -> -31816265 | S27: -14709982 | T27: -10364619 | U27: -10364619 | V27: -20482011 | W27: -20440729 | X27: -30667169 | Y27: -41219533 | Z27: -27431796 | AA27: -31307044 | AB27: -35640907 | AC27: -26085448 | AD27: -38924042 | AE27: -28293693 | AF27: -38190433 | AG27: -35194936 | AH27: -53133636 | AI27: -54864721 | AJ27: -52818305 | AK27: -49017962 | AL27: -45818016 | AM27: -43282956 | AN27: -42991538 | AS27: -42065362 | AT27: 50344997 | AU27: 42591064 | AV27: 44047927 | AW27: 48511188 | AX27: 54283435 | AZ27: 41897611 | BA27: 41756059 | BB27: 42954285 | BC27: 43763548 | BD27: 44982409 | BE27: 43898703 | BF27: 26898173 | BG27: 32087694 | BH27: 21912102 | BI27: 27076837 | BJ27: 26916313 | BK27: 28129938 | BL27: 26635920 | BM27: 26925027 | BN27: 22789621 | BO27: 23996162 | BP27: 23691500 | BQ27: 24455795 | BR27: 38360675 | BS27: 23748642 | BT27: 28356816 | BU27: 30300776 | BV27: 28660542 | BW27: 42808669 | BX27: 42308175 | BY27: 41499014 | BZ27: 41446926 | CA27: 45245396 | CB27: 42520866 | CC27: 41857694 | CD27: 41053075 | CE27: 41044632 | CF27: =CE27-CD27 -> -8442.56 | CG27: 41044632 | CH27: 43082503 | CI27: 40082532 | CJ27: 36607691 | CK27: 35997992 | CL27: 35020598 | CM27: 35973687 | CN27: 36040154
A28: Short Terrm Deposits | C28: 7112519 | D28: 7748319 | F28: 0 | G28: 16697146 | H28: 13713413 | I28: 2237547 | J28: 2281417 | K28: 2137430.3 | L28: 0 | M28: 0 | N28: 0 | O28: 0 | P28: 0 | Q28: 0 | S28: 11125696 | T28: 476276.34 | U28: 476276.34 | V28: 479276.34 | W28: 465276.34 | X28: 1.5998507e+08 | Y28: 348116.94 | Z28: 424657.25 | AA28: 410624.25 | AB28: 59541.31 | AC28: 213125.25 | AD28: 208708.25 | AF28: 176675.25 | AG28: 144105.95 | AH28: 0 | AI28: 153105.95 | AJ28: 151069.95 | AK28: 151569.95 | AL28: 152069.95 | AM28: 152569.95 | AN28: 153069.95 | AS28: 155069.95 | AT28: 155569.95 | AU28: 156069.95 | AV28: 156569.95 | AW28: 151033.95 | AX28: 151533.95 | AZ28: 155244.35 | BA28: 200321.55 | BB28: 202321.55 | BC28: 198261.55 | BD28: 200701.55 | BF28: 101207.04 | BG28: 101207.04 | BH28: 101207.04 | BI28: 101207.04 | BJ28: 75757.04 | BK28: 45757.04 | BL28: 45757.04 | BM28: 45157.04 | BN28: 45057.04 | BO28: 44957.04 | BP28: 44857.04 | BQ28: 1657.04 | BS28: 1607.04 | BT28: 1557.04 | BU28: 1557.04 | BV28: 1557.04 | BW28: 1557.04 | BX28: 1557.04 | BY28: 1557.04 | BZ28: 1557.04 | CA28: 1557.04 | CB28: 1557.04 | CC28: 1557.04 | CD28: 1557.04 | CF28: =CE28-CD28 -> -1557.04 | CH28: 0 | CI28: 0 | CJ28: 0 | CK28: 0 | CL28: 0 | CM28: 0 | CN28: 0
A29: Non Withdrawable Deposits | B29: 128848216 | C29: 130204762 | D29: 145890587 | E29: 156610517 | F29: 1.5671857e+08 | G29: 1.5838375e+08 | H29: 1.5896245e+08 | I29: 1.3637148e+08 | J29: 161715862 | K29: 1.6185376e+08 | L29: 0 | M29: 0 | N29: 0 | O29: 0 | P29: 0 | Q29: 0 | R29: 161769899 | S29: 1.6178052e+08 | T29: 1.6125205e+08 | U29: 1.6125205e+08 | V29: 1.5995688e+08 | W29: 1.6197022e+08 | X29: 0 | Y29: 1.6004019e+08 | Z29: 1.6148697e+08 | AA29: 1.5409612e+08 | AB29: 1.5120571e+08 | AC29: 1.5312251e+08 | AD29: 1.5502215e+08 | AE29: 157923433 | AF29: 1.5340365e+08 | AG29: 1.5361809e+08 | AH29: 1.5264917e+08 | AI29: 1.5241044e+08 | AJ29: 1.5252124e+08 | AK29: 1.5250097e+08 | AL29: 1.5227467e+08 | AM29: 1.5201312e+08 | AN29: 1.5219687e+08 | AS29: 1.5217194e+08 | AT29: 1.5213616e+08 | AU29: 1.5204878e+08 | AV29: 1.5197089e+08 | AW29: 1.5219423e+08 | AX29: 1.5199217e+08 | AZ29: 1.5447931e+08 | BA29: 1.5222877e+08 | BB29: 1.5113678e+08 | BC29: 1.4955925e+08 | BD29: 1.4987494e+08 | BE29: 149658884 | BF29: 1.6295599e+08 | BG29: 1.6310723e+08 | BH29: 1.6185558e+08 | BI29: 1.5733913e+08 | BJ29: 1.5627358e+08 | BK29: 1.5676967e+08 | BL29: 1.5564191e+08 | BM29: 1.553147e+08 | BN29: 1.553467e+08 | BO29: 1.5548696e+08 | BP29: 1.5478064e+08 | BQ29: 1.5571877e+08 | BR29: 149658884 | BS29: 1.5610297e+08 | BT29: 1.5769099e+08 | BU29: 1.5772671e+08 | BV29: 1.5727119e+08 | BW29: 1.4264036e+08 | BX29: 1.4262557e+08 | BY29: 1.4217613e+08 | BZ29: 1.4222665e+08 | CA29: 1.4248021e+08 | CB29: 1.4268014e+08 | CC29: 1.4320854e+08 | CD29: 1.4412939e+08 | CE29: 144129387 | CF29: =CE29-CD29 -> 0.47999999 | CG29: 144129387 | CH29: 1.4728323e+08 | CI29: 1.4714901e+08 | CJ29: 1.4493057e+08 | CK29: 1.4480849e+08 | CL29: 1.4451672e+08 | CM29: 1.4334142e+08 | CN29: 1.4303848e+08
A30: Total Deposit Liabilities | B30: =SUM(B27:B29) -> 186817277 | C30: =SUM(C27:C29) -> 170977491 | D30: =SUM(D27:D29) -> 170258234 | E30: =SUM(E27:E29) -> 174558061 | F30: =SUM(F27:F29) -> 1.5032662e+08 | G30: =SUM(G27:G29) -> 1.8015749e+08 | H30: =SUM(H27:H29) -> 1.7733028e+08 | I30: =SUM(I27:I29) -> 1.698913e+08 | ... CE30: =SUM(CE27:CE29) -> 185174019 | CF30: =CE30-CD30 -> -9999.12 | CG30: =SUM(CG27:CG29) -> 185174019 | CH30: =SUM(CH27:CH29) -> 1.9036574e+08 | CI30: =SUM(CI27:CI29) -> 1.8723154e+08 | CJ30: =SUM(CJ27:CJ29) -> 1.8153826e+08 | CK30: =SUM(CK27:CK29) -> 1.8080648e+08 | CL30: =SUM(CL27:CL29) -> 1.7953732e+08 | CM30: =SUM(CM27:CM29) -> 1.7931511e+08 | CN30: =SUM(CN27:CN29) -> 1.7907863e+08
A31: Tax Payable | C31: 0 | F31: 0 | G31: 0 | H31: 0 | I31: 0 | J31: 0 | K31: 0 | L31: 0 | M31: 0 | N31: 0 | O31: 0 | P31: 0 | Q31: 0 | R31: 0 | S31: 0 | T31: 0 | U31: 0 | V31: 0 | W31: 1042683 | X31: 0 | Y31: 0 | Z31: 0 | AA31: 0 | AB31: 0 | AC31: 0 | AD31: 0 | AE31: 1042683 | AF31: 0 | AG31: 0 | AH31: 0 | AI31: 0 | AJ31: 0 | AK31: 0 | AL31: 0 | AM31: 0 | AN31: 0 | AS31: 0 | AT31: 0 | AU31: 0 | AV31: 0 | AW31: 0 | AX31: 0 | AZ31: 0 | BA31: 0 | BB31: 0 | BC31: 0 | BD31: 0 | BE31: 136406 | BF31: 0 | BG31: 0 | BH31: 0 | BI31: 0 | BJ31: 0 | BK31: 0 | BL31: 0 | BM31: 0 | BN31: 0 | BO31: 0 | BP31: 0 | BQ31: 0 | BR31: 136406 | BS31: 0 | BT31: 0 | BU31: 0 | BV31: 0 | BW31: 0 | BX31: 0 | BY31: 0 | BZ31: 0 | CA31: 0 | CB31: 0 | CC31: 0 | CD31: 0 | CE31: 136406 | CF31: =CE31-CD31 -> 136406 | CG31: 136406 | CH31: 0 | CI31: 0 | CJ31: 0 | CK31: 0 | CL31: 0 | CM31: 0 | CN31: 0
A32: Dividends Payable | C32: 0 | F32: 0 | G32: 0 | H32: 0 | I32: 0 | L32: 0 | M32: 0 | N32: 0 | O32: 0 | P32: 0 | Q32: 0 | R32: 0 | S32: 1042683 | T32: 1042683 | U32: 1042683 | V32: 1042683 | W32: 0 | X32: 0 | Y32: 0 | Z32: 0 | AA32: 0 | AB32: 0 | AC32: 0 | AD32: 0 | AF32: 0 | AG32: 0 | AH32: 0 | AI32: 0 | AJ32: 0 | AK32: 0 | AL32: 0 | AM32: 0 | AN32: 0 | AS32: 0 | AT32: 0 | AU32: 0 | AV32: 0 | AW32: 0 | AX32: 0 | AZ32: 0 | BA32: 0 | BB32: 0 | BC32: 0 | BD32: 0 | BF32: 0 | BG32: 0 | BH32: 0 | BI32: 0 | BJ32: 0 | BK32: 0 | BL32: 0 | BM32: 0 | BN32: 0 | BO32: 0 | BP32: 0 | BQ32: 0 | BS32: 0 | BT32: 0 | BU32: 0 | BV32: 0 | BW32: 0 | BX32: 0 | BY32: 0 | BZ32: 0 | CA32: 0 | CB32: 0 | CC32: 0 | CD32: 0 | CF32: =CE32-CD32 -> 0 | CH32: 0 | CI32: 0 | CJ32: 0 | CK32: 0 | CL32: 0 | CM32: 0 | CN32: 0
A33: Deferred Tax Liability | C33: 0 | F33: 0 | G33: 0 | H33: 0 | I33: 0 | L33: 0 | M33: 0 | N33: 0 | O33: 0 | P33: 0 | Q33: 0 | R33: 0 | S33: 0 | T33: 0 | U33: 0 | V33: 0 | W33: 0 | X33: 2735015.9 | Y33: 3464782.5 | Z33: 10942375 | AA33: 14519640 | AB33: 10678179 | AC33: -2824086.5 | AD33: 0 | AF33: -9257363.7 | AG33: 6274559.2 | AH33: 8266876.7 | AI33: 0 | AJ33: 5093329.7 | AK33: -2023697.9 | AL33: 9767507.1 | AM33: 8935102 | AN33: 8024562.5 | AS33: 9276903.2 | AT33: 18124506 | AU33: 22870275 | AV33: 18762521 | AW33: 18680443 | AX33: 22314158 | AZ33: 26608336 | BA33: 25262334 | BB33: 27379840 | BC33: 27161524 | BD33: 28891592 | BE33: 0 | BF33: 0 | BG33: 18792412 | BH33: 27538024 | BI33: 0 | BJ33: 14694137 | BK33: 15160895 | BL33: 13992983 | BM33: 14847996 | BN33: 17165913 | BO33: -4532781.4 | BP33: 12881050 | BQ33: 17070839 | BS33: 15110494 | BT33: 0 | BU33: 0 | BV33: 12389089 | BW33: 24548441 | BX33: 15293757 | BY33: 25137339 | BZ33: 25137339 | CA33: 17022136 | CB33: 32641631 | CC33: 41756059 | CD33: 32641631 | CF33: =CE33-CD33 -> -32641631 | CH33: 11227276 | CI33: 14154846 | CJ33: 11305068 | CK33: 10864906 | CL33: 10616199 | CM33: 15732582 | CN33: 16063820
A34: Retirement Benefits Liabilty | C34: 0 | F34: 0 | G34: 0 | H34: 0 | I34: 0 | L34: 0 | M34: 0 | N34: 0 | O34: 0 | P34: 0 | Q34: 0 | R34: 0 | S34: 0 | T34: 0 | U34: 0 | V34: 0 | W34: 0 | X34: 0 | Y34: 0 | Z34: 0 | AA34: 0 | AB34: 0 | AC34: 0 | AD34: 0 | AF34: 0 | AG34: 0 | AH34: 0 | AI34: 0 | AJ34: 0 | AK34: 0 | AL34: 0 | AM34: 0 | AN34: 0 | AS34: 0 | AT34: 0 | AU34: 0 | AV34: 0 | AW34: 0 | AX34: 0 | AZ34: 0 | BA34: 0 | BB34: 0 | BC34: 0 | BD34: 0 | BF34: 0 | BG34: 0 | BH34: 0 | BI34: 0 | BJ34: 0 | BK34: 0 | BL34: 0 | BM34: 0 | BN34: 0 | BO34: 0 | BP34: 0 | BQ34: 0 | BS34: 0 | BT34: 0 | BU34: 0 | BV34: 0 | BW34: 0 | BX34: 0 | BY34: 0 | BZ34: 0 | CA34: 0 | CB34: 0 | CC34: 0 | CD34: 0 | CF34: =CE34-CD34 -> 0 | CH34: 0 | CI34: 0 | CJ34: 0 | CK34: 0 | CL34: 0 | CM34: 0 | CN34: 0
A35: Other Liabilities | B35: 33671151 | C35: 14909432 | D35: 17468618 | E35: 19703464 | F35: 3374285.2 | G35: 22071660 | H35: 6893937.5 | I35: 1626901 | J35: 7979658 | K35: 7466349.9 | L35: 0 | M35: 0 | N35: 0 | O35: 0 | P35: 0 | Q35: 0 | R35: =1042683+8823138 -> 9865821 | S35: 0 | T35: 0 | U35: 4512705.1 | V35: 3836489.6 | W35: 8337542.6 | X35: 0 | Y35: 0 | Z35: 0 | AA35: 0 | AB35: 0 | AC35: 0 | AD35: 4882916.4 | AE35: 16538988 | AF35: 0 | AG35: 0 | AH35: 0 | AI35: 5072297.7 | AJ35: 0 | AK35: 0 | AL35: 0 | AM35: 0 | AN35: 0 | AS35: 0 | AT35: 0 | AU35: 0 | AV35: 0 | AW35: 0 | AX35: 0 | AZ35: 0 | BA35: 0 | BB35: 0 | BC35: 0 | BD35: 0 | BE35: 16707213 | BF35: 22287053 | BG35: 0 | BH35: 0 | BI35: 17881211 | BJ35: 0 | BK35: 0 | BL35: 0 | BM35: 0 | BN35: 0 | BO35: 0 | BP35: 0 | BQ35: 0 | BR35: 17586293 | BS35: 0 | BT35: 16109929 | BU35: 20456018 | BV35: 0 | BW35: 21491853 | BX35: 39174033 | BY35: 25091945 | BZ35: 25091945 | CA35: 215876.44 | CB35: 215876.44 | CC35: 215876.44 | CD35: 215876.44 | CE35: 23456880 | CF35: =CE35-CD35 -> 23241004 | CG35: 23456880 | CH35: 0 | CI35: 0 | CJ35: 0 | CK35: 0 | CL35: 0 | CM35: 0 | CN35: 0
A36: External Borrowings | B36: 5711235 | C36: 3146881 | D36: 18495124 | E36: 29110952 | F36: 28512340 | G36: 28010877 | H36: 24962488 | I36: 24962488 | J36: 23353476 | K36: 23353476 | L36: 0 | M36: 0 | N36: 0 | O36: 0 | P36: 0 | Q36: 0 | R36: 29133453 | S36: 29996387 | T36: 29996387 | U36: 29996387 | V36: 28410979 | W36: 28410979 | X36: 28410979 | Y36: 28410979 | Z36: 28410979 | AA36: 28603585 | AB36: 28410979 | AC36: 24541568 | AD36: 22783568 | AE36: 23403274 | AF36: 23382166 | AG36: 22985845 | AH36: 26089275 | AI36: 22783568 | AJ36: 22783568 | AK36: 22783568 | AL36: 22783568 | AM36: 22783568 | AN36: 27899605 | AS36: 20179593 | AT36: 20179593 | AU36: 23981224 | AV36: 23981224 | AW36: 23981224 | AX36: 23981224 | AZ36: 25384883 | BA36: 25084883 | BB36: 25182043 | BC36: 25032043 | BD36: 25032043 | BE36: 25032043 | BF36: 25032043 | BG36: 26387951 | BH36: 26786652 | BI36: 26187951 | BJ36: 25987951 | BK36: 26174164 | BL36: 26014514 | BM36: 25814514 | BN36: 25814514 | BO36: 25814514 | BP36: 25814514 | BQ36: 25814514 | BR36: 24058606 | BS36: 25814514 | BT36: 25814514 | BU36: 25814514 | BV36: 25814514 | BW36: 25814514 | BX36: 26537750 | BY36: 26597168 | BZ36: 26597168 | CA36: 26597168 | CB36: 26597168 | CC36: 26597168 | CD36: 26597168 | CE36: 26597168 | CF36: =CE36-CD36 -> 0.030000001 | CG36: 26597168 | CH36: 23782824 | CI36: 23685664 | CJ36: 24033302 | CK36: 24033302 | CL36: 24033302 | CM36: 24033302 | CN36: 25789408
A37: Total Liabilities | B37: =SUM(B30:B36) -> 226199663 | C37: =SUM(C30:C36) -> 189033804 | D37: =SUM(D30:D36) -> 206221976 | E37: =SUM(E30:E36) -> 223372477 | F37: =SUM(F30:F36) -> 1.8221325e+08 | G37: =SUM(G30:G36) -> 2.3024003e+08 | H37: =SUM(H30:H36) -> 2.091867e+08 | I37: =SUM(I30:I36) -> 1.9648069e+08 | ... CE37: =SUM(CE30:CE36) -> 235364473 | CF37: =CE37-CD37 -> -9274220.5 | CG37: =SUM(CG30:CG36) -> 235364473 | CH37: =SUM(CH30:CH36) -> 2.2537584e+08 | CI37: =SUM(CI30:CI36) -> 2.2507205e+08 | CJ37: =SUM(CJ30:CJ36) -> 2.1687663e+08 | CK37: =SUM(CK30:CK36) -> 2.1570469e+08 | CL37: =SUM(CL30:CL36) -> 2.1418682e+08 | CM37: =SUM(CM30:CM36) -> 2.19081e+08 | CN37: =SUM(CN30:CN36) -> 2.2093186e+08
A38: Share Capital | B38: 3584500 | C38: 9299642 | D38: 10539885 | E38: 11804277 | F38: 11804277 | G38: 11804277 | H38: 12789238 | I38: 12794938 | J38: 12794938 | K38: 12795398 | L38: 0 | M38: 0 | N38: 0 | O38: 0 | P38: 0 | Q38: 0 | R38: 13382089 | S38: 13383289 | T38: 13384489 | U38: 13364989 | V38: 13364989 | W38: 13408596 | X38: 13408596 | Y38: 0 | Z38: 13408596 | AA38: 13408596 | AB38: 13408596 | AC38: 13418596 | AD38: 13428596 | AE38: 13428596 | AF38: 13468796 | AG38: 13468796 | AH38: 13473796 | AI38: 13473796 | AJ38: 13473796 | AK38: 13473796 | AL38: 13473796 | AM38: 13473796 | AN38: 13473796 | AS38: 13473796 | AT38: 13473796 | AU38: 13473796 | AV38: 13473796 | AW38: 13473796 | AX38: 13473796 | AZ38: 13473796 | BA38: 13580324 | BB38: 13586624 | BC38: 13585924 | BD38: 13613124 | BE38: 13598624 | BF38: 13629924 | BG38: 13629924 | BH38: 13652824 | BI38: 13703324 | BJ38: 13712524 | BK38: 13721824 | BL38: 13721824 | BM38: 13742725 | BN38: 13742724 | BO38: 13742724 | BP38: 13744724 | BQ38: 13747224 | BR38: 13598624 | BS38: 13757224 | BT38: 13763124 | BU38: 13766924 | BV38: 13766924 | BW38: 13766924 | BX38: 13770424 | BY38: 13769924 | BZ38: 13776924 | CA38: 13777924 | CB38: 13793624 | CC38: 13802624 | CD38: 13793624 | CE38: 13824124 | CF38: =CE38-CD38 -> 30499.74 | CG38: 13824124 | CH38: 13849924 | CI38: 13854224 | CJ38: 13854224 | CK38: 13882924 | CL38: 13939124 | CM38: 13939124 | CN38: 13939424
A39: Capital Grants | C39: 0 | F39: 0 | G39: 0 | H39: 0 | I39: 0 | J39: 0 | L39: 0 | M39: 0 | N39: 0 | O39: 0 | P39: 0 | Q39: 0 | R39: 0 | S39: 0 | T39: 0 | U39: 0 | V39: 0 | W39: 0 | X39: 0 | Y39: 13408596 | Z39: 0 | AA39: 0 | AB39: 0 | AC39: 0 | AD39: 0 | AF39: 0 | AG39: 0 | AH39: 0 | AI39: 0 | AJ39: 0 | AK39: 0 | AL39: 0 | AM39: 0 | AN39: 0 | AS39: 0 | AT39: 0 | AU39: 0 | AV39: 0 | AW39: 0 | AX39: 0 | AZ39: 0 | BA39: 0 | BB39: 0 | BC39: 0 | BD39: 0 | BF39: 0 | BG39: 0 | BH39: 0 | BI39: 0 | BJ39: 0 | BK39: 0 | BL39: 0 | BM39: 0 | BN39: 0 | BO39: 0 | BP39: 0 | BQ39: 0 | BS39: 0 | BT39: 0 | BU39: 0 | BV39: 0 | BW39: 0 | BX39: 0 | BY39: 0 | BZ39: 0 | CA39: 0 | CB39: 0 | CC39: 0 | CD39: 0 | CF39: =CE39-CD39 -> 0 | CH39: 0 | CI39: 0 | CJ39: 0 | CK39: 0 | CL39: 0 | CM39: 0 | CN39: 0
A40: Prior Year Retained Earnigs | B40: 45148055 | C40: 22321562 | D40: =22765246-4678446+131265 -> 18218065 | E40: 17898031 | F40: 16488457 | G40: 16418457 | H40: 400110 | I40: 400110 | J40: 14698072 | K40: 14698072 | L40: 0 | M40: 0 | N40: 0 | O40: 0 | P40: 0 | Q40: 0 | R40: 14698071 | S40: 7209735 | T40: 7209735 | U40: 7209735 | V40: 7209735 | W40: 7209735 | X40: 14618579 | Y40: 14618579 | Z40: 14618579 | AA40: 14618579 | AB40: 14618579 | AC40: 14618579 | AD40: 14618579 | AE40: 7209735 | AF40: 14618579 | AG40: 14618579 | AH40: 14618579 | AI40: 14618579 | AJ40: 14618579 | AK40: 14618579 | AL40: 14618579 | AM40: 14618579 | AN40: 14618579 | AS40: -13871946 | AT40: -1.2150779e+08 | AU40: -121507788 | AV40: -121507788 | AW40: -121507788 | AX40: -121507788 | AZ40: -121507788 | BA40: -121507788 | BB40: -121507788 | BC40: -121507788 | BD40: -121507788 | BE40: =-121507788 -> -121507788 | BF40: -1.0417919e+08 | BG40: -121507788 | BH40: -121507788 | BI40: -121507788 | BJ40: -121507788 | BK40: -1.0824497e+08 | BL40: -121507788 | BM40: -121507788 | BN40: -121507788 | BO40: -121507788 | BP40: -121508188 | BQ40: -121508188 | BR40: =-111971756 -> -111971756 | BS40: -121508188 | BT40: -121508188 | BU40: -121507788 | BV40: -121508188 | BW40: -121507788 | BX40: -121507788 | BY40: -121507788 | BZ40: -121507788 | CA40: -121507788 | CB40: -121507788 | CC40: -121507788 | CD40: -121507788 | CE40: =-92767830 -> -92767830 | CF40: =CE40-CD40 -> 28739958 | CG40: =-92767830 -> -92767830 | CH40: -1.1319383e+08 | CI40: -1.1319383e+08 | CJ40: -1.1319383e+08 | CK40: -1.1319383e+08 | CL40: -1.1319383e+08 | CM40: -1.1319383e+08 | CN40: -1.1319383e+08
...

Sheet Evolutitve SCI
B2: 2013 Audited | C2: Audited 2014 | D2: Audited 2015 | E2: Audited 2016 | F2: 42736 | G2: 42767 | H2: 42795 | I2: 42826 | J2: 42856 | K2: 42887 | L2: 42917 | M2: 42948 | N2: 42979 | O2: 43009 | P2: 43040 | Q2: 43070 | R2: Audit 2017 | S2: 43101 | T2: 43132 | U2: 43160 | V2: 43191 | W2: 43221 | X2: 43252 | Y2: 43282 | Z2: 43313 | AA2: 43344 | AB2: 43374 | AC2: 43405 | AD2: 43435 | AE2: 43466 | AF2: Audited 2018 | AG2: 43466 | AH2: 43497 | AI2: 43525 | AJ2: 43556 | AK2: 43586 | AL2: 43617 | AM2: 43647 | AN2: 43678 | AO2: 43709 | AP2: 43739 | AQ2: 43770 | AR2: 43800 | AS2: Auidted 2019 | AT2: 43831 | AU2: 43862 | AV2: 43891 | AW2: 43922 | AX2: 43952 | AY2: 43983 | AZ2: 44013 | BA2: 44044 | BB2: 44075 | BC2: 44105 | BD2: 44136 | BE2: 44166 | BF2: Audited 2020 | BG2: 44197 | BH2: 44228 | BI2: 44256 | BJ2: 44287 | BK2: 44317 | BL2: 44348 | BM2: 44378 | BN2: 44409 | BO2: 44440 | BP2: 44470 | BQ2: 44501 | BR2: 44531 | BS2: Audited 2021 | BT2: 44562 | BU2: 44593 | BV2: 44621 | BW2: 44652 | BX2: 44682 | BY2: 44713 | BZ2: 44743 | CA2: 44774 | CB2: 44805 | CC2: 44835 | CD2: 44866 | CE2: 44896 | CF2: Audited 2022 | CG2: Variances | CH2: Audited 2022 | CI2: 44927 | CJ2: 44958 | CK2: 44986 | CL2: 45017 | CM2: 45047 | CN2: 45078 | CO2: 45108
A3: Financial Income | B3: =B4+B7 -> 45996799 | C3: =C4+C7 -> 54375159 | D3: =D4+D7 -> 48595560 | E3: =E4+E7 -> 53989254 | F3: =F4+F7 -> 4232315.6 | G3: =G4+G7 -> 8563411.9 | H3: =H4+H7 -> 12434932 | I3: =I4+I7 -> 16148706 | ... AB3: =AB4+AB7 -> 18629345 | AC3: 21674260 | AD3: 24091900 | AE3: 24091900 | AF3: =AF4+AF7 -> 24282938 | AG3: =AG4+AG7 -> 484352.05 | AH3: =AH4+AH7 -> 586883.45 | AI3: =AI4+AI7 -> 2517771.5 | AJ3: =AJ4+AJ7 -> 2774906.4 | AK3: =AK4+AK7 -> 2886183.7 | AL3: =AL4+AL7 -> 2976988.7 | AM3: =AM4+AM7 -> 3640147.8 | ... CF3: =CF4+CF7 -> 25717356 | CG3: =CF3-CE3 -> 0.17 | CH3: =CH4+CH7 -> 25717356 | CI3: =CI4+CI7 -> 3262799.5 | CJ3: =CJ4+CJ7 -> 5776818 | CK3: =CK4+CK7 -> 9110763.5 | CL3: =CL4+CL7 -> 11470956 | CM3: =CM4+CM7 -> 13293140 | CN3: =CN4+CN7 -> 14978316 | CO3: =CO4+CO7 -> 15539423
A4: Financial Income From Loans Portfolio | B4: =SUM(B5:B6) -> 26629812 | C4: =SUM(C5:C6) -> 33720956 | D4: =SUM(D5:D6) -> 31919015 | E4: =SUM(E5:E6) -> 35153610 | F4: =SUM(F5:F6) -> 2793175.3 | G4: =SUM(G5:G6) -> 5647256.6 | H4: =SUM(H5:H6) -> 8610510.9 | I4: =SUM(I5:I6) -> 11276471 | ... AB4: =SUM(AB5:AB6) -> 14358650 | AC4: 17010028 | AD4: 18944497 | AE4: 18944497 | AF4: =AF5+AF6 -> 18223801 | AG4: =AG5+AG6 -> 386158.6 | AH4: =AH5+AH6 -> 384148.6 | AI4: =AI5+AI6 -> 2075992.9 | AJ4: =AJ5+AJ6 -> 2303470.3 | AK4: =AK5+AK6 -> 2402914.5 | AL4: =AL5+AL6 -> 2462600.6 | AM4: =AM5+AM6 -> 2963880.2 | ... CF4: =CF5+CF6 -> 18523663 | CG4: =CF4-CE4 -> -743887.57 | CH4: =CH5+CH6 -> 18523663 | CI4: =CI5+CI6 -> 2754256.8 | CJ4: =CJ5+CJ6 -> 4819209.5 | CK4: =CK5+CK6 -> 7604065.7 | CL4: =CL5+CL6 -> 9624921 | CM4: =CM5+CM6 -> 10020314 | CN4: =CN5+CN6 -> 10608632 | CO4: =CO5+CO6 -> 10948367
A5: Interest from Loans Portfolio | B5: 26629812 | C5: 32831263 | D5: 29010493 | E5: 34153522 | F5: 2541350.3 | G5: 5368816.4 | H5: 8291411 | I5: 10838487 | J5: 11420544 | K5: =11659081 -> 11659081 | R5: 18220126 | S5: 3349347.4 | T5: 6874118.8 | U5: 7455625.7 | V5: 7729074.3 | W5: 8050570.3 | X5: 8176809.5 | Y5: 8277293.4 | Z5: 9369594 | AA5: 10998176 | AB5: 13587714 | AC5: 16179875 | AD5: 18613489 | AF5: 18067672 | AG5: 314008.6 | AH5: 322048.6 | AI5: 1954396.5 | AJ5: 2180423.9 | AK5: 2279868.1 | AL5: 2329154.2 | AM5: 2802385.5 | AN5: 2906964.4 | AO5: 3277435.5 | AT5: 135158.58 | AU5: 229973.02 | AV5: 442819.19 | AW5: 464443.95 | AX5: 520041.95 | AY5: 672981.85 | BA5: 1119392.4 | BB5: 8234682.4 | BC5: 13615592 | BD5: 14195772 | BE5: 19554038 | BF5: 6826396 | BG5: 570980.43 | BH5: 1722009.8 | BI5: 2476006.2 | BJ5: 3919148.7 | BK5: 4935804.8 | BL5: 6338174.8 | BM5: 7295164.2 | BN5: 8282751.8 | BO5: 9228114.3 | BP5: 10281782 | BQ5: 11730040 | BR5: 12871953 | BS5: 12929353 | BT5: 1596459.6 | BU5: 2170273.3 | BV5: 3752634.6 | BW5: 5570810.6 | BX5: 7457810 | BY5: 7955855 | BZ5: 9281787.2 | CA5: 9836172.6 | CB5: 11632675 | CC5: 14563480 | CD5: 17901667 | CE5: 18523663 | CF5: 18523663 | CG5: =CF5-CE5 -> 0 | CH5: 18523663 | CI5: 2674471.8 | CJ5: 4676624.5 | CK5: 7413930.7 | CL5: 9397186 | CM5: 9776479 | CN5: 10352897 | CO5: 10690232
A6: Fees&Commision on Loan Portfolio | C6: =114723+586850+188120 -> 889693 | D6: 2908522 | E6: 1000088 | F6: 251825 | G6: 278440.2 | H6: 319100 | I6: 437983.3 | J6: 511428 | K6: =287980+313492+96170 -> 697642 | S6: 203477.4 | T6: 171458 | U6: 348210.85 | V6: 428009.75 | W6: 398317.43 | X6: 448171.77 | Y6: 462871.77 | Z6: 879571.77 | AA6: 541657.77 | AB6: 770936.08 | AC6: 830152.74 | AD6: 331008 | AF6: 156129 | AG6: 72150 | AH6: 62100 | AI6: 121596.43 | AJ6: 123046.43 | AK6: 123046.43 | AL6: 133446.43 | AM6: 161494.68 | AN6: 164494.68 | AO6: 166644.68 | AT6: 13750 | AU6: 19900 | AV6: 22400 | AW6: 23450 | AX6: 36700 | AY6: 76500 | BA6: 168900 | BB6: 235400 | BC6: 286350 | BD6: 358114 | BE6: 420514 | BF6: 1211724 | BG6: 310066.83 | BH6: 741194.34 | BI6: 1616714.6 | BJ6: 2247477.3 | BK6: 2923979.6 | BL6: 3445004.8 | BM6: 4262910 | BN6: 4575424.3 | BO6: 5114206.1 | BP6: 5590163.9 | BQ6: 6142077 | BR6: 7208654 | BT6: 603098.54 | BU6: 1469848.2 | BV6: 2195845.1 | BW6: 2602022.4 | BX6: 376070 | BY6: 388237.57 | BZ6: 413137.57 | CA6: 463137.57 | CB6: 532187.57 | CC6: 591987.57 | CD6: 669537.57 | CE6: 743887.57 | CG6: =CF6-CE6 -> -743887.57 | CI6: 79785 | CJ6: 142585 | CK6: 190135 | CL6: 227735 | CM6: 243835 | CN6: 255735 | CO6: 258135
A7: Financial Income from Investments | B7: =SUM(B8:B11) -> 19366987 | C7: =SUM(C8:C11) -> 20654203 | D7: =SUM(D8:D11) -> 16676545 | E7: =SUM(E8:E11) -> 18835644 | F7: =SUM(F8:F11) -> 1439140.3 | G7: =SUM(G8:G11) -> 2916155.3 | H7: =SUM(H8:H11) -> 3824420.7 | I7: =SUM(I8:I11) -> 4872235.2 | ... CF7: =SUM(CF8:CF11) -> 7193693 | CG7: =CF7-CE7 -> 743887.74 | CH7: =SUM(CH8:CH11) -> 7193693 | CI7: =SUM(CI8:CI11) -> 508542.67 | CJ7: =SUM(CJ8:CJ11) -> 957608.59 | CK7: =SUM(CK8:CK11) -> 1506697.9 | CL7: =SUM(CL8:CL11) -> 1846035.1 | CM7: =SUM(CM8:CM11) -> 3272826.3 | CN7: =SUM(CN8:CN11) -> 4369683.9 | CO7: =SUM(CO8:CO11) -> 4591055.7
A8: Government Securities | C8: 0 | E8: 0 | F8: 0 | G8: 0 | H8: 0 | I8: 0 | J8: 0 | K8: 0 | S8: 0 | T8: 0 | U8: 0 | V8: 0 | W8: 0 | X8: 0 | Y8: 0 | AC8: 0 | AD8: 0 | AG8: 0 | AH8: 0 | AI8: 0 | AJ8: 0 | AK8: 0 | AL8: 0 | AM8: 0 | AN8: 0 | AO8: 0 | AT8: 0 | AU8: 0 | AV8: 0 | AW8: 0 | AX8: 0 | AY8: 0 | BA8: 0 | BB8: 0 | BC8: 0 | BD8: 0 | BE8: 0 | BG8: 0 | BH8: 0 | BI8: 0 | BJ8: 0 | BK8: 0 | BL8: 0 | BM8: 0 | BN8: 0 | BO8: 0 | BP8: 0 | BQ8: 0 | BR8: 0 | BT8: 0 | BU8: 0 | BV8: 0 | BW8: 0 | BX8: 0 | BY8: 0 | BZ8: 0 | CA8: 0 | CB8: 0 | CC8: 0 | CD8: 0 | CE8: 0 | CG8: =CF8-CE8 -> 0 | CI8: 0 | CJ8: 0 | CK8: 0 | CL8: 0 | CM8: 0 | CN8: 0 | CO8: 0
A9: Deposits with Banks & other Financial Institutions | B9: 2381220 | C9: 595785 | D9: 1366790 | E9: 1851959 | F9: 0 | G9: 376777.54 | H9: 188388.77 | I9: 188388.77 | J9: 188388.77 | K9: 188388.77 | S9: 22387.36 | T9: 22387.36 | U9: 27255.65 | V9: 98971.56 | W9: 155090.06 | X9: 191449.66 | Y9: 0 | Z9: 127834.41 | AA9: 155090.06 | AB9: 155090.06 | AC9: 155090.06 | AD9: 163044.41 | AG9: 0 | AH9: 0 | AI9: 0 | AJ9: 0 | AK9: 0 | AL9: 0 | AM9: 0 | AN9: 0 | AO9: 0 | AT9: 0 | AU9: 0 | AV9: 0 | AW9: 0 | AX9: 0 | AY9: 0 | BA9: 0 | BB9: 0 | BC9: 0 | BD9: 0 | BE9: 0 | BG9: 0 | BH9: 0 | BI9: 0 | BJ9: 0 | BK9: 0 | BL9: 0 | BM9: 0 | BN9: 0 | BO9: 0 | BP9: 0 | BQ9: 0 | BR9: 0 | BS9: =36189+478187+64555 -> 578931 | BT9: 0 | BU9: 0 | BV9: 0 | BW9: 0 | BX9: 0 | BY9: 0 | BZ9: 0 | CA9: 0 | CB9: 0 | CC9: 0 | CD9: 0 | CE9: 0 | CG9: =CF9-CE9 -> 0 | CI9: 0 | CJ9: 0 | CK9: 0 | CL9: 0 | CM9: 0 | CN9: 0 | CO9: 0
A10: Other Investments | C10: =1726071-239557-3825-10500-9000 -> 1463189 | D10: 462867 | E10: 1127954 | F10: 0 | G10: 0 | H10: 244962 | I10: 244962 | J10: 244962 | K10: 244962 | S10: 0 | T10: 0 | U10: 0 | V10: 0 | W10: 36359.6 | X10: 0 | Y10: 63615.25 | Z10: 63615.25 | AA10: 1573214.6 | AB10: 1573214.6 | AC10: 1573214.6 | AD10: 1621268.1 | AG10: 0 | AH10: 0 | AI10: 0 | AJ10: 0 | AK10: 0 | AL10: 0 | AM10: 0 | AN10: 0 | AO10: 4299019.3 | AT10: 0 | AU10: 0 | AV10: 10836886 | AW10: 10836886 | AX10: 10836886 | AY10: 10836886 | BA10: 10836886 | BB10: 10836886 | BC10: 10836886 | BD10: 10836886 | BE10: 10836886 | BF10: 10836886 | BG10: 0 | BH10: 0 | BI10: 0 | BJ10: 478187.2 | BK10: 478187.2 | BL10: 478187.2 | BM10: 478187.2 | BN10: 478187.2 | BO10: 478187.2 | BP10: 478187.2 | BQ10: 478187.2 | BR10: 478187.2 | BT10: 0 | BU10: 0 | BV10: 0 | BW10: 109937.8 | BX10: 109937.8 | BY10: 286772.4 | BZ10: 747774.7 | CA10: 286772.4 | CB10: 739393.54 | CC10: 901831.34 | CD10: 925345.94 | CE10: 925391.78 | CF10: 243190 | CG10: =CF10-CE10 -> -682201.78 | CH10: 243190 | CI10: 0 | CJ10: 0 | CK10: 0 | CL10: 0 | CM10: 1182180.4 | CN10: 1927060.1 | CO10: 1978247.1
A11: Other Operating Income | B11: 16985767 | C11: =239557+3825+10500+9000+19222040-C6 -> 18595229 | D11: 14846888 | E11: 15855731 | F11: 1439140.3 | G11: 2539377.7 | H11: 3391070 | I11: 4438884.4 | J11: 4390882.3 | K11: =4590814+137900+7509+22893 -> 4759116 | R11: =923419+13153284 -> 14076703 | S11: 562706.33 | T11: 1466211.6 | U11: 1621778.9 | V11: 1761114.9 | W11: 2082584 | X11: 1972634.2 | Y11: 2120522.8 | Z11: 1773924.2 | AA11: 2265427.3 | AB11: 2542390 | AC11: 2935927.3 | AD11: 3363091.4 | AF11: 6059137 | AG11: 98193.45 | AH11: 202734.85 | AI11: 441778.58 | AJ11: 471436.1 | AK11: 483269.17 | AL11: 514388.04 | AM11: 676267.61 | AN11: 2787056.1 | AO11: 602544.09 | AT11: 21657.22 | AU11: 36820.54 | AV11: 85505.95 | AW11: 280782.88 | AX11: 495050.86 | AY11: 762460.27 | BA11: 1383936 | BB11: 1875845.9 | BC11: 2328187.6 | BD11: 2612366.6 | BE11: 3171949.9 | BF11: =14421755-BF10-BF6+1500 -> 2374645 | BG11: 2750 | BH11: 2750 | BI11: 47000 | BJ11: 97120 | BK11: 17120 | BL11: 52907 | BM11: 52907 | BN11: 52907 | BO11: 52907 | BP11: 52907 | BQ11: 52907.33 | BR11: 51108.71 | BS11: 7134262 | BT11: 500 | BU11: 1400 | BV11: 2500 | BW11: 2500 | BX11: 2569992.1 | BY11: 2810105.4 | BZ11: 3140857 | CA11: 3415473.2 | CB11: 3840615.5 | CC11: 4429793.3 | CD11: 4862019.8 | CE11: 5524413.5 | CF11: 6950503 | CG11: =CF11-CE11 -> 1426089.5 | CH11: 6950503 | CI11: 508542.67 | CJ11: 957608.59 | CK11: 1506697.9 | CL11: 1846035.1 | CM11: 2090645.9 | CN11: 2442623.8 | CO11: 2612808.5
A12: Financial Expenses | B12: =SUM(B13:B18) -> 18442033 | C12: =SUM(C13:C18) -> 15779774 | D12: =SUM(D13:D18) -> 12975878 | E12: =SUM(E13:E18) -> 16791656 | F12: =SUM(F13:F18) -> 302389.25 | G12: =SUM(G13:G18) -> 1609364.9 | H12: =SUM(H13:H18) -> 1206799.6 | I12: =SUM(I13:I18) -> 3344707.8 | ... CF12: =SUM(CF13:CF18) -> 1936065 | CG12: =CF12-CE12 -> -0.04 | CH12: =SUM(CH13:CH18) -> 1936065 | CI12: =SUM(CI13:CI18) -> 314225.1 | CJ12: =SUM(CJ13:CJ18) -> 661102.1 | CK12: =SUM(CK13:CK18) -> 692430.04 | CL12: =SUM(CL13:CL18) -> 704607.04 | CM12: =SUM(CM13:CM18) -> 438459.04 | CN12: =SUM(CN13:CN18) -> 443039.04 | CO12: =SUM(CO13:CO18) -> 473375.7
A13: Interest Expense on Deposits | B13: 13850551 | C13: =11067405+2038636 -> 13106041 | D13: 9728141 | E13: 11745789 | F13: 0 | G13: 0 | H13: 72000 | I13: 2029631.5 | J13: 2107631.5 | K13: =2936447+71880 -> 3008327 | S13: 0 | T13: 0 | U13: 0 | V13: 0 | W13: 23836.17 | X13: 23836.17 | Y13: 0 | Z13: 0 | AA13: 0 | AB13: 0 | AC13: 0 | AD13: 23836.17 | AG13: 0 | AH13: 0 | AI13: 0 | AJ13: 0 | AK13: 0 | AL13: 0 | AM13: 0 | AN13: 0 | AO13: 0 | AT13: 0 | AU13: 0 | AV13: 0 | AW13: 0 | AX13: 0 | AY13: 0 | BA13: 0 | BB13: 0 | BC13: 0 | BD13: 0 | BE13: 0 | BG13: 0 | BH13: 0 | BI13: 2776 | BJ13: 2776.03 | BK13: 2776 | BL13: 2776 | BM13: 2776.03 | BN13: 2776.03 | BO13: 2776.03 | BP13: 2776.03 | BQ13: 2776.03 | BR13: 2776.03 | BT13: 0 | BU13: 0 | BV13: 0 | BW13: 0 | BX13: 211770.01 | BY13: 0 | BZ13: 0 | CB13: 0 | CC13: 0 | CD13: 0 | CE13: 0 | CG13: =CF13-CE13 -> 0 | CI13: 0 | CJ13: 0 | CK13: 0 | CL13: 0 | CM13: 0 | CN13: 0 | CO13: 0
A14: Cost of External Borrowings | B14: 2151415 | C14: =191540+439562 -> 631102 | D14: 855130 | E14: 1183523 | F14: 60641.25 | G14: 142725.93 | H14: 231860.45 | I14: 231860.45 | J14: 260648 | K14: 260648 | R14: 767778 | S14: 0 | T14: 43345.04 | U14: 72132.22 | V14: 72132.22 | W14: 72132.22 | X14: 72132.22 | Y14: 72132.22 | Z14: 72132.22 | AA14: 52623.35 | AB14: 72132.22 | AC14: 72132.22 | AD14: 72132.22 | AG14: 0 | AH14: 0 | AI14: 3305707 | AJ14: 0 | AK14: 0 | AL14: 0 | AM14: 0 | AN14: 0 | AO14: 5116036.2 | AT14: 0 | AU14: 0 | AV14: 0 | AW14: 0 | AX14: 0 | AY14: 0 | BA14: 1503659 | BB14: 1503659 | BC14: 1503659 | BD14: 1503659 | BE14: 1503659 | BF14: 1503659 | BG14: 0 | BH14: 0 | BI14: 0 | BJ14: 0 | BK14: 0 | BL14: 0 | BM14: 0 | BN14: 0 | BO14: 0 | BP14: 0 | BQ14: 226563 | BR14: 0 | BS14: 226563 | BT14: 0 | BU14: 0 | BV14: 0 | BW14: 0 | BX14: 0 | BY14: 935006.01 | BZ14: 994424.01 | CA14: 935006.01 | CB14: 994424 | CC14: 994424 | CD14: 1118764.2 | CE14: 1118764.2 | CF14: 1118764 | CG14: =CF14-CE14 -> -0.24 | CH14: 1118764 | CI14: 211770.1 | CJ14: 211770.1 | CK14: 222288.04 | CL14: 222288.04 | CM14: 222288.04 | CN14: 222288.04 | CO14: 222288.04
A15: Dividend Expenses | E15: 590214 | F15: 0 | G15: 72000 | H15: 0 | I15: 0 | J15: 0 | K15: 0 | R15: 145720 | S15: 0 | T15: 0 | U15: 0 | V15: 0 | W15: 0 | X15: 0 | Y15: 0 | Z15: 0 | AA15: 0 | AB15: 0 | AC15: 0 | AD15: 0 | AG15: 0 | AH15: 0 | AI15: 0 | AJ15: 0 | AK15: 0 | AL15: 0 | AM15: 0 | AN15: 0 | AO15: 0 | AT15: 0 | AU15: 0 | AV15: 0 | AW15: 0 | AX15: 0 | AY15: 0 | BA15: 0 | BB15: 0 | BC15: 0 | BD15: 0 | BE15: 0 | BG15: 0 | BH15: 0 | BI15: 0 | BJ15: 0 | BK15: 0 | BL15: 0 | BM15: 0 | BN15: 0 | BO15: 0 | BP15: 0 | BQ15: 0 | BR15: 0 | BT15: 0 | BU15: 0 | BV15: 0 | BW15: 0 | BX15: 0 | BY15: 0 | BZ15: 0 | CA15: 0 | CB15: 0 | CC15: 0 | CD15: 0 | CE15: 0 | CG15: =CF15-CE15 -> 0 | CI15: 0 | CJ15: 0 | CK15: 0 | CL15: 0 | CM15: 0 | CN15: 0 | CO15: 0
A16: Other Financial Expense | C16: 2042631 | D16: 2392607 | E16: 733492 | F16: 71490 | G16: 0 | H16: 902939.1 | I16: 1083215.9 | J16: 1372493 | K16: 1307975 | R16: 2654015 | S16: 278166.42 | T16: 1540900.9 | U16: 1550498.4 | V16: 1552498.4 | W16: 1657219.9 | X16: 1784979 | Y16: 2070573.1 | Z16: 600324.96 | AA16: 2305834.7 | AB16: 2335356.9 | AC16: 2335356.9 | AD16: 2421478.3 | AF16: 3401675 | AG16: 52543.8 | AH16: 52543.8 | AI16: 52543.8 | AJ16: 52543.8 | AK16: 89710.8 | AL16: 89710.8 | AM16: 187198.8 | AN16: 187198.8 | AO16: 0 | AT16: 0 | AU16: 0 | AV16: 377400 | AW16: 377400 | AX16: 49870 | AY16: 49870 | BA16: 146350 | BB16: 146350 | BC16: 213774 | BD16: 228494 | BE16: 250494 | BF16: 213774 | BG16: 0 | BH16: 0 | BI16: 49221 | BJ16: 49221 | BK16: 49221 | BL16: 77750 | BM16: 77750 | BN16: 77750 | BO16: 77750 | BP16: 77750 | BQ16: 77750 | BR16: 77750 | BS16: 421216 | BT16: 305620 | BU16: 305620 | BV16: 305620 | BW16: 305620 | BX16: 578484.73 | BY16: 348311 | BZ16: 302987.29 | CA16: 348311 | CB16: 348311 | CC16: 348311 | CD16: 348311 | CE16: 348311 | CF16: 817301 | CG16: =CF16-CE16 -> 468990 | CH16: 817301 | CI16: 73369 | CJ16: 378989 | CK16: 378989 | CL16: 378989 | CM16: 73369 | CN16: 77949 | CO16: 77949
A17: Fees & Commision Expense | B17: 699121 | C17: 0 | F17: 170258 | G17: 0 | H17: 0 | I17: 0 | S17: 0 | T17: 0 | U17: 0 | V17: 0 | W17: 0 | X17: 0 | Y17: 204558 | Z17: 174558 | AA17: 364558 | AB17: 827158 | AC17: 827158 | AD17: 1181649 | AG17: 95500 | AH17: 125500 | AI17: 131000 | AJ17: 125500 | AK17: 125500 | AL17: 125500 | AM17: 125500 | AN17: 125500 | AO17: 246015.71 | AT17: 0 | AU17: 0 | AV17: 0 | AW17: 0 | AX17: 0 | AY17: 0 | BA17: 0 | BB17: 0 | BC17: 0 | BD17: 0 | BE17: 0 | BG17: 300 | BH17: 300 | BI17: 27120 | BJ17: 51909.96 | BK17: 64941.96 | BL17: 83554 | BM17: 88066 | BN17: 114766 | BO17: 137086 | BP17: 137086 | BQ17: 148036 | BR17: 329256.66 | BT17: 205243.33 | BU17: 205243.33 | BV17: 219723.33 | BW17: 227643.33 | BX17: 670000 | BY17: 281219.33 | BZ17: 348311 | CA17: 319689.29 | CB17: 319689.29 | CC17: 386129.29 | CD17: 408569.29 | CE17: 468989.8 | CG17: =CF17-CE17 -> -468989.8 | CI17: 29086 | CJ17: 70343 | CK17: 91153 | CL17: 103330 | CM17: 142802 | CN17: 142802 | CO17: 173138.66
A18: Other Expenses | B18: 1740946 | C18: 0 | E18: 2538638 | F18: 0 | G18: 1394639 | H18: 0 | I18: 0 | S18: 0 | T18: 0 | U18: 0 | V18: 0 | W18: 0 | X18: 0 | Y18: 0 | Z18: 1510248.2 | AA18: 0 | AB18: 0 | AC18: 0 | AD18: 0 | AF18: 2806015 | AG18: 0 | AH18: 0 | AI18: 0 | AJ18: 0 | AK18: 0 | AL18: 0 | AM18: 0 | AN18: 0 | AO18: 0 | AT18: 0 | AU18: 0 | AV18: 0 | AW18: 0 | AX18: 0 | AY18: 0 | BA18: 0 | BB18: 0 | BC18: 0 | BD18: 0 | BE18: 0 | BG18: 0 | BH18: 0 | BI18: 0 | BJ18: 0 | BK18: 0 | BL18: 0 | BM18: 0 | BN18: 0 | BO18: 0 | BP18: 0 | BQ18: 0 | BR18: 225923 | BT18: 0 | BU18: 211770 | BV18: 211770 | BW18: 0 | BX18: 0 | BY18: 0 | BZ18: 0 | CB18: 0 | CC18: 0 | CD18: 0 | CE18: 0 | CG18: =CF18-CE18 -> 0 | CI18: 0 | CJ18: 0 | CK18: 0 | CL18: 0 | CM18: 0 | CN18: 0 | CO18: 0
A19: Net Financial Income | B19: =B3-B12 -> 27554766 | C19: =C3-C12 -> 38595385 | D19: =D3-D12 -> 35619682 | E19: =E3-E12 -> 37197598 | F19: =F3-F12 -> 3929926.3 | G19: =G3-G12 -> 6954047 | H19: =H3-H12 -> 11228132 | I19: =I3-I12 -> 12803998 | ... CF19: =CF3-CF12 -> 23781291 | CG19: =CF19-CE19 -> 0.21 | CH19: =CH3-CH12 -> 23781291 | CI19: =CI3-CI12 -> 2948574.4 | CJ19: =CJ3-CJ12 -> 5115715.9 | CK19: =CK3-CK12 -> 8418333.5 | CL19: =CL3-CL12 -> 10766349 | CM19: =CM3-CM12 -> 12854681 | CN19: =CN3-CN12 -> 14535277 | CO19: =CO3-CO12 -> 15066047
A20: Allowance for Loan Loss | B20: =B21-B22 -> 0 | C20: =C21-C22 -> 2025688 | D20: =D21-D22 -> 3790859 | E20: =E21-E22 -> 616690 | F20: =F21-F22 -> 0 | G20: =G21-G22 -> 3979310.3 | H20: =H21-H22 -> 3835462.4 | I20: =I21-I22 -> 3835462.4 | ... AB20: =AB21-AB22 -> 0 | AC20: 0 | AD20: 0 | AE20: 0 | AF20: =AF21 -> 10805841 | AG20: =AG21 -> 0 | AH20: =AH21 -> 0 | AI20: =AI21 -> 0 | AJ20: =AJ21 -> 0 | AK20: =AK21 -> 0 | AL20: =AL21 -> 0 | AM20: =AM21 -> 0 | ... BR20: =BR21 -> 0 | BS20: =BS21+BS22 -> 0 | BT20: =BT21+BT22 -> 0 | BU20: =BU21+BU22 -> 0 | BV20: =BV21+BV22 -> 0 | BW20: =BW21+BW22 -> 0 | BX20: =BX21+BX22 -> 0 | BY20: =BY21+BY22 -> 0 | BZ20: =BZ21+BZ22 -> 0 | ... CF20: =CF21+CF22 -> 0 | CG20: =CF20-CE20 -> 0 | CH20: =CH21+CH22 -> 0 | CI20: =CI21+CI22 -> 0 | CJ20: =CJ21+CJ22 -> 0 | CK20: =CK21+CK22 -> 0 | CL20: =CL21+CL22 -> 0 | CM20: =CM21+CM22 -> 0 | CN20: =CN21+CN22 -> 0 | CO20: =CO21+CO22 -> 0
