Workbook
Name BALANCE1_LDA01: '[1]Financial Statements'!$E$112
Name BALANCE1_LDA12: '[1]Financial Statements'!$E$123
Name BALANCE2_LDA01: '[1]Financial Statements'!$F$112
Name BALANCE2_LDA12: '[1]Financial Statements'!$F$123
Name BALANCE3_LDA01: '[1]Financial Statements'!$G$112
Name BALANCE3_LDA12: '[1]Financial Statements'!$G$123
Name BALANCE4_LDA01: '[1]Financial Statements'!$H$112
Name BALANCE4_LDA12: '[1]Financial Statements'!$H$123
Name BALANCE5_LDA01: '[1]Financial Statements'!$I$112
Name BALANCE5_LDA12: '[1]Financial Statements'!$I$123
Name BALANCE6_LDA01: '[1]Financial Statements'!$J$112
Name BALANCE6_LDA12: '[1]Financial Statements'!$J$123
Name NotApplicable: 'Prudential Ratios'!$B$76
Name PEARLS1_LA002: '[1]Financial Statements'!$E$280
Name PEARLS1_LE008: '[1]Financial Statements'!$E$275
Name PEARLS1_LE009: '[1]Financial Statements'!$E$276
Name PEARLS1_LR001: '[1]Financial Statements'!$E$282
Name PEARLS1_LR005: '[1]Financial Statements'!$E$286
Name PEARLS1_LR006: '[1]Financial Statements'!$E$287
Name PEARLS1_LR007: '[1]Financial Statements'!$E$288
Name PEARLS1_LR009: '[1]Financial Statements'!$E$290
Name PEARLS1_LS001: '[1]Financial Statements'!$E$298
Name PEARLS1_LS005: '[1]Financial Statements'!$E$302
Name PEARLS1_LS011: '[1]Financial Statements'!$E$308
Name PEARLS2_LA002: '[1]Financial Statements'!$F$280
Name PEARLS2_LE008: '[1]Financial Statements'!$F$275
Name PEARLS2_LE009: '[1]Financial Statements'!$F$276
Name PEARLS2_LR001: '[1]Financial Statements'!$F$282
Name PEARLS2_LR005: '[1]Financial Statements'!$F$286
Name PEARLS2_LR006: '[1]Financial Statements'!$F$287
Name PEARLS2_LR007: '[1]Financial Statements'!$F$288
Name PEARLS2_LR009: '[1]Financial Statements'!$F$290
Name PEARLS2_LS001: '[1]Financial Statements'!$F$298
Name PEARLS2_LS005: '[1]Financial Statements'!$F$302
Name PEARLS2_LS010: '[1]Financial Statements'!$F$307
Name PEARLS2_LS011: '[1]Financial Statements'!$F$308
Name PEARLS3_LA002: '[1]Financial Statements'!$G$280
Name PEARLS3_LE008: '[1]Financial Statements'!$G$275
Name PEARLS3_LE009: '[1]Financial Statements'!$G$276
Name PEARLS3_LR001: '[1]Financial Statements'!$G$282
Name PEARLS3_LR005: '[1]Financial Statements'!$G$286
Name PEARLS3_LR006: '[1]Financial Statements'!$G$287
Name PEARLS3_LR007: '[1]Financial Statements'!$G$288
Name PEARLS3_LR009: '[1]Financial Statements'!$G$290
Name PEARLS3_LS001: '[1]Financial Statements'!$G$298
Name PEARLS3_LS005: '[1]Financial Statements'!$G$302
Name PEARLS3_LS010: '[1]Financial Statements'!$G$307
Name PEARLS3_LS011: '[1]Financial Statements'!$G$308
Name PEARLS4_LA002: '[1]Financial Statements'!$H$280
Name PEARLS4_LE008: '[1]Financial Statements'!$H$275
Name PEARLS4_LE009: '[1]Financial Statements'!$H$276
Name PEARLS4_LR001: '[1]Financial Statements'!$H$282
Name PEARLS4_LR005: '[1]Financial Statements'!$H$286
Name PEARLS4_LR006: '[1]Financial Statements'!$H$287
Name PEARLS4_LR007: '[1]Financial Statements'!$H$288
Name PEARLS4_LR009: '[1]Financial Statements'!$H$290
Name PEARLS4_LS001: '[1]Financial Statements'!$H$298
Name PEARLS4_LS005: '[1]Financial Statements'!$H$302
Name PEARLS4_LS010: '[1]Financial Statements'!$H$307
Name PEARLS4_LS011: '[1]Financial Statements'!$H$308

Sheet compliance status
B2: audited2017 | C2: 43101 | D2: 43133 | E2: 43165 | F2: 43197 | G2: 43229 | H2: 43261 | I2: 43293 | J2: 43325 | K2: 43357 | L2: 43389 | M2: 43421 | N2: 43453
A3: CORE CAPITAL | B3: =IF('Prudential Ratios'!I6>10,"compliant","not compliant") -> compliant | C3: =IF('Prudential Ratios'!J6>10,"compliant","not compliant") -> compliant | D3: =IF('Prudential Ratios'!K6>10,"compliant","not compliant") -> compliant | E3: =IF('Prudential Ratios'!L6>10,"compliant","not compliant") -> compliant | F3: =IF('Prudential Ratios'!M6>10,"compliant","not compliant") -> compliant | G3: =IF('Prudential Ratios'!N6>10,"compliant","not compliant") -> compliant | H3: =IF('Prudential Ratios'!O6>10,"compliant","not compliant") -> compliant | I3: =IF('Prudential Ratios'!P6>10,"compliant","not compliant") -> compliant | ... N3: =IF('Prudential Ratios'!U6>10,"compliant","not compliant") -> compliant
A4: CCA (Min 10%) | B4: =IF('Prudential Ratios'!I7>10%,"compliant","not compliant") -> compliant | C4: =IF('Prudential Ratios'!J7>10%,"compliant","not compliant") -> compliant | D4: =IF('Prudential Ratios'!K7>10%,"compliant","not compliant") -> compliant | E4: =IF('Prudential Ratios'!L7>10%,"compliant","not compliant") -> compliant | F4: =IF('Prudential Ratios'!M7>10%,"compliant","not compliant") -> compliant | G4: =IF('Prudential Ratios'!N7>10%,"compliant","not compliant") -> compliant | H4: =IF('Prudential Ratios'!O7>10%,"compliant","not compliant") -> compliant | I4: =IF('Prudential Ratios'!P7>10%,"compliant","not compliant") -> compliant | ... N4: =IF('Prudential Ratios'!U7>10%,"compliant","not compliant") -> compliant
A5: ICA (Min 8%) | B5: =IF('Prudential Ratios'!I10>8%,"compliant","not compliant") -> compliant | C5: =IF('Prudential Ratios'!J10>8%,"compliant","not compliant") -> compliant | D5: =IF('Prudential Ratios'!K10>8%,"compliant","not compliant") -> compliant | E5: =IF('Prudential Ratios'!L10>8%,"compliant","not compliant") -> compliant | F5: =IF('Prudential Ratios'!M10>8%,"compliant","not compliant") -> compliant | G5: =IF('Prudential Ratios'!N10>8%,"compliant","not compliant") -> compliant | H5: =IF('Prudential Ratios'!O10>8%,"compliant","not compliant") -> compliant | I5: =IF('Prudential Ratios'!P10>8%,"compliant","not compliant") -> compliant | ... N5: =IF('Prudential Ratios'!U10>8%,"compliant","not compliant") -> compliant
A6: CCD (Min 8%) | B6: =IF('Prudential Ratios'!I8>8%,"compliant","not compliant") -> compliant | C6: =IF('Prudential Ratios'!J8>8%,"compliant","not compliant") -> compliant | D6: =IF('Prudential Ratios'!K8>8%,"compliant","not compliant") -> compliant | E6: =IF('Prudential Ratios'!L8>8%,"compliant","not compliant") -> compliant | F6: =IF('Prudential Ratios'!M8>8%,"compliant","not compliant") -> compliant | G6: =IF('Prudential Ratios'!N8>8%,"compliant","not compliant") -> compliant | H6: =IF('Prudential Ratios'!O8>8%,"compliant","not compliant") -> compliant | I6: =IF('Prudential Ratios'!P8>8%,"compliant","not compliant") -> compliant | ... N6: =IF('Prudential Ratios'!U8>8%,"compliant","not compliant") -> compliant
A7: NPL(5%)
A8: Liquidity(15%) | B8: =IF('Prudential Ratios'!I47>15%,"compliant","not compliant") -> not compliant | C8: =IF('Prudential Ratios'!J47>15%,"compliant","not compliant") -> not compliant | D8: =IF('Prudential Ratios'!K47>15%,"compliant","not compliant") -> not compliant | E8: =IF('Prudential Ratios'!L47>15%,"compliant","not compliant") -> not compliant | F8: =IF('Prudential Ratios'!M47>15%,"compliant","not compliant") -> not compliant | G8: =IF('Prudential Ratios'!N47>15%,"compliant","not compliant") -> not compliant | H8: =IF('Prudential Ratios'!O47>15%,"compliant","not compliant") -> not compliant | I8: =IF('Prudential Ratios'!P47>15%,"compliant","not compliant") -> not compliant | ... N8: =IF('Prudential Ratios'!U47>15%,"compliant","not compliant") -> compliant
A9: NEA (Max 10%) | B9: =IF('Prudential Ratios'!I14<10%,"compliant","not compliant") -> not compliant | C9: =IF('Prudential Ratios'!J14<10%,"compliant","not compliant") -> not compliant | D9: =IF('Prudential Ratios'!K14<10%,"compliant","not compliant") -> not compliant | E9: =IF('Prudential Ratios'!L14<10%,"compliant","not compliant") -> not compliant | F9: =IF('Prudential Ratios'!M14<10%,"compliant","not compliant") -> not compliant | G9: =IF('Prudential Ratios'!N14<10%,"compliant","not compliant") -> not compliant | H9: =IF('Prudential Ratios'!O14<10%,"compliant","not compliant") -> compliant | I9: =IF('Prudential Ratios'!P14<10%,"compliant","not compliant") -> compliant | ... N9: =IF('Prudential Ratios'!U14<10%,"compliant","not compliant") -> compliant
A10: LB ratio (Max 5%) | B10: =IF('Prudential Ratios'!I15<5%,"compliant","not compliant") -> compliant | C10: =IF('Prudential Ratios'!J15<5%,"compliant","not compliant") -> compliant | D10: =IF('Prudential Ratios'!K15<5%,"compliant","not compliant") -> compliant | E10: =IF('Prudential Ratios'!L15<5%,"compliant","not compliant") -> compliant | F10: =IF('Prudential Ratios'!M15<5%,"compliant","not compliant") -> compliant | G10: =IF('Prudential Ratios'!N15<5%,"compliant","not compliant") -> compliant | H10: =IF('Prudential Ratios'!O15<5%,"compliant","not compliant") -> compliant | I10: =IF('Prudential Ratios'!P15<5%,"compliant","not compliant") -> compliant | ... N10: =IF('Prudential Ratios'!U15<5%,"compliant","not compliant") -> compliant
A11: FITD (Max 5%) | B11: =IF('Prudential Ratios'!I19<5%,"compliant","not compliant") -> not compliant | C11: =IF('Prudential Ratios'!J19<5%,"compliant","not compliant") -> not compliant | D11: =IF('Prudential Ratios'!K19<5%,"compliant","not compliant") -> not compliant | E11: =IF('Prudential Ratios'!L19<5%,"compliant","not compliant") -> not compliant | F11: =IF('Prudential Ratios'!M19<5%,"compliant","not compliant") -> not compliant | G11: =IF('Prudential Ratios'!N19<5%,"compliant","not compliant") -> not compliant | H11: =IF('Prudential Ratios'!O19<5%,"compliant","not compliant") -> not compliant | I11: =IF('Prudential Ratios'!P19<5%,"compliant","not compliant") -> not compliant | ... N11: =IF('Prudential Ratios'!U19<5%,"compliant","not compliant") -> not compliant
A12: FICC (Max 40%) | B12: =IF('Prudential Ratios'!I20<40%,"compliant","not compliant") -> not compliant | C12: =IF('Prudential Ratios'!J20<40%,"compliant","not compliant") -> not compliant | D12: =IF('Prudential Ratios'!K20<40%,"compliant","not compliant") -> not compliant | E12: =IF('Prudential Ratios'!L20<40%,"compliant","not compliant") -> not compliant | F12: =IF('Prudential Ratios'!M20<40%,"compliant","not compliant") -> not compliant | G12: =IF('Prudential Ratios'!N20<40%,"compliant","not compliant") -> compliant | H12: =IF('Prudential Ratios'!O20<40%,"compliant","not compliant") -> compliant | I12: =IF('Prudential Ratios'!P20<40%,"compliant","not compliant") -> compliant | ... N12: =IF('Prudential Ratios'!U20<40%,"compliant","not compliant") -> compliant
A13: EB ratio | B13: =IF('Prudential Ratios'!I27<25%,"compliant","not compliant") -> compliant | C13: =IF('Prudential Ratios'!J27<25%,"compliant","not compliant") -> compliant | D13: =IF('Prudential Ratios'!K27<25%,"compliant","not compliant") -> compliant | E13: =IF('Prudential Ratios'!L27<25%,"compliant","not compliant") -> compliant | F13: =IF('Prudential Ratios'!M27<25%,"compliant","not compliant") -> compliant | G13: =IF('Prudential Ratios'!N27<25%,"compliant","not compliant") -> compliant | H13: =IF('Prudential Ratios'!O27<25%,"compliant","not compliant") -> compliant | I13: =IF('Prudential Ratios'!P27<25%,"compliant","not compliant") -> compliant | ... N13: =IF('Prudential Ratios'!U27<25%,"compliant","not compliant") -> compliant
A14: A=S+L | B14: =IF(SFP!#REF!=SFP!#REF!,"balancing","notbalancing") -> #REF! | C14: =IF(SFP!#REF!=SFP!#REF!,"balancing","notbalancing") -> #REF! | D14: =IF(SFP!#REF!=SFP!#REF!,"balancing","notbalancing") -> #REF! | E14: =IF(SFP!#REF!=SFP!#REF!,"balancing","notbalancing") -> #REF! | F14: =IF(SFP!#REF!=SFP!#REF!,"balancing","notbalancing") -> #REF! | G14: =IF(SFP!#REF!=SFP!#REF!,"balancing","notbalancing") -> #REF! | H14: =IF(SFP!#REF!=SFP!#REF!,"balancing","notbalancing") -> #REF! | I14: =IF(SFP!#REF!=SFP!#REF!,"balancing","notbalancing") -> #REF! | ... N14: =IF(SFP!#REF!=SFP!#REF!,"balancing","notbalancing") -> #REF!

Sheet Prudential Ratios
C1: FORTITUDE SACCO SOCIETY LTD
C2: Sacco Financial Performance
C4: FINANCIAL SOUNDNESS INDICATORS | D4: Prude. Std | E4: AUDITED 2013 | F4: AUDITED 2014 | G4: AUDITED 2015 | H4: AUDITED 2016 | I4: AUDITED 2017 | J4: 43101 | K4: 43132 | L4: 43160 | M4: 43191 | N4: 43221 | O4: 43252 | P4: 43282 | Q4: 43313 | R4: 43344 | S4: 43374 | T4: 43405 | U4: 43435 | V4: AUDITED 2018 | W4: 43466 | X4: 43497 | Y4: 43525 | Z4: 43556 | AA4: 43586 | AB4: 43617 | AC4: 43647 | AD4: 43678 | AE4: 43709 | AF4: 43739 | AG4: 43770 | AH4: 43800 | AI4: AUDITED 2019 | AJ4: 43831 | AK4: 43862 | AL4: 43891 | AM4: 43922 | AN4: 43952 | AO4: 43983 | AP4: 44013 | AQ4: 44044 | AR4: 44075 | AS4: 44105 | AT4: 44136 | AU4: 44166 | AV4: 44197 | AW4: 44197 | AX4: 44228 | AY4: 44256 | AZ4: 44287 | BA4: 44317 | BB4: 44348 | BC4: 44378 | BD4: 44409 | BE4: 44440 | BF4: 44470 | BG4: 44501 | BH4: 44531 | BI4: Audited-2021 | BJ4: 44583 | BK4: 44614 | BL4: 44642 | BM4: 44673 | BN4: 44703 | BO4: 44734 | BP4: 44764 | BQ4: 44795 | BR4: 44826 | BS4: 44856 | BT4: 44887 | BU4: 44917 | BV4: Audited-2022 | BW4: 44949 | BX4: 44980 | BY4: 45008 | BZ4: 45039 | CA4: 45069 | CB4: 45100 | CC4: 45130 | CD4: 45161
B5: 1 | C5: CAPITAL ADEQUACY REQUIREMENTS
B6: 1.1 | C6: Core capital | D6: ≥ Ksh.10M | E6: =Financials!C14/1000000 -> 25.989635 | F6: =Financials!D14/1000000 -> 35.288687 | G6: =Financials!E14/1000000 -> 94.944699 | H6: =Financials!F14/1000000 -> 75.269883 | I6: =Financials!G14/1000000 -> 78.35088 | J6: =Financials!H14/1000000 -> 85.261209 | K6: =Financials!I14/1000000 -> 89.373249 | L6: =Financials!J14/1000000 -> 93.106244 | ... AU6: =Financials!AS14/1000000 -> 179.88597 | AW6: =Financials!AU14/1000000 -> 62.318939 | AX6: =Financials!AV14/1000000 -> 62.166031 | AY6: =Financials!AW14/1000000 -> 64.837345 | AZ6: =Financials!AX14/1000000 -> 73.34804 | BA6: =Financials!AY14/1000000 -> 76.554846 | BB6: =Financials!AZ14/1000000 -> 77.700708 | BC6: =Financials!BA14/1000000 -> 79.695653 | BD6: =Financials!BB14/1000000 -> 81.326497 | ... CC6: =Financials!CA14/1000000 -> 0
B7: 1.2 | C7: Core capital /Total Assets | D7: ≥ 10% | E7: =Financials!C14/Financials!C5 -> 0.06345526 | F7: =Financials!D14/Financials!D5 -> 0.083161502 | G7: =Financials!E14/Financials!E5 -> 0.20483458 | H7: =Financials!F14/Financials!F5 -> 0.16493137 | I7: =Financials!G14/Financials!G5 -> 0.17936092 | J7: =Financials!H14/Financials!H5 -> 0.20150658 | K7: =Financials!I14/Financials!I5 -> 0.21135201 | L7: =Financials!J14/Financials!J5 -> 0.22749189 | ... AU7: =Financials!AS14/Financials!AS5 -> 0.24569813 | AW7: =Financials!AU14/Financials!AU5 -> 0.27949299 | AX7: =Financials!AV14/Financials!AV5 -> 0.27821053 | AY7: =Financials!AW14/Financials!AW5 -> 0.28743071 | AZ7: =Financials!AX14/Financials!AX5 -> 0.32214302 | BA7: =Financials!AY14/Financials!AY5 -> 0.3322442 | BB7: =Financials!AZ14/Financials!AZ5 -> 0.33311786 | BC7: =Financials!BA14/Financials!BA5 -> 0.33321642 | BD7: =Financials!BB14/Financials!BB5 -> 0.3314577 | ... CC7: =Financials!CA14/Financials!CA5 -> #DIV/0!
B8: 1.3 | C8: Core capital /Total Deposits | D8: ≥ 8% | E8: =Financials!C14/Financials!C6 -> 0.087708088 | F8: =Financials!D14/Financials!D6 -> 0.10820486 | G8: =Financials!E14/Financials!E6 -> 0.26090139 | H8: =Financials!F14/Financials!F6 -> 0.21334302 | I8: =Financials!G14/Financials!G6 -> 0.22591234 | J8: =Financials!H14/Financials!H6 -> 0.25547967 | K8: =Financials!I14/Financials!I6 -> 0.27117475 | L8: =Financials!J14/Financials!J6 -> 0.29894231 | ... AU8: =Financials!AS14/Financials!AS6 -> 0.33302157 | AW8: =Financials!AU14/Financials!AU6 -> 0.46131948 | AX8: =Financials!AV14/Financials!AV6 -> 0.45505957 | AY8: =Financials!AW14/Financials!AW6 -> 0.47614928 | AZ8: =Financials!AX14/Financials!AX6 -> 0.52261514 | BA8: =Financials!AY14/Financials!AY6 -> 0.54483248 | BB8: =Financials!AZ14/Financials!AZ6 -> 0.54787086 | BC8: =Financials!BA14/Financials!BA6 -> 0.5494075 | BD8: =Financials!BB14/Financials!BB6 -> 0.5440463 | ... CC8: =Financials!CA14/Financials!CA6 -> #DIV/0!
B9: 1.4 | C9: Share Capital/Total Assets | D9: ≤2% | E9: =Financials!C18/Financials!C5 -> 0.019594444 | F9: =Financials!D18/Financials!D5 -> 0.022998192 | G9: =Financials!E18/Financials!E5 -> 0.021441489 | H9: =Financials!F18/Financials!F5 -> 0.021777319 | I9: =Financials!G18/Financials!G5 -> 0.024372395 | J9: =Financials!H18/Financials!H5 -> 0.030581228 | K9: =Financials!I18/Financials!I5 -> 0.034259821 | L9: =Financials!J18/Financials!J5 -> 0.037908675 | ... AU9: =Financials!AS18/Financials!AS5 -> 0.037884342 | AW9: =Financials!AU18/Financials!AU5 -> 0.12436864 | AX9: =Financials!AV18/Financials!AV5 -> 0.12483962 | AY9: =Financials!AW18/Financials!AW5 -> 0.12441108 | AZ9: =Financials!AX18/Financials!AX5 -> 0.12377008 | BA9: =Financials!AY18/Financials!AY5 -> 0.12310058 | BB9: =Financials!AZ18/Financials!AZ5 -> 0.12232881 | BC9: =Financials!BA18/Financials!BA5 -> 0.1200291 | BD9: =Financials!BB18/Financials!BB5 -> 0.11773735 | ... CC9: =Financials!CA18/Financials!CA5 -> #DIV/0!
B10: 1.5 | C10: Institutional Capital/Total Assets | D10: ≥ 8% | E10: =Financials!C15/Financials!C5 -> 0.043860816 | F10: =Financials!D15/Financials!D5 -> 0.06016331 | G10: =Financials!E15/Financials!E5 -> 0.18339309 | H10: =Financials!F15/Financials!F5 -> 0.14315405 | I10: =Financials!G15/Financials!G5 -> 0.15498853 | J10: =Financials!H15/Financials!H5 -> 0.17092535 | K10: =Financials!I15/Financials!I5 -> 0.17709219 | L10: =Financials!J15/Financials!J5 -> 0.18958322 | ... AU10: =Financials!AS15/Financials!AS5 -> 0.20781379 | AW10: =Financials!AU15/Financials!AU5 -> 0.15512435 | AX10: =Financials!AV15/Financials!AV5 -> 0.15337091 | AY10: =Financials!AW15/Financials!AW5 -> 0.16301963 | AZ10: =Financials!AX15/Financials!AX5 -> 0.19837294 | BA10: =Financials!AY15/Financials!AY5 -> 0.20914362 | BB10: =Financials!AZ15/Financials!AZ5 -> 0.21078905 | BC10: =Financials!BA15/Financials!BA5 -> 0.21318733 | BD10: =Financials!BB15/Financials!BB5 -> 0.21372034 | ... CC10: =Financials!CA15/Financials!CA5 -> #DIV/0!
B12: 2 | C12: ASSET MIX AND QUALITY
B13: 2.1 | C13: Non Earning Assets
B14: 2.1.1 | C14: Non earning Assets/Total assets | D14: ≤ 10% | E14: =Financials!C38/Financials!C5 -> 0.13921023 | F14: =Financials!D38/Financials!D5 -> 0.094990974 | G14: =Financials!E38/Financials!E5 -> 0.11800484 | H14: =Financials!F38/Financials!F5 -> 0.12675515 | I14: =Financials!G38/Financials!G5 -> 0.10067358 | J14: =Financials!H38/Financials!H5 -> 0.13039883 | K14: =Financials!I38/Financials!I5 -> 0.1264507 | L14: =Financials!J38/Financials!J5 -> 0.12800998 | ... AU14: =Financials!AS38/Financials!AS5 -> 0.03147327 | AW14: =Financials!AU38/Financials!AU5 -> 0.12843819 | AX14: =Financials!AV38/Financials!AV5 -> 0.12652995 | AY14: =Financials!AW38/Financials!AW5 -> 0.12687347 | AZ14: =Financials!AX38/Financials!AX5 -> 0.11583736 | BA14: =Financials!AY38/Financials!AY5 -> 0.12433636 | BB14: =Financials!AZ38/Financials!AZ5 -> 0.12067688 | BC14: =Financials!BA38/Financials!BA5 -> 0.11768697 | BD14: =Financials!BB38/Financials!BB5 -> 0.12012869 | ... CB14: =Financials!BZ38/Financials!BZ5 -> 0.08297919
B15: 2.1.2 | C15: Property and Equipment/Total Assets | D15: ≤ 5% | E15: =Financials!C39/Financials!C5 -> 0.017833781 | F15: =Financials!D39/Financials!D5 -> 0.01452311 | G15: =Financials!E39/Financials!E5 -> 0.01288188 | H15: =Financials!F39/Financials!F5 -> 0.012663382 | I15: =Financials!G39/Financials!G5 -> 0.013661078 | J15: =Financials!H39/Financials!H5 -> 0.013696816 | K15: =Financials!I39/Financials!I5 -> 0.013297813 | L15: =Financials!J39/Financials!J5 -> 0.013318733 | ... AU15: =Financials!AS39/Financials!AS5 -> 0.0078216417 | AW15: =Financials!AU39/Financials!AU5 -> 0.090453429 | AX15: =Financials!AV39/Financials!AV5 -> 0.089961577 | AY15: =Financials!AW39/Financials!AW5 -> 0.091433653 | AZ15: =Financials!AX39/Financials!AX5 -> 0.090922642 | BA15: =Financials!AY39/Financials!AY5 -> 0.089513999 | BB15: =Financials!AZ39/Financials!AZ5 -> 0.088144287 | BC15: =Financials!BA39/Financials!BA5 -> 0.085622297 | BD15: =Financials!BB39/Financials!BB5 -> 0.083150844 | ... CB15: =Financials!BZ39/Financials!BZ5 -> 0.056581642
B16: 2.1.3 | C16: Non Performing loans/Gross Loans | D16: ≤ 6%
B18: 2.2 | C18: Earning Assets
B19: 2.2.1 | C19: Equities & Investments/Deposits | D19: ≤ 5% | E19: =Financials!C26/Financials!C6 -> 0.060285214 | F19: =Financials!D26/Financials!D6 -> 0.13586799 | G19: =Financials!E26/Financials!E6 -> 0.12176194 | H19: =Financials!F26/Financials!F6 -> 0.11269646 | I19: =Financials!G26/Financials!G6 -> 0.11464343 | J19: =Financials!H26/Financials!H6 -> 0.11914009 | K19: =Financials!I26/Financials!I6 -> 0.12064096 | L19: =Financials!J26/Financials!J6 -> 0.127662 | ... AU19: =Financials!AS26/Financials!AS6 -> 0.0078282924 | AW19: =Financials!AU26/Financials!AU6 -> 0.070609206 | AX19: =Financials!AV26/Financials!AV6 -> 0.069822388 | AY19: =Financials!AW26/Financials!AW6 -> 0.070048282 | AZ19: =Financials!AX26/Financials!AX6 -> 0.067963081 | BA19: =Financials!AY26/Financials!AY6 -> 0.067884385 | BB19: =Financials!AZ26/Financials!AZ6 -> 0.067256274 | BC19: =Financials!BA26/Financials!BA6 -> 0.0667907 | BD19: =Financials!BB26/Financials!BB6 -> 0.064812659 | ... CB19: =Financials!BZ26/Financials!BZ6 -> 0.050172843
B20: 2.2.2 | C20: Equities & Investments/Core Capital | D20: ≤ 40% | E20: =Financials!C26/Financials!C14 -> 0.68733928 | F20: =Financials!D26/Financials!D14 -> 1.2556552 | G20: =Financials!E26/Financials!E14 -> 0.46669717 | H20: =Financials!F26/Financials!F14 -> 0.52824067 | I20: =Financials!G26/Financials!G14 -> 0.50746862 | J20: =Financials!H26/Financials!H14 -> 0.46633884 | K20: =Financials!I26/Financials!I14 -> 0.44488271 | L20: =Financials!J26/Financials!J14 -> 0.42704562 | ... AU20: =Financials!AS26/Financials!AS14 -> 0.023506863 | AW20: =Financials!AU26/Financials!AU14 -> 0.15305923 | AX20: =Financials!AV26/Financials!AV14 -> 0.15343571 | AY20: =Financials!AW26/Financials!AW14 -> 0.14711412 | AZ20: =Financials!AX26/Financials!AX14 -> 0.13004422 | BA20: =Financials!AY26/Financials!AY14 -> 0.1245968 | BB20: =Financials!AZ26/Financials!AZ14 -> 0.12275936 | BC20: =Financials!BA26/Financials!BA14 -> 0.1215686 | BD20: =Financials!BB26/Financials!BB14 -> 0.11913078 | ... CB20: =Financials!BZ26/Financials!BZ14 -> 0.085822356
B21: 2.2.3 | C21: Net Loans & advances /Total assets | D21: NPR | E21: =Financials!C31/Financials!C5 -> 0.76404585 | F21: =Financials!D31/Financials!D5 -> 0.68763307 | G21: =Financials!E31/Financials!E5 -> 0.64642687 | H21: =Financials!F31/Financials!F5 -> 0.67849007 | I21: =Financials!G31/Financials!G5 -> 0.7111169 | J21: =Financials!H31/Financials!H5 -> 0.74479353 | K21: =Financials!I31/Financials!I5 -> 0.73132542 | L21: =Financials!J31/Financials!J5 -> 0.75374882 | ... AU21: =Financials!AS31/Financials!AS5 -> 0.80532255 | AW21: =Financials!AU31/Financials!AU5 -> 0.74028501 | AX21: =Financials!AV31/Financials!AV5 -> 0.72998044 | AY21: =Financials!AW31/Financials!AW5 -> 0.72420355 | AZ21: =Financials!AX31/Financials!AX5 -> 0.71862915 | BA21: =Financials!AY31/Financials!AY5 -> 0.71080982 | BB21: =Financials!AZ31/Financials!AZ5 -> 0.70448937 | BC21: =Financials!BA31/Financials!BA5 -> 0.72125273 | BD21: =Financials!BB31/Financials!BB5 -> 0.70429393 | ... CB21: =Financials!BZ31/Financials!BZ5 -> 0.80124146
B23: 3 | C23: FUNDING MIX
B24: 3.1 | C24: Total Deposits/Total Assets | D24: NPR | E24: =Financials!C6/Financials!C5 -> 0.72348243 | F24: =Financials!D6/Financials!D5 -> 0.76855605 | G24: =Financials!E6/Financials!E5 -> 0.78510346 | H24: =Financials!F6/Financials!F5 -> 0.77308071 | I24: =Financials!G6/Financials!G5 -> 0.79394033 | J24: =Financials!H6/Financials!H5 -> 0.7887382 | K24: =Financials!I6/Financials!I5 -> 0.77939414 | L24: =Financials!J6/Financials!J5 -> 0.76098928 | ... AU24: =Financials!AS6/Financials!AS5 -> 0.73778445 | AW24: =Financials!AU6/Financials!AU5 -> 0.60585559 | AX24: =Financials!AV6/Financials!AV5 -> 0.61137167 | AY24: =Financials!AW6/Financials!AW5 -> 0.60365672 | AZ24: =Financials!AX6/Financials!AX5 -> 0.61640583 | BA24: =Financials!AY6/Financials!AY5 -> 0.60980982 | BB24: =Financials!AZ6/Financials!AZ5 -> 0.60802259 | BC24: =Financials!BA6/Financials!BA5 -> 0.60650141 | BD24: =Financials!BB6/Financials!BB5 -> 0.60924539 | ... CB24: =Financials!BZ6/Financials!BZ5 -> 0.57783879
B25: 3.1.1 | C25: BOSA Deposits/Total Assets | D25: NPR | E25: =Financials!C7/Financials!C5 -> 0.60032314 | F25: =Financials!D7/Financials!D5 -> 0.56787731 | G25: =Financials!E7/Financials!E5 -> 0.5227007 | H25: =Financials!F7/Financials!F5 -> 0.53606475 | I25: =Financials!G7/Financials!G5 -> 0.55681232 | J25: =Financials!H7/Financials!H5 -> 0.56256362 | K25: =Financials!I7/Financials!I5 -> 0.54611909 | L25: =Financials!J7/Financials!J5 -> 0.55267113 | ... AU25: =Financials!AS7/Financials!AS5 -> 0.66533188 | AW25: =Financials!AU7/Financials!AU5 -> 0.55193275 | AX25: =Financials!AV7/Financials!AV5 -> 0.55725721 | AY25: =Financials!AW7/Financials!AW5 -> 0.55615789 | AZ25: =Financials!AX7/Financials!AX5 -> 0.55433576 | BA25: =Financials!AY7/Financials!AY5 -> 0.55238565 | BB25: =Financials!AZ7/Financials!AZ5 -> 0.5492847 | BC25: =Financials!BA7/Financials!BA5 -> 0.54040482 | BD25: =Financials!BB7/Financials!BB5 -> 0.53128651 | ... CB25: =Financials!BZ7/Financials!BZ5 -> 0.51735354
B26: 3.1.2 | C26: FOSA Deposits/Total Assets | D26: NPR | E26: =Financials!C8/Financials!C5 -> 0.12315929 | F26: =Financials!D8/Financials!D5 -> 0.19320636 | G26: =Financials!E8/Financials!E5 -> 0.0087900989 | H26: =Financials!F8/Financials!F5 -> 0.01092182 | I26: =Financials!G8/Financials!G5 -> 0.011620509 | J26: =Financials!H8/Financials!H5 -> 0.016878266 | K26: =Financials!I8/Financials!I5 -> 0.01688339 | L26: =Financials!J8/Financials!J5 -> 0.020765494 | ... AU26: =Financials!AS8/Financials!AS5 -> 0.015541452 | AW26: =Financials!AU8/Financials!AU5 -> 0.053922836 | AX26: =Financials!AV8/Financials!AV5 -> 0.054114463 | AY26: =Financials!AW8/Financials!AW5 -> 0.047498829 | AZ26: =Financials!AX8/Financials!AX5 -> 0.062070074 | BA26: =Financials!AY8/Financials!AY5 -> 0.057424172 | BB26: =Financials!AZ8/Financials!AZ5 -> 0.05873789 | BC26: =Financials!BA8/Financials!BA5 -> 0.066096592 | BD26: =Financials!BB8/Financials!BB5 -> 0.077958881 | ... CB26: =Financials!BZ8/Financials!BZ5 -> 0.060485243
B27: 3.2 | C27: External Borrowing/Total assets | D27: ≤ 25% | E27: =Financials!C9/Financials!C5 -> 0.14272236 | F27: =Financials!D9/Financials!D5 -> 0.0018448707 | G27: =Financials!E9/Financials!E5 -> 0.001688932 | H27: =Financials!F9/Financials!F5 -> 0.0017153851 | I27: =Financials!G9/Financials!G5 -> 0.0017921054 | J27: =Financials!H9/Financials!H5 -> 0.0018501943 | K27: =Financials!I9/Financials!I5 -> 0.001851307 | L27: =Financials!J9/Financials!J5 -> 0.0019127875 | ... AU27: =Financials!AS9/Financials!AS5 -> 0.010282182 | AW27: =Financials!AU9/Financials!AU5 -> 0 | AX27: =Financials!AV9/Financials!AV5 -> 0 | AY27: =Financials!AW9/Financials!AW5 -> 0 | AZ27: =Financials!AX9/Financials!AX5 -> 0 | BA27: =Financials!AY9/Financials!AY5 -> 0 | BB27: =Financials!AZ9/Financials!AZ5 -> 0 | BC27: =Financials!BA9/Financials!BA5 -> 0 | BD27: =Financials!BB9/Financials!BB5 -> 0 | ... CB27: =Financials!BZ9/Financials!BZ5 -> 0.046027731
B29: 4 | C29: GROWTH RATIOS
B30: 4.1 | C30: Total Assets | D30: NPR | E30: =Financials!C5/Financials!B5-1 -> #VALUE! | F30: =Financials!D5/Financials!C5-1 -> 0.036049779 | G30: =Financials!E5/Financials!D5-1 -> 0.092331022 | H30: =Financials!F5/Financials!E5-1 -> -0.015421079 | I30: =Financials!G5/Financials!F5-1 -> -0.042810163 | J30: =Financials!H5/Financials!G5-1 -> -0.031396118 | K30: =Financials!I5/Financials!H5-1 -> -0.00060103252 | L30: =Financials!J5/Financials!I5-1 -> -0.032141825 | ... AU30: =Financials!AS5/Financials!AR5-1 -> 0.021311881 | AW30: =Financials!AU5/Financials!AT5-1 -> -0.69397124 | AX30: =Financials!AV5/Financials!AU5-1 -> 0.0021447072 | AY30: =Financials!AW5/Financials!AV5-1 -> 0.0095143163 | AZ30: =Financials!AX5/Financials!AW5-1 -> 0.0093638189 | BA30: =Financials!AY5/Financials!AX5-1 -> 0.011988304 | BB30: =Financials!AZ5/Financials!AY5-1 -> 0.012305935 | BC30: =Financials!BA5/Financials!AZ5-1 -> 0.025371342 | BD30: =Financials!BB5/Financials!BA5-1 -> 0.025878006 | ... CB30: =Financials!BZ5/Financials!BY5-1 -> 0.040630359
B31: 4.2 | C31: Total Deposits | D31: NPR | E31: =Financials!C6/Financials!B6-1 -> #VALUE! | F31: =Financials!D6/Financials!C6-1 -> 0.10059664 | G31: =Financials!E6/Financials!D6-1 -> 0.11584946 | H31: =Financials!F6/Financials!E6-1 -> -0.03049851 | I31: =Financials!G6/Financials!F6-1 -> -0.016982827 | J31: =Financials!H6/Financials!G6-1 -> -0.037742693 | K31: =Financials!I6/Financials!H6-1 -> -0.012440757 | L31: =Financials!J6/Financials!I6-1 -> -0.054997136 | ... AU31: =Financials!AS6/Financials!AR6-1 -> 0.012195621 | AW31: =Financials!AU6/Financials!AT6-1 -> -0.74982265 | AX31: =Financials!AV6/Financials!AU6-1 -> 0.011268855 | AY31: =Financials!AW6/Financials!AV6-1 -> -0.0032248379 | AZ31: =Financials!AX6/Financials!AW6-1 -> 0.030681386 | BA31: =Financials!AY6/Financials!AX6-1 -> 0.0011592561 | BB31: =Financials!AZ6/Financials!AY6-1 -> 0.0093390731 | BC31: =Financials!BA6/Financials!AZ6-1 -> 0.022806016 | BD31: =Financials!BB6/Financials!BA6-1 -> 0.030519362 | ... CB31: =Financials!BZ6/Financials!BY6-1 -> 0.0075016351
B32: 4.2.1 | C32: FOSA Deposits | D32: NPR | E32: =Financials!C8/Financials!B8-1 -> #VALUE! | F32: =Financials!D8/Financials!C8-1 -> 0.62530497 | G32: =Financials!E8/Financials!D8-1 -> -0.95030341 | H32: =Financials!F8/Financials!E8-1 -> 0.22335302 | I32: =Financials!G8/Financials!F8-1 -> 0.018422997 | J32: =Financials!H8/Financials!G8-1 -> 0.40685358 | K32: =Financials!I8/Financials!H8-1 -> -0.00029768491 | L32: =Financials!J8/Financials!I8-1 -> 0.19040394 | ... AU32: =Financials!AS8/Financials!AR8-1 -> 0.080968024 | AW32: =Financials!AU8/Financials!AT8-1 -> -0.78836591 | AX32: =Financials!AV8/Financials!AU8-1 -> 0.0057060514 | AY32: =Financials!AW8/Financials!AV8-1 -> -0.11390145 | AZ32: =Financials!AX8/Financials!AW8-1 -> 0.31900698 | BA32: =Financials!AY8/Financials!AX8-1 -> -0.063758312 | BB32: =Financials!AZ8/Financials!AY8-1 -> 0.035464906 | BC32: =Financials!BA8/Financials!AZ8-1 -> 0.1538302 | BD32: =Financials!BB8/Financials!BA8-1 -> 0.20999129 | ... CB32: =Financials!BZ8/Financials!BY8-1 -> -0.077330785
B33: 4.2.2 | C33: BOSA Deposits | D33: NPR | E33: =Financials!C7/Financials!B7-1 -> #VALUE! | F33: =Financials!D7/Financials!C7-1 -> -0.019945888 | G33: =Financials!E7/Financials!D7-1 -> 0.0054323143 | H33: =Financials!F7/Financials!E7-1 -> 0.0097519449 | I33: =Financials!G7/Financials!F7-1 -> -0.0057635786 | J33: =Financials!H7/Financials!G7-1 -> -0.021391436 | K33: =Financials!I7/Financials!H7-1 -> -0.029814884 | L33: =Financials!J7/Financials!I7-1 -> -0.020529993 | ... AU33: =Financials!AS7/Financials!AR7-1 -> 0.015944235 | AW33: =Financials!AU7/Financials!AT7-1 -> -0.7452906 | AX33: =Financials!AV7/Financials!AU7-1 -> 0.011812331 | AY33: =Financials!AW7/Financials!AV7-1 -> 0.0075228121 | AZ33: =Financials!AX7/Financials!AW7-1 -> 0.0060568529 | BA33: =Financials!AY7/Financials!AX7-1 -> 0.0084282049 | BB33: =Financials!AZ7/Financials!AY7-1 -> 0.0066231185 | BC33: =Financials!BA7/Financials!AZ7-1 -> 0.0087949143 | BD33: =Financials!BB7/Financials!BA7-1 -> 0.0085682569 | ... CB33: =Financials!BZ7/Financials!BY7-1 -> 0.018449192
B34: 4.3 | C34: Net Loans & advances | D34: NPR | E34: =Financials!C31/Financials!B31-1 -> #VALUE! | F34: =Financials!D31/Financials!C31-1 -> -0.067566311 | G34: =Financials!E31/Financials!D31-1 -> 0.026873422 | H34: =Financials!F31/Financials!E31-1 -> 0.033414684 | I34: =Financials!G31/Financials!F31-1 -> 0.003218627 | J34: =Financials!H31/Financials!G31-1 -> 0.014474421 | K34: =Financials!I31/Financials!H31-1 -> -0.018673179 | L34: =Financials!J31/Financials!I31-1 -> -0.0024660287 | ... AU34: =Financials!AS31/Financials!AR31-1 -> 0.0020600059 | AW34: =Financials!AU31/Financials!AT31-1 -> -0.72004851 | AX34: =Financials!AV31/Financials!AU31-1 -> -0.011804878 | AY34: =Financials!AW31/Financials!AV31-1 -> 0.0015252647 | AZ34: =Financials!AX31/Financials!AW31-1 -> 0.0015944496 | BA34: =Financials!AY31/Financials!AX31-1 -> 0.0009769708 | BB34: =Financials!AZ31/Financials!AY31-1 -> 0.0033046062 | BC34: =Financials!BA31/Financials!AZ31-1 -> 0.049770102 | BD34: =Financials!BB31/Financials!BA31-1 -> 0.0017565645 | ... CB34: =Financials!BZ31/Financials!BY31-1 -> 0.0090317643
B35: 4.4 | C35: Core capital | D35: NPR | E35: =Financials!C14/Financials!B14-1 -> #VALUE! | F35: =Financials!D14/Financials!C14-1 -> 0.35779848 | G35: =Financials!E14/Financials!D14-1 -> 1.6905138 | H35: =Financials!F14/Financials!E14-1 -> -0.20722395 | I35: =Financials!G14/Financials!F14-1 -> 0.040932663 | J35: =Financials!H14/Financials!G14-1 -> 0.088197213 | K35: =Financials!I14/Financials!H14-1 -> 0.048228729 | L35: =Financials!J14/Financials!I14-1 -> 0.041768589 | ... AU35: =Financials!AS14/Financials!AR14-1 -> 0.046783666 | AW35: =Financials!AU14/Financials!AT14-1 -> -0.39979136 | AX35: =Financials!AV14/Financials!AU14-1 -> -0.0024536308 | AY35: =Financials!AW14/Financials!AV14-1 -> 0.042970636 | AZ35: =Financials!AX14/Financials!AW14-1 -> 0.13126224 | BA35: =Financials!AY14/Financials!AX14-1 -> 0.043720401 | BB35: =Financials!AZ14/Financials!AY14-1 -> 0.014967861 | BC35: =Financials!BA14/Financials!AZ14-1 -> 0.025674733 | BD35: =Financials!BB14/Financials!BA14-1 -> 0.020463401 | ... CB35: =Financials!BZ14/Financials!BY14-1 -> 0.13313176
B36: 4.5 | C36: Total Gross Income | D36: NPR | E36: =Financials!C41/Financials!B41-1 -> #VALUE! | F36: =Financials!D41/Financials!C41-1 -> 1.6737639 | G36: =Financials!E41/Financials!D41-1 -> -0.8490746 | H36: =Financials!F41/Financials!E41-1 -> 5.6488554 | I36: =Financials!G41/Financials!F41-1 -> 0.00069450885 | J36: =Financials!H41/Financials!G41-1 -> -0.015117212 | K36: =Financials!I41/Financials!H41-1 -> 0.0014209695 | L36: =Financials!J41/Financials!I41-1 -> 0.0014608583 | ... AU36: =Financials!AS41/Financials!AR41-1 -> 0.042065144 | AW36: =Financials!AU41/Financials!AT41-1 -> -0.30068395 | AX36: =Financials!AV41/Financials!AU41-1 -> 0.38074807 | AY36: =Financials!AW41/Financials!AV41-1 -> 0 | AZ36: =Financials!AX41/Financials!AW41-1 -> 0 | BA36: =Financials!AY41/Financials!AX41-1 -> 0 | BB36: =Financials!AZ41/Financials!AY41-1 -> 0 | BC36: =Financials!BA41/Financials!AZ41-1 -> 0 | BD36: =Financials!BB41/Financials!BA41-1 -> 0 | ... CB36: =Financials!BZ41/Financials!BY41-1 -> -0.00016918768
B37: 4.6 | C37: Membership | D37: NPR | E37: =Financials!C4/Financials!B4-1 -> #VALUE! | F37: =Financials!D4/Financials!C4-1 -> #DIV/0! | G37: =Financials!E4/Financials!D4-1 -> #DIV/0! | H37: =Financials!F4/Financials!E4-1 -> #DIV/0! | I37: =Financials!G4/Financials!F4-1 -> #DIV/0! | J37: =Financials!H4/Financials!G4-1 -> #DIV/0! | K37: =Financials!I4/Financials!H4-1 -> #DIV/0! | L37: =Financials!J4/Financials!I4-1 -> #DIV/0! | ... Q37: =Financials!O4/Financials!N4-1 -> #DIV/0!
B39: 5 | C39: Efficiency Ratios
B40: 5.1 | C40: FinCost-Deposits/Average Deposits | D40: NPR | E40: =Financials!C48/((Financials!C6+Financials!B6)/2) -> #VALUE! | F40: =Financials!D48/((Financials!D6+Financials!C6)/2) -> 0.076341227 | G40: =Financials!E48/((Financials!E6+Financials!D6)/2) -> 0.0071337245 | H40: =Financials!F48/((Financials!F6+Financials!E6)/2) -> 0.0020536809 | I40: =Financials!G48/((Financials!G6+Financials!F6)/2) -> 0.0031188738 | J40: =Financials!H48/((Financials!H6+Financials!G6)/2) -> 0.0042094763 | K40: =Financials!I48/((Financials!I6+Financials!H6)/2) -> 0.0052784953 | L40: =Financials!J48/((Financials!J6+Financials!I6)/2) -> 0.0063742263 | ... AU40: =Financials!AS48/((Financials!AS6+Financials!AR6)/2) -> 0.0026978036 | AW40: =Financials!AU48/((Financials!AU6+Financials!AT6)/2) -> 0.02188751 | AX40: =Financials!AV48/((Financials!AV6+Financials!AU6)/2) -> 0 | AY40: =Financials!AW48/((Financials!AW6+Financials!AV6)/2) -> 0 | AZ40: =Financials!AX48/((Financials!AX6+Financials!AW6)/2) -> 0 | BA40: =Financials!AY48/((Financials!AY6+Financials!AX6)/2) -> 0 | BB40: =Financials!AZ48/((Financials!AZ6+Financials!AY6)/2) -> 0 | BC40: =Financials!BA48/((Financials!BA6+Financials!AZ6)/2) -> 0 | BD40: =Financials!BB48/((Financials!BB6+Financials!BA6)/2) -> 0 | ... CB40: =Financials!BZ48/((Financials!BZ6+Financials!BY6)/2) -> 0
B41: 5.2 | C41: FinCost-Shares/Average Share capital | D41: NPR | E41: =Financials!C49/((Financials!C18+Financials!B18)/2) -> #VALUE! | F41: =Financials!D49/((Financials!D18+Financials!C18)/2) -> 0 | G41: =Financials!E49/((Financials!E18+Financials!D18)/2) -> 0 | H41: =Financials!F49/((Financials!F18+Financials!E18)/2) -> 0 | I41: =Financials!G49/((Financials!G18+Financials!F18)/2) -> 0 | J41: =Financials!H49/((Financials!H18+Financials!G18)/2) -> 0 | K41: =Financials!I49/((Financials!I18+Financials!H18)/2) -> 0 | L41: =Financials!J49/((Financials!J18+Financials!I18)/2) -> 0 | ... AU41: =Financials!AS49/((Financials!AS18+Financials!AR18)/2) -> 0 | AW41: =Financials!AU49/((Financials!AU18+Financials!AT18)/2) -> 0.11899175 | AX41: =Financials!AV49/((Financials!AV18+Financials!AU18)/2) -> 0 | AY41: =Financials!AW49/((Financials!AW18+Financials!AV18)/2) -> 0 | AZ41: =Financials!AX49/((Financials!AX18+Financials!AW18)/2) -> 0 | BA41: =Financials!AY49/((Financials!AY18+Financials!AX18)/2) -> 0 | BB41: =Financials!AZ49/((Financials!AZ18+Financials!AY18)/2) -> 0 | BC41: =Financials!BA49/((Financials!BA18+Financials!AZ18)/2) -> 0 | BD41: =Financials!BB49/((Financials!BB18+Financials!BA18)/2) -> 0 | ... CB41: =Financials!BZ49/((Financials!BZ18+Financials!BY18)/2) -> 0
B42: 5.3 | C42: FinCost-Ext Loans/Average Ext Loans | D42: NPR | E42: =Financials!C50/((Financials!C9+Financials!B9)/2) -> #VALUE! | F42: =Financials!D50/((Financials!D9+Financials!C9)/2) -> 0.20523164 | G42: =Financials!E50/((Financials!E9+Financials!D9)/2) -> 7.2103165 | H42: =Financials!F50/((Financials!F9+Financials!E9)/2) -> 0.081587017 | I42: =Financials!G50/((Financials!G9+Financials!F9)/2) -> 0.097970436 | J42: =Financials!H50/((Financials!H9+Financials!G9)/2) -> 0.14430267 | K42: =Financials!I50/((Financials!I9+Financials!H9)/2) -> 0.24657017 | L42: =Financials!J50/((Financials!J9+Financials!I9)/2) -> 0.30480118 | ... AU42: =Financials!AS50/((Financials!AS9+Financials!AR9)/2) -> 0.0091447684 | AW42: =Financials!AU50/((Financials!AU9+Financials!AT9)/2) -> 0.090580353 | AX42: =Financials!AV50/((Financials!AV9+Financials!AU9)/2) -> #DIV/0! | AY42: =Financials!AW50/((Financials!AW9+Financials!AV9)/2) -> #DIV/0! | AZ42: =Financials!AX50/((Financials!AX9+Financials!AW9)/2) -> #DIV/0! | BA42: =Financials!AY50/((Financials!AY9+Financials!AX9)/2) -> #DIV/0! | BB42: =Financials!AZ50/((Financials!AZ9+Financials!AY9)/2) -> #DIV/0! | BC42: =Financials!BA50/((Financials!BA9+Financials!AZ9)/2) -> #DIV/0! | BD42: =Financials!BB50/((Financials!BB9+Financials!BA9)/2) -> #DIV/0! | ... CB42: =Financials!BZ50/((Financials!BZ9+Financials!BY9)/2) -> 0.064849268
B43: 5.4 | C43: OpEx/Average Total Assets | D43: NPR | E43: =(Financials!C52+Financials!C53)/((Financials!C5+Financials!B5)/2) -> #VALUE! | F43: =(Financials!D52+Financials!D53)/((Financials!D5+Financials!C5)/2) -> 0.026206336 | G43: =(Financials!E52+Financials!E53)/((Financials!E5+Financials!D5)/2) -> 0.017617452 | H43: =(Financials!F52+Financials!F53)/((Financials!F5+Financials!E5)/2) -> 0.0015180532 | I43: =(Financials!G52+Financials!G53)/((Financials!G5+Financials!F5)/2) -> 0.003302234 | J43: =(Financials!H52+Financials!H53)/((Financials!H5+Financials!G5)/2) -> 0.0042012774 | K43: =(Financials!I52+Financials!I53)/((Financials!I5+Financials!H5)/2) -> 0.0049105247 | L43: =(Financials!J52+Financials!J53)/((Financials!J5+Financials!I5)/2) -> 0.006504271 | ... AU43: =(Financials!AS52+Financials!AS53)/((Financials!AS5+Financials!AR5)/2) -> 0.021523732 | AW43: =(Financials!AU52+Financials!AU53)/((Financials!AU5+Financials!AT5)/2) -> 0.024843636 | AX43: =(Financials!AV52+Financials!AV53)/((Financials!AV5+Financials!AU5)/2) -> 0.0058252793 | AY43: =(Financials!AW52+Financials!AW53)/((Financials!AW5+Financials!AV5)/2) -> 0.0091475651 | AZ43: =(Financials!AX52+Financials!AX53)/((Financials!AX5+Financials!AW5)/2) -> 0.010498944 | BA43: =(Financials!AY52+Financials!AY53)/((Financials!AY5+Financials!AX5)/2) -> 0.013498185 | BB43: =(Financials!AZ52+Financials!AZ53)/((Financials!AZ5+Financials!AY5)/2) -> 0.016553811 | BC43: =(Financials!BA52+Financials!BA53)/((Financials!BA5+Financials!AZ5)/2) -> 0.017892709 | BD43: =(Financials!BB52+Financials!BB53)/((Financials!BB5+Financials!BA5)/2) -> 0.020732625 | ... CB43: =(Financials!BZ52+Financials!BZ53)/((Financials!BZ5+Financials!BY5)/2) -> 0.019647727
B44: 5.5 | C44: Avge yield on Net loans | D44: NPR | E44: =Financials!C42/((Financials!C31+Financials!B31)/2) -> #VALUE! | F44: =Financials!D42/((Financials!D31+Financials!C31)/2) -> 0.025609859 | G44: =Financials!E42/((Financials!E31+Financials!D31)/2) -> 0.021452183 | H44: =Financials!F42/((Financials!F31+Financials!E31)/2) -> 0.025418561 | I44: =Financials!G42/((Financials!G31+Financials!F31)/2) -> 0.024967436 | J44: =Financials!H42/((Financials!H31+Financials!G31)/2) -> 0.024748276 | K44: =Financials!I42/((Financials!I31+Financials!H31)/2) -> 0.024803301 | L44: =Financials!J42/((Financials!J31+Financials!I31)/2) -> 0.025070198 | ... AU44: =Financials!AS42/((Financials!AS31+Financials!AR31)/2) -> 0.035811744 | AW44: =Financials!AU42/((Financials!AU31+Financials!AT31)/2) -> 0.028391682 | AX44: =Financials!AV42/((Financials!AV31+Financials!AU31)/2) -> 0.089496305 | AY44: =Financials!AW42/((Financials!AW31+Financials!AV31)/2) -> 0.089962253 | AZ44: =Financials!AX42/((Financials!AX31+Financials!AW31)/2) -> 0.089822141 | BA44: =Financials!AY42/((Financials!AY31+Financials!AX31)/2) -> 0.089706826 | BB44: =Financials!AZ42/((Financials!AZ31+Financials!AY31)/2) -> 0.089515143 | BC44: =Financials!BA42/((Financials!BA31+Financials!AZ31)/2) -> 0.087197802 | BD44: =Financials!BB42/((Financials!BB31+Financials!BA31)/2) -> 0.085056054 | ... CB44: =Financials!BZ42/((Financials!BZ31+Financials!BY31)/2) -> 0.079003776
B46: 6 | C46: Liquidity Ratio
B47: 6.1 | C47: minimum Liquidity | D47: 0.15 | E47: =(SFP!B4+SFP!B11)/(SFP!B31+SFP!B34+SFP!B35+SFP!B36+SFP!B37+SFP!B38) -> 0.12988214 | F47: =(SFP!C4+SFP!C11)/(SFP!C31+SFP!C34+SFP!C35+SFP!C36+SFP!C37+SFP!C38) -> 0.19610163 | G47: =(SFP!D4+SFP!D11)/(SFP!D31+SFP!D34+SFP!D35+SFP!D36+SFP!D37+SFP!D38) -> 0.28117848 | H47: =(SFP!E4+SFP!E11)/(SFP!E31+SFP!E34+SFP!E35+SFP!E36+SFP!E37+SFP!E38) -> 0.1804874 | I47: =(SFP!F4+SFP!F11)/(SFP!F31+SFP!F34+SFP!F35+SFP!F36+SFP!F37+SFP!F38) -> 0.14704211 | J47: =(SFP!G4+SFP!G11)/(SFP!G31+SFP!G34+SFP!G35+SFP!G36+SFP!G37+SFP!G38) -> 0.054056084 | K47: =(SFP!H4+SFP!H11)/(SFP!H31+SFP!H34+SFP!H35+SFP!H36+SFP!H37+SFP!H38) -> 0.08678322 | L47: =(SFP!I4+SFP!I11)/(SFP!I31+SFP!I34+SFP!I35+SFP!I36+SFP!I37+SFP!I38) -> 0.037384218 | ... AU47: =(SFP!AR4+SFP!AR11)/(SFP!AR31+SFP!AR34+SFP!AR35+SFP!AR36+SFP!AR37+SFP!AR38) -> 0.23441974 | AW47: =(SFP!AT4+SFP!AT11)/(SFP!AT31+SFP!AT34+SFP!AT35+SFP!AT36+SFP!AT37+SFP!AT38) -> 0.13809821 | AX47: =(SFP!AU4+SFP!AU11)/(SFP!AU31+SFP!AU34+SFP!AU35+SFP!AU36+SFP!AU37+SFP!AU38) -> 0.15701801 | AY47: =(SFP!AV4+SFP!AV11)/(SFP!AV31+SFP!AV34+SFP!AV35+SFP!AV36+SFP!AV37+SFP!AV38) -> 0.16672167 | AZ47: =(SFP!AW4+SFP!AW11)/(SFP!AW31+SFP!AW34+SFP!AW35+SFP!AW36+SFP!AW37+SFP!AW38) -> 0.20935865 | BA47: =(SFP!AX4+SFP!AX11)/(SFP!AX31+SFP!AX34+SFP!AX35+SFP!AX36+SFP!AX37+SFP!AX38) -> 0.21088948 | BB47: =(SFP!AY4+SFP!AY11)/(SFP!AY31+SFP!AY34+SFP!AY35+SFP!AY36+SFP!AY37+SFP!AY38) -> 0.22953567 | BC47: =(SFP!AZ4+SFP!AZ11)/(SFP!AZ31+SFP!AZ34+SFP!AZ35+SFP!AZ36+SFP!AZ37+SFP!AZ38) -> 0.20904444 | BD47: =(SFP!BA4+SFP!BA11)/(SFP!BA31+SFP!BA34+SFP!BA35+SFP!BA36+SFP!BA37+SFP!BA38) -> 0.23994181 | ... CB47: =(SFP!BY4+SFP!BY11)/(SFP!BY31+SFP!BY34+SFP!BY35+SFP!BY36+SFP!BY37+SFP!BY38) -> 0.1610208
...

Sheet CAELS
B1: FORTITUDE SACCO
B2: FINANCIAL SOUNDNESS INDICATORS | C2: Prude. Std | D2: AUDITED 2013 | E2: AUDITED 2014 | F2: AUDITED 2015 | G2: AUDITED 2016 | H2: AUDITED 2017 | I2: 43101 | J2: 43132 | K2: 43160 | L2: 43191 | M2: 43221 | N2: 43252 | O2: 43282 | P2: 43313 | Q2: 43344 | R2: 43374 | S2: 43405 | T2: 43435 | U2: AUDITED 2018 | V2: 43466 | W2: 43497 | X2: 43525 | Y2: 43556 | Z2: 43586 | AA2: 43617 | AB2: 43647 | AC2: 43678 | AD2: 43709 | AE2: 43739 | AF2: 43770 | AG2: 43800 | AH2: AUDITED 2019 | AI2: 43831 | AJ2: 43862 | AK2: 43891 | AL2: 43922 | AM2: 43952 | AN2: 43983 | AO2: 44013 | AP2: 44044 | AQ2: 44075 | AR2: 44105 | AS2: 44136 | AT2: 44166 | AU2: Audited 2020 | AV2: 44197 | AW2: 44228 | AX2: 44256 | AY2: 44287 | AZ2: 44317 | BA2: 44348 | BB2: 44378 | BC2: 44409 | BD2: 44440 | BE2: 44470 | BF2: 44501 | BG2: 44531 | BH2: Audited-2021 | BI2: 44583 | BJ2: 44614 | BK2: 44642 | BL2: 44673 | BM2: 44703 | BN2: 44734 | BO2: 44764 | BP2: 44795 | BQ2: 44826 | BR2: 44856 | BS2: 44887 | BT2: 44917 | BU2: Audited-2022 | BV2: 44949 | BW2: 44980 | BX2: 45008 | BY2: 45039 | BZ2: 45069 | CA2: 45100
B3: CAPITAL
B4: CORE CAPITAL | C4: ≥ Ksh.10M | D4: ='Prudential Ratios'!E6 -> 25.989635 | E4: ='Prudential Ratios'!F6 -> 35.288687 | F4: ='Prudential Ratios'!G6 -> 94.944699 | G4: ='Prudential Ratios'!H6 -> 75.269883 | H4: ='Prudential Ratios'!I6 -> 78.35088 | I4: ='Prudential Ratios'!J6 -> 85.261209 | J4: ='Prudential Ratios'!K6 -> 89.373249 | K4: ='Prudential Ratios'!L6 -> 93.106244 | ... CA4: ='Prudential Ratios'!CB6 -> 116.20579
B5: CCA | C5: ≥ 10% | D5: ='Prudential Ratios'!E7 -> 0.06345526 | E5: ='Prudential Ratios'!F7 -> 0.083161502 | F5: ='Prudential Ratios'!G7 -> 0.20483458 | G5: ='Prudential Ratios'!H7 -> 0.16493137 | H5: ='Prudential Ratios'!I7 -> 0.17936092 | I5: ='Prudential Ratios'!J7 -> 0.20150658 | J5: ='Prudential Ratios'!K7 -> 0.21135201 | K5: ='Prudential Ratios'!L7 -> 0.22749189 | ... CA5: ='Prudential Ratios'!CB7 -> 0.33781192
B6: ICA | C6: ≥ 8% | D6: ='Prudential Ratios'!E10 -> 0.043860816 | E6: ='Prudential Ratios'!F10 -> 0.06016331 | F6: ='Prudential Ratios'!G10 -> 0.18339309 | G6: ='Prudential Ratios'!H10 -> 0.14315405 | H6: ='Prudential Ratios'!I10 -> 0.15498853 | I6: ='Prudential Ratios'!J10 -> 0.17092535 | J6: ='Prudential Ratios'!K10 -> 0.17709219 | K6: ='Prudential Ratios'!L10 -> 0.18958322 | ... CA6: ='Prudential Ratios'!CB10 -> 0.22992606
B7: CCD | C7: ≥ 8% | D7: ='Prudential Ratios'!E8 -> 0.087708088 | E7: ='Prudential Ratios'!F8 -> 0.10820486 | F7: ='Prudential Ratios'!G8 -> 0.26090139 | G7: ='Prudential Ratios'!H8 -> 0.21334302 | H7: ='Prudential Ratios'!I8 -> 0.22591234 | I7: ='Prudential Ratios'!J8 -> 0.25547967 | J7: ='Prudential Ratios'!K8 -> 0.27117475 | K7: ='Prudential Ratios'!L8 -> 0.29894231 | ... CA7: ='Prudential Ratios'!CB8 -> 0.58461275
B8: Asset Quality
B9: NPL | C9: ≤ 6% | Q9: =form4!#REF! -> #REF!
B10: Earnings
B11: ROA | D11: ='Prudential Ratios'!E55 -> #REF! | E11: ='Prudential Ratios'!F55 -> #REF! | F11: ='Prudential Ratios'!G55 -> #REF! | G11: ='Prudential Ratios'!H55 -> #REF! | H11: ='Prudential Ratios'!I55 -> #REF! | I11: ='Prudential Ratios'!J55 -> #REF! | J11: ='Prudential Ratios'!K55 -> #REF! | K11: ='Prudential Ratios'!L55 -> #REF! | ... CA11: ='Prudential Ratios'!CB55 -> 0.053347726
B12: CIR | D12: ='Prudential Ratios'!E56 -> #REF! | E12: ='Prudential Ratios'!F56 -> #REF! | F12: ='Prudential Ratios'!G56 -> #REF! | G12: ='Prudential Ratios'!H56 -> #REF! | H12: ='Prudential Ratios'!I56 -> #REF! | I12: ='Prudential Ratios'!J56 -> #REF! | J12: ='Prudential Ratios'!K56 -> #REF! | K12: ='Prudential Ratios'!L56 -> #REF! | ... CA12: ='Prudential Ratios'!CB56 -> 0.31228585
B13: OER | D13: ='Prudential Ratios'!E57 -> 0.085116251 | E13: ='Prudential Ratios'!F57 -> 0.060332293 | F13: ='Prudential Ratios'!G57 -> 0.050864587 | G13: ='Prudential Ratios'!H57 -> 0.006821232 | H13: ='Prudential Ratios'!I57 -> 0.012065152 | I13: ='Prudential Ratios'!J57 -> 0.016300071 | J13: ='Prudential Ratios'!K57 -> 0.019844365 | K13: ='Prudential Ratios'!L57 -> 0.024996546 | ... CA13: ='Prudential Ratios'!CB57 -> 0.041496513
B14: LIQUIDITY
B15: MIN LIQ | C15: 0.15 | D15: ='Prudential Ratios'!E47 -> 0.12988214 | E15: ='Prudential Ratios'!F47 -> 0.19610163 | F15: ='Prudential Ratios'!G47 -> 0.28117848 | G15: ='Prudential Ratios'!H47 -> 0.1804874 | H15: ='Prudential Ratios'!I47 -> 0.14704211 | I15: ='Prudential Ratios'!J47 -> 0.054056084 | J15: ='Prudential Ratios'!K47 -> 0.08678322 | K15: ='Prudential Ratios'!L47 -> 0.037384218 | ... CA15: ='Prudential Ratios'!CB47 -> 0.1610208
B16: TEC LIQ | D16: ='Prudential Ratios'!E48 -> 0.10957701 | E16: ='Prudential Ratios'!F48 -> 0.14876492 | F16: ='Prudential Ratios'!G48 -> 0.18838483 | G16: ='Prudential Ratios'!H48 -> 0.12915454 | H16: ='Prudential Ratios'!I48 -> 0.10373806 | I16: ='Prudential Ratios'!J48 -> 0.038709044 | J16: ='Prudential Ratios'!K48 -> 0.061113504 | K16: ='Prudential Ratios'!L48 -> 0.02730301 | ... CA16: ='Prudential Ratios'!CB48 -> 0.14477411
B17: EB | C17: ≤ 25% | D17: ='Prudential Ratios'!E27 -> 0.14272236 | E17: ='Prudential Ratios'!F27 -> 0.0018448707 | F17: ='Prudential Ratios'!G27 -> 0.001688932 | G17: ='Prudential Ratios'!H27 -> 0.0017153851 | H17: ='Prudential Ratios'!I27 -> 0.0017921054 | I17: ='Prudential Ratios'!J27 -> 0.0018501943 | J17: ='Prudential Ratios'!K27 -> 0.001851307 | K17: ='Prudential Ratios'!L27 -> 0.0019127875 | ... CA17: ='Prudential Ratios'!CB27 -> 0.046027731
B18: LIQ/TA | D18: ='Prudential Ratios'!E58 -> 0.086323741 | E18: ='Prudential Ratios'!F58 -> 0.12367589 | F18: ='Prudential Ratios'!G58 -> 0.14978838 | G18: ='Prudential Ratios'!H58 -> 0.10763133 | H18: ='Prudential Ratios'!I58 -> 0.083528395 | I18: ='Prudential Ratios'!J58 -> 0.030837288 | J18: ='Prudential Ratios'!K58 -> 0.048197019 | K18: ='Prudential Ratios'!L58 -> 0.021091786 | ... CA18: ='Prudential Ratios'!CB58 -> 0.086787531
B19: STRUCTURE
B20: NEA | C20: ≤ 10% | D20: ='Prudential Ratios'!E14 -> 0.13921023 | E20: ='Prudential Ratios'!F14 -> 0.094990974 | F20: ='Prudential Ratios'!G14 -> 0.11800484 | G20: ='Prudential Ratios'!H14 -> 0.12675515 | H20: ='Prudential Ratios'!I14 -> 0.10067358 | I20: ='Prudential Ratios'!J14 -> 0.13039883 | J20: ='Prudential Ratios'!K14 -> 0.1264507 | K20: ='Prudential Ratios'!L14 -> 0.12800998 | ... CA20: ='Prudential Ratios'!CB14 -> 0.08297919
B21: LB | C21: ≤ 5% | D21: ='Prudential Ratios'!E15 -> 0.017833781 | E21: ='Prudential Ratios'!F15 -> 0.01452311 | F21: ='Prudential Ratios'!G15 -> 0.01288188 | G21: ='Prudential Ratios'!H15 -> 0.012663382 | H21: ='Prudential Ratios'!I15 -> 0.013661078 | I21: ='Prudential Ratios'!J15 -> 0.013696816 | J21: ='Prudential Ratios'!K15 -> 0.013297813 | K21: ='Prudential Ratios'!L15 -> 0.013318733 | ... CA21: ='Prudential Ratios'!CB15 -> 0.056581642
B22: FITD | C22: ≤ 5% | D22: ='Prudential Ratios'!E19 -> 0.060285214 | E22: ='Prudential Ratios'!F19 -> 0.13586799 | F22: ='Prudential Ratios'!G19 -> 0.12176194 | G22: ='Prudential Ratios'!H19 -> 0.11269646 | H22: ='Prudential Ratios'!I19 -> 0.11464343 | I22: ='Prudential Ratios'!J19 -> 0.11914009 | J22: ='Prudential Ratios'!K19 -> 0.12064096 | K22: ='Prudential Ratios'!L19 -> 0.127662 | ... CA22: ='Prudential Ratios'!CB19 -> 0.050172843
B23: FICC | C23: ≤ 40% | D23: ='Prudential Ratios'!E20 -> 0.68733928 | E23: ='Prudential Ratios'!F20 -> 1.2556552 | F23: ='Prudential Ratios'!G20 -> 0.46669717 | G23: ='Prudential Ratios'!H20 -> 0.52824067 | H23: ='Prudential Ratios'!I20 -> 0.50746862 | I23: ='Prudential Ratios'!J20 -> 0.46633884 | J23: ='Prudential Ratios'!K20 -> 0.44488271 | K23: ='Prudential Ratios'!L20 -> 0.42704562 | ... CA23: ='Prudential Ratios'!CB20 -> 0.085822356
BH26: =37194132-32071373 -> 5122759

Sheet Financials
B1: FORTITUDE SACCO SOCIETY
B3: Year | C3: AUDITED 2013 | D3: AUDITED 2014 | E3: AUDITED 2015 | F3: AUDITED 2016 | G3: AUDITED 2017 | H3: 43101 | I3: 43132 | J3: 43160 | K3: 43191 | L3: 43221 | M3: 43252 | N3: 43282 | O3: 43313 | P3: 43344 | Q3: 43374 | R3: 43405 | S3: 43435 | T3: AUDITED 2018 | U3: 43466 | V3: 43497 | W3: 43525 | X3: 43556 | Y3: 43586 | Z3: 43617 | AA3: 43647 | AB3: 43678 | AC3: 43709 | AD3: 43739 | AE3: 43770 | AF3: 43800 | AG3: AUDITED 2019 | AH3: 43831 | AI3: 43862 | AJ3: 43891 | AK3: 43922 | AL3: 43952 | AM3: 43983 | AN3: 44013 | AO3: 44044 | AP3: 44075 | AQ3: 44105 | AR3: 44136 | AS3: 44166 | AT3: AUDITED 2020 | AU3: 44197 | AV3: 44228 | AW3: 44256 | AX3: 44287 | AY3: 44317 | AZ3: 44348 | BA3: 44378 | BB3: 44409 | BC3: 44440 | BD3: 44470 | BE3: 44501 | BF3: 44531 | BG3: Audited-2021 | BH3: 44583 | BI3: 44614 | BJ3: 44642 | BK3: 44673 | BL3: 44703 | BM3: 44734 | BN3: 44764 | BO3: 44795 | BP3: 44826 | BQ3: 44856 | BR3: 44887 | BS3: 44917 | BT3: Audited-2022 | BU3: 44949 | BV3: 44980 | BW3: 45008 | BX3: 45039 | BY3: 45069 | BZ3: 45100
A4: 1 | B4: Membership
A5: 2 | B5: Total Assets | C5: =SFP!B27 -> 409574162 | D5: =SFP!C27 -> 424339220 | E5: =SFP!D27 -> 4.6351889e+08 | F5: =SFP!E27 -> 4.5637093e+08 | G5: =SFP!F27 -> 4.3683362e+08 | H5: =SFP!G27 -> 4.2311874e+08 | I5: =SFP!H27 -> 4.2286443e+08 | J5: =SFP!I27 -> 4.092728e+08 | ... BZ5: =SFP!BY27 -> 3.4399552e+08
A6: 3 | B6: Total Deposits | C6: =SFP!B32 -> 296319708 | D6: =SFP!C32 -> 326128476 | E6: =SFP!D32 -> 3.6391029e+08 | F6: =SFP!E32 -> 3.5281156e+08 | G6: =SFP!F32 -> 3.4681983e+08 | H6: =SFP!G32 -> 3.3372991e+08 | I6: =SFP!H32 -> 3.2957806e+08 | J6: =SFP!I32 -> 3.1145221e+08 | ... BZ6: =SFP!BY32 -> 1.9877396e+08
A7: 3.1 | B7: Deposits-Members(BOSA) | C7: =SFP!B31 -> 245876845 | D7: =SFP!C31 -> 240972613 | E7: =SFP!D31 -> 2.4228165e+08 | F7: =SFP!E31 -> 2.4464437e+08 | G7: =SFP!F31 -> 2.4323434e+08 | H7: =SFP!G31 -> 2.3803121e+08 | I7: =SFP!H31 -> 2.3093434e+08 | J7: =SFP!I31 -> 2.2619326e+08 | ... BZ7: =SFP!BY31 -> 1.779673e+08
A8: 3.2 | B8: Deposits-Customers(FOSA) | C8: =SFP!B29 -> 50442863 | D8: =SFP!C29 -> 81985036 | E8: =SFP!D29 -> 4074376.9 | F8: =SFP!E29 -> 4984401.3 | G8: =SFP!F29 -> 5076228.9 | H8: =SFP!G29 -> 7141510.8 | I8: =SFP!H29 -> 7139384.9 | J8: =SFP!I29 -> 8498751.9 | ... BZ8: =SFP!BY29 -> 20806653
A9: 4 | B9: External Borrowing | C9: =SFP!B39 -> 58455393 | D9: =SFP!C39 -> 782851 | E9: =SFP!D39 -> 782851.88 | F9: =SFP!E39 -> 782851.88 | G9: =SFP!F39 -> 782851.88 | H9: =SFP!G39 -> 782851.88 | I9: =SFP!H39 -> 782851.88 | J9: =SFP!I39 -> 782851.88 | ... BZ9: =SFP!BY39 -> 15833333
A10: 4.1 | B10: Short term Liabilities | C10: =SFP!B34+SFP!B35+SFP!B36+SFP!B37+SFP!B38 -> 26338982 | D10: =SFP!C34+SFP!C35+SFP!C36+SFP!C37+SFP!C38 -> 26646429 | E10: =SFP!D34+SFP!D35+SFP!D36+SFP!D37+SFP!D38 -> 4642444.9 | F10: =SFP!E34+SFP!E35+SFP!E36+SFP!E37+SFP!E38 -> 27506534 | G10: =SFP!F34+SFP!F35+SFP!F36+SFP!F37+SFP!F38 -> 4912342.2 | H10: =SFP!G34+SFP!G35+SFP!G36+SFP!G37+SFP!G38 -> 3344665.9 | I10: =SFP!H34+SFP!H35+SFP!H36+SFP!H37+SFP!H38 -> 3912962.6 | J10: =SFP!I34+SFP!I35+SFP!I36+SFP!I37+SFP!I38 -> 4714182.8 | ... BZ10: =SFP!BY34+SFP!BY35+SFP!BY36+SFP!BY37+SFP!BY38 -> 7440560
A13: 5 | B13: Share capital and Reserves
A14: 5.1 | B14: Core Capital | C14: =C17-C28 -> 25989635 | D14: =D17-D28 -> 35288687 | E14: =E17-E28 -> 94944699 | F14: =F17-F28 -> 75269883 | G14: =G17-G28 -> 78350880 | H14: =H17-H28 -> 85261209 | I14: =I17-I28 -> 89373249 | J14: =J17-J28 -> 93106244 | ... R14: =R17-R28 -> 62725037 | S14: =S17-S26 -> 1.5054802e+08 | T14: =T17-T26 -> 88729697 | U14: =U17-U26 -> 1.5578813e+08 | V14: =V17-V26 -> 1.6340642e+08 | W14: =W17-W26 -> 1.6700553e+08 | X14: =X17-X26 -> 1.1120986e+08 | Y14: =Y17-Y26 -> 1.138181e+08 | Z14: =Z17-Z26 -> 1.231101e+08 | ... AF14: =AF17-AF26 -> 1.6363229e+08 | AG14: =AG17 -> 102637695 | AH14: =AH17 -> 1.7237666e+08 | AI14: =AI17 -> 1.1375632e+08 | AJ14: =AJ17 -> 1.1874227e+08 | AK14: =AK17 -> 1.2874175e+08 | AL14: =AL17 -> 1.3453167e+08 | AM14: =AM17 -> 1.4103633e+08 | AN14: =AN17 -> 0 | ... BZ14: =BZ17 -> 1.1620579e+08
A15: 5.2 | B15: Institutional Capital | C15: =C14-C18 -> 17964257 | D15: =D14-D18 -> 25529652 | E15: =E14-E18 -> 85006164 | F15: =F14-F18 -> 65331348 | G15: =G14-G18 -> 67704199 | H15: =H14-H18 -> 72321719 | I15: =I14-I18 -> 74885989 | J15: =J14-J18 -> 77591254 | ... BZ15: =BZ14-BZ18 -> 79093535
A17: 5.3 | B17: Total Capital | C17: =SUM(C18:C21) -> 25989635 | D17: =SUM(D18:D21) -> 35288687 | E17: =SUM(E18:E21) -> 94944699 | F17: =SUM(F18:F21) -> 75269883 | G17: =SUM(G18:G21) -> 78350880 | H17: =SUM(H18:H21) -> 85261209 | I17: =SUM(I18:I21) -> 89373249 | J17: =SUM(J18:J21) -> 93106244 | ... BZ17: =SUM(BZ18:BZ21) -> 1.1620579e+08
A18: 5.3.1 | B18: Members Share Capital | C18: =SFP!B42 -> 8025378 | D18: =SFP!C42 -> 9759035 | E18: =SFP!D42 -> 9938535.4 | F18: =SFP!E42 -> 9938535.4 | G18: =SFP!F42 -> 10646681 | H18: =SFP!G42 -> 12939491 | I18: =SFP!H42 -> 14487260 | J18: =SFP!I42 -> 15514989 | ... BZ18: =SFP!BY42 -> 37112253
A19: 5.3.3 | B19: Retained Earnings | C19: =SFP!B45 -> 2911424 | D19: =SFP!C45 -> 17652005 | E19: =SFP!D45 -> 78460465 | F19: =SFP!E45 -> 21809944 | G19: =SFP!F45 -> 24152569 | H19: =SFP!G45 -> 29428468 | I19: =SFP!H45 -> 31931789 | J19: =SFP!I45 -> 34574304 | ... BZ19: =SFP!BY45 -> 52261563
A20: 5.3.5 | B20: Statutory Reserves | C20: =SFP!B50 -> 6343633 | D20: =SFP!C50 -> 7743437 | E20: =SFP!D50 -> 6343633 | F20: =SFP!E50 -> 7743437 | G20: =SFP!F50 -> 7743437 | H20: =SFP!G50 -> 7743437 | I20: =SFP!H50 -> 7743437 | J20: =SFP!I50 -> 7743437 | ... BZ20: =SFP!BY50 -> 21677841
A21: 5.3.6 | B21: Capital Reserve | C21: =SFP!B51 -> 8709200 | D21: =SFP!C51 -> 134210 | E21: =SFP!D51 -> 202065.67 | F21: =SFP!E51 -> 35777967 | G21: =SFP!F51 -> 35808193 | H21: =SFP!G51 -> 35149814 | I21: =SFP!H51 -> 35210764 | J21: =SFP!I51 -> 35273514 | ... BZ21: =SFP!BY51 -> 5154131.2
A22: 5.3.7 | B22: Supplementary Capital & reserves
A23: a | B23: Proposed Dividends | C23: =SFP!B53 -> 1302538 | D23: =SFP!C53 -> 0 | E23: =SFP!D53 -> 0 | F23: =SFP!E53 -> 0 | G23: =SFP!F53 -> 0 | H23: =SFP!G53 -> 0 | I23: =SFP!H53 -> 0 | J23: =SFP!I53 -> 0 | ... BZ23: =SFP!BY53 -> 0
A24: b
A26: 6 | B26: Investments | C26: =C27+C28+C29 -> 17863697 | D26: =D27+D28+D29 -> 44310422 | E26: =E27+E28+E29 -> 44310422 | F26: =F27+F28+F29 -> 39760613 | G26: =G27+G28+G29 -> 39760613 | H26: =H27+H28+H29 -> 39760613 | I26: =I27+I28+I29 -> 39760613 | J26: =J27+J28+J29 -> 39760613 | ... BZ26: =BZ27+BZ28+BZ29 -> 9973054.5
A27: 6.1 | B27: Investments in Coop bank, CIC, Kuscco, Kerussu & Codic | C27: =SFP!B13 -> 4267836 | D27: =SFP!C13 -> 39760613 | E27: =SFP!D13 -> 39760613 | F27: =SFP!E13 -> 39760613 | G27: =SFP!F13 -> 39760613 | H27: =SFP!G13 -> 39760613 | I27: =SFP!H13 -> 39760613 | J27: =SFP!I13 -> 39760613 | ... AF27: =SFP!AE13 -> 4228554.9 | AG27: =SFP!AF12 -> 4228556 | AH27: =SFP!AG12 -> 4228554.9 | AI27: =SFP!AH12 -> 4228554.9 | AJ27: =SFP!AI12 -> 4228554.9 | AK27: =SFP!AJ12 -> 4228554.9 | AL27: =SFP!AK12 -> 4228554.9 | AM27: =SFP!AL12 -> 4228554.9 | AN27: =SFP!AM12 -> 0 | ... BZ27: =SFP!BY12 -> 9973054.5
A28: 6.2 | B28: Equity Investments (at cost) | AG28: =SFP!AF13 -> 0 | AH28: =SFP!AG13 -> 0 | AI28: =SFP!AH13 -> 0 | AJ28: =SFP!AI13 -> 0 | AK28: =SFP!AJ13 -> 0 | AL28: =SFP!AK13 -> 0 | AM28: =SFP!AL13 -> 0 | AN28: =SFP!AM13 -> 0 | ... BZ28: =SFP!BY13 -> 0
A29: 6.3 | B29: Deposits in KUSCCO CFP | C29: =SFP!B11 -> 13595861 | D29: =SFP!C11 -> 4549809 | E29: =SFP!D11 -> 4549809 | F29: =SFP!E11 -> 0 | G29: =SFP!F11 -> 0 | H29: =SFP!G11 -> 0 | I29: =SFP!H11 -> 0 | J29: =SFP!I11 -> 0 | ... BZ29: =SFP!BY11 -> 0
A31: 7 | B31: Net Loans & advances | C31: =C32-C33 -> 312933438 | D31: =D32-D33 -> 291789680 | E31: =E32-E33 -> 2.9963107e+08 | F31: =F32-F33 -> 3.0964314e+08 | G31: =G32-G33 -> 3.1063977e+08 | H31: =H32-H33 -> 3.151361e+08 | I31: =I32-I33 -> 3.0925151e+08 | J31: =J32-J33 -> 3.0848889e+08 | ... BZ31: =BZ32-BZ33 -> 2.7562348e+08
A32: 7.1 | B32: Gross Loans & advances | C32: =SFP!B15 -> 320539200 | D32: =SFP!C15 -> 301762103 | E32: =SFP!D15 -> 3.0960349e+08 | F32: =SFP!E15 -> 3.1961557e+08 | G32: =SFP!F15 -> 3.2061219e+08 | H32: =SFP!G15 -> 3.2510852e+08 | I32: =SFP!H15 -> 3.1922393e+08 | J32: =SFP!I15 -> 3.1846131e+08 | ... BZ32: =SFP!BY15 -> 2.8892332e+08
A33: 7.3 | B33: Allowance for loan losses | C33: =SFP!B16 -> 7605762 | D33: =SFP!C16 -> 9972423 | E33: =SFP!D16 -> 9972423.1 | F33: =SFP!E16 -> 9972423.1 | G33: =SFP!F16 -> 9972423.1 | H33: =SFP!G16 -> 9972423.1 | I33: =SFP!H16 -> 9972423.1 | J33: =SFP!I16 -> 9972423.1 | ... BZ33: =SFP!BY16 -> 13299846
