Workbook

Sheet Evolutive SFP
B3: 2010 Audited | C3: 2020 Audited | D3: 44197 | E3: 44228 | F3: 44256 | G3: 44287 | H3: 44317 | I3: 44348 | J3: 44378 | K3: 44409 | L3: 44440 | M3: 44470 | N3: 44501 | O3: 44531 | P3: Audited 2021 | Q3: 44562 | R3: 44593 | S3: 44621 | T3: 44652 | U3: 44682 | V3: 44713 | W3: 44743 | X3: 44774 | Y3: 44805 | Z3: 44835 | AA3: 44866 | AB3: 44896 | AC3: Audited 2022 | AD3: 44927 | AE3: 44958 | AF3: 44986 | AG3: 45017 | AH3: 45047 | AI3: 45078 | AJ3: 45108 | AK3: 45139 | AL3: 45170 | AM3: 45200 | AN3: 45231 | AO3: 45261
A4: Cash & cash Equivalent | B4: =SUM(B5:B6) -> 19363224 | C4: =SUM(C5:C6) -> 193574959 | D4: =SUM(D5:D6) -> 144256863 | E4: =SUM(E5:E6) -> 165308030 | F4: =SUM(F5:F6) -> 150475348 | G4: =SUM(G5:G6) -> 124153511 | H4: =SUM(H5:H6) -> 104105177 | I4: =SUM(I5:I6) -> 54932058 | ... AO4: =SUM(AO5:AO6) -> 0
A5: Cash In Hand | B5: 19363224 | C5: 31678367 | D5: 22607925 | E5: 25776920 | F5: 18846746 | G5: 29309335 | H5: 22456230 | I5: 19492745 | J5: 25501165 | K5: 31191005 | L5: 5979570 | M5: 66954690 | N5: 48228890 | O5: 29753135 | P5: 29753135 | Q5: 38136445 | R5: 23434740 | S5: 24588825 | T5: 27966793 | U5: 30018198 | V5: 27753135 | W5: 68402478 | X5: 17795838 | Y5: 29753135 | Z5: 27170698 | AA5: 14845058 | AB5: 27138810 | AC5: 27138810 | AD5: 12566055 | AE5: 20707485 | AF5: 21780650 | AG5: 18317825 | AH5: 12229965 | AI5: 16835450
A6: Cash at Bank | C6: =193574959-C5 -> 161896592 | D6: 121648938 | E6: 139531110 | F6: 131628602 | G6: 94844176 | H6: 81648947 | I6: 35439313 | J6: 12491083 | K6: -7913475 | L6: -15517561 | M6: 148798080 | N6: 63318986 | O6: 67069333 | P6: =111409082-P5 -> 81655947 | Q6: 46227303 | R6: 56255406 | S6: 24765692 | T6: 49705881 | U6: 23955405 | V6: 13529676 | W6: 277425416 | X6: 264942430 | Y6: 202426975 | Z6: 166124229 | AA6: 157217691 | AB6: 128546955 | AC6: =175369190-AC5 -> 148230380 | AD6: 129162432 | AE6: 68069142 | AF6: 68754920 | AG6: 40485229 | AH6: 27514648 | AI6: 69511188
A7: Prepayment and Sundry | B7: 13400392 | D7: 0 | E7: 0 | F7: 0 | G7: 0 | H7: 0 | I7: 0 | J7: 0 | K7: 0 | L7: 0 | M7: 0 | N7: 0 | O7: 0 | Q7: 0 | R7: 0 | S7: 0 | T7: 0 | U7: 0 | V7: 0 | W7: 0 | X7: 0 | Y7: 0 | Z7: 0 | AA7: 0 | AB7: 0 | AC7: 0 | AD7: 0 | AE7: 0 | AF7: 0 | AG7: 0 | AH7: 0 | AI7: 0
A8: Financial Investment | B8: =SUM(B9:B13) -> 472260 | C8: =SUM(C9:C13) -> 4306550 | D8: =SUM(D9:D13) -> 18693600 | E8: =SUM(E9:E13) -> 18693600 | F8: =SUM(F9:F13) -> 18693600 | G8: =SUM(G9:G13) -> 18693600 | H8: =SUM(H9:H13) -> 18693600 | I8: =SUM(I9:I13) -> 18693600 | ... AO8: =SUM(AO9:AO13) -> 0
A9: Government Securities - Treasury Bills/bonds, | D9: 0 | E9: 0 | F9: 0 | G9: 0 | H9: 0 | I9: 0 | J9: 0 | K9: 0 | L9: 0 | M9: 0 | N9: 0 | O9: 0 | Q9: 0 | R9: 0 | S9: 0 | T9: 0 | U9: 0 | V9: 0 | W9: 0 | X9: 0 | Y9: 0 | Z9: 0 | AA9: 0 | AB9: 0 | AC9: 0 | AD9: 0 | AE9: 0 | AF9: 0 | AG9: 0 | AH9: 0 | AI9: 0
A10: Other Securities - Commercial papers/Bonds | D10: 0 | E10: 0 | F10: 0 | G10: 0 | H10: 0 | I10: 0 | J10: 0 | K10: 0 | L10: 0 | M10: 0 | N10: 0 | O10: 0 | Q10: 0 | R10: 0 | S10: 0 | T10: 0 | U10: 0 | V10: 0 | W10: 0 | X10: 0 | Y10: 0 | Z10: 0 | AA10: 0 | AB10: 0 | AC10: 0 | AD10: 0 | AE10: 0 | AF10: 0 | AG10: 0 | AH10: 0 | AI10: 0
A11: Balances in NACCOS (E.g Jungu Kuu, ESS, Savings,Money Market,Coop FD, CFP) | D11: 13774433 | E11: 13774433 | F11: 13774433 | G11: 13774433 | H11: 13774433 | I11: 13774433 | J11: 13774433 | K11: 13774433 | L11: 13774433 | M11: 13774433 | N11: 13774433 | O11: 13774433 | Q11: 13774433 | R11: 13774433 | S11: 13774433 | T11: 13774433 | U11: 13774433 | V11: 13774433 | W11: 13774433 | X11: 13774433 | Y11: 13774433 | Z11: 13774433 | AA11: 13774433 | AB11: 13774433 | AC11: 0 | AD11: 16341406 | AE11: 16341406 | AF11: 16341406 | AG11: 16341406 | AH11: 17818676 | AI11: 16341406
A12: Equity Investments in NACCOs(Shares in- CIC, KUSCCO, COOP BANK,CAK, KERUSSU) | C12: =4306550-C13 -> 4256550 | P12: =4606550-P13 -> 4556550 | AC12: =4702814-AC13 -> 4652814 | AD12: 4752850 | AE12: 4752850 | AF12: 4752850 | AI12: 4752850
A13: Equity Investments in companies - shares/stocks | B13: 472260 | C13: 50000 | D13: 4919167 | E13: 4919167 | F13: 4919167 | G13: 4919167 | H13: 4919167 | I13: 4919167 | J13: 4919167 | K13: 4919167 | L13: 4919167 | M13: 4919167 | N13: 4919167 | O13: 6006550 | P13: 50000 | Q13: 4406550 | R13: 4406550 | S13: 4406550 | T13: 4406550 | U13: 4406550 | V13: 4406550 | W13: 4406550 | X13: 4406550 | Y13: 4406550 | Z13: 4406550 | AA13: 4406550 | AB13: 4406550 | AC13: 50000 | AG13: 4752850 | AH13: 4752850
A14: Net Loan Portfolio | B14: =B15-B16 -> 112905266 | C14: =C15-C16 -> 560836016 | D14: =D15-D16 -> 600020729 | E14: =E15-E16 -> 596739329 | F14: =F15-F16 -> 576874598 | G14: =G15-G16 -> 579838637 | H14: =H15-H16 -> 557595581 | I14: =I15-I16 -> 6.0581952e+08 | ... AO14: =AO15-AO16 -> 0
A15: Gross Loan Portfolio | B15: 112905266 | C15: 664592356 | D15: 703777069 | E15: 701542064 | F15: 682074733 | G15: 695038772 | H15: 674348122 | I15: 723335812 | J15: 743868312 | K15: 762934145 | L15: 810800645 | M15: 707054084 | N15: 764974931 | O15: 792587190 | P15: 792589211 | Q15: 813471307 | R15: 825025727 | S15: 839202702 | T15: 850862106 | U15: 880182835 | V15: 896587782 | W15: 762077134 | X15: 797954008 | Y15: 830850911 | Z15: 862590172 | AA15: 888516741 | AB15: 910801986 | AC15: 910801986 | AD15: 907335219 | AE15: 969521479 | AF15: 1005641110 | AG15: 1026968565 | AH15: 1054521639 | AI15: 1061569759
A16: Allowance For Loan Loss | C16: 103756340 | D16: 103756340 | E16: 104802735 | F16: 105200135 | G16: 115200135 | H16: 116752541 | I16: 1.1751629e+08 | J16: 128040892 | K16: 134067963 | L16: 138067963 | M16: 136930002 | N16: 141430333 | O16: 153567952 | P16: 153567951 | Q16: 155069054 | R16: 158421154 | S16: 159553734 | T16: 165053734 | U16: 167980236 | V16: 166866302 | W16: 171963037 | X16: 177495137 | Y16: 182689348 | Z16: 189814658 | AA16: 201065908 | AB16: 211297468 | AC16: 211297468 | AD16: 212145200 | AE16: 215936435 | AF16: 232145200 | AG16: 250715325 | AH16: 250715325 | AI16: 251515451
A17: Accounts Recievables | B17: =SUM(B18:B20) -> 0 | C17: =SUM(C18:C20) -> 0 | D17: =SUM(D18:D20) -> 0 | E17: =SUM(E18:E20) -> 0 | F17: =SUM(F18:F20) -> 0 | G17: =SUM(G18:G20) -> 0 | H17: =SUM(H18:H20) -> 0 | I17: =SUM(I18:I20) -> 0 | ... AO17: =SUM(AO18:AO20) -> 0
A18: Tax Recoverable | D18: 0 | E18: 0 | F18: 0 | G18: 0 | H18: 0 | I18: 0 | J18: 0 | K18: 0 | L18: 0 | M18: 0 | N18: 0 | O18: 0 | Q18: 0 | R18: 0 | S18: 0 | T18: 0 | U18: 0 | V18: 0 | W18: 0 | X18: 0 | Y18: 0 | Z18: 0 | AA18: 0 | AB18: 0 | AC18: 0 | AD18: 0 | AE18: 0 | AF18: 0 | AG18: 0 | AH18: 0 | AI18: 0
A19: Deffered Tax Assets | D19: 0 | E19: 0 | F19: 0 | G19: 0 | H19: 0 | I19: 0 | J19: 0 | K19: 0 | L19: 0 | M19: 0 | N19: 0 | O19: 0 | Q19: 0 | R19: 0 | S19: 0 | T19: 0 | U19: 0 | V19: 0 | W19: 0 | X19: 0 | Y19: 0 | Z19: 0 | AA19: 0 | AB19: 0 | AC19: 0 | AD19: 0 | AE19: 0 | AF19: 0 | AG19: 0 | AH19: 0 | AI19: 0
A20: Retirement Benefit Assets | D20: 0 | E20: 0 | F20: 0 | G20: 0 | H20: 0 | I20: 0 | J20: 0 | K20: 0 | L20: 0 | M20: 0 | N20: 0 | O20: 0 | Q20: 0 | R20: 0 | S20: 0 | T20: 0 | U20: 0 | V20: 0 | W20: 0 | X20: 0 | Y20: 0 | Z20: 0 | AA20: 0 | AB20: 0 | AC20: 0 | AD20: 0 | AE20: 0 | AF20: 0 | AG20: 0 | AH20: 0 | AI20: 0
A21: Property&Equipments&Other Assets | B21: =SUM(B22:B26) -> 4874587 | C21: =SUM(C22:C26) -> 14341369 | D21: =SUM(D22:D26) -> 16586304 | E21: =SUM(E22:E26) -> 15545404 | F21: =SUM(F22:F26) -> 16915536 | G21: =SUM(G22:G26) -> 15915536 | H21: =SUM(H22:H26) -> 17664687 | I21: =SUM(I22:I26) -> 17664687 | ... AO21: =SUM(AO22:AO26) -> 0
A22: Investment Properties | D22: 0 | E22: 0 | F22: 0 | G22: 0 | H22: 0 | I22: 0 | J22: 0 | K22: 0 | L22: 0 | M22: 0 | N22: 0 | O22: 0 | Q22: 0 | R22: 0 | S22: 0 | T22: 0 | U22: 0 | V22: 0 | W22: 0 | X22: 0 | Y22: 0 | Z22: 0 | AA22: 0 | AB22: 0 | AC22: 0 | AD22: 0 | AE22: 0 | AF22: 0 | AG22: 0 | AH22: 0 | AI22: 0
A23: Property and Equipment | B23: 4123114 | C23: 13929886 | D23: 13929887 | E23: 13929887 | F23: 13929887 | G23: 13929887 | H23: 13929887 | I23: 13929887 | J23: 13929887 | K23: 13929887 | L23: 13929887 | M23: 13929887 | N23: 13929887 | O23: 13342075 | P23: 13342075 | Q23: 13342074 | R23: 13342075 | S23: 13342074 | T23: 13342074 | U23: 13342074 | V23: 13342074 | W23: 13342075 | X23: 13342074 | Y23: 13342074 | Z23: 13342074 | AA23: 13342074 | AB23: 14463787 | AC23: 18183924 | AD23: 18183924 | AE23: 18183924 | AF23: 18183924 | AG23: 18183924 | AH23: 18183924 | AI23: 18183924
A24: Prepaid Lease Rentals | B24: 0 | D24: 0 | E24: 0 | F24: 0 | G24: 0 | H24: 0 | I24: 0 | J24: 0 | K24: 0 | L24: 0 | M24: 0 | N24: 0 | O24: 0 | Q24: 0 | R24: 0 | S24: 0 | T24: 0 | U24: 0 | V24: 0 | W24: 0 | X24: 0 | Y24: 0 | Z24: 0 | AA24: 0 | AB24: 0 | AC24: 0 | AD24: 0 | AE24: 0 | AF24: 0 | AG24: 0 | AH24: 0 | AI24: 0
A25: Intangible Assets | B25: 751473 | C25: 411483 | D25: 411483 | E25: 411483 | F25: 411483 | G25: 411483 | H25: 411483 | I25: 411483 | J25: 411483 | K25: 411483 | L25: 411483 | M25: 411483 | N25: 411483 | O25: 470038 | P25: 470038 | Q25: 470038 | R25: 470038 | S25: 470038 | T25: 470038 | U25: 470038 | V25: 470038 | W25: 470038 | X25: 470038 | Y25: 470038 | Z25: 470038 | AA25: 470038 | AB25: 470038 | AC25: 343727 | AD25: 343727 | AE25: 343727 | AF25: 343727 | AG25: 343727 | AH25: 343727 | AI25: 343727
A26: Other Assets | D26: 2244934 | E26: 1204034 | F26: 2574166 | G26: 1574166 | H26: 3323317 | I26: 3323317 | J26: 5265077 | K26: 7675926 | L26: 4695409 | M26: 6685000 | N26: 17236444 | O26: 0 | Q26: 4669113 | R26: 4086336 | S26: 16666527 | T26: 16666527 | U26: 19214296 | V26: 10023281 | W26: 19460291 | X26: 19460291 | Y26: 10473583 | Z26: 10473583 | AA26: 10473583 | AB26: 7248129 | AC26: 4789641 | AD26: 27704844 | AE26: 27704844 | AF26: 15870034 | AG26: 27704844 | AH26: 27704844 | AI26: 4616035
A27: Total Assets | B27: =B21+B17+B14+B8+B7+B4 -> 151015729 | C27: =C21+C17+C14+C8+C7+C4 -> 773058894 | D27: =D21+D17+D14+D8+D7+D4 -> 779557496 | E27: =E21+E17+E14+E8+E7+E4 -> 796286363 | F27: =F21+F17+F14+F8+F7+F4 -> 762959082 | G27: =G21+G17+G14+G8+G7+G4 -> 738601284 | H27: =H21+H17+H14+H8+H7+H4 -> 698059045 | I27: =I21+I17+I14+I8+I7+I4 -> 6.9710987e+08 | ... AO27: =AO21+AO17+AO14+AO8+AO7+AO4 -> 0
A28: Savings and Deposits | B28: 8112861 | C28: 417162829 | D28: 231857578 | E28: 229648701 | F28: 177997753 | G28: 117562001 | H28: 89323514 | I28: 78357806 | J28: 69379943 | K28: 74367353 | L28: 80072655 | M28: 176480245 | N28: 132255721 | O28: 115650681 | P28: 111884960 | Q28: 111384499 | R28: 109193930 | S28: 101588304 | T28: 115839712 | U28: 106899491 | V28: 98528350 | W28: 243357988 | X28: 194783142 | Y28: 164073613 | Z28: 143283961 | AA28: 141539250 | AB28: 123538735 | AC28: 123549662 | AD28: 130211376 | AE28: 125373572 | AF28: 133233726 | AG28: 122776559 | AH28: 112078489 | AI28: 114091527
A29: Short Terrm Deposits | B29: 8350444 | D29: 7640525 | E29: 6520000 | F29: 9330078 | G29: 12100078 | H29: 7911500 | I29: 11547125 | J29: 10422200 | K29: 10280600 | L29: 6562400 | M29: 8705925 | N29: 8777425 | O29: 8674425 | P29: 8674425 | Q29: 7040025 | R29: 7040025 | S29: 5756125 | T29: 6901425 | U29: 3759625 | V29: 5310000 | W29: 5310000 | X29: 8427000 | Y29: 11041000 | Z29: 12696800 | AA29: 11163325 | AB29: 12468325 | AC29: 12468325 | AD29: 12562825 | AE29: 13605825 | AF29: 11598625 | AG29: 12848625 | AH29: 14237620 | AI29: 14109120
A30: Non Withdrawable Deposits | B30: 112140909 | D30: 202175362 | E30: 212892161 | F30: 210439250 | G30: 214664550 | H30: 218244629 | I30: 223052827 | J30: 226286299 | K30: 226395385 | L30: 221262473 | M30: 224452536 | N30: 231484607 | O30: 236671325 | P30: 236671325 | Q30: 240688808 | R30: 242681313 | S30: 245274436 | T30: 249945160 | U30: 253770648 | V30: 256399465 | W30: 260667240 | X30: 263479539 | Y30: 266728664 | Z30: 268829096 | AA30: 271197041 | AB30: 274173279 | AC30: 274173279 | AD30: 279485749 | AE30: 283197560 | AF30: 286982955 | AG30: 289770963 | AH30: 289770963 | AI30: 295543488
A31: Total Deposit Liabilities | B31: =SUM(B28:B30) -> 128604214 | C31: =SUM(C28:C30) -> 417162829 | D31: =SUM(D28:D30) -> 441673465 | E31: =SUM(E28:E30) -> 449060862 | F31: =SUM(F28:F30) -> 397767081 | G31: =SUM(G28:G30) -> 344326629 | H31: =SUM(H28:H30) -> 315479643 | I31: =SUM(I28:I30) -> 312957758 | ... AO31: =SUM(AO28:AO30) -> 0
A32: Tax Payable | B32: 27231 | D32: 0 | E32: 0 | F32: 0 | G32: 348330 | H32: 0 | I32: 348500 | J32: 348500 | K32: 348500 | L32: 510314 | M32: 1074937 | N32: 1074937 | O32: 0 | Q32: 646992 | R32: 644861 | S32: 533603 | T32: 1051195 | U32: 701327 | V32: 697627 | W32: 697627 | X32: 1119955 | Y32: 565709 | Z32: 1177100 | AA32: 526761 | AB32: 0 | AC32: 0 | AD32: 612374 | AE32: 1847529 | AF32: 612374 | AG32: 1031023 | AH32: 974182 | AI32: 984631
A33: Dividends Payable | B33: 3618123 | C33: 3000000 | D33: 0 | E33: 0 | F33: 0 | G33: 0 | H33: 0 | I33: 0 | J33: 0 | K33: 0 | L33: 0 | M33: 0 | N33: 0 | O33: 0 | P33: 3000000 | Q33: 0 | R33: 0 | S33: 0 | T33: 0 | U33: 0 | V33: 0 | W33: 0 | X33: 0 | Y33: 0 | Z33: 0 | AA33: 0 | AB33: 0 | AC33: 6186195 | AD33: 0 | AE33: 0 | AF33: 0 | AG33: 0 | AH33: 0 | AI33: 0
A34: Deferred Tax Liability | D34: 0 | E34: 0 | F34: 0 | G34: 0 | H34: 0 | I34: 0 | J34: 0 | K34: 0 | L34: 0 | M34: 0 | N34: 0 | O34: 0 | Q34: 0 | R34: 0 | S34: 0 | T34: 0 | U34: 0 | V34: 0 | W34: 0 | X34: 0 | Y34: 0 | Z34: 0 | AA34: 0 | AB34: 0 | AC34: 0 | AD34: 0 | AE34: 0 | AF34: 0 | AG34: 0 | AH34: 0 | AI34: 0
A35: Retirement Benefits Liabilty | D35: 0 | E35: 0 | F35: 0 | G35: 0 | H35: 0 | I35: 0 | J35: 0 | K35: 0 | L35: 0 | M35: 0 | N35: 0 | O35: 0 | Q35: 0 | R35: 0 | S35: 0 | T35: 0 | U35: 0 | V35: 0 | W35: 0 | X35: 0 | Y35: 0 | Z35: 0 | AA35: 0 | AB35: 0 | AC35: 0 | AD35: 0 | AE35: 0 | AF35: 0 | AG35: 0 | AH35: 0 | AI35: 0
A36: Other Liabilities | B36: 1214920 | C36: =450674088-C33-C28 -> 30511259 | D36: 17698129 | E36: 27559387 | F36: 41391640 | G36: 58187204 | H36: 35421347 | I36: 36028307 | J36: 40037364 | K36: 35037364 | L36: 35049958 | M36: 52631188 | N36: 43521075 | O36: 54878851 | P36: =1699875+360000+53466886 -> 55526761 | Q36: 58482251 | R36: 57835259 | S36: 53693531 | T36: 59122317 | U36: 63367184 | V36: 54884015 | W36: 60691900 | X36: 73850884 | Y36: 63324985 | Z36: 63655123 | AA36: 64155106 | AB36: 66654574 | AC36: =78479206+1706242+360000 -> 80545448 | AD36: 63471781 | AE36: 61001446 | AF36: 62682823 | AG36: 61001447 | AH36: 70862955 | AI36: 77850756
A37: External Borrowings | B37: 2291669 | D37: 0 | E37: 0 | F37: 0 | G37: 0 | H37: 0 | I37: 0 | J37: 0 | K37: 0 | L37: 0 | M37: 0 | N37: 0 | O37: 0 | Q37: 0 | R37: 0 | S37: 0 | T37: 0 | U37: 0 | V37: 0 | W37: 0 | X37: 0 | Y37: 0 | Z37: 0 | AA37: 0 | AB37: 0 | AC37: 0 | AD37: 0 | AE37: 0 | AF37: 0 | AG37: 0 | AH37: 0 | AI37: 0
A38: Total Liabilities | B38: =SUM(B31:B37) -> 135756157 | C38: =SUM(C31:C37) -> 450674088 | D38: =SUM(D31:D37) -> 459371594 | E38: =SUM(E31:E37) -> 476620249 | F38: =SUM(F31:F37) -> 439158721 | G38: =SUM(G31:G37) -> 402862163 | H38: =SUM(H31:H37) -> 350900990 | I38: =SUM(I31:I37) -> 349334565 | ... AO38: =SUM(AO31:AO37) -> 0
A39: Share Capital | B39: 10494697 | C39: 86891078 | D39: 87010295 | E39: 87653870 | F39: 87985754 | G39: 88330956 | H39: 60324040 | I39: 89133528 | J39: 90252541 | K39: 90252541 | L39: 98819410 | M39: 99715365 | N39: 100696507 | O39: 103103252 | P39: 103103252 | Q39: 105860215 | R39: 105860214 | S39: 105995457 | T39: 109181781 | U39: 110955643 | V39: 112663220 | W39: 116817678 | X39: 118049351 | Y39: 119412990 | Z39: 120821691 | AA39: 122284744 | AB39: 123927301 | AC39: 124551811 | AD39: 125899763 | AE39: 128909507 | AF39: 131492284 | AG39: 132892782 | AH39: 134459781 | AI39: 136523862
A40: Capital Grants | B40: 340425 | D40: 0 | E40: 0 | F40: 0 | G40: 0 | H40: 0 | I40: 0 | J40: 0 | K40: 0 | L40: 0 | M40: 0 | N40: 0 | O40: 0 | Q40: 0 | R40: 0 | S40: 0 | T40: 0 | U40: 0 | V40: 0 | W40: 0 | X40: 0 | Y40: 0 | Z40: 0 | AA40: 0 | AB40: 0 | AC40: 0 | AD40: 0 | AE40: 0 | AF40: 0 | AG40: 0 | AH40: 0 | AI40: 0
A41: Prior Year Retained Earnigs | B41: 351220 | C41: 149736730 | D41: 168025282 | E41: 168025282 | F41: 167455625 | G41: 175717378 | H41: 149736730 | I41: 175717378 | J41: 175717378 | K41: 175717378 | L41: 175717378 | M41: 175717378 | N41: 175717378 | O41: 175717378 | P41: 175717378 | Q41: 186259393 | R41: 186301045 | S41: 186301045 | T41: 186301045 | U41: 186301045 | V41: 186301045 | W41: 186301045 | X41: 186301045 | Y41: 186301045 | Z41: 186301045 | AA41: 186301045 | AB41: 186301045 | AC41: 186301045 | AD41: 2.0899271e+08 | AE41: 208992712 | AF41: 209795207 | AG41: 208992712 | AH41: 208992712 | AI41: 209795207
A42: Current Year Surplus | B42: 3541956 | C42: =25980648 -> 25980648 | D42: 5865490 | E42: 4702128 | F42: 9216560 | G42: 11914437 | H42: 16818170 | I42: 23148044 | J42: 19899140 | K42: 20679137 | L42: 23154132 | M42: 27042898 | N42: 32059888 | O42: 14962540 | P42: =19554428-3000000-3910886-360000-720000-979875 -> 10583667 | Q42: 5344203 | R42: 9130268 | S42: 14833370 | T42: 20110797 | U42: 27941394 | V42: 34549709 | W42: 49864663 | X42: 44952373 | Y42: 47673109 | Z42: 48085068 | AA42: 41125752 | AB42: 44802725 | AC42: =39683249-6186195-986242-720000-360000-7936650 -> 23494162 | AD42: 11631964 | AE42: 15383558 | AF42: 11501541 | AG42: 1692221 | AH42: 9601533 | AI42: 20116411
...

Sheet Evolutitve SCI
B2: 2010 Audited | C2: 2020 Audited | D2: 44197 | E2: 44229 | F2: 44258 | G2: 44290 | H2: 44321 | I2: 44353 | J2: 44384 | K2: 44416 | L2: 44448 | M2: 44479 | N2: 44511 | O2: 44542 | P2: Audited 2021 | Q2: 44562 | R2: 44593 | S2: 44621 | T2: 44652 | U2: 44682 | V2: 44713 | W2: 44743 | X2: 44774 | Y2: 44805 | Z2: 44835 | AA2: 44866 | AB2: 44896 | AC2: Audited 2022 | AD2: 44927 | AE2: 44958 | AF2: 44986 | AG2: 45017 | AH2: 45047 | AI2: 45078 | AJ2: 45108 | AK2: 45139 | AL2: 45170 | AM2: 45200 | AN2: 45231 | AO2: 45261
A3: Financial Income | B3: =B4+B7 -> 14599.248 | C3: =C4+C7 -> 89988820 | D3: =D4+D7 -> 30585996 | E3: =E4+E7 -> 18854461 | F3: =F4+F7 -> 18857461 | G3: =G4+G7 -> 38776809 | H3: =H4+H7 -> 49832011 | I3: =I4+I7 -> 56848071 | ... AO3: =AO4+AO7 -> 0
A4: Financial Income From Loans Portfolio | B4: =SUM(B5:B6) -> 12855.806 | C4: =SUM(C5:C6) -> 57716167 | D4: =SUM(D5:D6) -> 22002313 | E4: =SUM(E5:E6) -> 15103211 | F4: =SUM(F5:F6) -> 15106211 | G4: =SUM(G5:G6) -> 29315810 | H4: =SUM(H5:H6) -> 38443297 | I4: =SUM(I5:I6) -> 43484342 | ... AO4: =SUM(AO5:AO6) -> 0
A5: Interest from Loans Portfolio | B5: 11945.435 | C5: 52206140 | D5: 20400486 | E5: 13911917 | F5: 13911917 | G5: 27136249 | H5: 35808173 | I5: 40435218 | J5: 47535267 | K5: 54482616 | L5: 60808672 | M5: 69824956 | N5: 77347789 | O5: 84111193 | P5: 110111193 | Q5: 7777104 | R5: 15618002 | S5: 24175866 | T5: 34233265 | U5: 45358395 | V5: 51108181 | W5: 67791255 | X5: 70038993 | Y5: 77520374 | Z5: 85311861 | AA5: 93839845 | AB5: 102493547 | AC5: 137493546 | AD5: 11746334 | AE5: 20907743 | AF5: 35885583 | AG5: 44515350 | AH5: 54529442 | AI5: 67196381
A6: Fees&Commision on Loan Portfolio | B6: 910.371 | C6: 5510027.4 | D6: 1601827 | E6: 1191294 | F6: 1194294 | G6: 2179561 | H6: 2635124 | I6: 3049124 | J6: 3495837 | K6: 3796764 | L6: 3994621 | M6: 4011544 | N6: 5194311 | O6: 7015044 | P6: 7015044 | Q6: 421912 | R6: 813895 | S6: 1239896 | T6: 1909763 | U6: 2533020 | V6: 2852117 | W6: 3900276 | X6: 4607180 | Y6: 5262317 | Z6: 5823897 | AA6: 6376912 | AB6: 6882732 | AC6: 8293781 | AD6: 819720 | AE6: 1491223.4 | AF6: 2094238 | AG6: 2565993.9 | AH6: 3228411.6 | AI6: 3641532
A7: Financial Income from Investments | B7: =SUM(B8:B11) -> 1743.4416 | C7: =SUM(C8:C11) -> 32272653 | D7: =SUM(D8:D11) -> 8583683 | E7: =SUM(E8:E11) -> 3751250 | F7: =SUM(F8:F11) -> 3751250 | G7: =SUM(G8:G11) -> 9460999 | H7: =SUM(H8:H11) -> 11388714 | I7: =SUM(I8:I11) -> 13363729 | ... AO7: =SUM(AO8:AO11) -> 0
A8: Government Securities | D8: 0 | E8: 0 | F8: 0 | G8: 0 | H8: 0 | I8: 0 | J8: 0 | K8: 0 | L8: 0 | M8: 0 | N8: 0 | O8: 0 | Q8: 0 | R8: 0 | S8: 0 | T8: 0 | U8: 0 | V8: 0 | W8: 0 | X8: 0 | Y8: 0 | Z8: 0 | AA8: 0 | AB8: 0 | AC8: 0 | AD8: 0 | AE8: 0 | AF8: 0 | AG8: 0 | AH8: 0 | AI8: 0
A9: Deposits with Banks & other Financial Institutions | C9: 1740558 | D9: 0 | E9: 0 | F9: 0 | G9: 0 | H9: 0 | I9: 0 | J9: 0 | K9: 0 | L9: 0 | M9: 0 | N9: 0 | O9: 0 | P9: =741527+71072 -> 812599 | Q9: 0 | R9: 0 | S9: 0 | T9: 0 | U9: 0 | V9: 0 | W9: 0 | X9: 0 | Y9: 0 | Z9: 0 | AA9: 0 | AB9: 0 | AC9: 726958 | AD9: 0 | AE9: 0 | AF9: 0 | AG9: 0 | AH9: 0 | AI9: 0
A10: Other Investments | D10: 795353 | E10: 0 | F10: 0 | G10: 812599 | H10: 812599 | I10: 812599 | J10: 812599 | K10: 812599 | L10: 812599 | M10: 812599 | N10: 812599 | O10: 812599 | Q10: 0 | R10: 0 | S10: 0 | T10: 0 | U10: 0 | V10: 0 | W10: 0 | X10: 0 | Y10: 0 | Z10: 0 | AA10: 0 | AB10: 7515068 | AC10: 0 | AD10: 0 | AE10: 0 | AF10: 0 | AG10: 0 | AH10: 0 | AI10: 0
A11: Other Operating Income | B11: 1743.4416 | C11: =36042122.4-C6 -> 30532095 | D11: 7788330 | E11: 3751250 | F11: 3751250 | G11: 8648400 | H11: 10576115 | I11: 12551130 | J11: 14569725 | K11: 16451165 | L11: 18257610 | M11: 22755265 | N11: 25314120 | O11: 27268071 | P11: =17518494-P9-P6 -> 9690851 | Q11: 2251350 | R11: 4317215 | S11: 6958690 | T11: 10663825 | U11: 13122485 | V11: 15604760 | W11: 21980985 | X11: 24271975 | Y11: 26695535 | Z11: 29264605 | AA11: 31803810 | AB11: 34475755 | AC11: =25803676-AC9-AC6 -> 16782937 | AD11: 4226215 | AE11: 7114394.5 | AF11: 9609612.5 | AG11: 12739323 | AH11: 15310300 | AI11: 18297556
A12: Financial Expenses | B12: =SUM(B13:B18) -> 549.0847 | C12: =SUM(C13:C18) -> 4015405 | D12: =SUM(D13:D18) -> 1344541 | E12: =SUM(E13:E18) -> 313601 | F12: =SUM(F13:F18) -> 945205 | G12: =SUM(G13:G18) -> 679804 | H12: =SUM(H13:H18) -> 797403 | I12: =SUM(I13:I18) -> 909537 | ... AO12: =SUM(AO13:AO18) -> 0
A13: Interest Expense on Deposits | B13: 185.36 | C13: 4015405 | D13: 0 | E13: 125632 | F13: 0 | G13: 0 | H13: 0 | I13: 0 | J13: 0 | K13: 0 | L13: 0 | M13: 0 | N13: 0 | O13: 7910004 | P13: 6368527 | Q13: 0 | R13: 0 | S13: 0 | T13: 0 | U13: 0 | V13: 0 | W13: 0 | X13: 0 | Y13: 0 | Z13: 0 | AA13: 0 | AB13: 0 | AC13: =7100139.75+729732 -> 7829871.8 | AD13: 0 | AE13: 0 | AF13: 0 | AG13: 0 | AH13: 0 | AI13: 0
A14: Cost of External Borrowings | B14: 363.7247 | D14: 0 | E14: 0 | F14: 0 | G14: 0 | H14: 0 | I14: 0 | J14: 0 | K14: 155435 | L14: 155435 | M14: 155436 | N14: 155436 | O14: 825237 | Q14: 0 | R14: 0 | S14: 0 | T14: 0 | U14: 0 | V14: 0 | W14: 0 | X14: 0 | Y14: 0 | Z14: 0 | AA14: 0 | AB14: 0 | AC14: 0 | AD14: 0 | AE14: 0 | AF14: 0 | AG14: 0 | AH14: 0 | AI14: 0
A15: Dividend Expenses | D15: 0 | E15: 0 | F15: 0 | G15: 0 | H15: 0 | I15: 0 | J15: 0 | K15: 0 | L15: 0 | M15: 0 | N15: 0 | O15: 0 | Q15: 0 | R15: 0 | S15: 0 | T15: 0 | U15: 0 | V15: 0 | W15: 0 | X15: 0 | Y15: 0 | Z15: 0 | AA15: 0 | AB15: 0 | AC15: 0 | AD15: 0 | AE15: 0 | AF15: 0 | AG15: 0 | AH15: 0 | AI15: 0
A16: Other Financial Expense | D16: 824611 | E16: 112134 | F16: 425275 | G16: 508091 | H16: 625690 | I16: 737824 | J16: 737824 | K16: 962092 | L16: 1110216 | M16: 1222350 | N16: 1427844 | O16: 1441153 | Q16: 151334 | R16: 250694 | S16: 411602 | T16: 523736 | U16: 635870 | V16: 751004 | W16: 866138 | X16: 981272 | Y16: 1096406 | Z16: 1220405 | AA16: 1335539 | AB16: 1565807 | AC16: 0 | AD16: 108225 | AE16: 132255 | AF16: 484566 | AG16: 477657 | AH16: 592791 | AI16: 707925
A17: Fees & Commision Expense | D17: 519930 | E17: 75835 | F17: 519930 | G17: 171713 | H17: 171713 | I17: 171713 | J17: 441983 | K17: 725177 | L17: 968865 | M17: 1143357 | N17: 1272877 | O17: 1424125 | Q17: 195970 | R17: 338302 | S17: 1754338 | T17: 1935600 | U17: 2139671 | V17: 1754338 | W17: 2112134 | X17: 2112134 | Y17: 1484121 | Z17: 1682739 | AA17: 3482547 | AB17: 3689063 | AC17: 0 | AD17: 126500 | AE17: 162315 | AF17: 175632 | AG17: 97374 | AH17: 209760 | AI17: 284707.15
A18: Other Expenses | D18: 0 | E18: 0 | F18: 0 | G18: 0 | H18: 0 | I18: 0 | J18: 0 | K18: 0 | L18: 0 | M18: 0 | N18: 0 | O18: 0 | P18: =52743744-P21 -> 2932133 | Q18: 0 | R18: 0 | S18: 0 | T18: 0 | U18: 0 | V18: 0 | W18: 0 | X18: 0 | Y18: 0 | Z18: 0 | AA18: 0 | AB18: 0 | AC18: =63062722-AC21+226883 -> 5560088 | AD18: 0 | AE18: 0 | AF18: 0 | AG18: 0 | AH18: 0 | AI18: 0
A19: Net Financial Income | B19: =B3-B12 -> 14050.163 | C19: =C3-C12 -> 85973415 | D19: =D3-D12 -> 29241455 | E19: =E3-E12 -> 18540860 | F19: =F3-F12 -> 17912256 | G19: =G3-G12 -> 38097005 | H19: =H3-H12 -> 49034608 | I19: =I3-I12 -> 55938534 | ... AO19: =AO3-AO12 -> 0
A20: Allowance for Loan Loss | B20: =B21-B22 -> 0 | C20: =C21-C22 -> 6731110 | D20: =D21-D22 -> 1340135 | E20: =E21-E22 -> 1046395 | F20: =F21-F22 -> 1443795 | G20: =G21-G22 -> 11443795 | H20: =H21-H22 -> 12996201 | I20: =I21-I22 -> 13759952 | ... AO20: =AO21-AO22 -> 0
A21: Provision for Loan Losses | C21: 6731110 | D21: 98365365 | E21: 104802735 | F21: 105200135 | G21: 115200135 | H21: 116752541 | I21: 1.1751629e+08 | J21: 128040891 | K21: 134067963 | L21: 138067963 | M21: 136930002 | N21: 141430333 | O21: 153567952 | P21: 49811611 | Q21: 155069054 | R21: 158421154 | S21: 159553734 | T21: 165053734 | U21: 167980236 | V21: 166866302 | W21: 171963037 | X21: 177495137 | Y21: 182689348 | Z21: 189814658 | AA21: 201065908 | AB21: 211297468 | AC21: 57729517 | AD21: 212145200 | AE21: 215936435 | AF21: 232145200 | AG21: 250715325 | AH21: 250715325 | AI21: 251515451
A22: Value of Loans Recovered | D22: 97025230 | E22: 103756340 | F22: 103756340 | G22: 103756340 | H22: 103756340 | I22: 103756340 | J22: 103756340 | K22: 103756340 | L22: 103756340 | M22: 103756340 | N22: 103756340 | O22: 103756340 | Q22: 153567951 | R22: 153567951 | S22: 153567951 | T22: 153567951 | U22: 153567951 | V22: 153567951 | W22: 153567951 | X22: 153567951 | Y22: 153567951 | Z22: 153567951 | AA22: 153567951 | AB22: 153567951 | AC22: 0 | AD22: 211297468 | AE22: 211297468 | AF22: 211297468 | AG22: 211297468 | AH22: 211297468 | AI22: 211297468
A23: Operating Expeses | B23: =SUM(B24:B28) -> 11019.38 | C23: =SUM(C24:C28) -> 41954424 | D23: =SUM(D24:D28) -> 11268205 | E23: =SUM(E24:E28) -> 12743928 | F23: =SUM(F24:F28) -> 7203492 | G23: =SUM(G24:G28) -> 14770903 | H23: =SUM(H24:H28) -> 16799638 | I23: =SUM(I24:I28) -> 18842693 | ... AO23: =SUM(AO24:AO28) -> 0
A24: Personel Expenses | B24: 3512.444 | C24: 13381925 | D24: 4015380 | E24: 7203057 | F24: 2807941 | G24: 6283605.3 | H24: 6337605 | I24: 6433605 | J24: 6624455 | K24: 6772255 | L24: 6812555 | M24: 16154594 | N24: 16949453 | O24: 19012053 | P24: 19797057 | Q24: 1511544 | R24: 3117450 | S24: 4699799 | T24: 6253907 | U24: 7867667 | V24: 9486634 | W24: 10969215 | X24: 12519274 | Y24: 14088672 | Z24: 15793602 | AA24: 17571459 | AB24: 19614180 | AC24: 19612580 | AD24: 1617391 | AE24: 3842988.8 | AF24: 5782451 | AG24: 7436948.2 | AH24: 10661308 | AI24: 12734843
A25: Governance Expenses | B25: 401.873 | C25: =10316051+799332+2165546+162400 -> 13443329 | D25: 2653410 | E25: 2807941 | F25: 1662185 | G25: 3486480 | H25: 4701680 | I25: 5364635 | J25: 5869130 | K25: 6594370 | L25: 7082465 | M25: 7672180 | N25: 8586440 | O25: 10989475 | P25: 11412615 | Q25: 542705 | R25: 1113115 | S25: 2027590 | T25: 3361525 | U25: 4225905 | V25: 4814815 | W25: 5716795 | X25: 7629415 | Y25: 8345135 | Z25: 8922030 | AA25: 10647080 | AB25: 13649955 | AC25: 14849285 | AD25: 1286136 | AE25: 2813798 | AF25: 5087435 | AG25: 6118396 | AH25: 6987978 | AI25: 8212437
A26: Marketing Expenses | B26: 919.3528 | D26: 118890 | E26: 60000 | F26: 60000 | G26: 60000 | H26: 60000 | I26: 60000 | J26: 72000 | K26: 72000 | L26: 72000 | M26: 72000 | N26: 72000 | O26: 72000 | P26: 42000 | Q26: 0 | R26: 0 | S26: 0 | T26: 0 | U26: 69000 | V26: 69000 | W26: 69000 | X26: 69000 | Y26: 70500 | Z26: 70500 | AA26: 120500 | AB26: 120500 | AC26: 120500 | AD26: 56500 | AE26: 79500 | AF26: 99500 | AG26: 99500 | AH26: 99500 | AI26: 99500
A27: Depreciation and Amortization | B27: 1276.981 | C27: 2250348.1 | D27: 815244 | E27: 427667 | F27: 427667 | G27: 874088 | H27: 1105358 | I27: 1336628 | J27: 1567898 | K27: 1799168 | L27: 2030438 | M27: 2261708 | N27: 2492978 | O27: 2662015 | P27: 2157687 | Q27: 219307 | R27: 438613 | S27: 657920 | T27: 877227 | U27: 1096535 | V27: 1315841 | W27: 1577790 | X27: 1992863 | Y27: 2460918 | Z27: 2910458 | AA27: 3359998 | AB27: 2542207 | AC27: 2539507 | AD27: 449539 | AE27: 899079.23 | AF27: 1348618 | AG27: 1798158.4 | AH27: 2247698.1 | AI27: 2697237.7
A28: Administrative Expenses | B28: 4908.7291 | C28: 12878822 | D28: 3665281 | E28: 2245263 | F28: 2245699 | G28: 4066730 | H28: 4594995 | I28: 5647825 | J28: 6816940 | K28: 7465449 | L28: 8221769 | M28: 8667969 | N28: 8835444 | O28: 10346099 | P28: =14020195-P26 -> 13978195 | Q28: 1076605 | R28: 1618840 | S28: 2338610 | T28: 2849765 | U28: 3411009 | V28: 4457954 | W28: 5410914 | X28: 6328354 | Y28: 6998104 | Z28: 7598689 | AA28: 9275812 | AB28: 10197862 | AC28: =13645594-AC26 -> 13525094 | AD28: 1033365 | AE28: 2116305 | AF28: 2796690 | AG28: 3677427.1 | AH28: 4480064.1 | AI28: 5599194.1
A29: Net Operating Income | B29: =B19-B20-B23 -> 3030.7829 | C29: =C19-C20-C23 -> 37287881 | D29: =D19-D20-D23 -> 16633115 | E29: =E19-E20-E23 -> 4750537 | F29: =F19-F20-F23 -> 9264969 | G29: =G19-G20-G23 -> 11882307 | H29: =H19-H20-H23 -> 19238769 | I29: =I19-I20-I23 -> 23335889 | ... AO29: =AO19-AO20-AO23 -> 0
A30: Net Non operating Income/Expense | B30: =B31-B32 -> 0 | C30: =C31-C32 -> 0 | D30: =D31-D32 -> 185055 | E30: =E31-E32 -> -48409 | F30: =F31-F32 -> -48409 | G30: =G31-G32 -> 32130 | H30: =H31-H32 -> -94865 | I30: =I31-I32 -> -187845 | ... AO30: =AO31-AO32 -> 0
A31: Non Operating Income | D31: 1274275 | E31: 612532 | F31: 612532 | G31: 1437847 | H31: 1749213 | I31: 2080259 | J31: 2441083 | K31: 2745634 | L31: 3029084 | M31: 3515034 | N31: 4134781 | O31: 4284853 | Q31: 357829 | R31: 643535 | S31: 1024250 | T31: 1532075 | U31: 1963145 | V31: 2290316 | W31: 2910209 | X31: 3427248 | Y31: 3911957 | Z31: 4415134 | AA31: 4903370 | AB31: 5396807 | AD31: 687764 | AE31: 1193429.8 | AF31: 1716901 | AG31: 2591358.7 | AH31: 3094465 | AI31: 3671981.5
A32: Non Operating Expense | D32: 1089220 | E32: 660941 | F32: 660941 | G32: 1405717 | H32: 1844078 | I32: 2268104 | J32: 2540589 | K32: 2752072 | L32: 2983088 | M32: 3353244 | N32: 3277247 | O32: 4035447 | Q32: 265424 | R32: 532162 | S32: 689689 | T32: 940588 | U32: 1177709 | V32: 1357727 | W32: 1600990 | X32: 1833525 | Y32: 2051820 | Z32: 2285299 | AA32: 2507293 | AB32: 2852093 | AD32: 322681 | AE32: 638024 | AF32: 1182169 | AG32: 1596486.5 | AH32: 1864128 | AI32: 2137212.5
A33: Net Income(Before Tax & Donations) | B33: =B29+B30 -> 3030.7829 | C33: =C29+C30 -> 37287881 | D33: =D29+D30 -> 16818170 | E33: =E29+E30 -> 4702128 | F33: =F29+F30 -> 9216560 | G33: =G29+G30 -> 11914437 | H33: =H29+H30 -> 19143904 | I33: =I29+I30 -> 23148044 | ... AO33: =AO29+AO30 -> 0
A34: Taxes | B34: 20 | D34: 0 | E34: 0 | F34: 0 | G34: 0 | H34: 0 | I34: 0 | J34: 0 | K34: 0 | L34: 0 | M34: 0 | N34: 0 | O34: 0 | P34: 1574433 | Q34: 0 | R34: 0 | S34: 0 | T34: 0 | U34: 0 | V34: 0 | W34: 0 | X34: 0 | Y34: 0 | AC34: 1847529.3 | AD34: 0 | AE34: 0 | AF34: 0 | AG34: 0 | AH34: 0 | AI34: 0
A35: Net Income(After Tax Before Donations) | B35: =B33-B34 -> 3010.7829 | C35: =C33-C34 -> 37287881 | D35: =D33-D34 -> 16818170 | E35: =E33-E34 -> 4702128 | F35: =F33-F34 -> 9216560 | G35: =G33-G34 -> 11914437 | H35: =H33-H34 -> 19143904 | I35: =I33-I34 -> 23148044 | ... AO35: =AO33-AO34 -> 0
A36: Donations | D36: 0 | E36: 0 | F36: 0 | G36: 0 | H36: 0 | I36: 0 | J36: 0 | K36: 0 | L36: 0 | M36: 0 | N36: 0 | O36: 0 | Q36: 0 | R36: 0 | S36: 0 | T36: 0 | U36: 0 | V36: 0 | W36: 0 | X36: 0 | Y36: 0 | AD36: 0 | AE36: 0 | AF36: 0 | AG36: 0 | AH36: 0 | AI36: 0
A37: Net Income/(After Tax & Donations) | B37: =B35-B36 -> 3010.7829 | C37: =C35-C36 -> 37287881 | D37: =D35-D36 -> 16818170 | E37: =E35-E36 -> 4702128 | F37: =F35-F36 -> 9216560 | G37: =G35-G36 -> 11914437 | H37: =H35-H36 -> 19143904 | I37: =I35-I36 -> 23148044 | ... AO37: =AO35-AO36 -> 0
A39: Total Expenses | B39: =B12+B23 -> 11568.465 | C39: =C12+C23 -> 45969829 | D39: =D12+D23 -> 12612746 | E39: =E12+E23 -> 13057529 | F39: =F12+F23 -> 8148697 | G39: =G12+G23 -> 15450707 | H39: =H12+H23 -> 17597041 | I39: =I12+I23 -> 19752230 | ... AF39: =AF12+AF23 -> 15774892
J41: =J39-I39 -> 2378000 | K41: =K39-J39 -> 2415716 | L41: =L39-K39 -> 1907797 | M41: =M39-L39 -> 10895851 | N41: =N39-M39 -> 2442878 | O41: =O39-N39 -> 14889689 | P41: =P39-O39 -> 2006053 | Q41: =Q39-P39 -> -52990749 | ... AE41: =AE39-AD39 -> 5368585

Sheet FORM 4 2021
D1: 44256
B2: CLASSIFICATION | C2: NO. OF A/Cs | D2: OUTSTANDING LOAN PORTFOLIO(Kshs) | E2: REQUIRED PROVISION | F2: REQUIRED PROVISION AMOUNT(Kshs)
B3: Performing | C3: 4163 | D3: 2.7040329e+08 | E3: 0.01 | F3: =D3*E3 -> 2704032.9
B4: Watch | C4: 924 | D4: 93093914 | E4: 0.05 | F4: =D4*E4 -> 4654695.7 | H4: NPL | I4: =D5+D6+D7 -> 1.8865752e+08
B5: Substandard | C5: 856 | D5: 85502588 | E5: 0.25 | F5: =D5*E5 -> 21375647 | H5: PAR | I5: =I4/D8 -> 0.3416751
B6: Doubtful | C6: 647 | D6: 67308390 | E6: 0.5 | F6: =D6*E6 -> 33654195
B7: Loss | C7: 757 | D7: 35846545 | E7: 1 | F7: =D7*E7 -> 35846545
B8: subtotal | C8: =SUM(C3:C7) -> 7347 | D8: =SUM(D3:D7) -> 5.5215472e+08 | E8: =SUM(E3:E7) -> 1.81 | F8: =SUM(F3:F7) -> 98235116
D10: 44348
B11: CLASSIFICATION | C11: NO. OF A/Cs | D11: OUTSTANDING LOAN PORTFOLIO(Kshs) | E11: REQUIRED PROVISION | F11: REQUIRED PROVISION AMOUNT(Kshs)
B12: Performing | C12: 5926 | D12: 479841003 | E12: 0.01 | F12: =D12*E12 -> 4798410
B13: Watch | C13: 473 | D13: 40683976 | E13: 0.05 | F13: =D13*E13 -> 2034198.8 | H13: NPL | I13: =D14+D15+D16 -> 202810833
B14: Substandard | C14: 481 | D14: 76036591 | E14: 0.25 | F14: =D14*E14 -> 19009148 | H14: PAR | I14: =I13/D17 -> 0.28038268
B15: Doubtful | C15: 313 | D15: 70199414 | E15: 0.5 | F15: =D15*E15 -> 35099707
B16: Loss | C16: 2445 | D16: 56574828 | E16: 1 | F16: =D16*E16 -> 56574828
B17: subtotal | C17: =SUM(C12:C16) -> 9638 | D17: =SUM(D12:D16) -> 723335812 | E17: 1.81 | F17: =SUM(F12:F16) -> 1.1751629e+08
D19: 44440
B20: CLASSIFICATION | C20: NO. OF A/Cs | D20: OUTSTANDING LOAN PORTFOLIO(Kshs) | E20: REQUIRED PROVISION | F20: REQUIRED PROVISION AMOUNT(Kshs)
B21: Performing | C21: 15854 | D21: 415920910 | E21: 0.01 | F21: =D21*E21 -> 4159209.1
B22: Watch | C22: 7037 | D22: 165142422 | E22: 0.05 | F22: =D22*E22 -> 8257121.1 | H22: NPL | I22: =D23+D24+D25 -> 229737313
B23: Substandard | C23: 4575 | D23: 90431503 | E23: 0.25 | F23: =D23*E23 -> 22607876 | H23: PAR | I23: =I22/D26 -> 0.28334624
B24: Doubtful | C24: 2972 | D24: 71744152 | E24: 0.5 | F24: =D24*E24 -> 35872076
B25: Loss | C25: 3724 | D25: 67561658 | E25: 1 | F25: =D25*E25 -> 67561658
B26: subtotal | C26: =SUM(C21:C25) -> 34162 | D26: =SUM(D21:D25) -> 810800645 | E26: 1.81 | F26: =SUM(F21:F25) -> 1.3845794e+08
D28: 44531
B29: CLASSIFICATION | C29: NO. OF A/Cs | D29: OUTSTANDING LOAN PORTFOLIO(Kshs) | E29: REQUIRED PROVISION | F29: REQUIRED PROVISION AMOUNT(Kshs)
B30: Performing | C30: 12109 | D30: 485769781 | E30: 0.01 | F30: =D30*E30 -> 4857697.8
B31: Watch | C31: 1718 | D31: 62577728 | E31: 0.05 | F31: =D31*E31 -> 3128886.4 | H31: NPL | I31: =D32+D33+D34 -> 244239681
B32: Substandard | C32: 2596 | D32: 89577728 | E32: 0.25 | F32: =D32*E32 -> 22394432 | H32: PAR | I32: =I31/D35 -> 0.30815497
B33: Doubtful | C33: 1269 | D33: 62950035 | E33: 0.5 | F33: =D33*E33 -> 31475018
B34: Loss | C34: 3601 | D34: 91711918 | E34: 1 | F34: =D34*E34 -> 91711918
B35: subtotal | C35: =SUM(C30:C34) -> 21293 | D35: =SUM(D30:D34) -> 792587190 | E35: 1.81 | F35: =SUM(F30:F34) -> 1.5356795e+08
D38: Audited 2021
B39: CLASSIFICATION | C39: NO. OF A/Cs | D39: OUTSTANDING LOAN PORTFOLIO(Kshs) | E39: REQUIRED PROVISION | F39: REQUIRED PROVISION AMOUNT(Kshs)
B40: Performing | C40: 12109 | D40: 485771802 | E40: 0.01 | F40: =D40*E40 -> 4857718
B41: Watch | C41: 1718 | D41: 62577728 | E41: 0.05 | F41: =D41*E41 -> 3128886.4
B42: Substandard | C42: 2596 | D42: 89577728 | E42: 0.25 | F42: =D42*E42 -> 22394432 | H42: npl | I42: =(D42+D43+D44)/D45 -> 0.30815418
B43: Doubtful | C43: 1269 | D43: 62950035 | E43: 0.5 | F43: =D43*E43 -> 31475018
B44: Loss | C44: 3601 | D44: 91711918 | E44: 1 | F44: =D44*E44 -> 91711918
B45: subtotal | C45: =SUM(C40:C44) -> 21293 | D45: =SUM(D40:D44) -> 792589211 | E45: 1.81 | F45: =SUM(F40:F44) -> 1.5356797e+08

Sheet FORM 4 2022
D1: 44621
B2: CLASSIFICATION | C2: NO. OF A/Cs | D2: OUTSTANDING LOAN PORTFOLIO(Kshs) | E2: REQUIRED PROVISION | F2: REQUIRED PROVISION AMOUNT(Kshs)
B3: Performing | C3: 12109 | D3: 514493872 | E3: 0.01 | F3: =D3*E3 -> 5144938.7
B4: Watch | C4: 1718 | D4: 69304416 | E4: 0.05 | F4: =D4*E4 -> 3465220.8 | H4: NPL | I4: =D5+D6+D7 -> 255404414
B5: Substandard | C5: 2596 | D5: 94846185 | E5: 0.25 | F5: =D5*E5 -> 23711546 | H5: PAR | I5: =I4/D8 -> 0.30434174
B6: Doubtful | C6: 1269 | D6: 66652402 | E6: 0.5 | F6: =D6*E6 -> 33326201
B7: Loss | C7: 3601 | D7: 93905827 | E7: 1 | F7: =D7*E7 -> 93905827
B8: subtotal | C8: =SUM(C3:C7) -> 21293 | D8: =SUM(D3:D7) -> 839202702 | E8: =SUM(E3:E7) -> 1.81 | F8: =SUM(F3:F7) -> 1.5955373e+08
D10: 44713
B11: CLASSIFICATION | C11: NO. OF A/Cs | D11: OUTSTANDING LOAN PORTFOLIO(Kshs) | E11: REQUIRED PROVISION | F11: REQUIRED PROVISION AMOUNT(Kshs)
B12: Performing | C12: 4166 | D12: 337244315 | E12: 0.01 | F12: =D12*E12 -> 3372443.1
B13: Watch | C13: 2646 | D13: 277722659 | E13: 0.05 | F13: =D13*E13 -> 13886133 | H13: NPL | I13: =D14+D15+D16 -> 281620808
B14: Substandard | C14: 1931 | D14: 134456314 | E14: 0.25 | F14: =D14*E14 -> 33614078 | H14: PAR | I14: =I13/D17 -> 0.31410288
B15: Doubtful | C15: 1003 | D15: 62341693 | E15: 0.5 | F15: =D15*E15 -> 31170846
B16: Loss | C16: 1420 | D16: 84822801 | E16: 1 | F16: =D16*E16 -> 84822801
B17: subtotal | C17: =SUM(C12:C16) -> 11166 | D17: =SUM(D12:D16) -> 896587782 | E17: 1.81 | F17: =SUM(F12:F16) -> 1.668663e+08
D19: 44805
B20: CLASSIFICATION | C20: NO. OF A/Cs | D20: OUTSTANDING LOAN PORTFOLIO(Kshs) | E20: REQUIRED PROVISION | F20: REQUIRED PROVISION AMOUNT(Kshs)
B21: Performing | C21: 10973 | D21: 353678866 | E21: 0.01 | F21: =D21*E21 -> 3536788.7
B22: Watch | C22: 4578 | D22: 158818427 | E22: 0.05 | F22: =D22*E22 -> 7940921.4 | H22: NPL | I22: =D23+D24+D25 -> 318353618
B23: Substandard | C23: 3452 | D23: 122412276 | E23: 0.25 | F23: =D23*E23 -> 30603069 | H23: PAR | I23: =I22/D26 -> 0.38316576
B24: Doubtful | C24: 3020 | D24: 110665547 | E24: 0.5 | F24: =D24*E24 -> 55332774
B25: Loss | C25: 1404 | D25: 85275795 | E25: 1 | F25: =D25*E25 -> 85275795
B26: subtotal | C26: =SUM(C21:C25) -> 23427 | D26: =SUM(D21:D25) -> 830850911 | E26: 1.81 | F26: =SUM(F21:F25) -> 1.8268935e+08
D28: 44896
B29: CLASSIFICATION | C29: NO. OF A/Cs | D29: OUTSTANDING LOAN PORTFOLIO(Kshs) | E29: REQUIRED PROVISION | F29: REQUIRED PROVISION AMOUNT(Kshs)
B30: Performing | C30: 15019 | D30: 363059866 | E30: 0.01 | F30: =D30*E30 -> 3630598.7
B31: Watch | C31: 3039 | D31: 156328657 | E31: 0.05 | F31: =D31*E31 -> 7816432.9 | H31: NPL | I31: =D32+D33+D34 -> 391413462
B32: Substandard | C32: 2830 | D32: 139254109 | E32: 0.25 | F32: =D32*E32 -> 34813527 | H32: PAR | I32: =I31/D35 -> 0.42974595
B33: Doubtful | C33: 3214 | D33: 174244887 | E33: 0.5 | F33: =D33*E33 -> 87122444
B34: Loss | C34: 1572 | D34: 77914466 | E34: 1 | F34: =D34*E34 -> 77914466
B35: subtotal | C35: =SUM(C30:C34) -> 25674 | D35: =SUM(D30:D34) -> 910801985 | E35: 1.81 | F35: =SUM(F30:F34) -> 2.1129747e+08
D38: Audited 2022
B39: CLASSIFICATION | C39: NO. OF A/Cs | D39: OUTSTANDING LOAN PORTFOLIO(Kshs) | E39: REQUIRED PROVISION | F39: REQUIRED PROVISION AMOUNT(Kshs)
B40: Performing | C40: 15019 | D40: 363059866 | E40: 0.01 | F40: =D40*E40 -> 3630598.7
B41: Watch | C41: 3039 | D41: 156328657 | E41: 0.05 | F41: =D41*E41 -> 7816432.9 | H41: NPL | I41: =D42+D43+D44 -> 391413462
B42: Substandard | C42: 2830 | D42: 139254109 | E42: 0.25 | F42: =D42*E42 -> 34813527 | H42: PAR | I42: =I41/D45 -> 0.42974595
B43: Doubtful | C43: 3214 | D43: 174244887 | E43: 0.5 | F43: =D43*E43 -> 87122444
B44: Loss | C44: 1572 | D44: 77914466 | E44: 1 | F44: =D44*E44 -> 77914466
B45: subtotal | C45: =SUM(C40:C44) -> 25674 | D45: =SUM(D40:D44) -> 910801985 | E45: 1.81 | F45: =SUM(F40:F44) -> 2.1129747e+08

Sheet CAELS
A1: K-PILAR SACCO 2022 CAELS
D2: 2010 Audited | E2: 2020Audited | F2: 44198 | G2: 44230 | H2: 44259 | I2: 44291 | J2: 44322 | K2: 44354 | L2: 44385 | M2: 44417 | N2: 44449 | O2: 44480 | P2: 44512 | Q2: 44543 | R2: Audited 2021 | S2: 44562 | T2: 44593 | U2: 44621 | V2: 44652 | W2: 44682 | X2: 44713 | Y2: 44743 | Z2: 44774 | AA2: 44805 | AB2: 44835 | AC2: 44866 | AD2: 44896 | AE2: Audied 2022 | AF2: 44927 | AG2: 44958 | AH2: 44986 | AI2: 45017 | AJ2: 45047 | AK2: 45078 | AL2: 45108 | AM2: 45139 | AN2: 45170 | AO2: 45200 | AP2: 45231 | AQ2: 45261 | AR2: 45292 | AS2: 45323 | AT2: 45352 | AU2: 45383 | AV2: 45413 | AW2: 45444 | AX2: 45474
A3: CAPITAL ADEQUACY | B3: Core Capital | C3: 10 M | D3: =(('Evolutive SFP'!B39+'Evolutive SFP'!B40+'Evolutive SFP'!B41+'Evolutive SFP'!B42+'Evolutive SFP'!B43+'Evolutive SFP'!B44)-'Evolutive SFP'!B10)/1000000 -> 15.259572 | E3: =(('Evolutive SFP'!C39+'Evolutive SFP'!C40+'Evolutive SFP'!C41+'Evolutive SFP'!C42+'Evolutive SFP'!C43+'Evolutive SFP'!C44)-'Evolutive SFP'!C10)/1000000 -> 322.38481 | F3: =(('Evolutive SFP'!D39+'Evolutive SFP'!D40+'Evolutive SFP'!D41+'Evolutive SFP'!D42+'Evolutive SFP'!D43+'Evolutive SFP'!D44)-'Evolutive SFP'!D10)/1000000 -> 320.1859 | G3: =(('Evolutive SFP'!E39+'Evolutive SFP'!E40+'Evolutive SFP'!E41+'Evolutive SFP'!E42+'Evolutive SFP'!E43+'Evolutive SFP'!E44)-'Evolutive SFP'!E10)/1000000 -> 319.66611 | H3: =(('Evolutive SFP'!F39+'Evolutive SFP'!F40+'Evolutive SFP'!F41+'Evolutive SFP'!F42+'Evolutive SFP'!F43+'Evolutive SFP'!F44)-'Evolutive SFP'!F10)/1000000 -> 323.80036 | I3: =(('Evolutive SFP'!G39+'Evolutive SFP'!G40+'Evolutive SFP'!G41+'Evolutive SFP'!G42+'Evolutive SFP'!G43+'Evolutive SFP'!G44)-'Evolutive SFP'!G10)/1000000 -> 335.73912 | J3: =(('Evolutive SFP'!H39+'Evolutive SFP'!H40+'Evolutive SFP'!H41+'Evolutive SFP'!H42+'Evolutive SFP'!H43+'Evolutive SFP'!H44)-'Evolutive SFP'!H10)/1000000 -> 279.32013 | K3: =(('Evolutive SFP'!I39+'Evolutive SFP'!I40+'Evolutive SFP'!I41+'Evolutive SFP'!I42+'Evolutive SFP'!I43+'Evolutive SFP'!I44)-'Evolutive SFP'!I10)/1000000 -> 347.7753 | ... AT3: =(('Evolutive SFP'!AR39+'Evolutive SFP'!AR40+'Evolutive SFP'!AR41+'Evolutive SFP'!AR42+'Evolutive SFP'!AR43+'Evolutive SFP'!AR44)-'Evolutive SFP'!AR10)/1000000 -> 0
B4: CCA | C4: Min 10% | D4: =D3/(('Evolutive SFP'!B27)/1000000) -> 0.10104624 | E4: =E3/(('Evolutive SFP'!C27)/1000000) -> 0.4170249 | F4: =F3/(('Evolutive SFP'!D27)/1000000) -> 0.41072776 | G4: =G3/(('Evolutive SFP'!E27)/1000000) -> 0.40144617 | H4: =H3/(('Evolutive SFP'!F27)/1000000) -> 0.42440069 | I4: =I3/(('Evolutive SFP'!G27)/1000000) -> 0.45456071 | J4: =J3/(('Evolutive SFP'!H27)/1000000) -> 0.40013825 | K4: =K3/(('Evolutive SFP'!I27)/1000000) -> 0.49888162 | ... AT4: =AT3/(('Evolutive SFP'!AR27)/1000000) -> #DIV/0!
B5: CCD | C5: Min 8% | D5: =D3/('Evolutive SFP'!B31/1000000) -> 0.1186553 | E5: =E3/('Evolutive SFP'!C31/1000000) -> 0.77280329 | F5: =F3/('Evolutive SFP'!D31/1000000) -> 0.72493805 | G5: =G3/('Evolutive SFP'!E31/1000000) -> 0.71185476 | H5: =H3/('Evolutive SFP'!F31/1000000) -> 0.81404514 | I5: =I3/('Evolutive SFP'!G31/1000000) -> 0.97505999 | J5: =J3/('Evolutive SFP'!H31/1000000) -> 0.88538241 | K5: =K3/('Evolutive SFP'!I31/1000000) -> 1.1112532 | ... AT5: =AT3/('Evolutive SFP'!AR31/1000000) -> #DIV/0!
B6: ICA | C6: Min 8% | D6: =((D3*1000000)-'Evolutive SFP'!B39)/'Evolutive SFP'!B27 -> 0.031552177 | E6: =((E3*1000000)-'Evolutive SFP'!C39)/'Evolutive SFP'!C27 -> 0.30462586 | F6: =((F3*1000000)-'Evolutive SFP'!D39)/'Evolutive SFP'!D27 -> 0.29911278 | G6: =((G3*1000000)-'Evolutive SFP'!E39)/'Evolutive SFP'!E27 -> 0.29136785 | H6: =((H3*1000000)-'Evolutive SFP'!F39)/'Evolutive SFP'!F27 -> 0.30907897 | I6: =((I3*1000000)-'Evolutive SFP'!G39)/'Evolutive SFP'!G27 -> 0.3349685 | J6: =((J3*1000000)-'Evolutive SFP'!H39)/'Evolutive SFP'!H27 -> 0.31372144 | K6: =((K3*1000000)-'Evolutive SFP'!I39)/'Evolutive SFP'!I27 -> 0.3710201 | ... AT6: =((AT3*1000000)-'Evolutive SFP'!AR39)/'Evolutive SFP'!AR27 -> #DIV/0!
A7: ASSET QUALITY | B7: A/LNPL30 | H7: ='Evolutive SFP'!P312 -> 0 | N7: ='Evolutive SFP'!G16/('FORM 4 2021'!E5+'FORM 4 2021'!E6+'FORM 4 2021'!E7) -> 65828649 | P7: ='Evolutive SFP'!N16/('FORM 4 2021'!D14+'FORM 4 2021'!D15+'FORM 4 2021'!D16) -> 0.69735098
B8: NPL30 | H8: =('FORM 4 2021'!D5+'FORM 4 2021'!D6+'FORM 4 2021'!D7) -> 1.8865752e+08 | K8: =('FORM 4 2021'!D14+'FORM 4 2021'!D15+'FORM 4 2021'!D16)/'Evolutive SFP'!I15 -> 0.28038268 | M8: =('FORM 4 2021'!D5+'FORM 4 2021'!D6+'FORM 4 2021'!D7)/'Evolutive SFP'!K15 -> 0.24727891 | N8: =('FORM 4 2021'!D23+'FORM 4 2021'!D24+'FORM 4 2021'!D25)/'Evolutive SFP'!L15 -> 0.28334624 | O8: =('FORM 4 2021'!F5+'FORM 4 2021'!F6+'FORM 4 2021'!F7)/'Evolutive SFP'!M15 -> 0.1285282 | P8: =('FORM 4 2021'!G5+'FORM 4 2021'!G6+'FORM 4 2021'!G7)/'Evolutive SFP'!N15 -> 0 | Q8: =('FORM 4 2021'!D32+'FORM 4 2021'!D33+'FORM 4 2021'!D34)/'Evolutive SFP'!O15 -> 0.30815497 | R8: =('FORM 4 2021'!D42+'FORM 4 2021'!D43+'FORM 4 2021'!D44)/'Evolutive SFP'!P15 -> 0.30815418 | U8: =('FORM 4 2022'!D5+'FORM 4 2022'!D6+'FORM 4 2022'!D7)/'Evolutive SFP'!S15 -> 0.30434174 | X8: =('FORM 4 2022'!D14+'FORM 4 2022'!D15+'FORM 4 2022'!D16)/'Evolutive SFP'!V15 -> 0.31410288 | AA8: =('FORM 4 2022'!D23+'FORM 4 2022'!D24+'FORM 4 2022'!D25)/'Evolutive SFP'!Y15 -> 0.38316576 | AD8: =('FORM 4 2022'!D32+'FORM 4 2022'!D33+'FORM 4 2022'!D34)/'Evolutive SFP'!AB15 -> 0.42974595 | AE8: =('FORM 4 2022'!D42+'FORM 4 2022'!D43+'FORM 4 2022'!D44)/'Evolutive SFP'!AC15 -> 0.42974595 | AF8: =('FORM 4 2022'!E42+'FORM 4 2022'!E43+'FORM 4 2022'!E44)/'Evolutive SFP'!AD15 -> 1.9287249e-09 | AG8: =('FORM 4 2022'!F42+'FORM 4 2022'!F43+'FORM 4 2022'!F44)/'Evolutive SFP'!AE15 -> 0.20613307 | AH8: =('FORM 4 2022'!G42+'FORM 4 2022'!G43+'FORM 4 2022'!G44)/'Evolutive SFP'!AF15 -> 0 | AI8: =('FORM 4 2022'!H42+'FORM 4 2022'!H43+'FORM 4 2022'!H44)/'Evolutive SFP'!AG15 -> #VALUE! | AJ8: =('FORM 4 2022'!I42+'FORM 4 2022'!I43+'FORM 4 2022'!I44)/'Evolutive SFP'!AH15 -> 4.0752691e-10 | AK8: =('FORM 4 2022'!J42+'FORM 4 2022'!J43+'FORM 4 2022'!J44)/'Evolutive SFP'!AI15 -> 0 | AL8: =('FORM 4 2022'!K42+'FORM 4 2022'!K43+'FORM 4 2022'!K44)/'Evolutive SFP'!AJ15 -> #DIV/0! | ... AT8: =('FORM 4 2022'!S42+'FORM 4 2022'!S43+'FORM 4 2022'!S44)/'Evolutive SFP'!AR15 -> #DIV/0!
A9: EARNINGS | B9: ROA | E9: ='Evolutitve SCI'!C33/(('Evolutive SFP'!B27+'Evolutive SFP'!C27)/2) -> 0.080703182 | F9: ='Evolutitve SCI'!D33/(('Evolutive SFP'!C27+'Evolutive SFP'!D27)/2) -> 0.021664295 | G9: ='Evolutitve SCI'!E33/(('Evolutive SFP'!D27+'Evolutive SFP'!E27)/2) -> 0.0059677588 | H9: ='Evolutitve SCI'!F33/(('Evolutive SFP'!E27+'Evolutive SFP'!F27)/2) -> 0.011821821 | I9: ='Evolutitve SCI'!G33/(('Evolutive SFP'!F27+'Evolutive SFP'!G27)/2) -> 0.015869408 | J9: ='Evolutitve SCI'!H33/(('Evolutive SFP'!G27+'Evolutive SFP'!H27)/2) -> 0.026650564 | K9: ='Evolutitve SCI'!I33/(('Evolutive SFP'!H27+'Evolutive SFP'!I27)/2) -> 0.033183143 | L9: ='Evolutitve SCI'!J33/(('Evolutive SFP'!I27+'Evolutive SFP'!J27)/2) -> 0.028647736 | ... AT9: ='Evolutitve SCI'!AR33/(('Evolutive SFP'!AQ27+'Evolutive SFP'!AR27)/2) -> #DIV/0!
B10: Cost Income ratio | D10: ='Evolutitve SCI'!B23/'Evolutitve SCI'!B19 -> 0.78428841 | E10: ='Evolutitve SCI'!C23/'Evolutitve SCI'!C19 -> 0.48799299 | F10: ='Evolutitve SCI'!D23/'Evolutitve SCI'!D19 -> 0.38535035 | G10: ='Evolutitve SCI'!E23/'Evolutitve SCI'!E19 -> 0.68734287 | H10: ='Evolutitve SCI'!F23/'Evolutitve SCI'!F19 -> 0.40215437 | I10: ='Evolutitve SCI'!G23/'Evolutitve SCI'!G19 -> 0.38771823 | J10: ='Evolutitve SCI'!H23/'Evolutitve SCI'!H19 -> 0.34260778 | K10: ='Evolutitve SCI'!I23/'Evolutitve SCI'!I19 -> 0.33684639 | ... AT10: ='Evolutitve SCI'!AR23/'Evolutitve SCI'!AR19 -> #DIV/0!
B11: Operating Expense ratio | D11: =('Evolutitve SCI'!B23+'Evolutitve SCI'!B12)/(('Evolutive SFP'!B27+'Evolutive SFP'!C27)/2) -> 2.5037945e-05 | E11: =('Evolutitve SCI'!C23+'Evolutitve SCI'!C12)/(('Evolutive SFP'!C27+'Evolutive SFP'!D27)/2) -> 0.059215952 | F11: =('Evolutitve SCI'!D23+'Evolutitve SCI'!D12)/(('Evolutive SFP'!D27+'Evolutive SFP'!E27)/2) -> 0.016007609 | G11: =('Evolutitve SCI'!E23+'Evolutitve SCI'!E12)/(('Evolutive SFP'!E27+'Evolutive SFP'!F27)/2) -> 0.016748523 | H11: =('Evolutitve SCI'!F23+'Evolutitve SCI'!F12)/(('Evolutive SFP'!F27+'Evolutive SFP'!G27)/2) -> 0.010853639 | I11: =('Evolutitve SCI'!G23+'Evolutitve SCI'!G12)/(('Evolutive SFP'!G27+'Evolutive SFP'!H27)/2) -> 0.0215092 | J11: =('Evolutitve SCI'!H23+'Evolutitve SCI'!H12)/(('Evolutive SFP'!H27+'Evolutive SFP'!I27)/2) -> 0.025225678 | K11: =('Evolutitve SCI'!I23+'Evolutitve SCI'!I12)/(('Evolutive SFP'!I27+'Evolutive SFP'!J27)/2) -> 0.028436236 | ... AT11: =('Evolutitve SCI'!AR23+'Evolutitve SCI'!AR12)/(('Evolutive SFP'!AR27+'Evolutive SFP'!AS27)/2) -> #DIV/0!
A12: LIQUIDITY | B12: MIN LIQ ratio | C12: Min 15% | D12: =('Evolutive SFP'!B4)/('Evolutive SFP'!B28+'Evolutive SFP'!B29+'Evolutive SFP'!B32+'Evolutive SFP'!B33+'Evolutive SFP'!B34+'Evolutive SFP'!B35+'Evolutive SFP'!B36) -> 0.90806632 | E12: =('Evolutive SFP'!C4)/('Evolutive SFP'!C28+'Evolutive SFP'!C29+'Evolutive SFP'!C32+'Evolutive SFP'!C33+'Evolutive SFP'!C34+'Evolutive SFP'!C35+'Evolutive SFP'!C36) -> 0.42952316 | F12: =('Evolutive SFP'!D4)/('Evolutive SFP'!D28+'Evolutive SFP'!D29+'Evolutive SFP'!D32+'Evolutive SFP'!D33+'Evolutive SFP'!D34+'Evolutive SFP'!D35+'Evolutive SFP'!D36) -> 0.56088249 | G12: =('Evolutive SFP'!E4)/('Evolutive SFP'!E28+'Evolutive SFP'!E29+'Evolutive SFP'!E32+'Evolutive SFP'!E33+'Evolutive SFP'!E34+'Evolutive SFP'!E35+'Evolutive SFP'!E36) -> 0.62681238 | H12: =('Evolutive SFP'!F4)/('Evolutive SFP'!F28+'Evolutive SFP'!F29+'Evolutive SFP'!F32+'Evolutive SFP'!F33+'Evolutive SFP'!F34+'Evolutive SFP'!F35+'Evolutive SFP'!F36) -> 0.65790353 | I12: =('Evolutive SFP'!G4)/('Evolutive SFP'!G28+'Evolutive SFP'!G29+'Evolutive SFP'!G32+'Evolutive SFP'!G33+'Evolutive SFP'!G34+'Evolutive SFP'!G35+'Evolutive SFP'!G36) -> 0.65969759 | J12: =('Evolutive SFP'!H4)/('Evolutive SFP'!H28+'Evolutive SFP'!H29+'Evolutive SFP'!H32+'Evolutive SFP'!H33+'Evolutive SFP'!H34+'Evolutive SFP'!H35+'Evolutive SFP'!H36) -> 0.78477335 | K12: =('Evolutive SFP'!I4)/('Evolutive SFP'!I28+'Evolutive SFP'!I29+'Evolutive SFP'!I32+'Evolutive SFP'!I33+'Evolutive SFP'!I34+'Evolutive SFP'!I35+'Evolutive SFP'!I36) -> 0.43499606 | ... AT12: =('Evolutive SFP'!AR4)/('Evolutive SFP'!AR28+'Evolutive SFP'!AR29+'Evolutive SFP'!AR32+'Evolutive SFP'!AR33+'Evolutive SFP'!AR34+'Evolutive SFP'!AR35+'Evolutive SFP'!AR36) -> #DIV/0!
B13: T/LIQ ratio | D13: ='Evolutive SFP'!B4/('Evolutive SFP'!B31+'Evolutive SFP'!B36) -> 0.14915539 | E13: ='Evolutive SFP'!C4/('Evolutive SFP'!C31+'Evolutive SFP'!C36) -> 0.43240153 | F13: ='Evolutive SFP'!D4/('Evolutive SFP'!D31+'Evolutive SFP'!D36) -> 0.31403087 | G13: ='Evolutive SFP'!E4/('Evolutive SFP'!E31+'Evolutive SFP'!E36) -> 0.34683384 | H13: ='Evolutive SFP'!F4/('Evolutive SFP'!F31+'Evolutive SFP'!F36) -> 0.34264456 | I13: ='Evolutive SFP'!G4/('Evolutive SFP'!G31+'Evolutive SFP'!G36) -> 0.30844533 | J13: ='Evolutive SFP'!H4/('Evolutive SFP'!H31+'Evolutive SFP'!H36) -> 0.29667963 | K13: ='Evolutive SFP'!I4/('Evolutive SFP'!I31+'Evolutive SFP'!I36) -> 0.15740473 | ... AT13: ='Evolutive SFP'!AR4/('Evolutive SFP'!AR31+'Evolutive SFP'!AR36) -> #DIV/0!
B14: EB ratio | C14: Max 25% | D14: ='Evolutive SFP'!B37/'Evolutive SFP'!B27 -> 0.015175035 | E14: ='Evolutive SFP'!C37/'Evolutive SFP'!C27 -> 0 | F14: ='Evolutive SFP'!D37/'Evolutive SFP'!D27 -> 0 | G14: ='Evolutive SFP'!E37/'Evolutive SFP'!E27 -> 0 | H14: ='Evolutive SFP'!F37/'Evolutive SFP'!F27 -> 0 | I14: ='Evolutive SFP'!G37/'Evolutive SFP'!G27 -> 0 | J14: ='Evolutive SFP'!H37/'Evolutive SFP'!H27 -> 0 | K14: ='Evolutive SFP'!I37/'Evolutive SFP'!I27 -> 0 | ... AT14: ='Evolutive SFP'!AR37/'Evolutive SFP'!AR27 -> #DIV/0!
B15: LA to TA ratio | D15: ='Evolutive SFP'!B4/'Evolutive SFP'!B27 -> 0.12821992 | E15: ='Evolutive SFP'!C4/'Evolutive SFP'!C27 -> 0.25040131 | F15: ='Evolutive SFP'!D4/'Evolutive SFP'!D27 -> 0.18504968 | G15: ='Evolutive SFP'!E4/'Evolutive SFP'!E27 -> 0.20759872 | H15: ='Evolutive SFP'!F4/'Evolutive SFP'!F27 -> 0.19722597 | I15: ='Evolutive SFP'!G4/'Evolutive SFP'!G27 -> 0.16809274 | J15: ='Evolutive SFP'!H4/'Evolutive SFP'!H27 -> 0.1491352 | K15: ='Evolutive SFP'!I4/'Evolutive SFP'!I27 -> 0.078799714 | ... AT15: ='Evolutive SFP'!AR4/'Evolutive SFP'!AR27 -> #DIV/0!
A16: STRUCTURE | B16: NEA ratio | C16: Max 10% | D16: =('Evolutive SFP'!B7+'Evolutive SFP'!B21)/'Evolutive SFP'!B27 -> 0.12101375 | E16: =('Evolutive SFP'!C7+'Evolutive SFP'!C21)/'Evolutive SFP'!C27 -> 0.018551457 | F16: =('Evolutive SFP'!D7+'Evolutive SFP'!D21)/'Evolutive SFP'!D27 -> 0.021276563 | G16: =('Evolutive SFP'!E7+'Evolutive SFP'!E21)/'Evolutive SFP'!E27 -> 0.019522379 | H16: =('Evolutive SFP'!F7+'Evolutive SFP'!F21)/'Evolutive SFP'!F27 -> 0.022170961 | I16: =('Evolutive SFP'!G7+'Evolutive SFP'!G21)/'Evolutive SFP'!G27 -> 0.021548211 | J16: =('Evolutive SFP'!H7+'Evolutive SFP'!H21)/'Evolutive SFP'!H27 -> 0.025305434 | K16: =('Evolutive SFP'!I7+'Evolutive SFP'!I21)/'Evolutive SFP'!I27 -> 0.02533989 | ... AT16: =('Evolutive SFP'!AR7+'Evolutive SFP'!AR21)/'Evolutive SFP'!AR27 -> #DIV/0!
B17: LB ratio | C17: Max 5% | D17: ='Evolutive SFP'!B21/'Evolutive SFP'!B27 -> 0.032278671 | E17: ='Evolutive SFP'!C21/'Evolutive SFP'!C27 -> 0.018551457 | F17: ='Evolutive SFP'!D21/'Evolutive SFP'!D27 -> 0.021276563 | G17: ='Evolutive SFP'!E21/'Evolutive SFP'!E27 -> 0.019522379 | H17: ='Evolutive SFP'!F21/'Evolutive SFP'!F27 -> 0.022170961 | I17: ='Evolutive SFP'!G21/'Evolutive SFP'!G27 -> 0.021548211 | J17: ='Evolutive SFP'!H21/'Evolutive SFP'!H27 -> 0.025305434 | K17: ='Evolutive SFP'!I21/'Evolutive SFP'!I27 -> 0.02533989 | ... AT17: ='Evolutive SFP'!AR21/'Evolutive SFP'!AR27 -> #DIV/0!
B18: PI to Deposit ratio | C18: Max 5% | D18: ='Evolutive SFP'!B13/'Evolutive SFP'!B31 -> 0.0036721969 | E18: ='Evolutive SFP'!C13/'Evolutive SFP'!C31 -> 0.00011985728 | F18: ='Evolutive SFP'!D13/'Evolutive SFP'!D31 -> 0.011137565 | G18: ='Evolutive SFP'!E13/'Evolutive SFP'!E31 -> 0.010954344 | H18: ='Evolutive SFP'!F13/'Evolutive SFP'!F31 -> 0.012366954 | I18: ='Evolutive SFP'!G13/'Evolutive SFP'!G31 -> 0.014286339 | J18: ='Evolutive SFP'!H13/'Evolutive SFP'!H31 -> 0.015592661 | K18: ='Evolutive SFP'!I13/'Evolutive SFP'!I31 -> 0.01571831 | ... AT18: ='Evolutive SFP'!AR13/'Evolutive SFP'!AR31 -> #DIV/0!
B19: PI to CC ratio | C19: Max 40% | D19: ='Evolutive SFP'!B13/(CAELS!D3*1000000) -> 0.030948443 | E19: ='Evolutive SFP'!C13/(CAELS!E3*1000000) -> 0.00015509416 | F19: ='Evolutive SFP'!D13/(CAELS!F3*1000000) -> 0.015363472 | G19: ='Evolutive SFP'!E13/(CAELS!G3*1000000) -> 0.015388453 | H19: ='Evolutive SFP'!F13/(CAELS!H3*1000000) -> 0.015191975 | I19: ='Evolutive SFP'!G13/(CAELS!I3*1000000) -> 0.014651754 | J19: ='Evolutive SFP'!H13/(CAELS!J3*1000000) -> 0.017611216 | K19: ='Evolutive SFP'!I13/(CAELS!K3*1000000) -> 0.01414467 | ... AT19: ='Evolutive SFP'!AR13/(CAELS!AT3*1000000) -> #DIV/0!
B20: Gross loans/TA | D20: ='Evolutive SFP'!B15/'Evolutive SFP'!B27 -> 0.74763912 | E20: ='Evolutive SFP'!C15/'Evolutive SFP'!C27 -> 0.85969175 | F20: ='Evolutive SFP'!D15/'Evolutive SFP'!D27 -> 0.90279046 | G20: ='Evolutive SFP'!E15/'Evolutive SFP'!E27 -> 0.8810173 | H20: ='Evolutive SFP'!F15/'Evolutive SFP'!F27 -> 0.89398599 | I20: ='Evolutive SFP'!G15/'Evolutive SFP'!G27 -> 0.94102026 | J20: ='Evolutive SFP'!H15/'Evolutive SFP'!H27 -> 0.96603307 | K20: ='Evolutive SFP'!I15/'Evolutive SFP'!I27 -> 1.037621 | ... AT20: ='Evolutive SFP'!AR15/'Evolutive SFP'!AR27 -> #DIV/0!
A21: FUNDING MIX | B21: Total Deposits/Total Assets | D21: ='Evolutive SFP'!B31/'Evolutive SFP'!B27 -> 0.85159483 | E21: ='Evolutive SFP'!C31/'Evolutive SFP'!C27 -> 0.53962619 | F21: ='Evolutive SFP'!D31/'Evolutive SFP'!D27 -> 0.56656945 | G21: ='Evolutive SFP'!E31/'Evolutive SFP'!E27 -> 0.56394393 | H21: ='Evolutive SFP'!F31/'Evolutive SFP'!F27 -> 0.52134786 | I21: ='Evolutive SFP'!G31/'Evolutive SFP'!G27 -> 0.46618742 | J21: ='Evolutive SFP'!H31/'Evolutive SFP'!H27 -> 0.45193834 | K21: ='Evolutive SFP'!I31/'Evolutive SFP'!I27 -> 0.44893606 | ... AT21: ='Evolutive SFP'!AR31/'Evolutive SFP'!AR27 -> #DIV/0!
B22: BOSA Deposits/Total Assets | D22: ='Evolutive SFP'!B30/'Evolutive SFP'!B27 -> 0.74257768 | E22: ='Evolutive SFP'!C30/'Evolutive SFP'!C27 -> 0 | F22: ='Evolutive SFP'!D30/'Evolutive SFP'!D27 -> 0.25934631 | G22: ='Evolutive SFP'!E30/'Evolutive SFP'!E27 -> 0.26735628 | H22: ='Evolutive SFP'!F30/'Evolutive SFP'!F27 -> 0.27581984 | I22: ='Evolutive SFP'!G30/'Evolutive SFP'!G27 -> 0.29063658 | J22: ='Evolutive SFP'!H30/'Evolutive SFP'!H27 -> 0.31264494 | K22: ='Evolutive SFP'!I30/'Evolutive SFP'!I27 -> 0.31996797 | ... AT22: ='Evolutive SFP'!AR30/'Evolutive SFP'!AR27 -> #DIV/0!
B23: FOSA Deposits/Total Assets | D23: =('Evolutive SFP'!B28+'Evolutive SFP'!B29)/'Evolutive SFP'!B27 -> 0.10901715 | E23: =('Evolutive SFP'!C28+'Evolutive SFP'!C29)/'Evolutive SFP'!C27 -> 0.53962619 | F23: =('Evolutive SFP'!D28+'Evolutive SFP'!D29)/'Evolutive SFP'!D27 -> 0.30722314 | G23: =('Evolutive SFP'!E28+'Evolutive SFP'!E29)/'Evolutive SFP'!E27 -> 0.29658765 | H23: =('Evolutive SFP'!F28+'Evolutive SFP'!F29)/'Evolutive SFP'!F27 -> 0.24552802 | I23: =('Evolutive SFP'!G28+'Evolutive SFP'!G29)/'Evolutive SFP'!G27 -> 0.17555084 | J23: =('Evolutive SFP'!H28+'Evolutive SFP'!H29)/'Evolutive SFP'!H27 -> 0.13929339 | K23: =('Evolutive SFP'!I28+'Evolutive SFP'!I29)/'Evolutive SFP'!I27 -> 0.12896809 | ... AT23: =('Evolutive SFP'!AR28+'Evolutive SFP'!AR29)/'Evolutive SFP'!AR27 -> #DIV/0!
A24: GROWTH RATIOS | B24: Total Assets | D24: =(Financials!C4-Financials!B4)/Financials!B4 -> #VALUE! | E24: =(Financials!D4-Financials!C4)/Financials!C4 -> 4.1190621 | F24: =(Financials!E4-Financials!D4)/Financials!D4 -> 0.0084063479 | G24: =(Financials!F4-Financials!E4)/Financials!E4 -> 0.02145944 | H24: =(Financials!G4-Financials!F4)/Financials!F4 -> -0.041853387 | I24: =(Financials!H4-Financials!G4)/Financials!G4 -> -0.031925432 | J24: =(Financials!I4-Financials!H4)/Financials!H4 -> -0.054890561 | K24: =(Financials!J4-Financials!I4)/Financials!I4 -> -0.0013597411 | ... AT24: =(Financials!AS4-Financials!AR4)/Financials!AR4 -> #DIV/0!
B25: Total Deposits | C25: =IF(CAELS!D16<6%,"1",IF) -> #NAME? | D25: =Financials!D5/Financials!C5-1 -> 2.2437726 | E25: =Financials!E5/Financials!D5-1 -> 0.058755561 | F25: =Financials!F5/Financials!E5-1 -> 0.016725924 | G25: =Financials!G5/Financials!F5-1 -> -0.11422456 | H25: =Financials!H5/Financials!G5-1 -> -0.13435112 | I25: =Financials!I5/Financials!H5-1 -> -0.08377797 | J25: =Financials!J5/Financials!I5-1 -> -0.0079938121 | K25: =Financials!K5/Financials!J5-1 -> -0.021949659 | ... AT25: =Financials!AT5/Financials!AS5-1 -> #DIV/0!
B26: BOSA Deposits | D26: =Financials!D6/Financials!C6-1 -> -1 | E26: =Financials!E6/Financials!D6-1 -> #DIV/0! | F26: =Financials!F6/Financials!E6-1 -> 0.053007443 | G26: =Financials!G6/Financials!F6-1 -> -0.011521847 | H26: =Financials!H6/Financials!G6-1 -> 0.020078479 | I26: =Financials!I6/Financials!H6-1 -> 0.016677551 | J26: =Financials!J6/Financials!I6-1 -> 0.022031232 | K26: =Financials!K6/Financials!J6-1 -> 0.01449644 | ... AT26: =Financials!AT6/Financials!AS6-1 -> #DIV/0!
B27: FOSA Deposits | D27: =Financials!D7/Financials!C7-1 -> 24.338948 | E27: =Financials!E7/Financials!D7-1 -> -0.4258882 | F27: =Financials!F7/Financials!E7-1 -> -0.01390158 | G27: =Financials!G7/Financials!F7-1 -> -0.20680501 | H27: =Financials!H7/Financials!G7-1 -> -0.30783334 | I27: =Financials!I7/Financials!H7-1 -> -0.25008904 | J27: =Financials!J7/Financials!I7-1 -> -0.075385221 | K27: =Financials!K7/Financials!J7-1 -> -0.1123719 | ... AT27: =Financials!AT7/Financials!AS7-1 -> #DIV/0!
