Workbook

Sheet Balance Sheet
B1: KENYA BANKERS SACCO SOCIETY | Q1: =+V:V -> 0
B2: STATEMENT OF FINANCIAL POSITION
B3: FINANCIAL YEAR 2020 | C3: Jan | D3: Feb | E3: Mar | F3: Apr | G3: May | H3: Jun | I3: Jul | J3: Aug | K3: Sep | L3: Oct | M3: Nov | N3: Dec | O3: Aud-21
A4: 1 | B4: Cash & Cash Equivalent | C4: =C5+C6 -> 1.4729131e+08 | D4: =D5+D6 -> 1.0259974e+08 | E4: =E5+E6 -> 1.2357917e+08 | F4: =F5+F6 -> -2344782.4 | G4: =G5+G6 -> 96062402 | H4: =H5+H6 -> 1.1798726e+08 | I4: =I5+I6 -> 96460508 | J4: =J5+J6 -> 1.8864061e+08 | ... AF4: =AF5+AF6 -> 1.3626877e+08
A5: 1.1 | B5: Cash in hand(both local and foreign notes and coins) | C5: 8079045 | D5: 7800650 | E5: 5143063.8 | F5: 8703851.8 | G5: 5808633 | H5: 8497425 | I5: 4285853 | J5: 7941319 | K5: 6098657 | L5: 6699976 | M5: 7795055 | N5: 5445340 | O5: 5445340 | P5: 5445340 | Q5: 5445340 | R5: 5445340 | S5: 5445340 | T5: 5445340 | U5: 5445340 | V5: 5445340 | W5: 5445340 | X5: 5445340 | Y5: 5445340 | Z5: 5445340 | AA5: 5445340 | AB5: 5445340 | AC5: 5445340 | AD5: 5445340 | AE5: 5445340 | AF5: 5445340
A6: 1.2 | B6: Cash at bank:(placement with financial institutions) | C6: 1.3921227e+08 | D6: 94799091 | E6: 1.1843611e+08 | F6: -11048634 | G6: 90253769 | H6: 1.0948984e+08 | I6: 92174656 | J6: 1.8069929e+08 | K6: 1.9065183e+08 | L6: 1.7456905e+08 | M6: 1.8722295e+08 | N6: 1.3082343e+08 | O6: 1.3082343e+08 | P6: 1.3082343e+08 | Q6: 1.3082343e+08 | R6: 1.3082343e+08 | S6: 1.3082343e+08 | T6: 1.3082343e+08 | U6: 1.3082343e+08 | V6: 1.3082343e+08 | W6: 1.3082343e+08 | X6: 1.3082343e+08 | Y6: 1.3082343e+08 | Z6: 1.3082343e+08 | AA6: 1.3082343e+08 | AB6: 1.3082343e+08 | AC6: 1.3082343e+08 | AD6: 1.3082343e+08 | AE6: 1.3082343e+08 | AF6: 1.3082343e+08
A7: 2 | B7: Prepayments & Sundry Receivables | C7: 0 | D7: 0 | E7: 0 | F7: 0 | G7: 0 | H7: 0 | I7: 0 | J7: 0 | K7: 0 | L7: 0 | M7: 0 | N7: 0 | O7: 880187024 | P7: 880187024 | Q7: 880187024 | R7: 880187024 | S7: 880187024 | T7: 880187024 | U7: 880187024 | V7: 880187024 | W7: 880187024 | X7: 880187024 | Y7: 880187024 | Z7: 880187024 | AA7: 880187024 | AB7: 880187024 | AC7: 880187024 | AD7: 880187024 | AE7: 880187024 | AF7: 880187024
A8: 3 | B8: Financial Investments | C8: =SUM(C9:C12) -> 93386179 | D8: =SUM(D9:D12) -> 76980777 | E8: =SUM(E9:E12) -> 76980777 | F8: =SUM(F9:F12) -> 76980777 | G8: =SUM(G9:G12) -> 76980777 | H8: =SUM(H9:H12) -> 76980777 | I8: =SUM(I9:I12) -> 76980777 | J8: =SUM(J9:J12) -> 76980777 | ... AF8: =SUM(AF9:AF12) -> 81097869
A9: 3.1 | B9: Government Securities - Treasury Bills/bonds, | C9: 0 | D9: 0 | E9: 0 | F9: 0 | G9: 0 | H9: 0 | I9: 0 | J9: 0 | K9: 0 | L9: 0 | M9: 0 | N9: 0
A10: 3.2 | B10: Other Securities - Commercial papers/Bonds | C10: 0 | D10: 0 | E10: 0 | F10: 0 | G10: 0 | H10: 0 | I10: 0 | J10: 0 | K10: 0 | L10: 0 | M10: 0 | N10: 0
A11: 3.3a | B11: Balances with other SACCO Societies | C11: 0 | D11: 0 | E11: 0 | F11: 0 | G11: 0 | H11: 0 | I11: 0 | J11: 0 | K11: 0 | L11: 0 | M11: 0 | N11: 0
A12: 3.3b | B12: Investments in companies - shares/stocks | C12: 93386179 | D12: 76980777 | E12: 76980777 | F12: 76980777 | G12: 76980777 | H12: 76980777 | I12: 76980777 | J12: 76980777 | K12: 76980777 | L12: 76980777 | M12: 76980777 | N12: 76980777 | O12: 81097852 | P12: 81097853 | Q12: 81097854 | R12: 81097855 | S12: 81097856 | T12: 81097857 | U12: 81097858 | V12: 81097859 | W12: 81097860 | X12: 81097861 | Y12: 81097862 | Z12: 81097863 | AA12: 81097864 | AB12: 81097865 | AC12: 81097866 | AD12: 81097867 | AE12: 81097868 | AF12: 81097869
A13: 4 | B13: Net Loan Portfolio | C13: =C14-C15 -> 5.9430778e+09 | D13: =D14-D15 -> 5.973187e+09 | E13: =E14-E15 -> 6.0500559e+09 | F13: =F14-F15 -> 6.065138e+09 | G13: =G14-G15 -> 6.1709147e+09 | H13: =H14-H15 -> 6.2283523e+09 | I13: =I14-I15 -> 6.3031761e+09 | J13: =J14-J15 -> 6.3517236e+09 | ... AF13: =AF14-AF15 -> 6.7473244e+09
A14: 4.1 | B14: Gross Loan Portfolio | C14: 6.3630278e+09 | D14: 6.4136727e+09 | E14: 6.4151384e+09 | F14: 6.4406371e+09 | G14: 6.5568305e+09 | H14: 6.6246848e+09 | I14: 6.7099252e+09 | J14: 6.7688894e+09 | K14: 6.8021682e+09 | L14: 6.8819186e+09 | M14: 6.902719e+09 | N14: 7.0263254e+09 | O14: 7.0263254e+09 | P14: 7.0263254e+09 | Q14: 7.0263254e+09 | R14: 7.0263254e+09 | S14: 7.0263254e+09 | T14: 7.0263254e+09 | U14: 7.0263254e+09 | V14: 7.0263254e+09 | W14: 7.0263254e+09 | X14: 7.0263254e+09 | Y14: 7.0263254e+09 | Z14: 7.0263254e+09 | AA14: 7.0263254e+09 | AB14: 7.0263254e+09 | AC14: 7.0263254e+09 | AD14: 7.0263254e+09 | AE14: 7.0263254e+09 | AF14: 7.0263254e+09
A15: 4.2 | B15: Allowance for Loan Loss | C15: 4.1995003e+08 | D15: 4.4048571e+08 | E15: 3.6508245e+08 | F15: 3.7549912e+08 | G15: 3.8591579e+08 | H15: 3.9633245e+08 | I15: 4.0674912e+08 | J15: 4.1716579e+08 | K15: 4.271751e+08 | L15: 4.3759176e+08 | M15: 4.4800843e+08 | N15: 3.6356153e+08 | O15: 279001058 | P15: 279001058 | Q15: 279001058 | R15: 279001058 | S15: 279001058 | T15: 279001058 | U15: 279001058 | V15: 279001058 | W15: 279001058 | X15: 279001058 | Y15: 279001058 | Z15: 279001058 | AA15: 279001058 | AB15: 279001058 | AC15: 279001058 | AD15: 279001058 | AE15: 279001058 | AF15: 279001058
A16: 5 | B16: Accounts Receivables | C16: =C17+C18+C19 -> 28741928 | D16: =D17+D18+D19 -> 28741928 | E16: =E17+E18+E19 -> 28781528 | F16: =F17+F18+F19 -> 24756888 | G16: =G17+G18+G19 -> 25020226 | H16: =H17+H18+H19 -> 26631261 | I16: =I17+I18+I19 -> 26631261 | J16: =J17+J18+J19 -> 26640315 | ... AF16: =AF17+AF18+AF19 -> 23421554
A17: 5.1 | B17: Tax Recoverable | C17: 28741928 | D17: 28741928 | E17: 28781528 | F17: 24756888 | G17: 25020226 | H17: 26631261 | I17: 26631261 | J17: 26640315 | K17: 28172061 | L17: 28172061 | M17: 28245554 | N17: 29748787 | O17: 23421537 | P17: 23421538 | Q17: 23421539 | R17: 23421540 | S17: 23421541 | T17: 23421542 | U17: 23421543 | V17: 23421544 | W17: 23421545 | X17: 23421546 | Y17: 23421547 | Z17: 23421548 | AA17: 23421549 | AB17: 23421550 | AC17: 23421551 | AD17: 23421552 | AE17: 23421553 | AF17: 23421554
A18: 5.2 | B18: Deferred Tax Assets | C18: 0 | D18: 0 | E18: 0 | F18: 0 | G18: 0 | H18: 0 | I18: 0 | J18: 0 | K18: 0 | L18: 0 | M18: 0 | N18: 0
A19: 5.3 | B19: Retirement Benefit Assets | C19: 0 | D19: 0 | E19: 0 | F19: 0 | G19: 0 | H19: 0 | I19: 0 | J19: 0 | K19: 0 | L19: 0 | M19: 0 | N19: 0
A20: 6 | B20: Property & Equipment & Other assets | C20: =SUM(C21:C25) -> 2.2612288e+09 | D20: =SUM(D21:D25) -> 2.2653815e+09 | E20: =SUM(E21:E25) -> 2.2894412e+09 | F20: =SUM(F21:F25) -> 2.2581132e+09 | G20: =SUM(G21:G25) -> 2.2476172e+09 | H20: =SUM(H21:H25) -> 2.2759246e+09 | I20: =SUM(I21:I25) -> 2.2452509e+09 | J20: =SUM(J21:J25) -> 2.2194119e+09 | ... AF20: =SUM(AF21:AF25) -> 1.235038e+09
A21: 6.1 | B21: Investment Properties | C21: 2.9228211e+08 | D21: 2.9146795e+08 | E21: 2.906538e+08 | F21: 2.8983964e+08 | G21: 2.8902548e+08 | H21: 2.8821133e+08 | I21: 2.8739717e+08 | J21: 2.8658302e+08 | K21: 2.8576886e+08 | L21: 2.849547e+08 | M21: 2.8414055e+08 | N21: 2.8332639e+08 | O21: 2.8332639e+08 | P21: 2.8332639e+08 | Q21: 2.8332639e+08 | R21: 2.8332639e+08 | S21: 2.8332639e+08 | T21: 2.8332639e+08 | U21: 2.8332639e+08 | V21: 2.8332639e+08 | W21: 2.8332639e+08 | X21: 2.8332639e+08 | Y21: 2.8332639e+08 | Z21: 2.8332639e+08 | AA21: 2.8332639e+08 | AB21: 2.8332639e+08 | AC21: 2.8332639e+08 | AD21: 2.8332639e+08 | AE21: 2.8332639e+08 | AF21: 2.8332639e+08
A22: 6.2 | B22: Property & Equipment | C22: 9.1113038e+08 | D22: 9.1031516e+08 | E22: 9.0949994e+08 | F22: 9.0868472e+08 | G22: 9.078695e+08 | H22: 9.0705427e+08 | I22: 9.0623905e+08 | J22: 9.0542383e+08 | K22: 9.0460861e+08 | L22: 9.0379339e+08 | M22: 9.0297816e+08 | N22: 9.0216294e+08 | O22: 922136847 | P22: 922136847 | Q22: 922136847 | R22: 922136847 | S22: 922136847 | T22: 922136847 | U22: 922136847 | V22: 922136847 | W22: 922136847 | X22: 922136847 | Y22: 922136847 | Z22: 922136847 | AA22: 922136847 | AB22: 922136847 | AC22: 922136847 | AD22: 922136847 | AE22: 922136847 | AF22: 922136847
A23: 6.3 | B23: Prepaid Lease rentals | C23: 14867672 | D23: 14826258 | E23: 14784844 | F23: 14743430 | G23: 14702015 | H23: 14660601 | I23: 14619187 | J23: 14577773 | K23: 14536359 | L23: 14494945 | M23: 14453531 | N23: 14412117 | O23: 14412117 | P23: 14412117 | Q23: 14412117 | R23: 14412117 | S23: 14412117 | T23: 14412117 | U23: 14412117 | V23: 14412117 | W23: 14412117 | X23: 14412117 | Y23: 14412117 | Z23: 14412117 | AA23: 14412117 | AB23: 14412117 | AC23: 14412117 | AD23: 14412117 | AE23: 14412117 | AF23: 14412117
A24: 6.4 | B24: Intangible Assets | C24: 8395745.4 | D24: 17942524 | E24: 20303961 | F24: 20017480 | G24: 19072289 | H24: 18127099 | I24: 17181909 | J24: 16703385 | K24: 15741528 | L24: 14779671 | M24: 13817813 | N24: 15162623 | O24: 15162623 | P24: 15162623 | Q24: 15162623 | R24: 15162623 | S24: 15162623 | T24: 15162623 | U24: 15162623 | V24: 15162623 | W24: 15162623 | X24: 15162623 | Y24: 15162623 | Z24: 15162623 | AA24: 15162623 | AB24: 15162623 | AC24: 15162623 | AD24: 15162623 | AE24: 15162623 | AF24: 15162623
A25: 6.5 | B25: Other Assets | C25: 1.0345529e+09 | D25: 1.0308296e+09 | E25: 1.0541986e+09 | F25: 1.024828e+09 | G25: 1.0169479e+09 | H25: 1.0478713e+09 | I25: 1.0198136e+09 | J25: 9.9612385e+08 | K25: 9.559728e+08 | L25: 9.3622639e+08 | M25: 9.1089967e+08 | N25: 8.8233129e+08
B26: Total Assets | C26: =C4+C7+C8+C13+C16+C20 -> 8.473726e+09 | D26: =D4+D7+D8+D13+D16+D20 -> 8.446891e+09 | E26: =E4+E7+E8+E13+E16+E20 -> 8.5688386e+09 | F26: =F4+F7+F8+F13+F16+F20 -> 8.4226441e+09 | G26: =G4+G7+G8+G13+G16+G20 -> 8.6165953e+09 | H26: =H4+H7+H8+H13+H16+H20 -> 8.7258762e+09 | I26: =I4+I7+I8+I13+I16+I20 -> 8.7484996e+09 | J26: =J4+J7+J8+J13+J16+J20 -> 8.8633972e+09 | ... AF26: =AF4+AF7+AF8+AF13+AF16+AF20 -> 9.1033376e+09
A27: 7 | B27: Savings Deposits - Withdrawable deposits - FOSA) | C27: 2.4933391e+08 | D27: 2.5070718e+08 | E27: 2.4870435e+08 | F27: 3.7166343e+08 | G27: 3.3236623e+08 | H27: 3.5764162e+08 | I27: 3.1208834e+08 | J27: 3.034737e+08 | K27: 2.8829496e+08 | L27: 2.8098015e+08 | M27: 2.7985456e+08 | N27: 2.9223505e+08 | O27: 2.9223505e+08 | P27: 2.9223505e+08 | Q27: 2.9223505e+08 | R27: 2.9223505e+08 | S27: 2.9223505e+08 | T27: 2.9223505e+08 | U27: 2.9223505e+08 | V27: 2.9223505e+08 | W27: 2.9223505e+08 | X27: 2.9223505e+08 | Y27: 2.9223505e+08 | Z27: 2.9223505e+08 | AA27: 2.9223505e+08 | AB27: 2.9223505e+08 | AC27: 2.9223505e+08 | AD27: 2.9223505e+08 | AE27: 2.9223505e+08 | AF27: 2.9223505e+08
A28: 8 | B28: Short Term Deposits (e.g Fixed deposits, special savings) | C28: 0 | D28: 0 | E28: 0 | F28: 0 | G28: 394000 | H28: 7494000 | I28: 8039000 | J28: 9295000 | K28: 10158100 | L28: 9856066.7 | M28: 10628184 | N28: 21109326 | O28: 21109326 | P28: 21109326 | Q28: 21109326 | R28: 21109326 | S28: 21109326 | T28: 21109326 | U28: 21109326 | V28: 21109326 | W28: 21109326 | X28: 21109326 | Y28: 21109326 | Z28: 21109326 | AA28: 21109326 | AB28: 21109326 | AC28: 21109326 | AD28: 21109326 | AE28: 21109326 | AF28: 21109326
A29: 9 | B29: Non withdrawable deposits (BOSA member deposits) | C29: 6.3707385e+09 | D29: 6.3868349e+09 | E29: 6.3905167e+09 | F29: 6.3246728e+09 | G29: 6.3480927e+09 | H29: 6.363003e+09 | I29: 6.3736711e+09 | J29: 6.3872117e+09 | K29: 6.3790737e+09 | L29: 6.390194e+09 | M29: 6.3821645e+09 | N29: 6.3707315e+09 | O29: 6.3707315e+09 | P29: 6.3707315e+09 | Q29: 6.3707315e+09 | R29: 6.3707315e+09 | S29: 6.3707315e+09 | T29: 6.3707315e+09 | U29: 6.3707315e+09 | V29: 6.3707315e+09 | W29: 6.3707315e+09 | X29: 6.3707315e+09 | Y29: 6.3707315e+09 | Z29: 6.3707315e+09 | AA29: 6.3707315e+09 | AB29: 6.3707315e+09 | AC29: 6.3707315e+09 | AD29: 6.3707315e+09 | AE29: 6.3707315e+09 | AF29: 6.3707315e+09
B30: Total Deposit liabilities | C30: =SUM(C27:C29) -> 6.6200724e+09 | D30: =SUM(D27:D29) -> 6.6375421e+09 | E30: =SUM(E27:E29) -> 6.639221e+09 | F30: =SUM(F27:F29) -> 6.6963362e+09 | G30: =SUM(G27:G29) -> 6.6808529e+09 | H30: =SUM(H27:H29) -> 6.7281386e+09 | I30: =SUM(I27:I29) -> 6.6937985e+09 | J30: =SUM(J27:J29) -> 6.6999804e+09 | ... AF30: =SUM(AF27:AF29) -> 6.6840759e+09
A31: 10 | B31: Accounts Payable & Other Liabilities | C31: =SUM(C32:C37) -> 5.9891407e+08 | D31: =SUM(D32:D37) -> 5.6609793e+08 | E31: =SUM(E32:E37) -> 5.7493683e+08 | F31: =SUM(F32:F37) -> 5.6712301e+08 | G31: =SUM(G32:G37) -> 7.7878842e+08 | H31: =SUM(H32:H37) -> 8.4700955e+08 | I31: =SUM(I32:I37) -> 8.7720565e+08 | J31: =SUM(J32:J37) -> 9.6787778e+08 | ... AF31: =SUM(AF32:AF37) -> 1.2195176e+09
A32: 10.1 | B32: Tax Payable | C32: 0 | D32: 0 | E32: 0 | F32: 0 | G32: 0 | H32: 0 | I32: 0 | J32: 0 | K32: 0 | L32: 0 | M32: 0 | N32: 0
A33: 10.2 | B33: Dividends Payable | C33: 0 | D33: 0 | E33: 0 | F33: 0 | G33: 0 | H33: 0 | I33: 0 | J33: 0 | K33: 0 | L33: 0 | M33: 0 | N33: 0 | O33: 298281586 | P33: 298281586 | Q33: 298281586 | R33: 298281586 | S33: 298281586 | T33: 298281586 | U33: 298281586 | V33: 298281586 | W33: 298281586 | X33: 298281586 | Y33: 298281586 | Z33: 298281586 | AA33: 298281586 | AB33: 298281586 | AC33: 298281586 | AD33: 298281586 | AE33: 298281586 | AF33: 298281586
A34: 10.3 | B34: Deferred Tax Liability | C34: 0 | D34: 0 | E34: 0 | F34: 0 | G34: 0 | H34: 0 | I34: 0 | J34: 0 | K34: 0 | L34: 0 | M34: 0 | N34: 0 | O34: 1235123 | P34: 1235123 | Q34: 1235123 | R34: 1235123 | S34: 1235123 | T34: 1235123 | U34: 1235123 | V34: 1235123 | W34: 1235123 | X34: 1235123 | Y34: 1235123 | Z34: 1235123 | AA34: 1235123 | AB34: 1235123 | AC34: 1235123 | AD34: 1235123 | AE34: 1235123 | AF34: 1235123
A35: 10.4 | B35: Retirement Benefits Liability | C35: 0 | D35: 0 | E35: 0 | F35: 0 | G35: 0 | H35: 0 | I35: 0 | J35: 0 | K35: 0 | L35: 0 | M35: 0 | N35: 0
A36: 10.5 | B36: Other Liabilities | C36: 1.1141405e+08 | D36: 93521445 | E36: 1.1286205e+08 | F36: 1.1554993e+08 | G36: 1.5699874e+08 | H36: 2.0728354e+08 | I36: 1.7297988e+08 | J36: 1.7871111e+08 | K36: 1.64855e+08 | L36: 1.7683015e+08 | M36: 1.6348117e+08 | N36: 3.2108064e+08 | O36: 324167601 | P36: 324167601 | Q36: 324167601 | R36: 324167601 | S36: 324167601 | T36: 324167601 | U36: 324167601 | V36: 324167601 | W36: 324167601 | X36: 324167601 | Y36: 324167601 | Z36: 324167601 | AA36: 324167601 | AB36: 324167601 | AC36: 324167601 | AD36: 324167601 | AE36: 324167601 | AF36: 324167601
A37: 10.6 | B37: External Borrowings | C37: 4.8750002e+08 | D37: 4.7257648e+08 | E37: 4.6207478e+08 | F37: 4.5157308e+08 | G37: 6.2178968e+08 | H37: 6.3972601e+08 | I37: 7.0422577e+08 | J37: 7.8916667e+08 | K37: 7.7833333e+08 | L37: 7.6748047e+08 | M37: 7.5639242e+08 | N37: 5.9583333e+08 | O37: 5.9583333e+08 | P37: 5.9583333e+08 | Q37: 5.9583333e+08 | R37: 5.9583333e+08 | S37: 5.9583333e+08 | T37: 5.9583333e+08 | U37: 5.9583333e+08 | V37: 5.9583333e+08 | W37: 5.9583333e+08 | X37: 5.9583333e+08 | Y37: 5.9583333e+08 | Z37: 5.9583333e+08 | AA37: 5.9583333e+08 | AB37: 5.9583333e+08 | AC37: 5.9583333e+08 | AD37: 5.9583333e+08 | AE37: 5.9583333e+08 | AF37: 5.9583333e+08
B38: Total Liabilities | C38: =C30+C31 -> 7.2189865e+09 | D38: =D30+D31 -> 7.20364e+09 | E38: =E30+E31 -> 7.2141579e+09 | F38: =F30+F31 -> 7.2634592e+09 | G38: =G30+G31 -> 7.4596414e+09 | H38: =H30+H31 -> 7.5751482e+09 | I38: =I30+I31 -> 7.5710041e+09 | J38: =J30+J31 -> 7.6678581e+09 | ... AF38: =AF30+AF31 -> 7.9035935e+09
A39: 11 | B39: Share Capital (Members share capital per Bylaws) | C39: 3.977344e+08 | D39: 3.9792867e+08 | E39: 3.9858449e+08 | F39: 4.3650281e+08 | G39: 4.3654727e+08 | H39: 4.3675346e+08 | I39: 4.4333245e+08 | J39: 4.4786485e+08 | K39: 4.6355402e+08 | L39: 4.6613899e+08 | M39: 4.6899363e+08 | N39: 4.7221939e+08 | O39: 4.7221939e+08 | P39: 4.7221939e+08 | Q39: 4.7221939e+08 | R39: 4.7221939e+08 | S39: 4.7221939e+08 | T39: 4.722194e+08 | U39: 4.722194e+08 | V39: 4.722194e+08 | W39: 4.722194e+08 | X39: 4.722194e+08 | Y39: 4.722194e+08 | Z39: 4.722194e+08 | AA39: 4.722194e+08 | AB39: 4.722194e+08 | AC39: 4.722194e+08 | AD39: 4.7221941e+08 | AE39: 4.7221941e+08 | AF39: 4.7221941e+08
A40: 12 | B40: Capital Grants | C40: 0 | D40: 0 | E40: 0 | G40: 0 | H40: 0 | I40: 0 | J40: 0 | K40: 0 | L40: 0 | M40: 0 | N40: 0
...

Sheet InsiderLending
A2: No. | B2: Name | C2: Designation | D2: Loan Type/Name | E2: Ref No | F2: Amount Granted | G2: Disbursement Date | H2: BOSA Deposits | I2: Security | J2: Repayment Commencement | K2: Repayment Period | L2: Amnt. Outstanding | M2: Status
A3: 1 | B3: Everlyne Kavetsa | C3: Tea Lady | D3: Staff Personal Loan | E3: 3006 | F3: 30000 | G3: 28/09/2021 | I3: Salary | J3: 30/10/2021 | K3: 24M
A4: 2 | B4: Everlyne Kavetsa | C4: Tea Lady | D4: Land Purchase Loan | F4: 486000 | G4: 28/08/2018 | I4: Title | J4: 30/09/2018 | K4: 72M | L4: 258085.12 | M4: Performing
A5: 3 | B5: Everlyne Kavetsa | C5: Tea Lady | D5: Development Loan | F5: 1092000 | G5: 43985 | I5: Guarantors | J5: 30/04/2020 | K5: 48M | L5: 747914.92 | M5: Performing
A6: 4 | B6: Samir Makokha | C6: Clerk | D6: Education Loan | E6: 3011 | F6: 42000 | G6: 30/09/2021 | I6: Guarantors | J6: 30/10/2021 | K6: 36M
A7: 5 | B7: Samir Makokha | C7: Clerk | D7: Staff Personal Loan | F7: 130000 | G7: 25/06/2021 | I7: Salary | J7: 30/07/2021 | K7: 24M | L7: 114393.49 | M7: Performing
A8: 6 | B8: Samir Makokha | C8: Clerk | D8: SDevelopment Loan | F8: 320000 | G8: 44257 | I8: Guarantors | J8: 30/03/2021 | K8: 48M | L8: 285192.53 | M8: Performing
A9: 7 | B9: Vincent Mutambu | C9: Director | D9: Micro Loan | E9: 3020 | F9: 300000 | G9: 27/09/2021 | I9: Guarantors | J9: 30/10/2021 | K9: 36M
A10: 8 | B10: Vincent Mutambu | C10: Director | D10: Super Loan | F10: 3800000 | G10: 44116 | I10: Guarantors | J10: 30/12/2021 | K10: 72M | L10: 3514678 | M10: Performing
A11: 9 | B11: Getrude Wambuga | C11: Director | D11: Micro Loan | E11: 3020 | F11: 1000000 | G11: 30/09/2021 | I11: Guarantors | J11: 30/10/2021 | K11: 36M
A12: 10 | B12: Getrude Wambuga | C12: Director | D12: Super Loan | F12: 10429000 | G12: 13/11/2020 | I12: Security | J12: 30/12/2020 | K12: 72M | L12: 9757941.7 | M12: Performing
A13: 11 | B13: Yvonne Muhonja | C13: Clerk | D13: Staff Personal Loan | E13: 3006 | F13: 300000 | G13: 29/09/2021 | I13: Salary | J13: 30/10/2021 | K13: 24M
A14: 12 | B14: Yvonne Muhonja | C14: Clerk | D14: Education Loan | F14: 210000 | G14: 16/07/2021 | I14: Guarantors | J14: 30/08/2021 | K14: 36M | L14: 198484.71 | M14: Performing
A15: 13 | B15: Yvonne Muhonja | C15: Clerk | D15: SDevelopment Loan | F15: 744000 | G15: 22/12/2020 | I15: Guarantors | J15: 30/01/2021 | K15: 48M | L15: 632288.44 | M15: Performing

Sheet Income Stat.
A1: KENYA BANKERS SACCO SOCIETY
A2: STATEMENT OF COMPREHENSIVE INCOME
A3: FINANCIAL YEAR 2020 | C3: Jan | D3: Feb | E3: Mar | F3: Apr | G3: May | H3: Jun | I3: Jul | J3: Aug | K3: Sep | L3: Oct | M3: Nov | N3: Dec | O3: Aud-21
A4: 1 | B4: Financial Income | C4: 78948582 | D4: 1.5385348e+08 | E4: 2.3308428e+08 | F4: 3.1443812e+08 | G4: 4.017811e+08 | H4: 4.8317304e+08 | I4: 5.6681704e+08 | J4: 6.5452735e+08 | K4: 7.3390629e+08 | L4: 8.1638663e+08 | M4: 8.9814715e+08 | N4: 9.8266676e+08 | O4: =O8+O5 -> 1.000688e+09
A5: 2 | B5: Financial Income from Loans Portfolio | C5: 69094322 | D5: 1.3387912e+08 | E5: 2.0429935e+08 | F5: 2.7607341e+08 | G5: 3.4775592e+08 | H5: 4.203079e+08 | I5: 4.9460423e+08 | J5: 5.6932914e+08 | K5: 6.4035346e+08 | L5: 7.1387917e+08 | M5: 7.8640989e+08 | N5: 8.6141783e+08 | O5: =O6+O7 -> 948974631
A6: 2.1 | B6: Interest on Loan Portfolio | C6: 67898220 | D6: 1.3165494e+08 | E6: 2.0085845e+08 | F6: 2.7130717e+08 | G6: 3.4193432e+08 | H6: 4.0941418e+08 | I6: 4.8184109e+08 | J6: 5.5449515e+08 | K6: 6.2132995e+08 | L6: 6.931537e+08 | M6: 7.6162342e+08 | N6: 8.3387167e+08 | O6: 948974631
A7: 2.2 | B7: Fees & Commission on Loan Portfolio | C7: 1196101.1 | D7: 2224174.2 | E7: 3440890.1 | F7: 4766244.1 | G7: 5821593.7 | H7: 10893717 | I7: 12763140 | J7: 14833996 | K7: 19023504 | L7: 20725474 | M7: 24786465 | N7: 27546154 | O7: 0
A8: 3 | B8: Financial Income from Investments in: | C8: 41803.25 | D8: 476923 | E8: 622054.16 | F8: 622054.16 | G8: 7014046.8 | H8: 7014046.8 | I8: 7014046.8 | J8: 11214047 | K8: 11214047 | L8: 11214047 | M8: 11214047 | N8: 11214047 | O8: =O9+O10+O11+O12 -> 51713338
A9: 3.1 | B9: Government Securities | C9: 0 | D9: 0 | E9: 0 | F9: 0 | G9: 0 | H9: 0 | I9: 0 | J9: 0 | K9: 0 | L9: 0 | M9: 0 | N9: 0 | O9: 0
A10: 3.2 | B10: Deposit with Banks and Other Financial Inst. | C10: 41803.25 | D10: 0 | E10: 139131.16 | F10: 139131.16 | G10: 139131.16 | H10: 139131.16 | I10: 139131.16 | J10: 4339131.2 | K10: 4339131.2 | L10: 4339131.2 | M10: 4339131.2 | N10: 4339131.2 | O10: 4339131.2
A11: 3.3 | B11: Other Investments - dividend & Interest incomes from investments | C11: 0 | D11: 476923 | E11: 482923 | F11: 482923 | G11: 6874915.6 | H11: 6874915.6 | I11: 6874915.6 | J11: 6874915.6 | K11: 6874915.6 | L11: 6874915.6 | M11: 6874915.6 | N11: 6874915.6
A12: 3.4 | B12: Other Operating Income- Salary processing fees, transaction fees, membership fees | C12: 9812457.5 | D12: 19497440 | E12: 28162884 | F12: 37742652 | G12: 47011139 | H12: 55851094 | I12: 65198759 | J12: 73984161 | K12: 82338783 | L12: 91293410 | M12: 1.0052321e+08 | N12: 1.1003489e+08 | O12: 47374207
A13: 4 | B13: Financial Expense | C13: 6240404 | D13: 11742326 | E13: 17000143 | F13: 19746697 | G13: 35854014 | H13: 38295867 | I13: 54387956 | J13: 73436064 | K13: 81634156 | L13: 91380046 | M13: 99366544 | N13: 1.0935491e+08 | O13: =O14+O15+O16+O17+O18+O19 -> 4.3736558e+08 | R13: =30+16 -> 46
A14: 4.2 | B14: Interest Expense on Deposits | C14: 792148.4 | D14: 1227938.6 | E14: 1729489.1 | F14: 3104850 | G14: 4593995.7 | H14: 5791387.9 | I14: 7346315.6 | J14: 8483382.9 | K14: 9397844.4 | L14: 10242396 | M14: 10826022 | N14: 11451139 | O14: =384025545-74292819 -> 309732726
A15: 4.3 | B15: Cost of External Borrowings | C15: 4820856 | D15: 9394160.6 | E15: 13661872 | F15: 14016362 | G15: 25214861 | H15: 25634748 | I15: 36339754 | J15: 40474314 | K15: 52245032 | L15: 60487786 | M15: 67147995 | N15: 74292819 | O15: 74292819
A16: 4.4 | B16: Dividend Expenses (on member shares) | C16: 0 | D16: 0 | E16: 0 | F16: 0 | G16: 0 | H16: 0 | I16: 0 | J16: 0 | K16: 0 | L16: 0 | M16: 0 | N16: 0
A17: 4.5 | B17: Other Financial Expense | C17: 0 | D17: 0 | E17: 0 | F17: 0 | G17: 0 | H17: 0 | I17: 0 | J17: 0 | K17: 0 | L17: 0 | M17: 0 | N17: 23610948 | O17: 23610948
A18: 4.6 | B18: Fees & Commission Expense | C18: 627399.6 | D18: 1120227.1 | E18: 1608782.2 | F18: 2625485 | G18: 6045157.7 | H18: 6869731.4 | I18: 10701887 | J18: 24478366 | K18: 19991280 | L18: 20649865 | M18: 21392527 | N18: 0 | O18: 496970
A19: 4.7 | B19: Other Expense | C19: 0 | D19: 0 | E19: 0 | F19: 0 | G19: 0 | H19: 0 | I19: 0 | J19: 0 | K19: 0 | L19: 0 | M19: 0 | N19: 0 | O19: 29232116
A20: 5 | B20: Net Financial Income/(Loss) | C20: 72708178 | D20: 1.4211115e+08 | E20: 2.1608414e+08 | F20: 2.9469142e+08 | G20: 3.6592709e+08 | H20: 4.4487717e+08 | I20: 5.1242908e+08 | J20: 5.8109129e+08 | K20: 6.5227213e+08 | L20: 7.2500658e+08 | M20: 7.987806e+08 | N20: 8.7331185e+08 | O20: =O4-O13 -> 5.6332239e+08
A21: 6 | B21: Allowance for Loan Loss | C21: 10416667 | D21: 20833333 | E21: 31250000 | F21: 56666667 | G21: 70833333 | H21: 85000000 | I21: 99166667 | J21: 1.1333333e+08 | K21: 1.275e+08 | L21: 1.4166667e+08 | M21: 1.5583333e+08 | N21: 75961193 | O21: =O22-O23 -> 29729076
A22: 6.1 | B22: Provision for Loan Losses | C22: 10416667 | D22: 20833333 | E22: 31250000 | F22: 56666667 | G22: 70833333 | H22: 85000000 | I22: 99166667 | J22: 1.1333333e+08 | K22: 1.275e+08 | L22: 1.4166667e+08 | M22: 1.5583333e+08 | N22: 75961193 | O22: 29729076
A23: 6.2 | B23: Value of Loans Recovered | C23: 0 | D23: 0 | E23: 0 | F23: 0 | G23: 0 | H23: 0 | I23: 0 | J23: 0 | K23: 0 | L23: 0 | M23: 0 | N23: 0
A24: 7 | B24: Operating Expenses | C24: 27660898 | D24: 60346992 | E24: 97812986 | F24: 1.3276495e+08 | G24: 1.6652222e+08 | H24: 2.3468512e+08 | I24: 2.7149158e+08 | J24: 3.1375901e+08 | K24: 3.4942284e+08 | L24: 3.8462047e+08 | M24: 4.2138522e+08 | N24: 4.6216506e+08 | O24: =O25+O26+O27+O28+O29 -> 4.6441893e+08
A25: 7.1 | B25: Personnel Expenses | C25: 15532706 | D25: 34822552 | E25: 49612509 | F25: 65001932 | G25: 79812699 | H25: 1.3378808e+08 | I25: 1.5376604e+08 | J25: 1.7352748e+08 | K25: 1.9382155e+08 | L25: 2.1410292e+08 | M25: 2.3430497e+08 | N25: 2.5570016e+08 | O25: 2.5570016e+08
A26: 7.2 | B26: Governance Expenses | C26: 1785126 | D26: 4378692.6 | E26: 11262769 | F26: 17635999 | G26: 21596361 | H26: 24283077 | I26: 27135578 | J26: 29663457 | K26: 34423928 | L26: 36669984 | M26: 38138650 | N26: 40612973 | O26: 40612973
A27: 7.3 | B27: Marketing Expenses | C27: 2233906.7 | D27: 3871993.3 | E27: 4326200 | F27: 9115133.3 | G27: 11811987 | H27: 13543150 | I27: 15209263 | J27: 17903957 | K27: 19481062 | L27: 21371908 | M27: 24026278 | N27: 26223260 | O27: 26323260
A28: 7.4 | B28: Depreciation and Amortization Charges | C28: 2813890.3 | D28: 6220657.3 | E28: 10012018 | F28: 13611557 | G28: 16998486 | H28: 20360243 | I28: 23770457 | J28: 27786899 | K28: 31197823 | L28: 34576247 | M28: 38101709 | N28: 41928145 | O28: 41431174
A29: 7.5 | B29: Administrative Expenses | C29: 5295269.4 | D29: 11053097 | E29: 22599489 | F29: 27400327 | G29: 36302682 | H29: 42710576 | I29: 51610235 | J29: 64877218 | K29: 70498472 | L29: 77899416 | M29: 86813620 | N29: 97700523 | O29: =126674620-26323260 -> 100351360
A30: 8 | B30: Net Operating Income | C30: 34630614 | D30: 60930828 | E30: 87021153 | F30: 1.0525981e+08 | G30: 1.2857154e+08 | H30: 125192052 | I30: 1.4177084e+08 | J30: 1.5399894e+08 | K30: 1.7534929e+08 | L30: 1.9871944e+08 | M30: 2.2156205e+08 | N30: 3.3518559e+08 | O30: =O20-O21-O24 -> 69174385
A31: 9 | B31: Net Non- Operating Income/ (Expense) | C31: 3380093.2 | D31: 2688939.5 | E31: 4523860.4 | F31: 3945663.8 | G31: 4432327.1 | H31: 5376939.6 | I31: 6399849.4 | J31: 8819539.9 | K31: 10189525 | L31: 11050404 | M31: 14052578 | N31: 15955750 | O31: =O32-O33 -> 0
A32: 9.1 | B32: Non- Operating Income | C32: 3380093.2 | D32: 2688939.5 | E32: 4523860.4 | F32: 5220713.8 | G32: 5765377.1 | H32: 7023839.6 | I32: 8098309.4 | J32: 10519000 | K32: 12254985 | L32: 13115864 | M32: 16118038 | N32: 18021210
A33: 9.2 | B33: Non- Operating Expense | C33: 0 | D33: 0 | E33: 0 | F33: 1275050 | G33: 1333050 | H33: 1646900 | I33: 1698460 | J33: 1699460 | K33: 2065460 | L33: 2065460 | M33: 2065460 | N33: 2065460
A34: 10 | B34: Net Income (Before Taxes and Donations) | C34: 38010707 | D34: 63619767 | E34: 91545014 | F34: 1.0920547e+08 | G34: 1.3300387e+08 | H34: 1.3056899e+08 | I34: 1.4817069e+08 | J34: 1.6281848e+08 | K34: 1.8553882e+08 | L34: 2.0976985e+08 | M34: 2.3561463e+08 | N34: 3.5114134e+08 | O34: =O30+O31 -> 69174385
A35: 11 | B35: Taxes (Incomes taxes & Other payable to KRA) | C35: 0 | D35: 0 | E35: 0 | F35: 0 | G35: 0 | H35: 0 | I35: 0 | J35: 0 | K35: 0 | L35: 0 | M35: 0 | N35: 0 | O35: 6327250
A36: 12 | B36: Net Income (After Taxes before Donations) | C36: 38010707 | D36: 63619767 | E36: 91545014 | F36: 1.0920547e+08 | G36: 1.3300387e+08 | H36: 1.3056899e+08 | I36: 1.4817069e+08 | J36: 1.6281848e+08 | K36: 1.8553882e+08 | L36: 2.0976985e+08 | M36: 2.3561463e+08 | N36: 3.5114134e+08 | O36: =O34-O35 -> 62847135
A37: 13 | B37: Donations | C37: -126040 | D37: -146040 | E37: -574015 | F37: -594015 | G37: -645575 | H37: -506875 | I37: -526875 | J37: -645375 | K37: -645375 | L37: -685375 | M37: -685375 | N37: -685375
A38: 14 | B38: Net Income/(After Taxes and Donations) | C38: 38136747 | D38: 63765807 | E38: 92119029 | F38: 1.0979949e+08 | G38: 1.3364944e+08 | H38: 1.3107587e+08 | I38: 1.4869756e+08 | J38: 1.6346386e+08 | K38: 1.8618419e+08 | L38: 2.1045522e+08 | M38: 2.363e+08 | N38: 3.5182672e+08 | O38: =O36-O37 -> 62847135

Sheet Form 4
C6: FORM 4
E7: June 2021
C9: CLASSIFICATION | D9: NO. OF A/Cs | E9: OUTSTANDING LOAN PORTFOLIO(Kshs) | F9: REQUIRED PROVISION | G9: REQUIRED PROVISION AMOUNT(Kshs)
C10: Performing | F10: 0.01 | G10: =F10*E10 -> 0
C11: Watch | F11: 0.05 | G11: =F11*E11 -> 0
C12: Substandard | F12: 0.25 | G12: =F12*E12 -> 0
C13: Doubtful | F13: 0.5 | G13: =F13*E13 -> 0
C14: Loss | F14: 1 | G14: =F14*E14 -> 0
C15: subtotal | F15: 1.81
C17: Performing | F17: 0.01 | G17: -
C18: Watch | F18: 0.05 | G18: -
C19: Substandard | F19: 0.25 | G19: -
C20: Doubtful | F20: 0.5 | G20: -
C21: Loss | F21: 1 | G21: -
C22: subtotal
D26: NPL
D27: PAR

Sheet Financials
A1: KENYA BANKERS SACCO FINANCIALS
A3: Year/month | B3: Jan | C3: Feb | D3: Mar | E3: Apr | F3: May | G3: Jun | H3: Jul | I3: Aug | J3: Sep | K3: Oct | L3: Nov | M3: Dec | N3: Aud-20
A4: Membership
A5: Total Assets | B5: ='Balance Sheet'!C26 -> 8.473726e+09 | C5: ='Balance Sheet'!D26 -> 8.446891e+09 | D5: ='Balance Sheet'!E26 -> 8.5688386e+09 | E5: ='Balance Sheet'!F26 -> 8.4226441e+09 | F5: ='Balance Sheet'!G26 -> 8.6165953e+09 | G5: ='Balance Sheet'!H26 -> 8.7258762e+09 | H5: ='Balance Sheet'!I26 -> 8.7484996e+09 | I5: ='Balance Sheet'!J26 -> 8.8633972e+09 | ... O5: ='Balance Sheet'!P26 -> 9.1033375e+09
A6: Total Deposits | B6: =B7+B8 -> 6.6200724e+09 | C6: =C7+C8 -> 6.6375421e+09 | D6: =D7+D8 -> 6.639221e+09 | E6: =E7+E8 -> 6.6963362e+09 | F6: =F7+F8 -> 6.6804589e+09 | G6: =G7+G8 -> 6.7206446e+09 | H6: =H7+H8 -> 6.6857595e+09 | I6: =I7+I8 -> 6.6906854e+09 | ... O6: =O7+O8 -> 6.6629666e+09
A7: Deposits-Members(BOSA) | B7: ='Balance Sheet'!C29 -> 6.3707385e+09 | C7: ='Balance Sheet'!D29 -> 6.3868349e+09 | D7: ='Balance Sheet'!E29 -> 6.3905167e+09 | E7: ='Balance Sheet'!F29 -> 6.3246728e+09 | F7: ='Balance Sheet'!G29 -> 6.3480927e+09 | G7: ='Balance Sheet'!H29 -> 6.363003e+09 | H7: ='Balance Sheet'!I29 -> 6.3736711e+09 | I7: ='Balance Sheet'!J29 -> 6.3872117e+09 | ... O7: ='Balance Sheet'!P29 -> 6.3707315e+09
A8: Deposits-Customers(FOSA) | B8: ='Balance Sheet'!C27 -> 2.4933391e+08 | C8: ='Balance Sheet'!D27 -> 2.5070718e+08 | D8: ='Balance Sheet'!E27 -> 2.4870435e+08 | E8: ='Balance Sheet'!F27 -> 3.7166343e+08 | F8: ='Balance Sheet'!G27 -> 3.3236623e+08 | G8: ='Balance Sheet'!H27 -> 3.5764162e+08 | H8: ='Balance Sheet'!I27 -> 3.1208834e+08 | I8: ='Balance Sheet'!J27 -> 3.034737e+08 | ... O8: ='Balance Sheet'!P27 -> 2.9223505e+08
A9: Deposits-Term | B9: ='Balance Sheet'!C28 -> 0 | C9: ='Balance Sheet'!D28 -> 0 | D9: ='Balance Sheet'!E28 -> 0 | E9: ='Balance Sheet'!F28 -> 0 | F9: ='Balance Sheet'!G28 -> 394000 | G9: ='Balance Sheet'!H28 -> 7494000 | H9: ='Balance Sheet'!I28 -> 8039000 | I9: ='Balance Sheet'!J28 -> 9295000 | ... O9: ='Balance Sheet'!P28 -> 21109326
A10: External Borrowing | B10: ='Balance Sheet'!C37 -> 4.8750002e+08 | C10: ='Balance Sheet'!D37 -> 4.7257648e+08 | D10: ='Balance Sheet'!E37 -> 4.6207478e+08 | E10: ='Balance Sheet'!F37 -> 4.5157308e+08 | F10: ='Balance Sheet'!G37 -> 6.2178968e+08 | G10: ='Balance Sheet'!H37 -> 6.3972601e+08 | H10: ='Balance Sheet'!I37 -> 7.0422577e+08 | I10: ='Balance Sheet'!J37 -> 7.8916667e+08 | ... O10: ='Balance Sheet'!P37 -> 5.9583333e+08
A12: Share capital and Reserves
A13: Core Capital | B13: =B15-B28 -> 1.0346532e+09 | C13: =C15-C28 -> 1.0231646e+09 | D13: =D15-D28 -> 1.1509998e+09 | E13: =E15-E28 -> 9.5550396e+08 | F13: =F15-F28 -> 9.5327303e+08 | G13: =G15-G28 -> 9.4704719e+08 | H13: =H15-H28 -> 9.7381461e+08 | I13: =I15-I28 -> 9.9185818e+08 | ... O13: =O15-O28 -> 9.4116723e+08
A14: Institutional Capital | B14: =B13-B16 -> 6.369188e+08 | C14: =C13-C16 -> 6.2523596e+08 | D14: =D13-D16 -> 7.5241532e+08 | E14: =E13-E16 -> 5.1900114e+08 | F14: =F13-F16 -> 5.1672576e+08 | G14: =G13-G16 -> 5.1029373e+08 | H14: =H13-H16 -> 5.3048216e+08 | I14: =I13-I16 -> 5.4399333e+08 | ... O14: =O13-O16 -> 4.6894784e+08
A15: Total Capital | B15: =B16+B17+B18+B19+B20+B21 -> 1.0346532e+09 | C15: =C16+C17+C18+C19+C20+C21 -> 1.0231646e+09 | D15: =D16+D17+D18+D19+D20+D21 -> 1.1509998e+09 | E15: =E16+E17+E18+E19+E20+E21 -> 9.5550396e+08 | F15: =F16+F17+F18+F19+F20+F21 -> 9.5327303e+08 | G15: =G16+G17+G18+G19+G20+G21 -> 9.4704719e+08 | H15: =H16+H17+H18+H19+H20+H21 -> 9.7381461e+08 | I15: =I16+I17+I18+I19+I20+I21 -> 9.9185818e+08 | ... O15: =O16+O17+O18+O19+O20+O21 -> 9.4116723e+08
A16: Members Share Capital | B16: ='Balance Sheet'!C39 -> 3.977344e+08 | C16: ='Balance Sheet'!D39 -> 3.9792867e+08 | D16: ='Balance Sheet'!E39 -> 3.9858449e+08 | E16: ='Balance Sheet'!F39 -> 4.3650281e+08 | F16: ='Balance Sheet'!G39 -> 4.3654727e+08 | G16: ='Balance Sheet'!H39 -> 4.3675346e+08 | H16: ='Balance Sheet'!I39 -> 4.4333245e+08 | I16: ='Balance Sheet'!J39 -> 4.4786485e+08 | ... O16: ='Balance Sheet'!P39 -> 4.7221939e+08
A17: Entrance Fees
A18: Retained Earnings | B18: ='Balance Sheet'!C41 -> 1.8451279e+08 | C18: ='Balance Sheet'!D41 -> 2.314654e+08 | D18: ='Balance Sheet'!E41 -> 3.2805625e+08 | E18: ='Balance Sheet'!F41 -> 93574466 | F18: ='Balance Sheet'!G41 -> 1.0002902e+08 | G18: ='Balance Sheet'!H41 -> 97732847 | H18: ='Balance Sheet'!I41 -> 1.1531454e+08 | I18: ='Balance Sheet'!J41 -> 1.2984384e+08 | ... N18: ='Balance Sheet'!O41 -> -31530815 | O18: ='Balance Sheet'!P42 -> -32329268
A19: Appropriation Account | B19: ='Balance Sheet'!C48 -> 0 | C19: ='Balance Sheet'!D48 -> 0 | D19: ='Balance Sheet'!E48 -> 0 | E19: ='Balance Sheet'!F48 -> 0 | F19: ='Balance Sheet'!G48 -> 0 | G19: ='Balance Sheet'!H48 -> 0 | H19: ='Balance Sheet'!I48 -> 0 | I19: ='Balance Sheet'!J48 -> 0 | ... O19: ='Balance Sheet'!P48 -> 47221939
A20: Statutory Reserves | B20: ='Balance Sheet'!C45 -> 145522017 | C20: ='Balance Sheet'!D45 -> 145522017 | D20: ='Balance Sheet'!E45 -> 160648412 | E20: ='Balance Sheet'!F45 -> 160648412 | F20: ='Balance Sheet'!G45 -> 160648412 | G20: ='Balance Sheet'!H45 -> 160648412 | H20: ='Balance Sheet'!I45 -> 160648412 | I20: ='Balance Sheet'!J45 -> 160648412 | ... N20: ='Balance Sheet'!O45 -> 173217839 | O20: ='Balance Sheet'!P47 -> 206562827
A21: Capital Reserves | B21: ='Balance Sheet'!C46 -> 3.0688399e+08 | C21: ='Balance Sheet'!D46 -> 2.4824854e+08 | D21: ='Balance Sheet'!E46 -> 2.6371066e+08 | E21: ='Balance Sheet'!F46 -> 2.6477826e+08 | F21: ='Balance Sheet'!G46 -> 2.5604832e+08 | G21: ='Balance Sheet'!H46 -> 2.5191247e+08 | H21: ='Balance Sheet'!I46 -> 2.545192e+08 | I21: ='Balance Sheet'!J46 -> 2.5350108e+08 | ... O21: ='Balance Sheet'!P46 -> 247492339
A22: Supplementary Capital & reserves
A23: Proposed Dividends
A24: Benevolent Fund
A25: Investments | B25: =B26+B27+B29 -> 93386179 | C25: =C26+C27+C29 -> 76980777 | D25: =D26+D27+D29 -> 76980777 | E25: =E26+E27+E29 -> 76980777 | F25: =F26+F27+F29 -> 76980777 | G25: =G26+G27+G29 -> 76980777 | H25: =H26+H27+H29 -> 76980777 | I25: =I26+I27+I29 -> 76980777 | ... O25: =O26+O27+O29 -> 81097853
A26: Govt bills | B26: ='Balance Sheet'!C8 -> 93386179 | C26: ='Balance Sheet'!D8 -> 76980777 | D26: ='Balance Sheet'!E8 -> 76980777 | E26: ='Balance Sheet'!F8 -> 76980777 | F26: ='Balance Sheet'!G8 -> 76980777 | G26: ='Balance Sheet'!H8 -> 76980777 | H26: ='Balance Sheet'!I8 -> 76980777 | I26: ='Balance Sheet'!J8 -> 76980777 | ... O26: ='Balance Sheet'!P8 -> 81097853
A27: Investments in naccos | B27: ='Balance Sheet'!C11 -> 0 | C27: ='Balance Sheet'!D11 -> 0 | D27: ='Balance Sheet'!E11 -> 0 | E27: ='Balance Sheet'!F11 -> 0 | F27: ='Balance Sheet'!G11 -> 0 | G27: ='Balance Sheet'!H11 -> 0 | H27: ='Balance Sheet'!I11 -> 0 | I27: ='Balance Sheet'!J11 -> 0 | ... O27: ='Balance Sheet'!P11 -> 0
A28: Equity Investments (at cost) | B28: ='Balance Sheet'!C9 -> 0 | C28: ='Balance Sheet'!D9 -> 0 | D28: ='Balance Sheet'!E9 -> 0 | E28: ='Balance Sheet'!F9 -> 0 | F28: ='Balance Sheet'!G9 -> 0 | G28: ='Balance Sheet'!H9 -> 0 | H28: ='Balance Sheet'!I9 -> 0 | I28: ='Balance Sheet'!J9 -> 0 | ... O28: ='Balance Sheet'!P9 -> 0
A29: Deposits in KUSCCO CFP | B29: ='Balance Sheet'!C10 -> 0 | C29: ='Balance Sheet'!D10 -> 0 | D29: ='Balance Sheet'!E10 -> 0 | E29: ='Balance Sheet'!F10 -> 0 | F29: ='Balance Sheet'!G10 -> 0 | G29: ='Balance Sheet'!H10 -> 0 | H29: ='Balance Sheet'!I10 -> 0 | I29: ='Balance Sheet'!J10 -> 0 | ... O29: ='Balance Sheet'!P10 -> 0
A30: Net Loans & Advances | B30: =B31-B32 -> -4.1995003e+08 | C30: =C31-C32 -> -4.4048571e+08 | D30: =D31-D32 -> -3.6508245e+08 | E30: =E31-E32 -> -3.7549912e+08 | F30: =F31-F32 -> -3.8591579e+08 | G30: =G31-G32 -> -3.9633245e+08 | H30: =H31-H32 -> -4.0674912e+08 | I30: =I31-I32 -> -4.1716579e+08 | ... O30: =O31-O32 -> -279001058
A31: Gross Loans & advances | B31: ='Balance Sheet'!C13 -> 5.9430778e+09 | C31: ='Balance Sheet'!D13 -> 5.973187e+09 | D31: ='Balance Sheet'!E13 -> 6.0500559e+09 | E31: ='Balance Sheet'!F13 -> 6.065138e+09 | F31: ='Balance Sheet'!G13 -> 6.1709147e+09 | G31: ='Balance Sheet'!H13 -> 6.2283523e+09 | H31: ='Balance Sheet'!I13 -> 6.3031761e+09 | I31: ='Balance Sheet'!J13 -> 6.3517236e+09 | ... O31: ='Balance Sheet'!P13 -> 6.7473244e+09
A32: Allowance for loan losses | B32: ='Balance Sheet'!C14 -> 6.3630278e+09 | C32: ='Balance Sheet'!D14 -> 6.4136727e+09 | D32: ='Balance Sheet'!E14 -> 6.4151384e+09 | E32: ='Balance Sheet'!F14 -> 6.4406371e+09 | F32: ='Balance Sheet'!G14 -> 6.5568305e+09 | G32: ='Balance Sheet'!H14 -> 6.6246848e+09 | H32: ='Balance Sheet'!I14 -> 6.7099252e+09 | I32: ='Balance Sheet'!J14 -> 6.7688894e+09 | ... O32: ='Balance Sheet'!P14 -> 7.0263254e+09
A34: Non-Earning Assets | B34: ='Balance Sheet'!C6+'Balance Sheet'!C15+'Balance Sheet'!C19 -> 5.591623e+08 | C34: ='Balance Sheet'!D6+'Balance Sheet'!D15+'Balance Sheet'!D19 -> 5.352848e+08 | D34: ='Balance Sheet'!E6+'Balance Sheet'!E15+'Balance Sheet'!E19 -> 4.8351856e+08 | E34: ='Balance Sheet'!F6+'Balance Sheet'!F15+'Balance Sheet'!F19 -> 3.6445049e+08 | F34: ='Balance Sheet'!G6+'Balance Sheet'!G15+'Balance Sheet'!G19 -> 4.7616956e+08 | G34: ='Balance Sheet'!H6+'Balance Sheet'!H15+'Balance Sheet'!H19 -> 5.0582229e+08 | H34: ='Balance Sheet'!I6+'Balance Sheet'!I15+'Balance Sheet'!I19 -> 4.9892378e+08 | I34: ='Balance Sheet'!J6+'Balance Sheet'!J15+'Balance Sheet'!J19 -> 5.9786508e+08 | ... O34: ='Balance Sheet'!P6+'Balance Sheet'!P15+'Balance Sheet'!P19 -> 4.0982449e+08
A35: Property and Equipment | B35: ='Balance Sheet'!C19 -> 0 | C35: ='Balance Sheet'!D19 -> 0 | D35: ='Balance Sheet'!E19 -> 0 | E35: ='Balance Sheet'!F19 -> 0 | F35: ='Balance Sheet'!G19 -> 0 | G35: ='Balance Sheet'!H19 -> 0 | H35: ='Balance Sheet'!I19 -> 0 | I35: ='Balance Sheet'!J19 -> 0 | ... O35: ='Balance Sheet'!P19 -> 0
A38: Turnover | B38: =B39+B41+B42 -> 69136125 | C38: =C39+C41+C42 -> 1.3435604e+08 | D38: =D39+D41+D42 -> 2.049214e+08 | E38: =E39+E41+E42 -> 2.7669547e+08 | F38: =F39+F41+F42 -> 3.5476996e+08 | G38: =G39+G41+G42 -> 4.2732195e+08 | H38: =H39+H41+H42 -> 5.0161828e+08 | I38: =I39+I41+I42 -> 5.8054319e+08 | ... O38: =O39+O41+O42 -> 0
A39: Loan Interest | B39: ='Income Stat.'!C6 -> 67898220 | C39: ='Income Stat.'!D6 -> 1.3165494e+08 | D39: ='Income Stat.'!E6 -> 2.0085845e+08 | E39: ='Income Stat.'!F6 -> 2.7130717e+08 | F39: ='Income Stat.'!G6 -> 3.4193432e+08 | G39: ='Income Stat.'!H6 -> 4.0941418e+08 | H39: ='Income Stat.'!I6 -> 4.8184109e+08 | I39: ='Income Stat.'!J6 -> 5.5449515e+08 | ... O39: ='Income Stat.'!P6 -> 0
A40: Yield on loans | B40: ='Income Stat.'!C6/'Income Stat.'!C14 -> 85.714016 | C40: ='Income Stat.'!D6/'Income Stat.'!D14 -> 107.21622 | D40: ='Income Stat.'!E6/'Income Stat.'!E14 -> 116.13745 | E40: ='Income Stat.'!F6/'Income Stat.'!F14 -> 87.381732 | F40: ='Income Stat.'!G6/'Income Stat.'!G14 -> 74.430702 | G40: ='Income Stat.'!H6/'Income Stat.'!H14 -> 70.693622 | H40: ='Income Stat.'!I6/'Income Stat.'!I14 -> 65.58949 | I40: ='Income Stat.'!J6/'Income Stat.'!J14 -> 65.362504 | ... O40: ='Income Stat.'!P6/'Income Stat.'!P14 -> #DIV/0!
A41: Income from investments | B41: ='Income Stat.'!C8 -> 41803.25 | C41: ='Income Stat.'!D8 -> 476923 | D41: ='Income Stat.'!E8 -> 622054.16 | E41: ='Income Stat.'!F8 -> 622054.16 | F41: ='Income Stat.'!G8 -> 7014046.8 | G41: ='Income Stat.'!H8 -> 7014046.8 | H41: ='Income Stat.'!I8 -> 7014046.8 | I41: ='Income Stat.'!J8 -> 11214047 | ... O41: ='Income Stat.'!P8 -> 0
A42: Fees & Commissions | B42: ='Income Stat.'!C7 -> 1196101.1 | C42: ='Income Stat.'!D7 -> 2224174.2 | D42: ='Income Stat.'!E7 -> 3440890.1 | E42: ='Income Stat.'!F7 -> 4766244.1 | F42: ='Income Stat.'!G7 -> 5821593.7 | G42: ='Income Stat.'!H7 -> 10893717 | H42: ='Income Stat.'!I7 -> 12763140 | I42: ='Income Stat.'!J7 -> 14833996 | ... O42: ='Income Stat.'!P7 -> 0
A44: Finanacial and Operating costs | B44: =B45+B46+B47+B48 -> 40243618 | C44: =C45+C46+C47+C48 -> 71552927 | D44: =D45+D46+D47+D48 -> 1.0241251e+08 | E44: =E45+E46+E47+E48 -> 1.2238102e+08 | F44: =F45+F46+F47+F48 -> 1.583804e+08 | G44: =G45+G46+G47+G48 -> 1.5661819e+08 | H44: =H45+H46+H47+H48 -> 1.8545691e+08 | I44: =I45+I46+I47+I48 -> 2.0295664e+08 | ... O44: =O45+O46+O47+O48 -> 0
A45: Interest expense on deposits | B45: ='Income Stat.'!C14 -> 792148.4 | C45: ='Income Stat.'!D14 -> 1227938.6 | D45: ='Income Stat.'!E14 -> 1729489.1 | E45: ='Income Stat.'!F14 -> 3104850 | F45: ='Income Stat.'!G14 -> 4593995.7 | G45: ='Income Stat.'!H14 -> 5791387.9 | H45: ='Income Stat.'!I14 -> 7346315.6 | I45: ='Income Stat.'!J14 -> 8483382.9 | ... O45: ='Income Stat.'!P14 -> 0
A46: Dividend expense on share capital | B46: ='Income Stat.'!C16 -> 0 | C46: ='Income Stat.'!D16 -> 0 | D46: ='Income Stat.'!E16 -> 0 | E46: ='Income Stat.'!F16 -> 0 | F46: ='Income Stat.'!G16 -> 0 | G46: ='Income Stat.'!H16 -> 0 | H46: ='Income Stat.'!I16 -> 0 | I46: ='Income Stat.'!J16 -> 0 | ... O46: ='Income Stat.'!P16 -> 0
...

Sheet CAEL
A1: KENYA BANKERS SACCO CAELS 2020
C2: Regulatory Stds | D2: Jan | E2: Feb | F2: Mar | G2: Apr | H2: May | I2: Jun | J2: Jul | K2: Aug | L2: Sep | M2: Oct | N2: Nov | O2: Dec | P2: Aud-21
A3: CAPITAL ADEQUACY | B3: Core Capital | C3: 10 M | D3: =Financials!B13 -> 1.0346532e+09 | E3: =Financials!C13 -> 1.0231646e+09 | F3: =Financials!D13 -> 1.1509998e+09 | G3: =Financials!E13 -> 9.5550396e+08 | H3: =Financials!F13 -> 9.5327303e+08 | I3: =Financials!G13 -> 9.4704719e+08 | J3: =Financials!H13 -> 9.7381461e+08 | K3: =Financials!I13 -> 9.9185818e+08 | ... P3: =Financials!N13 -> 9.0862069e+08 | Q3: =Financials!U14 -> 0 | R3: =Financials!V14 -> 0 | S3: =Financials!W14 -> 0 | T3: =Financials!X14 -> 0
B4: CCA | C4: 0.1 | D4: =Financials!B13/Financials!B5 -> 0.12210133 | E4: =Financials!C13/Financials!C5 -> 0.12112914 | F4: =Financials!D13/Financials!D5 -> 0.1343239 | G4: =Financials!E13/Financials!E5 -> 0.11344466 | H4: =Financials!F13/Financials!F5 -> 0.11063222 | I4: =Financials!G13/Financials!G5 -> 0.10853319 | J4: =Financials!H13/Financials!H5 -> 0.11131219 | K4: =Financials!I13/Financials!I5 -> 0.11190497 | ... P4: =Financials!N13/Financials!N5 -> 0.099811821
B5: CCD | C5: 0.08 | D5: =Financials!B13/Financials!B6 -> 0.15629031 | E5: =Financials!C13/Financials!C6 -> 0.15414812 | F5: =Financials!D13/Financials!D6 -> 0.17336368 | G5: =Financials!E13/Financials!E6 -> 0.14269056 | H5: =Financials!F13/Financials!F6 -> 0.14269574 | I5: =Financials!G13/Financials!G6 -> 0.14091612 | J5: =Financials!H13/Financials!H6 -> 0.14565505 | K5: =Financials!I13/Financials!I6 -> 0.14824463 | ... P5: =Financials!N13/Financials!N6 -> 0.13636879
B6: ICA | C6: 0.08 | D6: =(Financials!B15-Financials!B16)/Financials!B5 -> 0.075163959 | E6: =(Financials!C15-Financials!C16)/Financials!C5 -> 0.074019656 | F6: =(Financials!D15-Financials!D16)/Financials!D5 -> 0.087808321 | G6: =(Financials!E15-Financials!E16)/Financials!E5 -> 0.061619741 | H6: =(Financials!F15-Financials!F16)/Financials!F5 -> 0.05996867 | I6: =(Financials!G15-Financials!G16)/Financials!G5 -> 0.058480514 | J6: =(Financials!H15-Financials!H16)/Financials!H5 -> 0.06063693 | K6: =(Financials!I15-Financials!I16)/Financials!I5 -> 0.061375262 | ... P6: =(Financials!N15-Financials!N16)/Financials!N5 -> 0.047938605
A7: ASSET QUALITY | B7: A/LNPL30
B8: NPL30 | D8: =6.5% -> 0.065 | E8: =6.5% -> 0.065 | F8: =6.5% -> 0.065 | G8: =6.5% -> 0.065 | H8: =6.5% -> 0.065 | I8: =6.5% -> 0.065 | J8: =6.5% -> 0.065 | K8: =6.5% -> 0.065 | ... P8: =6.5% -> 0.065
B9: Non-earning Asset ratio | C9: Max 10% | D9: =('Balance Sheet'!C7+'Balance Sheet'!C20)/'Balance Sheet'!C26 -> 0.26685177 | E9: =('Balance Sheet'!D7+'Balance Sheet'!D20)/'Balance Sheet'!D26 -> 0.26819116 | F9: =('Balance Sheet'!E7+'Balance Sheet'!E20)/'Balance Sheet'!E26 -> 0.2671822 | G9: =('Balance Sheet'!F7+'Balance Sheet'!F20)/'Balance Sheet'!F26 -> 0.26810028 | H9: =('Balance Sheet'!G7+'Balance Sheet'!G20)/'Balance Sheet'!G26 -> 0.26084748 | I9: =('Balance Sheet'!H7+'Balance Sheet'!H20)/'Balance Sheet'!H26 -> 0.26082476 | J9: =('Balance Sheet'!I7+'Balance Sheet'!I20)/'Balance Sheet'!I26 -> 0.25664412 | K9: =('Balance Sheet'!J7+'Balance Sheet'!J20)/'Balance Sheet'!J26 -> 0.25040194 | ... P9: =('Balance Sheet'!O7+'Balance Sheet'!O20)/'Balance Sheet'!O26 -> 0.23235709
B10: Land and Building ratio | C10: Max 5% | D10: =('Balance Sheet'!C21+'Balance Sheet'!C22)/'Balance Sheet'!C26 -> 0.14201692 | E10: =('Balance Sheet'!D21+'Balance Sheet'!D22)/'Balance Sheet'!D26 -> 0.1422752 | F10: =('Balance Sheet'!E21+'Balance Sheet'!E22)/'Balance Sheet'!E26 -> 0.14006026 | G10: =('Balance Sheet'!F21+'Balance Sheet'!F22)/'Balance Sheet'!F26 -> 0.14229788 | H10: =('Balance Sheet'!G21+'Balance Sheet'!G22)/'Balance Sheet'!G26 -> 0.13890579 | I10: =('Balance Sheet'!H21+'Balance Sheet'!H22)/'Balance Sheet'!H26 -> 0.13697944 | J10: =('Balance Sheet'!I21+'Balance Sheet'!I22)/'Balance Sheet'!I26 -> 0.13643896 | K10: =('Balance Sheet'!J21+'Balance Sheet'!J22)/'Balance Sheet'!J26 -> 0.13448645 | ... P10: =('Balance Sheet'!O21+'Balance Sheet'!O22)/'Balance Sheet'!O26 -> 0.13241992
A11: EARNINGS | B11: Non-Government Investment to Deposit ratio | C11: Max 5% | D11: ='Balance Sheet'!C11/'Balance Sheet'!C29 -> 0 | E11: ='Balance Sheet'!D11/'Balance Sheet'!D29 -> 0 | F11: ='Balance Sheet'!E11/'Balance Sheet'!E29 -> 0 | G11: ='Balance Sheet'!F11/'Balance Sheet'!F29 -> 0 | H11: ='Balance Sheet'!G11/'Balance Sheet'!G29 -> 0 | I11: ='Balance Sheet'!H11/'Balance Sheet'!H29 -> 0 | J11: ='Balance Sheet'!I11/'Balance Sheet'!I29 -> 0 | K11: ='Balance Sheet'!J11/'Balance Sheet'!J29 -> 0 | ... P11: ='Balance Sheet'!O11/'Balance Sheet'!O29 -> 0
B12: Non-Government Investment to Core Capital ratio | C12: Max 40% | D12: ='Balance Sheet'!C11/Financials!B13 -> 0 | E12: ='Balance Sheet'!D11/Financials!C13 -> 0 | F12: ='Balance Sheet'!E11/Financials!D13 -> 0 | G12: ='Balance Sheet'!F11/Financials!E13 -> 0 | H12: ='Balance Sheet'!G11/Financials!F13 -> 0 | I12: ='Balance Sheet'!H11/Financials!G13 -> 0 | J12: ='Balance Sheet'!I11/Financials!H13 -> 0 | K12: ='Balance Sheet'!J11/Financials!I13 -> 0 | ... P12: ='Balance Sheet'!O11/Financials!N13 -> 0
B13: Gross loans/TA | D13: =Financials!B31/Financials!B5 -> 0.70135355 | E13: =Financials!C31/Financials!C5 -> 0.70714622 | F13: =Financials!D31/Financials!D5 -> 0.70605321 | G13: =Financials!E31/Financials!E5 -> 0.72009905 | H13: =Financials!F31/Financials!F5 -> 0.71616625 | I13: =Financials!G31/Financials!G5 -> 0.71377959 | J13: =Financials!H31/Financials!H5 -> 0.72048653 | K13: =Financials!I31/Financials!I5 -> 0.71662405 | ... P13: =Financials!N31/Financials!N5 -> 0.74119238
B14: ROA | D14: ='Income Stat.'!C38/Financials!B5 -> 0.0045005877 | E14: ='Income Stat.'!D38/Financials!C5 -> 0.0075490269 | F14: ='Income Stat.'!E38/Financials!D5 -> 0.010750468 | G14: ='Income Stat.'!F38/Financials!E5 -> 0.013036225 | H14: ='Income Stat.'!G38/Financials!F5 -> 0.015510702 | I14: ='Income Stat.'!H38/Financials!G5 -> 0.015021513 | J14: ='Income Stat.'!I38/Financials!H5 -> 0.016996922 | K14: ='Income Stat.'!J38/Financials!I5 -> 0.018442574 | ... P14: ='Income Stat.'!O38/Financials!N5 -> 0.0069037465
B15: Cost Income ratio | D15: ='Income Stat.'!C24/('Income Stat.'!C20-'Income Stat.'!C22) -> 0.44405566 | E15: ='Income Stat.'!D24/('Income Stat.'!D20-'Income Stat.'!D22) -> 0.49759298 | F15: ='Income Stat.'!E24/('Income Stat.'!E20-'Income Stat.'!E22) -> 0.52919329 | G15: ='Income Stat.'!F24/('Income Stat.'!F20-'Income Stat.'!F22) -> 0.5577779 | H15: ='Income Stat.'!G24/('Income Stat.'!G20-'Income Stat.'!G22) -> 0.56430274 | I15: ='Income Stat.'!H24/('Income Stat.'!H20-'Income Stat.'!H22) -> 0.65212561 | J15: ='Income Stat.'!I24/('Income Stat.'!I20-'Income Stat.'!I22) -> 0.65694718 | K15: ='Income Stat.'!J24/('Income Stat.'!J20-'Income Stat.'!J22) -> 0.67077216 | ... P15: ='Income Stat.'!O24/('Income Stat.'!O20-'Income Stat.'!O22) -> 0.87036122
B16: Operating Expense ratio | D16: ='Income Stat.'!C24/'Income Stat.'!C4 -> 0.35036599 | E16: ='Income Stat.'!D24/'Income Stat.'!D4 -> 0.39223677 | F16: ='Income Stat.'!E24/'Income Stat.'!E4 -> 0.41964642 | G16: ='Income Stat.'!F24/'Income Stat.'!F4 -> 0.42222918 | H16: ='Income Stat.'!G24/'Income Stat.'!G4 -> 0.41446005 | I16: ='Income Stat.'!H24/'Income Stat.'!H4 -> 0.48571651 | J16: ='Income Stat.'!I24/'Income Stat.'!I4 -> 0.47897568 | K16: ='Income Stat.'!J24/'Income Stat.'!J4 -> 0.47936731 | ... P16: ='Income Stat.'!O24/'Income Stat.'!O4 -> 0.46409964
A17: LIQUIDITY | B17: MIN LIQ ratio | C17: Min 15% | D17: ='Balance Sheet'!C4/'Balance Sheet'!C27 -> 0.5907392 | E17: ='Balance Sheet'!D4/'Balance Sheet'!D27 -> 0.40924133 | F17: ='Balance Sheet'!E4/'Balance Sheet'!E27 -> 0.49689188 | G17: ='Balance Sheet'!F4/'Balance Sheet'!F27 -> -0.0063088866 | H17: ='Balance Sheet'!G4/'Balance Sheet'!G27 -> 0.28902576 | I17: ='Balance Sheet'!H4/'Balance Sheet'!H27 -> 0.32990361 | J17: ='Balance Sheet'!I4/'Balance Sheet'!I27 -> 0.30908078 | K17: ='Balance Sheet'!J4/'Balance Sheet'!J27 -> 0.62160447 | ... P17: ='Balance Sheet'!O4/'Balance Sheet'!O27 -> 0.46629851
B18: Technical LIQ ratio | D18: ='Balance Sheet'!C4/'Balance Sheet'!C29 -> 0.023119975 | E18: ='Balance Sheet'!D4/'Balance Sheet'!D29 -> 0.016064254 | F18: ='Balance Sheet'!E4/'Balance Sheet'!E29 -> 0.0193379 | G18: ='Balance Sheet'!F4/'Balance Sheet'!F29 -> -0.00037073576 | H18: ='Balance Sheet'!G4/'Balance Sheet'!G29 -> 0.015132483 | I18: ='Balance Sheet'!H4/'Balance Sheet'!H29 -> 0.018542701 | J18: ='Balance Sheet'!I4/'Balance Sheet'!I29 -> 0.015134215 | K18: ='Balance Sheet'!J4/'Balance Sheet'!J29 -> 0.029534109 | ... P18: ='Balance Sheet'!O4/'Balance Sheet'!O29 -> 0.021389815
B19: External Borrowing ratio | C19: Max 25% | D19: ='Balance Sheet'!C37/'Balance Sheet'!C26 -> 0.057530775 | E19: ='Balance Sheet'!D37/'Balance Sheet'!D26 -> 0.055946795 | F19: ='Balance Sheet'!E37/'Balance Sheet'!E26 -> 0.053925019 | G19: ='Balance Sheet'!F37/'Balance Sheet'!F26 -> 0.053614171 | H19: ='Balance Sheet'!G37/'Balance Sheet'!G26 -> 0.072161876 | I19: ='Balance Sheet'!H37/'Balance Sheet'!H26 -> 0.07331367 | J19: ='Balance Sheet'!I37/'Balance Sheet'!I26 -> 0.080496748 | K19: ='Balance Sheet'!J37/'Balance Sheet'!J26 -> 0.089036591 | ... P19: ='Balance Sheet'!O37/'Balance Sheet'!O26 -> 0.065452185
