Workbook

Sheet Balance Sheet
B1: FORM 6 SASRA2/006
B2: STATEMENT OF FINANCIAL POSITION
B3: FINANCIAL YEAR 2020 | D3: 44216 | E3: 44247 | F3: 44275 | G3: 44306 | H3: 44336 | I3: 44367 | J3: 44428 | K3: 44459 | L3: 44489 | M3: 44520 | N3: 44550 | O3: Aud-20 | P3: 44197 | Q3: 44229 | R3: 44258 | S3: 44290 | T3: 44321 | U3: 44353 | V3: 44384 | W3: 44416 | X3: 44448 | Y3: 44479 | Z3: 44511 | AA3: 44542 | AB3: Audited 2021 | AC3: 44562 | AD3: 44593 | AE3: 44621 | AF3: 44652 | AG3: 44682 | AH3: 44713 | AI3: 44743 | AJ3: 44774 | AK3: 44805 | AL3: 44835 | AM3: 44866 | AN3: 44896 | AO3: AUDITED 2022 | AP3: 44927 | AQ3: 44958 | AR3: 44986 | AS3: 45017 | AT3: 45047 | AU3: 45078 | AV3: 45108 | AW3: 45139 | AX3: 45170
A4: 1 | B4: Cash & Cash Equivalent | C4: =C5+C6 -> 0 | D4: =D5+D6 -> 70753766 | E4: =E5+E6 -> 44838923 | F4: =F5+F6 -> 35209696 | G4: =G5+G6 -> 47752535 | H4: =H5+H6 -> 51170182 | I4: =I5+I6 -> 54428356 | J4: =J5+J6 -> 42109273 | ... AX4: =AX5+AX6 -> 35776780
A5: 1.1 | B5: Cash in hand(both local and foreign notes and coins) | D5: 8234269 | E5: 28909179 | F5: 19851472 | G5: 12206208 | H5: 5644954.1 | I5: 14756969 | J5: 28445220 | K5: 13084775 | L5: 46366513 | M5: 17923892 | N5: 19065207 | O5: 19065207 | P5: 15001554 | Q5: 29179749 | R5: 9869600.7 | S5: 15167130 | T5: 18479015 | U5: 13440726 | V5: 12042215 | W5: 21054030 | X5: 14937726 | Y5: 55329783 | Z5: 15247528 | AA5: 13304069 | AB5: 14090543 | AC5: 9485096 | AD5: 12261612 | AE5: 9893931 | AF5: 10440623 | AG5: 13647724 | AH5: 8339549 | AI5: 9459039 | AJ5: 10388526 | AK5: 12501270 | AL5: 2424911.3 | AM5: 2887917.3 | AN5: 2972296.3 | AO5: =6699320 -> 6699320 | AP5: 16551992 | AQ5: 16918843 | AR5: 10255264 | AS5: 10735843 | AT5: 6715858 | AU5: 11882991 | AV5: 28994632 | AW5: 15776451 | AX5: 21527386
A6: 1.2 | B6: Cash at bank:(placement with financial institutions) | D6: 62519497 | E6: 15929744 | F6: 15358224 | G6: 35546327 | H6: 45525228 | I6: 39671387 | J6: 13664053 | K6: 23814006 | L6: 1.0288392e+08 | M6: 35428449 | N6: 19276706 | O6: 82251422 | P6: 28597258 | Q6: 21499480 | R6: 16986989 | S6: 42193248 | T6: 18151805 | U6: 14918051 | V6: 34792871 | W6: 22502740 | X6: 16199277 | Y6: 56003547 | Z6: 26599338 | AA6: 15689096 | AB6: =61531261-14090543 -> 47440718 | AC6: 56622246 | AD6: 57308576 | AE6: 58168960 | AF6: 44545422 | AG6: 54609627 | AH6: 53666100 | AI6: 46478711 | AJ6: 60283462 | AK6: 38438972 | AL6: 63211407 | AM6: 47611499 | AN6: 49630990 | AO6: =4652946+5697729+31271240 -> 41621915 | AP6: 18785042 | AQ6: 17378733 | AR6: 13562308 | AS6: 13423718 | AT6: 16771657 | AU6: 27032515 | AV6: 11857674 | AW6: 18217467 | AX6: 14249394
A7: 2 | B7: Prepayments & Sundry Receivables | D7: 88761804 | E7: 85675530 | F7: 85012981 | G7: 86253649 | H7: 87238948 | I7: 88522804 | J7: 93677879 | K7: 94146757 | L7: 81442583 | M7: 84025024 | N7: 85551635 | O7: 87010349 | P7: 83827308 | Q7: 79764381 | R7: 81924016 | S7: 82410540 | T7: 80013921 | U7: 83622011 | V7: 81393323 | W7: 76684277 | X7: 86782520 | Y7: 81185877 | Z7: 83214458 | AA7: 90313385 | AB7: 88215792 | AC7: 26649305 | AD7: 25537563 | AE7: 25034687 | AF7: 25029074 | AG7: 17657990 | AH7: 26779331 | AI7: 22626698 | AJ7: 23082447 | AK7: 30551829 | AL7: 11822015 | AM7: 21842274 | AN7: 22415856 | AO7: =5414080 -> 5414080 | AP7: 72861098 | AQ7: 77264443 | AR7: 71081039 | AS7: 75486948 | AT7: 72987375 | AU7: 72938422 | AV7: 67006912 | AW7: 72408540 | AX7: 71927264
A8: 3 | B8: Financial Investments | C8: =SUM(C9:C12) -> 0 | D8: =SUM(D9:D12) -> 21017328 | E8: =SUM(E9:E12) -> 51105313 | F8: =SUM(F9:F12) -> 51346745 | G8: =SUM(G9:G12) -> 51580714 | H8: =SUM(H9:H12) -> 51822331 | I8: =SUM(I9:I12) -> 51822331 | J8: =SUM(J9:J12) -> 52537195 | ... AX8: =SUM(AX9:AX12) -> 39995012
A9: 3.1 | B9: Government Securities - Treasury Bills/bonds, | D9: 0 | E9: 0 | F9: 0 | G9: 0 | H9: 0 | I9: 0 | J9: 0 | K9: 0 | L9: 0 | M9: 0 | N9: 0 | P9: 0 | Q9: 0 | R9: 0 | S9: 0 | T9: 0 | U9: 0 | V9: 0 | W9: 0 | X9: 0 | Y9: 0 | Z9: 0 | AA9: 0 | AC9: 0 | AD9: 0 | AE9: 0 | AF9: 0 | AG9: 0 | AH9: 0 | AI9: 0 | AJ9: 0 | AK9: 0 | AL9: 0 | AM9: 0 | AN9: 0 | AP9: 0 | AQ9: 0 | AR9: 0 | AS9: 0 | AT9: 0 | AU9: 0 | AV9: 0 | AW9: 0 | AX9: 0
A10: 3.2 | B10: Other Securities - Commercial papers/Bonds | D10: 120305.43 | E10: 30208291 | F10: 30449722 | G10: 30683692 | H10: 30925308 | I10: 30925308 | J10: 31640172 | K10: 31874154 | L10: 31874154 | M10: 62508718 | N10: 62974716 | P10: 62974716 | Q10: 63866342 | R10: 64346271 | S10: 54764215 | T10: 55182994 | U10: 55182994 | V10: 45958048 | W10: 45958048 | X10: 41269987 | Y10: 41920114 | Z10: 42223996 | AA10: 32538096 | AC10: 0 | AD10: 0 | AE10: 0 | AF10: 0 | AG10: 0 | AH10: 0 | AI10: 0 | AJ10: 0 | AK10: 0 | AL10: 0 | AM10: 0 | AN10: 0 | AP10: 16400560 | AQ10: 16512417 | AR10: 10512417 | AS10: 10512417 | AT10: 10512417 | AU10: 10876744 | AV10: 10964464 | AW10: 11056508 | AX10: 11147990
A11: 3.3a | B11: Balances with other SACCO Societies | D11: 0 | E11: 0 | F11: 0 | G11: 0 | H11: 0 | I11: 0 | J11: 0 | K11: 0 | L11: 0 | M11: 0 | N11: 0 | O11: 20897023 | P11: 0 | Q11: 0 | R11: 0 | S11: 0 | T11: 0 | U11: 0 | V11: 0 | W11: 0 | X11: 0 | Y11: 0 | Z11: 0 | AA11: 0 | AC11: 24965219 | AD11: 25715219 | AE11: 27228726 | AF11: 27215219 | AG11: 27965218 | AH11: 28802022 | AI11: 29552021 | AJ11: 30393648 | AK11: 43736158 | AL11: 31695062 | AM11: 32445062 | AN11: 32895062 | AP11: 0 | AQ11: 0 | AR11: 0 | AS11: 0 | AT11: 0 | AU11: 0 | AV11: 0 | AW11: 0 | AX11: 0
A12: 3.3b | B12: Investments in companies - shares/stocks | D12: 20897022 | E12: 20897022 | F12: 20897022 | G12: 20897022 | H12: 20897022 | I12: 20897022 | J12: 20897022 | K12: 20897022 | L12: 20897022 | M12: 20897022 | N12: 20897022 | O12: 0 | P12: 20897022 | Q12: 20897022 | R12: 20897022 | S12: 20897022 | T12: 21097022 | U12: 26097022 | V12: 26097022 | W12: 26097022 | X12: 26097022 | Y12: 26097022 | Z12: 26097022 | AA12: 26097022 | AB12: =12939000+13158023 -> 26097023 | AC12: 14269632 | AD12: 14022273 | AE12: 14239055 | AF12: 14239055 | AG12: 14289055 | AH12: 14339055 | AI12: 14389055 | AJ12: 14439055 | AK12: 14489055 | AL12: 14539055 | AM12: 14589055 | AN12: 14589055 | AO12: =13208023 -> 13208023 | AP12: 26147022 | AQ12: 26147022 | AR12: 26147022 | AS12: 26147022 | AT12: 26347022 | AU12: 26347022 | AV12: 28847022 | AW12: 28847022 | AX12: 28847022
A13: 4 | B13: Net Loan Portfolio | C13: =C14-C15 -> 0 | D13: =D14-D15 -> 1.6636237e+08 | E13: =E14-E15 -> 1.6573191e+08 | F13: =F14-F15 -> 1.6324565e+08 | G13: =G14-G15 -> 1.5979864e+08 | H13: =H14-H15 -> 1.555884e+08 | I13: =I14-I15 -> 1.5199095e+08 | J13: =J14-J15 -> 1.496773e+08 | ... AX13: =AX14-AX15 -> 2.0154508e+08
A14: 4.1 | B14: Gross Loan Portfolio | D14: 1.899167e+08 | E14: 1.8928624e+08 | F14: 1.8679998e+08 | G14: 1.8335297e+08 | H14: 1.7914273e+08 | I14: 1.7554529e+08 | J14: 1.7323163e+08 | K14: 1.6814696e+08 | L14: 1.4193923e+08 | M14: 1.4301852e+08 | N14: 146599270 | O14: 146599270 | P14: 1.4863768e+08 | Q14: 1.4967038e+08 | R14: 1.5649244e+08 | S14: 1.5776077e+08 | T14: 1.6127869e+08 | U14: 1.6484118e+08 | V14: 1.6918035e+08 | W14: 1.7157169e+08 | X14: 1.7000486e+08 | Y14: 1.6239147e+08 | Z14: 1.6879596e+08 | AA14: 1.7498727e+08 | AB14: 1.7498727e+08 | AC14: 3.2860576e+08 | AD14: 3.3271653e+08 | AE14: 3.3472764e+08 | AF14: 3.3450016e+08 | AG14: 333608688 | AH14: 339341459 | AI14: 3.4252029e+08 | AJ14: 3.3804929e+08 | AK14: 336629735 | AL14: 3.5584925e+08 | AM14: 3.6077402e+08 | AN14: 3.6279644e+08 | AP14: 2.2132489e+08 | AQ14: 2.2398002e+08 | AR14: 233799329 | AS14: 2.33414e+08 | AT14: 2.3237601e+08 | AU14: 2.3095057e+08 | AV14: 2.2888864e+08 | AW14: 2.3077285e+08 | AX14: 2.2855718e+08
A15: 4.2 | B15: Allowance for Loan Loss | D15: 23554331 | E15: 23554331 | F15: 23554331 | G15: 23554331 | H15: 23554331 | I15: 23554331 | J15: 23554331 | K15: 23554331 | L15: 23554331 | M15: 23554331 | N15: 27016546 | O15: 27016546 | P15: 27016546 | Q15: 27016546 | R15: 27016546 | S15: 27016546 | T15: 27016546 | U15: 27016546 | V15: 27016546 | W15: 27016546 | X15: 27016546 | Y15: 27016546 | Z15: 27016546 | AA15: 26825887 | AB15: 26825887 | AC15: 36776544 | AD15: 36496592 | AE15: 37192544 | AF15: 37400544 | AG15: 37608544 | AH15: 37816544 | AI15: 38024544 | AJ15: 38232544 | AK15: 38440544 | AL15: 38648544 | AM15: 38856544 | AN15: 39068544 | AP15: 27012102 | AQ15: 27012102 | AR15: 27012102 | AS15: 27012102 | AT15: 27012102 | AU15: 27012102 | AV15: 27012102 | AW15: 27012102 | AX15: 27012102
A16: 5 | B16: Accounts Receivables | C16: =SUM(C17:C19) -> 0 | D16: =SUM(D17:D19) -> 0 | E16: =SUM(E17:E19) -> 0 | F16: =SUM(F17:F19) -> 0 | G16: =SUM(G17:G19) -> 0 | H16: =SUM(H17:H19) -> 0 | I16: =SUM(I17:I19) -> 0 | J16: =SUM(J17:J19) -> 0 | ... AX16: =SUM(AX17:AX19) -> 0
A17: 5.1 | B17: Tax Recoverable | C17: 0 | D17: 0 | E17: 0 | F17: 0 | G17: 0 | H17: 0 | I17: 0 | J17: 0 | K17: 0 | L17: 0 | M17: 0 | N17: 0 | O17: 834036 | P17: 0 | Q17: 0 | R17: 0 | S17: 0 | T17: 0 | U17: 0 | V17: 0 | W17: 0 | X17: 0 | Y17: 0 | Z17: 0 | AA17: 0 | AB17: 1622250 | AC17: 0 | AD17: 0 | AE17: 0 | AF17: 0 | AG17: 0 | AH17: 0 | AI17: 0 | AJ17: 0 | AK17: 0 | AL17: 0 | AM17: 0 | AN17: 0 | AO17: 18017874 | AP17: 0 | AQ17: 0 | AR17: 0 | AS17: 0 | AT17: 0 | AU17: 0 | AV17: 0 | AW17: 0 | AX17: 0
A18: 5.2 | B18: Deferred Tax Assets | C18: 0 | D18: 0 | E18: 0 | F18: 0 | G18: 0 | H18: 0 | I18: 0 | J18: 0 | K18: 0 | L18: 0 | M18: 0 | N18: 0 | P18: 0 | Q18: 0 | R18: 0 | S18: 0 | T18: 0 | U18: 0 | V18: 0 | W18: 0 | X18: 0 | Y18: 0 | Z18: 0 | AA18: 0 | AC18: 0 | AD18: 0 | AE18: 0 | AF18: 0 | AG18: 0 | AH18: 0 | AI18: 0 | AJ18: 0 | AK18: 0 | AL18: 0 | AM18: 0 | AN18: 0 | AP18: 0 | AQ18: 0 | AR18: 0 | AS18: 0 | AT18: 0 | AU18: 0 | AV18: 0 | AW18: 0 | AX18: 0
A19: 5.3 | B19: Retirement Benefit Assets | C19: 0 | D19: 0 | E19: 0 | F19: 0 | G19: 0 | H19: 0 | I19: 0 | J19: 0 | K19: 0 | L19: 0 | M19: 0 | N19: 0 | P19: 0 | Q19: 0 | R19: 0 | S19: 0 | T19: 0 | U19: 0 | V19: 0 | W19: 0 | X19: 0 | Y19: 0 | Z19: 0 | AA19: 0 | AC19: 0 | AD19: 0 | AE19: 0 | AF19: 0 | AG19: 0 | AH19: 0 | AI19: 0 | AJ19: 0 | AK19: 0 | AL19: 0 | AM19: 0 | AN19: 0 | AP19: 0 | AQ19: 0 | AR19: 0 | AS19: 0 | AT19: 0 | AU19: 0 | AV19: 0 | AW19: 0 | AX19: 0
A20: 6 | B20: Property & Equipment & Other assets | C20: =SUM(C21:C25) -> 0 | D20: =SUM(D21:D25) -> 70696432 | E20: =SUM(E21:E25) -> 70062684 | F20: =SUM(F21:F25) -> 69428936 | G20: =SUM(G21:G25) -> 68795188 | H20: =SUM(H21:H25) -> 68199895 | I20: =SUM(I21:I25) -> 67573122 | J20: =SUM(J21:J25) -> 67510417 | ... AX20: =SUM(AX21:AX25) -> 72641184
A21: 6.1 | B21: Investment Properties | D21: 0 | E21: 0 | F21: 0 | G21: 0 | H21: 0 | I21: 0 | J21: 0 | K21: 0 | L21: 0 | M21: 0 | N21: 0 | P21: 0 | Q21: 0 | R21: 0 | S21: 0 | T21: 0 | U21: 0 | V21: 0 | W21: 0 | X21: 0 | Y21: 0 | Z21: 0 | AA21: 0 | AC21: 0 | AD21: 0 | AE21: 0 | AF21: 0 | AG21: 0 | AH21: 0 | AI21: 0 | AJ21: 0 | AK21: 0 | AL21: 0 | AM21: 0 | AN21: 0 | AP21: 0 | AQ21: 0 | AR21: 0 | AS21: 0 | AT21: 0 | AU21: 0 | AV21: 0 | AW21: 0 | AX21: 0
A22: 6.2 | B22: Property & Equipment | D22: 60155672 | E22: 59700581 | F22: 59245490 | G22: 58790399 | H22: 58373763 | I22: 57925647 | J22: 57784189 | K22: 57323060 | L22: 56907656 | M22: 56445751 | N22: 55983847 | O22: 55983847 | P22: 55593701 | Q22: 55203555 | R22: 55010723 | S22: 54836233 | T22: 54609861 | U22: 54369089 | V22: 53970291 | W22: 53684203 | X22: 56389732 | Y22: 55953145 | Z22: 55516559 | AA22: 55079972 | AB22: 55079972 | AC22: 6977431.8 | AD22: 6879106.5 | AE22: 6565342.2 | AF22: 6467016.7 | AG22: 6368691 | AH22: 6270366 | AI22: 6172040.2 | AJ22: 6106214.7 | AK22: 6117277 | AL22: 7114777.7 | AM22: 6315749.7 | AN22: 6465276.7 | AO22: 53236684 | AP22: 52874530 | AQ22: 52683377 | AR22: 52319444 | AS22: 51955510 | AT22: 51591577 | AU22: 51227643 | AV22: 56363710 | AW22: 55988318 | AX22: 57169298
A23: 6.3 | B23: Prepaid Lease rentals | D23: 0 | E23: 0 | F23: 0 | G23: 0 | H23: 0 | I23: 0 | J23: 0 | K23: 0 | L23: 0 | M23: 0 | N23: 0 | P23: 0 | Q23: 0 | R23: 0 | S23: 0 | T23: 0 | U23: 0 | V23: 0 | W23: 0 | X23: 0 | Y23: 0 | Z23: 0 | AA23: 0 | AC23: 0 | AD23: 0 | AE23: 0 | AF23: 0 | AG23: 0 | AH23: 0 | AI23: 0 | AJ23: 0 | AK23: 0 | AL23: 0 | AM23: 0 | AN23: 0 | AP23: 0 | AQ23: 0 | AR23: 0 | AS23: 0 | AT23: 0 | AU23: 0 | AV23: 0 | AW23: 0 | AX23: 0
A24: 6.4 | B24: Intangible Assets | D24: 10540760 | E24: 10362103 | F24: 10183446 | G24: 10004789 | H24: 9826132.1 | I24: 9647475.1 | J24: 9726228.3 | K24: 9540180.3 | L24: 10042466 | M24: 9844751.2 | N24: 9647036.6 | O24: 9647036.6 | P24: 9486252.7 | Q24: 11044589 | R24: 10855153 | S24: 10665717 | T24: 10476281 | U24: 10286845 | V24: 10097409 | W24: 9907973.2 | X24: 9718537.3 | Y24: 9529101.4 | Z24: 9339665.5 | AA24: 9150229.5 | AB24: 9150229.5 | AC24: 915280.2 | AD24: 899767 | AE24: 812280 | AF24: 796767 | AG24: 781254 | AH24: 765741 | AI24: 750228 | AJ24: 734715 | AK24: 719202 | AL24: 703689 | AM24: 688176 | AN24: 672663 | AP24: 7312589.3 | AQ24: 7188647.1 | AR24: 7064704.9 | AS24: 6940762.7 | AT24: 6816820.6 | AU24: 6692878.4 | AV24: 15918936 | AW24: 15751661 | AX24: 15471885
A25: 6.5 | B25: Other Assets | D25: 0 | E25: 0 | F25: 0 | G25: 0 | H25: 0 | I25: 0 | J25: 0 | K25: 0 | L25: 0 | M25: 0 | N25: 0 | P25: 0 | Q25: 0 | R25: 0 | S25: 0 | T25: 0 | U25: 0 | V25: 0 | W25: 0 | X25: 0 | Y25: 0 | Z25: 0 | AA25: 0 | AC25: 0 | AD25: 0 | AE25: 0 | AF25: 0 | AG25: 0 | AH25: 0 | AI25: 473500 | AJ25: 470900 | AK25: 335700 | AL25: 91300 | AM25: 90000 | AN25: 74400 | AP25: 0 | AQ25: 0 | AR25: 0 | AS25: 0 | AT25: 0 | AU25: 0 | AV25: 0 | AW25: 0 | AX25: 0
B26: Total Assets | C26: =C4+C7+C8+C13+C16+C20 -> 0 | D26: =D4+D7+D8+D13+D16+D20 -> 4.175917e+08 | E26: =E4+E7+E8+E13+E16+E20 -> 4.1741436e+08 | F26: =F4+F7+F8+F13+F16+F20 -> 4.04244e+08 | G26: =G4+G7+G8+G13+G16+G20 -> 4.1418073e+08 | H26: =H4+H7+H8+H13+H16+H20 -> 4.1401975e+08 | I26: =I4+I7+I8+I13+I16+I20 -> 4.1433757e+08 | J26: =J4+J7+J8+J13+J16+J20 -> 4.0551207e+08 | ... AX26: =AX4+AX7+AX8+AX13+AX16+AX20 -> 4.2188532e+08
A27: 7 | B27: Savings Deposits - Withdrawable deposits - FOSA) | D27: 59630574 | E27: 58215786 | F27: 49872824 | G27: 55465019 | H27: 53901544 | I27: 55761279 | J27: 50262044 | K27: 55289578 | L27: 1.2256892e+08 | M27: 66576679 | N27: 59169383 | O27: 59169383 | P27: 60234820 | Q27: 67496602 | R27: 53350486 | S27: 63129250 | T27: 50746612 | U27: 52127298 | V27: 59765850 | W27: 54341051 | X27: 50600951 | Y27: 1.2154513e+08 | Z27: 64046009 | AA27: 51498067 | AB27: 51498067 | AC27: 4796073.6 | AD27: 12045479 | AE27: 11884977 | AF27: 14850075 | AG27: 8255800 | AH27: 18089489 | AI27: 10059813 | AJ27: 15845535 | AK27: 9427938 | AL27: 12242543 | AM27: 12450431 | AN27: 5374149.7 | AO27: 55901331 | AP27: 58281030 | AQ27: 65788964 | AR27: 55613517 | AS27: 59602931 | AT27: 56839922 | AU27: 58477195 | AV27: 63167258 | AW27: 62771252 | AX27: 64411687
A28: 8 | B28: Short Term Deposits (e.g Fixed deposits, special savings) | D28: 20345999 | E28: 21480875 | F28: 21124180 | G28: 18516430 | H28: 20682592 | I28: 20527834 | J28: 21739978 | K28: 21752978 | L28: 19608178 | M28: 18407035 | N28: 16835433 | O28: 16835433 | P28: 18842815 | Q28: 16998236 | R28: 16918837 | S28: 17650467 | T28: 17978511 | U28: 17090559 | V28: 19883252 | W28: 21390002 | X28: 22409160 | Y28: 21580907 | Z28: 21672292 | AA28: 21063922 | AB28: 21063922 | AC28: 21328690 | AD28: 21290325 | AE28: 20547398 | AF28: 15715130 | AG28: 22545221 | AH28: 19886971 | AI28: 21043065 | AJ28: 21028004 | AK28: 24723621 | AL28: 21281583 | AM28: 18662705 | AN28: 25266564 | AO28: 24478057 | AP28: 24061299 | AQ28: 21850756 | AR28: 23473844 | AS28: 25191893 | AT28: 24724234 | AU28: 24991462 | AV28: 24330053 | AW28: 25088039 | AX28: 24470524
A29: 9 | B29: Non withdrawable deposits (BOSA member deposits) | D29: 1.0043538e+08 | E29: 1.0029842e+08 | F29: 1.0038082e+08 | G29: 1.0049819e+08 | H29: 1.006155e+08 | I29: 1.0080875e+08 | J29: 1.01328e+08 | K29: 99983310 | L29: 1.0268213e+08 | M29: 1.0288812e+08 | N29: 1.0265731e+08 | O29: 1.0265731e+08 | P29: 1.0299956e+08 | Q29: 1.0350885e+08 | R29: 1.0407527e+08 | S29: 1.0505504e+08 | T29: 1.0540879e+08 | U29: 1.0310879e+08 | V29: 1.0414058e+08 | W29: 1.0478012e+08 | X29: 1.0515283e+08 | Y29: 1.06869e+08 | Z29: 1.0710239e+08 | AA29: 1.0848913e+08 | AB29: 1.0848913e+08 | AC29: 2.6078025e+08 | AD29: 2.5757478e+08 | AE29: 2.609283e+08 | AF29: 2.6100768e+08 | AG29: 259991196 | AH29: 261577229 | AI29: 2.6338975e+08 | AJ29: 2.6427556e+08 | AK29: 262780561 | AL29: 2.6810572e+08 | AM29: 2.7094573e+08 | AN29: 2.7164143e+08 | AO29: =142125456-AO28 -> 117647399 | AP29: 1.1833177e+08 | AQ29: 1.188886e+08 | AR29: 1.1894144e+08 | AS29: 1.1890265e+08 | AT29: 1.1919162e+08 | AU29: 1.1969628e+08 | AV29: 120265003 | AW29: 1.2080597e+08 | AX29: 1.2081867e+08
B30: Total Deposit liabilities | C30: =SUM(C27:C29) -> 0 | D30: =SUM(D27:D29) -> 1.8041195e+08 | E30: =SUM(E27:E29) -> 1.7999508e+08 | F30: =SUM(F27:F29) -> 1.7137783e+08 | G30: =SUM(G27:G29) -> 1.7447964e+08 | H30: =SUM(H27:H29) -> 1.7519963e+08 | I30: =SUM(I27:I29) -> 1.7709787e+08 | J30: =SUM(J27:J29) -> 1.7333002e+08 | ... AX30: =SUM(AX27:AX29) -> 2.0970088e+08
A31: 10 | B31: Accounts Payable & Other Liabilities | C31: =SUM(C32:C37) -> 0 | D31: =SUM(D32:D37) -> 66860976 | E31: =SUM(E32:E37) -> 67260169 | F31: =SUM(F32:F37) -> 69784792 | G31: =SUM(G32:G37) -> 67455040 | H31: =SUM(H32:H37) -> 66708258 | I31: =SUM(I32:I37) -> 65393209 | J31: =SUM(J32:J37) -> 62636745 | ... AX31: =SUM(AX32:AX37) -> 9551126.5
A32: 10.1 | B32: Tax Payable | D32: -3701796 | E32: -4151238.5 | F32: -7424.39 | G32: -1238840.4 | H32: -1241645.1 | I32: -1019087.5 | J32: -2408623.8 | K32: -2440459.6 | L32: -2950682.5 | M32: -3956976.2 | N32: -5041092.5 | P32: -5044593.4 | Q32: -5035516.6 | R32: -5044384.9 | S32: -6221489.7 | T32: -2013231.1 | U32: -2718192.6 | V32: -2292509.5 | W32: -3187583.8 | X32: -4758929.9 | Y32: -6397614 | Z32: -6336912.2 | AA32: -6300581.2 | AC32: 131097 | AD32: 760479.11 | AE32: 131097 | AF32: 0 | AG32: 2162355 | AH32: -252783 | AI32: 0 | AJ32: 0 | AK32: -566566 | AL32: 0 | AM32: 0 | AN32: 47679.85 | AP32: -6721891.1 | AQ32: -1457581.3 | AR32: -742096.15 | AS32: -1451423 | AT32: -951671.07 | AU32: -4526858.3 | AV32: -4526566.3 | AW32: -4518108.6 | AX32: -5968797.9
A33: 10.2 | B33: Dividends Payable | D33: 0 | E33: 0 | F33: 40256.79 | G33: 39362.9 | H33: 39362.9 | I33: 39362.9 | J33: 39362.9 | K33: 39362.9 | L33: 39362.9 | M33: 39362.9 | N33: 39362.9 | P33: 39362.9 | Q33: 39362.9 | R33: 39362.9 | S33: 39362.9 | T33: 39362.9 | U33: 39362.9 | V33: 39362.9 | W33: 39362.9 | X33: 39362.9 | Y33: 39362.9 | Z33: 39362.9 | AA33: 39362.9 | AB33: 5325175 | AC33: 0 | AD33: 0 | AE33: 17548031 | AF33: 0 | AG33: 0 | AH33: 0 | AI33: 0 | AJ33: 0 | AK33: 0 | AL33: 0 | AM33: 0 | AN33: 0 | AP33: -102260.77 | AQ33: 5930312.3 | AR33: 0 | AS33: 0 | AT33: 0 | AU33: 0 | AV33: 0 | AW33: 0 | AX33: 0
A34: 10.3 | B34: Deferred Tax Liability | D34: 0 | E34: 0 | F34: 0 | G34: 0 | H34: 0 | I34: 0 | J34: 0 | K34: 0 | L34: 0 | M34: 0 | N34: 0 | P34: 0 | Q34: 0 | R34: 0 | S34: 0 | T34: 0 | U34: 0 | V34: 0 | W34: 0 | X34: 0 | Y34: 0 | Z34: 0 | AA34: 0 | AC34: 0 | AD34: 0 | AE34: 0 | AF34: 0 | AG34: 0 | AH34: 0 | AI34: 0 | AJ34: 0 | AK34: 0 | AL34: 0 | AM34: 0 | AN34: 0 | AP34: 0 | AQ34: 0 | AR34: 0 | AS34: 0 | AT34: 0 | AU34: 0 | AV34: 0 | AW34: 0 | AX34: 0
A35: 10.4 | B35: Retirement Benefits Liability | D35: 0 | E35: 0 | F35: 0 | G35: 0 | H35: 0 | I35: 0 | J35: 0 | K35: 0 | L35: 0 | M35: 0 | N35: 0 | P35: 0 | Q35: 0 | R35: 0 | S35: 0 | T35: 0 | U35: 0 | V35: 0 | W35: 0 | X35: 0 | Y35: 0 | Z35: 0 | AA35: 0 | AC35: 0 | AD35: 0 | AE35: 0 | AF35: 0 | AG35: 0 | AH35: 0 | AI35: 0 | AJ35: 0 | AK35: 0 | AL35: 0 | AM35: 0 | AN35: 0 | AO35: 3147642 | AP35: 0 | AQ35: 0 | AR35: 0 | AS35: 0 | AT35: 0 | AU35: 0 | AV35: 0 | AW35: 0 | AX35: 0
A36: 10.5 | B36: Other Liabilities | D36: 8562771.5 | E36: 9411407.4 | F36: 9131029.9 | G36: 8734347.9 | H36: 8698720.3 | I36: 7877133.5 | J36: 7965606.1 | K36: -5778839.5 | L36: 4333603.8 | M36: 1682250.1 | N36: 1857339 | O36: =3127425+91512 -> 3218937 | P36: 3485297.1 | Q36: 3422797.5 | R36: 2204654.3 | S36: 3127562.2 | T36: -4031773.8 | U36: 1348358.5 | V36: -1049250.4 | W36: 858724.36 | X36: -656055.33 | Y36: 4763274.8 | Z36: 2730222.7 | AA36: 2923968.3 | AB36: =291512+574930 -> 866442 | AC36: 13962061 | AD36: 13854757 | AE36: 0 | AF36: 2816618 | AG36: 2770935 | AH36: 2957269 | AI36: 613705.71 | AJ36: 1709997.5 | AK36: 2792038 | AL36: 2692075.5 | AM36: 2517146.8 | AN36: 20740274 | AP36: 6218746.9 | AQ36: 5722796.4 | AR36: 4369919.4 | AS36: 2606122.1 | AT36: -83905.49 | AU36: 1495369.4 | AV36: 7535122.7 | AW36: 6506302.7 | AX36: 7523580.8
A37: 10.6 | B37: External Borrowings | D37: 62000000 | E37: 62000000 | F37: 60620930 | G37: 59920170 | H37: 59211820 | I37: 58495800 | J37: 57040400 | K37: 56300850 | L37: 47553290 | M37: 46797630 | N37: 46033780 | O37: 46033780 | P37: 45261660 | Q37: 44481180 | R37: 43692240 | S37: 42894750 | T37: 42088620 | U37: 41273760 | V37: 40450070 | W37: 39617460 | X37: 38775830 | Y37: 29925080 | Z37: 29065120 | AA37: 27721622 | AB37: 27721622 | AC37: 23610305 | AD37: 22026971 | AE37: 20443637 | AF37: 18860303 | AG37: 17276969 | AH37: 15693653 | AI37: 14804764 | AJ37: 13073862 | AK37: 12006949 | AL37: 10541383 | AM37: 9474473 | AN37: 8407563 | AO37: 8522056 | AP37: 7996343.6 | AQ37: 7996343.6 | AR37: 7996343.6 | AS37: 7996343.6 | AT37: 7996343.6 | AU37: 7996343.6 | AV37: 7996343.6 | AW37: 7996343.6 | AX37: 7996343.6
B38: Total Liabilities | C38: =C30+C31 -> 0 | D38: =D30+D31 -> 2.4727293e+08 | E38: =E30+E31 -> 2.4725525e+08 | F38: =F30+F31 -> 2.4116262e+08 | G38: =G30+G31 -> 2.4193468e+08 | H38: =H30+H31 -> 2.4190789e+08 | I38: =I30+I31 -> 2.4249107e+08 | J38: =J30+J31 -> 2.3596677e+08 | ... AX38: =AX30+AX31 -> 2.1925201e+08
A39: 11 | B39: Share Capital (Members share capital per Bylaws) | D39: 1.1408588e+08 | E39: 1.1421876e+08 | F39: 1.1492446e+08 | G39: 1.1595726e+08 | H39: 1.1693326e+08 | I39: 1.1757238e+08 | J39: 1.181094e+08 | K39: 1.1835345e+08 | L39: 1.1838784e+08 | M39: 1.1859882e+08 | N39: 1.1884448e+08 | O39: =100653830+18194250 -> 118848080 | P39: 1.1907784e+08 | Q39: 1.1934067e+08 | R39: 1.1973107e+08 | S39: 1.2015809e+08 | T39: 1.2047042e+08 | U39: 1.2327235e+08 | V39: 1.2358524e+08 | W39: 1.238573e+08 | X39: 1.2407201e+08 | Y39: 1.2430739e+08 | Z39: 1.2460593e+08 | AA39: 1.2512205e+08 | AB39: =106930847+18191203 -> 125122050 | AC39: 63616039 | AD39: 64821977 | AE39: 65855397 | AF39: 66988398 | AG39: 68073149 | AH39: 69154603 | AI39: 70271602 | AJ39: 71243914 | AK39: 72393800 | AL39: 71895602 | AM39: 68582360 | AN39: 67256355 | AO39: 134853474 | AP39: 1.3538791e+08 | AQ39: 1.3596371e+08 | AR39: 1.346342e+08 | AS39: 1.3706991e+08 | AT39: 1.3765543e+08 | AU39: 1.383996e+08 | AV39: 1.3894189e+08 | AW39: 1.3957131e+08 | AX39: 1.4006871e+08
A40: 12 | B40: Capital Grants | D40: 0 | E40: 0 | F40: 0 | G40: 0 | H40: 0 | I40: 0 | J40: 0 | K40: 0 | L40: 0 | M40: 0 | N40: 0 | P40: 0 | Q40: 0 | R40: 0 | S40: 0 | T40: 0 | U40: 0 | V40: 0 | W40: 0 | X40: 0 | Y40: 0 | Z40: 0 | AA40: 0 | AC40: 0 | AD40: 0 | AE40: 0 | AF40: 0 | AG40: 0 | AH40: 0 | AI40: 0 | AJ40: 0 | AK40: 0 | AL40: 0 | AM40: 0 | AN40: 0 | AP40: 0 | AQ40: 0 | AR40: 0 | AS40: 0 | AT40: 0 | AU40: 0 | AV40: 0 | AW40: 0 | AX40: 0
...

Sheet Income Statement
A1: FORM 7 SASRA/007
A2: STATEMENT OF COMPREHENSIVE INCOME
A3: FINANCIAL YEAR 2020 | D3: 44216 | E3: 44247 | F3: 44275 | G3: 44306 | H3: 44336 | I3: 44367 | J3: 44428 | K3: 44459 | L3: 44489 | M3: 44520 | N3: 44550 | O3: Aud-20 | P3: 44197 | Q3: 44229 | R3: 44258 | S3: 44290 | T3: 44321 | U3: 44353 | V3: 44384 | W3: 44416 | X3: 44448 | Y3: 44479 | Z3: 44511 | AA3: 44542 | AB3: Audited 2021 | AC3: 44562 | AD3: 44593 | AE3: 44621 | AF3: 44652 | AG3: 44682 | AH3: 44713 | AI3: 44743 | AJ3: 44774 | AK3: 44805 | AL3: 44835 | AM3: 44866 | AN3: 44896 | AO3: AUDITED 2022 | AP3: 44927 | AQ3: 44958 | AR3: 44986 | AS3: 45017 | AT3: 45047 | AU3: 45078 | AV3: 45108 | AW3: 45139 | AX3: 45170
A4: 1 | B4: Financial Income | C4: =C5+C8 -> 0 | D4: =D5+D8 -> 6946463.7 | E4: =E5+E8 -> 14316592 | F4: =F5+F8 -> 22150806 | G4: =G5+G8 -> 36822712 | H4: =H5+H8 -> 42641103 | I4: =I5+I8 -> 48381577 | J4: =J5+J8 -> 60431757 | ... AX4: =AX5+AX8 -> 74683234
A5: 2 | B5: Financial Income from Loans Portfolio | D5: 4536098.5 | E5: 6207544 | F5: 8367483.5 | G5: 9162697.5 | H5: 10103613 | I5: 11515870 | J5: 14253400 | K5: 16122607 | L5: 18709552 | M5: 20723323 | N5: 23173762 | O5: 28723281 | P5: =SUM(P6:P7) -> 2418946.7 | Q5: =SUM(Q6:Q7) -> 4463160.7 | R5: =SUM(R6:R7) -> 7526031.8 | S5: =SUM(S6:S7) -> 9380059.7 | T5: =SUM(T6:T7) -> 12392584 | U5: =SUM(U6:U7) -> 14279704 | V5: =SUM(V6:V7) -> 17445543 | W5: =SUM(W6:W7) -> 20248364 | ... AX5: =SUM(AX6:AX7) -> 26140637
A6: 2.1 | B6: Interest on Loan Portfolio | D6: 3434593.2 | E6: 4547619.2 | F6: 6319984.7 | G6: 6933096.7 | H6: 7701931.2 | I6: 8847278.2 | J6: 11007267 | K6: 12475504 | L6: 14871343 | M6: 16632500 | N6: 18723281 | P6: 2114530.2 | Q6: 3780943.2 | R6: 6564890.3 | S6: 8076078.2 | T6: 10743485 | U6: 12393265 | V6: 15183382 | W6: 17706598 | X6: 19421846 | Y6: 21159667 | Z6: 24631411 | AA6: 35075458 | AB6: 35075458 | AC6: 2114530.2 | AD6: 3780943.2 | AE6: 6564890.3 | AF6: 8076078.2 | AG6: 10743485 | AH6: 12393265 | AI6: 15183382 | AJ6: 17706598 | AK6: 19421846 | AL6: 21159667 | AM6: 24631411 | AN6: 35075458 | AO6: 33277753 | AP6: 3141524 | AQ6: 5855497 | AR6: 11648958 | AS6: 12343589 | AT6: 14546817 | AU6: 17096683 | AV6: 19501383 | AW6: 21399955 | AX6: 23300522
A7: 2.2 | B7: Fees & Commission on Loan Portfolio | D7: 1101505.3 | E7: 1659924.8 | F7: 2047498.8 | G7: 2229600.8 | H7: 2401681.9 | I7: 2668591.4 | J7: 3246132.4 | K7: 3647102.4 | L7: 3838208.9 | M7: 4090822.9 | N7: 4450480.9 | P7: 304416.5 | Q7: 682217.5 | R7: 961141.5 | S7: 1303981.5 | T7: 1649099 | U7: 1886439.5 | V7: 2262161 | W7: 2541766 | X7: 2747386.5 | Y7: 2998456.5 | Z7: 3343108.5 | AA7: 3751711 | AC7: 304416.5 | AD7: 682217.5 | AE7: 961141.5 | AF7: 1303981.5 | AG7: 1649099 | AH7: 1886439.5 | AI7: 2262161 | AJ7: 2541766 | AK7: 2747386.5 | AL7: 2998456.5 | AM7: 3343108.5 | AN7: 3751711 | AP7: 620248 | AQ7: 982057.3 | AR7: 0 | AS7: 1467758.4 | AT7: 1762651.4 | AU7: 2082188.3 | AV7: 2306400.1 | AW7: 2600368.8 | AX7: 2840115.3
A8: 3 | B8: Financial Income from Investments in: | C8: =C9+C10+C11+C12 -> 0 | D8: =D9+D10+D11+D12 -> 2410365.2 | E8: =E9+E10+E11+E12 -> 8109048.2 | F8: =F9+F10+F11+F12 -> 13783323 | G8: =G9+G10+G11+G12 -> 27660014 | H8: =H9+H10+H11+H12 -> 32537490 | I8: =I9+I10+I11+I12 -> 36865707 | J8: =J9+J10+J11+J12 -> 46178357 | ... AX8: =AX9+AX10+AX11+AX12 -> 48542597
A9: 3.1 | B9: Government Securities | D9: 0 | E9: 0 | F9: 0 | G9: 0 | H9: 0 | I9: 0 | J9: 0 | K9: 0 | L9: 0 | M9: 0 | N9: 0 | P9: 0 | Q9: 0 | R9: 0 | S9: 0 | T9: 0 | U9: 0 | V9: 0 | W9: 0 | X9: 0 | Y9: 0 | Z9: 0 | AA9: 0 | AC9: 0 | AD9: 0 | AE9: 0 | AF9: 0 | AG9: 0 | AH9: 0 | AI9: 0 | AJ9: 0 | AK9: 0 | AL9: 0 | AM9: 0 | AN9: 0 | AP9: 0 | AQ9: 0 | AR9: 0 | AS9: 0 | AT9: 0 | AU9: 0 | AV9: 0 | AW9: 0 | AX9: 0
A10: 3.2 | B10: Deposit with Banks and Other Financial Inst. | D10: 0 | E10: 87985.24 | F10: 329417.02 | G10: 563386.26 | H10: 805002.85 | I10: 805002.85 | J10: 1519866.6 | K10: 1753848.5 | L10: 1753848.5 | M10: 2388412.1 | N10: 2854410.7 | O10: 2854410.7 | P10: 0 | Q10: 891626.04 | R10: 1371555.4 | S10: 1789498.7 | T10: 2208277.6 | U10: 2208277.6 | V10: 2983331.6 | W10: 2983331.6 | X10: 3295271.4 | Y10: 3945398 | Z10: 4249280 | AA10: 4563380.3 | AB10: 4563380 | AC10: 0 | AD10: 891626.04 | AE10: 1371555.4 | AF10: 1789498.7 | AG10: 2208277.6 | AH10: 2208277.6 | AI10: 2983331.6 | AJ10: 2983331.6 | AK10: 3295271.4 | AL10: 3945398 | AM10: 4249280 | AN10: 4563380.3 | AO10: =3733144 -> 3733144 | AP10: 129319.48 | AQ10: 241177.36 | AR10: 241177.36 | AS10: 241177.36 | AT10: 241177.36 | AU10: 605503.51 | AV10: 693223.92 | AW10: 785268.34 | AX10: 876749.59
A11: 3.3 | B11: Other Investments - dividend & Interest incomes from investments | D11: 0 | E11: 0 | F11: 0 | G11: 9433834.7 | H11: 9433834.7 | I11: 9433834.7 | J11: 9433834.7 | K11: 9433834.7 | L11: 9433834.7 | M11: 9781019.7 | N11: 9781019.7 | P11: 0 | Q11: 0 | R11: 0 | S11: 9284889.6 | T11: 9284889.6 | U11: 9284889.6 | V11: 9284889.6 | W11: 9284889.6 | X11: 9284889.6 | Y11: 9284889.6 | Z11: 9284889.6 | AA11: 9548750.6 | AC11: 0 | AD11: 0 | AE11: 0 | AF11: 9284889.6 | AG11: 9284889.6 | AH11: 9284889.6 | AI11: 9284889.6 | AJ11: 9284889.6 | AK11: 9284889.6 | AL11: 9284889.6 | AM11: 9284889.6 | AN11: 9548750.6 | AP11: 0 | AQ11: 0 | AR11: 9244687 | AS11: 0 | AT11: 504018.05 | AU11: 13914340 | AV11: 13914340 | AW11: 13914340 | AX11: 13914340
A12: 3.4 | B12: Other Operating Income- Salary processing fees, transaction fees, membership fees | D12: 2410365.2 | E12: 8021062.9 | F12: 13453906 | G12: 17662793 | H12: 22298653 | I12: 26626870 | J12: 35224656 | K12: 39145256 | L12: 62523166 | M12: 68058393 | N12: 73376564 | O12: 77746050 | P12: 3665618.5 | Q12: 7449728.3 | R12: 11178565 | S12: 17089225 | T12: 20518252 | U12: 24346902 | V12: 27502614 | W12: 30964829 | X12: 34837579 | Y12: 47799518 | Z12: 51309883 | AA12: 55583097 | AB12: =68883561+190658 -> 69074219 | AC12: 3665618.5 | AD12: 7449728.3 | AE12: 11178565 | AF12: 17089225 | AG12: 20518252 | AH12: 24346902 | AI12: 27502614 | AJ12: 30964829 | AK12: 34837579 | AL12: 47799518 | AM12: 51309883 | AN12: 55583097 | AO12: =81065833 -> 81065833 | AP12: 3174143.2 | AQ12: 7336840 | AR12: 10205922 | AS12: 14509864 | AT12: 18570957 | AU12: 23061425 | AV12: 26715492 | AW12: 30126163 | AX12: 33751508
A13: 4 | B13: Financial Expense | C13: =C14+C15+C16+C17+C18+C19 -> 0 | D13: =D14+D15+D16+D17+D18+D19 -> 637662.03 | E13: =E14+E15+E16+E17+E18+E19 -> 1172662.2 | F13: =F14+F15+F16+F17+F18+F19 -> 2311382.4 | G13: =G14+G15+G16+G17+G18+G19 -> 3198685.4 | H13: =H14+H15+H16+H17+H18+H19 -> 3936982.5 | I13: =I14+I15+I16+I17+I18+I19 -> 4851738.9 | J13: =J14+J15+J16+J17+J18+J19 -> 6610216 | ... AX13: =AX14+AX15+AX16+AX17+AX18+AX19 -> 4049773.4
A14: 4.2 | B14: Interest Expense on Deposits | D14: 165958 | E14: 263501 | F14: 371471 | G14: 494306 | H14: 540204 | I14: 743308.3 | J14: 1010942.3 | K14: 1078087.3 | L14: 1168495.3 | M14: 1296990.3 | N14: 1575034.6 | O14: 1575034.6 | P14: 166887.2 | Q14: 269079.4 | R14: 373124.4 | S14: 460552.4 | T14: 506596.4 | U14: 659313 | V14: 792119.8 | W14: 982294.8 | X14: 1083273.8 | Y14: 1173399.8 | Z14: 1370658.4 | AA14: 1542549 | AB14: =10732109-4933693 -> 5798416 | AC14: 166887.2 | AD14: 269079.4 | AE14: 373124.4 | AF14: 460552.4 | AG14: 506596.4 | AH14: 659313 | AI14: 792119.8 | AJ14: 982294.8 | AK14: 1083273.8 | AL14: 1173399.8 | AM14: 1370658.4 | AN14: 1542549 | AO14: 9965297 | AP14: 294397 | AQ14: 499451 | AR14: 652985 | AS14: 731995 | AT14: 776580 | AU14: 952508 | AV14: 1189159 | AW14: 1394874 | AX14: 1582992
A15: 4.3 | B15: Cost of External Borrowings | D15: 339726.03 | E15: 668493.16 | F15: 1628871.4 | G15: 2278657.4 | H15: 2909894.5 | I15: 3544410.6 | J15: 4779143.7 | K15: 5390139.8 | L15: 5982166.9 | M15: 6494861.2 | N15: 6988406.5 | O15: 6988406.5 | P15: 493494.53 | Q15: 970409.88 | R15: 1422426.9 | S15: 1890551.4 | T15: 2341816.8 | U15: 2792571.3 | V15: 3226276.6 | W15: 3659281.2 | X15: 4075046.5 | Y15: 4481691.9 | Z15: 4807894.3 | AA15: 4933692.5 | AB15: 4933692.5 | AC15: 493494.53 | AD15: 970409.88 | AE15: 1422426.9 | AF15: 1890551.4 | AG15: 2341816.8 | AH15: 2792571.3 | AI15: 3226276.6 | AJ15: 3659281.2 | AK15: 4075046.5 | AL15: 4481691.9 | AM15: 4807894.3 | AN15: 4933692.5 | AP15: 84931.51 | AQ15: 169863.02 | AR15: 246575.35 | AS15: 331506.86 | AT15: 413698.65 | AU15: 498630.16 | AV15: 580821.94 | AW15: 665753.45 | AX15: 750684.95
A16: 4.4 | B16: Dividend Expenses (on member shares) | D16: 0 | E16: 0 | F16: 0 | G16: 0 | H16: 0 | I16: 0 | J16: 0 | K16: 0 | L16: 0 | M16: 0 | N16: 0 | P16: 0 | Q16: 0 | R16: 0 | S16: 0 | T16: 0 | U16: 0 | V16: 0 | W16: 0 | X16: 0 | Y16: 0 | Z16: 0 | AA16: 0 | AC16: 0 | AD16: 0 | AE16: 0 | AF16: 0 | AG16: 0 | AH16: 0 | AI16: 0 | AJ16: 0 | AK16: 0 | AL16: 0 | AM16: 0 | AN16: 0 | AP16: 0 | AQ16: 0 | AR16: 0 | AS16: 0 | AT16: 0 | AU16: 0 | AV16: 0 | AW16: 0 | AX16: 0
A17: 4.5 | B17: Other Financial Expense | D17: 76700 | E17: 147968 | F17: 214340 | G17: 269522 | H17: 328884 | I17: 405720 | J17: 562230 | K17: 619106 | L17: 770640.5 | M17: 842796.5 | N17: 925129.5 | O17: 11525011 | P17: 48330 | Q17: 96660 | R17: 148372 | S17: 232800 | T17: 302802 | U17: 367564 | V17: 428912 | W17: 428912 | X17: 0 | Y17: 549190 | Z17: 624034 | AA17: 755654.71 | AC17: 48330 | AD17: 96660 | AE17: 148372 | AF17: 232800 | AG17: 302802 | AH17: 367564 | AI17: 428912 | AJ17: 428912 | AK17: 0 | AL17: 549190 | AM17: 624034 | AN17: 755654.71 | AP17: 75378.05 | AQ17: 174990.1 | AR17: 252964.74 | AS17: 319747.74 | AT17: 418036.44 | AU17: 523114.94 | AV17: 605927.94 | AW17: 645650.94 | AX17: 709541.69
A18: 4.6 | B18: Fees & Commission Expense | D18: 0 | E18: 0 | F18: 0 | G18: 0 | H18: 0 | I18: 0 | J18: 0 | K18: 0 | L18: 0 | M18: 0 | N18: 0 | P18: 0 | Q18: 0 | R18: 0 | S18: 0 | T18: 0 | U18: 0 | V18: 0 | W18: 0 | X18: 483766 | Y18: 0 | Z18: 0 | AA18: 0 | AC18: 0 | AD18: 0 | AE18: 0 | AF18: 0 | AG18: 0 | AH18: 0 | AI18: 0 | AJ18: 0 | AK18: 483766 | AL18: 0 | AM18: 0 | AN18: 0 | AP18: 0 | AQ18: 0 | AR18: 0 | AS18: 0 | AT18: 0 | AU18: 0 | AV18: 0 | AW18: 0 | AX18: 0
A19: 4.7 | B19: Other Expense | D19: 55278 | E19: 92700 | F19: 96700 | G19: 156200 | H19: 158000 | I19: 158300 | J19: 257900 | K19: 307500 | L19: 11882552 | M19: 11913147 | N19: 11940927 | P19: 0 | Q19: 8000 | R19: 109900 | S19: 115700 | T19: 128180 | U19: 135680 | V19: 153080 | W19: 176520 | X19: 231270 | Y19: 7755711.7 | Z19: 7788211.7 | AA19: 8949787.4 | AB19: =4249021+3267421+1179323-228947 -> 8466818 | AC19: 0 | AD19: 8000 | AE19: 109900 | AF19: 115700 | AG19: 128180 | AH19: 135680 | AI19: 153080 | AJ19: 176520 | AK19: 231270 | AL19: 7755711.7 | AM19: 7788211.7 | AN19: 8949787.4 | AP19: 111304.8 | AQ19: 226683.8 | AR19: 372654.8 | AS19: 568654.8 | AT19: 1235244.4 | AU19: 1374744.4 | AV19: 867554.8 | AW19: 886884.8 | AX19: 1006554.8
A20: 5 | B20: Net Financial Income/(Loss) | C20: =C4-C13 -> 0 | D20: =D4-D13 -> 6308801.7 | E20: =E4-E13 -> 13143930 | F20: =F4-F13 -> 19839424 | G20: =G4-G13 -> 33624027 | H20: =H4-H13 -> 38704121 | I20: =I4-I13 -> 43529838 | J20: =J4-J13 -> 53821541 | ... AX20: =AX4-AX13 -> 70633460
A21: 6 | B21: Allowance for Loan Loss | C21: =C22-C23 -> 0 | D21: =D22-D23 -> 0 | E21: =E22-E23 -> 0 | F21: =F22-F23 -> 0 | G21: =G22-G23 -> 0 | H21: =H22-H23 -> 0 | I21: =I22-I23 -> 0 | J21: =J22-J23 -> 0 | ... AX21: =AX22-AX23 -> 0
A22: 6.1 | B22: Provision for Loan Losses | D22: 0 | E22: 0 | F22: 0 | G22: 0 | H22: 0 | I22: 0 | J22: 0 | K22: 0 | L22: 0 | M22: 0 | N22: 3462215.3 | O22: 3462215.3 | P22: 0 | Q22: 0 | R22: 0 | S22: 0 | T22: 0 | U22: 0 | V22: 0 | W22: 0 | X22: 0 | Y22: 0 | Z22: 0 | AA22: -190658.9 | AC22: 0 | AD22: 0 | AE22: 0 | AF22: 0 | AG22: 0 | AH22: 0 | AI22: 0 | AJ22: 0 | AK22: 0 | AL22: 0 | AM22: 0 | AN22: -190658.9 | AO22: 186215 | AP22: 0 | AQ22: 0 | AR22: 0 | AS22: 0 | AT22: 0 | AU22: 0 | AV22: 0 | AW22: 0 | AX22: 0
A23: 6.2 | B23: Value of Loans Recovered | D23: 0 | E23: 0 | F23: 0 | G23: 0 | H23: 0 | I23: 0 | J23: 0 | K23: 0 | L23: 0 | M23: 0 | N23: 0 | P23: 0 | Q23: 0 | R23: 0 | S23: 0 | T23: 0 | U23: 0 | V23: 0 | W23: 0 | X23: 0 | Y23: 0 | Z23: 0 | AA23: 0 | AC23: 0 | AD23: 0 | AE23: 0 | AF23: 0 | AG23: 0 | AH23: 0 | AI23: 0 | AJ23: 0 | AK23: 0 | AL23: 0 | AM23: 0 | AN23: 0 | AP23: 0 | AQ23: 0 | AR23: 0 | AS23: 0 | AT23: 0 | AU23: 0 | AV23: 0 | AW23: 0 | AX23: 0
A24: 7 | B24: Operating Expenses | C24: =C25+C26+C27+C28+C29 -> 0 | D24: =D25+D26+D27+D28+D29 -> 4760406.8 | E24: =E25+E26+E27+E28+E29 -> 11888069 | F24: =F25+F26+F27+F28+F29 -> 18921006 | G24: =G25+G26+G27+G28+G29 -> 24573748 | H24: =H25+H26+H27+H28+H29 -> 30740835 | I24: =I25+I26+I27+I28+I29 -> 36471038 | J24: =J25+J26+J27+J28+J29 -> 49600956 | ... AX24: =AX25+AX26+AX27+AX28+AX29 -> 58534511
A25: 7.1 | B25: Personnel Expenses | D25: 2891667.5 | E25: 5705647.3 | F25: 8564470 | G25: 11563692 | H25: 14564616 | I25: 17463134 | J25: 23265056 | K25: 25362996 | L25: 27457036 | M25: 29699569 | N25: 32365066 | O25: 32365066 | P25: 2180448.8 | Q25: 4377469.6 | R25: 6606592.7 | S25: 8802439.5 | T25: 11016428 | U25: 13256867 | V25: 15481158 | W25: 17588213 | X25: 19759432 | Y25: 22163313 | Z25: 24342995 | AA25: 27317217 | AB25: 30351767 | AC25: 2180448.8 | AD25: 4377469.6 | AE25: 6606592.7 | AF25: 8802439.5 | AG25: 11016428 | AH25: 13256867 | AI25: 15481158 | AJ25: 17588213 | AK25: 19759432 | AL25: 22163313 | AM25: 24342995 | AN25: 27317217 | AO25: 34303158 | AP25: 2480800.3 | AQ25: 4960962.5 | AR25: 7431064.8 | AS25: 9916411 | AT25: 12396997 | AU25: 14852828 | AV25: 17354258 | AW25: 19871007 | AX25: 22525760
A26: 7.2 | B26: Governance Expenses | D26: 152000 | E26: 557650 | F26: 1082350 | G26: 1338350 | H26: 1347350 | I26: 1421350 | J26: 1843850 | K26: 1888850 | L26: 2846100 | M26: 4582860 | N26: 5133860 | O26: 5025260 | P26: 179650 | Q26: 456650 | R26: 807150 | S26: 1042250 | T26: 1363390 | U26: 1893380 | V26: 2162880 | W26: 2628730 | X26: 2719730 | Y26: 3722030 | Z26: 5180030 | AA26: 6652530 | AB26: 6652530 | AC26: 179650 | AD26: 456650 | AE26: 807150 | AF26: 1042250 | AG26: 1363390 | AH26: 1893380 | AI26: 2162880 | AJ26: 2628730 | AK26: 2719730 | AL26: 3722030 | AM26: 5180030 | AN26: 6652530 | AO26: 6595647 | AP26: 316500 | AQ26: 758000 | AR26: 1145000 | AS26: 1614100 | AT26: 1847600 | AU26: 2314650 | AV26: 3033050 | AW26: 3137050 | AX26: 3295050
A27: 7.3 | B27: Marketing Expenses | D27: 81800 | E27: 437900 | F27: 629450 | G27: 703350 | H27: 916300 | I27: 988000 | J27: 1744742 | K27: 2185292 | L27: 2530312 | M27: 3536712 | N27: 4111772.6 | O27: 4111773 | P27: 152800 | Q27: 442400 | R27: 715700 | S27: 910400 | T27: 1358100 | U27: 1674700 | V27: 1858450 | W27: 2473350 | X27: 2804800 | Y27: 3312000 | Z27: 4811890 | AA27: 5538965 | AB27: 5538965 | AC27: 152800 | AD27: 442400 | AE27: 715700 | AF27: 910400 | AG27: 1358100 | AH27: 1674700 | AI27: 1858450 | AJ27: 2473350 | AK27: 2804800 | AL27: 3312000 | AM27: 4811890 | AN27: 5538965 | AO27: 7048890 | AP27: 251225 | AQ27: 435425 | AR27: 808715 | AS27: 1132575 | AT27: 1461925 | AU27: 2084565 | AV27: 2431015 | AW27: 2968755 | AX27: 3378855
A28: 7.4 | B28: Depreciation and Amortization Charges | D28: 633748.12 | E28: 1267496.2 | F28: 1901244.4 | G28: 2534992.5 | H28: 3161765.3 | I28: 3788538.1 | J28: 5075501.2 | K28: 5722678.3 | L28: 6382297.1 | M28: 7041915.8 | N28: 7701534.5 | O28: 7701534 | P28: 550930.13 | Q28: 1101860.3 | R28: 1684786.7 | S28: 2267713.2 | T28: 2852920.9 | U28: 3438128.7 | V28: 4026362.7 | W28: 4616507 | X28: 5242529.6 | Y28: 5868552.2 | Z28: 6494574.9 | AA28: 7120597.5 | AB28: 7120598 | AC28: 550930.13 | AD28: 1101860.3 | AE28: 1684786.7 | AF28: 2267713.2 | AG28: 2852920.9 | AH28: 3438128.7 | AI28: 4026362.7 | AJ28: 4616507 | AK28: 5242529.6 | AL28: 5868552.2 | AM28: 6494574.9 | AN28: 7120597.5 | AO28: 6601506 | AP28: 486094.41 | AQ28: 972188.82 | AR28: 1460064.5 | AS28: 1947940.1 | AT28: 2435815.8 | AU28: 2923691.5 | AV28: 3411567.1 | AW28: 3954234.4 | AX28: 4609401.8
A29: 7.5 | B29: Administrative Expenses | D29: 1001191.2 | E29: 3919375.2 | F29: 6743491.1 | G29: 8433363.3 | H29: 10750804 | I29: 12810016 | J29: 17671807 | K29: 19345865 | L29: 24039553 | M29: 27252727 | N29: 29614224 | O29: 31063869 | P29: 1792733.8 | Q29: 3808119.7 | R29: 6392866 | S29: 8558868.2 | T29: 11322381 | U29: 14076830 | V29: 15469098 | W29: 20554937 | X29: 22813515 | Y29: 25775393 | Z29: 28679515 | AA29: 34500690 | AB29: 32704769 | AC29: 1792733.8 | AD29: 3808119.7 | AE29: 6392866 | AF29: 8558868.2 | AG29: 11322381 | AH29: 14076830 | AI29: 15469098 | AJ29: 20554937 | AK29: 22813515 | AL29: 25775393 | AM29: 28679515 | AN29: 34500690 | AO29: =34507108+6942391+4413187+349680 -> 46212366 | AP29: 3120123 | AQ29: 6306150.4 | AR29: 8749410.8 | AS29: 10779404 | AT29: 13370704 | AU29: 17293757 | AV29: 20002352 | AW29: 22182255 | AX29: 24725445
A30: 8 | B30: Net Operating Income | C30: =C20-C21-C24 -> 0 | D30: =D20-D21-D24 -> 1548394.9 | E30: =E20-E21-E24 -> 1255861.3 | F30: =F20-F21-F24 -> 918418.19 | G30: =G20-G21-G24 -> 9050278.5 | H30: =H20-H21-H24 -> 7963285.2 | I30: =I20-I21-I24 -> 7058800.1 | J30: =J20-J21-J24 -> 4220584.5 | ... AX30: =AX20-AX21-AX24 -> 12098949
A31: 9 | B31: Net Non- Operating Income/ (Expense) | C31: 0 | D31: 0 | E31: 0 | F31: 0 | G31: 0 | H31: 0 | I31: 0 | J31: 0 | K31: 0 | L31: 0 | M31: 0 | N31: 0 | P31: 0 | Q31: 0 | R31: 0 | S31: 0 | T31: 0 | U31: 0 | V31: 0 | W31: 0
A32: 9.1 | B32: Non- Operating Income | C32: 0 | D32: 0 | E32: 0 | F32: 0 | G32: 0 | H32: 0 | I32: 0 | J32: 0 | K32: 0 | L32: 0 | M32: 0 | N32: 0 | P32: 0 | Q32: 0 | R32: 0 | S32: 0 | T32: 0 | U32: 0 | V32: 0 | W32: 0 | AC32: 0 | AD32: 0 | AE32: 0 | AF32: 0 | AG32: 0 | AH32: 0 | AI32: 0 | AJ32: 0 | AK32: 0 | AL32: 0 | AM32: 0 | AN32: 0 | AO32: 0 | AP32: 0 | AQ32: 0 | AR32: 0 | AS32: 0 | AT32: 0 | AU32: 0 | AV32: 0 | AW32: 0 | AX32: 0
A33: 9.2 | B33: Non- Operating Expense | C33: 0 | D33: 0 | E33: 0 | F33: 0 | G33: 0 | H33: 0 | I33: 0 | J33: 0 | K33: 0 | L33: 0 | M33: 0 | N33: 0 | AC33: 0 | AD33: 0 | AE33: 0 | AF33: 0 | AG33: 0 | AH33: 0 | AI33: 0 | AJ33: 0 | AK33: 0 | AL33: 0 | AM33: 0 | AN33: 0 | AO33: 0 | AP33: 0 | AQ33: 0 | AR33: 0 | AS33: 0 | AT33: 0 | AU33: 0 | AV33: 0 | AW33: 0 | AX33: 0
A34: 10 | B34: Net Income (Before Taxes and Donations) | C34: =C30+C31 -> 0 | D34: =D30+D31 -> 1548394.9 | E34: =E30+E31 -> 1255861.3 | F34: =F30+F31 -> 918418.19 | G34: =G30+G31 -> 9050278.5 | H34: =H30+H31 -> 7963285.2 | I34: =I30+I31 -> 7058800.1 | J34: =J30+J31 -> 4220584.5 | ... AS34: =AS30+AS31 -> 1220054.4 | AT34: =AT30+AT33 -> 1269019.1 | AU34: =AU30+AU33 -> 13941651 | AV34: =AV30+AV33 -> 13655134 | AW34: =AW30+AW33 -> 13119630 | AX34: =AX30+AX33 -> 12098949
A35: 11 | B35: Taxes (Incomes taxes & Other payable to KRA) | C35: 0 | D35: 0 | E35: 0 | F35: 0 | G35: 0 | H35: 0 | I35: 0 | J35: 0 | K35: 0 | L35: 0 | M35: 0 | N35: 0 | O35: 4208562 | P35: 0 | Q35: 0 | R35: 0 | S35: 0 | T35: 0 | U35: 0 | V35: 0 | W35: 0 | AB35: 4679034 | AC35: 4679035 | AD35: 4679036 | AE35: 4679037 | AF35: 4679038 | AG35: 4679039 | AH35: 4679040 | AI35: 4679041 | AJ35: 4679042 | AK35: 4679043 | AL35: 4679044 | AM35: 4679045 | AN35: 4679046 | AO35: 5302920 | AP35: 0 | AQ35: 0 | AR35: 0 | AS35: 0 | AT35: 0 | AU35: 0 | AV35: 0 | AW35: 0 | AX35: 0
A36: 12 | B36: Net Income (After Taxes before Donations) | C36: =C34-C35 -> 0 | D36: =D34-D35 -> 1548394.9 | E36: =E34-E35 -> 1255861.3 | F36: =F34-F35 -> 918418.19 | G36: =G34-G35 -> 9050278.5 | H36: =H34-H35 -> 7963285.2 | I36: =I34-I35 -> 7058800.1 | J36: =J34-J35 -> 4220584.5 | ... AX36: =AX34-AX35 -> 12098949
A37: 13 | B37: Donations | C37: 0 | D37: 0 | E37: 0 | F37: 0 | G37: 0 | H37: 0 | I37: 0 | J37: 0 | K37: 0 | L37: 0 | M37: 0 | N37: 0 | P37: 0 | Q37: 0 | R37: 0 | S37: 0 | T37: 0 | U37: 0 | V37: 0 | W37: 0 | AP37: 0 | AQ37: 0 | AR37: 0 | AS37: 0 | AT37: 0 | AU37: 0 | AV37: 0 | AW37: 0 | AX37: 0
A38: 14 | B38: Net Income/(After Taxes and Donations) | C38: =C36-C37 -> 0 | D38: =D36-D37 -> 1548394.9 | E38: =E36-E37 -> 1255861.3 | F38: =F36-F37 -> 918418.19 | G38: =G36-G37 -> 9050278.5 | H38: =H36-H37 -> 7963285.2 | I38: =I36-I37 -> 7058800.1 | J38: =J36-J37 -> 4220584.5 | ... AX38: =AX36-AX37 -> 12098949
AO41: =27012101-26825886 -> 186215
AO42: 78

Sheet performance report
A1: KENYA ACHIEVAS SACCO SOCIETY LIMITED
A2: PERFORMANCE AND COMPLIANCE REPORT AS AT : 31st December , 2020
B3: Prudential Standard | C3: Audited | D3: Returns | F3: audited 2020
C4: 2019 | D4: 30th September , 2020 | E4: 31st December , 2020
A5: A. CAPITAL ADEQUACY
A6: Core Capital | B6: ≥10M | C6: 105761017 | D6: 1.3090778e+08 | E6: 1.3180408e+08 | F6: 151314319
A7: Core Capital/Total Assets | B7: ≥10% | C7: 0.25651421 | D7: 0.33118356 | E7: 0.33539735 | F7: 0.38281096
A8: Institutional Capital/Total Assets | B8: ≥8% | C8: 0.075663262 | D8: 0.078922816 | E8: 0.079383462 | F8: 0.082144729
A9: B. ASSET QUALITY
A10: NPL (Substandard+Doubtful+Loss) | B10: <5% | C10: 0 | D10: 0.35335718 | E10: 0.17684352 | F10: 0.17709617
A11: Non-Earning Assets | B11: <10% | C11: 0.39367662 | D11: 0.40733915 | E11: 0.384709 | F11: 0.38827796
A12: Equity investments/Deposits | B12: <5% | C12: 0.10766462 | D12: 0.11804502 | E12: 0.11696392 | F12: 0.11696392
A13: Equity investments/Core capital | B13: <40% | C13: 0.1975872 | D13: 0.15963163 | E13: 0.1585461 | F13: 0.1381034
A14: C. EARNINGS RATING
A15: Yield on Gross Loans | C15: 0.21113871 | D15: 0.095884024 | E15: 0.15807556 | F15: 0.71974145
A16: Total Expense/Total Income | C16: 0.94538921 | D16: 0.93145747 | E16: 0.91913046 | F16: 0.94963975
A17: Net Income/Average Assets (ROA) | C17: 0.0011817921 | D17: 0.011032346 | E17: 0.013320391 | F17: 0.0032121204
A18: Operating Expenses/Financial Income (OPEX) | C18: 0.76738298 | D18: 0.82018259 | E18: 0.72286404 | F18: 0.7342184
A19: D. LIQUIDITY
A20: Liquid Assets/Short-term Liabilities | B20: >15% | C20: 0.82348453 | D20: 0.99869763 | E20: 1.3905577 | F20: 1.3905578
A21: External Borrowing/Total Assets | B21: <25% | C21: 0.15037564 | D21: 0.14243551 | E21: 0.11714059 | F21: 0.11646112
A22: Liquid Assets/Total Assets | C22: 0.17216881 | D22: 0.17398863 | E22: 0.25781697 | F22: 0.25632152
A23: E. STRUCTURE/SENSITIVITY TO RISK
A24: Gross loans /Total Assets | B24: 70-80 | C24: 0.44059964 | D24: 0.42539494 | E24: 0.37304617 | F24: 0.3703532
A25: Gross loans/Deposits | B25: >100% | C25: 0.93593771 | D25: 0.94984399 | E25: 0.82053915 | F25: 0.8193685
A26: Financial Investments/Total Assets | C26: 0.10766462 | D26: 0.29809868 | E26: 0.11696392 | F26: 0.11696392
A27: Dividends+Interest on Deposits/Total Income | C27: 0.038593323 | D27: 0.016222684 | E27: 0.014425275 | F27: 0
A28: F. KEY FINANCIAL STATISTICS | C28: 2015 | D28: 2016 | E28: 2017
A29: Total Assets | C29: 4.1230082e+08 | D29: 3.9527258e+08 | E29: 3.9297889e+08 | F29: 395271644
A30: Average Assets | C30: 3.9895258e+08 | D30: 4.1287967e+08 | E30: 4.0296011e+08 | F30: 4.0378623e+08
A31: Total Deposits | C31: 194093679 | D31: 1.7702587e+08 | E31: 1.7866213e+08 | F31: 178662126
A32: Gross Loans | C32: 1.8165959e+08 | D32: 1.6814696e+08 | E32: 146599270 | F32: 146390119
A33: Core Capital | C33: 105761017 | D33: 1.3090778e+08 | E33: 1.3180408e+08 | F33: 151314319
A34: Institutional Capital | C34: 31196025 | D34: 31196025 | E34: 31196025 | F34: 32469482
A35: Non-performing Loans | C35: 0 | D35: 59415934 | E35: 25925130 | F35: 25925130
A36: Non-Earning Assets | C36: 162313194 | D36: 1.6101e+08 | E36: 1.5118252e+08 | F36: 153475268
A37: Property and Equipment | C37: 70993240 | D37: 66863240 | E37: 65630884 | F37: 65630483
A38: Equity Investments | C38: 20897023 | D38: 20897022 | E38: 20897022 | F38: 20897022
A39: Financial Investments | C39: 20897023 | D39: 52771176 | E39: 20897022 | F39: 20897022
A40: Liquid Assets | C40: 70985340 | D40: 68772935 | E40: 1.0131663e+08 | F40: 101316629
...

Sheet Financials
A1: KENYA ACHIEVAS SACCO FINANCIALS
A3: Year/month | C3: 44216 | D3: 44247 | E3: 44275 | F3: 44306 | G3: 44336 | H3: 44397 | I3: 44428 | J3: 44459 | K3: 44489 | L3: 44520 | M3: 44550 | N3: AUDITED 2020 | O3: 44197 | P3: 44229 | Q3: 44258 | R3: 44290 | S3: 44321 | T3: 44353 | U3: 44384 | V3: 44416 | W3: 44448 | X3: 44479 | Y3: 44511 | Z3: 44542 | AA3: Audited 2021 | AB3: 44562 | AC3: 44593 | AD3: 44621 | AE3: 44652 | AF3: 44682 | AG3: 44713 | AH3: 44743 | AI3: 44774 | AJ3: 44805 | AK3: 44835 | AL3: 44866 | AM3: 44896 | AN3: AUDITED 2022 | AO3: 44927 | AP3: 44958 | AQ3: 44986 | AR3: 45017 | AS3: 45047 | AT3: 45078 | AU3: 45108 | AV3: 45139 | AW3: 45170 | AX3: 45200
A4: Membership
A5: Total Assets | B5: ='[1]Balance Sheet'!C26 -> 0 | C5: ='Balance Sheet'!D26 -> 4.175917e+08 | D5: ='Balance Sheet'!E26 -> 4.1741436e+08 | E5: ='Balance Sheet'!F26 -> 4.04244e+08 | F5: ='Balance Sheet'!G26 -> 4.1418073e+08 | G5: ='Balance Sheet'!H26 -> 4.1401975e+08 | H5: ='Balance Sheet'!I26 -> 4.1433757e+08 | I5: ='Balance Sheet'!J26 -> 4.0551207e+08 | J5: ='Balance Sheet'!K26 -> 3.9527258e+08 | ... AW5: ='Balance Sheet'!AX26 -> 4.2188532e+08
A6: Total Deposits | B6: =B7+B8 -> #REF! | C6: =C7+C8 -> 1.6006596e+08 | D6: =D7+D8 -> 1.585142e+08 | E6: =E7+E8 -> 1.5025365e+08 | F6: =F7+F8 -> 1.5596321e+08 | G6: =G7+G8 -> 1.5451704e+08 | H6: =H7+H8 -> 1.5657003e+08 | I6: =I7+I8 -> 1.5159004e+08 | ... AW6: =AW7+AW8 -> 1.8523036e+08
A7: Deposits-Members(BOSA) | B7: ='[1]Balance Sheet'!C29 -> #REF! | C7: ='Balance Sheet'!D29 -> 1.0043538e+08 | D7: ='Balance Sheet'!E29 -> 1.0029842e+08 | E7: ='Balance Sheet'!F29 -> 1.0038082e+08 | F7: ='Balance Sheet'!G29 -> 1.0049819e+08 | G7: ='Balance Sheet'!H29 -> 1.006155e+08 | H7: ='Balance Sheet'!I29 -> 1.0080875e+08 | I7: ='Balance Sheet'!J29 -> 1.01328e+08 | J7: ='Balance Sheet'!K29 -> 99983310 | ... AW7: ='Balance Sheet'!AX29 -> 1.2081867e+08
A8: Deposits-Customers(FOSA) | B8: ='[1]Balance Sheet'!C27 -> #REF! | C8: ='Balance Sheet'!D27 -> 59630574 | D8: ='Balance Sheet'!E27 -> 58215786 | E8: ='Balance Sheet'!F27 -> 49872824 | F8: ='Balance Sheet'!G27 -> 55465019 | G8: ='Balance Sheet'!H27 -> 53901544 | H8: ='Balance Sheet'!I27 -> 55761279 | I8: ='Balance Sheet'!J27 -> 50262044 | J8: ='Balance Sheet'!K27 -> 55289578 | ... AW8: ='Balance Sheet'!AX27 -> 64411687
A9: Deposits-Term | B9: ='[1]Balance Sheet'!C28 -> #REF! | C9: ='Balance Sheet'!D28 -> 20345999 | D9: ='Balance Sheet'!E28 -> 21480875 | E9: ='Balance Sheet'!F28 -> 21124180 | F9: ='Balance Sheet'!G28 -> 18516430 | G9: ='Balance Sheet'!H28 -> 20682592 | H9: ='Balance Sheet'!I28 -> 20527834 | I9: ='Balance Sheet'!J28 -> 21739978 | J9: ='Balance Sheet'!K28 -> 21752978 | ... AW9: ='Balance Sheet'!AX28 -> 24470524
A10: External Borrowing | B10: ='[1]Balance Sheet'!C37 -> #REF! | C10: ='Balance Sheet'!D37 -> 62000000 | D10: ='Balance Sheet'!E37 -> 62000000 | E10: ='Balance Sheet'!F37 -> 60620930 | F10: ='Balance Sheet'!G37 -> 59920170 | G10: ='Balance Sheet'!H37 -> 59211820 | H10: ='Balance Sheet'!I37 -> 58495800 | I10: ='Balance Sheet'!J37 -> 57040400 | J10: ='Balance Sheet'!K37 -> 56300850 | ... AW10: ='Balance Sheet'!AX37 -> 7996343.6
A12: Share capital and Reserves
A13: Core Capital | B13: =B15-B28 -> #REF! | C13: =C15 -> 1.5427629e+08 | D13: =D15 -> 1.5411664e+08 | E13: =E15 -> 1.470389e+08 | F13: =F15 -> 1.5620356e+08 | G13: =G15 -> 1.5606938e+08 | H13: =H15 -> 1.5580401e+08 | I13: =I15 -> 1.5350282e+08 | J13: =J15 -> 1.5408332e+08 | ... V13: =V15 -> 1.6656182e+08 | W13: =W15-5000000 -> 1.6177748e+08 | X13: =X15 -> 1.670259e+08 | Y13: =Y15 -> 1.6565655e+08 | Z13: =Z15-5000000 -> 1.6385528e+08 | AA13: =AA15-5000000 -> 153851067 | AB13: =AB15 -> 1.4019687e+08 | AC13: =AC15-AC28 -> 1.4300766e+08 | AD13: =AD15-AD28 -> 1.451759e+08 | AE13: =AE15-AE28 -> 1.474419e+08 | AF13: =AF15-AF28 -> 149611401 | AG13: =AG15-AG28 -> 151774309 | AH13: =AH15-AH28 -> 1.5400831e+08 | AI13: =AI15-AI28 -> 1.5595293e+08 | AJ13: =AJ15-AJ28 -> 158252703 | ... AW13: =AW15-AW28 -> 1.7544284e+08
A14: Institutional Capital | B14: =B13-B16 -> #REF! | C14: =C13-C16 -> 40190407 | D14: =D13-D16 -> 39897873 | E14: =E13-E16 -> 32114443 | F14: =F13-F16 -> 40246304 | G14: =G13-G16 -> 39136118 | H14: =H13-H16 -> 38231633 | I14: =I13-I16 -> 35393418 | ... AW14: =AW13-AW16 -> 35374121
A15: Total Capital | B15: =B16+B17+B18+B19+B20+B21 -> #REF! | C15: =C16+C17+C18+C19+C20+C21 -> 1.5427629e+08 | D15: =D16+D17+D18+D19+D20+D21 -> 1.5411664e+08 | E15: =E16+E17+E18+E19+E20+E21 -> 1.470389e+08 | F15: =F16+F17+F18+F19+F20+F21 -> 1.5620356e+08 | G15: =G16+G17+G18+G19+G20+G21 -> 1.5606938e+08 | H15: =H16+H17+H18+H19+H20+H21 -> 1.5580401e+08 | I15: =I16+I17+I18+I19+I20+I21 -> 1.5350282e+08 | ... AW15: =AW16+AW17+AW18+AW19+AW20+AW21 -> 1.8659082e+08
A16: Members Share Capital | B16: ='[1]Balance Sheet'!C39 -> #REF! | C16: ='Balance Sheet'!D39 -> 1.1408588e+08 | D16: ='Balance Sheet'!E39 -> 1.1421876e+08 | E16: ='Balance Sheet'!F39 -> 1.1492446e+08 | F16: ='Balance Sheet'!G39 -> 1.1595726e+08 | G16: ='Balance Sheet'!H39 -> 1.1693326e+08 | H16: ='Balance Sheet'!I39 -> 1.1757238e+08 | I16: ='Balance Sheet'!J39 -> 1.181094e+08 | J16: ='Balance Sheet'!K39 -> 1.1835345e+08 | ... AW16: ='Balance Sheet'!AX39 -> 1.4006871e+08
A17: Entrance Fees
A18: Retained Earnings | B18: ='[1]Balance Sheet'!C41 -> 0 | C18: ='Balance Sheet'!D41 -> 29865293 | D18: ='Balance Sheet'!E41 -> 29572759 | E18: ='Balance Sheet'!F41 -> 21739939 | F18: ='Balance Sheet'!G41 -> 29871800 | G18: ='Balance Sheet'!H41 -> 28761614 | H18: ='Balance Sheet'!I41 -> 27857129 | I18: ='Balance Sheet'!J41 -> 25018914 | J18: ='Balance Sheet'!K41 -> 25355361 | ... AW18: ='Balance Sheet'!AX41 -> 35022763
A19: Appropriation Account | B19: ='[1]Balance Sheet'!C42 -> #REF!
A20: Statutory Reserves | B20: ='[1]Balance Sheet'!C45 -> #REF! | C20: ='Balance Sheet'!D45 -> 8613865 | D20: ='Balance Sheet'!E45 -> 8613865 | E20: ='Balance Sheet'!F45 -> 8663255 | F20: ='Balance Sheet'!G45 -> 8663255 | G20: ='Balance Sheet'!H45 -> 8663255 | H20: ='Balance Sheet'!I45 -> 8663255 | I20: ='Balance Sheet'!J45 -> 8663255 | J20: ='Balance Sheet'!K45 -> 8663255 | ... AW20: ='Balance Sheet'!AX45 -> 9788098
A21: Capital Reserves | B21: ='[1]Balance Sheet'!C46 -> #REF! | C21: ='Balance Sheet'!D46 -> 1711249 | D21: ='Balance Sheet'!E46 -> 1711249 | E21: ='Balance Sheet'!F46 -> 1711249 | F21: ='Balance Sheet'!G46 -> 1711249 | G21: ='Balance Sheet'!H46 -> 1711249 | H21: ='Balance Sheet'!I46 -> 1711249 | I21: ='Balance Sheet'!J46 -> 1711249 | J21: ='Balance Sheet'!K46 -> 1711249 | ... AW21: ='Balance Sheet'!AX46 -> 1711249
A22: Supplementary Capital & reserves
A23: Proposed Dividends
A24: Benevolent Fund
A25: Investments | B25: =B26+B27+B29 -> #REF! | C25: =C26+C27+C29 -> 20897022 | D25: =D26+D27+D29 -> 20897022 | E25: =E26+E27+E29 -> 20897022 | F25: =F26+F27+F29 -> 20897022 | G25: =G26+G27+G29 -> 20897022 | H25: =H26+H27+H29 -> 20897022 | I25: =I26+I27+I29 -> 20897022 | ... AW25: =AW26+AW27+AW29 -> 28847022
A26: Govt bills | B26: ='[1]Balance Sheet'!C9 -> #REF! | C26: ='Balance Sheet'!D9 -> 0 | D26: ='Balance Sheet'!E9 -> 0 | E26: ='Balance Sheet'!F9 -> 0 | F26: ='Balance Sheet'!G9 -> 0 | G26: ='Balance Sheet'!H9 -> 0 | H26: ='Balance Sheet'!I9 -> 0 | I26: ='Balance Sheet'!J9 -> 0 | J26: ='Balance Sheet'!K9 -> 0 | ... AW26: ='Balance Sheet'!AX9 -> 0
A27: Investments in naccos | B27: ='[1]Balance Sheet'!C12 -> #REF! | C27: ='Balance Sheet'!D12 -> 20897022 | D27: ='Balance Sheet'!E12 -> 20897022 | E27: ='Balance Sheet'!F12 -> 20897022 | F27: ='Balance Sheet'!G12 -> 20897022 | G27: ='Balance Sheet'!H12 -> 20897022 | H27: ='Balance Sheet'!I12 -> 20897022 | I27: ='Balance Sheet'!J12 -> 20897022 | J27: ='Balance Sheet'!K12 -> 20897022 | ... AW27: ='Balance Sheet'!AX12 -> 28847022
A28: Equity Investments (at cost) | B28: ='[1]Balance Sheet'!C10 -> #REF! | C28: ='Balance Sheet'!D10 -> 120305.43 | D28: ='Balance Sheet'!E10 -> 30208291 | E28: ='Balance Sheet'!F10 -> 30449722 | F28: ='Balance Sheet'!G10 -> 30683692 | G28: ='Balance Sheet'!H10 -> 30925308 | H28: ='Balance Sheet'!I10 -> 30925308 | I28: ='Balance Sheet'!J10 -> 31640172 | J28: ='Balance Sheet'!K10 -> 31874154 | ... AW28: ='Balance Sheet'!AX10 -> 11147990
A29: Deposits in KUSCCO CFP | B29: ='[1]Balance Sheet'!C11 -> #REF! | C29: ='Balance Sheet'!D11 -> 0 | D29: ='Balance Sheet'!E11 -> 0 | E29: ='Balance Sheet'!F11 -> 0 | F29: ='Balance Sheet'!G11 -> 0 | G29: ='Balance Sheet'!H11 -> 0 | H29: ='Balance Sheet'!I11 -> 0 | I29: ='Balance Sheet'!J11 -> 0 | J29: ='Balance Sheet'!K11 -> 0 | ... AW29: ='Balance Sheet'!AX11 -> 0
A30: Net Loans & Advances | B30: =B31-B32 -> #REF! | C30: =C31-C32 -> 1.6636237e+08 | D30: =D31-D32 -> 1.6573191e+08 | E30: =E31-E32 -> 1.6324565e+08 | F30: =F31-F32 -> 1.5979864e+08 | G30: =G31-G32 -> 1.555884e+08 | H30: =H31-H32 -> 1.5199095e+08
A31: Gross Loans & advances | B31: ='[1]Balance Sheet'!C14 -> #REF! | C31: ='Balance Sheet'!D14 -> 1.899167e+08 | D31: ='Balance Sheet'!E14 -> 1.8928624e+08 | E31: ='Balance Sheet'!F14 -> 1.8679998e+08 | F31: ='Balance Sheet'!G14 -> 1.8335297e+08 | G31: ='Balance Sheet'!H14 -> 1.7914273e+08 | H31: ='Balance Sheet'!I14 -> 1.7554529e+08 | I31: ='Balance Sheet'!J14 -> 1.7323163e+08 | J31: ='Balance Sheet'!K14 -> 1.6814696e+08 | ... AW31: ='Balance Sheet'!AX14 -> 2.2855718e+08
A32: Allowance for loan losses | B32: ='[1]Balance Sheet'!C15 -> #REF! | C32: ='Balance Sheet'!D15 -> 23554331 | D32: ='Balance Sheet'!E15 -> 23554331 | E32: ='Balance Sheet'!F15 -> 23554331 | F32: ='Balance Sheet'!G15 -> 23554331 | G32: ='Balance Sheet'!H15 -> 23554331 | H32: ='Balance Sheet'!I15 -> 23554331 | I32: ='Balance Sheet'!J15 -> 23554331 | J32: ='Balance Sheet'!K15 -> 23554331 | ... AW32: ='Balance Sheet'!AX15 -> 27012102
A34: Non-Earning Assets | B34: ='[1]Balance Sheet'!C7+'[1]Balance Sheet'!C16+'[1]Balance Sheet'!C20 -> #REF! | C34: ='Balance Sheet'!D7+'Balance Sheet'!D16+'Balance Sheet'!D20 -> 1.5945824e+08 | D34: ='Balance Sheet'!E7+'Balance Sheet'!E16+'Balance Sheet'!E20 -> 1.5573821e+08 | E34: ='Balance Sheet'!F7+'Balance Sheet'!F16+'Balance Sheet'!F20 -> 1.5444192e+08 | F34: ='Balance Sheet'!G7+'Balance Sheet'!G16+'Balance Sheet'!G20 -> 1.5504884e+08 | G34: ='Balance Sheet'!H7+'Balance Sheet'!H16+'Balance Sheet'!H20 -> 1.5543884e+08 | H34: ='Balance Sheet'!I7+'Balance Sheet'!I16+'Balance Sheet'!I20 -> 1.5609593e+08 | I34: ='Balance Sheet'!J7+'Balance Sheet'!J16+'Balance Sheet'!J20 -> 1.611883e+08 | J34: ='Balance Sheet'!K7+'Balance Sheet'!K16+'Balance Sheet'!K20 -> 1.6101e+08 | ... AW34: ='Balance Sheet'!AX7+'Balance Sheet'!AX16+'Balance Sheet'!AX20 -> 1.4456845e+08
A35: Property and Equipment | B35: ='[1]Balance Sheet'!C20 -> 0 | C35: ='Balance Sheet'!D20 -> 70696432 | D35: ='Balance Sheet'!E20 -> 70062684 | E35: ='Balance Sheet'!F20 -> 69428936 | F35: ='Balance Sheet'!G20 -> 68795188 | G35: ='Balance Sheet'!H20 -> 68199895 | H35: ='Balance Sheet'!I20 -> 67573122 | I35: ='Balance Sheet'!J20 -> 67510417 | J35: ='Balance Sheet'!K20 -> 66863240 | ... AW35: ='Balance Sheet'!AX20 -> 72641184
A38: Turnover | B38: =B39+B41+B42 -> #REF! | C38: =C39+C41+C42 -> 6946463.7 | D38: =D39+D41+D42 -> 14316592 | E38: =E39+E41+E42 -> 22150806 | F38: =F39+F41+F42 -> 36822712 | G38: =G39+G41+G42 -> 42641103 | H38: =H39+H41+H42 -> 48381577
A39: Loan Interest | B39: ='[1]Income Statement'!C6 -> #REF! | C39: ='Income Statement'!D6 -> 3434593.2 | D39: ='Income Statement'!E6 -> 4547619.2 | E39: ='Income Statement'!F6 -> 6319984.7 | F39: ='Income Statement'!G6 -> 6933096.7 | G39: ='Income Statement'!H6 -> 7701931.2 | H39: ='Income Statement'!I6 -> 8847278.2 | I39: ='Income Statement'!J6 -> 11007267 | J39: ='Income Statement'!K6 -> 12475504 | ... AW39: ='Income Statement'!AX6 -> 23300522
A40: Yield on loans | B40: ='[1]Income Statement'!C6/'[1]Income Statement'!C14 -> #REF! | C40: ='Income Statement'!D6/'Income Statement'!D14 -> 20.695557 | D40: ='Income Statement'!E6/'Income Statement'!E14 -> 17.258451 | E40: ='Income Statement'!F6/'Income Statement'!F14 -> 17.0134 | F40: ='Income Statement'!G6/'Income Statement'!G14 -> 14.025921 | G40: ='Income Statement'!H6/'Income Statement'!H14 -> 14.257449 | H40: ='Income Statement'!I6/'Income Statement'!I14 -> 11.902569 | I40: ='Income Statement'!J6/'Income Statement'!J14 -> 10.888126 | J40: ='Income Statement'!K6/'Income Statement'!K14 -> 11.571887 | ... AW40: ='Income Statement'!AX6/'Income Statement'!AX14 -> 14.719292
A41: Income from investments | B41: ='[1]Income Statement'!C8 -> 0 | C41: ='Income Statement'!D8 -> 2410365.2 | D41: ='Income Statement'!E8 -> 8109048.2 | E41: ='Income Statement'!F8 -> 13783323 | F41: ='Income Statement'!G8 -> 27660014 | G41: ='Income Statement'!H8 -> 32537490 | H41: ='Income Statement'!I8 -> 36865707 | I41: ='Income Statement'!J8 -> 46178357 | J41: ='Income Statement'!K8 -> 50332939 | ... AW41: ='Income Statement'!AX8 -> 48542597
