Workbook

Sheet sofp
A1: KOLENGE SACCO
B2: Audited 2019 | C2: 43831 | D2: 43862 | E2: 43891 | F2: 43922 | G2: 43952 | H2: 43983 | I2: 44044 | J2: 44075 | K2: 44105 | L2: 44136 | M2: 44166 | N2: Audit 20 | O2: 44217 | P2: 44248 | Q2: 44276 | R2: 44307 | S2: 44337 | T2: 44368 | U2: 44398 | V2: 44429 | W2: 44460 | X2: 44490 | Y2: 44521 | Z2: 44551 | AA2: Audited 2021 | AB2: 44562 | AC2: 44593 | AD2: 44621 | AE2: 44652 | AF2: 44682 | AG2: 44713 | AH2: 44743
A3: Cash & cash Equivalent | B3: =SUM(B4:B5) -> 20169731 | C3: =SUM(C4:C5) -> 14896096 | D3: =SUM(D4:D5) -> 16021232 | E3: =SUM(E4:E5) -> 34153089 | F3: =SUM(F4:F5) -> 25607704 | G3: =SUM(G4:G5) -> 20680620 | H3: =SUM(H4:H5) -> 21452163 | I3: =SUM(I4:I5) -> 21208465 | ... AH3: =SUM(AH4:AH5) -> 15088393
A4: Cash In Hand | B4: =277824+380004 -> 657828 | C4: 1326784 | D4: 1340039 | E4: 12537269 | F4: 3716678 | G4: 1730398 | H4: 504122 | I4: 691459 | J4: 1738608 | K4: 1348867 | L4: 1004575 | M4: 1940206 | N4: =1382913+557293 -> 1940206 | O4: 2654121 | P4: 1080038 | Q4: 8746749 | R4: 3361652 | S4: 882292 | T4: 1786706 | U4: 2705233 | V4: 789086 | AA4: =1150953+86700 -> 1237653 | AB4: 3042274 | AC4: 1960906.6 | AD4: 5690322 | AE4: 1087018 | AF4: 1949090 | AG4: 2425270 | AH4: 2555612
A5: Cash at Bank | B5: =20169730.78-B4 -> 19511903 | C5: 13569312 | D5: 14681193 | E5: 21615820 | F5: 21891026 | G5: 18950222 | H5: 20948041 | I5: 20517006 | J5: 19687045 | K5: 20643851 | L5: 20519177 | M5: 21271450 | N5: =23211656.45-N4 -> 21271450 | O5: 14468597 | P5: 16047673 | Q5: 24871458 | R5: 20899706 | S5: 13574224 | T5: 13109654 | U5: 4089825.3 | V5: 5657752.8 | AA5: =14090331.68-AA4 -> 12852679 | AB5: 10441212 | AC5: 8596241.7 | AD5: 26016252 | AE5: 18881259 | AF5: 12522888 | AG5: 14027968 | AH5: 12532781
A6: Prepayment and Sundry | B6: =8721430.62+3249359.54 -> 11970790 | C6: 8294382 | D6: 10632495 | E6: 10345209 | F6: 9864723.2 | G6: 11742445 | H6: 11470579 | I6: 13014272 | J6: 14429148 | K6: 13593016 | L6: 15547516 | M6: 14110392 | N6: =6485507.01+7624885.23 -> 14110392 | O6: 9639724.8 | P6: 9782799.2 | Q6: 10369317 | R6: 13635316 | S6: 5771933.3 | T6: 6638154.5 | U6: 3640013.6 | V6: 14636707 | AA6: =6357721.19+4903070.43 -> 11260792 | AB6: 7449228.6 | AC6: 7707340.9 | AD6: 8348133.2 | AE6: 12587348 | AF6: 13798992 | AG6: 13058451 | AH6: 17479306
A7: Financial Investment | B7: =B8+B9+B10+B11 -> 661303 | C7: =C8+C9+C10+C11 -> 661303 | D7: =D8+D9+D10+D11 -> 661303 | E7: =E8+E9+E10+E11 -> 661303 | F7: =F8+F9+F10+F11 -> 661303 | G7: =G8+G9+G10+G11 -> 661303 | H7: =H8+H9+H10+H11 -> 661303 | I7: =I8+I9+I10+I11 -> 661303 | ... AH7: =AH8+AH9+AH10+AH11 -> 4675303
A8: Government Security | O8: 0 | P8: 0 | Q8: 0 | R8: 0 | S8: 0 | T8: 0 | U8: 0 | V8: 0 | AB8: 0 | AC8: 0 | AD8: 0 | AE8: 0 | AF8: 0 | AG8: 0 | AH8: 0
A9: Other Securities | O9: 0 | P9: 0 | Q9: 0 | R9: 0 | S9: 0 | T9: 0 | U9: 0 | V9: 0 | AB9: 0 | AC9: 0 | AD9: 0 | AE9: 0 | AF9: 0 | AG9: 0 | AH9: 0
A10: Balances with Other Saccos | O10: 0 | P10: 0 | Q10: 0 | R10: 0 | S10: 0 | T10: 0 | U10: 0 | V10: 0 | AA10: =570600+166703 -> 737303 | AB10: 0 | AC10: 0 | AD10: 0 | AE10: 0 | AF10: 0 | AG10: 0 | AH10: 0
A11: Investment In Companies | B11: 661303 | C11: 661303 | D11: 661303 | E11: 661303 | F11: 661303 | G11: 661303 | H11: 661303 | I11: 661303 | J11: 661303 | K11: 661303 | L11: 661303 | M11: 712303 | N11: 712303 | O11: 712303 | P11: 712303 | Q11: 712303 | R11: 712303 | S11: 712303 | T11: 712303 | U11: 3712303 | V11: 3712303 | AA11: 3938000 | AB11: 4675303 | AC11: 4675303 | AD11: 4675303 | AE11: 4675303 | AF11: 4675303 | AG11: 4675303 | AH11: 4675303
A12: Net Loan Portfolio | B12: =B13-B14 -> 56045241 | C12: =C13-C14 -> 60648363 | D12: =D13-D14 -> 58851210 | E12: =E13-E14 -> 55392166 | F12: =F13-F14 -> 57826486 | G12: =G13-G14 -> 61350105 | H12: =H13-H14 -> 62144243 | I12: =I13-I14 -> 64618146 | ... AH12: =AH13-AH14 -> 80437434
A13: Gross Loan Portfolio | B13: 57365819 | C13: 62076596 | D13: 60379033 | E13: 57030944 | F13: 59212362 | G13: 62939748 | H13: 63778715 | I13: 66314084 | J13: 66795066 | K13: 67805972 | L13: 68586041 | M13: 69038024 | N13: 69038024 | O13: 74541965 | P13: 75387405 | Q13: 70174337 | R13: 75666975 | S13: 86661210 | T13: 88293830 | U13: 96115932 | V13: 86784509 | AA13: 87521945 | AB13: 85380018 | AC13: 88986401 | AD13: 83079818 | AE13: 83179789 | AF13: 83569676 | AG13: 85620614 | AH13: 82060705
A14: Allowance For Loan Loss | B14: 1320577.6 | C14: 1428233 | D14: 1527823.6 | E14: 1638778.4 | F14: 1385875.8 | G14: 1589643.6 | H14: 1634471.6 | I14: 1695937.9 | J14: 1423080.9 | K14: 1589496.3 | L14: 2005711.8 | M14: 1698090.8 | N14: 1698090.8 | O14: 1817602.4 | P14: 1874422.2 | Q14: 2024909.2 | R14: 2122222.4 | S14: 2466586.4 | T14: 2398891.2 | U14: 2513841.9 | V14: 1906191.1 | AA14: 2339045 | AB14: 2417299.1 | AC14: 2053596.7 | AD14: 1976512.7 | AE14: 2334789.1 | AF14: 2498480.1 | AG14: 2339045.3 | AH14: 1623270.7
A15: Accounts Recievables | B15: =SUM(B16:B18) -> 0 | C15: =SUM(C16:C18) -> 0 | D15: =SUM(D16:D18) -> 0 | E15: =SUM(E16:E18) -> 0 | F15: =SUM(F16:F18) -> 0 | G15: =SUM(G16:G18) -> 0 | H15: =SUM(H16:H18) -> 0 | I15: =SUM(I16:I18) -> 0 | ... AH15: =SUM(AH16:AH18) -> 0
A16: Tax Recoverable | O16: 0 | P16: 0 | Q16: 0 | R16: 0 | S16: 0 | T16: 0 | U16: 0 | V16: 0
A17: Deffered Tax Assets | O17: 0 | P17: 0 | Q17: 0 | R17: 0 | S17: 0 | T17: 0 | U17: 0 | V17: 0
A18: Retirement Benefit Assets | O18: 0 | P18: 0 | Q18: 0 | R18: 0 | S18: 0 | T18: 0 | U18: 0 | V18: 0
A19: Property&Equipments&Other Assets | B19: =SUM(B20:B24) -> 55507075 | C19: =SUM(C20:C24) -> 55485741 | D19: =SUM(D20:D24) -> 55468328 | E19: =SUM(E20:E24) -> 55316440 | F19: =SUM(F20:F24) -> 55306692 | G19: =SUM(G20:G24) -> 55124112 | H19: =SUM(H20:H24) -> 55330749 | I19: =SUM(I20:I24) -> 55306860 | ... AH19: =SUM(AH20:AH24) -> 54225965
A20: Investment Properties | C20: 52176368 | D20: 52176368 | E20: 52045927 | F20: 52002447 | G20: 51958967 | H20: 51925487 | I20: 51826526 | J20: 51785046 | K20: 51741565 | L20: 51698085 | M20: 0 | N20: 51654605 | O20: 51611559 | P20: 51568514 | Q20: 51525468 | R20: 51482423 | S20: 51439377 | T20: 51493081 | U20: 51449954 | V20: 51406827 | AA20: 51234321 | AB20: 51191626 | AC20: 51148931 | AD20: 51106236 | AE20: 51063540 | AF20: 51020845 | AG20: 50978150 | AH20: 50935454
A21: Property and Equipment | B21: 55251628 | C21: 3060950.6 | D21: 3050563.2 | E21: 3036139.9 | F21: 3076897 | G21: 2944822.8 | H21: 3024964.6 | I21: 3008085.5 | J21: 3053742.2 | K21: 3146743.7 | L21: 3127177 | M21: 54759560 | N21: =54759560.16-N20 -> 3104955.4 | O21: 3088406.3 | P21: 3071857.1 | Q21: 3055308 | R21: 3140573 | S21: 3198979 | T21: 3184519.3 | U21: 3166225.8 | V21: 3147932.3 | AA21: =1395000+581395.21+737666.03+95058.33+70993.53+87757.67+106887.38 -> 3074758.1 | AB21: 3059018.6 | AC21: 3043278.9 | AD21: 3027539.4 | AE21: 3011799.9 | AF21: 2996060.3 | AG21: 2980320.8 | AH21: 2964581.1
A22: Prepaid Lease Rentals | C22: 0 | D22: 0 | E22: 0 | F22: 0 | G22: 0 | H22: 0 | I22: 0 | J22: 0 | K22: 0 | L22: 0 | M22: 0 | O22: 0 | P22: 0 | Q22: 0 | R22: 0 | S22: 0 | T22: 0 | U22: 0 | V22: 0 | AB22: 0 | AC22: 0 | AD22: 0 | AE22: 0 | AF22: 0 | AG22: 0 | AH22: 0
A23: Intangible Assets | B23: 255446.5 | C23: 248421.72 | D23: 241396.94 | E23: 234372.16 | F23: 227347.38 | G23: 220322.61 | H23: 380297.83 | I23: 472248.27 | J23: 455598 | K23: 438948.71 | L23: 422298.93 | M23: 506149.15 | N23: 506149.15 | O23: 492230.05 | P23: 478310.95 | Q23: 490892.92 | R23: 484748.42 | S23: 478074.39 | T23: 470870.82 | U23: 463137.59 | V23: 447365.1 | AA23: 403627.53 | AB23: 392527.77 | AC23: 381428.01 | AD23: 370328.25 | AE23: 359228.5 | AF23: 348128.74 | AG23: 337028.98 | AH23: 325929.22
A24: Other Assets | O24: 0 | P24: 0 | Q24: 0 | R24: 0 | S24: 0 | T24: 0 | U24: 0 | V24: 0 | AB24: 0 | AC24: 0 | AD24: 0 | AE24: 0 | AF24: 0 | AG24: 0 | AH24: 0
A25: Total Assets | B25: =B19+B15+B12+B7+B6+B3 -> 1.4435414e+08 | C25: =C19+C15+C12+C7+C6+C3 -> 1.3998588e+08 | D25: =D19+D15+D12+D7+D6+D3 -> 1.4163457e+08 | E25: =E19+E15+E12+E7+E6+E3 -> 1.5586821e+08 | F25: =F19+F15+F12+F7+F6+F3 -> 1.4926691e+08 | G25: =G19+G15+G12+G7+G6+G3 -> 1.4955858e+08 | H25: =H19+H15+H12+H7+H6+H3 -> 1.5105904e+08 | I25: =I19+I15+I12+I7+I6+I3 -> 1.5480905e+08 | ... AH25: =AH19+AH15+AH12+AH7+AH6+AH3 -> 1.719064e+08
A26: Savings and Deposits | B26: 15613501 | C26: 13262370 | D26: 13635118 | E26: 27186049 | F26: 20233888 | G26: 18909946 | H26: 18177280 | I26: 18265077 | J26: 18583040 | K26: 18454130 | L26: 18751586 | M26: 18489343 | N26: =4996861.54+1415534.37+2970174.84+3700924.59+5405847.43 -> 18489343 | O26: 16897878 | P26: 16315861 | Q26: 27505820 | R26: 22295743 | S26: 15431499 | T26: 16960539 | U26: 15154841 | V26: 14798589 | AB26: 14260031 | AC26: 13851604 | AD26: 29030314 | AE26: 20435923 | AF26: 16048466 | AG26: 17293581 | AH26: 14734685
A27: Short Terrm Deposits | C27: 0 | D27: 0 | E27: 0 | F27: 0 | G27: 0 | H27: 0 | I27: 0 | J27: 0 | K27: 0 | L27: 0 | M27: 0 | O27: 0 | P27: 0 | Q27: 0 | R27: 0 | S27: 0 | T27: 0 | U27: 0 | V27: 0 | AB27: 0 | AC27: 0 | AD27: 0 | AE27: 0 | AF27: 0 | AG27: 0 | AH27: 0
A28: Non Withdrawable Deposits | B28: 74005549 | C28: 74909237 | D28: 75827987 | E28: 76004400 | F28: 76848088 | G28: 77803092 | H28: 78350969 | I28: 80445981 | J28: 81494470 | K28: 81973863 | L28: 83125828 | M28: 84095876 | N28: =22406526.45+14207427.43+28159763.19+18210438.44+1111720.1 -> 84095876 | O28: 85036077 | P28: 85833677 | Q28: 86217200 | R28: 86876660 | S28: 86779456 | T28: 87509436 | U28: 88460868 | V28: 89159355 | AA28: 1.0350802e+08 | AB28: 88882733 | AC28: 89800753 | AD28: 89729581 | AE28: 90423825 | AF28: 90497508 | AG28: 91409162 | AH28: 92742860
A29: Total Deposit Liabilities | B29: =SUM(B26:B28) -> 89619050 | C29: =SUM(C26:C28) -> 88171607 | D29: =SUM(D26:D28) -> 89463105 | E29: =SUM(E26:E28) -> 1.0319045e+08 | F29: =SUM(F26:F28) -> 97081976 | G29: =SUM(G26:G28) -> 96713038 | H29: =SUM(H26:H28) -> 96528250 | I29: =SUM(I26:I28) -> 98711057 | ... AH29: =SUM(AH26:AH28) -> 1.0747754e+08
A30: Tax Payable | B30: 150000 | N30: 180000 | O30: 0 | P30: 0 | Q30: 0 | R30: 0 | S30: 0 | T30: 0 | U30: 0 | V30: 0 | AA30: 284207.16 | AB30: 0 | AC30: 0 | AD30: 0 | AE30: 0 | AF30: 0 | AG30: 0 | AH30: 0
A31: Dividends Payable | B31: 5072100 | N31: 4832741 | O31: 0 | P31: 0 | Q31: 0 | R31: 0 | S31: 0 | T31: 0 | U31: 0 | V31: 0 | AA31: =1100000+900000 -> 2000000 | AB31: 0 | AC31: 0 | AD31: 0 | AE31: 0 | AF31: 0 | AG31: 0 | AH31: 0
A32: Deferred Tax Liability | O32: 0 | P32: 0 | Q32: 0 | R32: 0 | S32: 0 | T32: 0 | U32: 0 | V32: 0 | AA32: 0 | AB32: 0 | AC32: 0 | AD32: 0 | AE32: 0 | AF32: 0 | AG32: 0 | AH32: 0
A33: Retirement Benefits Liabilty | O33: 0 | P33: 0 | Q33: 0 | R33: 0 | S33: 0 | T33: 0 | U33: 0 | V33: 0 | AA33: 0 | AB33: 0 | AC33: 0 | AD33: 0 | AE33: 0 | AF33: 0 | AG33: 0 | AH33: 0
A34: Other Liabilities | C34: 1373960 | D34: 1275820 | E34: 1177680 | F34: 0 | G34: 0 | H34: 0 | I34: 0 | J34: 0 | K34: 0 | L34: 0 | M34: 600000 | O34: 0 | P34: 0 | Q34: 0 | R34: 3140480 | S34: 3042340 | T34: 2944200 | U34: 2846060 | V34: 2747920 | AA34: =2355360+350000+4200000 -> 6905360 | AB34: 2257220 | AC34: 2159220 | AD34: 2061080 | AE34: 1962940 | AF34: 1864800 | AG34: 1766660 | AH34: 1668520
A35: External Borrowings | O35: 0 | P35: 0 | Q35: 0 | R35: 0 | S35: 0 | T35: 0 | U35: 0 | V35: 0 | AA35: 0 | AB35: 0 | AC35: 0 | AD35: 0 | AE35: 0 | AF35: 0 | AG35: 0 | AH35: 0
A36: Total Liabilities | B36: =SUM(B29:B35) -> 94841150 | C36: =SUM(C29:C35) -> 89545567 | D36: =SUM(D29:D35) -> 90738925 | E36: =SUM(E29:E35) -> 1.0436813e+08 | F36: =SUM(F29:F35) -> 97081976 | G36: =SUM(G29:G35) -> 96713038 | H36: =SUM(H29:H35) -> 96528250 | I36: =SUM(I29:I35) -> 98711057 | ... AH36: =SUM(AH29:AH35) -> 1.0914606e+08
A37: Share Capital | B37: 5186000 | C37: 5186000 | D37: 5186000 | E37: 5186000 | F37: 5186000 | G37: 5186000 | H37: 5186000 | I37: 5186000 | J37: 5186000 | K37: 5186000 | L37: 5186000 | M37: 5186000 | N37: 5186000 | O37: 5186000 | P37: 5186000 | Q37: 5186000 | R37: 5186000 | S37: 5186000 | T37: 5186000 | U37: 5186000 | V37: 5186000 | AA37: =7307000+38037055.28 -> 45344055 | AB37: 7307000 | AC37: 7307000 | AD37: 7307000 | AE37: 7307000 | AF37: 7307000 | AG37: 7307000 | AH37: 7307000
A38: Capital Grants | O38: 38037055 | P38: 38037055 | Q38: 38037055 | R38: 38037055 | S38: 38037055 | T38: 38037055 | U38: 38037055 | V38: 38037055 | AA38: 0 | AB38: 38037055 | AC38: 38037055 | AD38: 38037055 | AE38: 38037055 | AF38: 38037055 | AG38: 38037055 | AH38: 38037055
A39: Prior Year Retained Earnigs | B39: 2836262.5 | C39: 2907717.5 | D39: 2907717.5 | E39: 2907717.5 | F39: 2907717.5 | G39: 2907717.5 | H39: 2907717.5 | I39: 2907717.5 | J39: 2907717.5 | K39: 2907717.5 | L39: 2907717.5 | M39: 2907717.5 | N39: 2907717.5 | O39: 3782201.5 | P39: 3782201.5 | Q39: 3782201.5 | R39: 3782201.5 | S39: 3782201.5 | T39: 3782201.5 | U39: 3782201.5 | V39: 3782201.5 | AA39: 3782201.7 | AB39: 4961328.9 | AC39: 4961328.9 | AD39: 4961328.9 | AE39: 4961328.9 | AF39: 4961328.9 | AG39: 4961328.9 | AH39: 4961328.9
A40: Current Year Surplus | B40: 71455.02 | C40: 455434.08 | D40: 530934.4 | E40: 753728.08 | F40: 1027743.9 | G40: 1276398.7 | H40: 2331181.8 | I40: 3584943 | J40: 4390523.8 | K40: 4596773.5 | L40: 4852988.5 | M40: 874484 | N40: 874484.18 | O40: 332251.76 | P40: 850324.08 | Q40: 844694.16 | R40: 1525244.6 | S40: 1565181.7 | T40: 2267213.2 | U40: 2659983.4 | V40: 3942712.8 | AA40: =4411408.97-882281.79-1100000-900000-350000 -> 1179127.2 | AB40: 471583.92 | AC40: 1128170.6 | AD40: 1833598.4 | AE40: 1970691.7 | AF40: 2197827.8 | AG40: 3256170.6 | AH40: 4428713.9
...

Sheet soci
B2: Audited 2019 | C2: 43831 | D2: 43862 | E2: 43891 | F2: 43922 | G2: 43952 | H2: 43983 | I2: 44044 | J2: 44075 | K2: 44105 | L2: 44136 | M2: 44166 | N2: Audit 20 | O2: 44217 | P2: 44248 | Q2: 44276 | R2: 44307 | S2: 44337 | T2: 44368 | U2: 44398 | V2: 44429 | W2: 44460 | X2: 44490 | Y2: 44521 | Z2: 44551 | AA2: Auidted 2021 | AB2: 44562 | AC2: 44593 | AD2: 44621 | AE2: 44652 | AF2: 44682 | AG2: 44713 | AH2: 44743
A3: Financial Income | B3: =B7+B4 -> 12051864 | C3: =C7+C4 -> 874366 | D3: =D7+D4 -> 2141137 | E3: =E7+E4 -> 2798444 | F3: =F7+F4 -> 3322700 | G3: =G7+G4 -> 4166431 | H3: =H7+H4 -> 5920494 | I3: =I7+I4 -> 8466868.3 | ... AH3: =AH7+AH4 -> 10126205
A4: Financial Income From Loans Portfolio | B4: =B5+B6 -> 7965837 | C4: =C5+C6 -> 761226 | D4: =D5+D6 -> 1914857 | E4: =E5+E6 -> 2459024 | F4: =F5+F6 -> 2870140 | G4: =G5+G6 -> 3600731 | H4: =H5+H6 -> 5285654 | I4: =I5+I6 -> 7609748.3 | ... AH4: =AH5+AH6 -> 7241804.1
A5: Interest from Loans Portfolio | B5: 7965837 | C5: 674356 | D5: 1801930 | E5: 2295366 | F5: 2632389 | G5: 3285850 | H5: 4924390 | I5: 7088437.9 | J5: 7962433.9 | K5: 8614878.1 | L5: 9714049.3 | M5: 10535391 | N5: 10535391 | O5: 637890.79 | P5: 1542089.5 | Q5: 2452303.6 | R5: 3394936.1 | S5: 4321940.6 | T5: 5311546.1 | U5: 6131679.6 | V5: 7261916.8 | AA5: 11716504 | AB5: 841848.47 | AC5: 1998200.8 | AD5: 3117643.1 | AE5: 3948174.8 | AF5: 4490825.8 | AG5: 5900392.8 | AH5: 6895856.1
A6: Fees&Commision on Loan Portfolio | C6: 86870 | D6: 112927 | E6: 163658 | F6: 237751 | G6: 314881 | H6: 361264 | I6: 521310.4 | J6: 571784.4 | K6: 621689.4 | L6: 680257.4 | M6: 725307.4 | O6: 88614 | P6: 127182.5 | Q6: 166926.5 | R6: 275836 | S6: 345528.5 | T6: 410387.5 | U6: 519290.5 | V6: 561913.5 | AA6: 4255651.2 | AB6: 22027 | AC6: 0 | AD6: 106369 | AE6: 169806 | AF6: 216088 | AG6: 276070 | AH6: 345948
A7: Financial Income from Investments | B7: =SUM(B8:B11) -> 4086026.8 | C7: =SUM(C8:C11) -> 113140 | D7: =SUM(D8:D11) -> 226280 | E7: =SUM(E8:E11) -> 339420 | F7: =SUM(F8:F11) -> 452560 | G7: =SUM(G8:G11) -> 565700 | H7: =SUM(H8:H11) -> 634840 | I7: =SUM(I8:I11) -> 857120 | ... AH7: =SUM(AH8:AH11) -> 2884400.5
A8: Government Securities | O8: 0 | P8: 0 | Q8: 0 | R8: 0 | S8: 0 | T8: 0 | U8: 0 | V8: 0 | AB8: 0 | AC8: 0 | AD8: 0 | AE8: 0 | AF8: 0 | AG8: 0 | AH8: 0
A9: Deposits with Banks & other Financial Institutions | O9: 0 | P9: 0 | Q9: 0 | R9: 0 | S9: 0 | T9: 0 | U9: 0 | V9: 0 | AA9: =4308 -> 4308 | AB9: 0 | AC9: 0 | AD9: 0 | AE9: 0 | AF9: 0 | AG9: 0 | AH9: 0
A10: Other Investments | C10: 113140 | D10: 226280 | E10: 339420 | F10: 452560 | G10: 565700 | H10: 634840 | I10: 857120 | J10: 961260 | K10: 1065400 | L10: 1163540 | M10: 908813 | O10: 101140 | P10: 213780 | Q10: 329420 | R10: 448060 | S10: 563700 | T10: 685340 | U10: 806980 | V10: 928620 | AA10: =1110168 -> 1110168 | AB10: 118840 | AC10: 216700 | AD10: 356520 | AE10: 475360 | AF10: 594200 | AG10: 723040 | AH10: 822180
A11: Other Operating Income | B11: 4086026.8 | N11: 4391134.6 | O11: 213663.25 | P11: 385781.95 | Q11: 718561.3 | R11: 964053.87 | S11: 1194336 | T11: 1446599.4 | U11: 1700855 | V11: 1925168.9 | AB11: 249541.45 | AC11: 559160.32 | AD11: 987011 | AE11: 1266024.9 | AF11: 1516687.9 | AG11: 1792195.1 | AH11: 2062220.4
A12: Financial Expenses | B12: =SUM(B13:B18) -> 2425390 | C12: =SUM(C13:C18) -> 18708 | D12: =SUM(D13:D18) -> 37959 | E12: =SUM(E13:E18) -> 45177 | F12: =SUM(F13:F18) -> 53343 | G12: =SUM(G13:G18) -> 62403 | H12: =SUM(H13:H18) -> 70755 | I12: =SUM(I13:I18) -> 82203 | ... AH12: =SUM(AH13:AH18) -> 88681
A13: Interest Expense on Deposits | B13: 2300000 | N13: 3500000 | O13: 0 | P13: 0 | Q13: 0 | R13: 0 | S13: 0 | T13: 0 | U13: 0 | V13: 0 | AA13: 4200000 | AB13: 0 | AC13: 0 | AD13: 0 | AE13: 0 | AF13: 0 | AG13: 0 | AH13: 0
A14: Cost of External Borrowings | O14: 0 | P14: 0 | Q14: 0 | R14: 0 | S14: 0 | T14: 0 | U14: 0 | V14: 0 | AB14: 0 | AC14: 0 | AD14: 0 | AE14: 0 | AF14: 0 | AG14: 0 | AH14: 0
A15: Dividend Expenses | O15: 0 | P15: 0 | Q15: 0 | R15: 0 | S15: 0 | T15: 0 | U15: 0 | V15: 0 | AB15: 0 | AC15: 0 | AD15: 0 | AE15: 0 | AF15: 0 | AG15: 0 | AH15: 0
A16: Other Financial Expense | B16: 125390 | C16: 18708 | D16: 37959 | E16: 45177 | F16: 53343 | G16: 62403 | H16: 70755 | I16: 82203 | J16: 117484.38 | K16: 134466.38 | L16: 162121.3 | M16: 192116.22 | N16: 192116.22 | O16: 27750 | P16: 54138.92 | Q16: 79422.03 | R16: 99403.49 | S16: 107268.49 | T16: 129940.94 | U16: 153370.94 | V16: 162227.94 | AA16: 222769.94 | AB16: 19389 | AC16: 28521 | AD16: 39255 | AE16: 50979 | AF16: 62721 | AG16: 74673 | AH16: 88681
A17: Fees & Commision Expense | O17: 0 | P17: 0 | Q17: 0 | R17: 0 | S17: 0 | T17: 0 | U17: 0 | V17: 0 | AB17: 0 | AC17: 0 | AD17: 0 | AE17: 0 | AF17: 0 | AG17: 0 | AH17: 0
A18: Other Expenses | O18: 0 | P18: 0 | Q18: 0 | R18: 0 | S18: 0 | T18: 0 | U18: 0 | V18: 0 | AB18: 0 | AC18: 0 | AD18: 0 | AE18: 0 | AF18: 0 | AG18: 0 | AH18: 0
A19: Net Financial Income | B19: =B3-B12 -> 9626473.8 | C19: =C3-C12 -> 855658 | D19: =D3-D12 -> 2103178 | E19: =E3-E12 -> 2753267 | F19: =F3-F12 -> 3269357 | G19: =G3-G12 -> 4104028 | H19: =H3-H12 -> 5849739 | I19: =I3-I12 -> 8384665.3 | ... AH19: =AH3-AH12 -> 10037524
A20: Allowance for Loan Loss | AA20: 640954.54 | AB20: =AB22-AB21 -> -78253.8 | AC20: =AC22-AC21 -> 285448.6 | AD20: =AD22-AD21 -> 362532.6 | AE20: =AE22-AE21 -> 4256.2 | AF20: =AF22-AF21 -> -159434.8 | AG20: =AG22-AG21 -> 177659.8 | AH20: =AH22-AH21 -> 715774.6
A21: Provision for Loan Losses | C21: 1428233 | D21: 1527823.6 | E21: 1638778.4 | F21: 1385875.8 | G21: 1589643.6 | H21: 1634471.6 | I21: 1695937.9 | J21: 1423080.9 | K21: 1589496.3 | L21: 2005711.8 | M21: 1698090.8 | O21: 1817602.4 | P21: 1874422.2 | Q21: 2024909.2 | R21: 2122222.4 | S21: 2466586.4 | T21: 2398891.2 | U21: 2513841.9 | V21: 1906191.1 | AB21: 2417299.1 | AC21: 2053596.7 | AD21: 1976512.7 | AE21: 2334789.1 | AF21: 2498480.1 | AG21: 2161385.5 | AH21: 1623270.7
A22: Value of Loans Recovered | C22: 1320577.6 | D22: 1320577.6 | E22: 1320577.6 | F22: 1320577.6 | G22: 1320577.6 | H22: 1320577.6 | I22: 1320577.6 | J22: 1320577.6 | K22: 1320577.6 | L22: 1320577.6 | M22: 1320577.6 | O22: 1698090.8 | P22: 1698090.8 | Q22: 1698090.8 | R22: 1698090.8 | S22: 1698090.8 | T22: 1698090.8 | U22: 1698090.8 | V22: 1698090.8 | AB22: 2339045.3 | AC22: 2339045.3 | AD22: 2339045.3 | AE22: 2339045.3 | AF22: 2339045.3 | AG22: 2339045.3 | AH22: 2339045.3
A23: Operating Expeses | B23: =SUM(B24:B28) -> 7297058.6 | C23: =SUM(C24:C28) -> 597859.92 | D23: =SUM(D24:D28) -> 1508463.1 | E23: =SUM(E24:E28) -> 2110756.1 | F23: =SUM(F24:F28) -> 2752979 | G23: =SUM(G24:G28) -> 3302713.5 | H23: =SUM(H24:H28) -> 3854917.8 | I23: =SUM(I24:I28) -> 5132872.1 | ... AH23: =SUM(AH24:AH28) -> 4340847.8
A24: Personel Expenses | B24: 3246926 | C24: 278913 | D24: 565617 | E24: 839684 | F24: 1089616 | G24: 1366411 | H24: 1630754 | I24: 2178366 | J24: 2434400 | K24: 2733818 | L24: 2955729.2 | M24: 3225576.8 | N24: 3225576.8 | O24: 239265 | P24: 354420 | Q24: 702365 | R24: 944921 | S24: 1538695.6 | T24: 1673325.6 | U24: 2064549 | V24: 2271581.6 | AA24: 3174461.1 | AB24: 253196.7 | AC24: 542120.3 | AD24: 776144 | AE24: 1032362 | AF24: 1264492.3 | AG24: 1627866.9 | AH24: 1877734.6
A25: Governance Expenses | B25: 1496224 | C25: 89400 | D25: 480973 | E25: 583753 | F25: 644603 | G25: 715083 | H25: 780543 | I25: 916678 | J25: 966153 | K25: 1035628 | L25: 1154748 | M25: 1433549 | N25: 1433549 | O25: 41300 | P25: 102300 | Q25: 354320 | R25: 500160 | S25: 613260 | T25: 784860 | U25: 881945 | V25: 953435 | AA25: 1312180 | AB25: 72300 | AC25: 206306 | AD25: 582006 | AE25: 647381 | AF25: 750286 | AG25: 808801 | AH25: 882826
A26: Marketing Expenses | B26: 176687 | C26: 6980 | D26: 23820 | E26: 34920 | F26: 47100 | G26: 69150 | H26: 76540 | I26: 153027 | J26: 163027 | K26: 181439 | L26: 196109 | M26: 210309 | N26: 210309 | O26: 2320 | P26: 21590 | Q26: 53890 | R26: 84510 | S26: 103190 | T26: 147890 | U26: 165710 | V26: 171510 | AA26: 207905 | AB26: 900 | AC26: 6175 | AD26: 9475 | AE26: 36025 | AF26: 36625 | AG26: 44425 | AH26: 45050
A27: Depreciation and Amortization | B27: 437585.61 | C27: 21333.92 | D27: 115807.15 | E27: 194785.07 | F27: 266532.97 | G27: 327724.54 | H27: 441267.78 | I27: 622657.06 | J27: 705630.42 | K27: 796966.89 | L27: 876663.61 | M27: 1005565.3 | N27: 1005565.3 | O27: 73513.75 | P27: 147027.51 | Q27: 222924.19 | R27: 301802.19 | S27: 382743.21 | T27: 461566.67 | U27: 540347.81 | V27: 617540.33 | AA27: 935842 | AB27: 69534.62 | AC27: 139069.22 | AD27: 208603.81 | AE27: 278138.38 | AF27: 347672.99 | AG27: 417207.56 | AH27: 486742.16
A28: Administrative Expenses | B28: 1939636 | C28: 201233 | D28: 322246 | E28: 457614 | F28: 705127 | G28: 824345 | H28: 925813 | I28: 1262144 | J28: 1352201 | K28: 1499939 | L28: 1721262 | M28: 2042865 | N28: 2042865 | O28: 72333 | P28: 270121 | Q28: 371604 | R28: 721402 | S28: 855375 | T28: 1021473 | U28: 1112152 | V28: 1195490 | AA28: 1811766 | AB28: 79203 | AC28: 475705 | AD28: 621194 | AE28: 753972 | AF28: 847885 | AG28: 949613 | AH28: 1048495
A29: Net Operating Income | B29: =B19-B21-B23 -> 2329415.2 | C29: =C19-C21-C23 -> -1170434.9 | D29: =D19-D21-D23 -> -933108.75 | E29: =E19-E21-E23 -> -996267.47 | F29: =F19-F21-F23 -> -869497.77 | G29: =G19-G21-G23 -> -788329.14 | H29: =H19-H21-H23 -> 360349.62 | I29: =I19-I21-I23 -> 1555855.4 | ... N29: =N19-N21-N23 -> 3316544.7 | O29: =O19-O21-O23-O20+O22 -> 465314.69 | P29: =P19-P21-P23-P20+P22 -> 1142905.1 | Q29: =Q19-Q21-Q23-Q20+Q22 -> 1555867.8 | R29: =R19-R21-R23-R20+R22 -> 2006555.7 | S29: =S19-S21-S23-S20+S22 -> 2056477.2 | T29: =T19-T21-T23-T20+T22 -> 2934016.4 | U29: =U19-U21-U23-U20+U22 -> 3424979.3 | V29: =V19-V21-V23-V20+V22 -> 5097734 | W29: =W19-W21-W23 -> 0 | X29: =X19-X21-X23 -> 0 | Y29: =Y19-Y21-Y23 -> 0 | Z29: =Z19-Z21-Z23 -> 0 | AA29: =AA19-AA20-AA23 -> 4580752.3 | AB29: =AB19-AB20-AB23 -> 815987.4 | AC29: =AC19-AC20-AC23 -> 1090716 | AD29: =AD19-AD20-AD23 -> 1968332.7 | AE29: =AE19-AE20-AE23 -> 3056252.2 | AF29: =AF19-AF20-AF23 -> 3667554.2 | AG29: =AG19-AG20-AG23 -> 4591451.6 | AH29: =AH19-AH20-AH23 -> 4980901.2
A30: Net Non operating Income/Expense | B30: =B29 -> 2329415.2 | C30: =C29 -> -1170434.9 | D30: =D29 -> -933108.75 | E30: =E29 -> -996267.47 | F30: =F29 -> -869497.77 | G30: =G29 -> -788329.14 | H30: =H29 -> 360349.62 | I30: =I29 -> 1555855.4 | ... AH30: =AH29 -> 4980901.2
A31: Non Operating Income | O31: 0 | P31: 0 | Q31: 0 | R31: 0 | S31: 0 | T31: 0 | U31: 0 | V31: 0
A32: Non Operating Expense | O32: 0 | P32: 0 | Q32: 0 | R32: 0 | S32: 0 | T32: 0 | U32: 0 | V32: 0
A33: Net Income(Before Tax & Donations) | B33: =B30 -> 2329415.2 | C33: =C30 -> -1170434.9 | D33: =D30 -> -933108.75 | E33: =E30 -> -996267.47 | F33: =F30 -> -869497.77 | G33: =G30 -> -788329.14 | H33: =H30 -> 360349.62 | I33: =I30 -> 1555855.4 | ... AH33: =AH30 -> 4980901.2
A34: Taxes | B34: 150000 | C34: 100000 | D34: 120000 | E34: 120000 | F34: 120000 | G34: 100000 | H34: 150000 | I34: 150000 | J34: 150000 | K34: 150000 | L34: 170000 | M34: 180000 | N34: 180000 | O34: 50000 | P34: 80000 | Q34: 0 | R34: 100000 | S34: 100000 | T34: 100000 | U34: 100000 | V34: 169343 | AA34: 169343 | AB34: 70000 | AC34: 251400 | AD34: 401400 | AE34: 601400 | AF34: 601400 | AG34: 876558 | AH34: 876558
A35: Net Income(After Tax Before Donations) | B35: =B33-B34 -> 2179415.2 | C35: =C33-C34 -> -1270434.9 | D35: =D33-D34 -> -1053108.8 | E35: =E33-E34 -> -1116267.5 | F35: =F33-F34 -> -989497.77 | G35: =G33-G34 -> -888329.14 | H35: =H33-H34 -> 210349.62 | I35: =I33-I34 -> 1405855.4 | ... AH35: =AH33-AH34 -> 4104343.2
A36: Donations | O36: 0 | P36: 0 | Q36: 0 | R36: 0 | S36: 0 | T36: 0 | U36: 0 | V36: 0
A37: Net Income/(After Tax & Donations) | B37: =B35-B36 -> 2179415.2 | C37: =C35-C36 -> -1270434.9 | D37: =D35-D36 -> -1053108.8 | E37: =E35-E36 -> -1116267.5 | F37: =F35-F36 -> -989497.77 | G37: =G35-G36 -> -888329.14 | H37: =H35-H36 -> 210349.62 | I37: =I35-I36 -> 1405855.4 | ... AH37: =AH35-AH36 -> 4104343.2

Sheet financials
B1: Audited 2019 | C1: 43831 | D1: 43862 | E1: 43891 | F1: 43922 | G1: 43952 | H1: 43983 | I1: 44044 | J1: 44075 | K1: 44105 | L1: 44136 | M1: 44166 | N1: AUDITED 2020 | O1: 44197 | P1: 44228 | Q1: 44256 | R1: 44287 | S1: 44317 | T1: 44348 | U1: 44378 | V1: 44409 | W1: 44440 | X1: 44470 | Y1: 44501 | Z1: 44531 | AA1: Audited 2021 | AB1: 44562 | AC1: 44593 | AD1: 44621 | AE1: 44652 | AF1: 44682 | AG1: 44713 | AH1: 44743
A2: Membership
A3: Total Assets | B3: =sofp!B25 -> 1.4435414e+08 | C3: =sofp!C25 -> 1.3998588e+08 | D3: =sofp!D25 -> 1.4163457e+08 | E3: =sofp!E25 -> 1.5586821e+08 | F3: =sofp!F25 -> 1.4926691e+08 | G3: =sofp!G25 -> 1.4955858e+08 | H3: =sofp!H25 -> 1.5105904e+08 | I3: =sofp!I25 -> 1.5480905e+08 | ... AH3: =sofp!AH25 -> 1.719064e+08
A4: Total Deposits | B4: =sofp!B29 -> 89619050 | C4: =sofp!C29 -> 88171607 | D4: =sofp!D29 -> 89463105 | E4: =sofp!E29 -> 1.0319045e+08 | F4: =sofp!F29 -> 97081976 | G4: =sofp!G29 -> 96713038 | H4: =sofp!H29 -> 96528250 | I4: =sofp!I29 -> 98711057 | ... AH4: =sofp!AH29 -> 1.0747754e+08
A5: Deposits-Members(BOSA) | B5: =sofp!B28 -> 74005549 | C5: =sofp!C28 -> 74909237 | D5: =sofp!D28 -> 75827987 | E5: =sofp!E28 -> 76004400 | F5: =sofp!F28 -> 76848088 | G5: =sofp!G28 -> 77803092 | H5: =sofp!H28 -> 78350969 | I5: =sofp!I28 -> 80445981 | ... AH5: =sofp!AH28 -> 92742860
A6: Deposits-Customers(FOSA) | B6: =sofp!B26 + sofp!B28 -> 89619050 | C6: =sofp!C26 + sofp!C28 -> 88171607 | D6: =sofp!D26 + sofp!D28 -> 89463105 | E6: =sofp!E26 + sofp!E28 -> 1.0319045e+08 | F6: =sofp!F26 + sofp!F28 -> 97081976 | G6: =sofp!G26 + sofp!G28 -> 96713038 | H6: =sofp!H26 + sofp!H28 -> 96528250 | I6: =sofp!I26 + sofp!I28 -> 98711057 | ... AH6: =sofp!AH26 + sofp!AH28 -> 1.0747754e+08
A7: External Borrowing | B7: =sofp!B35 -> 0 | C7: =sofp!C35 -> 0 | D7: =sofp!D35 -> 0 | E7: =sofp!E35 -> 0 | F7: =sofp!F35 -> 0 | G7: =sofp!G35 -> 0 | H7: =sofp!H35 -> 0 | I7: =sofp!I35 -> 0 | ... AH7: =sofp!AH35 -> 0
A8: Short term liabilities | B8: =SUM(sofp!B30:B34) -> 5222100 | C8: =SUM(sofp!C30:C34) -> 1373960 | D8: =SUM(sofp!D30:D34) -> 1275820 | E8: =SUM(sofp!E30:E34) -> 1177680 | F8: =SUM(sofp!F30:F34) -> 0 | G8: =SUM(sofp!G30:G34) -> 0 | H8: =SUM(sofp!H30:H34) -> 0 | I8: =SUM(sofp!I30:I34) -> 0 | ... AH8: =SUM(sofp!AH30:AH34) -> 1668520
A10: Share Capital and Reserves
A11: Core Capital | B11: =B14 -> 49513013 | C11: =C14 -> 50440317 | D11: =D14 -> 50895644 | E11: =E14 -> 51500078 | F11: =F14 -> 52184932 | G11: =G14 -> 52845547 | H11: =H14 -> 54530787 | I11: =I14 -> 56097989 | ... M11: =M14 -> 53042035 | N11: =N14-sofp!N11 -> 52329732 | O11: =O14-sofp!O11+38037055 -> 52745046 | P11: =P14-sofp!P11+38037055 -> 53392637 | Q11: =Q14-sofp!Q11+38037055 -> 53485599 | R11: =R14-sofp!R11+38037055 -> 54236287 | S11: =S14-sofp!S11+38037055 -> 54286209 | T11: =T14-sofp!T11+38037055 -> 55163748 | U11: =U14-sofp!U11+38037055 -> 52654711 | V11: =V14-sofp!V11+38037055 -> 54258123 | W11: =W14-sofp!W11 -> 0 | X11: =X14-sofp!X11 -> 0 | Y11: =Y14-sofp!Y11 -> 0 | Z11: =Z14-sofp!Z11 -> 0 | AA11: =AA14-sofp!AA11 -> 53286444 | AB11: =AB14-sofp!AB11 -> 15101566 | AC11: =AC14-sofp!AC11 -> 15922299 | AD11: =AD14-sofp!AD11 -> 16804084 | ... AH11: =AH14-sofp!AH11 -> 20047978
A12: Institutional Capital | B12: =B11 - B15 -> 44327013 | C12: =C11 - C15 -> 45254317 | D12: =D11 - D15 -> 45709644 | E12: =E11 - E15 -> 46314078 | F12: =F11 - F15 -> 46998932 | G12: =G11 - G15 -> 47659547 | H12: =H11 - H15 -> 49344787 | I12: =I11 - I15 -> 50911989 | ... N12: =N11 - N15 -> 47143732 | O12: =O11 - O15+38037055 -> 85596101 | P12: =P11 - P15+38037055 -> 86243692 | Q12: =Q11 - Q15 -> 48299599 | R12: =R11 - R15 -> 49050287 | S12: =S11 - S15 -> 49100209 | T12: =T11 - T15 -> 49977748 | U12: =U11 - U15 -> 47468711 | V12: =V11 - V15 -> 49072123 | W12: =W11 - W15 -> 0 | X12: =X11 - X15 -> 0 | ... Z12: =Z11 - Z15 -> 0 | AA12: =AA11 - AA15+35037055.28 -> 42979444 | AB12: =AB11 - AB15+35037055.28 -> 42831621 | AC12: =AC11 - AC15+35037055.28 -> 43652354 | AD12: =AD11 - AD15+35037055.28 -> 44534139 | AE12: =AE11 - AE15+35037055.28 -> 44705506 | AF12: =AF11 - AF15+35037055.28 -> 44989426 | AG12: =AG11 - AG15+35037055.28 -> 46312354 | AH12: =AH11 - AH15+35037055.28 -> 47778034
A14: Total Capital | B14: =SUM(B15:B17) + B19 -> 49513013 | C14: =SUM(C15:C17) + C19 -> 50440317 | D14: =SUM(D15:D17) + D19 -> 50895644 | E14: =SUM(E15:E17) + E19 -> 51500078 | F14: =SUM(F15:F17) + F19 -> 52184932 | G14: =SUM(G15:G17) + G19 -> 52845547 | H14: =SUM(H15:H17) + H19 -> 54530787 | I14: =SUM(I15:I17) + I19 -> 56097989 | ... AH14: =SUM(AH15:AH17) + AH19 -> 24723281
A15: Members Share Capital | B15: =sofp!B37 -> 5186000 | C15: =sofp!C37 -> 5186000 | D15: =sofp!D37 -> 5186000 | E15: =sofp!E37 -> 5186000 | F15: =sofp!F37 -> 5186000 | G15: =sofp!G37 -> 5186000 | H15: =sofp!H37 -> 5186000 | I15: =sofp!I37 -> 5186000 | ... AH15: =sofp!AH37 -> 7307000
A16: Retained Earnings | B16: =sofp!B39 + sofp!B40 -> 2907717.5 | C16: =sofp!C39 + sofp!C40 -> 3363151.6 | D16: =sofp!D39 + sofp!D40 -> 3438651.9 | E16: =sofp!E39 + sofp!E40 -> 3661445.6 | F16: =sofp!F39 + sofp!F40 -> 3935461.4 | G16: =sofp!G39 + sofp!G40 -> 4184116.2 | H16: =sofp!H39 + sofp!H40 -> 5238899.3 | I16: =sofp!I39 + sofp!I40 -> 6492660.5 | ... AH16: =sofp!AH39 + sofp!AH40 -> 9390042.8
A17: Statutory Reserves | B17: =sofp!B41 -> 5484971.9 | C17: =sofp!C41 -> 5598830.4 | D17: =sofp!D41 -> 5617705.5 | E17: =sofp!E41 -> 5673403.9 | F17: =sofp!F41 -> 5741907.8 | G17: =sofp!G41 -> 5804071.5 | H17: =sofp!H41 -> 6067767.3 | I17: =sofp!I41 -> 6381207.6 | ... AH17: =sofp!AH41 -> 8026238.4
A18: Supplementary Capital & Reserves
A19: Capital Reserves | B19: =sofp!B42 -> 35934323 | C19: =sofp!C42 -> 36292335 | D19: =sofp!D42 -> 36653286 | E19: =sofp!E42 -> 36979229 | F19: =sofp!F42 -> 37321562 | G19: =sofp!G42 -> 37671359 | H19: =sofp!H42 -> 38038121 | I19: =sofp!I42 -> 38038121 | ... AH19: =sofp!AH42 -> 0
A20: Proposed Dividends | B20: =sofp!B44 -> 0 | C20: =sofp!C44 -> 0 | D20: =sofp!D44 -> 0 | E20: =sofp!E44 -> 0 | F20: =sofp!F44 -> 0 | G20: =sofp!G44 -> 0 | H20: =sofp!H44 -> 0 | I20: =sofp!I44 -> 0 | ... AH20: =sofp!AH44 -> 0
A22: Investments | B22: =SUM(B23:B24) -> 661303 | C22: =SUM(C23:C24) -> 661303 | D22: =SUM(D23:D24) -> 661303 | E22: =SUM(E23:E24) -> 661303 | F22: =SUM(F23:F24) -> 661303 | G22: =SUM(G23:G24) -> 661303 | H22: =SUM(H23:H24) -> 661303 | I22: =SUM(I23:I24) -> 661303 | ... AH22: =SUM(AH23:AH24) -> 4675303
A23: Investment in Coop Bank, Kuscco | B23: =sofp!B10 -> 0 | C23: =sofp!C10 -> 0 | D23: =sofp!D10 -> 0 | E23: =sofp!E10 -> 0 | F23: =sofp!F10 -> 0 | G23: =sofp!G10 -> 0 | H23: =sofp!H10 -> 0 | I23: =sofp!I10 -> 0 | ... AH23: =sofp!AH10 -> 0
A24: Equity investments (at Cost) | B24: =sofp!B9 + sofp!B11 -> 661303 | C24: =sofp!C9 + sofp!C11 -> 661303 | D24: =sofp!D9 + sofp!D11 -> 661303 | E24: =sofp!E9 + sofp!E11 -> 661303 | F24: =sofp!F9 + sofp!F11 -> 661303 | G24: =sofp!G9 + sofp!G11 -> 661303 | H24: =sofp!H9 + sofp!H11 -> 661303 | I24: =sofp!I9 + sofp!I11 -> 661303 | ... AH24: =sofp!AH9 + sofp!AH11 -> 4675303
A26: Net Loans & Advances | B26: =B27 - B28 -> 56045241 | C26: =C27 - C28 -> 60648363 | D26: =D27 - D28 -> 58851210 | E26: =E27 - E28 -> 55392166 | F26: =F27 - F28 -> 57826486 | G26: =G27 - G28 -> 61350105 | H26: =H27 - H28 -> 62144243 | I26: =I27 - I28 -> 64618146 | ... AH26: =AH27 - AH28 -> 80437434
A27: Gross Loans & Advances | B27: =sofp!B13 -> 57365819 | C27: =sofp!C13 -> 62076596 | D27: =sofp!D13 -> 60379033 | E27: =sofp!E13 -> 57030944 | F27: =sofp!F13 -> 59212362 | G27: =sofp!G13 -> 62939748 | H27: =sofp!H13 -> 63778715 | I27: =sofp!I13 -> 66314084 | ... AH27: =sofp!AH13 -> 82060705
A28: Allowance for loan loss | B28: =sofp!B14 -> 1320577.6 | C28: =sofp!C14 -> 1428233 | D28: =sofp!D14 -> 1527823.6 | E28: =sofp!E14 -> 1638778.4 | F28: =sofp!F14 -> 1385875.8 | G28: =sofp!G14 -> 1589643.6 | H28: =sofp!H14 -> 1634471.6 | I28: =sofp!I14 -> 1695937.9 | ... AH28: =sofp!AH14 -> 1623270.7
A30: Non-Performing loans
A31: Renegotiated loans
A32: Required Loan loss provision
A33: Cash and cash equivalents | B33: =sofp!B3 -> 20169731 | C33: =sofp!C3 -> 14896096 | D33: =sofp!D3 -> 16021232 | E33: =sofp!E3 -> 34153089 | F33: =sofp!F3 -> 25607704 | G33: =sofp!G3 -> 20680620 | H33: =sofp!H3 -> 21452163 | I33: =sofp!I3 -> 21208465 | ... AH33: =sofp!AH3 -> 15088393
A35: Non-Earning Assets | B35: =sofp!B19 + sofp!B6 -> 67477865 | C35: =sofp!C19 + sofp!C6 -> 63780123 | D35: =sofp!D19 + sofp!D6 -> 66100824 | E35: =sofp!E19 + sofp!E6 -> 65661649 | F35: =sofp!F19 + sofp!F6 -> 65171415 | G35: =sofp!G19 + sofp!G6 -> 66866557 | H35: =sofp!H19 + sofp!H6 -> 66801328 | I35: =sofp!I19 + sofp!I6 -> 68321132 | ... AH35: =sofp!AH19 + sofp!AH6 -> 71705271
A36: Property and Equipment | B36: =sofp!B21 -> 55251628 | C36: =sofp!C21 -> 3060950.6 | D36: =sofp!D21 -> 3050563.2 | E36: =sofp!E21 -> 3036139.9 | F36: =sofp!F21 -> 3076897 | G36: =sofp!G21 -> 2944822.8 | H36: =sofp!H21 -> 3024964.6 | I36: =sofp!I21 -> 3008085.5 | ... AH36: =sofp!AH21 -> 2964581.1
A37: Land and Building
A39: Turnover | B39: =SUM(B40:B42) -> 12051864 | C39: =SUM(C40:C42) -> 874366 | D39: =SUM(D40:D42) -> 2141137 | E39: =SUM(E40:E42) -> 2798444 | F39: =SUM(F40:F42) -> 3322700 | G39: =SUM(G40:G42) -> 4166431 | H39: =SUM(H40:H42) -> 5920494 | I39: =SUM(I40:I42) -> 8466868.3 | ... AH39: =SUM(AH40:AH42) -> 10126205
A40: Loan Interest | B40: =soci!B5 -> 7965837 | C40: =soci!C5 -> 674356 | D40: =soci!D5 -> 1801930 | E40: =soci!E5 -> 2295366 | F40: =soci!F5 -> 2632389 | G40: =soci!G5 -> 3285850 | H40: =soci!H5 -> 4924390 | I40: =soci!I5 -> 7088437.9 | ... AH40: =soci!AH5 -> 6895856.1
A41: Income from Investments | B41: =soci!B7 -> 4086026.8 | C41: =soci!C7 -> 113140 | D41: =soci!D7 -> 226280 | E41: =soci!E7 -> 339420 | F41: =soci!F7 -> 452560 | G41: =soci!G7 -> 565700 | H41: =soci!H7 -> 634840 | I41: =soci!I7 -> 857120 | ... AH41: =soci!AH7 -> 2884400.5
A42: Fees & Commissions | B42: =soci!B6 -> 0 | C42: =soci!C6 -> 86870 | D42: =soci!D6 -> 112927 | E42: =soci!E6 -> 163658 | F42: =soci!F6 -> 237751 | G42: =soci!G6 -> 314881 | H42: =soci!H6 -> 361264 | I42: =soci!I6 -> 521310.4 | ... AH42: =soci!AH6 -> 345948
A43: Average yield on loans | B43: =B40/B27 -> 0.13886034 | C43: =C40/C27 -> 0.010863289 | D43: =D40/D27 -> 0.029843638 | E43: =E40/E27 -> 0.040247729 | F43: =F40/F27 -> 0.044456747 | G43: =G40/G27 -> 0.052206278 | H43: =H40/H27 -> 0.077210556 | I43: =I40/I27 -> 0.10689189 | ... AH43: =AH40/AH27 -> 0.084033595
A45: Financial and operating Costs
A46: Interest expense on deposits | B46: =soci!B13 + soci!B16 -> 2425390 | C46: =soci!C13 + soci!C16 -> 18708 | D46: =soci!D13 + soci!D16 -> 37959 | E46: =soci!E13 + soci!E16 -> 45177 | F46: =soci!F13 + soci!F16 -> 53343 | G46: =soci!G13 + soci!G16 -> 62403 | H46: =soci!H13 + soci!H16 -> 70755 | I46: =soci!I13 + soci!I16 -> 82203 | ... AH46: =soci!AH13 + soci!AH16 -> 88681
A47: Dividend expense on share capital | B47: =soci!B15 -> 0 | C47: =soci!C15 -> 0 | D47: =soci!D15 -> 0 | E47: =soci!E15 -> 0 | F47: =soci!F15 -> 0 | G47: =soci!G15 -> 0 | H47: =soci!H15 -> 0 | I47: =soci!I15 -> 0 | ... AH47: =soci!AH15 -> 0
A48: Interest expense on borrowed funds | B48: =soci!B14 -> 0 | C48: =soci!C14 -> 0 | D48: =soci!D14 -> 0 | E48: =soci!E14 -> 0 | F48: =soci!F14 -> 0 | G48: =soci!G14 -> 0 | H48: =soci!H14 -> 0 | I48: =soci!I14 -> 0 | ... AH48: =soci!AH14 -> 0
...

Sheet caels
A1: KOLENGE SACCO SOCIETY | C1: Audited 2019 | D1: 43831 | E1: 43862 | F1: 43891 | G1: 43922 | H1: 43952 | I1: 43983 | J1: 44044 | K1: 44075 | L1: 44105 | M1: 44136 | N1: 44166 | O1: AUDITED 2020 | P1: 44197 | Q1: 44228 | R1: 44256 | S1: 44287 | T1: 44317 | U1: 44348 | V1: 44378 | W1: 44409 | X1: 44440 | Y1: 44470 | Z1: 44501 | AA1: 44531 | AB1: Audited 2021 | AC1: 44562 | AD1: 44593 | AE1: 44621 | AF1: 44652 | AG1: 44682 | AH1: 44713 | AI1: 44743
A2: CAPITAL ADEQUACY
A3: Core Capital | B3: > Kshs. 10 Million | C3: =financials!B11 -> 49513013 | D3: =financials!C11 -> 50440317 | E3: =financials!D11 -> 50895644 | F3: =financials!E11 -> 51500078 | G3: =financials!F11 -> 52184932 | H3: =financials!G11 -> 52845547 | I3: =financials!H11 -> 54530787 | J3: =financials!I11 -> 56097989 | ... AI3: =financials!AH11 -> 20047978
A4: Core Capital to Total Assets | B4: Min. 10% | C4: =financials!B11 /financials!B3 -> 0.34299683 | D4: =financials!C11 /financials!C3 -> 0.36032431 | E4: =financials!D11 /financials!D3 -> 0.35934478 | F4: =financials!E11 /financials!E3 -> 0.33040784 | G4: =financials!F11 /financials!F3 -> 0.34960818 | H4: =financials!G11 /financials!G3 -> 0.35334345 | I4: =financials!H11 /financials!H3 -> 0.3609899 | J4: =financials!I11 /financials!I3 -> 0.36236893 | ... AI4: =financials!AH11 /financials!AH3 -> 0.11662148
A5: Core Capital to Total Deposits | B5: Min. 8% | C5: =financials!B11 /financials!B4 -> 0.55248312 | D5: =financials!C11 /financials!C4 -> 0.57206984 | E5: =financials!D11 /financials!D4 -> 0.56890093 | F5: =financials!E11 /financials!E4 -> 0.49907796 | G5: =financials!F11 /financials!F4 -> 0.53753471 | H5: =financials!G11 /financials!G4 -> 0.54641596 | I5: =financials!H11 /financials!H4 -> 0.5649205 | J5: =financials!I11 /financials!I4 -> 0.56830501 | ... AI5: =financials!AH11 /financials!AH4 -> 0.18653178
A6: Institutional Capital to Total Assets | B6: Min 8% | C6: =financials!B12 /financials!B3 -> 0.3070713 | D6: =financials!C12 /financials!C4 -> 0.51325272 | E6: =financials!D12 /financials!D4 -> 0.5109329 | F6: =financials!E12 /financials!E3 -> 0.29713615 | G6: =financials!F12 /financials!F4 -> 0.48411593 | H6: =financials!G12 /financials!G4 -> 0.4927934 | I6: =financials!H12 /financials!H3 -> 0.32665896 | J6: =financials!I12 /financials!I4 -> 0.51576784 | K6: =financials!J12 /financials!J3 -> 0.33031014 | L6: =financials!K12 /financials!K4 -> 0.51954415 | M6: =financials!L12 /financials!L4 -> 0.51529621 | N6: =financials!M12 /financials!M3 -> 0.29790859 | O6: =financials!N12 /financials!N3 -> 0.29347444 | P6: =financials!O12 /financials!O3 -> 0.55084229 | Q6: =financials!P12 /financials!P3 -> 0.55194381 | R6: =financials!Q12 /financials!Q3 -> 0.287633 | S6: =financials!R12 /financials!R3 -> 0.29325514 | T6: =financials!S12 /financials!S3 -> 0.3063941 | U6: =financials!T12 /financials!T3 -> 0.30606699 | ... AI6: =financials!AH12 /financials!AH3 -> 0.27793051
A7: ASSET QUALITY
A8: A/LNPL30
A9: NPL30
A10: EARNINGS
A11: ROA | C11: =soci!B33 /sofp!B25 -> 0.016136809 | D11: =soci!C33 /sofp!C25 -> -0.0083610924 | E11: =soci!D33 /sofp!D25 -> -0.0065881427 | F11: =soci!E33 /sofp!E25 -> -0.0063917299 | G11: =soci!F33 /sofp!F25 -> -0.0058251208 | H11: =soci!G33 /sofp!G25 -> -0.005271039 | I11: =soci!H33 /sofp!H25 -> 0.0023854887 | J11: =soci!I33 /sofp!I25 -> 0.010050158 | ... AI11: =soci!AH33 /sofp!AH25 -> 0.028974495
A12: Cost Income Ratio | C12: =soci!B23 /sofp!B19 -> 0.13146178 | D12: =soci!C23 /sofp!C19 -> 0.010775019 | E12: =soci!D23 /sofp!D19 -> 0.027195035 | F12: =soci!E23 /sofp!E19 -> 0.038157844 | G12: =soci!F23 /sofp!F19 -> 0.049776598 | H12: =soci!G23 /sofp!G19 -> 0.059914136 | I12: =soci!H23 /sofp!H19 -> 0.069670443 | J12: =soci!I23 /sofp!I19 -> 0.092807151 | ... AI12: =soci!AH23 /sofp!AH19 -> 0.080051093
A13: Operating Expense Ratio | C13: =(soci!B12 + soci!B23) / ((sofp!B25 + sofp!C25)/2) -> 0.068386071 | D13: =(soci!C12 + soci!C23) / ((sofp!C25 + sofp!D25)/2) -> 0.0043787155 | E13: =(soci!D12 + soci!D23) / ((sofp!D25 + sofp!E25)/2) -> 0.010396018 | F13: =(soci!E12 + soci!E23) / ((sofp!E25 + sofp!F25)/2) -> 0.014131006 | G13: =(soci!F12 + soci!F23) / ((sofp!F25 + sofp!G25)/2) -> 0.018782346 | H13: =(soci!G12 + soci!G23) / ((sofp!G25 + sofp!H25)/2) -> 0.022388019 | I13: =(soci!H12 + soci!H23) / ((sofp!H25 + sofp!I25)/2) -> 0.025669058 | J13: =(soci!I12 + soci!I23) / ((sofp!I25 + sofp!K25)/2) -> 0.033365823 | K13: =(soci!J12 + soci!J23) / ((sofp!J25 + sofp!L25)/2) -> 0.03623693 | L13: =(soci!K12 + soci!K23) / ((sofp!K25 + sofp!M25)/2) -> 0.040085682 | M13: =(soci!L12 + soci!L23) / ((sofp!L25 + sofp!N25)/2) -> 0.044138807 | N13: =(soci!M12 + soci!M23) / ((sofp!M25 + sofp!O25)/2) -> 0.051323912 | O13: =(soci!N12 + soci!N23) / ((sofp!N25 + sofp!P25)/2) -> 0.073273486 | P13: =(soci!O12 + soci!O23) / ((sofp!O25 + sofp!Q25)/2) -> 0.0028237828 | Q13: =(soci!P12 + soci!P23) / ((sofp!P25 + sofp!R25)/2) -> 0.0058704829 | R13: =(soci!Q12 + soci!Q23) / ((sofp!Q25 + sofp!S25)/2) -> 0.010875524 | S13: =(soci!R12 + soci!R23) / ((sofp!R25 + sofp!S25)/2) -> 0.016195976 | T13: =(soci!S12 + soci!S23) / ((sofp!S25 + sofp!U25)/2) -> 0.022288757 | U13: =(soci!T12 + soci!T23) / ((sofp!T25 + sofp!V25)/2) -> 0.025728579 | V13: =(soci!U12 + soci!U23) / ((sofp!U25 + sofp!W25)/2) -> 0.060407929 | W13: =(soci!V12 + soci!V23) / ((sofp!V25 + sofp!X25)/2) -> 0.065240538 | X13: =(soci!W12 + soci!W23) / ((sofp!W25 + sofp!Y25)/2) -> #DIV/0! | Y13: =(soci!X12 + soci!X23) / ((sofp!X25 + sofp!Z25)/2) -> #DIV/0! | Z13: =(soci!Y12 + soci!Y23) / ((sofp!Y25 + sofp!AA25)/2) -> 0 | AA13: =(soci!Z12 + soci!Z23) / ((sofp!Z25 + sofp!AB25)/2) -> 0 | ... AI13: =(soci!AH12 + soci!AH23) / ((sofp!AH25 + sofp!AJ25)/2) -> 0.051534192
A14: LIQUIDITY
A15: Min Liquidity Ratio | B15: Min 15% | C15: =financials!B33/(financials!B8+financials!B6) -> 0.21266856 | D15: =financials!C33/(financials!C8+financials!C6) -> 0.16635213 | E15: =financials!D33/(financials!D8+financials!D6) -> 0.17656405 | F15: =financials!E33/(financials!E8+financials!E6) -> 0.32723677 | G15: =financials!F33/(financials!F8+financials!F6) -> 0.26377403 | H15: =financials!G33/(financials!G8+financials!G6) -> 0.21383487 | I15: =financials!H33/(financials!H8+financials!H6) -> 0.22223715 | J15: =financials!I33/(financials!I8+financials!I6) -> 0.214854 | ... AI15: =financials!AH33/(financials!AH8+financials!AH6) -> 0.13824037
A16: T/LIQ Ratio | C16: =financials!B33/financials!B3 -> 0.13972395 | D16: =financials!C33/financials!C3 -> 0.10641142 | E16: =financials!D33/financials!D3 -> 0.11311668 | F16: =financials!E33/financials!E3 -> 0.21911517 | G16: =financials!F33/financials!F3 -> 0.17155647 | H16: =financials!G33/financials!G3 -> 0.13827772 | I16: =financials!H33/financials!H3 -> 0.14201178 | J16: =financials!I33/financials!I3 -> 0.13699758 | ... AI16: =financials!AH33/financials!AH3 -> 0.087770978
A17: External Borrowing to TA Ratio | B17: Max 25% | C17: =sofp!B35 / sofp!B25 -> 0 | D17: =sofp!C35 / sofp!C25 -> 0 | E17: =sofp!D35 / sofp!D25 -> 0 | F17: =sofp!E35 / sofp!E25 -> 0 | G17: =sofp!F35 / sofp!F25 -> 0 | H17: =sofp!G35 / sofp!G25 -> 0 | I17: =sofp!H35 / sofp!H25 -> 0 | J17: =sofp!I35 / sofp!I25 -> 0 | ... AI17: =sofp!AH35 / sofp!AH25 -> 0
A18: Liquid Assets to TA Ratio | C18: =financials!B33 / financials!B3 -> 0.13972395 | D18: =financials!C33 / financials!C3 -> 0.10641142 | E18: =financials!D33 / financials!D3 -> 0.11311668 | F18: =financials!E33 / financials!E3 -> 0.21911517 | G18: =financials!F33 / financials!F3 -> 0.17155647 | H18: =financials!G33 / financials!G3 -> 0.13827772 | I18: =financials!H33 / financials!H3 -> 0.14201178 | J18: =financials!I33 / financials!I3 -> 0.13699758 | ... AI18: =financials!AH33 / financials!AH3 -> 0.087770978
A19: STRUCTURE
A20: Non-Earning to TA Ratio | B20: Max 10% | C20: =financials!B35 / financials!B3 -> 0.46744669 | D20: =financials!C35 / financials!C3 -> 0.45561824 | E20: =financials!D35 / financials!D3 -> 0.46669979 | F20: =financials!E35 / financials!E3 -> 0.4212639 | G20: =financials!F35 / financials!F3 -> 0.43660993 | H20: =financials!G35 / financials!G3 -> 0.44709274 | I20: =financials!H35 / financials!H3 -> 0.44222 | J20: =financials!I35 / financials!I3 -> 0.44132519 | ... AI20: =financials!AH35 / financials!AH3 -> 0.4171181
A21: LB Ratio | B21: Max 5% | C21: =financials!B36 / financials!B3 -> 0.38275056 | D21: =financials!C36 / financials!C3 -> 0.021866137 | E21: =financials!D36 / financials!D3 -> 0.021538267 | F21: =financials!E36 / financials!E3 -> 0.019478892 | G21: =financials!F36 / financials!F3 -> 0.02061339 | H21: =financials!G36 / financials!G3 -> 0.019690095 | I21: =financials!H36 / financials!H3 -> 0.020025049 | J21: =financials!I36 / financials!I3 -> 0.019430941 | ... AI21: =financials!AH36 / financials!AH3 -> 0.017245321
A22: Investments to Deposit Ratio | B22: Max 5% | C22: =financials!B22 / financials!B4 -> 0.007379045 | D22: =financials!C22 / financials!C4 -> 0.0075001809 | E22: =financials!D22 / financials!D4 -> 0.0073919075 | F22: =financials!E22 / financials!E4 -> 0.0064085679 | G22: =financials!F22 / financials!F4 -> 0.0068118 | H22: =financials!G22 / financials!G4 -> 0.0068377854 | I22: =financials!H22 / financials!H4 -> 0.0068508753 | J22: =financials!I22 / financials!I4 -> 0.0066993812 | ... AI22: =financials!AH22 / financials!AH4 -> 0.043500277
A23: Investments to Core Capital Ratio | B23: Max 40% | C23: =financials!B22 / C3 -> 0.013356145 | D23: =financials!C22 / D3 -> 0.013110603 | E23: =financials!D22 / E3 -> 0.012993312 | F23: =financials!E22 / F3 -> 0.012840815 | G23: =financials!F22 / G3 -> 0.012672298 | H23: =financials!G22 / H3 -> 0.012513883 | I23: =financials!H22 / I3 -> 0.012127149 | J23: =financials!I22 / J3 -> 0.011788355 | ... AI23: =financials!AH22 / AI3 -> 0.23320571
A24: Gross loans/TA | C24: =financials!B27 / financials!B3 -> 0.39739642 | D24: =financials!C27 / financials!C3 -> 0.44344897 | E24: =financials!D27 / financials!D3 -> 0.42630153 | F24: =financials!E27 / financials!E3 -> 0.36589209 | G24: =financials!F27 / financials!F3 -> 0.3966878 | H24: =financials!G27 / financials!G3 -> 0.42083675 | I24: =financials!H27 / financials!H3 -> 0.42221052 | J24: =financials!I27 / financials!I3 -> 0.42836052 | ... AI24: =financials!AH27 / financials!AH3 -> 0.47735689
A25: FUNDING MIX
A26: Total Deposits/Total Assets | C26: =financials!B4 / financials!B3 -> 0.62082771 | D26: =financials!C4 / financials!C3 -> 0.6298607 | E26: =financials!D4 / financials!D3 -> 0.63164739 | F26: =financials!E4 / financials!E3 -> 0.66203654 | G26: =financials!F4 / financials!F3 -> 0.65039182 | H26: =financials!G4 / financials!G3 -> 0.64665655 | I26: =financials!H4 / financials!H3 -> 0.6390101 | J26: =financials!I4 / financials!I3 -> 0.63763107 | ... AI26: =financials!AH4 / financials!AH3 -> 0.62520967
A27: BOSA Deposits/Total Assets | C27: =financials!B5 / financials!B3 -> 0.51266662 | D27: =financials!C5 / financials!C3 -> 0.53511993 | E27: =financials!D5 / financials!D3 -> 0.53537768 | F27: =financials!E5 / financials!E3 -> 0.48761965 | G27: =financials!F5 / financials!F3 -> 0.51483674 | H27: =financials!G5 / financials!G3 -> 0.52021816 | I27: =financials!H5 / financials!H3 -> 0.5186778 | J27: =financials!I5 / financials!I3 -> 0.51964651 | ... AI27: =financials!AH5 / financials!AH3 -> 0.53949626
A28: FOSA Deposits/Total Assets | C28: =financials!B6 / financials!B3 -> 0.62082771 | D28: =financials!C6 / financials!C3 -> 0.6298607 | E28: =financials!D6 / financials!D3 -> 0.63164739 | F28: =financials!E6 / financials!E3 -> 0.66203654 | G28: =financials!F6 / financials!F3 -> 0.65039182 | H28: =financials!G6 / financials!G3 -> 0.64665655 | I28: =financials!H6 / financials!H3 -> 0.6390101 | J28: =financials!I6 / financials!I3 -> 0.63763107 | ... AI28: =financials!AH6 / financials!AH3 -> 0.62520967
A29: GROWTH RATIOS
A30: Total Assets | C30: =(financials!C3 / financials!B3) - 1 -> -0.030260686 | D30: =(financials!D3 / financials!C3) - 1 -> 0.011777503 | E30: =(financials!E3 / financials!D3) - 1 -> 0.10049551 | F30: =(financials!F3 / financials!E3) - 1 -> -0.042351799 | G30: =(financials!G3 / financials!F3) - 1 -> 0.0019540659 | H30: =(financials!H3 / financials!G3) - 1 -> 0.01003254 | I30: =(financials!I3 / financials!H3) - 1 -> 0.02482479 | J30: =(financials!K3 / financials!I3) - 1 -> 0.01926066 | K30: =(financials!L3 / financials!J3) - 1 -> 0.015128819 | L30: =(financials!M3 / financials!K3) - 1 -> 0.018056973 | M30: =(financials!N3 / financials!L3) - 1 -> 0.0067656761 | N30: =(financials!O3 / financials!M3) - 1 -> -0.032673619 | O30: =(financials!P3 / financials!N3) - 1 -> -0.027300276 | P30: =(financials!Q3 / financials!O3) - 1 -> 0.080632691 | Q30: =(financials!R3 / financials!P3) - 1 -> 0.070442753 | R30: =(financials!S3 / financials!Q3) - 1 -> -0.045671002 | S30: =(financials!S3 / financials!R3) - 1 -> -0.04190844 | T30: =(financials!U3 / financials!S3) - 1 -> 0.016080793 | U30: =(financials!V3 / financials!T3) - 1 -> 0.0084883476 | V30: =(financials!W3 / financials!U3) - 1 -> -1 | W30: =(financials!X3 / financials!V3) - 1 -> -1 | X30: =(financials!Y3 / financials!W3) - 1 -> #DIV/0! | Y30: =(financials!Z3 / financials!X3) - 1 -> #DIV/0! | Z30: =(financials!AA3 / financials!Y3) - 1 -> #DIV/0! | AA30: =(financials!AB3 / financials!Z3) - 1 -> #DIV/0! | ... AI30: =(financials!AJ3 / financials!AH3) - 1 -> -1
A31: Total Deposits | C31: =(financials!C4 / financials!B4) - 1 -> -0.016151063 | D31: =(financials!D4 / financials!C4) - 1 -> 0.014647551 | E31: =(financials!E4 / financials!D4) - 1 -> 0.15344139 | F31: =(financials!F4 / financials!E4) - 1 -> -0.059196103 | G31: =(financials!G4 / financials!F4) - 1 -> -0.0038002741 | H31: =(financials!H4 / financials!G4) - 1 -> -0.001910683 | I31: =(financials!I4 / financials!H4) - 1 -> 0.022613147 | J31: =(financials!K4 / financials!I4) - 1 -> 0.017393555 | K31: =(financials!L4 / financials!J4) - 1 -> 0.017985103 | L31: =(financials!M4 / financials!K4) - 1 -> 0.021480313 | M31: =(financials!N4 / financials!L4) - 1 -> 0.0069476049 | N31: =(financials!O4 / financials!M4) - 1 -> -0.0063485143 | O31: =(financials!P4 / financials!N4) - 1 -> -0.0042470065 | P31: =(financials!Q4 / financials!O4) - 1 -> 0.11565397 | Q31: =(financials!R4 / financials!P4) - 1 -> 0.068750825 | R31: =(financials!S4 / financials!Q4) - 1 -> -0.10122899 | S31: =(financials!S4 / financials!R4) - 1 -> -0.063765646 | T31: =(financials!U4 / financials!S4) - 1 -> 0.013743673 | U31: =(financials!V4 / financials!T4) - 1 -> -0.0049012197 | V31: =(financials!W4 / financials!U4) - 1 -> -1 | W31: =(financials!X4 / financials!V4) - 1 -> -1 | X31: =(financials!Y4 / financials!W4) - 1 -> #DIV/0! | Y31: =(financials!Z4 / financials!X4) - 1 -> #DIV/0! | Z31: =(financials!AA4 / financials!Y4) - 1 -> #DIV/0! | AA31: =(financials!AB4 / financials!Z4) - 1 -> #DIV/0! | ... AI31: =(financials!AJ4 / financials!AH4) - 1 -> -1
A32: BOSA Deposits | C32: =(financials!C5 / financials!B5) - 1 -> 0.012211093 | D32: =(financials!D5 / financials!C5) - 1 -> 0.012264839 | E32: =(financials!E5 / financials!D5) - 1 -> 0.0023264859 | F32: =(financials!F5 / financials!E5) - 1 -> 0.011100512 | G32: =(financials!G5 / financials!F5) - 1 -> 0.012427167 | H32: =(financials!H5 / financials!G5) - 1 -> 0.0070418511 | I32: =(financials!I5 / financials!H5) - 1 -> 0.026738802 | J32: =(financials!K5 / financials!I5) - 1 -> 0.018992656 | K32: =(financials!L5 / financials!J5) - 1 -> 0.02001803 | L32: =(financials!M5 / financials!K5) - 1 -> 0.025886449 | M32: =(financials!N5 / financials!L5) - 1 -> 0.011669624 | N32: =(financials!O5 / financials!M5) - 1 -> 0.011180108 | O32: =(financials!P5 / financials!N5) - 1 -> 0.020664527 | P32: =(financials!Q5 / financials!O5) - 1 -> 0.013889677 | Q32: =(financials!R5 / financials!P5) - 1 -> 0.012151208 | R32: =(financials!S5 / financials!Q5) - 1 -> 0.0065213861 | S32: =(financials!S5 / financials!R5) - 1 -> -0.0011188754 | T32: =(financials!U5 / financials!S5) - 1 -> 0.019375688 | U32: =(financials!V5 / financials!T5) - 1 -> 0.01885419 | V32: =(financials!W5 / financials!U5) - 1 -> -1 | W32: =(financials!X5 / financials!V5) - 1 -> -1 | X32: =(financials!Y5 / financials!W5) - 1 -> #DIV/0! | Y32: =(financials!Z5 / financials!X5) - 1 -> #DIV/0! | Z32: =(financials!AA5 / financials!Y5) - 1 -> #DIV/0! | AA32: =(financials!AB5 / financials!Z5) - 1 -> #DIV/0! | ... AI32: =(financials!AJ5 / financials!AH5) - 1 -> -1
A33: FOSA Deposits | C33: =(financials!C6 / financials!B6) - 1 -> -0.016151063 | D33: =(financials!D6 / financials!C6) - 1 -> 0.014647551 | E33: =(financials!E6 / financials!D6) - 1 -> 0.15344139 | F33: =(financials!F6 / financials!E6) - 1 -> -0.059196103 | G33: =(financials!G6 / financials!F6) - 1 -> -0.0038002741 | H33: =(financials!H6 / financials!G6) - 1 -> -0.001910683 | I33: =(financials!I6 / financials!H6) - 1 -> 0.022613147 | J33: =(financials!K6 / financials!I6) - 1 -> 0.017393555 | K33: =(financials!L6 / financials!J6) - 1 -> 0.017985103 | L33: =(financials!M6 / financials!K6) - 1 -> 0.021480313 | M33: =(financials!N6 / financials!L6) - 1 -> 0.0069476049 | N33: =(financials!O6 / financials!M6) - 1 -> -0.0063485143 | O33: =(financials!P6 / financials!N6) - 1 -> -0.0042470065 | P33: =(financials!Q6 / financials!O6) - 1 -> 0.11565397 | Q33: =(financials!R6 / financials!P6) - 1 -> 0.068750825 | R33: =(financials!S6 / financials!Q6) - 1 -> -0.10122899 | S33: =(financials!S6 / financials!R6) - 1 -> -0.063765646 | T33: =(financials!U6 / financials!S6) - 1 -> 0.013743673 | U33: =(financials!V6 / financials!T6) - 1 -> -0.0049012197 | V33: =(financials!W6 / financials!U6) - 1 -> -1 | W33: =(financials!X6 / financials!V6) - 1 -> -1 | X33: =(financials!Y6 / financials!W6) - 1 -> #DIV/0! | Y33: =(financials!Z6 / financials!X6) - 1 -> #DIV/0! | Z33: =(financials!AA6 / financials!Y6) - 1 -> #DIV/0! | AA33: =(financials!AB6 / financials!Z6) - 1 -> #DIV/0! | ... AI33: =(financials!AJ6 / financials!AH6) - 1 -> -1
A34: Total Loans & Advances | C34: =(financials!C27 / financials!B27) - 1 -> 0.082118183 | D34: =(financials!D27 / financials!C27) - 1 -> -0.027346252 | E34: =(financials!E27 / financials!D27) - 1 -> -0.055451194 | F34: =(financials!F27 / financials!E27) - 1 -> 0.038249724 | G34: =(financials!G27 / financials!F27) - 1 -> 0.062949462 | H34: =(financials!H27 / financials!G27) - 1 -> 0.013329674 | I34: =(financials!I27 / financials!H27) - 1 -> 0.039752594 | J34: =(financials!K27 / financials!I27) - 1 -> 0.022497301 | K34: =(financials!L27 / financials!J27) - 1 -> 0.026812986 | L34: =(financials!M27 / financials!K27) - 1 -> 0.018170266 | M34: =(financials!N27 / financials!L27) - 1 -> 0.0065900228 | N34: =(financials!O27 / financials!M27) - 1 -> 0.079723325 | O34: =(financials!P27 / financials!N27) - 1 -> 0.091969332 | P34: =(financials!Q27 / financials!O27) - 1 -> -0.058592879 | Q34: =(financials!R27 / financials!P27) - 1 -> 0.0037084395 | R34: =(financials!S27 / financials!Q27) - 1 -> 0.23494164 | S34: =(financials!S27 / financials!R27) - 1 -> 0.14529767 | T34: =(financials!U27 / financials!S27) - 1 -> 0.10909982 | U34: =(financials!V27 / financials!T27) - 1 -> -0.017094301 | V34: =(financials!W27 / financials!U27) - 1 -> -1 | W34: =(financials!X27 / financials!V27) - 1 -> -1 | X34: =(financials!Y27 / financials!W27) - 1 -> #DIV/0! | Y34: =(financials!Z27 / financials!X27) - 1 -> #DIV/0! | Z34: =(financials!AA27 / financials!Y27) - 1 -> #DIV/0! | AA34: =(financials!AB27 / financials!Z27) - 1 -> #DIV/0! | ... AI34: =(financials!AJ27 / financials!AH27) - 1 -> -1
A35: Core Capital | C35: =(financials!C11 / financials!B11) - 1 -> 0.018728503 | D35: =(financials!D11 / financials!C11) - 1 -> 0.009027028 | E35: =(financials!E11 / financials!D11) - 1 -> 0.011875958 | F35: =(financials!F11 / financials!E11) - 1 -> 0.013298106 | G35: =(financials!G11 / financials!F11) - 1 -> 0.012659124 | H35: =(financials!H11 / financials!G11) - 1 -> 0.031889922 | I35: =(financials!I11 / financials!H11) - 1 -> 0.028739754 | J35: =(financials!K11 / financials!I11) - 1 -> 0.022546052 | K35: =(financials!L11 / financials!J11) - 1 -> 0.010123127 | L35: =(financials!M11 / financials!K11) - 1 -> -0.075323099 | M35: =(financials!N11 / financials!L11) - 1 -> -0.092805669 | N35: =(financials!O11 / financials!M11) - 1 -> -0.0055991174 | O35: =(financials!P11 / financials!N11) - 1 -> 0.020311677 | P35: =(financials!Q11 / financials!O11) - 1 -> 0.014040238 | Q35: =(financials!R11 / financials!P11) - 1 -> 0.015800879 | R35: =(financials!S11 / financials!Q11) - 1 -> 0.014968691 | S35: =(financials!S11 / financials!R11) - 1 -> 0.00092044261 | T35: =(financials!U11 / financials!S11) - 1 -> -0.030053633 | U35: =(financials!V11 / financials!T11) - 1 -> -0.016417041 | V35: =(financials!W11 / financials!U11) - 1 -> -1 | W35: =(financials!X11 / financials!V11) - 1 -> -1 | X35: =(financials!Y11 / financials!W11) - 1 -> #DIV/0! | Y35: =(financials!Z11 / financials!X11) - 1 -> #DIV/0! | Z35: =(financials!AA11 / financials!Y11) - 1 -> #DIV/0! | AA35: =(financials!AB11 / financials!Z11) - 1 -> #DIV/0! | ... AI35: =(financials!AJ11 / financials!AH11) - 1 -> -1
A36: Turnover | C36: =(financials!C39 / financials!B39) - 1 -> -0.92744973 | D36: =(financials!D39 / financials!C39) - 1 -> 1.448788 | E36: =(financials!E39 / financials!D39) - 1 -> 0.3069897 | F36: =(financials!F39 / financials!E39) - 1 -> 0.18733839 | G36: =(financials!G39 / financials!F39) - 1 -> 0.25392933 | H36: =(financials!H39 / financials!G39) - 1 -> 0.42099893 | I36: =(financials!I39 / financials!H39) - 1 -> 0.43009491 | J36: =(financials!K39 / financials!I39) - 1 -> 0.21673884 | K36: =(financials!L39 / financials!J39) - 1 -> 0.2171948 | L36: =(financials!M39 / financials!K39) - 1 -> 0.18128034 | M36: =(financials!N39 / financials!L39) - 1 -> 0.29146253 | N36: =(financials!O39 / financials!M39) - 1 -> -0.91443305 | O36: =(financials!P39 / financials!N39) - 1 -> -0.84799987 | P36: =(financials!Q39 / financials!O39) - 1 -> 2.5217354 | Q36: =(financials!R39 / financials!P39) - 1 -> 1.2403076 | R36: =(financials!S39 / financials!Q39) - 1 -> 0.75215017 | S36: =(financials!S39 / financials!R39) - 1 -> 0.26414504 | T36: =(financials!U39 / financials!S39) - 1 -> 0.42538291 | U36: =(financials!V39 / financials!T39) - 1 -> 0.3595355 | V36: =(financials!W39 / financials!U39) - 1 -> -1 | W36: =(financials!X39 / financials!V39) - 1 -> -1 | X36: =(financials!Y39 / financials!W39) - 1 -> #DIV/0! | Y36: =(financials!Z39 / financials!X39) - 1 -> #DIV/0! | Z36: =(financials!AA39 / financials!Y39) - 1 -> #DIV/0! | AA36: =(financials!AB39 / financials!Z39) - 1 -> #DIV/0! | ... AI36: =(financials!AJ39 / financials!AH39) - 1 -> -1
A37: Membership
