Workbook

Sheet Evolutive SFP
B3: 2010 Audited | C3: 2011 Audited | D3: 2012 Audited | E3: 2013 Audited | F3: 2014 Audited | G3: 2015 Audited | H3: Audited-2016 | I3: 42736 | J3: 42767 | K3: 42795 | L3: 42826 | M3: 42856 | N3: 42887 | O3: 42917 | P3: 42948 | Q3: 42979 | R3: 43009 | S3: 43040 | T3: 43070 | U3: Audited 2017 | V3: 43101 | W3: 43132 | X3: 43160 | Y3: 43191 | Z3: 43221 | AA3: 43252 | AB3: 43282 | AC3: 43313 | AD3: 43344 | AE3: 43374 | AF3: 43405 | AG3: 43435 | AH3: Audited 2018 | AI3: 43466 | AJ3: 43497 | AK3: 43525 | AL3: 43556 | AM3: 43586 | AN3: 43617 | AO3: 43647 | AP3: 43678 | AQ3: 43709 | AR3: 43739 | AS3: 43770 | AT3: 43800 | AU3: Aud-19 | AV3: 43862 | AW3: 43891 | AX3: 43922 | AY3: 43952 | AZ3: 43983 | BA3: 44013 | BB3: 44044 | BC3: 44075 | BD3: 44105 | BE3: 44136 | BF3: 44166 | BG3: Audited 2020 | BH3: 44197 | BI3: 44228 | BJ3: 44256 | BK3: 44287 | BL3: 44317 | BM3: 44348 | BN3: 44378 | BO3: 44409 | BP3: 44440 | BQ3: 44470 | BR3: 44501 | BS3: 44531 | BT3: AUDITED 2021 | BU3: 44562 | BV3: 44593 | BW3: 44621 | BX3: 44652 | BY3: 44682 | BZ3: 44713 | CA3: 44743 | CB3: 44774 | CC3: 44805 | CD3: 44835 | CE3: 44866 | CF3: 44896 | CG3: Audited 2022 | CH3: 44927 | CI3: 44958 | CJ3: 44986 | CK3: 45017 | CL3: 45047 | CM3: 45078 | CN3: 45108 | CO3: 45139 | CP3: 45170
A4: Cash & cash Equivalent | B4: =SUM(B5:B6) -> 57280489 | C4: =SUM(C5:C6) -> 19846649 | D4: =SUM(D5:D6) -> 12419314 | E4: =SUM(E5:E6) -> 40164453 | F4: =SUM(F5:F6) -> 49731794 | G4: =SUM(G5:G6) -> 72857216 | H4: =SUM(H5:H6) -> 36146766 | I4: =SUM(I5:I6) -> 24906108 | ... CP4: =SUM(CP5:CP6) -> 1.2038067e+08
A5: Cash In Hand | B5: 42792387 | C5: 3657881 | D5: 5498182 | E5: 2528632.8 | F5: 4097074 | G5: 2142692 | H5: 616773 | I5: 1274435.1 | J5: 9622851.9 | K5: 11215420 | L5: 3718678.4 | M5: 3130207.4 | N5: 3057417.1 | O5: 607114.25 | P5: 4984664.2 | Q5: 1307731.6 | R5: 4788129.6 | S5: 2171891.6 | T5: 2275034.6 | U5: 2295202 | V5: 2566469.6 | W5: 659071.6 | X5: 3304159.6 | Y5: 3112409.6 | Z5: 863851.4 | AA5: 5539159.4 | AB5: 5260229.4 | AC5: 8493587.6 | AD5: 4785883.4 | AE5: 4834666.1 | AF5: 3608998.1 | AG5: 5697079.8 | AH5: 5716646.8 | AI5: 5873655.8 | AJ5: 4339155.8 | AK5: 2439301.8 | AL5: 3908512.8 | AM5: 5401982.4 | AN5: 3462266.6 | AO5: 5281359.4 | AP5: 4332265.4 | AQ5: 2000357.4 | AR5: 3160732.4 | AS5: 3938515.4 | AT5: 4423576.4 | AU5: 4470464.5 | AV5: 3697628.4 | AW5: 5093580.6 | AX5: 4414958.6 | AY5: 4487148.6 | AZ5: 2322674.6 | BB5: 30536363 | BC5: 6523160.6 | BD5: 1758342.6 | BE5: 2799575.2 | BF5: 6916205.2 | BG5: =475+6000000+915730+5+1957116 -> 8873326 | BH5: 7868919.2 | BI5: 2464328.2 | BJ5: 3543201.2 | BK5: 4686877.2 | BL5: 3687249.2 | BM5: 5268448.2 | BN5: 3586157.2 | BO5: 5172829.2 | BP5: 4712634.7 | BQ5: 4083501.7 | BR5: 4409943.7 | BS5: 4494213 | BT5: =317+2100000+276861+5+2117030 -> 4494213 | BU5: 4715834.2 | BV5: 3959109.2 | BW5: 5722311.2 | BX5: 2235063.2 | BY5: 5149850.2 | BZ5: 6884467.2 | CA5: 2690159.2 | CB5: 5924509.2 | CC5: 4803588.2 | CD5: 2460256.2 | CE5: 4997653.2 | CF5: 6682379.7 | CG5: 7358553 | CH5: 5464582.2 | CI5: 5945150.2 | CJ5: 4436375.2 | CK5: 6245041.2 | CL5: 6015164.2 | CM5: 3560673.2 | CN5: 6412658.2 | CO5: 3050344.2 | CP5: 3095541.2
A6: Cash at Bank | B6: 14488102 | C6: 16188768 | D6: 6921132 | E6: 37635820 | F6: 45634720 | G6: 70714524 | H6: 35529993 | I6: 23631673 | J6: 50282839 | K6: 39534472 | L6: 13027084 | M6: 37837805 | N6: 28160849 | O6: 38138637 | P6: 22761430 | Q6: 40766447 | R6: 36262575 | S6: 53797792 | T6: 47070062 | U6: 47049895 | V6: 56934852 | W6: 72189384 | X6: 61542081 | Y6: 40231590 | Z6: 42117104 | AA6: 55597424 | AB6: 59298763 | AC6: 44746707 | AD6: 54569798 | AE6: 62131670 | AF6: 58301667 | AG6: 55270669 | AH6: 55250801 | AI6: 60500765 | AJ6: 65508386 | AK6: 64485984 | AL6: 41413490 | AM6: 40781864 | AN6: 64068748 | AO6: 51843260 | AP6: 57422859 | AQ6: 72900408 | AR6: 76367215 | AS6: 65894319 | AT6: 66576836 | AU6: 66577436 | AV6: 94491873 | AW6: 73489004 | AX6: 98687848 | AY6: 1.0721277e+08 | AZ6: 1.1091437e+08 | BB6: 5.5124051e+08 | BC6: 1.0321167e+08 | BD6: 1.0913492e+08 | BE6: 1.1192079e+08 | BF6: 1.0625311e+08 | BG6: =2271280+939631+526483+21879119+17128282+3928427+42456814+16190387-(1024438) -> 104295985 | BH6: 1.1225204e+08 | BI6: 1.0073774e+08 | BJ6: 1.0249473e+08 | BK6: 1.0399239e+08 | BL6: 1.1003877e+08 | BM6: 1.0878372e+08 | BN6: 1.2067191e+08 | BO6: 1.3653578e+08 | BP6: 1.3584375e+08 | BQ6: 1.426082e+08 | BR6: 1.5629014e+08 | BS6: 155848611 | BT6: =160342825-4494213 -> 155848612 | BU6: 1.592191e+08 | BV6: 1.3888693e+08 | BW6: 1.023467e+08 | BX6: 99243027 | BY6: 1.0438703e+08 | BZ6: 1.2767785e+08 | CA6: 1.4275253e+08 | CB6: 1.4336091e+08 | CC6: 1.5841691e+08 | CD6: 1.6940507e+08 | CE6: 1.731117e+08 | CF6: 1.6680488e+08 | CG6: 166128708 | CH6: 1.6962797e+08 | CI6: 1.8485086e+08 | CJ6: 1.4360327e+08 | CK6: 78441494 | CL6: 1.1124177e+08 | CM6: 1.4509659e+08 | CN6: 1.5519755e+08 | CO6: 1.2005299e+08 | CP6: 1.1728513e+08
A7: Prepayment and Sundry | B7: 12265847 | C7: 18760041 | D7: 35908122 | E7: 28737959 | F7: 61660581 | G7: 32276918 | H7: 39005377 | I7: 0 | J7: 0 | K7: 0 | L7: 0 | M7: 0 | N7: 0 | O7: 0 | P7: 0 | Q7: 0 | R7: 0 | S7: 0 | T7: 0 | U7: 18725028 | V7: 0 | W7: 0 | X7: 0 | Y7: 0 | Z7: 0 | AA7: 0 | AB7: 0 | AC7: 0 | AD7: 0 | AE7: 0 | AF7: 0 | AG7: 0 | AH7: 12540117 | AI7: 0 | AJ7: 0 | AK7: 0 | AL7: 0 | AM7: 0 | AN7: 0 | AO7: 0 | AP7: 0 | AQ7: 0 | AR7: 0 | AS7: 0 | AT7: 0 | AU7: 12920590 | AV7: 0 | AW7: 0 | AX7: 0 | AY7: 0 | AZ7: 0 | BB7: 0 | BC7: 0 | BD7: 0 | BE7: 0 | BF7: 0 | BG7: 14085464 | BH7: 0 | BI7: 0 | BJ7: 0 | BK7: 0 | BL7: 0 | BM7: 0 | BN7: 0 | BO7: 0 | BP7: 0 | BQ7: 0 | BR7: 0 | BS7: 0 | BT7: =7618001+5173177-538512 -> 12252666 | BU7: 0 | BV7: 0 | BW7: 0 | BX7: 0 | BY7: 0 | BZ7: 0 | CA7: 0 | CB7: 0 | CC7: 0 | CD7: 0 | CE7: 0 | CF7: 0 | CG7: 1747956 | CH7: 0 | CI7: 0 | CJ7: 0 | CK7: 0 | CL7: 0 | CM7: 0 | CN7: 0 | CO7: 0 | CP7: 0
A8: Financial Investment | B8: =SUM(B9:B13) -> 12265847 | C8: =SUM(C9:C13) -> 13675347 | D8: =SUM(D9:D13) -> 25329658 | E8: =SUM(E9:E13) -> 27684833 | F8: =SUM(F9:F13) -> 14582790 | G8: =SUM(G9:G13) -> 28191601 | H8: =SUM(H9:H13) -> 32411253 | I8: =SUM(I9:I13) -> 39637678 | ... CP8: =SUM(CP9:CP13) -> 1.2930389e+08
A9: Government Security | B9: 3323677 | I9: 0 | J9: 0 | K9: 0 | L9: 0 | M9: 0 | N9: 0 | O9: 0 | P9: 0 | Q9: 0 | R9: 0 | S9: 0 | T9: 0 | V9: 0 | W9: 0 | X9: 0 | Y9: 0 | Z9: 0 | AA9: 0 | AB9: 0 | AC9: 0 | AD9: 0 | AE9: 0 | AF9: 0 | AG9: 0 | AH9: 0 | AI9: 0 | AJ9: 0 | AK9: 0 | AL9: 0 | AM9: 0 | AN9: 0 | AO9: 0 | AP9: 0 | AQ9: 0 | AR9: 0 | AS9: 0 | AT9: 0 | AV9: 0 | AW9: 0 | AX9: 0 | AY9: 0 | AZ9: 0 | BB9: 0 | BC9: 0 | BD9: 0 | BE9: 0 | BF9: 0 | BG9: 0 | BH9: 0 | BI9: 0 | BJ9: 0 | BK9: 0 | BL9: 0 | BM9: 0 | BN9: 0 | BO9: 0 | BP9: 0 | BQ9: 0 | BR9: 0 | BS9: 0 | BU9: 0 | BV9: 0 | BW9: 0 | BX9: 0 | BY9: 0 | BZ9: 0 | CA9: 0 | CB9: 0 | CC9: 0 | CD9: 0 | CE9: 0 | CF9: 0 | CG9: 0 | CH9: 0 | CI9: 0 | CJ9: 0 | CK9: 0 | CL9: 0 | CM9: 0 | CN9: 0 | CO9: 0 | CP9: 0
A10: Other Securities | B10: 8942170 | G10: 139800 | I10: 0 | J10: 0 | K10: 0 | L10: 0 | M10: 0 | N10: 0 | O10: 0 | P10: 0 | Q10: 0 | R10: 0 | S10: 0 | T10: 0 | V10: 0 | W10: 0 | X10: 0 | Y10: 0 | Z10: 0 | AA10: 0 | AB10: 0 | AC10: 0 | AD10: 0 | AE10: 0 | AF10: 0 | AG10: 0 | AH10: 0 | AI10: 0 | AJ10: 0 | AK10: 0 | AL10: 0 | AM10: 0 | AN10: 0 | AO10: 0 | AP10: 0 | AQ10: 0 | AR10: 0 | AS10: 0 | AT10: 0 | AV10: 0 | AW10: 0 | AX10: 0 | AY10: 0 | AZ10: 0 | BB10: 0 | BC10: 0 | BD10: 0 | BE10: 0 | BF10: 0 | BG10: 0 | BH10: 0 | BI10: 0 | BJ10: 0 | BK10: 0 | BL10: 0 | BM10: 0 | BN10: 0 | BO10: 0 | BP10: 0 | BQ10: 0 | BR10: 0 | BS10: 0 | BU10: 0 | BV10: 0 | BW10: 0 | BX10: 0 | BY10: 0 | BZ10: 0 | CA10: 0 | CB10: 0 | CC10: 0 | CD10: 0 | CE10: 0 | CF10: 0 | CG10: 0 | CH10: 0 | CI10: 0 | CJ10: 0 | CK10: 0 | CL10: 0 | CM10: 0 | CN10: 0 | CO10: 0 | CP10: 0
A11: Balances in NACCOS (E.g Jungu Kuu, ESS, Savings,Money Market,Coop FD, CFP) | C11: 3676702 | D11: 15331014 | E11: 17343284 | G11: 12208811 | H11: 6774463 | I11: 13600888 | J11: 7174463.4 | K11: 7374463.4 | L11: 7574463.4 | M11: 7774463.4 | N11: 8036911.8 | O11: 8236911.8 | P11: 8436911.8 | Q11: 8669496.2 | R11: 8869496.2 | S11: 9069496.2 | T11: 9269496.2 | U11: 9269496 | V11: 9572745.6 | W11: 9772745.6 | X11: 9972745.6 | Y11: 10172746 | Z11: 10372746 | AA11: 10572746 | AB11: 10772746 | AC11: 10972746 | AD11: 11172746 | AE11: 11372746 | AF11: 11572746 | AG11: 11809941 | AH11: 11809941 | AI11: 12009941 | AJ11: 12209941 | AK11: 12409941 | AL11: 12609941 | AM11: 12809941 | AN11: 13009941 | AO11: 13209941 | AP11: 13409941 | AQ11: 13609941 | AR11: 13809941 | AS11: 14204391 | AT11: 14254391 | AU11: 46262880 | AV11: 14504391 | AW11: 14704391 | AX11: 9304390.8 | AY11: 9504390.8 | AZ11: 10054391 | BB11: 56415201 | BC11: 11833040 | BD11: 12383040 | BE11: 12933040 | BF11: 13483040 | BG11: =13483040+42334539+558750 -> 56376329 | BH11: 14033040 | BI11: 14583040 | BJ11: 15270413 | BK11: 15820413 | BL11: 16418165 | BM11: 16968165 | BN11: 17518165 | BO11: 10116905 | BP11: 10666905 | BQ11: 11266640 | BR11: 11816640 | BS11: 12416374 | BT11: =10296359+2120015 -> 12416374 | BU11: 0 | BV11: 0 | BW11: 0 | BX11: 0 | BY11: 0 | BZ11: 0 | CA11: 0 | CB11: 0 | CC11: 0 | CD11: 0 | CE11: 0 | CF11: 0 | CG11: 19548923 | CH11: 20098923 | CI11: 20648923 | CJ11: 11628908 | CK11: 42178905 | CL11: 42728908 | CM11: 43606543 | CN11: 44156543 | CO11: 74706543 | CP11: 75259559
A12: Equity Investments in NACCOs(Shares in- CIC, KUSCCO, COOP BANK,CAK, KERUSSU) | BT12: =2232936+18375400+23770019+25000+418950 -> 44822305 | BU12: 12967373 | BV12: 13517373 | BW12: 14067373 | BX12: 14617373 | BY12: 15167373 | BZ12: 15717373 | CA12: 16267373 | CB12: 16817373 | CC12: 17420119 | CD12: 17970119 | CE12: 18520119 | CF12: 19122795 | CG12: 50345579 | CH12: 51324329 | CI12: 51744329 | CJ12: 52164329 | CK12: 52584329 | CL12: 53004329 | CM12: 53424329 | CN12: 53844329 | CO12: 53944329 | CP12: 54044329
A13: Equity Investments in companies - shares/stocks | C13: 9998645 | D13: 9998644 | E13: 10341549 | F13: 14582790 | G13: 15842990 | H13: 25636790 | I13: 26036790 | J13: 26236790 | K13: 26236790 | L13: 26636790 | M13: 26836790 | N13: 27036790 | O13: 27236790 | P13: 27436790 | Q13: 27833289 | R13: 27853289 | S13: 27873289 | T13: 27493289 | U13: =26934539+558750 -> 27493289 | V13: 27513289 | W13: 27533289 | X13: 27553289 | Y13: 27773289 | Z13: 27993289 | AA13: 28213289 | AB13: 28433289 | AC13: 28653289 | AD13: 28873289 | AE13: 29093289 | AF13: 29313289 | AG13: 29533289 | AH13: 29533289 | AI13: 29753289 | AJ13: 29973289 | AK13: 30193289 | AL13: 30413289 | AM13: 30633289 | AN13: 30853289 | AO13: 31073289 | AP13: 31293289 | AQ13: 31513289 | AR13: 31733289 | AS13: 31953289 | AT13: 32173289 | AU13: 164800 | AV13: 32393289 | AW13: 32613289 | AX13: 33033289 | AY13: 33453289 | AZ13: 33873289 | BB13: 173566445 | BC13: 35133289 | BD13: 35553289 | BE13: 35973289 | BF13: 42893298 | BH13: 43313289 | BI13: 43733289 | BJ13: 44153289 | BK13: 44573289 | BL13: 44993289 | BM13: 45413289 | BN13: 45833289 | BO13: 46253289 | BP13: 46673289 | BQ13: 47093289 | BR13: 47513289 | BS13: 43933289 | BT13: =91050+48750 -> 139800 | BU13: 45381106 | BV13: 45801106 | BW13: 46221106 | BX13: 46641106 | BY13: 47061106 | BZ13: 47481106 | CA13: 47901106 | CB13: 48321106 | CC13: 48741106 | CD13: 49161106 | CE13: 49581106 | CF13: 50001106 | CG13: 558750
A14: Net Loan Portfolio | B14: =B15-B16 -> 263143330 | C14: =C15-C16 -> 294845459 | D14: =D15-D16 -> 318026558 | E14: =E15-E16 -> 3.516902e+08 | F14: =F15-F16 -> 350184189 | G14: =G15-G16 -> 376107614 | H14: =H15-H16 -> 468334250 | I14: =I15-I16 -> 4.9099259e+08 | ... CP14: =CP15-CP16 -> 8.5077549e+08
A15: Gross Loan Portfolio | B15: 263143330 | C15: 296918859 | D15: 325298062 | E15: 3.5915199e+08 | F15: 360786989 | G15: 389781182 | H15: 491527931 | I15: 5.0468456e+08 | J15: 4.9688591e+08 | K15: 4.9456015e+08 | L15: 5.046516e+08 | M15: 5.0493288e+08 | N15: 5.0912243e+08 | O15: 5.2653857e+08 | P15: 5.2816045e+08 | Q15: 5.3719316e+08 | R15: 5.5453225e+08 | S15: 5.6042011e+08 | T15: 5.7418481e+08 | U15: 574184811 | V15: 5.7267714e+08 | W15: 5.7280548e+08 | X15: 5.68068e+08 | Y15: 5.7858506e+08 | Z15: 5.8956632e+08 | AA15: 5.9674454e+08 | AB15: 6.0520294e+08 | AC15: 6.2625334e+08 | AD15: 6.3670917e+08 | AE15: 6.3477404e+08 | AF15: 6.5520604e+08 | AG15: 6.6105478e+08 | AH15: 6.6105478e+08 | AI15: 6.6863753e+08 | AJ15: 6.6872501e+08 | AK15: 6.5841062e+08 | AL15: 6.6243866e+08 | AM15: 6.738089e+08 | AN15: 6.7270673e+08 | AO15: 6.7966546e+08 | AP15: 6.9624739e+08 | AQ15: 6.9414492e+08 | AR15: 7.0307924e+08 | AS15: 7.2149301e+08 | AT15: 7.3129182e+08 | AU15: 7.3129182e+08 | AV15: 7.2598822e+08 | AW15: 7.2438179e+08 | AX15: 7.234794e+08 | AY15: 7.1536943e+08 | AZ15: 7.1114084e+08 | BB15: 3.6662176e+09 | BC15: 7.3903284e+08 | BD15: 7.513754e+08 | BE15: 7.5694821e+08 | BF15: 7.6410396e+08 | BG15: 764103964 | BH15: 7.6356731e+08 | BI15: 7.5297719e+08 | BJ15: 7.5821386e+08 | BK15: 7.7349083e+08 | BL15: 7.7601377e+08 | BM15: 7.8583422e+08 | BN15: 8.019999e+08 | BO15: 8.0320065e+08 | BP15: 8.1268225e+08 | BQ15: 8.2255972e+08 | BR15: 8.3008889e+08 | BS15: 8.4131721e+08 | BT15: 841317206 | BU15: 8.358757e+08 | BV15: 8.3215386e+08 | BW15: 8.3838315e+08 | BX15: 8.5671903e+08 | BY15: 8.5332865e+08 | BZ15: 8.4453671e+08 | CA15: 8.48169e+08 | CB15: 8.4600809e+08 | CC15: 8.4261621e+08 | CD15: 8.4413452e+08 | CE15: 8.4763921e+08 | CF15: 8.5151251e+08 | CG15: 8.5151251e+08 | CH15: 85088141 | CI15: 8.515083e+08 | CJ15: 8.4147088e+08 | CK15: 8.6511664e+08 | CL15: 8.4504385e+08 | CM15: 8.4100263e+08 | CN15: 8.4643626e+08 | CO15: 8.5947565e+08 | CP15: 8.7044124e+08
A16: Allowance For Loan Loss | C16: 2073400 | D16: 7271504 | E16: 7461796.2 | F16: 10602800 | G16: 13673568 | H16: 23193681 | I16: 13691966 | J16: 22112854 | K16: 21769492 | L16: 22284323 | M16: 21874658 | N16: 22134292 | O16: 21803919 | P16: 22059516 | Q16: 22755109 | R16: 22755109 | S16: 20824298 | T16: 22244039 | U16: 22244039 | V16: 24843404 | W16: 24175684 | X16: 23266218 | Y16: 22624083 | Z16: 21899472 | AA16: 21845790 | AB16: 21845790 | AC16: 21845790 | AD16: 22931845 | AE16: 21100958 | AF16: 20734413 | AG16: 20226997 | AH16: 20226997 | AI16: 20226997 | AJ16: 20226997 | AK16: 20090269 | AL16: 20090269 | AM16: 19056804 | AN16: 19646297 | AO16: 19646297 | AP16: 22710258 | AQ16: 24299438 | AR16: 24839110 | AS16: 26172473 | AT16: 26887990 | AU16: 26887990 | AV16: 24381963 | AW16: 23109616 | AX16: 24846795 | AY16: 26267745 | AZ16: 29696887 | BB16: 1.5804551e+08 | BC16: 33312188 | BD16: 32764675 | BE16: 39379954 | BF16: 34889602 | BG16: 34889602 | BH16: 30175001 | BI16: 33106988 | BJ16: 32020383 | BK16: 28999942 | BL16: 30535307 | BM16: 29685897 | BN16: 35353837 | BO16: 29230688 | BP16: 28719584 | BQ16: 26083348 | BR16: 26561584 | BS16: 25144187 | BT16: 34889602 | BU16: 34889602 | BV16: 27347683 | BW16: 27778804 | BX16: 26579178 | BY16: 25140574 | BZ16: 19843405 | CA16: 19770002 | CB16: 21248174 | CC16: 18728827 | CD16: 16745986 | CE16: 16713798 | CF16: 26869932 | CG16: 26869932 | CH16: -26869932 | CI16: 16693310 | CJ16: 16071034 | CK16: 15948034 | CL16: 16132261 | CM16: 15166570 | CN16: 19647865 | CO16: 18229323 | CP16: 19665756
A17: Accounts Recievables | E17: =SUM(E18:E20) -> 0 | F17: =SUM(F18:F20) -> 0 | G17: =SUM(G18:G20) -> 0 | H17: =SUM(H18:H20) -> 0 | I17: =SUM(I18:I20) -> 0 | J17: =SUM(J18:J20) -> 0 | K17: =SUM(K18:K20) -> 0 | L17: =SUM(L18:L20) -> 0 | ... CP17: =SUM(CP18:CP20) -> 0
A18: Tax Recoverable | H18: - | I18: 0 | J18: 0 | K18: 0 | L18: 0 | M18: 0 | N18: 0 | O18: 0 | P18: 0 | Q18: 0 | R18: 0 | S18: 0 | T18: 0 | V18: 0 | W18: 0 | X18: 0 | Y18: 0 | Z18: 0 | AA18: 0 | AB18: 0 | AC18: 0 | AD18: 0 | AE18: 0 | AF18: 0 | AG18: 0 | AH18: 0 | AI18: 0 | AJ18: 0 | AK18: 0 | AL18: 0 | AM18: 0 | AN18: 0 | AO18: 0 | AP18: 0 | AQ18: 0 | AR18: 0 | AS18: 0 | AT18: 0 | AU18: 0 | AV18: 0 | AW18: 0 | AX18: 0 | AY18: 0 | AZ18: 0 | BA18: 0 | BB18: 0 | BC18: 0 | BD18: 0 | BE18: 0 | BF18: 0 | BG18: 979706 | BH18: 0 | BI18: 0 | BJ18: 0 | BK18: 0 | BL18: 0 | BM18: 0 | BN18: 0 | BO18: 0 | BP18: 0 | BQ18: 0 | BR18: 0 | BS18: 0 | BT18: 928581 | BU18: 0 | BV18: 0 | BW18: 0 | BX18: 0 | BY18: 0 | BZ18: 0 | CA18: 0 | CB18: 0 | CC18: 0 | CD18: 0 | CE18: 0 | CF18: 0 | CG18: 3538581 | CH18: 0 | CI18: 0 | CJ18: 0 | CK18: 0 | CL18: 0 | CM18: 0 | CN18: 0 | CO18: 0 | CP18: 0
A19: Deffered Tax Assets | H19: - | I19: 0 | J19: 0 | K19: 0 | L19: 0 | M19: 0 | N19: 0 | O19: 0 | P19: 0 | Q19: 0 | R19: 0 | S19: 0 | T19: 0 | V19: 0 | W19: 0 | X19: 0 | Y19: 0 | Z19: 0 | AA19: 0 | AB19: 0 | AC19: 0 | AD19: 0 | AE19: 0 | AF19: 0 | AG19: 0 | AH19: 0 | AI19: 0 | AJ19: 0 | AK19: 0 | AL19: 0 | AM19: 0 | AN19: 0 | AO19: 0 | AP19: 0 | AQ19: 0 | AR19: 0 | AS19: 0 | AT19: 0 | AU19: 0 | AV19: 0 | AW19: 0 | AX19: 0 | AY19: 0 | AZ19: 0 | BA19: 0 | BB19: 0 | BC19: 0 | BD19: 0 | BE19: 0 | BF19: 0 | BG19: 0 | BH19: 0 | BI19: 0 | BJ19: 0 | BK19: 0 | BL19: 0 | BM19: 0 | BN19: 0 | BO19: 0 | BP19: 0 | BQ19: 0 | BR19: 0 | BS19: 0 | BU19: 0 | BV19: 0 | BW19: 0 | BX19: 0 | BY19: 0 | BZ19: 0 | CA19: 0 | CB19: 0 | CC19: 0 | CD19: 0 | CE19: 0 | CF19: 0 | CG19: 0 | CH19: 0 | CI19: 0 | CJ19: 0 | CK19: 0 | CL19: 0 | CM19: 0 | CN19: 0 | CO19: 0 | CP19: 0
A20: Retirement Benefit Assets | H20: - | I20: 0 | J20: 0 | K20: 0 | L20: 0 | M20: 0 | N20: 0 | O20: 0 | P20: 0 | Q20: 0 | R20: 0 | S20: 0 | T20: 0 | V20: 0 | W20: 0 | X20: 0 | Y20: 0 | Z20: 0 | AA20: 0 | AB20: 0 | AC20: 0 | AD20: 0 | AE20: 0 | AF20: 0 | AG20: 0 | AH20: 0 | AI20: 0 | AJ20: 0 | AK20: 0 | AL20: 0 | AM20: 0 | AN20: 0 | AO20: 0 | AP20: 0 | AQ20: 0 | AR20: 0 | AS20: 0 | AT20: 0 | AU20: 0 | AV20: 0 | AW20: 0 | AX20: 0 | AY20: 0 | AZ20: 0 | BA20: 0 | BB20: 0 | BC20: 0 | BD20: 0 | BE20: 0 | BF20: 0 | BG20: 0 | BH20: 0 | BI20: 0 | BJ20: 0 | BK20: 0 | BL20: 0 | BM20: 0 | BN20: 0 | BO20: 0 | BP20: 0 | BQ20: 0 | BR20: 0 | BS20: 0 | BU20: 0 | BV20: 0 | BW20: 0 | BX20: 0 | BY20: 0 | BZ20: 0 | CA20: 0 | CB20: 0 | CC20: 0 | CD20: 0 | CE20: 0 | CF20: 0 | CG20: 0 | CH20: 0 | CI20: 0 | CJ20: 0 | CK20: 0 | CL20: 0 | CM20: 0 | CN20: 0 | CO20: 0 | CP20: 0
A21: Property&Equipments&Other Assets | B21: =SUM(B22:B26) -> 75849622 | C21: =SUM(C22:C26) -> 75797990 | D21: =SUM(D22:D26) -> 62974319 | E21: =SUM(E22:E26) -> 60255949 | F21: =SUM(F22:F26) -> 58284975 | G21: =SUM(G22:G26) -> 94755272 | H21: =SUM(H22:H26) -> 121086191 | I21: =SUM(I22:I26) -> 1.5226473e+08 | ... CP21: =SUM(CP22:CP26) -> 56380373
A22: Investment Properties | G22: 16170871 | H22: 15847454 | I22: 16150520 | J22: 16123569 | K22: 16096617 | L22: 16069666 | M22: 16042714 | N22: 16015763 | O22: 16015763 | P22: 16015763 | Q22: 15961860 | R22: 15934909 | S22: 15907957 | T22: 15881006 | U22: 15530505 | V22: 15504621 | W22: 15478737 | X22: 15452852 | Y22: 15426968 | Z22: 15401084 | AA22: 15375200 | AB22: 15349316 | AC22: 15323432 | AD22: 15297547 | AE22: 15271663 | AF22: 15245779 | AG22: 15219895 | AH22: 15219895 | AI22: 15194529 | AJ22: 15169192 | AK22: 15143826 | AL22: 15118459 | AM22: 15093093 | AN22: 15064726 | AO22: 15042360 | AP22: 15016993 | AQ22: 14991627 | AR22: 14966260 | AS22: 14940894 | AT22: 14915527 | AU22: 14915497 | AV22: 14865809 | AW22: 14840950 | AX22: 14816090 | AY22: 14791231 | AZ22: 14766372 | BB22: 73582819 | BC22: 14691795 | BD22: 14666936 | BE22: 14642076 | BF22: 14617217 | BG22: 14617187 | BH22: 14592825 | BI22: 14568363 | BJ22: 14544001 | BK22: 14519739 | BL22: 14495377 | BM22: 14471015 | BN22: 14291536 | BO22: 14287168 | BP22: 14397929 | BQ22: 14373567 | BR22: 14349205 | BS22: 14324843 | BT22: 14324843 | BU22: 14300968 | BV22: 14277093 | BW22: 14253218 | BX22: 14229343 | BY22: 14205468 | BZ22: 14181593 | CA22: 14157718 | CB22: 14133843 | CC22: 14109968 | CD22: 14231488 | CE22: 14062218 | CF22: 14038343 | CG22: 14038346 | CH22: 14014946 | CI22: 13991549 | CJ22: 13968152 | CK22: 13944754 | CL22: 13921357 | CM22: 13897960 | CN22: 13874563 | CO22: 13851165 | CP22: 13827768
A23: Property and Equipment | B23: 75849622 | C23: 70621990 | D23: 58833519 | E23: 56943309 | F23: 55634863 | G23: 39960484 | H23: 40147340 | I23: 40050734 | J23: 39871668 | K23: 39938621 | L23: 39759555 | M23: 40309490 | N23: 40108424 | O23: 39931107 | P23: 41103170 | Q23: 40503244 | R23: 40307338 | S23: 40229745 | T23: 39762189 | U23: =55643190-U22 -> 40112685 | V23: 39921069 | W23: 39767350 | X23: 39600182 | Y23: 39611875 | Z23: 39775708 | AA23: 39591540 | AB23: 39631731 | AC23: 39455064 | AD23: 39270897 | AE23: 39102430 | AF23: 38918262 | AG23: 38647964 | AH23: 38648263 | AI23: 38542409 | AJ23: 38333876 | AK23: 38435617 | AL23: 38365183 | AM23: 38262942 | AN23: 38100513 | AO23: 37953164 | AP23: 37858275 | AQ23: 37713256 | AR23: 37550857 | AS23: 37388458 | AT23: 37319284 | AU23: 37330512 | AV23: 37491018 | AW23: 37535197 | AX23: 37465949 | AY23: 37396702 | AZ23: 37304455 | BB23: 1.8800401e+08 | BC23: 37687360 | BD23: 37553885 | BE23: 37069518 | BF23: 37026333 | BG23: =51643280-14617187 -> 37026093 | BH23: 36954800 | BI23: 36720311 | BJ23: 36567420 | BK23: 36414529 | BL23: 36351638 | BM23: 36198747 | BN23: 36200974 | BO23: 36147058 | BP23: 35859044 | BQ23: 35855533 | BR23: 35879535 | BS23: 35648339 | BT23: 35648339 | BU23: 35851380 | BV23: 35716983 | BW23: 35814845 | BX23: 35693221 | BY23: 35556597 | BZ23: 35889186 | CA23: 35762685 | CB23: 35624584 | CC23: 35502978 | CD23: 35265405 | CE23: 34960541 | CF23: 34928432 | CG23: 34928424 | CH23: 34804740 | CI23: 34681048 | CJ23: 34542013 | CK23: 34858405 | CL23: 35209810 | CM23: 35086118 | CN23: 35136111 | CO23: 34989220 | CP23: 34966225
A24: Prepaid Lease Rentals | I24: 0 | J24: 0 | K24: 0 | L24: 0 | M24: 0 | N24: 0 | O24: 0 | P24: 0 | Q24: 0 | R24: 0 | S24: 0 | T24: 0 | V24: 0 | W24: 0 | X24: 0 | Y24: 0 | Z24: 0 | AA24: 0 | AB24: 0 | AC24: 0 | AD24: 0 | AE24: 0 | AF24: 0 | AG24: 0 | AI24: 0 | AJ24: 0 | AK24: 0 | AL24: 0 | AM24: 0 | AN24: 0 | AO24: 0 | AP24: 0 | AQ24: 0 | AR24: 0 | AS24: 0 | AT24: 0 | AV24: 0 | AW24: 0 | AX24: 0 | AY24: 0 | AZ24: 0 | BB24: 0 | BC24: 0 | BD24: 0 | BE24: 0 | BF24: 0 | BG24: 0 | BH24: 0 | BI24: 0 | BJ24: 0 | BK24: 0 | BL24: 0 | BM24: 0 | BN24: 0 | BO24: 0 | BP24: 0 | BQ24: 0 | BR24: 0 | BS24: 0 | BU24: 0 | BV24: 0 | BW24: 0 | BX24: 0 | BY24: 0 | BZ24: 0 | CA24: 0 | CB24: 0 | CC24: 0 | CD24: 0 | CE24: 0 | CF24: 0 | CG24: 0 | CH24: 0 | CI24: 0 | CJ24: 0 | CK24: 0 | CL24: 0 | CM24: 0 | CN24: 0 | CO24: 0 | CP24: 0
A25: Intangible Assets | C25: 5176000 | D25: 4140800 | E25: 3312640 | F25: 2650112 | G25: 2120090 | H25: 2108549 | I25: 1660737.2 | J25: 1625402.4 | K25: 1590066.6 | L25: 1554732.7 | M25: 6536465.3 | N25: 6863050.5 | O25: 6827715.6 | P25: 7047207.7 | Q25: 7529686.2 | R25: 7784512.1 | S25: 7678507.6 | T25: 7522411.2 | U25: 7522411 | V25: 7397037.7 | W25: 7271664.2 | X25: 7273704.2 | Y25: 7273704.2 | Z25: 7022957.2 | AA25: 6897583.7 | AB25: 6772210.2 | AC25: 6646836.7 | AD25: 6521463.2 | AE25: 6521463.2 | AF25: 6396089.7 | AG25: 6119858.7 | AH25: 6119859.2 | AI25: 6017861 | AJ25: 5915863.4 | AK25: 5813865.7 | AL25: 5711868.1 | AM25: 5609870.4 | AN25: 5609870.4 | AO25: 5405875.1 | AP25: 5303877.5 | AQ25: 5201879.8 | AR25: 5099882.2 | AS25: 4997884.5 | AT25: 4895886.9 | AU25: 4895879.4 | AV25: 4732690.9 | AW25: 5151092.9 | AX25: 5269495 | AY25: 5187897 | AZ25: 5106299 | BB25: 24715515 | BC25: 4861505.1 | BD25: 4779907.1 | BE25: 4698309.2 | BF25: 4511711.2 | BG25: 4511711 | BH25: 4430113.2 | BI25: 4361320.8 | BJ25: 4286125.6 | BK25: 4210930.4 | BL25: 4135735.2 | BM25: 4060540 | BN25: 3985344.8 | BO25: 3910149.6 | BP25: 3834954.5 | BQ25: 3759759.3 | BR25: 3684564.1 | BS25: 3609368.9 | BT25: 3609369 | BU25: 3564251.9 | BV25: 3519134.9 | BW25: 3474017.9 | BX25: 3474017.9 | BY25: 3428900.9 | BZ25: 3428900.9 | CA25: 3428900.9 | CB25: 3428900.9 | CC25: 3428900.9 | CD25: 3203315.9 | CE25: 3158198.9 | CF25: 2887494.9 | CG25: 2887495 | CH25: 2839370 | CI25: 2791245 | CJ25: 2887888.1 | CK25: 2781855.2 | CL25: 2733730.3 | CM25: 2685605.4 | CN25: 2625499.6 | CO25: 2577374.7 | CP25: 4179249.8
A26: Other Assets | G26: 36503827 | H26: 62982848 | I26: 94402737 | J26: 85918460 | K26: 86835988 | L26: 92226637 | M26: 72775101 | N26: 91438092 | O26: 58856901 | P26: 95306328 | Q26: 82291455 | R26: 83226158 | S26: 80294701 | T26: 84480811 | U26: 65378903 | V26: 84074076 | W26: 82284057 | X26: 82778159 | Y26: 82606696 | Z26: 82597979 | AA26: 82633405 | AB26: 82678372 | AC26: 82728591 | AD26: 82768546 | AE26: 82624442 | AF26: 82493356 | AG26: 77858967 | AH26: 65318850 | AI26: 19906805 | AJ26: 20263406 | AK26: 17479708 | AL26: 18683128 | AM26: 18680711 | AN26: 19126388 | AO26: 21539072 | AP26: 19846391 | AQ26: 20621271 | AR26: 21142069 | AS26: 21233543 | AT26: 14417383 | AU26: 308457.22 | AV26: 14631632 | AW26: 14110254 | AX26: 13122169 | AY26: 12863273 | AZ26: 13772467 | BB26: 74177301 | BC26: 15662679 | BD26: 16221671 | BE26: 16999769 | BF26: 15206340 | BG26: 0 | BH26: 15698612 | BI26: 17467813 | BJ26: 16079587 | BK26: 15080317 | BL26: 14817845 | BM26: 15357171 | BN26: 15576750 | BO26: 15790048 | BP26: 16627988 | BQ26: 16805396 | BR26: 17250362 | BS26: 13181247 | BU26: 14452085 | BV26: 11293713 | BW26: 11018760 | BX26: 10205107 | BY26: 10357300 | BZ26: 9262330.4 | CA26: 9938720.9 | CB26: 6119388.9 | CC26: 6268977.6 | CD26: 7435848.8 | CE26: 7320150.6 | CF26: 5286536 | CH26: 3719690.2 | CI26: 4598842.2 | CJ26: 1951353.9 | CK26: 4117372.1 | CL26: 2827649 | CM26: 2630151.6 | CN26: 2577370.2 | CO26: 2518198.4 | CP26: 3407130.4
A27: Total Assets | B27: =B21+B17+B14+B8+B7+B4 -> 420805135 | C27: =C21+C17+C14+C8+C7+C4 -> 422925486 | D27: =D21+D17+D14+D8+D7+D4 -> 454657971 | E27: =E21+E17+E14+E8+E7+E4 -> 5.0853339e+08 | F27: =F21+F17+F14+F8+F7+F4 -> 534444329 | G27: =G21+G17+G14+G8+G7+G4 -> 604188621 | H27: =H21+H17+H14+H8+H7+H4 -> 696983837 | I27: =I21+I17+I14+I8+I7+I4 -> 7.0780111e+08 | ... CP27: =CP21+CP17+CP14+CP8+CP7+CP4 -> 1.1568404e+09
A28: Savings and Deposits | B28: 19165989 | C28: 235081887 | D28: 260205324 | E28: 2.8541463e+08 | F28: 19567215 | G28: 28830199 | H28: 54834830 | I28: 43919039 | J28: 55039630 | K28: 72708021 | L28: 50526228 | M28: 54138099 | N28: 50634340 | O28: 46788238 | P28: 54745233 | Q28: 50228624 | R28: 56773229 | S28: 61033583 | T28: 62681790 | U28: 64599717 | V28: 60397154 | W28: 61852949 | X28: 85444462 | Y28: 69606051 | Z28: 70386671 | AA28: 72834296 | AB28: 74577505 | AC28: 71697863 | AD28: 80470899 | AE28: 76840380 | AF28: 77750309 | AG28: 70831455 | AH28: 72798561 | AI28: 71956117 | AJ28: 66223067 | AK28: 89842958 | AL28: 67744169 | AM28: 69653590 | AN28: 67632785 | AO28: 61977586 | AP28: 71764765 | AQ28: 74129753 | AR28: 76889878 | AS28: 72938533 | AT28: 71278581 | AU28: 73210629 | AV28: 74781440 | AW28: 91036349 | AX28: 98064264 | AY28: 91550547 | AZ28: 78399939 | BB28: 4.1011584e+08 | BC28: 69749431 | BD28: 73860265 | BE28: 73073009 | BF28: 73990296 | BG28: 75859507 | BH28: 74432409 | BI28: 95573927 | BJ28: 91749622 | BK28: 86264426 | BL28: 85119678 | BM28: 86369092 | BN28: 99663297 | BO28: 95883995 | BP28: 92671215 | BQ28: 96654168 | BR28: 1.0171234e+08 | BS28: 96070398 | BT28: 96070398 | BU28: 87331704 | BV28: 1.3039114e+08 | BW28: 1.0011393e+08 | BX28: 99225297 | BY28: 95577508 | BZ28: 96559931 | CA28: 1.1002575e+08 | CB28: 1.0065431e+08 | CC28: 98093602 | CD28: 96614089 | CE28: 98168404 | CF28: 90703690 | CG28: 92429113 | CH28: 87160714 | CI28: 88445961 | CJ28: 1.0348374e+08 | CK28: 88144694 | CL28: 95035160 | CM28: 1.0054044e+08 | CN28: 1.0344796e+08 | CO28: 98320437 | CP28: 93558472
A29: Short Terrm Deposits | C29: 14522500 | D29: 19478821 | E29: 7732655.5 | F29: 2611021 | G29: 633522 | H29: 5613058 | I29: 3082059 | J29: 2902059 | K29: 2416061.1 | L29: 2925171.5 | M29: 2950383.8 | N29: 2761384.8 | O29: 2167616.1 | P29: 3786713.1 | Q29: 3801771.2 | R29: 3795213.1 | S29: 3801213.1 | T29: 3904555.5 | U29: 3904556 | V29: 6272519.1 | W29: 7143591.5 | X29: 7143591.5 | Y29: 5433591.5 | Z29: 5393591.5 | AA29: 5400678.8 | AB29: 5500678.8 | AC29: 5561878.8 | AD29: 3983114.7 | AE29: 3683114.7 | AF29: 3671914.7 | AG29: 3871914.7 | AH29: 3871914.7 | AI29: 5171914.7 | AJ29: 3271914.5 | AK29: 1769446.1 | AL29: 3809446.1 | AM29: 3809446.1 | AN29: 3609446.1 | AO29: 3074315.5 | AP29: 2274315.5 | AQ29: 2274315.5 | AR29: 2274315.5 | AS29: 2274315.5 | AT29: 2854315.5 | AU29: 2854315.5 | AV29: 4351393.5 | AW29: 3771393.5 | AX29: 6074315.5 | AY29: 9774315.5 | AZ29: 10374315 | BB29: 63584577 | BC29: 13672600 | BD29: 13772600 | BE29: 12272600 | BF29: 14211000 | BG29: 14211000 | BH29: 13511000 | BI29: 14521000 | BJ29: 14521000 | BK29: 13121000 | BL29: 12921000 | BM29: 12421000 | BN29: 13621000 | BO29: 14521000 | BP29: 14521000 | BQ29: 16321000 | BR29: 19971000 | BS29: 22220000 | BT29: 22220000 | BU29: 22420000 | BV29: 21454540 | BW29: 20164500 | BX29: 20764500 | BY29: 22764500 | BZ29: 23112500 | CA29: 21012500 | CB29: 23113478 | CC29: 25451022 | CD29: 25351000 | CE29: 23201000 | CF29: 19126000 | CG29: 19126000 | CH29: 18532000 | CI29: 18082000 | CJ29: 19233000 | CK29: 19233000 | CL29: 20733000 | CM29: 20783000 | CN29: 27093000 | CO29: 26763000 | CP29: 26161978
A30: Non Withdrawable Deposits | B30: 230364164 | C30: 2051000 | D30: 2136500 | E30: 474445.83 | F30: 300022565 | G30: 340939649 | H30: 380380553 | I30: 3.8154286e+08 | J30: 3.8756921e+08 | K30: 3.9012058e+08 | L30: 3.9337815e+08 | M30: 3.9587854e+08 | N30: 3.9903633e+08 | O30: 3.9676322e+08 | P30: 4.0302785e+08 | Q30: 4.0441526e+08 | R30: 4.0763727e+08 | S30: 4.1306786e+08 | T30: 4.1661354e+08 | U30: 414695613 | V30: 4.1875295e+08 | W30: 4.2270146e+08 | X30: 4.275702e+08 | Y30: 4.3270072e+08 | Z30: 4.3723721e+08 | AA30: 4.4186645e+08 | AB30: 4.458657e+08 | AC30: 4.5127342e+08 | AD30: 4.5172315e+08 | AE30: 4.5366494e+08 | AF30: 4.5755527e+08 | AG30: 4.6073869e+08 | AH30: 4.5877158e+08 | AI30: 4.6341671e+08 | AJ30: 4.6786503e+08 | AK30: 4.6919189e+08 | AL30: 4.7193559e+08 | AM30: 4.7443502e+08 | AN30: 4.7855895e+08 | AO30: 4.7912021e+08 | AP30: 4.8296453e+08 | AQ30: 4.855553e+08 | AR30: 4.8908412e+08 | AS30: 4.9199495e+08 | AT30: 4.9379049e+08 | AU30: 4.9185844e+08 | AV30: 4.976021e+08 | AW30: 4.9992735e+08 | AX30: 5.0396971e+08 | AY30: 5.0812073e+08 | AZ30: 5.1163117e+08 | BB30: 2.587018e+09 | BC30: 5.2061708e+08 | BD30: 5.2432741e+08 | BE30: 5.2824784e+08 | BF30: 5.3026791e+08 | BG30: 528398698 | BH30: 5.3429901e+08 | BI30: 5.3664328e+08 | BJ30: 5.4223199e+08 | BK30: 5.4744943e+08 | BL30: 5.5173539e+08 | BM30: 5.5397571e+08 | BN30: 5.5788583e+08 | BO30: 5.6328091e+08 | BP30: 5.6661867e+08 | BQ30: 5.7132642e+08 | BR30: 5.7522614e+08 | BS30: 578555889 | BT30: 578555889 | BU30: 5.8087755e+08 | BV30: 5.8464052e+08 | BW30: 5.9002917e+08 | BX30: 5.9396604e+08 | BY30: 5.9720211e+08 | BZ30: 5.9257098e+08 | CA30: 5.9622446e+08 | CB30: 5.9704795e+08 | CC30: 5.9953102e+08 | CD30: 6.0428353e+08 | CE30: 6.0807958e+08 | CF30: 6.0972224e+08 | CG30: 607996816 | CH30: 6.129141e+08 | CI30: 6.1748143e+08 | CJ30: 6.2145422e+08 | CK30: 624731589 | CL30: 6.3108703e+08 | CM30: 6.3292618e+08 | CN30: 6.3709977e+08 | CO30: 6.4090813e+08 | CP30: 6.4788293e+08
A31: Total Deposit Liabilities | B31: =SUM(B28:B30) -> 249530153 | C31: =SUM(C28:C30) -> 251655387 | D31: =SUM(D28:D30) -> 281820645 | E31: =SUM(E28:E30) -> 2.9362173e+08 | F31: =SUM(F28:F30) -> 322200801 | G31: =SUM(G28:G30) -> 370403370 | H31: =SUM(H28:H30) -> 440828441 | I31: =SUM(I28:I30) -> 4.2854396e+08 | ... CP31: =SUM(CP28:CP30) -> 7.6760338e+08
A32: Tax Payable | B32: 135550 | C32: 140547 | D32: 367209 | E32: 957101.88 | F32: 780541 | G32: 613419 | I32: 0 | J32: 0 | K32: 0 | L32: 0 | M32: 0 | N32: 0 | O32: 0 | P32: 0 | Q32: 0 | R32: 0 | S32: 0 | T32: 0 | U32: =1370163+1872695 -> 3242858 | V32: 0 | W32: 0 | X32: 0 | Y32: 0 | Z32: 0 | AA32: 0 | AB32: 0 | AC32: 0 | AD32: 0 | AE32: 0 | AF32: 0 | AG32: 0 | AH32: 0 | AI32: 0 | AJ32: 0 | AK32: 0 | AL32: 0 | AM32: 0 | AN32: 0 | AO32: 0 | AP32: 0 | AQ32: 0 | AR32: 0 | AS32: 0 | AT32: 0 | AU32: -141169 | AV32: 0 | AW32: 0 | AX32: 0 | AY32: 0 | AZ32: 0 | BB32: 0 | BC32: 0 | BD32: 0 | BE32: 0 | BF32: 0 | BG32: 32123 | BH32: 0 | BI32: 0 | BJ32: 0 | BK32: 0 | BL32: 0 | BM32: 0 | BN32: 0 | BO32: 0 | BP32: 0 | BQ32: 0 | BR32: 0 | BS32: 0 | BT32: 1043645 | BU32: 0 | BV32: 0 | BW32: 0 | BX32: 0 | BY32: 0 | BZ32: 0 | CA32: 0 | CB32: 0 | CC32: 0 | CD32: 0 | CE32: 0 | CF32: 0 | CG32: 2517171 | CH32: 0 | CI32: 0 | CJ32: 0 | CK32: 0 | CL32: 0 | CM32: 0 | CN32: 0 | CO32: 0 | CP32: 0
A33: Dividends Payable | C33: 18506917 | F33: 1 | G33: 35477551 | H33: 37389190 | I33: 0 | J33: 0 | K33: 78235.27 | L33: 0 | M33: 0 | N33: 0 | O33: 0 | P33: 0 | Q33: 0 | R33: 0 | S33: 0 | T33: 0 | U33: 0 | V33: 0 | W33: 0 | X33: 0 | Y33: 0 | Z33: 0 | AA33: 0 | AB33: 0 | AC33: 0 | AD33: 0 | AE33: 0 | AF33: 0 | AG33: 0 | AH33: 0 | AI33: 0 | AJ33: 0 | AK33: 0 | AL33: 0 | AM33: 0 | AN33: 0 | AO33: 0 | AP33: 0 | AQ33: 0 | AR33: 0 | AS33: 0 | AT33: 0 | AV33: 0 | AW33: 0 | AX33: 0 | AY33: 0 | AZ33: 0 | BB33: 0 | BC33: 0 | BD33: 0 | BE33: 0 | BF33: 0 | BG33: 0 | BH33: 0 | BI33: 0 | BJ33: 0 | BK33: 0 | BL33: 0 | BM33: 0 | BN33: 0 | BO33: 0 | BP33: 0 | BQ33: 0 | BR33: 0 | BS33: 0 | BT33: =77767126 -> 77767126 | BU33: 0 | BV33: 0 | BW33: 0 | BX33: 0 | BY33: 0 | BZ33: 0 | CA33: 0 | CB33: 0 | CC33: 0 | CD33: 0 | CE33: 0 | CF33: 0 | CG33: 80985972 | CH33: 0 | CI33: 0 | CJ33: 0 | CK33: 0 | CL33: 0 | CM33: 0 | CN33: 0 | CO33: 0 | CP33: 0
A34: Deferred Tax Liability | I34: 0 | J34: 0 | K34: 0 | L34: 0 | M34: 0 | N34: 0 | O34: 0 | P34: 0 | Q34: 0 | R34: 0 | S34: 0 | T34: 0 | V34: 0 | W34: 0 | X34: 0 | Y34: 0 | Z34: 0 | AA34: 0 | AB34: 0 | AC34: 0 | AD34: 0 | AE34: 0 | AF34: 0 | AG34: 0 | AH34: 0 | AI34: 0 | AJ34: 0 | AK34: 0 | AL34: 0 | AM34: 0 | AN34: 0 | AO34: 0 | AP34: 0 | AQ34: 0 | AR34: 0 | AS34: 0 | AT34: 0 | AV34: 0 | AW34: 0 | AX34: 0 | AY34: 0 | AZ34: 0 | BB34: 0 | BC34: 0 | BD34: 0 | BE34: 0 | BF34: 0 | BG34: 0 | BH34: 0 | BI34: 0 | BJ34: 0 | BK34: 0 | BL34: 0 | BM34: 0 | BN34: 0 | BO34: 0 | BP34: 0 | BQ34: 0 | BR34: 0 | BS34: 0 | BU34: 0 | BV34: 0 | BW34: 0 | BX34: 0 | BY34: 0 | BZ34: 0 | CA34: 0 | CB34: 0 | CC34: 0 | CD34: 0 | CE34: 0 | CF34: 0 | CG34: 0 | CH34: 0 | CI34: 0 | CJ34: 0 | CK34: 0 | CL34: 0 | CM34: 0 | CN34: 0 | CO34: 0 | CP34: 0
A35: Retirement Benefits Liabilty | I35: 0 | J35: 0 | K35: 0 | L35: 0 | M35: 0 | N35: 0 | O35: 0 | P35: 0 | Q35: 0 | R35: 0 | S35: 0 | T35: 0 | V35: 0 | W35: 0 | X35: 0 | Y35: 0 | Z35: 0 | AA35: 0 | AB35: 0 | AC35: 0 | AD35: 0 | AE35: 0 | AF35: 0 | AG35: 0 | AH35: 0 | AI35: 0 | AJ35: 0 | AK35: 0 | AL35: 0 | AM35: 0 | AN35: 0 | AO35: 0 | AP35: 0 | AQ35: 0 | AR35: 0 | AS35: 0 | AT35: 0 | AV35: 0 | AW35: 0 | AX35: 0 | AY35: 0 | AZ35: 0 | BB35: 0 | BC35: 0 | BD35: 0 | BE35: 0 | BF35: 0 | BG35: 0 | BH35: 0 | BI35: 0 | BJ35: 0 | BK35: 0 | BL35: 0 | BM35: 0 | BN35: 0 | BO35: 0 | BP35: 0 | BQ35: 0 | BR35: 0 | BS35: 0 | BU35: 0 | BV35: 0 | BW35: 0 | BX35: 0 | BY35: 0 | BZ35: 0 | CA35: 0 | CB35: 0 | CC35: 0 | CD35: 0 | CE35: 0 | CF35: 0 | CG35: 0 | CH35: 0 | CI35: 0 | CJ35: 0 | CK35: 0 | CL35: 0 | CM35: 0 | CN35: 0 | CO35: 0 | CP35: 0
A36: Other Liabilities | B36: 23813301 | C36: 4745318 | D36: 24806615 | E36: 37504104 | F36: 50368944 | G36: 27658614 | H36: 33476442 | I36: 85762468 | J36: 75420024 | K36: 42081591 | L36: 41771384 | M36: 44542336 | N36: 47583625 | O36: 50005482 | P36: 53568285 | Q36: 56681503 | R36: 61003355 | S36: 64544165 | T36: 97172958 | U36: =99234827-1872695 -> 97362132 | V36: 1.0386365e+08 | W36: 1.058956e+08 | X36: 64613289 | Y36: 66364445 | Z36: 68142261 | AA36: 72179503 | AB36: 76011611 | AC36: 78352881 | AD36: 82757925 | AE36: 85631243 | AF36: 89352891 | AG36: 1.0823349e+08 | AH36: 1.0826054e+08 | AI36: 53958233 | AJ36: 57713691 | AK36: 15868286 | AL36: 17484200 | AM36: 15910659 | AN36: 19949567 | AO36: 20719215 | AP36: 25234579 | AQ36: 28738625 | AR36: 33624447 | AS36: 48141127 | AT36: 59894224 | AU36: 59830495 | AV36: 69178371 | AW36: 28908854 | AX36: 19151176 | AY36: 20696932 | AZ36: 25013434 | BB36: 1.8554206e+08 | BC36: 43147513 | BD36: 49707267 | BE36: 52539744 | BF36: 60950910 | BG36: 60777338 | BH36: 66477412 | BI36: 17834656 | BJ36: 23741301 | BK36: 27703288 | BL36: 31503844 | BM36: 37965513 | BN36: 45501864 | BO36: 51899397 | BP36: 58120447 | BQ36: 61316585 | BR36: 68015118 | BS36: 82540334 | BT36: =3740379 -> 3740379 | BU36: 88322646 | BV36: 21196818 | BW36: 18826454 | BX36: 26886658 | BY36: 32149571 | BZ36: 38707340 | CA36: 41159181 | CB36: 43566772 | CC36: 50323031 | CD36: 58248332 | CE36: 65191920 | CF36: 86141666 | CG36: =2702447 -> 2702447 | CH36: 90353059 | CI36: 96801810 | CJ36: 20654991 | CK36: 29598136 | CL36: 29759881 | CM36: 38537429 | CN36: 47122284 | CO36: 54353885 | CP36: 60722400
A37: External Borrowings | B37: 98196182 | C37: 73980442 | D37: 75498160 | E37: 75604045 | F37: 14235893 | H37: 0 | I37: 0 | J37: 0 | K37: 0 | L37: 0 | M37: 0 | N37: 0 | O37: 0 | P37: 0 | Q37: 0 | R37: 0 | S37: 0 | T37: 0 | V37: 0 | W37: 0 | X37: 0 | Y37: 0 | Z37: 0 | AB37: 0 | AC37: 0 | AD37: 0 | AE37: 0 | AF37: 0 | AG37: 0 | AH37: 0 | AI37: 0 | AJ37: 0 | AK37: 0 | AL37: 0 | AM37: 0 | AN37: 0 | AO37: 0 | AP37: 0 | AQ37: 0 | AR37: 0 | AS37: 0 | AT37: 0 | AV37: 0 | AW37: 0 | AX37: 0 | AY37: 0 | AZ37: 0 | BB37: 0 | BC37: 0 | BD37: 0 | BE37: 0 | BF37: 0 | BG37: 0 | BH37: 0 | BI37: 0 | BJ37: 0 | BK37: 0 | BL37: 0 | BM37: 0 | BN37: 0 | BO37: 0 | BP37: 0 | BQ37: 0 | BR37: 0 | BS37: 0 | BU37: 0 | BV37: 0 | BW37: 0 | BX37: 0 | BY37: 0 | BZ37: 0 | CA37: 0 | CB37: 0 | CC37: 0 | CD37: 0 | CE37: 0 | CF37: 0 | CG37: 0 | CH37: 0 | CI37: 0 | CJ37: 0 | CK37: 0 | CL37: 0 | CM37: 0 | CN37: 0 | CO37: 0 | CP37: 0
A38: Total Liabilities | B38: =SUM(B31:B37) -> 371675186 | C38: =SUM(C31:C37) -> 349028611 | D38: =SUM(D31:D37) -> 382492629 | E38: =SUM(E31:E37) -> 4.0768699e+08 | F38: =SUM(F31:F37) -> 387586180 | G38: =SUM(G31:G37) -> 434152954 | H38: =SUM(H31:H37) -> 511694073 | I38: =SUM(I31:I37) -> 5.1430643e+08 | ... CP38: =SUM(CP31:CP37) -> 8.2832578e+08
A39: Share Capital | B39: 5058510 | C39: 41027979 | D39: 41319195 | E39: 44676737 | F39: 67258769 | G39: 67556532 | H39: 73461221 | I39: 73503822 | J39: 73685122 | K39: 73880951 | L39: 74103901 | M39: 74324907 | N39: 74536157 | O39: 74697357 | P39: 74738057 | Q39: 74882757 | R39: 74901757 | S39: 75043107 | T39: 75112907 | U39: 75112907 | V39: 75199407 | W39: 75263207 | X39: 75291930 | Y39: 75479350 | Z39: 75537150 | AA39: 75550950 | AB39: 75613870 | AC39: 75709870 | AD39: 75727050 | AE39: 76050950 | AF39: 76225450 | AG39: 76348050 | AH39: 76348050 | AI39: 76556815 | AJ39: 76756315 | AK39: 78671845 | AL39: 78779389 | AM39: 79033796 | AN39: 79083296 | AO39: 79167296 | AP39: 79255402 | AQ39: 79406108 | AR39: 79623746 | AS39: 79681767 | AT39: 80370014 | AU39: 80370014 | AV39: 81185589 | AW39: 81282836 | AX39: 81366780 | AY39: 82735268 | AZ39: 83348481 | BB39: 420356850 | BC39: 84224873 | BD39: 84471578 | BE39: 84643828 | BF39: 84738607 | BG39: =39709604+4368593+40660411 -> 84738608 | BH39: 84761007 | BI39: 84996324 | BJ39: 85232930 | BK39: 85548340 | BL39: 85923420 | BM39: 86199470 | BN39: 86369570 | BO39: 86700570 | BP39: 86951558 | BQ39: 87164925 | BR39: 87701751 | BS39: 87852651 | BT39: 87852651 | BU39: 88822455 | BV39: 88951167 | BW39: 89094869 | BX39: 89371617 | BY39: 89534757 | BZ39: 89881934 | CA39: 89947434 | CB39: 90048555 | CC39: 90251549 | CD39: 91231117 | CE39: 91406814 | CF39: 91740614 | CG39: 91740614 | CH39: 91886264 | CI39: 92080154 | CJ39: 92661204 | CK39: 92868404 | CL39: 93156630 | CM39: 93331730 | CN39: 93680930 | CO39: 94227146 | CP39: 94719939
A40: Capital Grants | B40: 5058510 | I40: 0 | J40: 0 | K40: 0 | L40: 0 | M40: 0 | N40: 0 | O40: 0 | P40: 0 | Q40: 0 | R40: 0 | S40: 0 | T40: 0 | U40: 0 | V40: 0 | W40: 0 | X40: 0 | Y40: 0 | Z40: 0 | AB40: 0 | AC40: 0 | AD40: 0 | AE40: 0 | AF40: 0 | AG40: 0 | AH40: 0 | AI40: 0 | AJ40: 0 | AK40: 0 | AL40: 0 | AM40: 0 | AN40: 0 | AO40: 0 | AP40: 0 | AQ40: 0 | AR40: 0 | AS40: 0 | AT40: 0 | AV40: 0 | AW40: 0 | AX40: 0 | AY40: 0 | AZ40: 0 | BB40: 0 | BC40: 0 | BD40: 0 | BE40: 0 | BF40: 0 | BG40: 0 | BH40: 0 | BI40: 0 | BJ40: 0 | BK40: 0 | BL40: 0 | BM40: 0 | BN40: 0 | BO40: 0 | BP40: 0 | BQ40: 0 | BR40: 0 | BS40: 0 | BU40: 0 | BV40: 0 | BW40: 0 | BX40: 0 | BY40: 0 | BZ40: 0 | CA40: 0 | CB40: 0 | CC40: 0 | CD40: 0 | CE40: 0 | CF40: 0 | CG40: 0 | CH40: 0 | CI40: 0 | CJ40: 0 | CK40: 0 | CL40: 0 | CM40: 0 | CN40: 0 | CO40: 0 | CP40: 0
A41: Prior Year Retained Earnigs | B41: 11835925 | C41: 22842014 | D41: 28642685 | E41: 28642685 | F41: 41987254 | G41: 66804781 | H41: 85290511 | I41: 1.0522816e+08 | J41: 92673150 | K41: 87459635 | L41: 87459635 | M41: 87459635 | N41: 87459997 | O41: 87459997 | P41: 87459997 | Q41: 87459997 | R41: 87459997 | S41: 87459997 | T41: 87459997 | U41: =92673511+4241241-9454756 -> 87459996 | V41: 98395373 | W41: 98395373 | X41: 98395373 | Y41: 98395373 | Z41: 98395373 | AA41: 98395373 | AB41: 98395373 | AC41: 98395373 | AD41: 98395373 | AE41: 98395373 | AF41: 98395373 | AG41: 99109747 | AH41: 99117197 | AI41: 1.2674323e+08 | AJ41: 1.2674323e+08 | AK41: 1.2674323e+08 | AL41: 1.266404e+08 | AM41: 1.3185392e+08 | AN41: 1.3185392e+08 | AO41: 1.3185392e+08 | AP41: 1.3185392e+08 | AQ41: 1.3185392e+08 | AR41: 1.3185392e+08 | AS41: 1.3185392e+08 | AT41: 1.266404e+08 | AU41: 1.2674323e+08 | AV41: 1.4538891e+08 | AW41: 1.4538891e+08 | AX41: 1.4538891e+08 | AY41: 1.4538891e+08 | AZ41: 1.4538891e+08 | BB41: 7.2694456e+08 | BC41: 1.4538891e+08 | BD41: 1.4538891e+08 | BE41: 1.4538891e+08 | BF41: 1.4538891e+08 | BG41: 145388913 | BH41: 1.6274497e+08 | BI41: 1.6274497e+08 | BJ41: 1.6274497e+08 | BK41: 1.6274497e+08 | BL41: 1.6274497e+08 | BM41: 1.6274497e+08 | BN41: 1.6274497e+08 | BO41: 1.6274497e+08 | BP41: 1.6274497e+08 | BQ41: 1.6274497e+08 | BR41: 1.6274497e+08 | BS41: 1.6274497e+08 | BT41: 162744967 | BU41: 1.7690475e+08 | BV41: 1.7690475e+08 | BW41: 1.7690475e+08 | BX41: 1.7690475e+08 | BY41: 1.7690475e+08 | BZ41: 1.7690475e+08 | CA41: 1.7690475e+08 | CB41: 1.7690475e+08 | CC41: 1.7690475e+08 | CD41: 1.7690475e+08 | CE41: 1.7697195e+08 | CF41: 1.7703915e+08 | CG41: 176904749 | CH41: 1.7710635e+08 | CI41: 1.7855689e+08 | CJ41: 1.7859189e+08 | CK41: 1.7859189e+08 | CL41: 1.7872629e+08 | CM41: 1.7872629e+08 | CN41: 1.7872629e+08 | CO41: 1.7877329e+08 | CP41: 1.7883049e+08
A42: Current Year Surplus | E42: 13344568 | F42: 19604846 | G42: 18304471 | H42: 7382638 | I42: -2547032.5 | J42: 5184516.2 | K42: 8499121.4 | L42: 8401507.7 | M42: 10638453 | N42: 21324690 | O42: 18334763 | P42: 27498158 | Q42: 37462432 | R42: 40863811 | S42: 47300356 | T42: 18380415 | U42: =104330710+4241241-9454756-U41 -> 11657199 | V42: 439270.18 | W42: 4336331.2 | X42: 5822529.8 | Y42: 6193149 | Z42: 10721731 | AA42: 25094260 | AB42: 27591487 | AC42: 32438939 | AD42: 35982398 | AE42: 42361872 | AF42: 49373027 | AG42: 34568896 | AH42: =126743228-99117196 -> 27626032 | AI42: 4215190.2 | AJ42: 7446296.2 | AK42: 8442656.9 | AL42: 7987493.3 | AM42: 13137787 | AN42: 27479635 | AO42: 31263361 | AP42: 30481937 | AQ42: 32247910 | AR42: 34528368 | AS42: 28795651 | AT42: 24360400 | AU42: 18645686 | AV42: 7048076.5 | AW42: 9615532.4 | AX42: 21852931 | AY42: 16852969 | AZ42: 16523321 | BB42: 92455243 | BC42: 19646034 | BD42: 20255977 | BE42: 19559975 | BF42: 21695270 | BG42: =162745129-BG41 -> 17356216 | BH42: 3092220 | BI42: -1025671.6 | BJ42: -307492.51 | BK42: 17740003 | BL42: 17250304 | BM42: 19775738 | BN42: 15305733 | BO42: 23934423 | BP42: 27733378 | BQ42: 33576266 | BR42: 36131737 | BS42: 26427142 | BT42: =17699727-3539945 -> 14159782 | BU42: 1225.02 | BV42: 1480825.1 | BW42: 1631135.9 | BX42: 2601389.2 | BY42: 2610646.7 | BZ42: 20720815 | CA42: 19266249 | CB42: 20396851 | CC42: 25267096 | CD42: 27310452 | CE42: 26859560 | CF42: 2530653 | CG42: =4368747-873749 -> 3494998 | CH42: 6402410.2 | CI42: 12808217 | CJ42: 4692622.7 | CK42: 1342571.7 | CL42: -1714145.6 | CM42: 11168490 | CN42: 3632321.7 | CO42: 3780132.3 | CP42: 5153741.8
...

Sheet Evolutitve SCI
B2: 2010 Audited | C2: 2011 Audited | D2: 2012 Audited | E2: 2013 Audited | F2: 2014 Audited | G2: 2015 Audited | H2: Audited-2016 | I2: 42736 | J2: 42767 | K2: 42795 | L2: 42826 | M2: 42856 | N2: 42887 | O2: 42917 | P2: 42948 | Q2: 42979 | R2: 43009 | S2: 43040 | T2: 43070 | U2: Audited 2017 | V2: 43101 | W2: 43132 | X2: 43160 | Y2: 43191 | Z2: 43221 | AA2: 43252 | AB2: 43282 | AC2: 43313 | AD2: 43344 | AE2: 43374 | AF2: 43405 | AG2: 43435 | AH2: Audited 2018 | AI2: 43466 | AJ2: 43497 | AK2: 43525 | AL2: 43556 | AM2: 43586 | AN2: 43617 | AO2: 43647 | AP2: 43678 | AQ2: 43709 | AR2: 43739 | AS2: 43770 | AT2: 43800 | AU2: Audited -19 | AV2: 43831 | AW2: 43862 | AX2: 43891 | AY2: 43922 | AZ2: 43952 | BA2: 43983 | BB2: 44013 | BC2: 44044 | BD2: 44075 | BE2: 44105 | BF2: 44136 | BG2: 44166 | BH2: Audited 2020 | BI2: 44197 | BJ2: 44228 | BK2: 44256 | BL2: 44287 | BM2: 44317 | BN2: 44348 | BO2: 44378 | BP2: 44409 | BQ2: 44440 | BR2: 44470 | BS2: 44501 | BT2: 44531 | BU2: AUDITED 2021 | BV2: 44562 | BW2: 44593 | BX2: 44621 | BY2: 44652 | BZ2: 44682 | CA2: 44713 | CB2: 44743 | CC2: 44774 | CD2: 44805 | CE2: 44835 | CF2: 44866 | CG2: 44896 | CH2: Audited 2022 | CI2: 44927 | CJ2: 44958 | CK2: 44986 | CL2: 45017 | CM2: 45047 | CN2: 45078 | CO2: 45108 | CP2: 45139 | CQ2: 45170
A3: Financial Income | B3: =B4+B7 -> 53102019 | C3: =C4+C7 -> 67876418 | D3: =D4+D7 -> 76649112 | E3: =E4+E7 -> 93967038 | F3: =F4+F7 -> 97400688 | G3: =G4+G7 -> 109849160 | H3: =H4+H7 -> 121408969 | I3: =I4+I7 -> 3091134.1 | ... CQ3: =CQ4+CQ7 -> 1.3218021e+08
A4: Financial Income From Loans Portfolio | B4: =SUM(B5:B6) -> 50952511 | C4: =SUM(C5:C6) -> 64376963 | D4: =SUM(D5:D6) -> 71327939 | E4: =SUM(E5:E6) -> 91151179 | F4: =SUM(F5:F6) -> 96129457 | G4: =SUM(G5:G6) -> 100764347 | H4: =SUM(H5:H6) -> 110622193 | I4: =SUM(I5:I6) -> 3028199.4 | ... CQ4: =SUM(CQ5:CQ6) -> 1.0459137e+08
A5: Interest from Loans Portfolio | B5: 50952511 | C5: 64376963 | D5: 71327939 | E5: 86602624 | F5: 88158935 | G5: 100764347 | H5: 110622193 | I5: 2868188.9 | J5: 14794810 | K5: 24180326 | L5: 31297315 | M5: 41273174 | N5: 49549690 | O5: 53182016 | P5: 68046945 | Q5: 84380465 | R5: 95511940 | S5: 1.0620336e+08 | T5: 1.1721042e+08 | U5: =98585000+19265753 -> 117850753 | V5: 9208005.3 | W5: 18006762 | X5: 26799725 | Y5: 37559024 | Z5: 47882224 | AA5: 57664039 | AB5: 67846813 | AC5: 81255071 | AD5: 92271849 | AE5: 1.0341602e+08 | AF5: 1.1626765e+08 | AG5: 1.340784e+08 | AH5: 1.3507927e+08 | AI5: 10779776 | AJ5: 20634639 | AK5: 29869064 | AL5: 40819244 | AM5: 51565485 | AN5: 61723671 | AO5: 72536460 | AP5: 85936392 | AQ5: 96493685 | AR5: 1.074543e+08 | AS5: 1.2030611e+08 | AT5: 1.3999979e+08 | AU5: =130842649+14178970 -> 145021619 | AV5: 11133372 | AW5: 21508770 | AX5: 32179727 | AY5: 42120329 | AZ5: 51676831 | BA5: 61706603 | BC5: 4.2683181e+08 | BD5: 97119582 | BE5: 1.0886469e+08 | BF5: 1.2376955e+08 | BG5: 1.3553253e+08 | BH5: =127900472+12767459 -> 140667931 | BI5: 10709523 | BJ5: 21229623 | BK5: 32780903 | BL5: 45271098 | BM5: 56726775 | BN5: 69182392 | BO5: 82435360 | BP5: 94223479 | BQ5: 1.0680823e+08 | BR5: 1.1977113e+08 | BS5: 1.3276324e+08 | BT5: 141785212 | BU5: =16202154+473815+2790361+20140471+26083517+931116+65625875+9537904+10679252+6010634 -> 158475099 | BV5: 11517400 | BW5: 23255634 | BX5: 36328633 | BY5: 49802954 | BZ5: 61411495 | CA5: 73628124 | CB5: 85826149 | CC5: 98360828 | CD5: 1.1065672e+08 | CE5: 1.2254381e+08 | CF5: 1.3545411e+08 | CG5: 1.4899086e+08 | CH5: =9125570+503604+2728651+16012771+23253585+2653613+66090976+18588530+14122299 -> 153079599 | CI5: 12585432 | CJ5: 24092713 | CK5: 35041788 | CL5: 45499156 | CM5: 55867888 | CN5: 65409827 | CO5: 75335349 | CP5: 85254974 | CQ5: 96635030
A6: Fees&Commision on Loan Portfolio | E6: 4548555 | F6: 7970522 | I6: 160010.5 | J6: 684903 | K6: 1082892 | L6: 1304579 | M6: 1765514 | N6: 2217595.5 | O6: 2422650 | P6: 3029184.5 | Q6: 3240640.4 | R6: 3659252.9 | S6: 4218798.9 | T6: 4659610.9 | V6: 419236.5 | W6: 739980 | X6: 1137050 | Y6: 1565835.5 | Z6: 1979664 | AA6: 2356294.5 | AB6: 2750586 | AC6: 3182866.5 | AD6: 3559697 | AE6: 3968232.5 | AF6: 4435514.5 | AG6: 4832283.5 | AH6: 1009779.5 | AI6: 356522 | AJ6: 719866 | AK6: 1561042 | AL6: 1962668.5 | AM6: 2432963 | AN6: 2886826 | AO6: 3155796.5 | AP6: 3796119 | AQ6: 4216612.5 | AR6: 4609835.5 | AS6: 5072617.5 | AT6: 5634613.3 | AU6: 15602300 | AV6: 384164 | AW6: 732437.5 | AX6: 1531351.5 | AY6: 1667915.8 | AZ6: 2026809.3 | BA6: 2432941.1 | BC6: 16427884 | BD6: 3946043 | BE6: 4653567.7 | BF6: 4993921 | BG6: 5773405.7 | BH6: 16934119 | BI6: 388395.8 | BJ6: 1343426.5 | BK6: 1587365.5 | BL6: 2358388.3 | BM6: 2866267.8 | BN6: 3450233.5 | BO6: 3927265.5 | BP6: 4314177 | BQ6: 4693065 | BR6: 5112169 | BS6: 5603306 | BT6: 16689886 | BV6: 354136 | BW6: 586116 | BX6: 1312992.5 | BY6: 1689955 | BZ6: 1979843.8 | CA6: 2219442.5 | CB6: 2552272.5 | CC6: 2896134 | CD6: 3236425 | CE6: 3121429 | CF6: 3448774 | CG6: 3807134 | CH6: 0 | CI6: 310464.5 | CJ6: 636643.5 | CK6: 918249 | CL6: 1060765.5 | CM6: 1460989.5 | CN6: 2467715 | CO6: 3868671 | CP6: 6063909.3 | CQ6: 7956337
A7: Financial Income from Investments | B7: =SUM(B8:B11) -> 2149508 | C7: =SUM(C8:C11) -> 3499455 | D7: =SUM(D8:D11) -> 5321173 | E7: =SUM(E8:E11) -> 2815858.9 | F7: =SUM(F8:F11) -> 1271231 | G7: =SUM(G8:G11) -> 9084813 | H7: =SUM(H8:H11) -> 10786776 | I7: =SUM(I8:I11) -> 62934.75 | ... CQ7: =SUM(CQ8:CQ11) -> 27588846
A8: Government Securities | I8: 0 | J8: 0 | K8: 0 | L8: 0 | M8: 0 | N8: 0 | O8: 0 | P8: 0 | Q8: 0 | R8: 0 | S8: 0 | T8: 0 | V8: 0 | W8: 0 | X8: 0 | Y8: 0 | Z8: 0 | AB8: 0 | AC8: 0 | AD8: 0 | AE8: 0 | AF8: 0 | AG8: 0 | AH8: 0 | AI8: 0 | AJ8: 0 | AK8: 0 | AL8: 0 | AM8: 0 | AN8: 0 | AO8: 0 | AP8: 0 | AQ8: 0 | AR8: 0 | AS8: 0 | AT8: 0 | AV8: 0 | AW8: 0 | AX8: 0 | AY8: 0 | AZ8: 0 | BA8: 0 | BC8: 0 | BD8: 0 | BE8: 0 | BF8: 0 | BG8: 0 | BH8: 0 | BI8: 0 | BJ8: 0 | BK8: 0 | BL8: 0 | BM8: 0 | BN8: 0 | BO8: 0 | BP8: 0 | BQ8: 0 | BR8: 0 | BS8: 0 | BT8: 0 | BV8: 0 | BW8: 0 | BX8: 0 | BY8: 0 | BZ8: 0 | CA8: 0 | CB8: 0 | CC8: 0 | CD8: 0 | CE8: 0 | CF8: 0 | CG8: 0 | CH8: 0 | CI8: 0 | CJ8: 0 | CK8: 0 | CL8: 0 | CM8: 0 | CN8: 0 | CO8: 0 | CP8: 0 | CQ8: 0
A9: Deposits with Banks & other Financial Institutions | D9: 192164 | G9: 3023515 | H9: 1911481 | I9: 0 | J9: 0 | K9: 0 | L9: 0 | M9: 0 | N9: 0 | O9: 0 | P9: 0 | Q9: 0 | R9: 0 | S9: 0 | T9: 0 | U9: 2754941 | V9: 0 | W9: 0 | X9: 0 | Y9: 0 | Z9: 0 | AA9: 0 | AB9: 0 | AC9: 0 | AD9: 0 | AE9: 0 | AF9: 0 | AG9: 0 | AH9: 3122591.9 | AI9: 0 | AJ9: 0 | AK9: 0 | AL9: 0 | AM9: 0 | AN9: 0 | AO9: 0 | AP9: 0 | AQ9: 0 | AR9: 0 | AS9: 0 | AT9: 0 | AV9: 0 | AW9: 0 | AX9: 0 | AY9: 0 | AZ9: 0 | BA9: 0 | BC9: 0 | BD9: 0 | BE9: 0 | BF9: 0 | BG9: 0 | BH9: 0 | BI9: 0 | BJ9: 0 | BK9: 0 | BL9: 0 | BM9: 0 | BN9: 0 | BO9: 0 | BP9: 0 | BQ9: 0 | BR9: 0 | BS9: 0 | BT9: 0 | BU9: =5866877+13846281 -> 19713158 | BV9: 0 | BW9: 0 | BX9: 0 | BY9: 0 | BZ9: 0 | CA9: 0 | CB9: 0 | CC9: 0 | CD9: 0 | CE9: 0 | CF9: 0 | CG9: 0 | CH9: =7362474 -> 7362474 | CI9: 0 | CJ9: 0 | CK9: 0 | CL9: 0 | CM9: 0 | CN9: 0 | CO9: 0 | CP9: 0 | CQ9: 0
A10: Other Investments | C10: 2985205 | D10: 3645569 | G10: 5162510 | H10: 7897142 | I10: 0 | J10: 0 | K10: 148904 | L10: 148904 | M10: 148904 | N10: 8322808.2 | O10: 8700967 | P10: 8700967 | Q10: 9499936.7 | R10: 9499936.7 | S10: 9499936.7 | T10: 11323411 | U10: =8568471 -> 8568471 | V10: 103249.31 | W10: 103249.31 | X10: 1117870.6 | Y10: 1161616.7 | Z10: 1161616.7 | AA10: 11514809 | AB10: 11935898 | AC10: 11935898 | AD10: 11935898 | AE10: 13000654 | AF10: 13000654 | AG10: 13896873 | AH10: 10774281 | AI10: 0 | AJ10: 0 | AK10: 405545.5 | AL10: 911783.55 | AM10: 911783.55 | AN10: 14471442 | AO10: 14471442 | AP10: 14471442 | AQ10: 14471442 | AR10: 14471442 | AS10: 15037042 | AT10: 15602300 | AV10: 0 | AW10: 0 | AX10: 661492.71 | AY10: 13634506 | AZ10: 13634506 | BA10: 14013961 | BC10: 72157761 | BD10: 14431552 | BE10: 14431552 | BF10: 15345940 | BG10: 16934119 | BI10: 0 | BJ10: 0 | BK10: 898828.96 | BL10: 14140931 | BM10: 14188683 | BN10: 14238957 | BO10: 15230178 | BP10: 15443936 | BQ10: 15443936 | BR10: 16803423 | BS10: 17176798 | BT10: 18684341 | BV10: 196712.23 | BW10: 368583.64 | BX10: 1794054 | BY10: 1984724.8 | BZ10: 2183937.3 | CA10: 15259034 | CB10: 15458457 | CC10: 15710336 | CD10: 17276219 | CE10: 17835289 | CF10: 18200130 | CG10: 20071347 | CH10: =14038227 -> 14038227 | CI10: 212475.66 | CJ10: 212475.66 | CK10: 2126424.2 | CL10: 2349875.6 | CM10: 2503122 | CN10: 21506463 | CO10: 22321501 | CP10: 22572106 | CQ10: 23831347
A11: Other Operating Income | B11: 2149508 | C11: 514250 | D11: 1483440 | E11: 2815858.9 | F11: 1271231 | G11: 898788 | H11: 978153 | I11: 62934.75 | J11: 134420.75 | K11: 590604.05 | L11: 640168.05 | M11: 689009.05 | N11: 735406.05 | O11: 782221.05 | P11: 850532.05 | Q11: 897139.05 | R11: 942942.05 | S11: 1003607.1 | T11: 1084933.1 | U11: =2352540+1207016+269395+1275263 -> 5104214 | V11: 66166 | W11: 113781 | X11: 694577.03 | Y11: 783282.03 | Z11: 883097.03 | AA11: 948752.03 | AB11: 1066777 | AC11: 1175999 | AD11: 1316779.5 | AE11: 1403479.5 | AF11: 1670776.2 | AG11: 1732964.5 | AH11: =2538450+2029096.49 -> 4567546.5 | AI11: 57671 | AJ11: 168370 | AK11: 338320.9 | AL11: 429615.2 | AM11: 556861.2 | AN11: 676841.2 | AO11: 769827.2 | AP11: 975013.2 | AQ11: 1143198.2 | AR11: 1225373.2 | AS11: 1301493.2 | AT11: 1552888.2 | AU11: 2165674 | AV11: 65745 | AW11: 151880 | AX11: 369402.54 | AY11: 672682.87 | AZ11: 718648.87 | BA11: 865957.87 | BC11: 5106864.3 | BD11: 1186662 | BE11: 1376874.9 | BF11: 1708680.6 | BG11: 1685748.7 | BH11: 2323752 | BI11: 82690 | BJ11: 774111.75 | BK11: 1529008.2 | BL11: 1673600.5 | BM11: 1842394 | BN11: 2018716.2 | BO11: 2208453.2 | BP11: 2418850.2 | BQ11: 2595095.8 | BR11: 2751830.2 | BS11: 3054745.2 | BT11: 4955778 | BU11: =427500+4255971+272308 -> 4955779 | BV11: 65376.5 | BW11: 1424116.5 | BX11: 1573642.8 | BY11: 1677630.2 | BZ11: 1880704.5 | CA11: 2183662.8 | CB11: 2336404.8 | CC11: 2491126.8 | CD11: 2638147.8 | CE11: 3194652.6 | CF11: 3608727.6 | CG11: 4990642 | CH11: =463500+4122116+123720 -> 4709336 | CI11: 112065 | CJ11: 393924 | CK11: 2139993.2 | CL11: 2294733.3 | CM11: 2800013.1 | CN11: 3057545.1 | CO11: 3364952.2 | CP11: 3465649.8 | CQ11: 3757499.2
A12: Financial Expenses | B12: =SUM(B13:B18) -> 24208136 | C12: =SUM(C13:C18) -> 28170518 | D12: =SUM(D13:D18) -> 34989634 | E12: =SUM(E13:E18) -> 39113127 | F12: =SUM(F13:F18) -> 35705528 | G12: =SUM(G13:G18) -> 35360127 | H12: =SUM(H13:H18) -> 37075248 | I12: =SUM(I13:I18) -> 2576230 | ... CQ12: =SUM(CQ13:CQ18) -> 57047544
A13: Interest Expense on Deposits | B13: 24208136 | C13: 16622609 | D13: 18348921 | E13: 23984697 | F13: 28323856 | G13: 33281648 | H13: 35950953 | I13: 2500000 | J13: 5000000 | K13: 7500000 | L13: 10500000 | M13: 13500000 | N13: 16500000 | O13: 19500000 | P13: 22500000 | Q13: 25500000 | R13: 28500000 | S13: 31500000 | T13: 41271904 | U13: 44018009 | V13: 3000000 | W13: 6000000 | X13: 9000000 | Y13: 12000000 | Z13: 15000000 | AA13: 18000000 | AB13: 20998521 | AC13: 23998521 | AD13: 26998521 | AE13: 26998521 | AF13: 32998521 | AG13: 44528105 | AH13: 44528105 | AI13: 3000000 | AJ13: 6000000 | AK13: 9000000 | AL13: 12000000 | AM13: 15000000 | AN13: 18000000 | AO13: 21000000 | AP13: 24000000 | AQ13: 27000000 | AR13: 30000000 | AS13: 43000000 | AT13: 54334919 | AU13: 54408213 | AV13: 3556219.6 | AW13: 7056219.6 | AX13: 10556220 | AY13: 14056220 | AZ13: 17556220 | BA13: 21056220 | BC13: 155281098 | BD13: 36056220 | BE13: 41056220 | BF13: 46056220 | BG13: 52341453 | BH13: 56353562 | BI13: 5000000 | BJ13: 10000000 | BK13: 15000000 | BL13: 20000000 | BM13: 25000000 | BN13: 30000000 | BO13: 35000000 | BP13: 40000000 | BQ13: 45000000 | BR13: 50000000 | BS13: 55000000 | BT13: 75922160 | BU13: =75922160+1158317 -> 77080477 | BV13: 5000000 | BW13: 10000000 | BX13: 15416667 | BY13: 20833334 | BZ13: 26250001 | CA13: 31666668 | CB13: 37083335 | CC13: 42500002 | CD13: 47916669 | CE13: 53333336 | CF13: 58750003 | CG13: 80488582 | CH13: =80488582+1465241 -> 81953823 | CI13: 5416667 | CJ13: 10833334 | CK13: 16250001 | CL13: 22916668 | CM13: 29583335 | CN13: 37215693 | CO13: 43882360 | CP13: 49299027 | CQ13: 54715694
A14: Cost of External Borrowings | C14: 10569123 | D14: 15436251 | E14: 14077264 | F14: 6809774 | G14: 1293620 | I14: 0 | J14: 0 | K14: 0 | L14: 0 | M14: 0 | N14: 0 | O14: 0 | P14: 0 | Q14: 0 | R14: 0 | S14: 0 | T14: 0 | U14: 0 | V14: 0 | W14: 0 | X14: 0 | Y14: 0 | Z14: 0 | AA14: 0 | AB14: 0 | AC14: 0 | AD14: 0 | AE14: 0 | AF14: 0 | AG14: 0 | AH14: -61659.54 | AI14: 0 | AJ14: 0 | AK14: 0 | AL14: 0 | AM14: 0 | AN14: 0 | AO14: 0 | AP14: 0 | AQ14: 0 | AR14: 0 | AS14: 0 | AT14: 0 | AU14: 0 | AV14: 0 | AW14: 0 | AX14: 0 | AY14: 0 | AZ14: 0 | BA14: 0 | BC14: 0 | BD14: 0 | BE14: 0 | BF14: 0 | BG14: 0 | BH14: 0 | BI14: 0 | BJ14: 0 | BK14: 0 | BL14: 0 | BM14: 0 | BN14: 0 | BO14: 0 | BP14: 0 | BQ14: 0 | BR14: 0 | BS14: 0 | BT14: 0 | BV14: 0 | BW14: 0 | BX14: 0 | BY14: 0 | BZ14: 0 | CA14: 0 | CB14: 0 | CC14: 0 | CD14: 0 | CE14: 0 | CF14: 0 | CG14: 0 | CH14: 0 | CI14: 0 | CJ14: 0 | CK14: 0 | CL14: 0 | CM14: 0 | CN14: 0 | CO14: 0 | CP14: 0 | CQ14: 0
A15: Dividend Expenses | I15: 0 | J15: 0 | K15: 0 | L15: 0 | M15: 0 | N15: 0 | O15: 0 | P15: 0 | Q15: 0 | R15: 0 | S15: 0 | T15: 0 | V15: 0 | W15: 0 | X15: 0 | Y15: 0 | Z15: 0 | AA15: 0 | AB15: 0 | AC15: 0 | AD15: 0 | AE15: 0 | AF15: 0 | AG15: 0 | AH15: 0 | AI15: 0 | AJ15: 0 | AK15: 0 | AL15: 0 | AM15: 0 | AN15: 0 | AO15: 0 | AP15: 0 | AQ15: 0 | AR15: 0 | AS15: 0 | AT15: 0 | AU15: 0 | AV15: 0 | AW15: 0 | AX15: 0 | AY15: 0 | AZ15: 0 | BA15: 0 | BC15: 0 | BD15: 0 | BE15: 0 | BF15: 0 | BG15: 0 | BH15: 0 | BI15: 0 | BJ15: 0 | BK15: 0 | BL15: 0 | BM15: 0 | BN15: 0 | BO15: 0 | BP15: 0 | BQ15: 0 | BR15: 0 | BS15: 0 | BT15: 0 | BV15: 0 | BW15: 0 | BX15: 0 | BY15: 0 | BZ15: 0 | CA15: 0 | CB15: 0 | CC15: 0 | CD15: 0 | CE15: 0 | CF15: 0 | CG15: 0 | CH15: 0 | CI15: 0 | CJ15: 0 | CK15: 0 | CL15: 0 | CM15: 0 | CN15: 0 | CO15: 0 | CP15: 0 | CQ15: 0
A16: Other Financial Expense | D16: 1204462 | E16: 1051165.3 | F16: 571898 | G16: 784859 | H16: 1124295 | I16: 76230 | J16: 186707.84 | K16: 219929.84 | L16: 314295.34 | M16: 459617.31 | N16: 492626.31 | O16: 562075.81 | P16: 646703.37 | Q16: 772138.12 | R16: 861243.38 | S16: 954127.88 | T16: 1510545.9 | U16: 1267985 | V16: 32407.26 | W16: 101627.26 | X16: 198168.26 | Y16: 349355.26 | Z16: 384184.76 | AA16: 411961.76 | AB16: 554577.76 | AC16: 607109.76 | AD16: 608863.76 | AE16: 646108.76 | AF16: 797413.76 | AG16: 996501.45 | AH16: 996703.74 | AI16: 56130 | AJ16: 102799 | AK16: 173438 | AL16: 497034.51 | AM16: 602206.25 | AN16: 695390.57 | AO16: 743053.57 | AP16: 1006424.9 | AQ16: 1035262.9 | AR16: 1133930.9 | AS16: 1234740.9 | AT16: 1843087.8 | AV16: 139380.61 | AW16: 169866.61 | AX16: 377071.61 | AY16: 451381.61 | AZ16: 505025.61 | BA16: 722671.61 | BC16: 4594739.1 | BD16: 967698.66 | BE16: 1130376.7 | BF16: 1271147.7 | BG16: 1484200.6 | BH16: =9290500-BH21 -> 1288888.2 | BI16: 44659 | BJ16: 277080 | BK16: 435759.03 | BL16: 534831.99 | BM16: 752659.37 | BN16: 912591.34 | BO16: 960204.34 | BP16: 1135739.6 | BQ16: 1325374.6 | BR16: 1387578.6 | BS16: 1618197.6 | BT16: 2519448 | BU16: 1361131 | BV16: 52440 | BW16: 237298 | BX16: 615045.65 | BY16: 893952.65 | BZ16: 1081672.6 | CA16: 1280877.6 | CB16: 1497006.5 | CC16: 1809049.9 | CD16: 1977916.2 | CE16: 2171780.2 | CF16: 2470034.2 | CG16: 2718497.3 | CH16: 1253256 | CI16: 245384.75 | CJ16: 402528.75 | CK16: 596088.59 | CL16: 893455.45 | CM16: 1102349.5 | CN16: 1478470.5 | CO16: 1767932 | CP16: 2067810.7 | CQ16: 2331850.4
