Workbook
Name BALANCE1_LDA01: '[1]Financial Statements'!$E$112
Name BALANCE1_LDA12: '[1]Financial Statements'!$E$123
Name BALANCE2_LDA01: '[1]Financial Statements'!$F$112
Name BALANCE2_LDA12: '[1]Financial Statements'!$F$123
Name BALANCE3_LDA01: '[1]Financial Statements'!$G$112
Name BALANCE3_LDA12: '[1]Financial Statements'!$G$123
Name BALANCE4_LDA01: '[1]Financial Statements'!$H$112
Name BALANCE4_LDA12: '[1]Financial Statements'!$H$123
Name BALANCE5_LDA01: '[1]Financial Statements'!$I$112
Name BALANCE5_LDA12: '[1]Financial Statements'!$I$123
Name BALANCE6_LDA01: '[1]Financial Statements'!$J$112
Name BALANCE6_LDA12: '[1]Financial Statements'!$J$123
Name NotApplicable: 'Prudential Ratios'!#REF!
Name PEARLS1_LA002: '[1]Financial Statements'!$E$280
Name PEARLS1_LE008: '[1]Financial Statements'!$E$275
Name PEARLS1_LE009: '[1]Financial Statements'!$E$276
Name PEARLS1_LR001: '[1]Financial Statements'!$E$282
Name PEARLS1_LR005: '[1]Financial Statements'!$E$286
Name PEARLS1_LR006: '[1]Financial Statements'!$E$287
Name PEARLS1_LR007: '[1]Financial Statements'!$E$288
Name PEARLS1_LR009: '[1]Financial Statements'!$E$290
Name PEARLS1_LS001: '[1]Financial Statements'!$E$298
Name PEARLS1_LS005: '[1]Financial Statements'!$E$302
Name PEARLS1_LS011: '[1]Financial Statements'!$E$308
Name PEARLS2_LA002: '[1]Financial Statements'!$F$280
Name PEARLS2_LE008: '[1]Financial Statements'!$F$275
Name PEARLS2_LE009: '[1]Financial Statements'!$F$276
Name PEARLS2_LR001: '[1]Financial Statements'!$F$282
Name PEARLS2_LR005: '[1]Financial Statements'!$F$286
Name PEARLS2_LR006: '[1]Financial Statements'!$F$287
Name PEARLS2_LR007: '[1]Financial Statements'!$F$288
Name PEARLS2_LR009: '[1]Financial Statements'!$F$290
Name PEARLS2_LS001: '[1]Financial Statements'!$F$298
Name PEARLS2_LS005: '[1]Financial Statements'!$F$302
Name PEARLS2_LS010: '[1]Financial Statements'!$F$307
Name PEARLS2_LS011: '[1]Financial Statements'!$F$308
Name PEARLS3_LA002: '[1]Financial Statements'!$G$280
Name PEARLS3_LE008: '[1]Financial Statements'!$G$275
Name PEARLS3_LE009: '[1]Financial Statements'!$G$276
Name PEARLS3_LR001: '[1]Financial Statements'!$G$282
Name PEARLS3_LR005: '[1]Financial Statements'!$G$286
Name PEARLS3_LR006: '[1]Financial Statements'!$G$287
Name PEARLS3_LR007: '[1]Financial Statements'!$G$288
Name PEARLS3_LR009: '[1]Financial Statements'!$G$290
Name PEARLS3_LS001: '[1]Financial Statements'!$G$298
Name PEARLS3_LS005: '[1]Financial Statements'!$G$302
Name PEARLS3_LS010: '[1]Financial Statements'!$G$307
Name PEARLS3_LS011: '[1]Financial Statements'!$G$308
Name PEARLS4_LA002: '[1]Financial Statements'!$H$280
Name PEARLS4_LE008: '[1]Financial Statements'!$H$275
Name PEARLS4_LE009: '[1]Financial Statements'!$H$276
Name PEARLS4_LR001: '[1]Financial Statements'!$H$282
Name PEARLS4_LR005: '[1]Financial Statements'!$H$286
Name PEARLS4_LR006: '[1]Financial Statements'!$H$287
Name PEARLS4_LR007: '[1]Financial Statements'!$H$288
Name PEARLS4_LR009: '[1]Financial Statements'!$H$290
Name PEARLS4_LS001: '[1]Financial Statements'!$H$298
Name PEARLS4_LS005: '[1]Financial Statements'!$H$302
Name PEARLS4_LS010: '[1]Financial Statements'!$H$307
Name PEARLS4_LS011: '[1]Financial Statements'!$H$308

Sheet SFP
A1: MAGEREZA SACCO SOCIETY
A2: STATEMENT OF FINANCIAL POSITION | N2: Approved | Z2: Restated 2021 | AA2: Variances btw
B3: january | C3: february | D3: march | E3: april | F3: may | G3: june | H3: july | I3: august | J3: september | K3: october | L3: november | M3: december | N3: Audited 2021 | O3: Feb | P3: Mar | Q3: Apr | R3: May | S3: Jun | T3: Jul | U3: Aug | V3: Sep | W3: Oct | X3: Nov | Y3: Dec | Z3: by the Auditor | AA3: Audited & restated 2021 | AB3: Audited 2022 | AC3: 44927 | AD3: 44958 | AE3: 44986 | AF3: 45017 | AG3: 45047 | AH3: 45078 | AI3: 45108 | AJ3: 45139 | AK3: 45170 | AL3: 45200 | AM3: 45231
A4: Cash & Cash Equivalent | B4: =SUM(B5:B6) -> 252652851 | C4: =SUM(C5:C6) -> 2.4646583e+08 | D4: =SUM(D5:D6) -> 2.8979676e+08 | E4: =SUM(E5:E6) -> 1.3139564e+08 | F4: =SUM(F5:F6) -> 4.7950328e+08 | G4: =SUM(G5:G6) -> 7.8374847e+08 | H4: =SUM(H5:H6) -> 4.8954418e+08 | I4: =SUM(I5:I6) -> 7.1282297e+08 | ... Z4: =SUM(Z5:Z6) -> 817345916 | AA4: =N4-Z4 -> 0.45999992 | AB4: =SUM(AB5:AB6) -> 576228117 | AC4: =SUM(AC5:AC6) -> 4.7511467e+08 | AD4: =SUM(AD5:AD6) -> 82486263 | AE4: =SUM(AE5:AE6) -> 2.2994973e+08 | AF4: =SUM(AF5:AF6) -> -1.8637487e+08 | AG4: =SUM(AG5:AG6) -> -1.9792849e+08 | AH4: =SUM(AH5:AH6) -> 4.576633e+08 | AI4: =SUM(AI5:AI6) -> 2.0244814e+08 | ... AM4: =SUM(AM5:AM6) -> 0
A5: Cash in hand | B5: 18470331 | C5: 16028065 | D5: 20227208 | E5: 15726577 | F5: 18747147 | G5: 16139622 | H5: 15034465 | I5: 22294319 | J5: 21418992 | L5: 20328685 | M5: 25406966 | N5: ='[2]Notes 5'!$F$28 -> 23061474 | O5: 29603301 | P5: 23865542 | Q5: 18204276 | R5: 21126692 | S5: 31702211 | T5: 19914594 | U5: 27118225 | V5: 28534340 | W5: 23705535 | X5: 30336093 | Y5: 44433202 | Z5: 23061474 | AA5: =N5-Z5 -> 0 | AB5: 42524958 | AC5: 12531247 | AD5: 35728786 | AE5: 29311432 | AF5: 26645935 | AG5: 20532897 | AH5: 22975898 | AI5: 31097132 | AJ5: 22037542
A6: Cash at bank | B6: 234182520 | C6: 2.3043776e+08 | D6: 2.6956955e+08 | E6: 1.1566906e+08 | F6: 4.6075614e+08 | G6: 7.6760885e+08 | H6: 4.7450971e+08 | I6: 6.9052865e+08 | J6: 4.4602846e+08 | L6: 7.169999e+08 | M6: 7.6036042e+08 | N6: ='[2]Notes 5'!$F$24 -> 7.9428444e+08 | O6: 5.203664e+08 | P6: 6.4949863e+08 | Q6: 1.6956189e+08 | R6: 4.0283222e+08 | S6: 4.7965176e+08 | T6: 4.7530917e+08 | U6: 3.3368232e+08 | V6: 6.0174176e+08 | W6: 3.9919773e+08 | X6: 3.200292e+08 | Y6: 4.9266075e+08 | Z6: 794284442 | AA6: =N6-Z6 -> 0.45999992 | AB6: 533703159 | AC6: 4.6258343e+08 | AD6: 46757478 | AE6: 2.006383e+08 | AF6: -2.1302081e+08 | AG6: -2.1846139e+08 | AH6: 4.346874e+08 | AI6: 1.7135101e+08 | AJ6: 1.8780237e+08
A7: Prepayments & Sundry Receivables | B7: 1.7805848e+09 | C7: 1.8771324e+09 | D7: 1.9104938e+09 | E7: 1.8974844e+09 | F7: 1.8620809e+09 | G7: 1.7166405e+09 | H7: 1.9175792e+09 | I7: 1.6453646e+09 | J7: 1.8845508e+09 | L7: 1.6378464e+09 | M7: 1.642468e+09 | N7: 1784001840 | O7: 0 | P7: 1.678583e+09 | Q7: 1.9955001e+09 | R7: 1.8082348e+09 | S7: 1.7831519e+09 | T7: 1.7969142e+09 | U7: 2.0108035e+09 | V7: 1.7738072e+09 | W7: 2.002785e+09 | X7: 2.0269788e+09 | Y7: 1.819218e+09 | Z7: 1684959514 | AA7: =N7-Z7 -> 99042326 | AB7: 1700774183 | AC7: 1.4577114e+09 | AD7: 1.8347652e+09 | AE7: 1.7864694e+09 | AF7: 2.1464706e+09 | AG7: 2.0513582e+09 | AH7: 1.8177274e+09 | AI7: 0 | AJ7: 2.1508153e+09
A8: Financial Investments | B8: =SUM(B9:B12) -> 486426946 | C8: =SUM(C9:C12) -> 4.183132e+08 | D8: =SUM(D9:D12) -> 4.183132e+08 | E8: =SUM(E9:E12) -> 4.183132e+08 | F8: =SUM(F9:F12) -> 4.183132e+08 | G8: =SUM(G9:G12) -> 4.183132e+08 | H8: =SUM(H9:H12) -> 4.183132e+08 | I8: =SUM(I9:I12) -> 4.183132e+08 | ... Z8: =SUM(Z9:Z12) -> 432468041 | AA8: =N8-Z8 -> -0.19999999 | AB8: =SUM(AB9:AB12) -> 423139325 | AC8: =SUM(AC9:AC12) -> 4.2372582e+08 | AD8: =SUM(AD9:AD12) -> 4.2372582e+08 | AE8: =SUM(AE9:AE12) -> 4.2372582e+08 | AF8: =SUM(AF9:AF12) -> 4.2372582e+08 | AG8: =SUM(AG9:AG12) -> 4.2372582e+08 | AH8: =SUM(AH9:AH12) -> 4.2372582e+08 | AI8: =SUM(AI9:AI12) -> 4.2313932e+08 | ... AM8: =SUM(AM9:AM12) -> 0
A9: Government Securities - Treasury Bills/bonds, | B9: 0 | C9: 0 | D9: 0 | E9: 0 | F9: 0 | G9: 0 | H9: 0 | I9: 0 | J9: 0 | L9: 0 | M9: 0 | N9: ='[2]Note 7'!$F$14 -> 23365868 | O9: 0 | P9: 0 | Q9: 0 | R9: 0 | S9: 0 | T9: 0 | U9: 0 | V9: 0 | W9: 0 | X9: 0 | Y9: 0 | AA9: =N9-Z9 -> 23365868 | AC9: 0 | AD9: 0 | AE9: 0 | AF9: 0 | AG9: 0 | AH9: 0 | AI9: 0 | AJ9: 0
A10: Other Securities - Commercial papers/Bonds | B10: 0 | C10: 0 | D10: 0 | E10: 0 | F10: 0 | G10: 0 | H10: 0 | I10: 0 | J10: 0 | L10: 0 | M10: 0 | O10: 0 | P10: 0 | Q10: 0 | R10: 0 | S10: 0 | T10: 0 | U10: 0 | V10: 0 | W10: 0 | X10: 0 | Y10: 0 | AA10: =N10-Z10 -> 0 | AC10: 0 | AD10: 0 | AE10: 0 | AF10: 0 | AG10: 0 | AH10: 0 | AI10: 0 | AJ10: 0
A11: Balances with other SACCO Societies | B11: 0 | C11: 0 | D11: 0 | E11: 0 | F11: 0 | G11: 0 | H11: 0 | I11: 0 | J11: 0 | L11: 0 | M11: 0 | O11: 0 | P11: 0 | Q11: 0 | R11: 0 | S11: 0 | T11: 0 | U11: 0 | V11: 0 | W11: 0 | X11: 0 | Y11: 0 | Z11: 409102173 | AA11: =N11-Z11 -> -409102173 | AB11: 400359957 | AC11: 0 | AD11: 0 | AE11: 0 | AF11: 0 | AG11: 0 | AH11: 0 | AI11: 0 | AJ11: 0
A12: Investments in companies - shares/stocks | B12: 486426946 | C12: 4.183132e+08 | D12: 4.183132e+08 | E12: 4.183132e+08 | F12: 4.183132e+08 | G12: 4.183132e+08 | H12: 4.183132e+08 | I12: 4.183132e+08 | J12: 4.183132e+08 | L12: 4.183132e+08 | M12: 4.183132e+08 | N12: ='[2]Note 7'!$F$20 -> 409102173 | O12: 4.183132e+08 | P12: 4.183132e+08 | Q12: 4.183132e+08 | R12: 4.183132e+08 | S12: 4.183132e+08 | T12: 4.183132e+08 | U12: 4.183132e+08 | V12: 4.183132e+08 | W12: 4.183132e+08 | X12: 4.183132e+08 | Y12: 4.183132e+08 | Z12: 23365868 | AA12: =N12-Z12 -> 385736305 | AB12: 22779368 | AC12: 4.2372582e+08 | AD12: 4.2372582e+08 | AE12: 4.2372582e+08 | AF12: 4.2372582e+08 | AG12: 4.2372582e+08 | AH12: 4.2372582e+08 | AI12: 4.2313932e+08 | AJ12: 4.2313932e+08
A13: Net Loan Portfolio | B13: =B14-B15 -> 3.3035756e+09 | C13: =C14-C15 -> 3.3794646e+09 | D13: =D14-D15 -> 3.4096313e+09 | E13: =E14-E15 -> 3.3737607e+09 | F13: =F14-F15 -> 3.3803658e+09 | G13: =G14-G15 -> 3.3723653e+09 | H13: =H14-H15 -> 3.4017131e+09 | I13: =I14-I15 -> 3.4401109e+09 | ... Z13: =Z14-Z15 -> 3432988413 | AA13: =N13-Z13 -> 27000000 | AB13: =AB14-AB15 -> 3681831574 | AC13: =AC14-AC15 -> 3.9317585e+09 | AD13: =AD14-AD15 -> 4.0157359e+09 | AE13: =AE14-AE15 -> 4.0616635e+09 | AF13: =AF14-AF15 -> 4.1165596e+09 | AG13: =AG14-AG15 -> 4.3469229e+09 | AH13: =AH14-AH15 -> 4.4442286e+09 | AI13: =AI14-AI15 -> 4.3827476e+09 | ... AM13: =AM14-AM15 -> 0
A14: Gross Loan Portfolio | B14: 3.4379818e+09 | C14: 3.5287339e+09 | D14: 3.5589006e+09 | E14: 3.5230299e+09 | F14: 3.529635e+09 | G14: 3.5216345e+09 | H14: 3.5509824e+09 | I14: 3.5893802e+09 | J14: 3.6260463e+09 | L14: 3.6651374e+09 | M14: 3.6621608e+09 | N14: 3614762641 | O14: 3.7163566e+09 | P14: 3.7370628e+09 | Q14: 3.6753057e+09 | R14: 3.668167e+09 | S14: 3.6660194e+09 | T14: 3.6919383e+09 | U14: 3.667341e+09 | V14: 3.6853384e+09 | W14: 3.7238451e+09 | X14: 3.9271114e+09 | Y14: 3.9533164e+09 | Z14: 3592762641 | AA14: =N14-Z14 -> 22000000 | AB14: 3858442217 | AC14: 4.0915327e+09 | AD14: 4.1755101e+09 | AE14: 4.2214377e+09 | AF14: 4.2931702e+09 | AG14: 4.5066972e+09 | AH14: 4.6040028e+09 | AI14: 4.5593582e+09 | AJ14: 4627367940
A15: Allowance for Loan Loss | B15: 134406232 | C15: 1.4926925e+08 | D15: 1.4926925e+08 | E15: 1.4926925e+08 | F15: 1.4926925e+08 | G15: 1.4926925e+08 | H15: 1.4926925e+08 | I15: 1.4926925e+08 | J15: 1.4926925e+08 | L15: 1.4926925e+08 | M15: 1.4926925e+08 | N15: 154774228 | O15: 1.4926925e+08 | P15: 70086567 | Q15: 70086567 | R15: 70086567 | S15: 70086567 | T15: 70086567 | U15: 70086567 | V15: 70086567 | W15: 70086567 | X15: 70086567 | Y15: 70086567 | Z15: 159774228 | AA15: =N15-Z15 -> -5000000 | AB15: 176610643 | AC15: 1.5977423e+08 | AD15: 1.5977423e+08 | AE15: 1.5977423e+08 | AF15: 176610643 | AG15: 1.5977423e+08 | AH15: 1.5977423e+08 | AI15: 1.7661064e+08 | AJ15: 1.7661064e+08
A16: Accounts Receivables | B16: =SUM(B17:B19) -> 0 | C16: =SUM(C17:C19) -> 0 | D16: =SUM(D17:D19) -> 0 | E16: =SUM(E17:E19) -> 0 | F16: =SUM(F17:F19) -> 0 | G16: =SUM(G17:G19) -> 0 | H16: =SUM(H17:H19) -> 0 | I16: =SUM(I17:I19) -> 0 | J16: =SUM(J17:J19) -> 0 | L16: =SUM(L17:L19) -> 0 | M16: =SUM(M17:M19) -> 0 | N16: =SUM(N17:N19) -> 12781984 | O16: =SUM(O17:O19) -> 0 | P16: =SUM(P17:P19) -> 0 | Q16: =SUM(Q17:Q19) -> 0 | R16: =SUM(R17:R19) -> 0 | S16: =SUM(S17:S19) -> 0 | ... Z16: =SUM(Z17:Z19) -> 12781984 | AA16: =N16-Z16 -> 0 | AB16: =SUM(AB17:AB19) -> 9983559 | AC16: =SUM(AC17:AC19) -> 0 | AD16: =SUM(AD17:AD19) -> 0 | AE16: =SUM(AE17:AE19) -> 0 | AF16: =SUM(AF17:AF19) -> 0 | AG16: =SUM(AG17:AG19) -> 0 | AH16: =SUM(AH17:AH19) -> 0 | AI16: =SUM(AI17:AI19) -> 0 | ... AM16: =SUM(AM17:AM19) -> 0
A17: Tax Recoverable | B17: 0 | C17: 0 | D17: 0 | E17: 0 | F17: 0 | G17: 0 | H17: 0 | I17: 0 | J17: 0 | L17: 0 | M17: 0 | O17: 0 | P17: 0 | Q17: 0 | R17: 0 | S17: 0 | T17: 0 | U17: 0 | V17: 0 | W17: 0 | X17: 0 | Y17: 0 | AA17: =N17-Z17 -> 0 | AC17: 0 | AD17: 0 | AE17: 0 | AF17: 0 | AG17: 0 | AH17: 0 | AI17: 0 | AJ17: 0 | AK17: 0
A18: Deferred Tax Assets | B18: 0 | C18: 0 | D18: 0 | E18: 0 | F18: 0 | G18: 0 | H18: 0 | I18: 0 | J18: 0 | L18: 0 | M18: 0 | N18: 12781984 | O18: 0 | P18: 0 | Q18: 0 | R18: 0 | S18: 0 | T18: 0 | U18: 0 | V18: 0 | W18: 0 | X18: 0 | Y18: 0 | Z18: 12781984 | AA18: =N18-Z18 -> 0 | AB18: 9983559 | AC18: 0 | AD18: 0 | AE18: 0 | AF18: 0 | AG18: 0 | AH18: 0 | AI18: 0 | AJ18: 0 | AK18: 0
A19: Retirement Benefit Assets | B19: 0 | C19: 0 | D19: 0 | E19: 0 | F19: 0 | G19: 0 | H19: 0 | I19: 0 | J19: 0 | L19: 0 | M19: 0 | O19: 0 | P19: 0 | Q19: 0 | R19: 0 | S19: 0 | T19: 0 | U19: 0 | V19: 0 | W19: 0 | X19: 0 | Y19: 0 | AA19: =N19-Z19 -> 0 | AC19: 0 | AD19: 0 | AE19: 0 | AF19: 0 | AG19: 0 | AH19: 0 | AI19: 0 | AJ19: 0 | AK19: 0
A20: Property & Equipment & Other assets | B20: =SUM(B21:B25) -> 5.0699869e+08 | C20: =SUM(C21:C25) -> 5.0685522e+08 | D20: =SUM(D21:D25) -> 5.1526463e+08 | E20: =SUM(E21:E25) -> 5.2143931e+08 | F20: =SUM(F21:F25) -> 5.2143931e+08 | G20: =SUM(G21:G25) -> 5.2154931e+08 | H20: =SUM(H21:H25) -> 5.3081252e+08 | I20: =SUM(I21:I25) -> 5.3082852e+08 | ... Z20: =SUM(Z21:Z25) -> 575846453 | AA20: =N20-Z20 -> 0 | AB20: =SUM(AB21:AB25) -> 657273113 | AC20: =SUM(AC21:AC25) -> 5.1587084e+08 | AD20: =SUM(AD21:AD25) -> 5.1903681e+08 | AE20: =SUM(AE21:AE25) -> 5.1939986e+08 | AF20: =SUM(AF21:AF25) -> 5.1982496e+08 | AG20: =SUM(AG21:AG25) -> 5.2033944e+08 | AH20: =SUM(AH21:AH25) -> 5.2063842e+08 | AI20: =SUM(AI21:AI25) -> 5.17078e+08 | ... AM20: =SUM(AM21:AM25) -> 0
A21: Investment Properties | B21: 4.5244252e+08 | C21: 4.5262816e+08 | D21: 4.5262816e+08 | E21: 4.5262816e+08 | F21: 4.5262816e+08 | G21: 4.5243816e+08 | H21: 4.5243816e+08 | I21: 4.5243816e+08 | J21: 4.5243816e+08 | L21: 4.5243816e+08 | M21: 4.4700768e+08 | O21: 4.4700768e+08 | P21: 4.4702768e+08 | Q21: 4.4702768e+08 | R21: 4.4702768e+08 | S21: 4.4508995e+08 | T21: 4.4508995e+08 | U21: 4.4508995e+08 | V21: 4.4508995e+08 | W21: 4.4524431e+08 | X21: 4.4524431e+08 | Y21: 4.4524431e+08 | Z21: 236778710 | AA21: =N21-Z21 -> -236778710 | AB21: 235015345 | AC21: 4.3998859e+08 | AD21: 4.4041359e+08 | AE21: 4.4047089e+08 | AF21: 4.4008089e+08 | AG21: 4.4008089e+08 | AH21: 4.4024339e+08 | AI21: 4.3594233e+08 | AJ21: 4.3600733e+08
A22: Property & Equipment | B22: 32568033 | C22: 32568034 | D22: 35773639 | E22: 41399718 | F22: 41399718 | G22: 41399718 | H22: 41399718 | I22: 41399718 | J22: 42949558 | L22: 42949558 | M22: 36626402 | N22: 243649762 | O22: 36626402 | P22: 43857269 | Q22: 45916419 | R22: 43239774 | S22: 43514549 | T22: 43563549 | U22: 43566899 | V22: 44499413 | W22: 44622265 | X22: 45576025 | Y22: 45801025 | Z22: 243649762 | AA22: =N22-Z22 -> 0 | AB22: 241918784 | AC22: 36945543 | AD22: 37603603 | AE22: 37621102 | AF22: 37649042 | AG22: 37649042 | AH22: 37785526 | AI22: 37803526 | AJ22: 37803526
A23: Prepaid Lease rentals | B23: 0 | C23: 0 | D23: 0 | E23: 0 | F23: 0 | G23: 0 | H23: 0 | I23: 0 | J23: 0 | L23: 0 | M23: 0 | O23: 0 | P23: 0 | Q23: 0 | R23: 0 | S23: 0 | T23: 0 | U23: 0 | V23: 0 | W23: 0 | X23: 0 | Y23: 0 | AA23: =N23-Z23 -> 0 | AC23: 0 | AD23: 0 | AE23: 0 | AF23: 0 | AG23: 0 | AH23: 0 | AI23: 0 | AJ23: 0
A24: Intangible Assets | B24: 7703332 | C24: 7703332 | D24: 11147720 | E24: 11246320 | F24: 11246320 | G24: 11246320 | H24: 20509536 | I24: 20509536 | J24: 22614240 | L24: 22614240 | M24: 15083698 | N24: 15083698 | O24: 15083698 | P24: 16805892 | Q24: 16805892 | R24: 16805892 | S24: 16805892 | T24: 16805892 | U24: 16805892 | V24: 16805892 | W24: 16805892 | X24: 16805892 | Y24: 17408534 | Z24: 15083698 | AA24: =N24-Z24 -> 0 | AB24: 11611492 | AC24: 11611492 | AD24: 12713840 | AE24: 12713840 | AF24: 12713840 | AG24: 12713840 | AH24: 12713840 | AI24: 12713840 | AJ24: 12713840
A25: Other Assets | B25: 14284804 | C25: 13955693 | D25: 15715110 | E25: 16165110 | F25: 16165110 | G25: 16465110 | H25: 16465110 | I25: 16481110 | J25: 16481110 | L25: 18136395 | M25: 19311815 | N25: =236778710+10250000+10161646+59922637 -> 317112993 | O25: 19627393 | P25: 19190416 | Q25: 19481110 | R25: 20081110 | S25: 20430726 | T25: 20430726 | U25: 20730726 | V25: 21330726 | W25: 21630726 | X25: 21930726 | Y25: 22230726 | Z25: =257190356+59922637-Z21 -> 80334283 | AA25: =N25-Z25 -> 236778710 | AB25: =309016568+94726269-AB21 -> 168727492 | AC25: 27325223 | AD25: 28305777 | AE25: 28594027 | AF25: 29381192 | AG25: 29895667 | AH25: 29895667 | AI25: 30618307 | AJ25: 31014072
A26: Total Assets | B26: =SUM(B4,B7,B8,B13,B16,B20) -> 6.3302389e+09 | C26: =SUM(C4,C7,C8,C13,C16,C20) -> 6.4282313e+09 | D26: =SUM(D4,D7,D8,D13,D16,D20) -> 6.5434997e+09 | E26: =SUM(E4,E7,E8,E13,E16,E20) -> 6.3423933e+09 | F26: =SUM(F4,F7,F8,F13,F16,F20) -> 6.6617024e+09 | G26: =SUM(G4,G7,G8,G13,G16,G20) -> 6.8126167e+09 | H26: =SUM(H4,H7,H8,H13,H16,H20) -> 6.7579623e+09 | I26: =SUM(I4,I7,I8,I13,I16,I20) -> 6.7474402e+09 | ... Z26: =SUM(Z4,Z7,Z8,Z13,Z16,Z20) -> 6956390321 | AA26: =N26-Z26 -> 1.2604233e+08 | AB26: =SUM(AB4,AB7,AB8,AB13,AB16,AB20) -> 7049229871 | AC26: =SUM(AC4,AC7,AC8,AC13,AC16,AC20) -> 6.8041813e+09 | AD26: =SUM(AD4,AD7,AD8,AD13,AD16,AD20) -> 6.8757499e+09 | AE26: =SUM(AE4,AE7,AE8,AE13,AE16,AE20) -> 7.0212083e+09 | AF26: =SUM(AF4,AF7,AF8,AF13,AF16,AF20) -> 7.0202061e+09 | AG26: =SUM(AG4,AG7,AG8,AG13,AG16,AG20) -> 7.1444179e+09 | AH26: =SUM(AH4,AH7,AH8,AH13,AH16,AH20) -> 7.6639835e+09 | AI26: =SUM(AI4,AI7,AI8,AI13,AI16,AI20) -> 5.5254131e+09 | ... AM26: =SUM(AM4,AM7,AM8,AM13,AM16,AM20) -> 0
A27: Savings Deposits - Withdrawable deposits - FOSA) | B27: 1.4508275e+08 | C27: 50126547 | D27: 54986080 | E27: 1.8095028e+08 | F27: 90227798 | G27: 99328975 | H27: 64548910 | I27: 71312236 | J27: 70450183 | L27: 43575722 | M27: 42772812 | N27: ='[2]Note 8'!$D$21 -> 46810692 | O27: 51447487 | P27: 3.8370442e+08 | Q27: 49687100 | R27: 40587004 | S27: 51321682 | T27: 50671163 | U27: 40398537 | V27: 46999007 | W27: 61341126 | X27: 1.7842135e+08 | Y27: 1.1072818e+08 | Z27: 46810692 | AA27: =N27-Z27 -> -0.14 | AB27: 102062910 | AC27: 80180894 | AD27: 69615023 | AE27: 153727806 | AF27: 93009595 | AG27: 71555549 | AH27: 92762960 | AI27: 102437741 | AJ27: 87295854
A28: Short Term Deposits (e.g Fixed deposits, special savings) | B28: 16592130 | C28: 18660130 | D28: 18588038 | E28: 19405538 | F28: 19092538 | G28: 20492538 | H28: 19626038 | I28: 17826038 | J28: 17126038 | L28: 18458038 | M28: 16288038 | N28: ='[2]Note 8'!$D$22 -> 16288038 | O28: 19371038 | P28: 20881638 | Q28: 21254238 | R28: 20144638 | S28: 22654638 | T28: 21483038 | U28: 24084038 | V28: 27266038 | W28: 27270838 | X28: 25548838 | Y28: 25378838 | Z28: 16286038 | AA28: =N28-Z28 -> 1999.55 | AB28: 25378838 | AC28: 23189838 | AD28: 26719838 | AE28: 26617838 | AF28: 28985038 | AG28: 26030552 | AH28: 30039737 | AI28: 31413521 | AJ28: 27147007
A29: Non withdrawable deposits (BOSA member deposits) | B29: 4.4982527e+09 | C29: 4.5415133e+09 | D29: 4.5877737e+09 | E29: 4.6331709e+09 | F29: 4.6708746e+09 | G29: 4.680367e+09 | H29: 4.7062754e+09 | I29: 4.7353454e+09 | J29: 4.7686859e+09 | L29: 4.8458975e+09 | M29: 4.8890807e+09 | N29: =4877606072-16491047 -> 4861115025 | O29: 4.9144309e+09 | P29: 4.9344628e+09 | Q29: 5.000962e+09 | R29: 5.0337356e+09 | S29: 5.025449e+09 | T29: 5.0445175e+09 | U29: 4.8670352e+09 | V29: 4.90337e+09 | W29: 4.9380862e+09 | X29: 4.9784386e+09 | Y29: 5.026152e+09 | Z29: 4891356072 | AA29: =N29-Z29 -> -30241047 | AB29: 5026214141 | AC29: 5.0670606e+09 | AD29: 5.1143677e+09 | AE29: 5.1558569e+09 | AF29: 5.1983355e+09 | AG29: 5.2130773e+09 | AH29: 5.2552684e+09 | AI29: 5.2877776e+09 | AJ29: 5.3325382e+09
A30: Total Deposit liabilities | B30: =SUM(B27:B29) -> 4.6599276e+09 | C30: =SUM(C27:C29) -> 4.6103e+09 | D30: =SUM(D27:D29) -> 4.6613478e+09 | E30: =SUM(E27:E29) -> 4.8335267e+09 | F30: =SUM(F27:F29) -> 4.780195e+09 | G30: =SUM(G27:G29) -> 4.8001885e+09 | H30: =SUM(H27:H29) -> 4.7904504e+09 | I30: =SUM(I27:I29) -> 4.8244837e+09 | ... Z30: =SUM(Z27:Z29) -> 4954452802 | AA30: =N30-Z30 -> -30239048 | AB30: =SUM(AB27:AB29) -> 5153655889 | AC30: =SUM(AC27:AC29) -> 5.1704314e+09 | AD30: =SUM(AD27:AD29) -> 5.2107025e+09 | AE30: =SUM(AE27:AE29) -> 5.3362026e+09 | AF30: =SUM(AF27:AF29) -> 5.3203301e+09 | AG30: =SUM(AG27:AG29) -> 5.3106634e+09 | AH30: =SUM(AH27:AH29) -> 5.3780711e+09 | AI30: =SUM(AI27:AI29) -> 5.4216288e+09 | ... AM30: =SUM(AM27:AM29) -> 0
A31: Accounts Payable & Other Liabilities | B31: =SUM(B32:B37) -> 2.9789071e+08 | C31: =SUM(C32:C37) -> 4.4449013e+08 | D31: =SUM(D32:D37) -> 4.5850111e+08 | E31: =SUM(E32:E37) -> 69029042 | F31: =SUM(F32:F37) -> 4.1622994e+08 | G31: =SUM(G32:G37) -> 4.6526934e+08 | H31: =SUM(H32:H37) -> 4.5949604e+08 | I31: =SUM(I32:I37) -> 4.0028446e+08 | ... Z31: =SUM(Z32:Z37) -> 693958758 | AA31: =N31-Z31 -> 84564484 | AB31: =SUM(AB32:AB37) -> 491262851 | AC31: =SUM(AC32:AC37) -> 2.3467623e+08 | AD31: =SUM(AD32:AD37) -> 2.2864744e+08 | AE31: =SUM(AE32:AE37) -> 2.2194042e+08 | AF31: =SUM(AF32:AF37) -> 1.8761959e+08 | AG31: =SUM(AG32:AG37) -> 2.7833863e+08 | AH31: =SUM(AH32:AH37) -> 6.2749369e+08 | AI31: =SUM(AI32:AI37) -> 6.5566794e+08 | ... AM31: =SUM(AM32:AM37) -> 0
A32: Tax Payable | B32: 10139396 | C32: 14921082 | D32: 10419890 | E32: 9340256.8 | F32: 9939305.7 | G32: 14932245 | H32: 11117248 | I32: 10276918 | J32: 13505270 | L32: 16358812 | M32: 9274006.4 | N32: 16288038 | O32: 3984363.3 | P32: 640368.66 | Q32: 901809.23 | R32: 159596.94 | S32: 498547.2 | T32: 1264060.1 | U32: 844363.14 | V32: 2954710.9 | W32: 977559.23 | X32: 1530107.1 | Y32: 1012717.2 | Z32: 11521899 | AA32: =N32-Z32 -> 4766139 | AB32: 23268815 | AC32: 267507 | AD32: 1001036.1 | AE32: 1493792.4 | AF32: 550863.97 | AG32: 2543127.5 | AH32: 710522.43 | AI32: 218406.04 | AJ32: 1511793.9
A33: Dividends Payable | B33: 0 | C33: 0 | D33: 0 | E33: 0 | F33: 0 | G33: 0 | H33: 0 | I33: 0 | J33: 0 | L33: 0 | M33: 0 | N33: 395841179 | O33: 0 | P33: 0 | Q33: 0 | R33: 0 | S33: 0 | T33: 0 | U33: 0 | V33: 0 | W33: 0 | X33: 0 | Y33: 0 | Z33: 303621910 | AA33: =N33-Z33 -> 92219269 | AB33: 241606685 | AC33: 0 | AD33: 0 | AE33: 0 | AF33: 0 | AG33: 0 | AH33: 0 | AI33: 0 | AJ33: 0
A34: Deferred Tax Liability | B34: 0 | C34: 0 | D34: 0 | E34: 0 | F34: 0 | G34: 0 | H34: 0 | I34: 0 | J34: 0 | L34: 0 | M34: 0 | O34: 0 | P34: 0 | Q34: 0 | R34: 0 | S34: 0 | T34: 0 | U34: 0 | V34: 0 | W34: 0 | X34: 0 | Y34: 0 | AA34: =N34-Z34 -> 0 | AC34: 0 | AD34: 0 | AE34: 0 | AF34: 0 | AG34: 0 | AH34: 0 | AI34: 0 | AJ34: 0
A35: Retirement Benefits Liability | B35: 0 | C35: 0 | D35: 0 | E35: 0 | F35: 0 | G35: 0 | H35: 0 | I35: 0 | J35: 0 | L35: 0 | M35: 0 | O35: 0 | P35: 0 | Q35: 0 | R35: 0 | S35: 0 | T35: 0 | U35: 0 | V35: 0 | W35: 0 | X35: 0 | Y35: 0 | AA35: =N35-Z35 -> 0 | AC35: 0 | AD35: 0 | AE35: 0 | AF35: 0 | AG35: 0 | AH35: 0 | AI35: 0 | AJ35: 0
A36: Other Liabilities | B36: 2.8775132e+08 | C36: 4.2956905e+08 | D36: 4.4808121e+08 | E36: 59688785 | F36: 6290638.8 | G36: 50337100 | H36: 59489906 | I36: 12229761 | J36: 8233461.2 | L36: 345061.23 | M36: 5893691.9 | N36: 33060692 | O36: 9931691.9 | P36: 13869892 | Q36: 4672082.8 | R36: -778282.83 | S36: 703282.83 | T36: 3069117.2 | U36: 10172296 | V36: 13895996 | W36: 17624396 | X36: 21305196 | Y36: 25719447 | Z36: 45481616 | AA36: =N36-Z36 -> -12420924 | AB36: 26387351 | AC36: 45519829 | AD36: 49868629 | AE36: 53779965 | AF36: 31513167 | AG36: 22462167 | AH36: 26783167 | AI36: 72116196 | AJ36: 76304789
A37: External Borrowings | B37: 0 | C37: 0 | D37: 0 | E37: 0 | F37: 400000000 | G37: 400000000 | H37: 3.8888889e+08 | I37: 3.7777778e+08 | J37: 3.6666667e+08 | L37: 3.4444444e+08 | M37: 3.3333333e+08 | N37: 333333333 | O37: 3.2222222e+08 | P37: 3e+08 | Q37: 2.8888889e+08 | R37: 2.7777778e+08 | S37: 2.6666667e+08 | T37: 2.5555556e+08 | U37: 2.4444444e+08 | V37: 2.3333333e+08 | W37: 2.3333333e+08 | X37: 2.1111111e+08 | Y37: 2e+08 | Z37: 333333333 | AA37: =N37-Z37 -> 0 | AB37: 200000000 | AC37: 1.8888889e+08 | AD37: 1.7777778e+08 | AE37: 1.6666667e+08 | AF37: 1.5555556e+08 | AG37: 2.5333333e+08 | AH37: 600000000 | AI37: 5.8333333e+08 | AJ37: 5.6666667e+08
A38: Total Liabilities | B38: =B31+B30 -> 4.9578183e+09 | C38: =C31+C30 -> 5.0547901e+09 | D38: =D31+D30 -> 5.1198489e+09 | E38: =E31+E30 -> 4.9025557e+09 | F38: =F31+F30 -> 5.1964249e+09 | G38: =G31+G30 -> 5.2654578e+09 | H38: =H31+H30 -> 5.2499464e+09 | I38: =I31+I30 -> 5.2247681e+09 | ... Z38: =Z31+Z30 -> 5648411560 | AA38: =N38-Z38 -> 54325436 | AB38: =AB31+AB30 -> 5644918740 | AC38: =AC31+AC30 -> 5.4051076e+09 | AD38: =AD31+AD30 -> 5.43935e+09 | AE38: =AE31+AE30 -> 5.558143e+09 | AF38: =AF31+AF30 -> 5.5079497e+09 | AG38: =AG31+AG30 -> 5.589002e+09 | AH38: =AH31+AH30 -> 6.0055647e+09 | AI38: =AI31+AI30 -> 6.0772968e+09 | ... AM38: =AM31+AM30 -> 0
A39: Share Capital (Members share capital per Bylaws) | B39: 4.4018821e+08 | C39: 4.4018781e+08 | D39: 4.4018741e+08 | E39: 4.4044526e+08 | F39: 4.4044526e+08 | G39: 4.4044746e+08 | H39: 4.4044606e+08 | I39: 4.4045204e+08 | J39: 4.4047334e+08 | L39: 4.4047404e+08 | M39: 4.4047464e+08 | N39: 440474635 | O39: 4.4047544e+08 | P39: 4.405981e+08 | Q39: 4.4051241e+08 | R39: 4.4049201e+08 | S39: 4.4049241e+08 | T39: 4.4049181e+08 | U39: 6.5011093e+08 | V39: 6.5005093e+08 | W39: 6.5007233e+08 | X39: 6.5002059e+08 | Y39: 6.5002199e+08 | Z39: 440474635 | AA39: =N39-Z39 -> 0 | AB39: 650021994 | AC39: 6.4999585e+08 | AD39: 6.4999625e+08 | AE39: 6.5010821e+08 | AF39: 6.5010356e+08 | AG39: 6.5007926e+08 | AH39: 6.5022061e+08 | AI39: 6.5022294e+08 | AJ39: 6.5022244e+08
A40: Capital Grants | B40: 0 | C40: 0 | D40: 0 | E40: 0 | F40: 0 | G40: 0 | H40: 0 | I40: 0 | J40: 0 | L40: 0 | M40: 0 | O40: 0 | P40: 0 | Q40: 0 | R40: 0 | S40: 0 | T40: 0 | U40: 0 | V40: 0 | W40: 0 | X40: 0 | Y40: 0 | AA40: =N40-Z40 -> 0 | AC40: 0 | AD40: 0 | AE40: 0 | AF40: 0 | AG40: 0 | AH40: 0 | AI40: 0 | AJ40: 0
...

Sheet SCI
A1: MAGEREZA SACCO SOCIETY | N1: Approved | Z1: Restated 2021 accounts | AA1: Variances btw
A2: STATEMENT OF COMPREHENSIVE INCOME | B2: Jan | C2: Feb | D2: Mar | E2: Apr | F2: May | G2: Jun | H2: Jul | I2: Aug | J2: Sep | K2: Oct | L2: Nov | M2: Dec | N2: Audited 2021 | O2: Feb | P2: Mar | Q2: Apr | R2: May | S2: Jun | T2: Jul | U2: Aug | V2: Sep | W2: Oct | X2: Nov | Y2: Dec | Z2: by the Auditor | AA2: Audited & restated 2021 | AB2: Audited 2022 | AC2: 44927 | AD2: 44958 | AE2: 44986 | AF2: 45017 | AG2: 45047 | AH2: 45078 | AI2: 45108 | AJ2: 45139 | AK2: 45170 | AL2: 45200 | AM2: 45231
A3: Financial Income | B3: =B4+B7 -> 42188053 | C3: =C4+C7 -> 79467027 | D3: =D4+D7 -> 1.3636454e+08 | E3: =E4+E7 -> 2.3243133e+08 | F3: =F4+F7 -> 2.7570247e+08 | G3: =G4+G7 -> 3.1900522e+08 | H3: =H4+H7 -> 3.6472629e+08 | I3: =I4+I7 -> 4.1137057e+08 | ... Z3: =Z4+Z7 -> 695984292 | AA3: =N3-Z3 -> 123985897 | AB3: =AB4+AB7 -> 712535574 | AC3: =AC4+AC7 -> 71713958 | AD3: =AD4+AD7 -> 1.3948346e+08 | AE3: =AE4+AE7 -> 2.079241e+08 | AF3: =AF4+AF7 -> 2.8314969e+08 | AG3: =AG4+AG7 -> 3.6235572e+08 | AH3: =AH4+AH7 -> 4.9681134e+08 | AI3: =AI4+AI7 -> 5.6393162e+08 | ... AM3: =AM4+AM7 -> 0
A4: Financial Income from Loans Portfolio | B4: =SUM(B5:B6) -> 40277499 | C4: =SUM(C5:C6) -> 75635249 | D4: =SUM(D5:D6) -> 1.2771036e+08 | E4: =SUM(E5:E6) -> 1.8034548e+08 | F4: =SUM(F5:F6) -> 2.2164721e+08 | G4: =SUM(G5:G6) -> 2.6298056e+08 | H4: =SUM(H5:H6) -> 3.0673223e+08 | I4: =SUM(I5:I6) -> 3.5142865e+08 | ... Z4: =SUM(Z5:Z6) -> 604120606 | AA4: =N4-Z4 -> 122564632 | AB4: =SUM(AB5:AB6) -> 580761538 | AC4: =SUM(AC5:AC6) -> 63865677 | AD4: =SUM(AD5:AD6) -> 1.2357749e+08 | AE4: =SUM(AE5:AE6) -> 1.8396e+08 | AF4: =SUM(AF5:AF6) -> 2.4813352e+08 | AG4: =SUM(AG5:AG6) -> 3.1589442e+08 | AH4: =SUM(AH5:AH6) -> 3.7983081e+08 | AI4: =SUM(AI5:AI6) -> 4.4231849e+08 | ... AM4: =SUM(AM5:AM6) -> 0
A5: Interest on Loan Portfolio | B5: 36107004 | C5: 65232689 | D5: 1.1139151e+08 | E5: 1.5394338e+08 | F5: 1.8968719e+08 | G5: 2.25625e+08 | H5: 2.6193996e+08 | I5: 2.9823513e+08 | J5: 3.342758e+08 | L5: 4.1092727e+08 | M5: 4.4854844e+08 | N5: 726685238 | O5: 35374160 | P5: 72718143 | Q5: 1.6425871e+08 | R5: 2.0388566e+08 | S5: 2.4287277e+08 | T5: 2.8137015e+08 | U5: 3.1950499e+08 | V5: 3.5698457e+08 | W5: 3.9552572e+08 | X5: 4.3556905e+08 | Y5: 4.8487513e+08 | Z5: 604120606 | AA5: =N5-Z5 -> 122564632 | AB5: 580761538 | AC5: 50553898 | AD5: 99478832 | AE5: 1.4813856e+08 | AF5: 1.9513279e+08 | AG5: 2.4538686e+08 | AH5: 2.9594335e+08 | AI5: 3.4667195e+08 | AJ5: 3.9587962e+08 | AK5: 4.4690321e+08
A6: Fees & Commission on Loan Portfolio | B6: 4170494.5 | C6: 10402560 | D6: 16318850 | E6: 26402092 | F6: 31960024 | G6: 37355561 | H6: 44792264 | I6: 53193522 | J6: 61349998 | L6: 74424695 | M6: 80965276 | O6: 5612456.5 | P6: 12842913 | Q6: 34515832 | R6: 41963658 | S6: 49454711 | T6: 58247437 | U6: 62566812 | V6: 69725487 | W6: 78794015 | X6: 87117274 | Y6: 95861038 | AA6: =N6-Z6 -> 0 | AC6: 13311779 | AD6: 24098658 | AE6: 35821440 | AF6: 53000729 | AG6: 70507560 | AH6: 83887465 | AI6: 95646535 | AJ6: 1.1228486e+08 | AK6: 1.3161017e+08
A7: Financial Income from Investments in: | B7: =SUM(B8:B11) -> 1910554.4 | C7: =SUM(C8:C11) -> 3831778.5 | D7: =SUM(D8:D11) -> 8654186.4 | E7: =SUM(E8:E11) -> 52085852 | F7: =SUM(F8:F11) -> 54055257 | G7: =SUM(G8:G11) -> 56024662 | H7: =SUM(H8:H11) -> 57994068 | I7: =SUM(I8:I11) -> 59941921 | ... Z7: =SUM(Z8:Z11) -> 91863686 | AA7: =N7-Z7 -> 1421265 | AB7: =SUM(AB8:AB11) -> 131774036 | AC7: =SUM(AC8:AC11) -> 7848281.3 | AD7: =SUM(AD8:AD11) -> 15905966 | AE7: =SUM(AE8:AE11) -> 23964101 | AF7: =SUM(AF8:AF11) -> 35016169 | AG7: =SUM(AG8:AG11) -> 46461297 | AH7: =SUM(AH8:AH11) -> 1.1698053e+08 | AI7: =SUM(AI8:AI11) -> 1.2161313e+08 | ... AM7: =SUM(AM8:AM11) -> 0
A8: Government Securities | B8: 0 | C8: 0 | D8: 0 | E8: 0 | F8: 0 | G8: 0 | H8: 0 | I8: 0 | J8: 0 | L8: 0 | M8: 0 | O8: 0 | P8: 0 | Q8: 0 | R8: 0 | S8: 0 | T8: 0 | U8: 0 | V8: 0 | W8: 0 | X8: 0 | Y8: 0 | AA8: =N8-Z8 -> 0 | AC8: 0 | AD8: 0 | AE8: 0 | AF8: 0 | AG8: 0 | AH8: 0 | AI8: 0 | AJ8: 0 | AK8: 0
A9: Deposit with Banks and Other Financial Inst. | B9: 0 | C9: 0 | D9: 0 | E9: 0 | F9: 0 | G9: 0 | H9: 0 | I9: 0 | J9: 0 | L9: 0 | M9: 0 | O9: 0 | P9: 0 | Q9: 0 | R9: 0 | S9: 0 | T9: 0 | U9: 0 | V9: 0 | W9: 0 | X9: 0 | Y9: 0 | AA9: =N9-Z9 -> 0 | AC9: 0 | AD9: 0 | AE9: 0 | AF9: 0 | AG9: 0 | AH9: 0 | AI9: 0 | AJ9: 0 | AK9: 0
A10: Other Investments - dividend & Interest incomes from investments | B10: 1910554.4 | C10: 3831778.5 | D10: 8654186.4 | E10: 52085852 | F10: 54055257 | G10: 56024662 | H10: 57994068 | I10: 59941921 | J10: 61878568 | L10: 64802401 | M10: 70210576 | N10: 93284951 | O10: 1889232.8 | P10: 1889232.8 | Q10: 6473698.3 | R10: 8396771 | S10: 50412285 | T10: 51801105 | U10: 53189925 | V10: 56258854 | W10: 57647675 | X10: 61389370 | Y10: 67288629 | Z10: 91863686 | AA10: =N10-Z10 -> 1421265 | AB10: 131774036 | AC10: 1948258.6 | AD10: 3924017.2 | AE10: 5927275.9 | AF10: 7875534.5 | AG10: 9048862.1 | AH10: 71751392 | AI10: 72504073 | AJ10: 74831403 | AK10: 75246435
A11: Other Operating Income- Salary processing fees, transaction fees, membership fees | O11: 662881.4 | P11: 2198551.6 | Q11: 4472215.6 | R11: 5383434.5 | S11: 6000214.5 | T11: 6763671.8 | U11: 10368204 | V11: 11421637 | W11: 12416206 | X11: 13925523 | Y11: 18493865 | AA11: =N11-Z11 -> 0 | AC11: 5900022.7 | AD11: 11981949 | AE11: 18036825 | AF11: 27140635 | AG11: 37412435 | AH11: 45229136 | AI11: 49109055 | AJ11: 53206099 | AK11: 58363200
A12: Financial Expense | B12: =B13+B14+B15+B16+B18+B17 -> 450231.88 | C12: =C13+C14+C15+C16+C18+C17 -> 450231.88 | D12: =D13+D14+D15+D16+D18+D17 -> 450231.88 | E12: =E13+E14+E15+E16+E18+E17 -> 450231.88 | F12: =F13+F14+F15+F16+F18+F17 -> 450231.88 | G12: =G13+G14+G15+G16+G18+G17 -> 450231.88 | H12: =H13+H14+H15+H16+H18+H17 -> 450231.88 | I12: =I13+I14+I15+I16+I18+I17 -> 450231.88 | ... Z12: =Z13+Z14+Z15+Z16+Z18+Z17 -> 374662272 | AA12: =N12-Z12 -> 126640917 | AB12: =AB13+AB14+AB15+AB16+AB18+AB17 -> 292711117 | AC12: =AC13+AC14+AC15+AC16+AC18+AC17 -> 2909434 | AD12: =AD13+AD14+AD15+AD16+AD18+AD17 -> 3012836.2 | AE12: =AE13+AE14+AE15+AE16+AE18+AE17 -> 2711641.7 | AF12: =AF13+AF14+AF15+AF16+AF18+AF17 -> 6710641.7 | AG12: =AG13+AG14+AG15+AG16+AG18+AG17 -> 10346656 | AH12: =AH13+AH14+AH15+AH16+AH18+AH17 -> 12844979 | AI12: =AI13+AI14+AI15+AI16+AI18+AI17 -> 13196958 | ... AM12: =AM13+AM14+AM15+AM16+AM18+AM17 -> 0
A13: Interest Expense on Deposits | B13: 368947.88 | C13: 368947.88 | D13: 368947.88 | E13: 368947.88 | F13: 368947.88 | G13: 368947.88 | H13: 368947.88 | I13: 368947.88 | J13: 368947.88 | L13: 1386128.8 | M13: 1410528.8 | N13: 395957045 | O13: 0 | P13: 6000 | Q13: 0 | R13: 0 | S13: 0 | T13: 0 | U13: 0 | V13: 0 | W13: 0 | X13: 0 | Y13: 0 | Z13: 294891893 | AA13: =N13-Z13 -> 101065152 | AB13: 258007684 | AC13: 0 | AD13: 0 | AE13: 0 | AF13: 0 | AG13: 0 | AH13: 0 | AI13: 0 | AJ13: 0 | AK13: 0
A14: Cost of External Borrowings | B14: 0 | C14: 0 | D14: 0 | E14: 0 | F14: 0 | G14: 0 | H14: 0 | I14: 0 | J14: 0 | L14: 0 | M14: 0 | O14: 0 | P14: 0 | Q14: 0 | R14: 0 | S14: 0 | T14: 0 | U14: 0 | V14: 0 | W14: 0 | X14: 0 | Y14: 0 | AA14: =N14-Z14 -> 0 | AC14: 0 | AD14: 0 | AE14: 0 | AF14: 0 | AG14: 0 | AH14: 0 | AI14: 0 | AJ14: 0 | AK14: 0
A15: Dividend Expenses (on member shares) | B15: 0 | C15: 0 | D15: 0 | E15: 0 | F15: 0 | G15: 0 | H15: 0 | I15: 0 | J15: 0 | L15: 0 | M15: 0 | O15: 0 | P15: 0 | Q15: 0 | R15: 0 | S15: 0 | T15: 0 | U15: 0 | V15: 0 | W15: 0 | X15: 0 | Y15: 0 | AA15: =N15-Z15 -> 0 | AC15: 0 | AD15: 0 | AE15: 0 | AF15: 0 | AG15: 0 | AH15: 0 | AI15: 0 | AJ15: 0 | AK15: 0
A16: Other Financial Expense | B16: 0 | C16: 0 | D16: 0 | E16: 0 | F16: 0 | G16: 0 | H16: 0 | I16: 0 | J16: 0 | L16: 0 | M16: 0 | N16: 85275359 | O16: 0 | P16: 0 | Q16: 0 | R16: 0 | S16: 0 | T16: 0 | U16: 0 | V16: 0 | W16: 0 | X16: 0 | Y16: 0 | AA16: =N16-Z16 -> 85275359 | AC16: 0 | AD16: 0 | AE16: 0 | AF16: 0 | AG16: 0 | AH16: 0 | AI16: 0 | AJ16: 0 | AK16: 0
A17: Fees & Commission Expense | B17: 81284 | C17: 81284 | D17: 81284 | E17: 81284 | F17: 81284 | G17: 81284 | H17: 81284 | I17: 81284 | J17: 81284 | L17: 35126853 | M17: 42688238 | N17: 20070785 | O17: 3517081.6 | P17: 6902675.9 | Q17: 11789321 | R17: 18994691 | S17: 22454542 | T17: 26410421 | U17: 26926251 | V17: 33347619 | W17: 33422579 | X17: 38700575 | Y17: 41656113 | AA17: =N17-Z17 -> 20070785 | AC17: 2909434 | AD17: 3012836.2 | AE17: 2711641.7 | AF17: 6710641.7 | AG17: 10346656 | AH17: 12844979 | AI17: 13196958 | AJ17: 14914964 | AK17: 15326565
A18: Other Expense | B18: 0 | C18: 0 | D18: 0 | E18: 0 | F18: 0 | G18: 0 | H18: 0 | I18: 0 | J18: 0 | L18: 0 | M18: 0 | O18: 0 | P18: 0 | Q18: 0 | R18: 0 | S18: 0 | T18: 0 | U18: 0 | V18: 0 | W18: 0 | X18: 0 | Y18: 0 | Z18: 79770379 | AA18: =N18-Z18 -> -79770379 | AB18: 34703433 | AC18: 0 | AD18: 0 | AE18: 0 | AF18: 0 | AG18: 0 | AH18: 0 | AI18: 0 | AJ18: 0 | AK18: 0
A19: Net Financial Income/(Loss) | B19: =B3-B12 -> 41737821 | C19: =C3-C12 -> 79016795 | D19: =D3-D12 -> 1.3591431e+08 | E19: =E3-E12 -> 2.319811e+08 | F19: =F3-F12 -> 2.7525224e+08 | G19: =G3-G12 -> 3.1855499e+08 | H19: =H3-H12 -> 3.6427606e+08 | I19: =I3-I12 -> 4.1092034e+08 | ... Z19: =Z3-Z12 -> 321322020 | AA19: =N19-Z19 -> -2655020 | AB19: =AB3-AB12 -> 419824457 | AC19: =AC3-AC12 -> 68804524 | AD19: =AD3-AD12 -> 1.3647062e+08 | AE19: =AE3-AE12 -> 2.0521246e+08 | AF19: =AF3-AF12 -> 2.7643905e+08 | AG19: =AG3-AG12 -> 3.5200906e+08 | AH19: =AH3-AH12 -> 4.8396636e+08 | AI19: =AI3-AI12 -> 5.5073466e+08 | ... AM19: =AM3-AM12 -> 0
A20: Allowance for Loan Loss | B20: =B21-B22 -> 0 | C20: =C21-C22 -> 0 | D20: =D21-D22 -> 0 | E20: =E21-E22 -> 0 | F20: =F21-F22 -> 0 | G20: =G21-G22 -> 0 | H20: =H21-H22 -> 0 | I20: =I21-I22 -> 0 | ... Z20: =Z21-Z22 -> 10504980 | AA20: =N20-Z20 -> -10504980 | AB20: =AB21-AB22 -> 16836415 | AC20: =AC21-AC22 -> 0 | AD20: =AD21-AD22 -> 0 | AE20: =AE21-AE22 -> 0 | AF20: =AF21-AF22 -> 0 | AG20: =AG21-AG22 -> 0 | AH20: =AH21-AH22 -> 0 | AI20: =AI21-AI22 -> 0 | ... AM20: =AM21-AM22 -> 0
A21: Provision for Loan Losses | B21: 0 | C21: 0 | D21: 0 | E21: 0 | F21: 0 | G21: 0 | H21: 0 | I21: 0 | J21: 0 | L21: 0 | M21: 0 | O21: 0 | P21: 0 | Q21: 0 | R21: 0 | S21: 0 | T21: 0 | U21: 0 | V21: 0 | W21: 0 | X21: 0 | Y21: 0 | Z21: 10504980 | AA21: =N21-Z21 -> -10504980 | AB21: 16836415 | AC21: 0 | AD21: 0 | AE21: 0 | AF21: 0 | AG21: 0 | AH21: 0 | AI21: 0 | AJ21: 0 | AK21: 0
A22: Value of Loans Recovered | B22: 0 | C22: 0 | D22: 0 | E22: 0 | F22: 0 | G22: 0 | H22: 0 | I22: 0 | J22: 0 | L22: 0 | M22: 0 | O22: 0 | P22: 0 | Q22: 0 | R22: 0 | S22: 0 | T22: 0 | U22: 0 | V22: 0 | W22: 0 | X22: 0 | Y22: 0 | AA22: =N22-Z22 -> 0 | AC22: 0 | AD22: 0 | AE22: 0 | AF22: 0 | AG22: 0 | AH22: 0 | AI22: 0 | AJ22: 0 | AK22: 0
A23: Operating Expenses | B23: =SUM(B24:B28) -> 13756948 | C23: =SUM(C24:C28) -> 25907964 | D23: =SUM(D24:D28) -> 46489717 | E23: =SUM(E24:E28) -> 68072060 | F23: =SUM(F24:F28) -> 86624429 | G23: =SUM(G24:G28) -> 98517771 | H23: =SUM(H24:H28) -> 1.2556816e+08 | I23: =SUM(I24:I28) -> 1.5479427e+08 | ... Z23: =SUM(Z24:Z28) -> 287495990 | AA23: =N23-Z23 -> -65800527 | AB23: =SUM(AB24:AB28) -> 300724749 | AC23: =SUM(AC24:AC28) -> 24186407 | AD23: =SUM(AD24:AD28) -> 54526622 | AE23: =SUM(AE24:AE28) -> 96715065 | AF23: =SUM(AF24:AF28) -> 1.1674232e+08 | AG23: =SUM(AG24:AG28) -> 1.4912851e+08 | AH23: =SUM(AH24:AH28) -> 1.7627722e+08 | AI23: =SUM(AI24:AI28) -> 2.013011e+08 | ... AM23: =SUM(AM24:AM28) -> 0
A24: Personnel Expenses | B24: 6130811.9 | C24: 13036341 | D24: 23929473 | E24: 39561446 | F24: 47643865 | G24: 55923812 | H24: 65084878 | I24: 75125662 | J24: 84296752 | L24: 1.0759178e+08 | M24: 116028086 | N24: 108600735 | O24: 3686772 | P24: 19985061 | Q24: 51525599 | R24: 52350417 | S24: 65131762 | T24: 75434334 | U24: 83560110 | V24: 94161024 | W24: 1.0693831e+08 | X24: 1.1658069e+08 | Y24: 1.29601e+08 | Z24: 134808061 | AA24: =N24-Z24 -> -26207326 | AB24: 137994298 | AC24: 10353612 | AD24: 22038937 | AE24: 40457461 | AF24: 53665898 | AG24: 69245108 | AH24: 96163684 | AI24: 1.0791929e+08 | AJ24: 1.203403e+08 | AK24: 1.3441957e+08
A25: Governance Expenses | B25: 4540475 | C25: 8511775 | D25: 12302075 | E25: 14755905 | F25: 17675745 | G25: 20436445 | H25: 34116459 | I25: 39444159 | J25: 50544554 | L25: 66990493 | M25: 69050553 | N25: 51267848 | O25: 3426062.4 | P25: 15059524 | Q25: 29329257 | R25: 32458308 | S25: 36291319 | T25: 48172390 | U25: 50567390 | V25: 63418032 | W25: 67730444 | X25: 70969684 | Y25: 74783498 | Z25: 65790264 | AA25: =N25-Z25 -> -14522416 | AB25: 66558805 | AC25: 4199805 | AD25: 21116265 | AE25: 33710515 | AF25: 36687915 | AG25: 41013032 | AH25: 43822032 | AI25: 51547806 | AJ25: 54062326 | AK25: 57336894
A26: Marketing Expenses | B26: 445500 | C26: 480500 | D26: 515500 | E26: 637674 | F26: 1672674 | G26: 1707674 | H26: 2082674 | I26: 2259330 | J26: 2294330 | L26: 2602330 | M26: 2806929 | O26: 38360 | P26: 325360 | Q26: 587236 | R26: 985543 | S26: 2717543 | T26: 2772463 | U26: 2807463 | V26: 3138683 | W26: 4723407 | X26: 5266506 | Y26: 8652906 | AA26: =N26-Z26 -> 0 | AC26: 262800 | AD26: 294905 | AE26: 510505 | AF26: 650145 | AG26: 794945 | AH26: 2978062 | AI26: 5172622 | AJ26: 5362622 | AK26: 6967872
A27: Depreciation and Amortization Charges | B27: 0 | C27: 0 | D27: 0 | E27: 0 | F27: 0 | G27: 0 | H27: 0 | I27: 0 | J27: 0 | L27: 0 | M27: 20355463 | N27: 20355463 | O27: 0 | P27: 0 | Q27: 0 | R27: 0 | S27: 0 | T27: 0 | U27: 0 | V27: 0 | W27: 0 | X27: 0 | Y27: 0 | Z27: 20355463 | AA27: =N27-Z27 -> 0 | AB27: 19908248 | AC27: 0 | AD27: 0 | AE27: 0 | AF27: 0 | AG27: 0 | AH27: 0 | AI27: 0 | AJ27: 0 | AK27: 0
A28: Administrative Expenses | B28: 2640161.1 | C28: 3879348.1 | D28: 9742668.7 | E28: 13117035 | F28: 19632145 | G28: 20449840 | H28: 24284147 | I28: 37965122 | J28: 45233289 | L28: 52263378 | M28: 55846593 | N28: 41471417 | O28: 5503147.3 | P28: 15683338 | Q28: 23959251 | R28: 27838521 | S28: 30307027 | T28: 39220967 | U28: 40462393 | V28: 46137466 | W28: 67528203 | X28: 83937179 | Y28: 93963190 | Z28: 66542202 | AA28: =N28-Z28 -> -25070785 | AB28: 76263398 | AC28: 9370190 | AD28: 11076515 | AE28: 22036584 | AF28: 25738367 | AG28: 38075425 | AH28: 33313442 | AI28: 36661382 | AJ28: 39955256 | AK28: 46445906
A29: Net Operating Income | B29: =B19-B20-B23 -> 27980873 | C29: =C19-C20-C23 -> 53108832 | D29: =D19-D20-D23 -> 89424595 | E29: =E19-E20-E23 -> 1.6390904e+08 | F29: =F19-F20-F23 -> 1.8862781e+08 | G29: =G19-G20-G23 -> 2.2003722e+08 | H29: =H19-H20-H23 -> 2.387079e+08 | I29: =I19-I20-I23 -> 2.5612606e+08 | ... Z29: =Z19-Z20-Z23 -> 23321050 | AA29: =N29-Z29 -> 73650487 | AB29: =AB19-AB20-AB23 -> 102263293 | AC29: =AC19-AC20-AC23 -> 44618117 | AD29: =AD19-AD20-AD23 -> 81943999 | AE29: =AE19-AE20-AE23 -> 1.084974e+08 | AF29: =AF19-AF20-AF23 -> 1.5969672e+08 | AG29: =AG19-AG20-AG23 -> 2.0288055e+08 | AH29: =AH19-AH20-AH23 -> 3.0768914e+08 | AI29: =AI19-AI20-AI23 -> 3.4943356e+08 | ... AN29: =AN19-AN20-AN23 -> 0
A30: Net Non- Operating Income/ (Expense) | B30: =B31-B32 -> 0 | C30: =C31-C32 -> 0 | D30: =D31-D32 -> 0 | E30: =E31-E32 -> 0 | F30: =F31-F32 -> 0 | G30: =G31-G32 -> 0 | H30: =H31-H32 -> 0 | I30: =I31-I32 -> 0 | ... Z30: =Z31-Z32 -> 0 | AA30: =N30-Z30 -> 0 | AB30: =AB31-AB32 -> 0 | AC30: =AC31-AC32 -> 0 | AD30: =AD31-AD32 -> 0 | AE30: =AE31-AE32 -> 0 | AF30: =AF31-AF32 -> 0 | AG30: =AG31-AG32 -> 0 | AH30: =AH31-AH32 -> 0 | AI30: =AI31-AI32 -> 0 | ... AN30: =AN31-AN32 -> 0
A31: Non- Operating Income | B31: 0 | C31: 0 | D31: 0 | E31: 0 | F31: 0 | G31: 0 | H31: 0 | I31: 0 | J31: 0 | K31: 0 | L31: 0 | M31: 0 | O31: 0 | P31: 0 | Q31: 0 | R31: 0 | S31: 0 | T31: 0 | U31: 0 | V31: 0 | W31: 0 | X31: 0 | Y31: 0 | AA31: =N31-Z31 -> 0 | AC31: 0 | AD31: 0 | AE31: 0 | AF31: 0 | AG31: 0 | AH31: 0 | AI31: 0 | AJ31: 0 | AK31: 0
A32: Non- Operating Expense | B32: 0 | C32: 0 | D32: 0 | E32: 0 | F32: 0 | G32: 0 | H32: 0 | I32: 0 | J32: 0 | K32: 0 | L32: 0 | M32: 0 | O32: 0 | P32: 0 | Q32: 0 | R32: 0 | S32: 0 | T32: 0 | U32: 0 | V32: 0 | W32: 0 | X32: 0 | Y32: 0 | AA32: =N32-Z32 -> 0 | AC32: 0 | AD32: 0 | AE32: 0 | AF32: 0 | AG32: 0 | AH32: 0 | AI32: 0 | AJ32: 0 | AK32: 0
A33: Net Income (Before Taxes and Donations) | B33: =B29+B30 -> 27980873 | C33: =C29+C30 -> 53108832 | D33: =D29+D30 -> 89424595 | E33: =E29+E30 -> 1.6390904e+08 | F33: =F29+F30 -> 1.8862781e+08 | G33: =G29+G30 -> 2.2003722e+08 | H33: =H29+H30 -> 2.387079e+08 | I33: =I29+I30 -> 2.5612606e+08 | ... Z33: =Z29+Z30 -> 23321050 | AA33: =N33-Z33 -> 73650487 | AB33: =AB29+AB30 -> 102263293 | AC33: =AC29+AC30 -> 44618117 | AD33: =AD29+AD30 -> 81943999 | AE33: =AE29+AE30 -> 1.084974e+08 | AF33: =AF29+AF30 -> 1.5969672e+08 | AG33: =AG29+AG30 -> 2.0288055e+08 | AH33: =AH29+AH30 -> 3.0768914e+08 | AI33: =AI29+AI30 -> 3.4943356e+08 | ... AN33: =AN29+AN30 -> 0
A34: Taxes (Incomes taxes & Other payable to KRA) | B34: 0 | C34: 0 | D34: 0 | E34: 1868739 | F34: 1868739 | G34: 3737478 | H34: 3737478 | I34: 3737478 | J34: 5606217 | L34: 5606217 | M34: 7474956 | N34: 6008559 | O34: 0 | P34: 0 | Q34: 1652354 | R34: 1652354 | S34: 3304708 | T34: 3304708 | U34: 3304708 | V34: 4957062 | W34: 4957062 | X34: 4957062 | Y34: 6609416 | AA34: =N34-Z34 -> 6008559 | AC34: 0 | AD34: 0 | AE34: 0 | AF34: 2003620 | AG34: 2003620 | AH34: 3950716 | AI34: 3950716 | AJ34: 3950716 | AK34: 5957786
A35: Net Income (After Taxes before Donations) | B35: =B33-B34 -> 27980873 | C35: =C33-C34 -> 53108832 | D35: =D33-D34 -> 89424595 | E35: =E33-E34 -> 1.620403e+08 | F35: =F33-F34 -> 1.8675907e+08 | G35: =G33-G34 -> 2.1629974e+08 | H35: =H33-H34 -> 2.3497043e+08 | I35: =I33-I34 -> 2.5238859e+08 | ... Z35: =Z33-Z34 -> 23321050 | AA35: =N35-Z35 -> 67641928 | AB35: =AB33-AB34 -> 102263293 | AC35: =AC33-AC34 -> 44618117 | AD35: =AD33-AD34 -> 81943999 | AE35: =AE33-AE34 -> 1.084974e+08 | AF35: =AF33-AF34 -> 1.576931e+08 | AG35: =AG33-AG34 -> 2.0087693e+08 | AH35: =AH33-AH34 -> 3.0373843e+08 | AI35: =AI33-AI34 -> 3.4548285e+08 | ... AN35: =AN33-AN34 -> 0
A36: Donations | B36: 0 | C36: 0 | D36: 0 | E36: 0 | F36: 0 | G36: 0 | H36: 0 | I36: 0 | J36: 0 | K36: 0 | L36: 0 | M36: 0 | O36: 0 | P36: 0 | Q36: 0 | R36: 0 | S36: 0 | T36: 0 | U36: 0 | V36: 0 | W36: 0 | X36: 0 | Y36: 0 | AA36: =N36-Z36 -> 0 | AC36: 0 | AD36: 0 | AE36: 0 | AF36: 0 | AG36: 0 | AH36: 0 | AI36: 0 | AJ36: 0 | AK36: 0 | AL36: 0
A37: Net Income/(After Taxes and Donations) | B37: =B35-B36 -> 27980873 | C37: =C35-C36 -> 53108832 | D37: =D35-D36 -> 89424595 | E37: =E35-E36 -> 1.620403e+08 | F37: =F35-F36 -> 1.8675907e+08 | G37: =G35-G36 -> 2.1629974e+08 | H37: =H35-H36 -> 2.3497043e+08 | I37: =I35-I36 -> 2.5238859e+08 | ... Z37: =Z35-Z36 -> 23321050 | AA37: =N37-Z37 -> 67641928 | AB37: =AB35-AB36 -> 102263293 | AC37: =AC35-AC36 -> 44618117 | AD37: =AD35-AD36 -> 81943999 | AE37: =AE35-AE36 -> 1.084974e+08 | AF37: =AF35-AF36 -> 1.576931e+08 | AG37: =AG35-AG36 -> 2.0087693e+08 | AH37: =AH35-AH36 -> 3.0373843e+08 | AI37: =AI35-AI36 -> 3.4548285e+08 | ... AN37: =AN35-AN36 -> 0

Sheet Financials
B2: ELIMU SACCO SOCIETY
B3: Year | C3: january | D3: february | E3: march | F3: april | G3: may | H3: june | I3: july | J3: august | K3: september | L3: october | M3: november | N3: december | O3: audited 21 | P3: Feb | Q3: Mar | R3: Apr | S3: May | T3: Jun | U3: Jul | V3: Aug | W3: Sep | X3: Oct | Y3: Nov | Z3: Dec | AA3: Restated 2021 | AC3: Aud-22 | AD3: 44927 | AE3: 44958 | AF3: 44986 | AG3: 45017 | AH3: 45047 | AI3: 45078 | AJ3: 45108 | AK3: 45139 | AL3: 45170
A4: 1 | B4: Membership
A5: 2 | B5: Total Assets | C5: =SFP!B26 -> 6.3302389e+09 | D5: =SFP!C26 -> 6.4282313e+09 | E5: =SFP!D26 -> 6.5434997e+09 | F5: =SFP!E26 -> 6.3423933e+09 | G5: =SFP!F26 -> 6.6617024e+09 | H5: =SFP!G26 -> 6.8126167e+09 | I5: =SFP!H26 -> 6.7579623e+09 | J5: =SFP!I26 -> 6.7474402e+09 | ... AL5: =SFP!AK26 -> 0
A6: 3 | B6: Total Deposits | C6: =SFP!B30 -> 4.6599276e+09 | D6: =SFP!C30 -> 4.6103e+09 | E6: =SFP!D30 -> 4.6613478e+09 | F6: =SFP!E30 -> 4.8335267e+09 | G6: =SFP!F30 -> 4.780195e+09 | H6: =SFP!G30 -> 4.8001885e+09 | I6: =SFP!H30 -> 4.7904504e+09 | J6: =SFP!I30 -> 4.8244837e+09 | ... AL6: =SFP!AK30 -> 0
A7: 3.1 | B7: Deposits-Members(BOSA) | C7: =SFP!B29 -> 4.4982527e+09 | D7: =SFP!C29 -> 4.5415133e+09 | E7: =SFP!D29 -> 4.5877737e+09 | F7: =SFP!E29 -> 4.6331709e+09 | G7: =SFP!F29 -> 4.6708746e+09 | H7: =SFP!G29 -> 4.680367e+09 | I7: =SFP!H29 -> 4.7062754e+09 | J7: =SFP!I29 -> 4.7353454e+09 | ... AL7: =SFP!AK29 -> 0
A8: 3.2 | B8: Deposits-Customers(FOSA) | C8: =SFP!B27 -> 1.4508275e+08 | D8: =SFP!C27 -> 50126547 | E8: =SFP!D27 -> 54986080 | F8: =SFP!E27 -> 1.8095028e+08 | G8: =SFP!F27 -> 90227798 | H8: =SFP!G27 -> 99328975 | I8: =SFP!H27 -> 64548910 | J8: =SFP!I27 -> 71312236 | ... AL8: =SFP!AK27 -> 0
A9: 4 | B9: External Borrowing | C9: =SFP!B37 -> 0 | D9: =SFP!C37 -> 0 | E9: =SFP!D37 -> 0 | F9: =SFP!E37 -> 0 | G9: =SFP!F37 -> 400000000 | H9: =SFP!G37 -> 400000000 | I9: =SFP!H37 -> 3.8888889e+08 | J9: =SFP!I37 -> 3.7777778e+08 | ... AL9: =SFP!AK37 -> 0
A10: 4.1 | B10: Short term Liabilities | C10: =SFP!B32+SFP!B33+SFP!B34+SFP!B35+SFP!B36 -> 2.9789071e+08 | D10: =SFP!C32+SFP!C33+SFP!C34+SFP!C35+SFP!C36 -> 4.4449013e+08 | E10: =SFP!D32+SFP!D33+SFP!D34+SFP!D35+SFP!D36 -> 4.5850111e+08 | F10: =SFP!E32+SFP!E33+SFP!E34+SFP!E35+SFP!E36 -> 69029042 | G10: =SFP!F32+SFP!F33+SFP!F34+SFP!F35+SFP!F36 -> 16229944 | H10: =SFP!G32+SFP!G33+SFP!G34+SFP!G35+SFP!G36 -> 65269345 | I10: =SFP!H32+SFP!H33+SFP!H34+SFP!H35+SFP!H36 -> 70607155 | J10: =SFP!I32+SFP!I33+SFP!I34+SFP!I35+SFP!I36 -> 22506679 | ... AL10: =SFP!AK32+SFP!AK33+SFP!AK34+SFP!AK35+SFP!AK36 -> 0
A13: 5 | B13: Share capital and Reserves | C13: =C18+C20+C21 -> 5.3565537e+08 | D13: =D18+D20+D21 -> 5.5319249e+08 | E13: =E18+E20+E21 -> 5.5323948e+08 | F13: =F18+F20+F21 -> 5.5349733e+08 | G13: =G18+G20+G21 -> 5.5349733e+08 | H13: =H18+H20+H21 -> 5.5349953e+08 | I13: =I18+I20+I21 -> 5.5349813e+08 | J13: =J18+J20+J21 -> 5.5350411e+08 | ... AL13: =AL18+AL20+AL21 -> 0
A14: 5.1 | B14: Core Capital | C14: =C17 -> 7.4307015e+08 | D14: =D17 -> 7.6162549e+08 | E14: =E17 -> 7.9412828e+08 | F14: =F17 -> 8.6671489e+08 | G14: =G17 -> 8.870124e+08 | H14: =H17 -> 9.1763641e+08 | I14: =I17 -> 9.2975076e+08 | J14: =J17 -> 9.4440697e+08 | ... AL14: =AL17 -> 0
A15: 5.2 | B15: Institutional Capital | C15: =C14-C18 -> 3.0288194e+08 | D15: =D14-D18 -> 3.2143768e+08 | E15: =E14-E18 -> 3.5394087e+08 | F15: =F14-F18 -> 4.2626963e+08 | G15: =G14-G18 -> 4.4656714e+08 | H15: =H14-H18 -> 4.7718895e+08 | I15: =I14-I18 -> 4.893047e+08 | J15: =J14-J18 -> 5.0395494e+08 | ... AL15: =AL14-AL18 -> 0
A17: 5.3 | B17: Total Capital | C17: =SUM(C18:C21) -> 7.4307015e+08 | D17: =SUM(D18:D21) -> 7.6162549e+08 | E17: =SUM(E18:E21) -> 7.9412828e+08 | F17: =SUM(F18:F21) -> 8.6671489e+08 | G17: =SUM(G18:G21) -> 8.870124e+08 | H17: =SUM(H18:H21) -> 9.1763641e+08 | I17: =SUM(I18:I21) -> 9.2975076e+08 | J17: =SUM(J18:J21) -> 9.4440697e+08 | ... AL17: =SUM(AL18:AL21) -> 0
A18: 5.3.1 | B18: Members Share Capital | C18: =SFP!B39 -> 4.4018821e+08 | D18: =SFP!C39 -> 4.4018781e+08 | E18: =SFP!D39 -> 4.4018741e+08 | F18: =SFP!E39 -> 4.4044526e+08 | G18: =SFP!F39 -> 4.4044526e+08 | H18: =SFP!G39 -> 4.4044746e+08 | I18: =SFP!H39 -> 4.4044606e+08 | J18: =SFP!I39 -> 4.4045204e+08 | ... AL18: =SFP!AK39 -> 0
A19: 5.3.3 | B19: Retained Earnings | C19: =SFP!B41 -> 2.0741478e+08 | D19: =SFP!C41 -> 2.0843299e+08 | E19: =SFP!D41 -> 2.408888e+08 | F19: =SFP!E41 -> 3.1321756e+08 | G19: =SFP!F41 -> 3.3351507e+08 | H19: =SFP!G41 -> 3.6413688e+08 | I19: =SFP!H41 -> 3.7625263e+08 | J19: =SFP!I41 -> 3.9090287e+08 | ... AL19: =SFP!AK41 -> 0
A20: 5.3.5 | B20: Statutory Reserves | C20: =SFP!B45 -> 90967158 | D20: =SFP!C45 -> 108504682 | E20: =SFP!D45 -> 108552071 | F20: =SFP!E45 -> 108552071 | G20: =SFP!F45 -> 108552071 | H20: =SFP!G45 -> 108552071 | I20: =SFP!H45 -> 108552071 | J20: =SFP!I45 -> 108552071 | ... AL20: =SFP!AK45 -> 0
A21: 5.3.6 | B21: Capital Reserve | C21: =SFP!B46 -> 4500000 | D21: =SFP!C46 -> 4500000 | E21: =SFP!D46 -> 4500000 | F21: =SFP!E46 -> 4500000 | G21: =SFP!F46 -> 4500000 | H21: =SFP!G46 -> 4500000 | I21: =SFP!H46 -> 4500000 | J21: =SFP!I46 -> 4500000 | ... AL21: =SFP!AK46 -> 0
A22: 5.3.7 | B22: Supplementary Capital & reserves
A23: a | B23: Proposed Dividends | C23: =SFP!B48 -> 0 | D23: =SFP!C48 -> 50579027 | E23: =SFP!D48 -> 51257379 | F23: =SFP!E48 -> 0 | G23: =SFP!F48 -> 0 | H23: =SFP!G48 -> 51257379 | I23: =SFP!H48 -> 0 | J23: =SFP!I48 -> 0 | ... AL23: =SFP!AK48 -> 0
A24: b
A26: 6 | B26: Investments | C26: =C27+C28+C29 -> 486426946 | D26: =D27+D28+D29 -> 4.183132e+08 | E26: =E27+E28+E29 -> 4.183132e+08 | F26: =F27+F28+F29 -> 4.183132e+08 | G26: =G27+G28+G29 -> 4.183132e+08 | H26: =H27+H28+H29 -> 4.183132e+08 | I26: =I27+I28+I29 -> 4.183132e+08 | J26: =J27+J28+J29 -> 4.183132e+08 | ... AL26: =AL27+AL28+AL29 -> 0
A27: 6.1 | B27: Investments in Coop bank, CIC, Kuscco, Kerussu & Codic | C27: =SFP!B12 -> 486426946 | D27: =SFP!C12 -> 4.183132e+08 | E27: =SFP!D12 -> 4.183132e+08 | F27: =SFP!E12 -> 4.183132e+08 | G27: =SFP!F12 -> 4.183132e+08 | H27: =SFP!G12 -> 4.183132e+08 | I27: =SFP!H12 -> 4.183132e+08 | J27: =SFP!I12 -> 4.183132e+08 | ... AL27: =SFP!AK12 -> 0
A28: 6.2 | B28: Equity Investments (at cost)
A29: 6.3 | B29: Deposits in KUSCCO CFP | C29: =SFP!B11 -> 0 | D29: =SFP!C11 -> 0 | E29: =SFP!D11 -> 0 | F29: =SFP!E11 -> 0 | G29: =SFP!F11 -> 0 | H29: =SFP!G11 -> 0 | I29: =SFP!H11 -> 0 | J29: =SFP!I11 -> 0 | ... AL29: =SFP!AK11 -> 0
A31: 7 | B31: Net Loans & advances | C31: =C32-C33 -> 3.3035756e+09 | D31: =D32-D33 -> 3.3794646e+09 | E31: =E32-E33 -> 3.4096313e+09 | F31: =F32-F33 -> 3.3737607e+09 | G31: =G32-G33 -> 3.3803658e+09 | H31: =H32-H33 -> 3.3723653e+09 | I31: =I32-I33 -> 3.4017131e+09 | J31: =J32-J33 -> 3.4401109e+09 | ... AL31: =AL32-AL33 -> 0
A32: 7.1 | B32: Gross Loans & advances | C32: =SFP!B14 -> 3.4379818e+09 | D32: =SFP!C14 -> 3.5287339e+09 | E32: =SFP!D14 -> 3.5589006e+09 | F32: =SFP!E14 -> 3.5230299e+09 | G32: =SFP!F14 -> 3.529635e+09 | H32: =SFP!G14 -> 3.5216345e+09 | I32: =SFP!H14 -> 3.5509824e+09 | J32: =SFP!I14 -> 3.5893802e+09 | ... AL32: =SFP!AK14 -> 0
A33: 7.3 | B33: Allowance for loan losses | C33: =SFP!B15 -> 134406232 | D33: =SFP!C15 -> 1.4926925e+08 | E33: =SFP!D15 -> 1.4926925e+08 | F33: =SFP!E15 -> 1.4926925e+08 | G33: =SFP!F15 -> 1.4926925e+08 | H33: =SFP!G15 -> 1.4926925e+08 | I33: =SFP!H15 -> 1.4926925e+08 | J33: =SFP!I15 -> 1.4926925e+08 | ... AL33: =SFP!AK15 -> 0
A34: 7.4 | B34: Non Performing Loans | AC34: =162502879+19518299+151715259 -> 333736437 | AD34: =162502879+19518299+151715259 -> 333736437 | AE34: =162502879+19518299+151715259 -> 333736437 | AF34: =162502879+19518299+151715259 -> 333736437 | AG34: =162502879+19518299+151715259 -> 333736437 | AH34: =162502879+19518299+151715259 -> 333736437 | AI34: =162502879+19518299+151715259 -> 333736437 | AJ34: =162502879+19518299+151715259 -> 333736437 | ... AL34: =162502879+19518299+151715259 -> 333736437
A35: 7.5 | B35: Required loan loss provision
A36: 7.6 | B36: Cash and Cash equipments | C36: =SFP!B4 -> 252652851 | D36: =SFP!C4 -> 2.4646583e+08 | E36: =SFP!D4 -> 2.8979676e+08 | F36: =SFP!E4 -> 1.3139564e+08 | G36: =SFP!F4 -> 4.7950328e+08 | H36: =SFP!G4 -> 7.8374847e+08 | I36: =SFP!H4 -> 4.8954418e+08 | J36: =SFP!I4 -> 7.1282297e+08 | ... AL36: =SFP!AK4 -> 0
A38: 8 | B38: Non-Earning Assets | C38: =SFP!B7+SFP!B16+SFP!B22+SFP!B23+SFP!B24+SFP!B25 -> 1.835141e+09 | D38: =SFP!C7+SFP!C16+SFP!C22+SFP!C23+SFP!C24+SFP!C25 -> 1.9313595e+09 | E38: =SFP!D7+SFP!D16+SFP!D22+SFP!D23+SFP!D24+SFP!D25 -> 1.9731302e+09 | F38: =SFP!E7+SFP!E16+SFP!E22+SFP!E23+SFP!E24+SFP!E25 -> 1.9662956e+09 | G38: =SFP!F7+SFP!F16+SFP!F22+SFP!F23+SFP!F24+SFP!F25 -> 1.930892e+09 | H38: =SFP!G7+SFP!G16+SFP!G22+SFP!G23+SFP!G24+SFP!G25 -> 1.7857516e+09 | I38: =SFP!H7+SFP!H16+SFP!H22+SFP!H23+SFP!H24+SFP!H25 -> 1.9959536e+09 | J38: =SFP!I7+SFP!I16+SFP!I22+SFP!I23+SFP!I24+SFP!I25 -> 1.723755e+09 | ... AL38: =SFP!AK7+SFP!AK16+SFP!AK22+SFP!AK23+SFP!AK24+SFP!AK25 -> 0
A39: 8.1 | B39: Property and Equipment | C39: =SFP!B22 -> 32568033 | D39: =SFP!C22 -> 32568034 | E39: =SFP!D22 -> 35773639 | F39: =SFP!E22 -> 41399718 | G39: =SFP!F22 -> 41399718 | H39: =SFP!G22 -> 41399718 | I39: =SFP!H22 -> 41399718 | J39: =SFP!I22 -> 41399718 | ... AL39: =SFP!AK22 -> 0
A41: 9 | B41: Turnover | C41: =C42+C43+C44 -> 42188053 | D41: =D42+D43+D44 -> 79467027 | E41: =E42+E43+E44 -> 1.3636454e+08 | F41: =F42+F43+F44 -> 2.3243133e+08 | G41: =G42+G43+G44 -> 2.7570247e+08 | H41: =H42+H43+H44 -> 3.1900522e+08 | I41: =I42+I43+I44 -> 3.6472629e+08 | J41: =J42+J43+J44 -> 4.1137057e+08 | ... AL41: =AL42+AL43+AL44 -> 7.1212301e+08
A42: 9.1 | B42: Loan Interest | C42: =SCI!B5 -> 36107004 | D42: =SCI!C5 -> 65232689 | E42: =SCI!D5 -> 1.1139151e+08 | F42: =SCI!E5 -> 1.5394338e+08 | G42: =SCI!F5 -> 1.8968719e+08 | H42: =SCI!G5 -> 2.25625e+08 | I42: =SCI!H5 -> 2.6193996e+08 | J42: =SCI!I5 -> 2.9823513e+08 | ... AL42: =SCI!AK5 -> 4.4690321e+08
B43: Income from investments | C43: =SCI!B7 -> 1910554.4 | D43: =SCI!C7 -> 3831778.5 | E43: =SCI!D7 -> 8654186.4 | F43: =SCI!E7 -> 52085852 | G43: =SCI!F7 -> 54055257 | H43: =SCI!G7 -> 56024662 | I43: =SCI!H7 -> 57994068 | J43: =SCI!I7 -> 59941921 | ... AL43: =SCI!AK7 -> 1.3360964e+08
A44: 9.2 | B44: Fees & Commissions | C44: =SCI!B6 -> 4170494.5 | D44: =SCI!C6 -> 10402560 | E44: =SCI!D6 -> 16318850 | F44: =SCI!E6 -> 26402092 | G44: =SCI!F6 -> 31960024 | H44: =SCI!G6 -> 37355561 | I44: =SCI!H6 -> 44792264 | J44: =SCI!I6 -> 53193522 | ... AL44: =SCI!AK6 -> 1.3161017e+08
B45: Average yield on loans | C45: =C42/C32 -> 0.010502384 | D45: =D42/D32 -> 0.018486146 | E45: =E42/E32 -> 0.031299415 | F45: =F42/F32 -> 0.043696303 | G45: =G42/G32 -> 0.053741304 | H45: =H42/H32 -> 0.064068261 | I45: =I42/I32 -> 0.073765492 | J45: =J42/J32 -> 0.083088197 | ... AL45: =AL42/AL32 -> #DIV/0!
A47: 10 | B47: Total Expenses (FinCosts + OpEx) | C47: =SUM(C48:C53) -> #REF! | D47: =SUM(D48:D53) -> #REF! | E47: =SUM(E48:E53) -> #REF! | F47: =SUM(F48:F53) -> #REF! | G47: =SUM(G48:G53) -> #REF! | H47: =SUM(H48:H53) -> #REF! | I47: =SUM(I48:I53) -> #REF! | J47: =SUM(J48:J53) -> #REF! | ... AL47: =SUM(AL48:AL53) -> #REF!
A48: 10.1 | B48: Financial Exp. (Interest on deposits) | C48: =SCI!B13 -> 368947.88 | D48: =SCI!C13 -> 368947.88 | E48: =SCI!D13 -> 368947.88 | F48: =SCI!E13 -> 368947.88 | G48: =SCI!F13 -> 368947.88 | H48: =SCI!G13 -> 368947.88 | I48: =SCI!H13 -> 368947.88 | J48: =SCI!I13 -> 368947.88 | ... AL48: =SCI!AK13 -> 0
A49: 10.2 | B49: Financial Exp. (Dividends) | C49: =SCI!B15 -> 0 | D49: =SCI!C15 -> 0 | E49: =SCI!D15 -> 0 | F49: =SCI!E15 -> 0 | G49: =SCI!F15 -> 0 | H49: =SCI!G15 -> 0 | I49: =SCI!H15 -> 0 | J49: =SCI!I15 -> 0 | ... AL49: =SCI!AK15 -> 0
...

Sheet Prudential Ratios
A1: MAGEREZA SACCO SOCIETY LTD
A2: Sacco Financial Performance
O3: Approved | AA3: Restated 2021 accounts
A4: FINANCIAL SOUNDNESS INDICATORS | B4: Prude. Std | C4: january | D4: february | E4: march | F4: april | G4: may | H4: june | I4: july | J4: august | K4: september | L4: october | M4: november | N4: december | O4: Audited 2021 | P4: Feb | Q4: Mar | R4: Apr | S4: May | T4: Jun | U4: Jul | V4: Aug | W4: Sep | X4: Oct | Y4: Nov | Z4: Dec | AA4: by the Auditor | AC4: Audited 2022 | AD4: 44927 | AE4: 44958 | AF4: 44986 | AG4: 45017 | AH4: 45047 | AI4: 45078 | AJ4: 45108 | AK4: 45139 | AL4: 45170
A5: CAPITAL ADEQUACY REQUIREMENTS
A6: Core capital | B6: ≥ Ksh.10M | C6: =Financials!C14/1000000 -> 743.07015 | D6: =Financials!D14/1000000 -> 761.62549 | E6: =Financials!E14/1000000 -> 794.12828 | F6: =Financials!F14/1000000 -> 866.71489 | G6: =Financials!G14/1000000 -> 887.0124 | H6: =Financials!H14/1000000 -> 917.63641 | I6: =Financials!I14/1000000 -> 929.75076 | J6: =Financials!J14/1000000 -> 944.40697 | K6: =Financials!K14/1000000 -> 958.63894 | M6: =Financials!M14/1000000 -> 998.14999 | N6: =Financials!N14/1000000 -> 1002.562 | O6: =Financials!O14/1000000 -> 742.42867 | P6: =Financials!P14/1000000 -> 727.85137 | Q6: =Financials!Q14/1000000 -> 732.29361 | R6: =Financials!R14/1000000 -> 791.39848 | S6: =Financials!S14/1000000 -> 825.85033 | T6: =Financials!T14/1000000 -> 889.03413 | ... AL6: =Financials!AL14/1000000 -> 0
A7: Core capital /Total Assets | B7: ≥ 10% | C7: =Financials!C14/Financials!C5 -> 0.11738422 | D7: =Financials!D14/Financials!D5 -> 0.11848134 | E7: =Financials!E14/Financials!E5 -> 0.1213614 | F7: =Financials!F14/Financials!F5 -> 0.13665423 | G7: =Financials!G14/Financials!G5 -> 0.13315101 | H7: =Financials!H14/Financials!H5 -> 0.13469661 | I7: =Financials!I14/Financials!I5 -> 0.13757857 | J7: =Financials!J14/Financials!J5 -> 0.13996522 | K7: =Financials!K14/Financials!K5 -> 0.14135941 | M7: =Financials!M14/Financials!M5 -> 0.14581123 | N7: =Financials!N14/Financials!N5 -> 0.14577484 | O7: =Financials!O14/Financials!O5 -> 0.10482679 | P7: =Financials!P14/Financials!P5 -> 0.14402302 | Q7: =Financials!Q14/Financials!Q5 -> 0.10515239 | R7: =Financials!R14/Financials!R5 -> 0.11748738 | S7: =Financials!S14/Financials!S5 -> 0.12188338 | T7: =Financials!T14/Financials!T5 -> 0.13007857 | ... AL7: =Financials!AL14/Financials!AL5 -> #DIV/0!
