Workbook

Sheet statement of deposit

Sheet SCI
A1: FORM 7 SASRA/007
A2: STATEMENT OF COMPREHENSIVE INCOME
A3: NAME OF SACCO SOCIETY: NYATI
A4: FINANCIAL YEAR 2020
A5: START DATE: 1st January
A6: END DATE: 31st December
A8: Ref No. | C8: AUDITED 2019 | D8: Audited 2020 | E8: 44197 | F8: 44228 | G8: 44256 | H8: 44287 | I8: 44317 | J8: 44348 | K8: 44378 | L8: 44409 | M8: 44440 | N8: 44470 | O8: 44501 | P8: 44531 | Q8: Audited 2022 | R8: 44562 | S8: 44593 | T8: 44621 | U8: 44652 | V8: 44682 | W8: 44713 | X8: 44743 | Y8: 44774 | Z8: 44805 | AA8: 44835 | AB8: 44866 | AC8: 44896 | AD8: AUDITED 2022 | AE8: 44927 | AF8: 44958 | AG8: 44986 | AH8: 45017 | AI8: 45047 | AJ8: 45078 | AK8: 45108 | AL8: 45139 | AM8: 45170
A10: 1 | B10: Financial Income | C10: =C11+C15 -> 583839786 | D10: =D11+D15 -> 573346290 | E10: =E11+E15 -> 56301430 | F10: =F11+F15 -> 1.05712e+08 | G10: =G11+G15 -> 1.6334855e+08 | H10: =H11+H15 -> 2.187406e+08 | I10: =I11+I15 -> 2.7177693e+08 | J10: =J11+J15 -> 3.2870363e+08 | ... AM10: =AM11+AM15 -> 5.6308842e+08
A11: 2 | B11: Financial Income from Loans Portfolio | C11: =SUM(C12:C13) -> 546947861 | D11: =SUM(D12:D13) -> 542499199 | E11: =SUM(E12:E13) -> 52116907 | F11: =SUM(F12:F13) -> 97560837 | G11: =SUM(G12:G13) -> 1.4628346e+08 | H11: =SUM(H12:H13) -> 1.9361755e+08 | I11: =SUM(I12:I13) -> 2.4231567e+08 | J11: =SUM(J12:J13) -> 2.9296922e+08 | ... AM11: =SUM(AM12:AM13) -> 5.0696667e+08
A12: 2.1 | B12: Interest on Loan Portfolio | C12: 546947861 | D12: 541188931 | E12: 51957907 | F12: 97235637 | G12: 1.4579594e+08 | H12: 1.9296479e+08 | I12: 2.4145639e+08 | J12: 2.918937e+08 | K12: 3.4351432e+08 | L12: 3.9198033e+08 | M12: 4.420435e+08 | N12: 4.9183535e+08 | O12: 5.4162509e+08 | P12: 5.8775632e+08 | Q12: 587756323 | R12: 51743882 | S12: 97736321 | T12: 1.4437856e+08 | U12: 1.9434648e+08 | V12: 2.3879074e+08 | W12: 2.8137089e+08 | X12: 3.2807096e+08 | Y12: 3.7260145e+08 | Z12: 4.1974736e+08 | AA12: 4.7051672e+08 | AB12: 5.2623257e+08 | AC12: 6.0421537e+08 | AD12: 604215368 | AE12: 57184862 | AF12: 1.0901153e+08 | AG12: 1.610605e+08 | AH12: 2.1636891e+08 | AI12: 2.7286321e+08 | AJ12: 3.295252e+08 | AK12: 3.8636711e+08 | AL12: 4.4470487e+08 | AM12: 5.033078e+08
A13: 2.2 | B13: Fees & Commission on Loan Portfolio | D13: =623888+686380 -> 1310268 | E13: 159000 | F13: 325200 | G13: 487520 | H13: 652760 | I13: 859280 | J13: 1075520 | K13: 1310840 | L13: 1497940 | M13: 1684060 | N13: 2055950 | O13: 2233300 | P13: 2369275 | Q13: =632405+807320 -> 1439725 | R13: 109640 | S13: 228440 | T13: 359670 | U13: 591930 | V13: 815140 | W13: 1014800 | X13: 1271340 | Y13: 1559390 | Z13: 1912170 | AA13: 2218220 | AB13: 2524425 | AC13: 2814925 | AD13: 4321085 | AE13: 323212 | AF13: 557833 | AG13: 757405 | AH13: 1046769.9 | AI13: 1685795.9 | AJ13: 2071654.9 | AK13: 2691021.9 | AL13: 3272984.9 | AM13: 3658862.9
A15: 3 | B15: Financial Income from Investments in: | C15: =SUM(C16:C19) -> 36891925 | D15: =SUM(D16:D19) -> 30847091 | E15: =SUM(E16:E19) -> 4184522.8 | F15: =SUM(F16:F19) -> 8151161.8 | G15: =SUM(G16:G19) -> 17065085 | H15: =SUM(H16:H19) -> 25123060 | I15: =SUM(I16:I19) -> 29461254 | J15: =SUM(J16:J19) -> 35734415 | ... AM15: =SUM(AM16:AM19) -> 56121755
A16: 3.1 | B16: Government Securities | E16: 0 | F16: 0 | G16: 0 | H16: 0 | I16: 0 | J16: 0 | K16: 0 | L16: 0 | M16: 0 | N16: 0 | O16: 0 | P16: 0 | Q16: 0 | R16: 0 | S16: 0 | T16: 0 | U16: 0 | V16: 0 | W16: 0 | X16: 0 | Y16: 0 | Z16: 0 | AA16: 0 | AB16: 0 | AC16: 0 | AE16: 0 | AF16: 0 | AG16: 0 | AH16: 0 | AI16: 0 | AJ16: 0 | AK16: 0 | AL16: 0 | AM16: 0
A17: 3.2 | B17: Deposit with Banks and Other Financial Inst. | D17: 1847945 | E17: 2313487.8 | F17: 4466199 | G17: 7996852.1 | H17: 10327842 | I17: 12705195 | J17: 16835800 | K17: 19703015 | L17: 22978218 | M17: 27369868 | N17: 30287364 | O17: 34581634 | P17: 39536285 | Q17: 39536285 | R17: 3830496 | S17: 7467142 | T17: 12648152 | U17: 16767890 | V17: 20594351 | W17: 26109146 | X17: 29332725 | Y17: 34755418 | Z17: 39925709 | AA17: 44993222 | AB17: 50452037 | AC17: 58222912 | AD17: 20710733 | AE17: 4713888.7 | AF17: 8477614.2 | AG17: 11434132 | AH17: 14390097 | AI17: 17250885 | AJ17: 23820783 | AK17: 26929809 | AL17: 30826875 | AM17: 35150698
A18: 3.3 | B18: Other Investments - dividend & Interest incomes from investments | C18: 10632970 | D18: =28332525-D17 -> 26484580 | E18: 0 | F18: 27184 | G18: 27184 | H18: 3372961.8 | I18: 3372961.8 | J18: 3372961.8 | K18: 3372961.8 | L18: 3372961.8 | M18: 3372961.8 | N18: 3372961.8 | O18: 3396038.8 | P18: 3396038.8 | Q18: 3396038.8 | R18: 0 | S18: 0 | T18: 0 | U18: 0 | V18: 4235.55 | W18: 3262781.6 | X18: 3262781.6 | Y18: 3262781.6 | Z18: 3262781.6 | AA18: 3262781.6 | AB18: 3262781.6 | AC18: 3262781.6 | AD18: 40919339 | AE18: 0 | AF18: 0 | AG18: 0 | AH18: 0 | AI18: 368940.2 | AJ18: 5196105.1 | AK18: 5196105.1 | AL18: 5196105.1 | AM18: 5196105.1
A19: 3.4 | B19: Other Operating Income- Salary processing fees, transaction fees, membership fees | C19: 26258955 | D19: =231000+2283566 -> 2514566 | E19: 1871035.1 | F19: 3657778.8 | G19: 9041049.2 | H19: 11422256 | I19: 13383097 | J19: 15525653 | K19: 17487653 | L19: 19295222 | M19: 21046279 | N19: 21491180 | O19: 22265404 | P19: 23986507 | Q19: =35354861-Q13 -> 33915136 | R19: 820632.5 | S19: 1443320.6 | T19: 6491927.8 | U19: 7272359.6 | V19: 7974078.5 | W19: 8598587.5 | X19: 9373727 | Y19: 10399177 | Z19: 11405424 | AA19: 11571854 | AB19: 11855540 | AC19: 14093229 | AD19: 19737892 | AE19: 859150.04 | AF19: 4397953.2 | AG19: 5948629.7 | AH19: 7617525.3 | AI19: 9550058.8 | AJ19: 11058713 | AK19: 12635291 | AL19: 14239519 | AM19: 15774952
A21: 4 | B21: Financial Expense | C21: =C22+C23+C24+C25+C27+C28 -> 231518407 | D21: =D22+D23+D24+D25+D27+D28 -> 250057522 | E21: =E22+E23+E24+E25+E27+E28 -> 371146.89 | F21: =F22+F23+F24+F25+F27+F28 -> 708714.3 | G21: =G22+G23+G24+G25+G27+G28 -> 1097316.7 | H21: =H22+H23+H24+H25+H27+H28 -> 1667225.9 | I21: =I22+I23+I24+I25+I27+I28 -> 2134765.5 | J21: =J22+J23+J24+J25+J27+J28 -> 2666458.6 | ... AM21: =AM22+AM23+AM24+AM25+AM27+AM28 -> 4191007
A22: 4.2 | B22: Interest Expense on Deposits | C22: =230548225-C23 -> 230056542 | D22: =249016415-D23 -> 248555614 | E22: 280810.11 | F22: 528301.52 | G22: 843653.96 | H22: 1270924 | I22: 1638682.7 | J22: 2082162.7 | K22: 2529478.1 | L22: 3022573.7 | M22: 3489817.6 | N22: 3558372.2 | O22: 4532916 | P22: 4627696.9 | Q22: =265744335+4627697 -> 270372032 | R22: 274903.99 | S22: 491705.86 | T22: 775934.99 | U22: 1094671.3 | V22: 1388269.2 | W22: 1698397.8 | X22: 2092799.2 | Y22: 2466811.7 | Z22: 2883068.3 | AA22: 3407930.2 | AB22: 3871139.8 | AC22: 4095359.3 | AD22: 286187291 | AE22: 318436.35 | AF22: 617732.25 | AG22: 929938.23 | AH22: 1295398.6 | AI22: 1602644.2 | AJ22: 1920649.5 | AK22: 2340548.9 | AL22: 2726433.5 | AM22: 3095137.2
A23: 4.3 | B23: Cost of External Borrowings | C23: 491683 | D23: 460801 | E23: 10360.78 | F23: 10360.78 | G23: 10360.78 | H23: 10360.78 | I23: 10360.78 | J23: 10360.78 | K23: 10360.78 | L23: 10360.78 | M23: 10360.76 | N23: 10360.78 | O23: 10360.78 | P23: 10360.78 | Q23: 10361 | R23: 0 | S23: 0 | T23: 0 | U23: 2.65 | V23: 2.65 | W23: 2.65 | X23: 2.65 | Y23: 2.65 | Z23: 2.65 | AA23: 2.65 | AB23: 2.65 | AC23: 2.65 | AE23: 0 | AF23: 0 | AG23: 0 | AH23: 0 | AI23: 0 | AJ23: 0 | AK23: 0 | AL23: 0 | AM23: 0
A24: 4.4 | B24: Dividend Expenses (on member shares) | E24: 0 | F24: 0 | G24: 0 | H24: 0 | I24: 0 | J24: 0 | K24: 0 | L24: 0 | M24: 0 | N24: 0 | O24: 0 | P24: 0 | R24: 0 | S24: 0 | T24: 0 | U24: 0 | V24: 0 | W24: 0 | X24: 0 | Y24: 0 | Z24: 0 | AA24: 0 | AB24: 0 | AC24: 0 | AE24: 0 | AF24: 0 | AG24: 0 | AH24: 0 | AI24: 0 | AJ24: 0 | AK24: 0 | AL24: 0 | AM24: 0
A25: 4.5 | B25: Other Financial Expense | C25: 970182 | D25: 1041107 | E25: 79976 | F25: 170052 | G25: 243302 | H25: 385941.16 | I25: 485722.01 | J25: 573935.12 | K25: 671944.84 | L25: 762946.84 | M25: 857736.54 | N25: 948906.64 | O25: 1041388.1 | P25: 1140134.6 | Q25: 1140135 | R25: 91040 | S25: 179773.19 | T25: 269366.75 | U25: 528360.06 | V25: 641237.12 | W25: 743507.06 | X25: 824449.48 | Y25: 955003.61 | Z25: 1053834.3 | AA25: 1140225.3 | AB25: 1255693.3 | AC25: 1359341.4 | AD25: 343381 | AE25: 112862.31 | AF25: 274273.36 | AG25: 417449.52 | AH25: 531537.14 | AI25: 679334.95 | AJ25: 730832.88 | AK25: 878207.13 | AL25: 992729.29 | AM25: 1095869.8
M26: 0 | N26: 0 | O26: 0 | P26: 0 | AK26: 0 | AL26: 0 | AM26: 0
A27: 4.6 | B27: Fees & Commission Expense | E27: 0 | F27: 0 | G27: 0 | H27: 0 | I27: 0 | J27: 0 | K27: 0 | L27: 0 | M27: 0 | N27: 0 | O27: 0 | P27: 0 | R27: 0 | S27: 0 | T27: 0 | U27: 0 | V27: 0 | W27: 0 | X27: 0 | Y27: 0 | Z27: 0 | AA27: 0 | AB27: 0 | AC27: 0 | AE27: 0 | AF27: 0 | AG27: 0 | AH27: 0 | AI27: 0 | AJ27: 0 | AK27: 0 | AL27: 0 | AM27: 0
A28: 4.7 | B28: Other Expense | E28: 0 | F28: 0 | G28: 0 | H28: 0 | I28: 0 | J28: 0 | K28: 0 | L28: 0 | R28: 0 | S28: 0 | T28: 0 | U28: 0 | V28: 0 | W28: 0 | X28: 0 | Y28: 0 | Z28: 0 | AA28: 0 | AB28: 0 | AC28: 0 | AE28: 0 | AF28: 0 | AG28: 0 | AH28: 0 | AI28: 0 | AJ28: 0 | AK28: 0 | AL28: 0 | AM28: 0
AK29: 0 | AL29: 0
A30: 5 | B30: Net Financial Income/(Loss) | C30: =C10-C21 -> 352321379 | D30: =D10-D21 -> 323288768 | E30: =E10-E21 -> 55930283 | F30: =F10-F21 -> 1.0500328e+08 | G30: =G10-G21 -> 1.6225123e+08 | H30: =H10-H21 -> 2.1707338e+08 | I30: =I10-I21 -> 2.6964216e+08 | J30: =J10-J21 -> 3.2603717e+08 | ... AM30: =AM10-AM21 -> 5.5889741e+08
A32: 6 | B32: Allowance for Loan Loss | C32: =C33-C34 -> 13900000 | D32: =D33-D34 -> 11087937 | E32: =E33-E34 -> 1031069.8 | F32: =F33-F34 -> 2054580.5 | G32: =G33-G34 -> 2937477.6 | H32: =H33-H34 -> 3870244 | I32: =I33-I34 -> 4791090.9 | J32: =J33-J34 -> 5735395.3 | ... AM32: =AM33-AM34 -> 20052170
A33: 6.1 | B33: Provision for Loan Losses | C33: 13900000 | D33: 11087937 | E33: 1031069.8 | F33: 2054580.5 | G33: 2937477.6 | H33: 3870244 | I33: 4791090.9 | J33: 5735395.3 | K33: 6868111.9 | L33: 7810675.3 | M33: 8858116.4 | N33: 9733116.4 | O33: 10608116 | P33: 11498290 | Q33: 10500000 | R33: 1007328.5 | S33: 2014656.9 | T33: 3004720 | U33: 4012048.5 | V33: 5311335.6 | W33: 6318664 | X33: 7321853.6 | Y33: 8329182.1 | Z33: 9387023.9 | AA33: 10394353 | AB33: 11401681 | AC33: 12431322 | AD33: 12087941 | AE33: 1125000 | AF33: 3250000 | AG33: 5351372.7 | AH33: 7476372.7 | AI33: 9601372.7 | AJ33: 11726373 | AK33: 13851373 | AL33: 16976373 | AM33: 20052170
A34: 6.2 | B34: Value of Loans Recovered | E34: 0 | F34: 0 | G34: 0 | H34: 0 | I34: 0 | J34: 0 | K34: 0 | L34: 0 | M34: 0 | N34: 0 | O34: 0 | P34: 0 | R34: 0 | S34: 0 | T34: 0 | U34: 0 | V34: 0 | W34: 0 | X34: 0 | Y34: 0 | Z34: 0 | AA34: 0 | AB34: 0 | AC34: 0 | AE34: 0 | AF34: 0 | AG34: 0 | AH34: 0 | AI34: 0 | AJ34: 0 | AK34: 0 | AL34: 0 | AM34: 0
A36: 7 | B36: Operating Expenses | C36: =SUM(C37:C41) -> 152589572 | D36: =SUM(D37:D41) -> 47651806 | E36: =SUM(E37:E41) -> 10083535 | F36: =SUM(F37:F41) -> 23677406 | G36: =SUM(G37:G41) -> 37665714 | H36: =SUM(H37:H41) -> 48278445 | I36: =SUM(I37:I41) -> 59127587 | J36: =SUM(J37:J41) -> 70749906 | ... AM36: =SUM(AM37:AM41) -> 1.6551404e+08
A37: 7.1 | B37: Personnel Expenses | C37: 83180130 | E37: 6846391.6 | F37: 14424663 | G37: 21709590 | H37: 28888748 | I37: 36073700 | J37: 43487031 | K37: 51028727 | L37: 58598129 | M37: 66461118 | N37: 73718746 | O37: 82063953 | P37: 92175301 | Q37: 92175300 | R37: 7169960.5 | S37: 14663465 | T37: 23897515 | U37: 31951664 | V37: 41742047 | W37: 51089482 | X37: 59562217 | Y37: 68033734 | Z37: 76952383 | AA37: 85642176 | AB37: 94222872 | AC37: 103868683 | AD37: 102435265 | AE37: 8863477.7 | AF37: 18676464 | AG37: 28270439 | AH37: 38031209 | AI37: 47783720 | AJ37: 57819211 | AK37: 68979877 | AL37: 80412524 | AM37: 90331972
A38: 7.2 | B38: Governance Expenses | C38: 18555496 | D38: 12796431 | E38: 646701.33 | F38: 2204133.7 | G38: 5913562.2 | H38: 6377784.9 | I38: 7063342 | J38: 8329283.4 | K38: 9508618 | L38: 11796616 | M38: 14284821 | N38: 17158719 | O38: 19116690 | P38: 20834461 | Q38: 20834461 | R38: 1129485.6 | S38: 5637386.6 | T38: 10774190 | U38: 12536117 | V38: 14891408 | W38: 16269016 | X38: 19300234 | Y38: 20402277 | Z38: 21071906 | AA38: 21785116 | AB38: 22808560 | AC38: 25394912 | AD38: 25394912 | AE38: 2104016.1 | AF38: 10610225 | AG38: 11786462 | AH38: 14318455 | AI38: 16097588 | AJ38: 18398959 | AK38: 20101372 | AL38: 24439315 | AM38: 26490226
A39: 7.3 | B39: Marketing Expenses | C39: 5623020 | D39: 2529990 | E39: 548488.64 | F39: 657591.71 | G39: 698626 | H39: 986608.04 | I39: 1541737.3 | J39: 1798050.4 | K39: 2410233.7 | L39: 3038618.6 | M39: 3329906.7 | N39: 3689657 | O39: 4040316.4 | P39: 4651814.2 | Q39: 4651814 | R39: 187971.33 | S39: 1539739.1 | T39: 2147698.4 | U39: 2955267 | V39: 3490436.9 | W39: 3892641.4 | X39: 5213628.7 | Y39: 5328923 | Z39: 5602869.2 | AA39: 5866759.2 | AB39: 6041715.6 | AC39: 6086438.2 | AD39: 6086438 | AE39: 159256.74 | AF39: 684029.03 | AG39: 1392510.9 | AH39: 2182705.8 | AI39: 3365323.1 | AJ39: 3962980.6 | AK39: 4709549.7 | AL39: 5782813.7 | AM39: 6389502.6
A40: 7.4 | B40: Depreciation and Amortization Charges | C40: 5000262 | D40: 4189816 | E40: 219508.47 | F40: 219508.47 | G40: 681804.73 | H40: 924592.52 | I40: 1167380.3 | J40: 1444691.9 | K40: 1739536.6 | L40: 2056159.1 | M40: 2372781.6 | N40: 2689404.2 | O40: 8006140.9 | P40: 8764703.8 | Q40: 8779256 | R40: 674770.05 | S40: 1553736.6 | T40: 2431866.3 | U40: 3309996.1 | V40: 4240149.3 | W40: 5148076.5 | X40: 6104861 | Y40: 7061645.2 | Z40: 7836454.7 | AA40: 8975214.1 | AB40: 9931998.5 | AC40: 10888783 | AD40: 10125136 | AE40: 807649.38 | AF40: 1611630.8 | AG40: 2420205.2 | AH40: 3297612.5 | AI40: 4175403.3 | AJ40: 5069078.3 | AK40: 5973538.2 | AL40: 6877998 | AM40: 7734732.3
A41: 7.5 | B41: Administrative Expenses | C41: 40230664 | D41: 28135569 | E41: 1822445.1 | F41: 6171509.7 | G41: 8662131.3 | H41: 11100712 | I41: 13281427 | J41: 15690849 | K41: 17968775 | L41: 21033092 | M41: 24030397 | N41: 26630758 | O41: 29521440 | P41: 32117371 | Q41: 33117199 | R41: 4824993 | S41: 7495181.5 | T41: 10408211 | U41: 13741543 | V41: 16724754 | W41: 19378454 | X41: 22497419 | Y41: 25333935 | Z41: 27842486 | AA41: 30166756 | AB41: 32425454 | AC41: 28369626 | AD41: 36813206 | AE41: 4487720.4 | AF41: 7780215.2 | AG41: 10489137 | AH41: 14914596 | AI41: 18705860 | AJ41: 22640415 | AK41: 26535600 | AL41: 30567262 | AM41: 34567603
A43: 8 | B43: Net Operating Income | C43: =C30-C32-C36 -> 185831807 | D43: =D30-D32-D36 -> 264549025 | E43: =E30-E32-E36 -> 44815678 | F43: =F30-F32-F36 -> 79271298 | G43: =G30-G32-G36 -> 1.2164804e+08 | H43: =H30-H32-H36 -> 1.6492469e+08 | I43: =I30-I32-I36 -> 2.0572348e+08 | J43: =J30-J32-J36 -> 2.4955187e+08 | ... AM43: =AM30-AM32-AM36 -> 3.7333121e+08
A45: 9 | B45: Net Non- Operating Income/ (Expense) | C45: =C46-C47 -> 0 | D45: =D46-D47 -> 0 | E45: =E46-E47 -> 0 | F45: =F46-F47 -> 0 | G45: =G46-G47 -> 0 | H45: =H46-H47 -> 0 | I45: =I46-I47 -> 0 | J45: =J46-J47 -> 0 | ... AM45: =AM46-AM47 -> 0
A46: 9.1 | B46: Non- Operating Income | C46: 0 | E46: 0 | F46: 0 | G46: 0 | H46: 0 | I46: 0 | J46: 0 | K46: 0 | L46: 0 | R46: 0 | S46: 0 | T46: 0 | U46: 0 | V46: 0 | W46: 0 | X46: 0 | Y46: 0 | Z46: 0 | AA46: 0 | AB46: 0 | AC46: 0 | AE46: 0 | AF46: 0 | AG46: 0 | AH46: 0 | AI46: 0 | AJ46: 0 | AK46: 0 | AL46: 0 | AM46: 0
A47: 9.2 | B47: Non- Operating Expense | C47: 0 | E47: 0 | F47: 0 | G47: 0 | H47: 0 | I47: 0 | J47: 0 | K47: 0 | L47: 0 | R47: 0 | S47: 0 | T47: 0 | U47: 0 | V47: 0 | W47: 0 | X47: 0 | Y47: 0 | Z47: 0 | AA47: 0 | AB47: 0 | AC47: 0 | AE47: 0 | AF47: 0 | AG47: 0 | AH47: 0 | AI47: 0 | AJ47: 0 | AK47: 0 | AL47: 0 | AM47: 0
A49: 10 | B49: Net Income (Before Taxes and Donations) | C49: =C43+C45 -> 185831807 | D49: =D43+D45 -> 264549025 | E49: =E43+E45 -> 44815678 | F49: =F43+F45 -> 79271298 | G49: =G43+G45 -> 1.2164804e+08 | H49: =H43+H45 -> 1.6492469e+08 | I49: =I43+I45 -> 2.0572348e+08 | J49: =J43+J45 -> 2.4955187e+08 | ... AM49: =AM43+AM45 -> 3.7333121e+08
...

Sheet SFP
B1: FORM 6 SASRA2/006
B2: STATEMENT OF FINANCIAL POSITION
B3: NAME OF SACCO SOCIETY: NYATI
B4: FINANCIAL YEAR : 2020
B5: START DATE: 1st September 2020
B6: END DATE: 31st December 2020
C7: Audited 2019 | D7: Audited 2020 | E7: 44197 | F7: 44228 | G7: 44256 | H7: 44287 | I7: 44317 | J7: 44348 | K7: 44378 | L7: 44409 | M7: 44440 | N7: 44470 | O7: 44501 | P7: 44531 | Q7: Audited 2021 | R7: 44562 | S7: 44593 | T7: 44621 | U7: 44652 | V7: 44682 | W7: 44713 | X7: 44743 | Y7: 44774 | Z7: 44805 | AA7: 44835 | AB7: 44866 | AC7: 44896 | AD7: AUDITED 2022 | AE7: 44927 | AF7: 44958 | AG7: 44986 | AH7: 45017 | AI7: 45047 | AJ7: 45078 | AK7: 45108 | AL7: 45139 | AM7: 45170
A9: Ref No | B9: ASSETS
A10: 1 | B10: Cash & Cash Equivalent | C10: =SUM(C11:C12) -> 168189222 | D10: =SUM(D11:D12) -> 457470051 | E10: =SUM(E11:E12) -> 4.3611838e+08 | F10: =SUM(F11:F12) -> 4.7844639e+08 | G10: =SUM(G11:G12) -> 3.9915184e+08 | H10: =SUM(H11:H12) -> 4.4246907e+08 | I10: =SUM(I11:I12) -> 4.7894901e+08 | J10: =SUM(J11:J12) -> 5.1357098e+08 | ... AM10: =SUM(AM11:AM12) -> 4.0127472e+08
A11: 1.1 | B11: Cash in hand(both local and foreign notes and coins) | C11: =3153311+46452+434972 -> 3634735 | D11: =2007+3731074+507727+329438 -> 4570246 | E11: 4423951 | F11: 5063149 | G11: 4408024 | H11: 5304447 | I11: 4189067 | J11: 3220369 | K11: 1726702 | L11: 4702649 | M11: 4942494 | N11: 4055560 | O11: 5910676.1 | P11: 4594916.1 | Q11: =3269890+534218+783008+7800 -> 4594916 | R11: 4423951 | S11: 5063149 | T11: 4408024 | U11: 5304447 | V11: 4189067 | W11: 3220369 | X11: 1726702 | Y11: 4702649 | Z11: 4942494 | AA11: 4055560 | AB11: 5910676.1 | AC11: 4594916.1 | AD11: 5502805 | AE11: 5695777 | AF11: 3454668 | AG11: 5212225 | AH11: 3876780 | AI11: 4332882 | AJ11: 2792957 | AK11: 4486250 | AL11: 5335599 | AM11: 3140201
A12: 1.2 | B12: Cash at bank:(placement with financial institutions) | C12: =168189222-C11 -> 164554487 | D12: =457470051-D11 -> 452899805 | E12: 4.3169443e+08 | F12: 4.7338324e+08 | G12: 3.9474381e+08 | H12: 4.3716462e+08 | I12: 4.7475994e+08 | J12: 5.1035061e+08 | K12: 4.8935e+08 | L12: 5.2957517e+08 | M12: 5.8322386e+08 | N12: 6.1696513e+08 | O12: 6.6282067e+08 | P12: 6.5545719e+08 | Q12: =672245671-4594916 -> 667650755 | R12: 4.3169443e+08 | S12: 4.7338324e+08 | T12: 3.9474381e+08 | U12: 4.3716462e+08 | V12: 4.7475994e+08 | W12: 5.1035061e+08 | X12: 4.8935e+08 | Y12: 5.2957517e+08 | Z12: 5.8322386e+08 | AA12: 6.1696513e+08 | AB12: 6.6282067e+08 | AC12: 6.5545719e+08 | AD12: 754991268 | AE12: 6.6850363e+08 | AF12: 5.1779022e+08 | AG12: 4.8527553e+08 | AH12: 4.5063578e+08 | AI12: 4.3248231e+08 | AJ12: 4.5886574e+08 | AK12: 4.5370795e+08 | AL12: 4.2108514e+08 | AM12: 3.9813452e+08
AK13: 0 | AL13: 0 | AM13: 0
A14: 2 | B14: Prepayments & Sundry Receivables | C14: 171980576 | D14: 176986761 | E14: 1.7519314e+08 | F14: 1.7401118e+08 | G14: 1.6862993e+08 | H14: 1.7175466e+08 | I14: 1.7234581e+08 | J14: 1.7264142e+08 | K14: 1.7911947e+08 | L14: 1.7904676e+08 | M14: 1.7865398e+08 | N14: 1.9580112e+08 | O14: 2.0301798e+08 | P14: 1.9189331e+08 | Q14: 188056264 | R14: 1.7519314e+08 | S14: 1.7401118e+08 | T14: 1.6862993e+08 | U14: 1.7175466e+08 | V14: 1.7234581e+08 | W14: 1.7264142e+08 | X14: 1.7911947e+08 | Y14: 1.7904676e+08 | Z14: 1.7865398e+08 | AA14: 1.9580112e+08 | AB14: 2.0301798e+08 | AC14: 1.9189331e+08 | AD14: 189228990 | AE14: 1.8517305e+08 | AF14: 1.7408137e+08 | AG14: 1.6925281e+08 | AH14: 1.7918614e+08 | AI14: 1.6866657e+08 | AJ14: 1.6553603e+08 | AK14: 1.6667795e+08 | AL14: 1.5984723e+08 | AM14: 1.6186952e+08
A16: 3 | B16: Financial Investments | C16: =SUM(C17:C20) -> 18661431 | D16: =SUM(D17:D20) -> 89875374 | E16: =SUM(E17:E20) -> 99665690 | F16: =SUM(F17:F20) -> 99911642 | G16: =SUM(G17:G20) -> 1.0011164e+08 | H16: =SUM(H17:H20) -> 1.0036082e+08 | I16: =SUM(I17:I20) -> 1.0056082e+08 | J16: =SUM(J17:J20) -> 1.0076082e+08 | ... AM16: =SUM(AM17:AM20) -> 1.4017462e+08
A17: 3.1 | B17: Government Securities - Treasury Bills/bonds, | E17: 0 | F17: 0 | G17: 0 | H17: 0 | I17: 0 | J17: 0 | K17: 0 | L17: 0 | M17: 0 | N17: 0 | O17: 0 | P17: 0 | Q17: 0 | R17: 0 | S17: 0 | T17: 0 | U17: 0 | V17: 0 | W17: 0 | X17: 0 | Y17: 0 | Z17: 0 | AA17: 0 | AB17: 0 | AC17: 0 | AE17: 0 | AF17: 0 | AG17: 0 | AH17: 0 | AI17: 0 | AJ17: 20000000 | AK17: 40000000 | AL17: 80000000 | AM17: 100000000
A18: 3.2 | B18: Other Securities - Commercial papers/Bonds | E18: 0 | F18: 0 | G18: 0 | H18: 0 | I18: 0 | J18: 0 | K18: 0 | L18: 0 | M18: 0 | N18: 0 | O18: 0 | P18: 0 | Q18: 0 | R18: 0 | S18: 0 | T18: 0 | U18: 0 | V18: 0 | W18: 0 | X18: 0 | Y18: 0 | Z18: 0 | AA18: 0 | AB18: 0 | AC18: 0 | AE18: 0 | AF18: 0 | AG18: 0 | AH18: 0 | AI18: 0 | AJ18: 0 | AK18: 0 | AL18: 0 | AM18: 0
A19: 3.3a | B19: Balances with other SACCO Societies | C19: =650003+3057180+2944248 -> 6651431 | D19: =650003+10000+3057180+2944248 -> 6661431 | E19: 9790316.5 | F19: 10036268 | G19: 10236268 | H19: 10485449 | I19: 10685449 | J19: 10885449 | K19: 11137877 | L19: 11337877 | M19: 11537877 | N19: 11737877 | O19: 11993566 | P19: 12193566 | Q19: =89890374-83228943 -> 6661431 | R19: 9790316.5 | S19: 10036268 | T19: 10236268 | U19: 10485449 | V19: 10685449 | W19: 10885449 | X19: 11137877 | Y19: 11337877 | Z19: 11537877 | AA19: 11737877 | AB19: 11993566 | AC19: 12193566 | AE19: 1121518.9 | AF19: 1321518.9 | AG19: 1521518.9 | AH19: 1723938.7 | AI19: 1923938.7 | AJ19: 2123938.7 | AK19: 2323938.7 | AL19: 2523938.7 | AM19: 2728248.6
A20: 3.3b | B20: Investments in companies - shares/stocks | C20: =10000+12000000 -> 12010000 | D20: 83213943 | E20: 89875374 | F20: 89875374 | G20: 89875374 | H20: 89875374 | I20: 89875374 | J20: 89875374 | K20: 89875374 | L20: 89875374 | M20: 89875374 | N20: 89875374 | O20: 89890374 | P20: 89890374 | Q20: 83228943 | R20: 89875374 | S20: 89875374 | T20: 89875374 | U20: 89875374 | V20: 89875374 | W20: 89875374 | X20: 89875374 | Y20: 89875374 | Z20: 89875374 | AA20: 89875374 | AB20: 89890374 | AC20: 89890374 | AD20: 37451038 | AE20: 37451038 | AF20: 37451038 | AG20: 37451038 | AH20: 37451038 | AI20: 37451038 | AJ20: 37446375 | AK20: 37446375 | AL20: 37446375 | AM20: 37446375
A22: 4 | B22: Net Loan Portfolio | C22: =C23-C24 -> 2994823414 | D22: =D23-D24 -> 3054612195 | E22: =E23-E24 -> 3.1229879e+09 | F22: =F23-F24 -> 3.1272368e+09 | G22: =G23-G24 -> 3.0371914e+09 | H22: =H23-H24 -> 3.0442169e+09 | I22: =I23-I24 -> 3.0658165e+09 | J22: =J23-J24 -> 3.1049186e+09 | ... AM22: =AM23-AM24 -> 3.6217876e+09
B23: Gross Loan Portfolio | C23: 3077148048 | D23: 3148024766 | E23: 3.2172755e+09 | F23: 3.2223994e+09 | G23: 3.133229e+09 | H23: 3.1411294e+09 | I23: 3.1636041e+09 | J23: 3.2035811e+09 | K23: 3.259149e+09 | L23: 3.2701667e+09 | M23: 3.281813e+09 | N23: 3.2917928e+09 | O23: 3.275913e+09 | P23: 3.2295605e+09 | Q23: =2941055936+179644514+113556259-4694744 -> 3229561965 | R23: 3.2172755e+09 | S23: 3.2223994e+09 | T23: 3.133229e+09 | U23: 3.1411294e+09 | V23: 3.1636041e+09 | W23: 3.2035811e+09 | X23: 3.259149e+09 | Y23: 3.2701667e+09 | Z23: 3.281813e+09 | AA23: 3.2917928e+09 | AB23: 3.275913e+09 | AC23: 3.2295605e+09 | AD23: 3526498770 | AE23: 3.5988765e+09 | AF23: 3.5259068e+09 | AG23: 3.5391007e+09 | AH23: 3.586282e+09 | AI23: 3.6357761e+09 | AJ23: 3.6595156e+09 | AK23: 3.6798135e+09 | AL23: 3.7301391e+09 | AM23: 3757913092
B24: Allowance for Loan Loss | C24: 82324634 | D24: 93412571 | E24: 94287571 | F24: 95162571 | G24: 96037571 | H24: 96912571 | I24: 97787571 | J24: 98662571 | K24: 99537571 | L24: 1.0041257e+08 | M24: 1.0128757e+08 | N24: 1.0216257e+08 | O24: 1.0303757e+08 | P24: 1.0391257e+08 | Q24: 103912571 | R24: 94287571 | S24: 95162571 | T24: 96037571 | U24: 96912571 | V24: 97787571 | W24: 98662571 | X24: 99537571 | Y24: 1.0041257e+08 | Z24: 1.0128757e+08 | AA24: 1.0216257e+08 | AB24: 1.0303757e+08 | AC24: 1.0391257e+08 | AD24: 116000512 | AE24: 1.1712551e+08 | AF24: 1.1925051e+08 | AG24: 1.2137551e+08 | AH24: 1.2350051e+08 | AI24: 1.2562551e+08 | AJ24: 1.2775051e+08 | AK24: 1.2987551e+08 | AL24: 1.3300051e+08 | AM24: 1.3612551e+08
A26: 5 | B26: Accounts Receivables | C26: =SUM(C27:C29) -> 0 | D26: =SUM(D27:D29) -> 0 | E26: =SUM(E27:E29) -> 0 | F26: =SUM(F27:F29) -> 0 | G26: =SUM(G27:G29) -> 0 | H26: =SUM(H27:H29) -> 0 | I26: =SUM(I27:I29) -> 0 | J26: =SUM(J27:J29) -> 0 | ... AM26: =SUM(AM27:AM29) -> 0
A27: 5.1 | B27: Tax Recoverable | E27: 0 | F27: 0 | G27: 0 | H27: 0 | I27: 0 | J27: 0 | K27: 0 | L27: 0 | M27: 0 | N27: 0 | O27: 0 | P27: 0 | Q27: 0 | R27: 0 | S27: 0 | T27: 0 | U27: 0 | V27: 0 | W27: 0 | X27: 0 | Y27: 0 | Z27: 0 | AA27: 0 | AB27: 0 | AC27: 0 | AE27: 0 | AF27: 0 | AG27: 0 | AH27: 0 | AI27: 0 | AJ27: 0 | AK27: 0 | AL27: 0 | AM27: 0
A28: 5.2 | B28: Deferred Tax Assets | E28: 0 | F28: 0 | G28: 0 | H28: 0 | I28: 0 | J28: 0 | K28: 0 | L28: 0 | M28: 0 | N28: 0 | O28: 0 | P28: 0 | Q28: 0 | R28: 0 | S28: 0 | T28: 0 | U28: 0 | V28: 0 | W28: 0 | X28: 0 | Y28: 0 | Z28: 0 | AA28: 0 | AB28: 0 | AC28: 0 | AE28: 0 | AF28: 0 | AG28: 0 | AH28: 0 | AI28: 0 | AJ28: 0 | AK28: 0 | AL28: 0 | AM28: 0
A29: 5.3 | B29: Retirement Benefit Assets | E29: 0 | F29: 0 | G29: 0 | H29: 0 | I29: 0 | J29: 0 | K29: 0 | L29: 0 | M29: 0 | N29: 0 | O29: 0 | P29: 0 | Q29: 0 | R29: 0 | S29: 0 | T29: 0 | U29: 0 | V29: 0 | W29: 0 | X29: 0 | Y29: 0 | Z29: 0 | AA29: 0 | AB29: 0 | AC29: 0 | AE29: 0 | AF29: 0 | AG29: 0 | AH29: 0 | AI29: 0 | AJ29: 0 | AK29: 0 | AL29: 0 | AM29: 0
A31: 6 | B31: Property & Equipment & Other assets | C31: =SUM(C32:C36) -> 12210244 | D31: =SUM(D32:D36) -> 9860927 | E31: =SUM(E32:E36) -> 9641418.8 | F31: =SUM(F32:F36) -> 9641418.8 | G31: =SUM(G32:G36) -> 10138851 | H31: =SUM(H32:H36) -> 9896062.8 | I31: =SUM(I32:I36) -> 9653275 | J31: =SUM(J32:J36) -> 10100963 | ... AM31: =SUM(AM32:AM36) -> 4.9197922e+08
A32: 6.1 | B32: Investment Properties | E32: 0 | F32: 0 | G32: 0 | H32: 0 | I32: 0 | J32: 0 | K32: 0 | L32: 0 | M32: 0 | N32: 0 | O32: 0 | P32: 0 | Q32: 0 | R32: 0 | S32: 0 | T32: 0 | U32: 0 | V32: 0 | W32: 0 | X32: 0 | Y32: 0 | Z32: 0 | AA32: 0 | AB32: 0 | AC32: 0 | AD32: 67876651 | AE32: 0 | AF32: 0 | AG32: 0 | AH32: 0 | AI32: 0 | AJ32: 0 | AK32: 0 | AL32: 0 | AM32: 0
A33: 6.2 | B33: Property & Equipment | C33: 11105461 | D33: 9128450 | E33: 8940448.7 | F33: 8940448.7 | G33: 9500901.9 | H33: 9289624.9 | I33: 9078347.8 | J33: 8867070.7 | K33: 8861914.7 | L33: 8637243 | M33: 8414949.4 | N33: 8414949.4 | O33: 8414949.4 | P33: 9397647 | Q33: 9397653 | R33: 8940448.7 | S33: 8940448.7 | T33: 9500901.9 | U33: 9289624.9 | V33: 9078347.8 | W33: 8867070.7 | X33: 8861914.7 | Y33: 8637243 | Z33: 8414949.4 | AA33: 8414949.4 | AB33: 8414949.4 | AC33: 9397647 | AD33: 8007060 | AE33: 1.4538007e+08 | AF33: 2.0103567e+08 | AG33: 2.3855423e+08 | AH33: 2.4210724e+08 | AI33: 3.0062192e+08 | AJ33: 3.0746253e+08 | AK33: 3.3709625e+08 | AL33: 3.6163822e+08 | AM33: 4.0853633e+08
A34: 6.3 | B34: Prepaid Lease rentals | E34: 0 | F34: 0 | G34: 0 | H34: 0 | I34: 0 | J34: 0 | K34: 0 | L34: 0 | M34: 0 | N34: 0 | O34: 0 | P34: 0 | R34: 0 | S34: 0 | T34: 0 | U34: 0 | V34: 0 | W34: 0 | X34: 0 | Y34: 0 | Z34: 0 | AA34: 0 | AB34: 0 | AC34: 0 | AE34: 67679511 | AF34: 67482372 | AG34: 67285232 | AH34: 67088093 | AI34: 66890953 | AJ34: 66693814 | AK34: 66496674 | AL34: 66299535 | AM34: 66102395
A35: 6.4 | B35: Intangible Assets | C35: 1104783 | D35: 732477 | E35: 700970.09 | F35: 700970.09 | G35: 637948.62 | H35: 606437.89 | I35: 574927.15 | J35: 1233892.6 | K35: 1277413.6 | L35: 1510834.6 | M35: 1416505.6 | N35: 1416505.6 | O35: 1416505.6 | P35: 24911187 | Q35: 24894054 | R35: 700970.09 | S35: 700970.09 | T35: 637948.62 | U35: 606437.89 | V35: 574927.15 | W35: 1233892.6 | X35: 1277413.6 | Y35: 1510834.6 | Z35: 1416505.6 | AA35: 1416505.6 | AB35: 1416505.6 | AC35: 24911187 | AD35: 21095480 | AE35: 20638718 | AF35: 20181952 | AG35: 19725187 | AH35: 19268422 | AI35: 18811656 | AJ35: 18354891 | AK35: 18275593 | AL35: 17808043 | AM35: 17340492
A36: 6.5 | B36: Other Assets | E36: 0 | F36: 0 | G36: 0 | H36: 0 | I36: 0 | J36: 0 | K36: 0 | L36: 2000 | M36: 0 | N36: 0 | O36: 0 | P36: 0 | R36: 0 | S36: 0 | T36: 0 | U36: 0 | V36: 0 | W36: 0 | X36: 0 | Y36: 2000 | Z36: 0 | AA36: 0 | AB36: 0 | AC36: 0 | AD36: 80826019 | AE36: 0 | AF36: 0 | AG36: 0 | AH36: 0 | AI36: 0 | AJ36: 0 | AK36: 0 | AL36: 0 | AM36: 0
B38: Total Assets | C38: =C10+C14+C16+C22+C26+C31 -> 3365864887 | D38: =D10+D14+D16+D22+D26+D31 -> 3788805308 | E38: =E10+E14+E16+E22+E26+E31 -> 3.8436065e+09 | F38: =F10+F14+F16+F22+F26+F31 -> 3.8892475e+09 | G38: =G10+G14+G16+G22+G26+G31 -> 3.7152236e+09 | H38: =H10+H14+H16+H22+H26+H31 -> 3.7686975e+09 | I38: =I10+I14+I16+I22+I26+I31 -> 3.8273255e+09 | J38: =J10+J14+J16+J22+J26+J31 -> 3.9019927e+09 | ... AM38: =AM10+AM14+AM16+AM22+AM26+AM31 -> 4.8170857e+09
B41: LIABILITIES
A42: 7 | B42: Savings Deposits - Withdrawable deposits - FOSA) | C42: 5510696 | D42: 6007705 | E42: 1.154031e+08 | F42: 1.136483e+08 | G42: 1.5531012e+08 | H42: 1.5066709e+08 | I42: 1.4619049e+08 | J42: 1.6364768e+08 | K42: 1.6292924e+08 | L42: 1.5527696e+08 | M42: 1.5527696e+08 | N42: 1.5880856e+08 | O42: 1.630063e+08 | P42: 1.0319614e+08 | Q42: 4928808 | R42: 1.154031e+08 | S42: 1.136483e+08 | T42: 1.5531012e+08 | U42: 1.5066709e+08 | V42: 1.4619049e+08 | W42: 1.6364768e+08 | X42: 1.6292924e+08 | Y42: 1.5527696e+08 | Z42: 1.5527696e+08 | AA42: 1.5880856e+08 | AB42: 1.630063e+08 | AC42: 1.0319614e+08 | AD42: 4878059 | AE42: 1.4688154e+08 | AF42: 2.0947862e+08 | AG42: 1.6070881e+08 | AH42: 1.5875844e+08 | AI42: 1.5372909e+08 | AJ42: 1.6392377e+08 | AK42: 1.6421058e+08 | AL42: 1.6203956e+08 | AM42: 1.6357974e+08
A43: 8 | B43: Short Term Deposits (e.g Fixed deposits, special savings) | C43: 106886071 | D43: 113281794 | E43: 0 | F43: 0 | G43: 0 | H43: 0 | I43: 0 | J43: 0 | K43: 0 | L43: 0 | M43: 0 | N43: 0 | O43: 0 | P43: 0 | Q43: 98250768 | R43: 0 | S43: 0 | T43: 0 | U43: 0 | V43: 0 | W43: 0 | X43: 0 | Y43: 0 | Z43: 0 | AA43: 0 | AB43: 0 | AC43: 0 | AD43: 142375969 | AE43: 0 | AF43: 0 | AG43: 0 | AH43: 0 | AI43: 0 | AJ43: 0 | AK43: 0 | AL43: 0 | AM43: 0
A44: 9 | B44: Non withdrawable deposits (BOSA member deposits) | C44: 2088840718 | D44: 2273006691 | E44: 2.2867172e+09 | F44: 2.2989133e+09 | G44: 2.3207206e+09 | H44: 2.3381251e+09 | I44: 2.3576807e+09 | J44: 2.3704595e+09 | K44: 2.3857547e+09 | L44: 2.4023048e+09 | M44: 2.4023048e+09 | N44: 2.4340451e+09 | O44: 2.4220238e+09 | P44: 2.4090308e+09 | Q44: 2409040533 | R44: 2.2867172e+09 | S44: 2.2989133e+09 | T44: 2.3207206e+09 | U44: 2.3381251e+09 | V44: 2.3576807e+09 | W44: 2.3704595e+09 | X44: 2.3857547e+09 | Y44: 2.4023048e+09 | Z44: 2.4023048e+09 | AA44: 2.4340451e+09 | AB44: 2.4220238e+09 | AC44: 2.4090308e+09 | AD44: 2623653589 | AE44: 2.6427236e+09 | AF44: 2.6625626e+09 | AG44: 2.6767288e+09 | AH44: 2.6845891e+09 | AI44: 2.6879901e+09 | AJ44: 2.6944614e+09 | AK44: 2.7052498e+09 | AL44: 2.7302015e+09 | AM44: 2.7504297e+09
B45: Total Deposit liabilities | C45: =SUM(C42:C44) -> 2201237485 | D45: =SUM(D42:D44) -> 2392296190 | E45: =SUM(E42:E44) -> 2.4021203e+09 | F45: =SUM(F42:F44) -> 2412561600 | G45: =SUM(G42:G44) -> 2.4760307e+09 | H45: =SUM(H42:H44) -> 2.4887922e+09 | I45: =SUM(I42:I44) -> 2.5038712e+09 | J45: =SUM(J42:J44) -> 2.5341072e+09 | ... AM45: =SUM(AM42:AM44) -> 2.9140095e+09
A47: 10 | B47: Accounts Payable & Other Liabilities | C47: =SUM(C48:C53) -> 337371662 | D47: =SUM(D48:D53) -> 356920447 | E47: =SUM(E48:E53) -> 3.5494421e+08 | F47: =SUM(F48:F53) -> 3.5322859e+08 | G47: =SUM(G48:G53) -> 71248579 | H47: =SUM(H48:H53) -> 66325840 | I47: =SUM(I48:I53) -> 67149579 | J47: =SUM(J48:J53) -> 65117426 | ... AM47: =SUM(AM48:AM53) -> 70010258
A48: 10.1 | B48: Tax Payable | C48: 1973453 | D48: -2319597 | E48: -3234.69 | F48: 14085168 | G48: -84173.81 | H48: 53570.79 | I48: 274.79 | J48: 1664.59 | K48: 173633.59 | L48: -14075.41 | M48: -14075.41 | N48: -27622.11 | O48: 265486.89 | P48: 710579.21 | Q48: 2040497 | R48: -3234.69 | S48: 14085168 | T48: -84173.81 | U48: 53570.79 | V48: 274.79 | W48: 1664.59 | X48: 173633.59 | Y48: -14075.41 | Z48: -14075.41 | AA48: -27622.11 | AB48: 265486.89 | AC48: 710579.21 | AD48: 1240355 | AE48: -112592.32 | AF48: 16538217 | AG48: -210198.52 | AH48: -153270.51 | AI48: -152025.82 | AJ48: -167604.54 | AK48: -193032.3 | AL48: -231677.97 | AM48: -176567.11
A49: 10.2 | B49: Dividends Payable | C49: 290486550 | D49: 291400006 | E49: 2.8243559e+08 | F49: 2.6831375e+08 | G49: 11888476 | H49: 10724539 | I49: 9922446.9 | J49: 9286694.2 | K49: 8895932 | L49: 8766023.1 | M49: 8766023.1 | N49: 8581055.3 | O49: 8521252.7 | P49: -1043.72 | Q49: 265746194 | R49: 2.8243559e+08 | S49: 2.6831375e+08 | T49: 11888476 | U49: 10724539 | V49: 9922446.9 | W49: 9286694.2 | X49: 8895932 | Y49: 8766023.1 | Z49: 8766023.1 | AA49: 8581055.3 | AB49: 8521252.7 | AC49: -1043.72 | AD49: 35402799 | AE49: 3.3375581e+08 | AF49: 29739178 | AG49: 19325547 | AH49: 18420976 | AI49: 17762437 | AJ49: 17462445 | AK49: 17195748 | AL49: 17001281 | AM49: 16741439
...

Sheet FINANCIALS
B1: NYATI SACCO
B2: Year | C2: 44166 | D2: Audited 2020 | E2: 44197 | F2: 44228 | G2: 44256 | H2: 44287 | I2: 44317 | J2: 44348 | K2: 44378 | L2: 44409 | M2: 44440 | N2: 44470 | O2: 44501 | P2: 44531 | Q2: Audited 2022 | R2: 44562 | S2: 44593 | T2: 44621 | U2: 44652 | V2: 44682 | W2: 44713 | X2: 44743 | Y2: 44774 | Z2: 44805 | AA2: 44835 | AB2: 44866 | AC2: 44896 | AD2: AUDITED 2022 | AE2: 44927 | AF2: 44958 | AG2: 44986 | AH2: 45017 | AI2: 45047 | AJ2: 45078 | AK2: 45108 | AL2: 45139 | AM2: 45170
A3: 1 | B3: Membership
A4: 2 | B4: Total Assets | C4: =SFP!C38 -> 3365864887 | D4: =SFP!D38 -> 3788805308 | E4: =SFP!E38 -> 3.8436065e+09 | F4: =SFP!F38 -> 3.8892475e+09 | G4: =SFP!G38 -> 3.7152236e+09 | H4: =SFP!H38 -> 3.7686975e+09 | I4: =SFP!I38 -> 3.8273255e+09 | J4: =SFP!J38 -> 3.9019927e+09 | ... AM4: =SFP!AM38 -> 4.8170857e+09
A5: 3 | B5: Total Deposits | C5: =SFP!C45 -> 2201237485 | D5: =SFP!D45 -> 2392296190 | E5: =SFP!E45 -> 2.4021203e+09 | F5: =SFP!F45 -> 2412561600 | G5: =SFP!G45 -> 2.4760307e+09 | H5: =SFP!H45 -> 2.4887922e+09 | I5: =SFP!I45 -> 2.5038712e+09 | J5: =SFP!J45 -> 2.5341072e+09 | ... AM5: =SFP!AM45 -> 2.9140095e+09
A6: 3.1 | B6: Deposits-Members(BOSA) | C6: =SFP!C44 -> 2088840718 | D6: =SFP!D44 -> 2273006691 | E6: =SFP!E44 -> 2.2867172e+09 | F6: =SFP!F44 -> 2.2989133e+09 | G6: =SFP!G44 -> 2.3207206e+09 | H6: =SFP!H44 -> 2.3381251e+09 | I6: =SFP!I44 -> 2.3576807e+09 | J6: =SFP!J44 -> 2.3704595e+09 | ... AM6: =SFP!AM44 -> 2.7504297e+09
A7: 3.2 | B7: Deposits-Customers(FOSA) | C7: =SFP!C42+SFP!C43 -> 112396767 | D7: =SFP!D42+SFP!D43 -> 119289499 | E7: =SFP!E42+SFP!E43 -> 1.154031e+08 | F7: =SFP!F42+SFP!F43 -> 1.136483e+08 | G7: =SFP!G42+SFP!G43 -> 1.5531012e+08 | H7: =SFP!H42+SFP!H43 -> 1.5066709e+08 | I7: =SFP!I42+SFP!I43 -> 1.4619049e+08 | J7: =SFP!J42+SFP!J43 -> 1.6364768e+08 | ... AM7: =SFP!AM42+SFP!AM43 -> 1.6357974e+08
A8: 4 | B8: External Borrowing | C8: =SFP!C53 -> 0 | D8: =SFP!D53 -> 0 | E8: =SFP!E53 -> 0 | F8: =SFP!F53 -> 0 | G8: =SFP!G53 -> 0 | H8: =SFP!H53 -> 0 | I8: =SFP!I53 -> 0 | J8: =SFP!J53 -> 0 | ... AM8: =SFP!AM53 -> 0
A10: 5 | B10: Share capital and Reserves
A11: 5.1 | B11: Core Capital | C11: =C14-C23 -> 815245740 | D11: =D14-D23 -> 956374726 | E11: =E14-E23 -> 9.9666665e+08 | F11: =F14-F23 -> 1.0335819e+09 | G11: =G14-G23 -> 1.078069e+09 | H11: =H14-H23 -> 1.123704e+09 | I11: =I14-I23 -> 1.1664293e+09 | J11: =J14-J23 -> 1.2128927e+09 | ... AM11: =AM14-AM23 -> 1.7649021e+09
A12: 5.2 | B12: Institutional Capital | C12: =C11-C15 -> 666793839 | D12: =D11-D15 -> 751665379 | E12: =E11-E15 -> 7.8981963e+08 | F12: =F11-F15 -> 8.2427524e+08 | G12: =G11-G15 -> 8.6665198e+08 | H12: =H11-H15 -> 9.0992863e+08 | I12: =I11-I15 -> 9.5062743e+08 | J12: =J11-J15 -> 9.9455582e+08 | ... AM12: =AM11-AM15 -> 1.462215e+09
A14: 5.3 | B14: Total Capital | C14: =SUM(C15:C21) -> 827255740 | D14: =SUM(D15:D21) -> 1039588669 | E14: =SUM(E15:E21) -> 1.086542e+09 | F14: =SUM(F15:F21) -> 1.1234573e+09 | G14: =SUM(G15:G21) -> 1.1679443e+09 | H14: =SUM(H15:H21) -> 1.2135794e+09 | I14: =SUM(I15:I21) -> 1.2563047e+09 | J14: =SUM(J15:J21) -> 1.3027681e+09 | ... AM14: =SUM(AM15:AM21) -> 1.8023484e+09
A15: 5.3.1 | B15: Members Share Capital | C15: =SFP!C57 -> 148451901 | D15: =SFP!D57 -> 204709347 | E15: =SFP!E57 -> 2.0684702e+08 | F15: =SFP!F57 -> 2.0930665e+08 | G15: =SFP!G57 -> 2.1141698e+08 | H15: =SFP!H57 -> 2.137754e+08 | I15: =SFP!I57 -> 2.1580189e+08 | J15: =SFP!J57 -> 2.183369e+08 | ... AM15: =SFP!AM57 -> 3.0268705e+08
A16: 5.3.3 | B16: Retained Earnings | C16: =SFP!C60 -> 438522803 | D16: =SFP!D60 -> 534907340 | E16: =SFP!E60 -> 6.3943328e+08 | F16: =SFP!F60 -> 6.1417864e+08 | G16: =SFP!G60 -> 6.5655538e+08 | H16: =SFP!H60 -> 6.9983203e+08 | I16: =SFP!I60 -> 7.4053083e+08 | J16: =SFP!J60 -> 7.8445922e+08 | ... AM16: =SFP!AM60 -> 1.0757075e+09
A17: 5.3.5 | B17: Statutory Reserves | C17: =SFP!C65 -> 163114085 | D17: =SFP!D65 -> 202908049 | E17: =SFP!E65 -> 1.631012e+08 | F17: =SFP!F65 -> 2.0290805e+08 | G17: =SFP!G65 -> 2.0290805e+08 | H17: =SFP!H65 -> 2.0290805e+08 | I17: =SFP!I65 -> 2.0290805e+08 | J17: =SFP!J65 -> 2.0290805e+08 | ... AM17: =SFP!AM65 -> 2.8556269e+08
A18: 5.3.6 | B18: Capital Reserves | C18: =SFP!C66 -> 77166951 | D18: =SFP!D66 -> 97063933 | E18: =SFP!E66 -> 77160512 | F18: =SFP!F66 -> 97063923 | G18: =SFP!G66 -> 97063923 | H18: =SFP!H66 -> 97063923 | I18: =SFP!I66 -> 97063933 | J18: =SFP!J66 -> 97063933 | ... AM18: =SFP!AM66 -> 1.3839125e+08
A19: 5.3.7 | B19: Supplementary Capital & reserves
A20: a | B20: Proposed Dividends
A21: b | B21: Risk Mgt Fund
A23: 6 | B23: Investments | C23: =C25+C24 -> 12010000 | D23: =D25+D24 -> 83213943 | E23: =E25+E24 -> 89875374 | F23: =F25+F24 -> 89875374 | G23: =G25+G24 -> 89875374 | H23: =H25+H24 -> 89875374 | I23: =I25+I24 -> 89875374 | J23: =J25+J24 -> 89875374 | ... AM23: =AM25+AM24 -> 37446375
B24: Liquidity investments
B25: Equity Investments (at cost) | C25: =SFP!C20 -> 12010000 | D25: =SFP!D20 -> 83213943 | E25: =SFP!E20 -> 89875374 | F25: =SFP!F20 -> 89875374 | G25: =SFP!G20 -> 89875374 | H25: =SFP!H20 -> 89875374 | I25: =SFP!I20 -> 89875374 | J25: =SFP!J20 -> 89875374 | ... AM25: =SFP!AM20 -> 37446375
A27: 7 | B27: Net Loans & Advances | C27: =C28-C29 -> 2994823414 | D27: =D28-D29 -> 3054612195 | E27: =E28-E29 -> 3.1229879e+09 | F27: =F28-F29 -> 3.1272368e+09 | G27: =G28-G29 -> 3.0371914e+09 | H27: =H28-H29 -> 3.0442169e+09 | I27: =I28-I29 -> 3.0658165e+09 | J27: =J28-J29 -> 3.1049186e+09 | ... AM27: =AM28-AM29 -> 3.6217876e+09
A28: 7.1 | B28: Gross Loans & advances | C28: =SFP!C23 -> 3077148048 | D28: =SFP!D23 -> 3148024766 | E28: =SFP!E23 -> 3.2172755e+09 | F28: =SFP!F23 -> 3.2223994e+09 | G28: =SFP!G23 -> 3.133229e+09 | H28: =SFP!H23 -> 3.1411294e+09 | I28: =SFP!I23 -> 3.1636041e+09 | J28: =SFP!J23 -> 3.2035811e+09 | ... AM28: =SFP!AM23 -> 3757913092
A29: 7.2 | B29: Allowance for loan losses | C29: =SFP!C24 -> 82324634 | D29: =SFP!D24 -> 93412571 | E29: =SFP!E24 -> 94287571 | F29: =SFP!F24 -> 95162571 | G29: =SFP!G24 -> 96037571 | H29: =SFP!H24 -> 96912571 | I29: =SFP!I24 -> 97787571 | J29: =SFP!J24 -> 98662571 | ... AM29: =SFP!AM24 -> 1.3612551e+08
A31: 8 | B31: Non-Earning Assets | C31: =SFP!C14+SFP!C31 -> 184190820 | D31: =SFP!D14+SFP!D31 -> 186847688 | E31: =SFP!E14+SFP!E31 -> 1.8483456e+08 | F31: =SFP!F14+SFP!F31 -> 183652595 | G31: =SFP!G14+SFP!G31 -> 1.7876878e+08 | H31: =SFP!H14+SFP!H31 -> 1.8165072e+08 | I31: =SFP!I14+SFP!I31 -> 1.8199909e+08 | J31: =SFP!J14+SFP!J31 -> 1.8274238e+08 | ... AM31: =SFP!AM14+SFP!AM31 -> 6.5384874e+08
A32: 8.1 | B32: Property and Equipment | C32: =SFP!C31 -> 12210244 | D32: =SFP!D31 -> 9860927 | E32: =SFP!E31 -> 9641418.8 | F32: =SFP!F31 -> 9641418.8 | G32: =SFP!G31 -> 10138851 | H32: =SFP!H31 -> 9896062.8 | I32: =SFP!I31 -> 9653275 | J32: =SFP!J31 -> 10100963 | ... AM32: =SFP!AM31 -> 4.9197922e+08
A34: 9 | B34: Turnover | C34: =SCI!C10 -> 583839786 | D34: =SCI!D10 -> 573346290 | E34: =SCI!E10 -> 56301430 | F34: =SCI!F10 -> 1.05712e+08 | G34: =SCI!G10 -> 1.6334855e+08 | H34: =SCI!H10 -> 2.187406e+08 | I34: =SCI!I10 -> 2.7177693e+08 | J34: =SCI!J10 -> 3.2870363e+08 | ... AM34: =SCI!AM10 -> 5.6308842e+08
A35: 9.1 | B35: Loan Interest | C35: =SCI!C12 -> 546947861 | D35: =SCI!D12 -> 541188931 | E35: =SCI!E12 -> 51957907 | F35: =SCI!F12 -> 97235637 | G35: =SCI!G12 -> 1.4579594e+08 | H35: =SCI!H12 -> 1.9296479e+08 | I35: =SCI!I12 -> 2.4145639e+08 | J35: =SCI!J12 -> 2.918937e+08 | ... AM35: =SCI!AM12 -> 5.033078e+08
A36: 9.2 | B36: Income from investments | C36: =SCI!C15 -> 36891925 | D36: =SCI!D15 -> 30847091 | E36: =SCI!E15 -> 4184522.8 | F36: =SCI!F15 -> 8151161.8 | G36: =SCI!G15 -> 17065085 | H36: =SCI!H15 -> 25123060 | I36: =SCI!I15 -> 29461254 | J36: =SCI!J15 -> 35734415 | ... AM36: =SCI!AM15 -> 56121755
A37: 9.3 | B37: Fees & Commissions | C37: =SCI!C13 -> 0 | D37: =SCI!D13 -> 1310268 | E37: =SCI!E13 -> 159000 | F37: =SCI!F13 -> 325200 | G37: =SCI!G13 -> 487520 | H37: =SCI!H13 -> 652760 | I37: =SCI!I13 -> 859280 | J37: =SCI!J13 -> 1075520 | ... AM37: =SCI!AM13 -> 3658862.9
A38: 9.4 | B38: Average yield on loans
A40: 10 | B40: Fianacial and Operating costs | C40: =SCI!C21+SCI!C36 -> 384107979 | D40: =SCI!D21+SCI!D36 -> 297709328 | E40: =SCI!E21+SCI!E36 -> 10454682 | F40: =SCI!F21+SCI!F36 -> 24386120 | G40: =SCI!G21+SCI!G36 -> 38763031 | H40: =SCI!H21+SCI!H36 -> 49945671 | I40: =SCI!I21+SCI!I36 -> 61262353 | J40: =SCI!J21+SCI!J36 -> 73416365 | ... AM40: =SCI!AM21+SCI!AM36 -> 1.6970504e+08
A41: 10.1 | B41: Interest expense on deposits | C41: =SCI!C22 -> 230056542 | D41: =SCI!D22 -> 248555614 | E41: =SCI!E22 -> 280810.11 | F41: =SCI!F22 -> 528301.52 | G41: =SCI!G22 -> 843653.96 | H41: =SCI!H22 -> 1270924 | I41: =SCI!I22 -> 1638682.7 | J41: =SCI!J22 -> 2082162.7 | ... AM41: =SCI!AM22 -> 3095137.2
A42: 10.2 | B42: Dividend expense on share capital
A43: 10.3 | B43: Interest expense on borrowed funds | C43: =SCI!C23 -> 491683 | D43: =SCI!D23 -> 460801 | E43: =SCI!E23 -> 10360.78 | F43: =SCI!F23 -> 10360.78 | G43: =SCI!G23 -> 10360.78 | H43: =SCI!H23 -> 10360.78 | I43: =SCI!I23 -> 10360.78 | J43: =SCI!J23 -> 10360.78 | ... AM43: =SCI!AM23 -> 0
A44: 10.4 | B44: Opperating expenses | C44: =SCI!C36 -> 152589572 | D44: =SCI!D36 -> 47651806 | E44: =SCI!E36 -> 10083535 | F44: =SCI!F36 -> 23677406 | G44: =SCI!G36 -> 37665714 | H44: =SCI!H36 -> 48278445 | I44: =SCI!I36 -> 59127587 | J44: =SCI!J36 -> 70749906 | ... AM44: =SCI!AM36 -> 1.6551404e+08

Sheet PRUDENTIAL RATIOS
A1: NYATI Sacco Ltd Financial Performance & Projections
B3: FINANCIAL SOUNDNESS INDICATORS | C3: Prudential Std | D3: 44075 | E3: 44105 | F3: 44136 | G3: 44166 | H3: Audited 2020 | I3: 44197 | J3: 44228 | K3: 44256 | L3: 44287 | M3: 44317 | N3: 44348 | O3: 44378 | P3: 44409 | Q3: 44440 | R3: 44470 | S3: 44501 | T3: 44531 | U3: Audited 2021 | V3: 44562 | W3: 44593 | X3: 44621 | Y3: 44652 | Z3: 44682 | AA3: 44713 | AB3: 44743 | AC3: 44774 | AD3: 44805 | AE3: 44835 | AF3: 44866 | AG3: 44896 | AH3: AUDITED 2022 | AI3: 44927 | AJ3: 44958 | AK3: 44986 | AL3: 45017 | AM3: 45047 | AN3: 45078 | AO3: 45108 | AP3: 45139 | AQ3: 45170
A4: 1 | B4: CAPITAL ADEQUACY REQUIREMENTS
A5: 1.1 | B5: Core capital | C5: ≥ Ksh.10M | D5: =FINANCIALS!#REF!/1000000 -> #REF! | E5: =FINANCIALS!#REF!/1000000 -> #REF! | F5: =FINANCIALS!#REF!/1000000 -> #REF! | G5: =FINANCIALS!C11/1000000 -> 815.24574 | H5: =FINANCIALS!D11/1000000 -> 956.37473 | I5: =FINANCIALS!E11/1000000 -> 996.66665 | J5: =FINANCIALS!F11/1000000 -> 1033.5819 | K5: =FINANCIALS!G11/1000000 -> 1078.069 | L5: =FINANCIALS!H11/1000000 -> 1123.704 | M5: =FINANCIALS!I11/1000000 -> 1166.4293 | N5: =FINANCIALS!J11/1000000 -> 1212.8927 | ... AQ5: =FINANCIALS!AM11/1000000 -> 1764.9021
A6: 1.2 | B6: Core capital /Total Assets | C6: ≥ 10% | D6: =FINANCIALS!#REF!/FINANCIALS!#REF! -> #REF! | E6: =FINANCIALS!#REF!/FINANCIALS!#REF! -> #REF! | F6: =FINANCIALS!#REF!/FINANCIALS!#REF! -> #REF! | G6: =FINANCIALS!C11/FINANCIALS!C4 -> 0.24220988 | H6: =FINANCIALS!D11/FINANCIALS!D4 -> 0.25242119 | I6: =FINANCIALS!E11/FINANCIALS!E4 -> 0.25930507 | J6: =FINANCIALS!F11/FINANCIALS!F4 -> 0.2657537 | K6: =FINANCIALS!G11/FINANCIALS!G4 -> 0.29017606 | L6: =FINANCIALS!H11/FINANCIALS!H4 -> 0.29816775 | M6: =FINANCIALS!I11/FINANCIALS!I4 -> 0.30476356 | N6: =FINANCIALS!J11/FINANCIALS!J4 -> 0.31083931 | ... AQ6: =FINANCIALS!AM11/FINANCIALS!AM4 -> 0.36638378
A7: 1.3 | B7: Core capital /Total Deposits | C7: ≥ 8% | D7: =FINANCIALS!#REF!/FINANCIALS!#REF! -> #REF! | E7: =FINANCIALS!#REF!/FINANCIALS!#REF! -> #REF! | F7: =FINANCIALS!#REF!/FINANCIALS!#REF! -> #REF! | G7: =FINANCIALS!C11/FINANCIALS!C5 -> 0.37035792 | H7: =FINANCIALS!D11/FINANCIALS!D5 -> 0.39977271 | I7: =FINANCIALS!E11/FINANCIALS!E5 -> 0.41491121 | J7: =FINANCIALS!F11/FINANCIALS!F5 -> 0.42841678 | K7: =FINANCIALS!G11/FINANCIALS!G5 -> 0.43540209 | L7: =FINANCIALS!H11/FINANCIALS!H5 -> 0.45150577 | M7: =FINANCIALS!I11/FINANCIALS!I5 -> 0.46585037 | N7: =FINANCIALS!J11/FINANCIALS!J5 -> 0.47862723 | ... AQ7: =FINANCIALS!AM11/FINANCIALS!AM5 -> 0.60566106
A8: 1.4 | B8: Institutional/Total Assets | C8: ≥ 8% | D8: =FINANCIALS!#REF!/FINANCIALS!#REF! -> #REF! | E8: =FINANCIALS!#REF!/FINANCIALS!#REF! -> #REF! | F8: =FINANCIALS!#REF!/FINANCIALS!#REF! -> #REF! | G8: =FINANCIALS!C12/FINANCIALS!C4 -> 0.19810476 | H8: =FINANCIALS!D12/FINANCIALS!D4 -> 0.19839113 | I8: =FINANCIALS!E12/FINANCIALS!E4 -> 0.2054892 | J8: =FINANCIALS!F12/FINANCIALS!F4 -> 0.21193695 | K8: =FINANCIALS!G12/FINANCIALS!G4 -> 0.23327047 | L8: =FINANCIALS!H12/FINANCIALS!H4 -> 0.2414438 | M8: =FINANCIALS!I12/FINANCIALS!I4 -> 0.24837904 | N8: =FINANCIALS!J12/FINANCIALS!J4 -> 0.25488408 | ... AQ8: =FINANCIALS!AM12/FINANCIALS!AM4 -> 0.30354765
A10: 2 | B10: ASSET MIX AND QUALITY
A11: 2.1 | B11: Non Earning Assets
A12: 2.1.1 | B12: Non earning Assets/Total assets | C12: ≤ 10% | D12: =FINANCIALS!#REF!/FINANCIALS!#REF! -> #REF! | E12: =FINANCIALS!#REF!/FINANCIALS!#REF! -> #REF! | F12: =FINANCIALS!#REF!/FINANCIALS!#REF! -> #REF! | G12: =FINANCIALS!C31/FINANCIALS!C4 -> 0.054723177 | H12: =FINANCIALS!D31/FINANCIALS!D4 -> 0.049315727 | I12: =FINANCIALS!E31/FINANCIALS!E4 -> 0.048088835 | J12: =FINANCIALS!F31/FINANCIALS!F4 -> 0.047220599 | K12: =FINANCIALS!G31/FINANCIALS!G4 -> 0.048117906 | L12: =FINANCIALS!H31/FINANCIALS!H4 -> 0.048199868 | M12: =FINANCIALS!I31/FINANCIALS!I4 -> 0.047552551 | N12: =FINANCIALS!J31/FINANCIALS!J4 -> 0.046833091 | ... AQ12: =FINANCIALS!AM31/FINANCIALS!AM4 -> 0.13573534
A13: 2.1.2 | B13: Property and Equipment/TA | C13: ≤ 5% | D13: =FINANCIALS!#REF!/FINANCIALS!#REF! -> #REF! | E13: =FINANCIALS!#REF!/FINANCIALS!#REF! -> #REF! | F13: =FINANCIALS!#REF!/FINANCIALS!#REF! -> #REF! | G13: =FINANCIALS!C32/FINANCIALS!C4 -> 0.0036276691 | H13: =FINANCIALS!D32/FINANCIALS!D4 -> 0.0026026481 | I13: =FINANCIALS!E32/FINANCIALS!E4 -> 0.0025084302 | J13: =FINANCIALS!F32/FINANCIALS!F4 -> 0.0024789934 | K13: =FINANCIALS!G32/FINANCIALS!G4 -> 0.0027290014 | L13: =FINANCIALS!H32/FINANCIALS!H4 -> 0.0026258576 | M13: =FINANCIALS!I32/FINANCIALS!I4 -> 0.0025221986 | N13: =FINANCIALS!J32/FINANCIALS!J4 -> 0.0025886679 | ... AQ13: =FINANCIALS!AM32/FINANCIALS!AM4 -> 0.10213213
A15: 2.2 | B15: Earning Assets
A16: 2.2.1 | B16: Non-Govt Securities/Deposits | C16: ≤ 5% | D16: =(SFP!#REF!+SFP!#REF!)/FINANCIALS!#REF! -> #REF! | E16: =(SFP!#REF!+SFP!#REF!)/FINANCIALS!#REF! -> #REF! | F16: =(SFP!#REF!+SFP!#REF!)/FINANCIALS!#REF! -> #REF! | G16: =(SFP!C18+SFP!C20)/FINANCIALS!C5 -> 0.0054560219 | H16: =(SFP!D18+SFP!D20)/FINANCIALS!D5 -> 0.034784131 | I16: =(SFP!#REF!+SFP!#REF!)/FINANCIALS!E5 -> #REF! | J16: =(SFP!E18+SFP!E20)/FINANCIALS!F5 -> 0.03725309 | K16: =(SFP!F18+SFP!F20)/FINANCIALS!G5 -> 0.036298166 | L16: =(SFP!G18+SFP!G20)/FINANCIALS!H5 -> 0.036112044 | M16: =(SFP!H18+SFP!H20)/FINANCIALS!I5 -> 0.035894567 | N16: =(SFP!I18+SFP!I20)/FINANCIALS!J5 -> 0.035466287 | O16: =(SFP!J18+SFP!J20)/FINANCIALS!K5 -> 0.035263444 | P16: =(SFP!K18+SFP!K20)/FINANCIALS!L5 -> 0.035140763 | Q16: =(SFP!L18+SFP!L20)/FINANCIALS!M5 -> 0.035140763 | ... AQ16: =(SFP!AL18+SFP!AL20)/FINANCIALS!AM5 -> 0.012850464
A17: 2.2.2 | B17: Non-Govt Securities/Core Capital | C17: ≤ 40% | D17: =(SFP!#REF!+SFP!#REF!)/FINANCIALS!#REF! -> #REF! | E17: =(SFP!#REF!+SFP!#REF!)/FINANCIALS!#REF! -> #REF! | F17: =(SFP!#REF!+SFP!#REF!)/FINANCIALS!#REF! -> #REF! | G17: =(SFP!C20+SFP!C23)/FINANCIALS!C11 -> 3.7892354 | H17: =(SFP!D20+SFP!D23)/FINANCIALS!D11 -> 3.3786325 | I17: =(SFP!#REF!+SFP!#REF!)/FINANCIALS!E11 -> #REF! | J17: =(SFP!E20+SFP!E23)/FINANCIALS!F11 -> 3.1996989 | K17: =(SFP!F20+SFP!F23)/FINANCIALS!G11 -> 3.0724146 | L17: =(SFP!G20+SFP!G23)/FINANCIALS!H11 -> 2.8682858 | M17: =(SFP!H20+SFP!H23)/FINANCIALS!I11 -> 2.7699962 | N17: =(SFP!I20+SFP!I23)/FINANCIALS!J11 -> 2.6824132 | O17: =(SFP!J20+SFP!J23)/FINANCIALS!K11 -> 2.6200103 | P17: =(SFP!K20+SFP!K23)/FINANCIALS!L11 -> 2.5814839 | Q17: =(SFP!L20+SFP!L23)/FINANCIALS!M11 -> 2.5899765 | ... AQ17: =(SFP!AL20+SFP!AL23)/FINANCIALS!AM11 -> 2.1347278
A18: 2.2.3 | B18: Gross Loans & advances /Total assets | D18: =FINANCIALS!#REF!/FINANCIALS!#REF! -> #REF! | E18: =FINANCIALS!#REF!/FINANCIALS!#REF! -> #REF! | F18: =FINANCIALS!#REF!/FINANCIALS!#REF! -> #REF! | G18: =FINANCIALS!C28/FINANCIALS!C4 -> 0.91422209 | H18: =FINANCIALS!D28/FINANCIALS!D4 -> 0.83087531 | I18: =FINANCIALS!E28/FINANCIALS!E4 -> 0.837046 | J18: =FINANCIALS!F28/FINANCIALS!F4 -> 0.82854059 | K18: =FINANCIALS!G28/FINANCIALS!G4 -> 0.84334868 | L18: =FINANCIALS!H28/FINANCIALS!H4 -> 0.8334788 | M18: =FINANCIALS!I28/FINANCIALS!I4 -> 0.82658351 | N18: =FINANCIALS!J28/FINANCIALS!J4 -> 0.82101155 | ... AQ18: =FINANCIALS!AM28/FINANCIALS!AM4 -> 0.78012171
B19: NPLs to Loan portfolio
A21: 3 | B21: FUNDING MIX
A22: 3.1 | B22: Total Deposits/Total Assets | D22: =FINANCIALS!#REF!/FINANCIALS!#REF! -> #REF! | E22: =FINANCIALS!#REF!/FINANCIALS!#REF! -> #REF! | F22: =FINANCIALS!#REF!/FINANCIALS!#REF! -> #REF! | G22: =FINANCIALS!C5/FINANCIALS!C4 -> 0.65398867 | H22: =FINANCIALS!D5/FINANCIALS!D4 -> 0.63141175 | I22: =FINANCIALS!E5/FINANCIALS!E4 -> 0.62496519 | J22: =FINANCIALS!F5/FINANCIALS!F4 -> 0.62031579 | K22: =FINANCIALS!G5/FINANCIALS!G4 -> 0.66645537 | L22: =FINANCIALS!H5/FINANCIALS!H4 -> 0.66038525 | M22: =FINANCIALS!I5/FINANCIALS!I4 -> 0.65420911 | N22: =FINANCIALS!J5/FINANCIALS!J4 -> 0.64943924 | ... AQ22: =FINANCIALS!AM5/FINANCIALS!AM4 -> 0.60493204
A23: 3.1.1 | B23: BOSA Deposits/Total Assets | D23: =FINANCIALS!#REF!/FINANCIALS!#REF! -> #REF! | E23: =FINANCIALS!#REF!/FINANCIALS!#REF! -> #REF! | F23: =FINANCIALS!#REF!/FINANCIALS!#REF! -> #REF! | G23: =FINANCIALS!C6/FINANCIALS!C4 -> 0.62059553 | H23: =FINANCIALS!D6/FINANCIALS!D4 -> 0.59992702 | I23: =FINANCIALS!E6/FINANCIALS!E4 -> 0.5949405 | J23: =FINANCIALS!F6/FINANCIALS!F4 -> 0.59109463 | K23: =FINANCIALS!G6/FINANCIALS!G4 -> 0.62465166 | L23: =FINANCIALS!H6/FINANCIALS!H4 -> 0.62040669 | M23: =FINANCIALS!I6/FINANCIALS!I4 -> 0.6160126 | N23: =FINANCIALS!J6/FINANCIALS!J4 -> 0.60749973 | ... AQ23: =FINANCIALS!AM6/FINANCIALS!AM4 -> 0.57097381
A24: 3.1.2 | B24: FOSA Deposits/Total Assets | D24: =FINANCIALS!#REF!/FINANCIALS!#REF! -> #REF! | E24: =FINANCIALS!#REF!/FINANCIALS!#REF! -> #REF! | F24: =FINANCIALS!#REF!/FINANCIALS!#REF! -> #REF! | G24: =FINANCIALS!C7/FINANCIALS!C4 -> 0.033393131 | H24: =FINANCIALS!D7/FINANCIALS!D4 -> 0.031484727 | I24: =FINANCIALS!E7/FINANCIALS!E4 -> 0.03002469 | J24: =FINANCIALS!F7/FINANCIALS!F4 -> 0.029221154 | K24: =FINANCIALS!G7/FINANCIALS!G4 -> 0.041803707 | L24: =FINANCIALS!H7/FINANCIALS!H4 -> 0.039978559 | M24: =FINANCIALS!I7/FINANCIALS!I4 -> 0.038196513 | N24: =FINANCIALS!J7/FINANCIALS!J4 -> 0.041939515 | ... AQ24: =FINANCIALS!AM7/FINANCIALS!AM4 -> 0.033958239
A25: 3.2 | B25: External Borrowing/Total assets | C25: ≤ 25% | D25: =FINANCIALS!#REF!/FINANCIALS!#REF! -> #REF! | E25: =FINANCIALS!#REF!/FINANCIALS!#REF! -> #REF! | F25: =FINANCIALS!#REF!/FINANCIALS!#REF! -> #REF! | G25: =FINANCIALS!C8/FINANCIALS!C4 -> 0 | H25: =FINANCIALS!D8/FINANCIALS!D4 -> 0 | I25: =FINANCIALS!E8/FINANCIALS!E4 -> 0 | J25: =FINANCIALS!F8/FINANCIALS!F4 -> 0 | K25: =FINANCIALS!G8/FINANCIALS!G4 -> 0 | L25: =FINANCIALS!H8/FINANCIALS!H4 -> 0 | M25: =FINANCIALS!I8/FINANCIALS!I4 -> 0 | N25: =FINANCIALS!J8/FINANCIALS!J4 -> 0 | ... AQ25: =FINANCIALS!AM8/FINANCIALS!AM4 -> 0
A26: 3.3 | B26: Core capital/total assets | C26: ≥ 10% | D26: =FINANCIALS!#REF!/FINANCIALS!#REF! -> #REF! | E26: =FINANCIALS!#REF!/FINANCIALS!#REF! -> #REF! | F26: =FINANCIALS!#REF!/FINANCIALS!#REF! -> #REF! | G26: =FINANCIALS!C11/FINANCIALS!C4 -> 0.24220988 | H26: =FINANCIALS!D11/FINANCIALS!D4 -> 0.25242119 | I26: =FINANCIALS!E11/FINANCIALS!E4 -> 0.25930507 | J26: =FINANCIALS!F11/FINANCIALS!F4 -> 0.2657537 | K26: =FINANCIALS!G11/FINANCIALS!G4 -> 0.29017606 | L26: =FINANCIALS!H11/FINANCIALS!H4 -> 0.29816775 | M26: =FINANCIALS!I11/FINANCIALS!I4 -> 0.30476356 | N26: =FINANCIALS!J11/FINANCIALS!J4 -> 0.31083931 | ... AQ26: =FINANCIALS!AM11/FINANCIALS!AM4 -> 0.36638378
A28: 4 | B28: GROWTH RATIOS
A29: 4.1 | B29: Total Assets | D29: =(FINANCIALS!#REF!-FINANCIALS!#REF!)/FINANCIALS!#REF! -> #REF! | E29: =(FINANCIALS!#REF!-FINANCIALS!#REF!)/FINANCIALS!#REF! -> #REF! | F29: =(FINANCIALS!#REF!-FINANCIALS!#REF!)/FINANCIALS!#REF! -> #REF! | G29: =(FINANCIALS!C4-FINANCIALS!#REF!)/FINANCIALS!#REF! -> #REF! | H29: =(FINANCIALS!D4-FINANCIALS!C4)/FINANCIALS!C4 -> 0.12565579 | I29: =(FINANCIALS!E4-FINANCIALS!D4)/FINANCIALS!D4 -> 0.014463988 | J29: =(FINANCIALS!F4-FINANCIALS!E4)/FINANCIALS!E4 -> 0.011874502 | K29: =(FINANCIALS!G4-FINANCIALS!F4)/FINANCIALS!F4 -> -0.044744853 | L29: =(FINANCIALS!H4-FINANCIALS!G4)/FINANCIALS!G4 -> 0.014393161 | M29: =(FINANCIALS!I4-FINANCIALS!H4)/FINANCIALS!H4 -> 0.015556571 | N29: =(FINANCIALS!J4-FINANCIALS!I4)/FINANCIALS!I4 -> 0.019508992 | O29: =(FINANCIALS!K4-FINANCIALS!J4)/FINANCIALS!J4 -> 0.0099865399 | ... AQ29: =(FINANCIALS!AM4-FINANCIALS!AL4)/FINANCIALS!AL4 -> 0.014310637
A30: 4.2 | B30: Total Deposits | D30: =(FINANCIALS!#REF!-FINANCIALS!#REF!)/FINANCIALS!#REF! -> #REF! | E30: =(FINANCIALS!#REF!-FINANCIALS!#REF!)/FINANCIALS!#REF! -> #REF! | F30: =(FINANCIALS!#REF!-FINANCIALS!#REF!)/FINANCIALS!#REF! -> #REF! | G30: =(FINANCIALS!C5-FINANCIALS!#REF!)/FINANCIALS!#REF! -> #REF! | H30: =(FINANCIALS!D5-FINANCIALS!C5)/FINANCIALS!C5 -> 0.086796044 | I30: =(FINANCIALS!E5-FINANCIALS!D5)/FINANCIALS!D5 -> 0.0041065652 | J30: =(FINANCIALS!F5-FINANCIALS!E5)/FINANCIALS!E5 -> 0.0043466972 | K30: =(FINANCIALS!G5-FINANCIALS!F5)/FINANCIALS!F5 -> 0.026307779 | L30: =(FINANCIALS!H5-FINANCIALS!G5)/FINANCIALS!G5 -> 0.0051540026 | M30: =(FINANCIALS!I5-FINANCIALS!H5)/FINANCIALS!H5 -> 0.0060587606 | N30: =(FINANCIALS!J5-FINANCIALS!I5)/FINANCIALS!I5 -> 0.012075704 | O30: =(FINANCIALS!K5-FINANCIALS!J5)/FINANCIALS!J5 -> 0.005752226 | ... AQ30: =(FINANCIALS!AM5-FINANCIALS!AL5)/FINANCIALS!AL5 -> 0.0075264921
A31: 4.2.1 | B31: BOSA Deposits | D31: =(FINANCIALS!#REF!-FINANCIALS!#REF!)/FINANCIALS!#REF! -> #REF! | E31: =(FINANCIALS!#REF!-FINANCIALS!#REF!)/FINANCIALS!#REF! -> #REF! | F31: =(FINANCIALS!#REF!-FINANCIALS!#REF!)/FINANCIALS!#REF! -> #REF! | G31: =(FINANCIALS!C6-FINANCIALS!#REF!)/FINANCIALS!#REF! -> #REF! | H31: =(FINANCIALS!D6-FINANCIALS!C6)/FINANCIALS!C6 -> 0.088166595 | I31: =(FINANCIALS!E6-FINANCIALS!D6)/FINANCIALS!D6 -> 0.0060318884 | J31: =(FINANCIALS!F6-FINANCIALS!E6)/FINANCIALS!E6 -> 0.0053334486 | K31: =(FINANCIALS!G6-FINANCIALS!F6)/FINANCIALS!F6 -> 0.009485922 | L31: =(FINANCIALS!H6-FINANCIALS!G6)/FINANCIALS!G6 -> 0.0074996099 | M31: =(FINANCIALS!I6-FINANCIALS!H6)/FINANCIALS!H6 -> 0.0083637964 | N31: =(FINANCIALS!J6-FINANCIALS!I6)/FINANCIALS!I6 -> 0.0054200774 | O31: =(FINANCIALS!K6-FINANCIALS!J6)/FINANCIALS!J6 -> 0.0064524178 | ... AQ31: =(FINANCIALS!AM6-FINANCIALS!AL6)/FINANCIALS!AL6 -> 0.0074090662
A32: 4.2.2 | B32: FOSA Deposits | D32: =(FINANCIALS!#REF!-FINANCIALS!#REF!)/FINANCIALS!#REF! -> #REF! | E32: =(FINANCIALS!#REF!-FINANCIALS!#REF!)/FINANCIALS!#REF! -> #REF! | F32: =(FINANCIALS!#REF!-FINANCIALS!#REF!)/FINANCIALS!#REF! -> #REF! | G32: =(FINANCIALS!C7-FINANCIALS!#REF!)/FINANCIALS!#REF! -> #REF! | H32: =(FINANCIALS!D7-FINANCIALS!C7)/FINANCIALS!C7 -> 0.061325002 | I32: =(FINANCIALS!E7-FINANCIALS!D7)/FINANCIALS!D7 -> -0.032579586 | J32: =(FINANCIALS!F7-FINANCIALS!E7)/FINANCIALS!E7 -> -0.015205822 | K32: =(FINANCIALS!G7-FINANCIALS!F7)/FINANCIALS!F7 -> 0.36658556 | L32: =(FINANCIALS!H7-FINANCIALS!G7)/FINANCIALS!G7 -> -0.02989522 | M32: =(FINANCIALS!I7-FINANCIALS!H7)/FINANCIALS!H7 -> -0.029711904 | N32: =(FINANCIALS!J7-FINANCIALS!I7)/FINANCIALS!I7 -> 0.11941404 | O32: =(FINANCIALS!K7-FINANCIALS!J7)/FINANCIALS!J7 -> -0.0043901508 | ... AQ32: =(FINANCIALS!AM7-FINANCIALS!AL7)/FINANCIALS!AL7 -> 0.0095049997
A33: 4.3 | B33: Total Loans & advances | D33: =(FINANCIALS!#REF!-FINANCIALS!#REF!)/FINANCIALS!#REF! -> #REF! | E33: =(FINANCIALS!#REF!-FINANCIALS!#REF!)/FINANCIALS!#REF! -> #REF! | F33: =(FINANCIALS!#REF!-FINANCIALS!#REF!)/FINANCIALS!#REF! -> #REF! | G33: =(FINANCIALS!C28-FINANCIALS!#REF!)/FINANCIALS!#REF! -> #REF! | H33: =(FINANCIALS!D28-FINANCIALS!C28)/FINANCIALS!C28 -> 0.023033249 | I33: =(FINANCIALS!E28-FINANCIALS!D28)/FINANCIALS!D28 -> 0.021998148 | J33: =(FINANCIALS!F28-FINANCIALS!E28)/FINANCIALS!E28 -> 0.0015926261 | K33: =(FINANCIALS!G28-FINANCIALS!F28)/FINANCIALS!F28 -> -0.027672063 | L33: =(FINANCIALS!H28-FINANCIALS!G28)/FINANCIALS!G28 -> 0.0025215088 | M33: =(FINANCIALS!I28-FINANCIALS!H28)/FINANCIALS!H28 -> 0.0071549736 | N33: =(FINANCIALS!J28-FINANCIALS!I28)/FINANCIALS!I28 -> 0.012636537 | O33: =(FINANCIALS!K28-FINANCIALS!J28)/FINANCIALS!J28 -> 0.017345538 | ... AQ33: =(FINANCIALS!AM28-FINANCIALS!AL28)/FINANCIALS!AL28 -> 0.007445824
A34: 4.4 | B34: Core capital | D34: =(FINANCIALS!#REF!-FINANCIALS!#REF!)/FINANCIALS!#REF! -> #REF! | E34: =(FINANCIALS!#REF!-FINANCIALS!#REF!)/FINANCIALS!#REF! -> #REF! | F34: =(FINANCIALS!#REF!-FINANCIALS!#REF!)/FINANCIALS!#REF! -> #REF! | G34: =(FINANCIALS!C11-FINANCIALS!#REF!)/FINANCIALS!#REF! -> #REF! | H34: =(FINANCIALS!D11-FINANCIALS!C11)/FINANCIALS!C11 -> 0.1731122 | I34: =(FINANCIALS!E11-FINANCIALS!D11)/FINANCIALS!D11 -> 0.04212985 | J34: =(FINANCIALS!F11-FINANCIALS!E11)/FINANCIALS!E11 -> 0.037038696 | K34: =(FINANCIALS!G11-FINANCIALS!F11)/FINANCIALS!F11 -> 0.043041657 | L34: =(FINANCIALS!H11-FINANCIALS!G11)/FINANCIALS!G11 -> 0.042330384 | M34: =(FINANCIALS!I11-FINANCIALS!H11)/FINANCIALS!H11 -> 0.038021831 | N34: =(FINANCIALS!J11-FINANCIALS!I11)/FINANCIALS!I11 -> 0.039833879 | O34: =(FINANCIALS!K11-FINANCIALS!J11)/FINANCIALS!J11 -> 0.036397934 | ... AQ34: =(FINANCIALS!AM11-FINANCIALS!AL11)/FINANCIALS!AL11 -> 0.027083007
A35: 4.5 | B35: Turnover | D35: =(FINANCIALS!#REF!-FINANCIALS!#REF!)/FINANCIALS!#REF! -> #REF! | E35: =(FINANCIALS!#REF!-FINANCIALS!#REF!)/FINANCIALS!#REF! -> #REF! | F35: =(FINANCIALS!#REF!-FINANCIALS!#REF!)/FINANCIALS!#REF! -> #REF! | G35: =(FINANCIALS!C34-FINANCIALS!#REF!)/FINANCIALS!#REF! -> #REF! | H35: =(FINANCIALS!D34-FINANCIALS!C35)/FINANCIALS!C34 -> 0.045215194 | I35: =(FINANCIALS!E34-FINANCIALS!D35)/FINANCIALS!D34 -> -0.8457149 | J35: =(FINANCIALS!F34-FINANCIALS!E35)/FINANCIALS!E34 -> 0.95475535 | K35: =(FINANCIALS!G34-FINANCIALS!F35)/FINANCIALS!F34 -> 0.62540593 | L35: =(FINANCIALS!H34-FINANCIALS!G35)/FINANCIALS!G34 -> 0.44655838 | M35: =(FINANCIALS!I34-FINANCIALS!H35)/FINANCIALS!H34 -> 0.36029955 | N35: =(FINANCIALS!J34-FINANCIALS!I35)/FINANCIALS!I34 -> 0.32102519 | O35: =(FINANCIALS!K34-FINANCIALS!J35)/FINANCIALS!J34 -> 0.28443584 | ... AQ35: =(FINANCIALS!AM34-FINANCIALS!AL35)/FINANCIALS!AL34 -> 0.2376033
A36: 4.6 | B36: Membership
