Workbook

Sheet CAELS (2)
A1: PATNAS SACCO CAELS
D2: 2013 Audited | E2: 2014 Audited | F2: 2015 Audited | G2: 42370 | H2: 42370 | I2: 42401 | J2: 42430 | K2: 42461 | L2: 42491 | M2: 42522 | N2: 42552 | O2: 42583 | P2: 42614 | Q2: 42644 | R2: 42675 | S2: 42705 | T2: Audited 2016 | U2: 42736 | V2: 42767 | W2: 42795 | X2: 42826 | Y2: 42856 | Z2: 42887 | AA2: 42917 | AB2: 42948 | AC2: 42979 | AD2: 43009 | AE2: 43040 | AF2: 43070 | AG2: Audited 2017 | AH2: 43101 | AI2: 43132 | AJ2: 43160 | AK2: 43191 | AL2: 43221 | AM2: 43252 | AN2: 43282 | AO2: 43313 | AP2: 43344 | AQ2: 43374 | AR2: 43405 | AS2: 43435 | AT2: Audited 2018 | AU2: 43466 | AV2: 43497 | AW2: 43525 | AX2: 43556 | AY2: 43586 | AZ2: 43617 | BA2: 43647 | BB2: 43678 | BC2: 43709 | BD2: 43739 | BE2: 43770 | BF2: 43800 | BG2: Audited | BH2: 43831 | BI2: 43862 | BJ2: 43891 | BK2: 43922 | BL2: 43952 | BM2: 43983 | BN2: 44013 | BO2: 44044 | BP2: 44075 | BQ2: 44105 | BR2: 44136 | BS2: 44166 | BT2: Audited 2020 | BU2: 44197 | BV2: 44228 | BW2: 44256 | BX2: 44287 | BY2: 44317 | BZ2: 44348 | CA2: 44378 | CB2: 44409 | CC2: 44440 | CD2: 44470 | CE2: 44501 | CF2: 44531 | CG2: Audited 2021 | CH2: 44562 | CI2: 44593 | CJ2: 44621 | CK2: 44652 | CL2: 44682 | CM2: 44713 | CN2: 44743 | CO2: 44774 | CP2: 44805 | CQ2: 44835 | CR2: 44866 | CS2: 44896 | CT2: Audited 2022 | CU2: 44927 | CV2: 44958 | CW2: 44986 | CX2: 45017
A3: CAPITAL ADEQUACY | B3: Core Capital | C3: Ksh10 M | D3: =(('Evolutive SFP'!B38+'Evolutive SFP'!B39+'Evolutive SFP'!B41+'Evolutive SFP'!B42+'Evolutive SFP'!B43+'Evolutive SFP'!B44)-'Evolutive SFP'!B12)/1000000 -> 38.667178 | E3: =('Evolutive SFP'!C38+'Evolutive SFP'!C39+'Evolutive SFP'!C41+'Evolutive SFP'!C42+'Evolutive SFP'!C43+'Evolutive SFP'!C44)/1000000 -> 64.157783 | G3: =('Evolutive SFP'!E38+'Evolutive SFP'!E39+'Evolutive SFP'!E41+'Evolutive SFP'!E42+'Evolutive SFP'!E43+'Evolutive SFP'!E44)/1000000 -> 63.857155 | H3: =('Evolutive SFP'!F38+'Evolutive SFP'!F39+'Evolutive SFP'!F41+'Evolutive SFP'!F42+'Evolutive SFP'!F43+'Evolutive SFP'!F44)/1000000 -> 65.035173 | I3: =('Evolutive SFP'!G38+'Evolutive SFP'!G39+'Evolutive SFP'!G41+'Evolutive SFP'!G42+'Evolutive SFP'!G43+'Evolutive SFP'!G44)/1000000 -> 61.475774 | J3: =('Evolutive SFP'!H38+'Evolutive SFP'!H39+'Evolutive SFP'!H41+'Evolutive SFP'!H42+'Evolutive SFP'!H43+'Evolutive SFP'!H44)/1000000 -> 61.650703 | K3: =('Evolutive SFP'!I38+'Evolutive SFP'!I39+'Evolutive SFP'!I41+'Evolutive SFP'!I42+'Evolutive SFP'!I43+'Evolutive SFP'!I44)/1000000 -> 115.24105 | L3: =('Evolutive SFP'!J38+'Evolutive SFP'!J39+'Evolutive SFP'!J41+'Evolutive SFP'!J42+'Evolutive SFP'!J43+'Evolutive SFP'!J44)/1000000 -> 59.101829 | M3: =('Evolutive SFP'!K38+'Evolutive SFP'!K39+'Evolutive SFP'!K41+'Evolutive SFP'!K42+'Evolutive SFP'!K43+'Evolutive SFP'!K44)/1000000 -> 56.103923 | N3: =('Evolutive SFP'!L38+'Evolutive SFP'!L39+'Evolutive SFP'!L41+'Evolutive SFP'!L42+'Evolutive SFP'!L43+'Evolutive SFP'!L44)/1000000 -> 64.761452 | ... CT3: =('Evolutive SFP'!CR38+'Evolutive SFP'!CR39+'Evolutive SFP'!CR41+'Evolutive SFP'!CR42+'Evolutive SFP'!CR43+'Evolutive SFP'!CR44)/1000000 -> 96.970145 | CU3: =('Evolutive SFP'!CS38+'Evolutive SFP'!CS39+'Evolutive SFP'!CS41+'Evolutive SFP'!CS42+'Evolutive SFP'!CS43+'Evolutive SFP'!CS45)/1000000 -> 269.66136
B4: CCA | C4: Min 10% | D4: =D3/(('Evolutive SFP'!B26)/1000000) -> 0.1169964 | E4: =E3/(('Evolutive SFP'!C26)/1000000) -> 0.18423259 | F4: =F3/(('Evolutive SFP'!D26)/1000000) -> 0 | G4: =G3/(('Evolutive SFP'!E26)/1000000) -> 0.16111582 | H4: =H3/(('Evolutive SFP'!F26)/1000000) -> 0.17156387 | I4: =I3/(('Evolutive SFP'!G26)/1000000) -> 0.15983438 | J4: =J3/(('Evolutive SFP'!H26)/1000000) -> 0.16246825 | K4: =K3/(('Evolutive SFP'!I26)/1000000) -> 0.15593274 | ... CU4: =CU3/(('Evolutive SFP'!CS26)/1000000) -> 0.51918439
B5: CCD | C5: Min 8% | D5: =D3/('Evolutive SFP'!B30/1000000) -> 0.23615494 | E5: =E3/('Evolutive SFP'!C30/1000000) -> 0.51041171 | F5: =F3/('Evolutive SFP'!D30/1000000) -> 0 | G5: =G3/('Evolutive SFP'!E30/1000000) -> 0.49271519 | H5: =H3/('Evolutive SFP'!F30/1000000) -> 0.44298293 | I5: =I3/('Evolutive SFP'!G30/1000000) -> 0.40910939 | J5: =J3/('Evolutive SFP'!H30/1000000) -> 0.42548606 | K5: =K3/('Evolutive SFP'!I30/1000000) -> 0.41387063 | ... CU5: =CU3/('Evolutive SFP'!CS30/1000000) -> 1.3813628
B6: ICA | C6: Min 8% | D6: =((D3*1000000)-'Evolutive SFP'!B38)/'Evolutive SFP'!B26 -> -0.044330441 | E6: =((E3*1000000)-'Evolutive SFP'!C38)/'Evolutive SFP'!C26 -> 0.030380074 | F6: =((F3*1000000)-'Evolutive SFP'!D38)/'Evolutive SFP'!D26 -> -0.1408684 | G6: =((G3*1000000)-'Evolutive SFP'!E38)/'Evolutive SFP'!E26 -> 0.025896831 | H6: =((H3*1000000)-'Evolutive SFP'!F38)/'Evolutive SFP'!F26 -> 0.02799707 | I6: =((I3*1000000)-'Evolutive SFP'!G38)/'Evolutive SFP'!G26 -> 0.018338862 | J6: =((J3*1000000)-'Evolutive SFP'!H38)/'Evolutive SFP'!H26 -> 0.019048637 | K6: =((K3*1000000)-'Evolutive SFP'!I38)/'Evolutive SFP'!I26 -> 0.0081133968 | ... CU6: =((CU3*1000000)-'Evolutive SFP'!CS38)/'Evolutive SFP'!CS26 -> 0.37307979
A7: ASSET QUALITY | B7: NPL30 | J7: ='Evolutitve SCI'!H20/('FORM 4'!D14+'FORM 4'!D15+'FORM 4'!D16) -> 0.0996161 | M7: ='Evolutive SFP'!K15/('FORM 4'!D14+'FORM 4'!D15+'FORM 4'!D16) -> 0.65295388 | P7: ='Evolutive SFP'!N15/('FORM 4'!D23+'FORM 4'!D24+'FORM 4'!D25) -> 0.66699908 | S7: ='Evolutive SFP'!K15/('FORM 4'!D14+'FORM 4'!D15+'FORM 4'!D16) -> 0.65295388 | T7: ='Evolutive SFP'!L15/('FORM 4'!D41+'FORM 4'!D42+'FORM 4'!D43) -> 0.72125888 | U7: ='Evolutive SFP'!M15/('FORM 4'!E41+'FORM 4'!E42+'FORM 4'!E43) -> 9420494.3 | V7: ='Evolutive SFP'!N15/('FORM 4'!F41+'FORM 4'!F42+'FORM 4'!F43) -> 0.91879889 | W7: ='Evolutive SFP'!O15/('FORM 4'!G41+'FORM 4'!G42+'FORM 4'!G43) -> #DIV/0! | X7: ='Evolutive SFP'!P15/('FORM 4'!H41+'FORM 4'!H42+'FORM 4'!H43) -> #DIV/0! | Y7: ='Evolutive SFP'!Q15/('FORM 4'!I41+'FORM 4'!I42+'FORM 4'!I43) -> #DIV/0! | Z7: ='Evolutive SFP'!R15/('FORM 4'!J41+'FORM 4'!J42+'FORM 4'!J43) -> #DIV/0! | AA7: ='Evolutive SFP'!S15/('FORM 4'!K41+'FORM 4'!K42+'FORM 4'!K43) -> #DIV/0! | ... AF7: ='Evolutive SFP'!X15/('FORM 4'!P41+'FORM 4'!P42+'FORM 4'!P43) -> #DIV/0! | AG7: 0 | AH7: 1 | AI7: 2 | AJ7: 3 | AK7: 4 | AL7: 5 | AM7: 6 | AN7: 7 | AO7: 8 | AP7: 9 | AQ7: 10 | AR7: 11 | AS7: 12 | AT7: 13 | AU7: 14 | AV7: 15 | AW7: 16 | AX7: 17 | AY7: 18 | AZ7: 19 | BA7: 20 | BB7: 21 | BC7: 22 | BD7: 23 | BE7: 24 | BF7: 25 | BG7: 26 | BH7: 27 | BI7: 28 | BJ7: 29 | BK7: 30 | BL7: 31 | BM7: 32 | BN7: 33 | BO7: 34 | BP7: 35 | BQ7: 36 | BR7: 37 | BS7: 38 | BT7: 39 | BU7: 40 | BV7: 41 | BW7: 42 | BX7: 43 | BY7: 44 | BZ7: 45 | CA7: 46 | CB7: 47 | CC7: 48 | CD7: 49 | CE7: 50 | CF7: 51 | CG7: 52 | CH7: 53 | CI7: 54 | CJ7: 55 | CK7: 56 | CL7: 57 | CM7: 58 | CN7: 59 | CO7: 60 | CP7: 61 | CQ7: 62 | CR7: 63 | CS7: 64 | CT7: 65 | CU7: 66
A9: EARNINGS | B9: ROA | E9: ='Evolutitve SCI'!C33/(('Evolutive SFP'!B26+'Evolutive SFP'!C26)/2) -> 0.027471151 | F9: ='Evolutitve SCI'!D33/(('Evolutive SFP'!C26+'Evolutive SFP'!D26)/2) -> 0.012565004 | G9: ='Evolutitve SCI'!E33/(('Evolutive SFP'!D26+'Evolutive SFP'!E26)/2) -> -0.00080671348 | H9: ='Evolutitve SCI'!F33/(('Evolutive SFP'!E26+'Evolutive SFP'!F26)/2) -> 8.5797319e-05 | I9: ='Evolutitve SCI'!G33/(('Evolutive SFP'!F26+'Evolutive SFP'!G26)/2) -> -0.0084523794 | J9: ='Evolutitve SCI'!H33/(('Evolutive SFP'!G26+'Evolutive SFP'!H26)/2) -> -0.0079907036 | K9: ='Evolutitve SCI'!I33/(('Evolutive SFP'!H26+'Evolutive SFP'!I26)/2) -> -0.026045327 | L9: ='Evolutitve SCI'!J33/(('Evolutive SFP'!I26+'Evolutive SFP'!J26)/2) -> -0.010553779 | ... CU9: ='Evolutitve SCI'!CS33/(('Evolutive SFP'!CR26+'Evolutive SFP'!CS26)/2) -> 0.004148878
B10: Cost Income ratio | D10: ='Evolutitve SCI'!B23/'Evolutitve SCI'!B19 -> 0.85142686 | E10: ='Evolutitve SCI'!C23/'Evolutitve SCI'!C19 -> 0.8298036 | F10: ='Evolutitve SCI'!D23/'Evolutitve SCI'!D19 -> 0.90824195 | G10: ='Evolutitve SCI'!E23/'Evolutitve SCI'!E19 -> 0.88951046 | H10: ='Evolutitve SCI'!F23/'Evolutitve SCI'!F19 -> 0.64141686 | I10: ='Evolutitve SCI'!G23/'Evolutitve SCI'!G19 -> 1.0851038 | J10: ='Evolutitve SCI'!H23/'Evolutitve SCI'!H19 -> 1.0525412 | K10: ='Evolutitve SCI'!I23/'Evolutitve SCI'!I19 -> 1.5009166 | ... CU10: ='Evolutitve SCI'!CS23/'Evolutitve SCI'!CS19 -> 0.59601911
B11: Operating Expense ratio | D11: =('Evolutitve SCI'!B23+'Evolutitve SCI'!B12)/(('Evolutive SFP'!B26+'Evolutive SFP'!C26)/2) -> 0.16569149 | E11: =('Evolutitve SCI'!C23+'Evolutitve SCI'!C12)/(('Evolutive SFP'!C26+'Evolutive SFP'!D26)/2) -> 0.19354259 | F11: =('Evolutitve SCI'!D23+'Evolutitve SCI'!D12)/(('Evolutive SFP'!D26+'Evolutive SFP'!E26)/2) -> 0.18151855 | G11: =('Evolutitve SCI'!E23+'Evolutitve SCI'!E12)/(('Evolutive SFP'!E26+'Evolutive SFP'!F26)/2) -> 0.01334902 | H11: =('Evolutitve SCI'!F23+'Evolutitve SCI'!F12)/(('Evolutive SFP'!F26+'Evolutive SFP'!G26)/2) -> 0.010920595 | I11: =('Evolutitve SCI'!G23+'Evolutitve SCI'!G12)/(('Evolutive SFP'!G26+'Evolutive SFP'!H26)/2) -> 0.02747963 | J11: =('Evolutitve SCI'!H23+'Evolutitve SCI'!H12)/(('Evolutive SFP'!H26+'Evolutive SFP'!I26)/2) -> 0.025862472 | K11: =('Evolutitve SCI'!I23+'Evolutitve SCI'!I12)/(('Evolutive SFP'!I26+'Evolutive SFP'!J26)/2) -> 0.08180729 | ... CU11: =('Evolutitve SCI'!CS23+'Evolutitve SCI'!CS12)/(('Evolutive SFP'!CS26+'Evolutive SFP'!CT26)/2) -> 0.025259838
A12: LIQUIDITY | B12: MIN LIQ ratio | C12: Min 15% | D12: =('Evolutive SFP'!B4)/('Evolutive SFP'!B27+'Evolutive SFP'!B28+'Evolutive SFP'!B31+'Evolutive SFP'!B32+'Evolutive SFP'!B33+'Evolutive SFP'!B34+'Evolutive SFP'!B35) -> 0.38095275 | E12: =('Evolutive SFP'!C4)/('Evolutive SFP'!C27+'Evolutive SFP'!C28+'Evolutive SFP'!C31+'Evolutive SFP'!C32+'Evolutive SFP'!C33+'Evolutive SFP'!C34+'Evolutive SFP'!C35) -> 0.50360405 | F12: =('Evolutive SFP'!D4)/('Evolutive SFP'!D27+'Evolutive SFP'!D28+'Evolutive SFP'!D31+'Evolutive SFP'!D32+'Evolutive SFP'!D33+'Evolutive SFP'!D34+'Evolutive SFP'!D35) -> 0.77961975 | G12: =('Evolutive SFP'!E4)/('Evolutive SFP'!E27+'Evolutive SFP'!E28+'Evolutive SFP'!E31+'Evolutive SFP'!E32+'Evolutive SFP'!E33+'Evolutive SFP'!E34+'Evolutive SFP'!E35) -> 0.4019944 | H12: =('Evolutive SFP'!F4)/('Evolutive SFP'!F27+'Evolutive SFP'!F28+'Evolutive SFP'!F31+'Evolutive SFP'!F32+'Evolutive SFP'!F33+'Evolutive SFP'!F34+'Evolutive SFP'!F35) -> 0.23629838 | I12: =('Evolutive SFP'!G4)/('Evolutive SFP'!G27+'Evolutive SFP'!G28+'Evolutive SFP'!G31+'Evolutive SFP'!G32+'Evolutive SFP'!G33+'Evolutive SFP'!G34+'Evolutive SFP'!G35) -> 0.19872112 | J12: =('Evolutive SFP'!H4)/('Evolutive SFP'!H27+'Evolutive SFP'!H28+'Evolutive SFP'!H31+'Evolutive SFP'!H32+'Evolutive SFP'!H33+'Evolutive SFP'!H34+'Evolutive SFP'!H35) -> 0.18594944 | K12: =('Evolutive SFP'!I4)/('Evolutive SFP'!I27+'Evolutive SFP'!I28+'Evolutive SFP'!I31+'Evolutive SFP'!I32+'Evolutive SFP'!I33+'Evolutive SFP'!I34+'Evolutive SFP'!I35) -> 0.12341428 | ... CU12: =('Evolutive SFP'!CS4)/('Evolutive SFP'!CS27+'Evolutive SFP'!CS28+'Evolutive SFP'!CS31+'Evolutive SFP'!CS32+'Evolutive SFP'!CS33+'Evolutive SFP'!CS34+'Evolutive SFP'!CS35) -> -0.095478427
B13: T/LIQ ratio | D13: =('Evolutive SFP'!B4+'Evolutive SFP'!B8)/('Evolutive SFP'!B30+'Evolutive SFP'!B31+'Evolutive SFP'!B32+'Evolutive SFP'!B33+'Evolutive SFP'!B34+'Evolutive SFP'!B35) -> 0.48557591 | E13: =('Evolutive SFP'!C4+'Evolutive SFP'!C8)/('Evolutive SFP'!C30+'Evolutive SFP'!C31+'Evolutive SFP'!C32+'Evolutive SFP'!C33+'Evolutive SFP'!C34+'Evolutive SFP'!C35) -> 0.47225695 | F13: =('Evolutive SFP'!D4+'Evolutive SFP'!D8)/('Evolutive SFP'!D30+'Evolutive SFP'!D31+'Evolutive SFP'!D32+'Evolutive SFP'!D33+'Evolutive SFP'!D34+'Evolutive SFP'!D35) -> 0.66754314 | G13: =('Evolutive SFP'!E4+'Evolutive SFP'!E8)/('Evolutive SFP'!E30+'Evolutive SFP'!E31+'Evolutive SFP'!E32+'Evolutive SFP'!E33+'Evolutive SFP'!E34+'Evolutive SFP'!E35) -> 0.51054253 | H13: =('Evolutive SFP'!F4+'Evolutive SFP'!F8)/('Evolutive SFP'!F30+'Evolutive SFP'!F31+'Evolutive SFP'!F32+'Evolutive SFP'!F33+'Evolutive SFP'!F34+'Evolutive SFP'!F35) -> 0.39899382 | I13: =('Evolutive SFP'!G4+'Evolutive SFP'!G8)/('Evolutive SFP'!G30+'Evolutive SFP'!G31+'Evolutive SFP'!G32+'Evolutive SFP'!G33+'Evolutive SFP'!G34+'Evolutive SFP'!G35) -> 0.37183699 | J13: =('Evolutive SFP'!H4+'Evolutive SFP'!H8)/('Evolutive SFP'!H30+'Evolutive SFP'!H31+'Evolutive SFP'!H32+'Evolutive SFP'!H33+'Evolutive SFP'!H34+'Evolutive SFP'!H35) -> 0.3736823 | K13: =('Evolutive SFP'!I4+'Evolutive SFP'!I8)/('Evolutive SFP'!I30+'Evolutive SFP'!I31+'Evolutive SFP'!I32+'Evolutive SFP'!I33+'Evolutive SFP'!I34+'Evolutive SFP'!I35) -> 0.33925681 | ... CU13: =('Evolutive SFP'!CS4+'Evolutive SFP'!CS8)/('Evolutive SFP'!CS30+'Evolutive SFP'!CS31+'Evolutive SFP'!CS32+'Evolutive SFP'!CS33+'Evolutive SFP'!CS34+'Evolutive SFP'!CS35) -> 0.8517802
B14: EB ratio | C14: Max 25% | D14: ='Evolutive SFP'!B36/'Evolutive SFP'!B26 -> 0.27900143 | E14: ='Evolutive SFP'!C36/'Evolutive SFP'!C26 -> 0.41807179 | F14: ='Evolutive SFP'!D36/'Evolutive SFP'!D26 -> 0.42927942 | G14: ='Evolutive SFP'!E36/'Evolutive SFP'!E26 -> 0.47990153 | H14: ='Evolutive SFP'!F36/'Evolutive SFP'!F26 -> 0.43730632 | I14: ='Evolutive SFP'!G36/'Evolutive SFP'!G26 -> 0.43519042 | J14: ='Evolutive SFP'!H36/'Evolutive SFP'!H26 -> 0.44110663 | K14: ='Evolutive SFP'!I36/'Evolutive SFP'!I26 -> 0.45297395 | ... CU14: ='Evolutive SFP'!CS36/'Evolutive SFP'!CS26 -> 0.094702676
B15: LA to TA ratio | D15: ='Evolutive SFP'!B4/'Evolutive SFP'!B26 -> 0.14571754 | E15: ='Evolutive SFP'!C4/'Evolutive SFP'!C26 -> 0.12852377 | F15: ='Evolutive SFP'!D4/'Evolutive SFP'!D26 -> 0.21418621 | G15: ='Evolutive SFP'!E4/'Evolutive SFP'!E26 -> 0.096936938 | H15: ='Evolutive SFP'!F4/'Evolutive SFP'!F26 -> 0.062504337 | I15: ='Evolutive SFP'!G4/'Evolutive SFP'!G26 -> 0.054525095 | J15: ='Evolutive SFP'!H4/'Evolutive SFP'!H26 -> 0.050771498 | K15: ='Evolutive SFP'!I4/'Evolutive SFP'!I26 -> 0.032696043 | ... CU15: ='Evolutive SFP'!CS4/'Evolutive SFP'!CS26 -> -0.025688349
A16: STRUCTURE | B16: NEA ratio | C16: Max 10% | D16: =('Evolutive SFP'!B7+'Evolutive SFP'!B20)/'Evolutive SFP'!B26 -> 0.48806613 | E16: =('Evolutive SFP'!C7+'Evolutive SFP'!C20)/'Evolutive SFP'!C26 -> 0.54543449 | F16: =('Evolutive SFP'!D7+'Evolutive SFP'!D20)/'Evolutive SFP'!D26 -> 0.49515474 | G16: =('Evolutive SFP'!E7+'Evolutive SFP'!E20)/'Evolutive SFP'!E26 -> 0.47894506 | H16: =('Evolutive SFP'!F7+'Evolutive SFP'!F20)/'Evolutive SFP'!F26 -> 0.49839952 | I16: =('Evolutive SFP'!G7+'Evolutive SFP'!G20)/'Evolutive SFP'!G26 -> 0.49030077 | J16: =('Evolutive SFP'!H7+'Evolutive SFP'!H20)/'Evolutive SFP'!H26 -> 0.49605703 | K16: =('Evolutive SFP'!I7+'Evolutive SFP'!I20)/'Evolutive SFP'!I26 -> 0.50848057 | ... CU16: =('Evolutive SFP'!CS7+'Evolutive SFP'!CS20)/'Evolutive SFP'!CS26 -> 0.3011459
B17: LB ratio | C17: Max 5% | D17: ='Evolutive SFP'!B20/'Evolutive SFP'!B26 -> 0.26049891 | E17: ='Evolutive SFP'!C20/'Evolutive SFP'!C26 -> 0.25765617 | F17: ='Evolutive SFP'!D20/'Evolutive SFP'!D26 -> 0.22241994 | G17: ='Evolutive SFP'!E20/'Evolutive SFP'!E26 -> 0.4557139 | H17: ='Evolutive SFP'!F20/'Evolutive SFP'!F26 -> 0.46545298 | I17: ='Evolutive SFP'!G20/'Evolutive SFP'!G26 -> 0.45782955 | J17: ='Evolutive SFP'!H20/'Evolutive SFP'!H26 -> 0.46314439 | K17: ='Evolutive SFP'!I20/'Evolutive SFP'!I26 -> 0.47468246 | ... CU17: ='Evolutive SFP'!CS20/'Evolutive SFP'!CS26 -> 0.22342615
B18: PI to Deposit ratio | C18: Max 5% | D18: ='Evolutive SFP'!B12/'Evolutive SFP'!B30 -> 0.14759472 | E18: ='Evolutive SFP'!C12/'Evolutive SFP'!C30 -> 0.15299229 | F18: ='Evolutive SFP'!D12/'Evolutive SFP'!D30 -> 0.12918835 | G18: ='Evolutive SFP'!E12/'Evolutive SFP'!E30 -> 0.14739939 | H18: ='Evolutive SFP'!F12/'Evolutive SFP'!F30 -> 0.13012118 | I18: ='Evolutive SFP'!G12/'Evolutive SFP'!G30 -> 0.12712904 | J18: ='Evolutive SFP'!H12/'Evolutive SFP'!H30 -> 0.13184286 | K18: ='Evolutive SFP'!I12/'Evolutive SFP'!I30 -> 0.13721346 | ... CP18: ='Evolutive SFP'!CN12/'Evolutive SFP'!CN30 -> 0.00055005525 | CQ18: ='Evolutive SFP'!CO11/'Evolutive SFP'!CO30 -> 0.9233433 | CR18: ='Evolutive SFP'!CP11/'Evolutive SFP'!CP30 -> 0.93371844 | CS18: ='Evolutive SFP'!CQ11/'Evolutive SFP'!CQ30 -> 0.96278858 | CT18: ='Evolutive SFP'!CR12/'Evolutive SFP'!CR30 -> 0.0002299592 | CU18: ='Evolutive SFP'!CS12/'Evolutive SFP'!CS30 -> 0.00058909708
B19: PI to CC ratio | C19: Max 40% | D19: ='Evolutive SFP'!B12/('CAELS (2)'!D3*1000000) -> 0.62499104 | E19: ='Evolutive SFP'!C12/('CAELS (2)'!E3*1000000) -> 0.2997429 | F19: ='Evolutive SFP'!D12/('CAELS (2)'!F3*1000000) -> #DIV/0! | G19: ='Evolutive SFP'!E12/('CAELS (2)'!G3*1000000) -> 0.29915739 | H19: ='Evolutive SFP'!F12/('CAELS (2)'!H3*1000000) -> 0.29373859 | I19: ='Evolutive SFP'!G12/('CAELS (2)'!I3*1000000) -> 0.31074583 | J19: ='Evolutive SFP'!H12/('CAELS (2)'!J3*1000000) -> 0.3098641 | K19: ='Evolutive SFP'!I12/('CAELS (2)'!K3*1000000) -> 0.33153707 | ... CP19: ='Evolutive SFP'!CN12/('CAELS (2)'!CP3*1000000) -> 0.0010606667 | CQ19: ='Evolutive SFP'!CO11/('CAELS (2)'!CQ3*1000000) -> 1.727325 | CR19: ='Evolutive SFP'!CP11/('CAELS (2)'!CR3*1000000) -> 1.8783661 | CS19: ='Evolutive SFP'!CQ11/('CAELS (2)'!CS3*1000000) -> 1.8181813 | CT19: ='Evolutive SFP'!CR12/('CAELS (2)'!CT3*1000000) -> 0.00044905378 | CU19: ='Evolutive SFP'!CS12/('CAELS (2)'!CU3*1000000) -> 0.00042646081
B20: Gross loans/TA | D20: ='Evolutive SFP'!B14/'Evolutive SFP'!B26 -> 0.29265804 | E20: ='Evolutive SFP'!C14/'Evolutive SFP'!C26 -> 0.30746014 | F20: ='Evolutive SFP'!D14/'Evolutive SFP'!D26 -> 0.27422366 | G20: ='Evolutive SFP'!E14/'Evolutive SFP'!E26 -> 0.37189575 | H20: ='Evolutive SFP'!F14/'Evolutive SFP'!F26 -> 0.38419483 | I20: ='Evolutive SFP'!G14/'Evolutive SFP'!G26 -> 0.39952832 | J20: ='Evolutive SFP'!H14/'Evolutive SFP'!H26 -> 0.39635854 | K20: ='Evolutive SFP'!I14/'Evolutive SFP'!I26 -> 0.40018695 | ... CU20: ='Evolutive SFP'!CS14/'Evolutive SFP'!CS26 -> 0.39729413
A21: FUNDING MIX | B21: Total Deposits/Total Assets | D21: ='Evolutive SFP'!B30/'Evolutive SFP'!B26 -> 0.49542222 | E21: ='Evolutive SFP'!C30/'Evolutive SFP'!C26 -> 0.36094899 | F21: ='Evolutive SFP'!D30/'Evolutive SFP'!D26 -> 0.38548435 | G21: ='Evolutive SFP'!E30/'Evolutive SFP'!E26 -> 0.32699584 | H21: ='Evolutive SFP'!F30/'Evolutive SFP'!F26 -> 0.38729228 | I21: ='Evolutive SFP'!G30/'Evolutive SFP'!G26 -> 0.39068862 | J21: ='Evolutive SFP'!H30/'Evolutive SFP'!H26 -> 0.38184154 | K21: ='Evolutive SFP'!I30/'Evolutive SFP'!I26 -> 0.37676687 | ... CU21: ='Evolutive SFP'!CS30/'Evolutive SFP'!CS26 -> 0.37584942
B22: BOSA Deposits/Total Assets | D22: ='Evolutive SFP'!B29/'Evolutive SFP'!B26 -> 0.14232084 | E22: ='Evolutive SFP'!C29/'Evolutive SFP'!C26 -> 0.13387297 | F22: ='Evolutive SFP'!D29/'Evolutive SFP'!D26 -> 0.1207279 | G22: ='Evolutive SFP'!E29/'Evolutive SFP'!E26 -> 0.11784263 | H22: ='Evolutive SFP'!F29/'Evolutive SFP'!F26 -> 0.12661535 | I22: ='Evolutive SFP'!G29/'Evolutive SFP'!G26 -> 0.13059523 | J22: ='Evolutive SFP'!H29/'Evolutive SFP'!H26 -> 0.12338586 | K22: ='Evolutive SFP'!I29/'Evolutive SFP'!I26 -> 0.12616413 | ... CU22: ='Evolutive SFP'!CS29/'Evolutive SFP'!CS26 -> 0.11706421
B23: FOSA Deposits/Total Assets | D23: =('Evolutive SFP'!B27+'Evolutive SFP'!B28)/'Evolutive SFP'!B26 -> 0.35310138 | E23: =('Evolutive SFP'!C27+'Evolutive SFP'!C28)/'Evolutive SFP'!C26 -> 0.22707602 | F23: =('Evolutive SFP'!D27+'Evolutive SFP'!D28)/'Evolutive SFP'!D26 -> 0.26475646 | G23: =('Evolutive SFP'!E27+'Evolutive SFP'!E28)/'Evolutive SFP'!E26 -> 0.20915322 | H23: =('Evolutive SFP'!F27+'Evolutive SFP'!F28)/'Evolutive SFP'!F26 -> 0.26067692 | I23: =('Evolutive SFP'!G27+'Evolutive SFP'!G28)/'Evolutive SFP'!G26 -> 0.26009339 | J23: =('Evolutive SFP'!H27+'Evolutive SFP'!H28)/'Evolutive SFP'!H26 -> 0.25845568 | K23: =('Evolutive SFP'!I27+'Evolutive SFP'!I28)/'Evolutive SFP'!I26 -> 0.25060274 | ... CU23: =('Evolutive SFP'!CS27+'Evolutive SFP'!CS28)/'Evolutive SFP'!CS26 -> 0.2587852
A24: GROWTH RATIOS | B24: Total Assets | E24: =(Financials!D4-Financials!C4)/Financials!C4 -> 0.053690144 | F24: =(Financials!E4-Financials!D4)/Financials!D4 -> 0.10888185 | G24: =(Financials!F4-Financials!E4)/Financials!E4 -> 0.026368251 | H24: =(Financials!G4-Financials!F4)/Financials!F4 -> -0.043574592 | I24: =(Financials!H4-Financials!G4)/Financials!G4 -> 0.014638445 | J24: =(Financials!I4-Financials!H4)/Financials!H4 -> -0.013412214 | K24: =(Financials!J4-Financials!I4)/Financials!I4 -> 0.94760266 | L24: =(Financials!K4-Financials!J4)/Financials!J4 -> -0.512337 | ... CU24: =(Financials!CT4-Financials!CS4)/Financials!CS4 -> 0.0042244376
B25: Total Deposits | D25: =Financials!D5/Financials!C5-1 -> -0.23231463 | E25: =Financials!E5/Financials!D5-1 -> 0.18425766 | F25: =Financials!F5/Financials!E5-1 -> -0.12935985 | G25: =Financials!G5/Financials!F5-1 -> 0.13278556 | H25: =Financials!H5/Financials!G5-1 -> 0.023536278 | I25: =Financials!I5/Financials!H5-1 -> -0.035753337 | J25: =Financials!J5/Financials!I5-1 -> 0.92171906 | K25: =Financials!K5/Financials!J5-1 -> -0.53734598 | ... CU25: =Financials!CU5/Financials!CT5-1 -> -1
B26: BOSA Deposits | D26: =Financials!D6/Financials!C6-1 -> -0.0088547237 | E26: =Financials!G6/Financials!D6-1 -> 0.029515903 | F26: =Financials!H6/Financials!E6-1 -> 0.077420715 | G26: =Financials!I6/Financials!F6-1 -> 0.0024463072 | H26: =Financials!J6/Financials!G6-1 -> 0.9426606 | I26: =Financials!K6/Financials!H6-1 -> -0.11167451 | J26: =Financials!L6/Financials!I6-1 -> -0.046988087 | K26: =Financials!M6/Financials!J6-1 -> -0.51527218 | L26: =Financials!N6/Financials!K6-1 -> 0.013785428 | ... CU26: =Financials!CW6/Financials!CT6-1 -> -1
B27: FOSA Deposits | D27: =Financials!D7/Financials!C7-1 -> -0.32238225 | E27: =Financials!G7/Financials!D7-1 -> 0.24959968 | F27: =Financials!H7/Financials!E7-1 -> -0.021528056 | G27: =Financials!I7/Financials!F7-1 -> 0.18309519 | H27: =Financials!J7/Financials!G7-1 -> 0.87426348 | I27: =Financials!K7/Financials!H7-1 -> -0.15827356 | J27: =Financials!L7/Financials!I7-1 -> -0.17449455 | K27: =Financials!M7/Financials!J7-1 -> -0.57458793 | L27: =Financials!N7/Financials!K7-1 -> -0.069048362 | ... CU27: =Financials!CW7/Financials!CT7-1 -> -1
B28: Total Loans & advances | D28: =Financials!D31/Financials!C31-1 -> 0.10698385 | E28: =Financials!G31/Financials!D31-1 -> 0.36019847 | F28: =Financials!H31/Financials!E31-1 -> 0.45113654 | G28: =Financials!I31/Financials!F31-1 -> 0.020387568 | H28: =Financials!J31/Financials!G31-1 -> 1.030761 | I28: =Financials!K31/Financials!H31-1 -> -0.076395419 | J28: =Financials!L31/Financials!I31-1 -> -0.082465571 | K28: =Financials!M31/Financials!J31-1 -> -0.5351027 | L28: =Financials!N31/Financials!K31-1 -> -0.016640504 | ... CU28: =Financials!CW31/Financials!CT31-1 -> -1
B29: Core capital | D29: =Financials!D11/Financials!C11-1 -> 0.73610117 | E29: =Financials!G11/Financials!D11-1 -> -0.40906467 | F29: =Financials!H11/Financials!E11-1 -> -0.44569956 | G29: =Financials!I11/Financials!F11-1 -> -0.046181999 | H29: =Financials!J11/Financials!G11-1 -> 0.95248053 | I29: =Financials!K11/Financials!H11-1 -> 0.007779852 | J29: =Financials!L11/Financials!I11-1 -> 0.0077720195 | K29: =Financials!M11/Financials!J11-1 -> -0.50750475 | L29: =Financials!N11/Financials!K11-1 -> -0.015001789 | ... CU29: =Financials!CW11/Financials!CT11-1 -> -1
B30: Turnover | D30: =Financials!D37/Financials!C37-1 -> 0.27995599 | E30: =Financials!G37/Financials!D37-1 -> -0.92511335 | F30: =Financials!H37/Financials!E37-1 -> -0.86891384 | G30: =Financials!I37/Financials!F37-1 -> 1.4751376 | H30: =Financials!J37/Financials!G37-1 -> 4.7740024 | I30: =Financials!K37/Financials!H37-1 -> 1.1942473 | J30: =Financials!L37/Financials!I37-1 -> 0.89882119 | K30: =Financials!M37/Financials!J37-1 -> 0.25486461 | L30: =Financials!N37/Financials!K37-1 -> 5.6811849 | ... CU30: =Financials!CW37/Financials!CT37-1 -> -1
B31: Membership
B32: Expenses | D32: ='Evolutitve SCI'!C38/'Evolutitve SCI'!B38-1 -> 0.2638822 | E32: ='Evolutitve SCI'!E38/'Evolutitve SCI'!C38-1 -> -0.92717636 | F32: ='Evolutitve SCI'!F38/'Evolutitve SCI'!D38-1 -> -0.94128374 | G32: ='Evolutitve SCI'!G38/'Evolutitve SCI'!E38-1 -> 1.028469 | H32: ='Evolutitve SCI'!H38/'Evolutitve SCI'!F38-1 -> 2.4685073 | I32: ='Evolutitve SCI'!I38/'Evolutitve SCI'!G38-1 -> 3.2836504 | J32: ='Evolutitve SCI'!J38/'Evolutitve SCI'!H38-1 -> 0.7885561 | K32: ='Evolutitve SCI'!K38/'Evolutitve SCI'!I38-1 -> -0.29528124 | L32: ='Evolutitve SCI'!L38/'Evolutitve SCI'!J38-1 -> 0.57680951 | ... CU32: ='Evolutitve SCI'!CU38/'Evolutitve SCI'!CS38-1 -> #DIV/0!
A33: Efficiency Ratios | B33: FinCost-Deposits/Avg Deposits | E33: =Financials!D44/('Evolutive SFP'!B29+'Evolutive SFP'!C29)/2 -> 0.006732922 | F33: =Financials!E44/('Evolutive SFP'!C29+'Evolutive SFP'!D29)/2 -> 0.0089328521 | G33: =Financials!F44/('Evolutive SFP'!D29+'Evolutive SFP'!E29)/2 -> 0.00036170327 | H33: =Financials!G44/('Evolutive SFP'!E29+'Evolutive SFP'!F29)/2 -> 0.00052585706 | I33: =Financials!H44/('Evolutive SFP'!F29+'Evolutive SFP'!G29)/2 -> 0.0013457461 | J33: =Financials!I44/('Evolutive SFP'!G29+'Evolutive SFP'!H29)/2 -> 0.0023331342 | K33: =Financials!J44/('Evolutive SFP'!H29+'Evolutive SFP'!I29)/2 -> 0.0044338139 | L33: =Financials!K44/('Evolutive SFP'!I29+'Evolutive SFP'!J29)/2 -> 0.0025653532 | ... CU33: =Financials!CT44/('Evolutive SFP'!CR29+'Evolutive SFP'!CS29)/2 -> 0.0037920945
B34: FinCost-Shares/Avg Share capital | E34: =Financials!D45/('Evolutive SFP'!B38+'Evolutive SFP'!C38)/2 -> 0 | F34: =Financials!E45/('Evolutive SFP'!C38+'Evolutive SFP'!D38)/2 -> 0 | G34: =Financials!F45/('Evolutive SFP'!D38+'Evolutive SFP'!E38)/2 -> 0 | H34: =Financials!G45/('Evolutive SFP'!E38+'Evolutive SFP'!F38)/2 -> 0 | I34: =Financials!H45/('Evolutive SFP'!F38+'Evolutive SFP'!G38)/2 -> 0 | J34: =Financials!I45/('Evolutive SFP'!G38+'Evolutive SFP'!H38)/2 -> 0 | K34: =Financials!J45/('Evolutive SFP'!H38+'Evolutive SFP'!I38)/2 -> 0 | L34: =Financials!K45/('Evolutive SFP'!I38+'Evolutive SFP'!J38)/2 -> 0 | ... CU34: =Financials!CT45/('Evolutive SFP'!CR38+'Evolutive SFP'!CS38)/2 -> 0
B35: FinCost-Ext Loans/Avg Ext Loans | E35: =Financials!D46/(Financials!C31+Financials!D31)/2 -> 0.043191523 | F35: =Financials!E46/(Financials!D31+Financials!E31)/2 -> 0.049193375 | G35: =Financials!F46/(Financials!E31+Financials!F31)/2 -> 0.0018100636 | H35: =Financials!G46/(Financials!F31+Financials!G31)/2 -> 0 | I35: =Financials!H46/(Financials!G31+Financials!H31)/2 -> 0.0037408076 | J35: =Financials!I46/(Financials!H31+Financials!I31)/2 -> 0.0035745783 | K35: =Financials!J46/(Financials!I31+Financials!J31)/2 -> 0.013618093 | L35: =Financials!K46/(Financials!J31+Financials!K31)/2 -> 0.0069420411 | ... CU35: =Financials!CT46/(Financials!CS31+Financials!CT31)/2 -> 0
B36: OpEx/Average Total Assets | E36: =Financials!D47/(Financials!C4+Financials!D4)/2 -> 0.037092413 | F36: =Financials!E47/(Financials!D4+Financials!E4)/2 -> 0.031929876 | G36: =Financials!F47/(Financials!E4+Financials!F4)/2 -> 0.0022962286 | H36: =Financials!G47/(Financials!F4+Financials!G4)/2 -> 0.002220937 | I36: =Financials!H47/(Financials!G4+Financials!H4)/2 -> 0.0047383061 | J36: =Financials!I47/(Financials!H4+Financials!I4)/2 -> 0.0071928688 | K36: =Financials!J47/(Financials!I4+Financials!J4)/2 -> 0.013094088 | L36: =Financials!K47/(Financials!J4+Financials!K4)/2 -> 0.0081113195 | ... CU36: =Financials!CT47/(Financials!CS4+Financials!CT4)/2 -> 0.0026913157
B37: Opex/Turnover | E37: =Financials!D47/Financials!D37 -> 0.61860434 | F37: =Financials!E47/Financials!E37 -> 0.61906488 | G37: =Financials!F47/Financials!F37 -> 0.63921757 | H37: =Financials!G47/Financials!G37 -> 0.56505342 | I37: =Financials!H47/Financials!H37 -> 0.72876861 | J37: =Financials!I47/Financials!I37 -> 0.78993505 | K37: =Financials!J47/Financials!J37 -> 0.83225298 | L37: =Financials!K47/Financials!K37 -> 0.81851631 | ... CU37: =Financials!CT47/Financials!CT37 -> 0.53952511
B38: Avge yield on Net loans | E38: =Financials!D38/('Evolutive SFP'!C13+'Evolutive SFP'!B13)/2 -> 0.065646938 | F38: =Financials!E38/('Evolutive SFP'!D13+'Evolutive SFP'!C13)/2 -> 0.07859209 | G38: =Financials!F38/('Evolutive SFP'!E13+'Evolutive SFP'!D13)/2 -> 0.0044953459 | H38: =Financials!G38/('Evolutive SFP'!F13+'Evolutive SFP'!E13)/2 -> 0.0039594886 | I38: =Financials!H38/('Evolutive SFP'!G13+'Evolutive SFP'!F13)/2 -> 0.0069904328 | J38: =Financials!I38/('Evolutive SFP'!H13+'Evolutive SFP'!G13)/2 -> 0.01001621 | K38: =Financials!J38/('Evolutive SFP'!I13+'Evolutive SFP'!H13)/2 -> 0.01767662 | L38: =Financials!K38/('Evolutive SFP'!J13+'Evolutive SFP'!I13)/2 -> 0.011171998 | ... CU38: =Financials!CT38/('Evolutive SFP'!CS13+'Evolutive SFP'!CR13)/2 -> 0.0062371924
B39: Avge yield on Gross loans | E39: =Financials!D37/('Evolutive SFP'!C14+'Evolutive SFP'!B14)/2 -> 0.19970336 | F39: =Financials!E37/('Evolutive SFP'!D14+'Evolutive SFP'!C14)/2 -> 0.17786364 | G39: =Financials!F37/('Evolutive SFP'!E14+'Evolutive SFP'!D14)/2 -> 0.011097628 | H39: =Financials!G37/('Evolutive SFP'!F14+'Evolutive SFP'!E14)/2 -> 0.010400645 | I39: =Financials!H37/('Evolutive SFP'!G14+'Evolutive SFP'!F14)/2 -> 0.01658972 | J39: =Financials!I37/('Evolutive SFP'!H14+'Evolutive SFP'!G14)/2 -> 0.022881144 | K39: =Financials!J37/('Evolutive SFP'!I14+'Evolutive SFP'!H14)/2 -> 0.039442895 | L39: =Financials!K37/('Evolutive SFP'!J14+'Evolutive SFP'!I14)/2 -> 0.024893082 | ... CU39: =Financials!CT37/('Evolutive SFP'!CS14+'Evolutive SFP'!CR14)/2 -> 0.012651805
A41: ALL/Average Gross Loan portfolio

Sheet Evolutive SFP
B3: 2013 Audited | C3: 2014 Audited | D3: 2015 Audited | E3: 2016 Audited | F3: 42370 | G3: 42401 | H3: 42430 | I3: 42461 | J3: 42491 | K3: 42522 | L3: 42552 | M3: 42583 | N3: 42614 | O3: 42644 | P3: 42675 | Q3: 42705 | R3: Audited 2016 | S3: 42736 | T3: 42767 | U3: 42795 | V3: 42826 | W3: 42856 | X3: 42887 | Y3: 42917 | Z3: 42948 | AA3: 42979 | AB3: 43009 | AC3: 43040 | AD3: 43070 | AE3: Audited 2017 | AF3: 43101 | AG3: 43132 | AH3: 43160 | AI3: 43191 | AJ3: 43221 | AK3: 43252 | AL3: 43282 | AM3: 43313 | AN3: 43344 | AO3: 43374 | AP3: 43405 | AQ3: 43435 | AR3: Audited 2018 | AS3: 43466 | AT3: 43497 | AU3: 43525 | AV3: 43556 | AW3: 43586 | AX3: 43617 | AY3: 43647 | AZ3: 43678 | BA3: 43709 | BB3: 43739 | BC3: 43770 | BD3: 43800 | BE3: Audited2019 | BF3: 43831 | BG3: 43862 | BH3: 43891 | BI3: 43922 | BJ3: 43952 | BK3: 43983 | BL3: 44013 | BM3: 44044 | BN3: 44075 | BO3: 44105 | BP3: 44136 | BQ3: 44166 | BR3: Audited 2020 | BS3: 44197 | BT3: 44228 | BU3: 44256 | BV3: 44287 | BW3: 44317 | BX3: 44348 | BY3: 44378 | BZ3: 44409 | CA3: 44440 | CB3: 44470 | CC3: 44501 | CD3: 44531 | CE3: Audited 2021 | CF3: 44562 | CG3: 44593 | CH3: 44621 | CI3: 44652 | CJ3: 44682 | CK3: 44713 | CL3: 44743 | CM3: 44774 | CN3: 44805 | CO3: 44835 | CP3: 44866 | CQ3: 44896 | CR3: Audited 2022 | CS3: 44927 | CT3: 44958 | CU3: 44986 | CV3: 45017 | CW3: 45047
A4: Cash & cash Equivalent | B4: =SUM(B5:B6) -> 48159480 | C4: =SUM(C5:C6) -> 44757556 | D4: =SUM(D5:D6) -> 82710316 | E4: =SUM(E5:E6) -> 38420293 | F4: =SUM(F5:F6) -> 23693686 | G4: =SUM(G5:G6) -> 20971535 | H4: =SUM(H5:H6) -> 19265909 | I4: =SUM(I5:I6) -> 24163791 | ... CS4: =SUM(CS5:CS6) -> -13342379
A5: Cash In Hand | B5: 24191210 | C5: 15917353 | D5: 23182703 | E5: 15600124 | F5: 2905102 | G5: 2165682 | H5: 8964052 | I5: 8445808 | J5: 6460655 | K5: 5358831 | L5: 3892329 | M5: 1340041 | N5: 4158194 | O5: 86264247 | P5: 19156836 | Q5: 23806073 | R5: 23806073 | S5: 19370910 | T5: 14900455 | U5: 4870448.2 | V5: 8128181.7 | W5: 7555033 | X5: 7668864 | Y5: 29856502 | Z5: 9837900 | AA5: 57273755 | AB5: 44876260 | AC5: 27209625 | AD5: 16235537 | AE5: 16235537 | AF5: 9168589 | AG5: 19054403 | AH5: 5232305 | AI5: 5472940 | AJ5: 4071121 | AK5: 6902351 | AL5: 13606854 | AM5: 7085696 | AN5: 3820627 | AO5: 36107033 | AP5: 10370991 | AQ5: 3570118.3 | AR5: 3570118.3 | AS5: 11042681 | AT5: 8746086 | AU5: 6194519 | AV5: 9478302 | AW5: 3582148 | AX5: 7575945 | AY5: 9044277 | AZ5: 10688395 | BA5: 7108894 | BB5: 47364254 | BC5: 10217056 | BD5: 7918205.6 | BF5: 11683321 | BG5: 26020165 | BH5: 17774199 | BI5: 23055336 | BJ5: 18479062 | BK5: 14504890 | BM5: 39804411 | BN5: 21575514 | BO5: 50437171 | BP5: 22003764 | BQ5: 12623076 | BR5: ='[1]Draft accounts 2020'!$D$666 -> 12623076 | BS5: 17226617 | BT5: 19422922 | BU5: 14712181 | BV5: 13111204 | BW5: 20956748 | BX5: 8547077.3 | BY5: 13659649 | BZ5: 8933309.8 | CA5: 8431009.3 | CB5: 30713370 | CE5: 5989569.8 | CF5: 5363580.3 | CG5: 2257388.8 | CH5: 3879988.3 | CI5: 7134057.2 | CJ5: 9334661.4 | CK5: 11535720 | CL5: 40703387 | CM5: 35929261 | CN5: 8236404.4 | CO5: 7769412.3 | CP5: 8728570.1 | CQ5: 7093481.7 | CR5: =7093481.75 -> 7093481.8 | CS5: 6545584.4
A6: Cash at Bank | B6: 23968270 | C6: 28840203 | D6: 59527613 | E6: 22820169 | F6: 20788584 | G6: 18805853 | H6: 10301857 | I6: 15717983 | J6: -635948.28 | K6: 276689.11 | L6: 7069945.1 | M6: 6054457.1 | N6: 2006672.1 | O6: 1.5060728e+08 | P6: 1.5688878e+08 | Q6: 78695582 | R6: =102501655.09-R5 -> 78695582 | S6: 41574234 | T6: 13496336 | U6: 12018613 | V6: 5197794.3 | W6: 4918275.1 | X6: 13719484 | Y6: 48281181 | Z6: 19244293 | AA6: 62609595 | AB6: 7.5472002e+08 | AC6: 2.6938785e+08 | AD6: 62185737 | AE6: =78421274-16235536.85 -> 62185737 | AF6: 25759263 | AG6: 50112752 | AH6: 44487335 | AI6: 37955056 | AJ6: 41679118 | AK6: 60381816 | AL6: 60979482 | AM6: 56576376 | AN6: 59144583 | AO6: 3.0243707e+08 | AP6: 1.303618e+08 | AQ6: 1.4485507e+08 | AR6: =148425186.58-AR5 -> 1.4485507e+08 | AS6: 36488107 | AT6: 24675020 | AU6: 47400767 | AV6: 27939154 | AW6: 18893721 | AX6: 40272807 | AY6: 29758373 | AZ6: 23929398 | BA6: 27586920 | BB6: 39595519 | BC6: 28697762 | BD6: 15225746 | BF6: 14570807 | BG6: 20788975 | BH6: 81826276 | BI6: 93130189 | BJ6: 114086030 | BK6: 112964005 | BM6: 349289460 | BN6: 102782692 | BO6: 206079886 | BP6: 1.3989409e+08 | BQ6: 68539209 | BR6: ='[1]Draft accounts 2020'!$D$672-'[1]Draft accounts 2020'!$D$666 -> 68544209 | BS6: 41422945 | BT6: 85158059 | BU6: 67154357 | BV6: 94592469 | BW6: 69769880 | BX6: 71940530 | BY6: 68772615 | BZ6: 59486947 | CA6: 60672719 | CB6: 1.6503094e+08 | CE6: =9508131.7-5989569.84 -> 3518561.9 | CF6: 2200637.8 | CG6: -7254713.2 | CH6: -11432725 | CI6: -7184616.7 | CJ6: -26867184 | CK6: -13452662 | CL6: 92478670 | CM6: 47255722 | CN6: 32050649 | CO6: 13651718 | CP6: -3496922.9 | CQ6: -18984734 | CR6: =41.46+13286+3130758+1973576.41+388621.39+390956.49+275652.94+30000-15337551.35-9850075.04 -> -18984734 | CS6: -19887964
A7: Prepayment and Sundry | B7: 75210706 | C7: 1.002169e+08 | D7: 1.0531948e+08 | E7: 9207511.9 | F7: 12489133 | G7: 12489133 | H7: 12489133 | I7: 24978266 | J7: 12489133 | K7: 12489133 | L7: 12489133 | M7: 12489133 | N7: 12489133 | O7: 12489133 | P7: 24978266 | Q7: 9256907 | R7: =14420714.59+62098018.01 -> 76518733 | S7: 18513814 | T7: 9256907 | U7: 5250107 | V7: 5250107 | W7: 5250107 | X7: 5250107 | Y7: 15750321 | Z7: 10500214 | AA7: 26250535 | AB7: 10500214 | AC7: 15750321 | AD7: 5952520 | AE7: =6804770.95+49990796.59 -> 56795568 | AF7: 5952520 | AG7: 5952520 | AH7: 5952520 | AI7: 5952520 | AJ7: 5952520 | AK7: 16236716 | AL7: 15892642 | AM7: 16147384 | AN7: 15388577 | AO7: 8154766 | AP7: 8669242 | AQ7: 8411647.9 | AR7: =42204144.62-5000000 -> 37204145 | AS7: 25676409 | AT7: 25614419 | AU7: 25081340 | AV7: 24835164 | AW7: 24111337 | AX7: 22878958 | AY7: 21763057 | AZ7: 20440066 | BA7: 18675689 | BB7: 16617870 | BC7: 24320388 | BD7: 28115888 | BF7: 30105131 | BG7: 28736444 | BH7: 28650811 | BI7: 24094447 | BJ7: 22253974 | BK7: 22493631 | BM7: 51935187 | BN7: 18028296 | BO7: 9006376 | BP7: 28516614 | BQ7: 27523029 | BR7: ='[1]Draft accounts 2020'!$D$744 -> 44279560 | BS7: 28923107 | BT7: 28465473 | BU7: 28084165 | BV7: 26288320 | BW7: 25863394 | BX7: 27555825 | BY7: 27398042 | BZ7: 27423368 | CA7: 26494607 | CB7: 22692549 | CE7: 60916310 | CF7: 31781306 | CG7: 31748484 | CH7: 31542657 | CI7: 32573020 | CJ7: 33766181 | CK7: 34112377 | CL7: 41342289 | CM7: 34452561 | CN7: 35818343 | CO7: 36772945 | CP7: 37562594 | CQ7: 39913960 | CR7: 74737674 | CS7: 40367189
A8: Financial Investment | B8: =SUM(B9:B12) -> 36066278 | C8: =SUM(C9:C12) -> 19230840 | D8: =SUM(D9:D12) -> 19230840 | E8: =SUM(E9:E12) -> 34219862 | F8: =SUM(F9:F12) -> 35463780 | G8: =SUM(G9:G12) -> 36946633 | H8: =SUM(H9:H12) -> 36946633 | I8: =SUM(I9:I12) -> 73893265 | ... CS8: =SUM(CS9:CS12) -> 1.8416248e+08
A9: Government Security | B9: 0 | D9: 0 | E9: 0 | F9: 0 | G9: 0 | H9: 0 | I9: 0 | J9: 0 | K9: 0 | L9: 0 | M9: 0 | N9: 0 | O9: 0 | P9: 0 | Q9: 0 | S9: 0 | T9: 0 | U9: 0 | V9: 0 | W9: 0 | X9: 0 | Y9: 0 | Z9: 0 | AA9: 0 | AB9: 0 | AC9: 0 | AD9: 0 | AF9: 0 | AG9: 0 | AH9: 0 | AI9: 0 | AJ9: 0 | AK9: 0 | AL9: 0 | AM9: 0 | AN9: 0 | AO9: 0 | AP9: 0 | AQ9: 0 | AR9: 0 | AS9: 0 | AT9: 0 | AU9: 0 | AV9: 0 | AW9: 0 | AX9: 0 | AY9: 0 | AZ9: 0 | BA9: 0 | BB9: 0 | BC9: 0 | BD9: 0 | BF9: 0 | BG9: 0 | BH9: 0 | BI9: 0 | BJ9: 0 | BK9: 0 | BM9: 0 | BN9: 0 | BO9: 0 | BP9: 0 | BQ9: 0 | BS9: 0 | BT9: 0 | BU9: 0 | BV9: 0 | BW9: 0 | BX9: 0 | BY9: 0 | BZ9: 0 | CA9: 0 | CB9: 0 | CF9: 0 | CG9: 0 | CH9: 0 | CI9: 0 | CJ9: 0 | CK9: 0 | CL9: 0 | CM9: 0 | CN9: 0 | CO9: 0 | CP9: 0 | CQ9: 0 | CS9: 0
A10: Other Securities | B10: 64200 | D10: 0 | E10: 0 | F10: 0 | G10: 0 | H10: 0 | I10: 0 | J10: 0 | K10: 0 | L10: 0 | M10: 0 | N10: 0 | O10: 0 | P10: 0 | Q10: 0 | S10: 0 | T10: 0 | U10: 0 | V10: 0 | W10: 0 | X10: 0 | Y10: 0 | Z10: 0 | AA10: 0 | AB10: 0 | AC10: 0 | AD10: 0 | AF10: 0 | AG10: 0 | AH10: 0 | AI10: 0 | AJ10: 0 | AK10: 0 | AL10: 0 | AM10: 0 | AN10: 0 | AO10: 0 | AP10: 0 | AQ10: 0 | AR10: 0 | AS10: 0 | AT10: 0 | AU10: 0 | AV10: 0 | AW10: 0 | AX10: 0 | AY10: 0 | AZ10: 0 | BA10: 0 | BB10: 0 | BC10: 0 | BD10: 0 | BF10: 0 | BG10: 0 | BH10: 0 | BI10: 0 | BJ10: 0 | BK10: 0 | BM10: 0 | BN10: 0 | BO10: 0 | BP10: 0 | BQ10: 0 | BS10: 0 | BT10: 0 | BU10: 0 | BV10: 0 | BW10: 0 | BX10: 0 | BY10: 0 | BZ10: 0 | CA10: 0 | CB10: 0 | CF10: 0 | CG10: 0 | CH10: 0 | CI10: 0 | CJ10: 0 | CK10: 0 | CL10: 0 | CM10: 0 | CN10: 0 | CO10: 0 | CP10: 0 | CQ10: 0 | CS10: 0
A11: Balances with Other Saccos | B11: 11835438 | D11: 0 | E11: 15116522 | F11: 16360440 | G11: 17843293 | H11: 17843293 | I11: 35686585 | J11: 17843293 | K11: 17843293 | L11: 18232726 | M11: 18232726 | N11: 18232726 | O11: 18232726 | P11: 255000 | Q11: 127500 | S11: 255000 | T11: 127500 | U11: 127500 | V11: 127500 | W11: 127500 | X11: 127500 | Y11: 382500 | Z11: 255000 | AA11: 637500 | AB11: 255000 | AC11: 382500 | AD11: 127500 | AE11: =115000+11250 -> 126250 | AF11: 127500 | AG11: 127500 | AH11: 127500 | AI11: 127500 | AJ11: 127500 | AK11: 127500 | AL11: 127500 | AM11: 127500 | AN11: 127500 | AO11: 127500 | AP11: 127500 | AQ11: 127500 | AR11: =51000+115000+12500 -> 178500 | AS11: 127500 | AT11: 127500 | AU11: 127500 | AV11: 127500 | AW11: 127500 | AX11: 127500 | AY11: 127500 | AZ11: 127500 | BA11: 127500 | BB11: 127500 | BC11: 127500 | BD11: 127500 | BF11: 127500 | BG11: 127500 | BH11: 127500 | BI11: 127500 | BJ11: 127500 | BK11: 127500 | BM11: 382500 | BN11: 127500 | BO11: 127500 | BP11: 255000 | BQ11: 115000 | BR11: =130896272.03-BR12 -> 1.3089093e+08 | BS11: 115000 | BT11: 115000 | BU11: 115000 | BV11: 115000 | BW11: 115000 | BX11: 115000 | BY11: 115000 | BZ11: 115000 | CA11: 115000 | CB11: 115000 | CE11: =184162473.9-CE12 -> 1.8415966e+08 | CF11: 130781271 | CG11: 130781271 | CH11: 130781271 | CI11: 130781271 | CJ11: 130781271 | CK11: 1.8404748e+08 | CL11: 1.8404748e+08 | CM11: 1.8404748e+08 | CN11: 1.8404748e+08 | CO11: 1.8404748e+08 | CP11: 1.8404748e+08 | CQ11: 1.8404748e+08 | CR11: =187023834+318750.3+51000+115000+12500 -> 1.8752108e+08 | CS11: 1.8404748e+08
A12: Investment In Companies | B12: 24166640 | C12: 19230840 | D12: 19230840 | E12: 19103340 | F12: 19103340 | G12: 19103340 | H12: 19103340 | I12: 38206680 | J12: 19103340 | K12: 19103340 | L12: 19103340 | M12: 19103340 | N12: 19103340 | O12: 19103340 | P12: 38206680 | Q12: 19103340 | R12: 24230840 | S12: 38206680 | T12: 19103340 | U12: 24103340 | V12: 24103340 | W12: 24103340 | X12: 24103340 | Y12: 72310020 | Z12: 48206680 | AA12: 120516700 | AB12: 48206680 | AC12: 72310020 | AD12: 24103340 | AE12: =24230840-AE11 -> 24104590 | AF12: 24103340 | AG12: 24103340 | AH12: 24103340 | AI12: 24103340 | AJ12: 24103340 | AK12: 24103340 | AL12: 19103340 | AM12: 19103340 | AN12: 19103340 | AO12: 19103340 | AP12: 19103340 | AQ12: 19103340 | AR12: =174388650+40450+11250+643940 -> 175084290 | AS12: 19103340 | AT12: 19103340 | AU12: 19103340 | AV12: 19103340 | AW12: 19103340 | AX12: 19103340 | AY12: 19103340 | AZ12: 175135290 | BA12: 175135290 | BB12: 175135290 | BC12: 175135290 | BD12: 175135290 | BF12: 175135290 | BG12: 175135290 | BH12: 184323752 | BI12: 184323752 | BJ12: 184323752 | BK12: 184323752 | BM12: 552971256 | BN12: 184323752 | BO12: 184323752 | BP12: 368647504 | BQ12: 184115313 | BR12: 5342.8 | BS12: 184115313 | BT12: 184115313 | BU12: 184115313 | BV12: 184115313 | BW12: 184115313 | BX12: 130781271 | BY12: 130781271 | BZ12: 130781271 | CA12: 130781271 | CB12: 130781271 | CE12: 2812 | CF12: 115000 | CG12: 115000 | CH12: 115000 | CI12: 115000 | CJ12: 115000 | CK12: 115000 | CL12: 115000 | CM12: 115000 | CN12: 115000 | CO12: 115000 | CP12: 115000 | CQ12: 115000 | CR12: =38933.13+4611.68 -> 43544.81 | CS12: 115000
A13: Net Loan Portfolio | B13: =B14-B15 -> 84967806 | C13: =C14-C15 -> 94311040 | D13: =D14-D15 -> 93010285 | E13: =E14-E15 -> 1.3387641e+08 | F13: =F14-F15 -> 1.3098557e+08 | G13: =G14-G15 -> 1.3812322e+08 | H13: =H14-H15 -> 1.3501521e+08 | I13: =I14-I15 -> 2.6519709e+08 | ... CS13: =CS14-CS15 -> 1.9216066e+08 | CV13: =11891251.95-11887147 -> 4104.95
A14: Gross Loan Portfolio | B14: 96723149 | C14: 1.0707096e+08 | D14: 105894421 | E14: 1.4739834e+08 | F14: 145637760 | G14: 1.5366726e+08 | H14: 150403433 | I14: 295755486 | J14: 141927789 | K14: 138000328 | L14: 137495928 | M14: 139566039 | N14: 137451836 | O14: 73197047 | P14: 1.4885766e+08 | Q14: 55593921 | R14: 55593921 | S14: 2.3821571e+08 | T14: 141015739 | U14: 135436565 | V14: 132727985 | W14: 1.3002279e+08 | X14: 128080317 | Y14: 3.8064001e+08 | Z14: 276746700 | AA14: 676424635 | AB14: 152408112 | AC14: 231992676 | AD14: 68793951 | AE14: 68793951 | AF14: 141381095 | AG14: 141404734 | AH14: 141037223 | AI14: 140863573 | AJ14: 139164157 | AK14: 139797860 | AL14: 141481310 | AM14: 146106598 | AN14: 146675802 | AO14: 82475169 | AP14: 85885819 | AQ14: 79430798 | AR14: =79430797.92 -> 79430798 | AS14: 1.8735835e+08 | AT14: 1.9022386e+08 | AU14: 1.8989368e+08 | AV14: 1.9397416e+08 | AW14: 1.9682868e+08 | AX14: 1.9541412e+08 | AY14: 1.949776e+08 | AZ14: 1.9574019e+08 | BA14: 1.9078437e+08 | BB14: 1.5154295e+08 | BC14: 1.908062e+08 | BD14: 2.0962724e+08 | BF14: 2.2064624e+08 | BG14: 2.2011328e+08 | BH14: 2.1586534e+08 | BI14: 2.1000193e+08 | BJ14: 2.05317e+08 | BK14: 2.0375612e+08 | BM14: 5.9664985e+08 | BN14: 194469461 | BO14: 147931620 | BP14: 3.5427705e+08 | BQ14: 1.8689716e+08 | BR14: 1.879707e+08 | BS14: 2.0154244e+08 | BT14: 2.0331336e+08 | BU14: 2.0543681e+08 | BV14: 2.0304729e+08 | BW14: 2.0437697e+08 | BX14: 1.8181163e+08 | BY14: 185810871 | BZ14: 1.8816687e+08 | CA14: 1.8534577e+08 | CB14: 1.4973473e+08 | CE14: 1.7382977e+08 | CF14: 1.7193674e+08 | CG14: 1.7381435e+08 | CH14: 1.7291744e+08 | CI14: 1.7314388e+08 | CJ14: 1.8207436e+08 | CK14: 1.8562745e+08 | CL14: 163308792 | CM14: 1.7602823e+08 | CN14: 1.8514164e+08 | CO14: 1.9273268e+08 | CP14: 1.9852274e+08 | CQ14: 2.0234575e+08 | CR14: 2.0235575e+08 | CS14: 2.0635227e+08
A15: Allowance For Loan Loss | B15: 11755343 | C15: 12759924 | D15: 12884136 | E15: 13521929 | F15: 14652190 | G15: 15544042 | H15: 15388223 | I15: 30558396 | J15: 14607283 | K15: 16413553 | L15: 16401453 | M15: 16485865 | N15: 16121662 | O15: 14831688 | P15: 28788012 | Q15: 17888755 | R15: 17888756 | S15: 35814064 | T15: 18397974 | U15: 17372183 | V15: 17345097 | W15: 17345097 | X15: 16434025 | Y15: 49119223 | Z15: 33776022 | AA15: 86516519 | AB15: 34084866 | AC15: 51451324 | AD15: 17615426 | AE15: 17615426 | AF15: 16418756 | AG15: 15404995 | AH15: 15393980 | AI15: 15359325 | AJ15: 14347331 | AK15: 14645411 | AL15: 15791635 | AM15: 15675925 | AN15: 15690124 | AO15: 13499682 | AP15: 16405147 | AQ15: 18868723 | AR15: 18868723 | AS15: 15668321 | AT15: 15706616 | AU15: 16146615 | AV15: 16497027 | AW15: 16720527 | AX15: 16568360 | AY15: 16480410 | AZ15: 16674363 | BA15: 16656408 | BB15: 19960914 | BC15: 23970506 | BD15: 21541242 | BF15: 19681992 | BG15: 19500343 | BH15: 27193856 | BI15: 25267198 | BJ15: 23840367 | BK15: 22600296 | BM15: 65973817 | BN15: 20744769 | BO15: 17353245 | BP15: 39348088 | BQ15: 13353313 | BR15: 14426854 | BS15: 12813443 | BT15: 11724251 | BU15: 11758210 | BV15: 12454080 | BW15: 12958427 | BX15: 13180213 | BY15: 13495264 | BZ15: 15795094 | CA15: 15122250 | CB15: 13700800 | CE15: 13421527 | CF15: 15902970 | CG15: 16549098 | CH15: 16690077 | CI15: 16697813 | CJ15: 16919953 | CK15: 20215974 | CL15: 18087960 | CM15: 18560803 | CN15: 18751211 | CO15: 19134182 | CP15: 19858362 | CQ15: 12560097 | CR15: 12560097 | CS15: 14191608
A16: Accounts Recievables | B16: =SUM(B17:B19) -> 0 | C16: =SUM(C17:C19) -> 0 | D16: =SUM(D17:D19) -> 0 | E16: =SUM(E17:E19) -> 0 | F16: =SUM(F17:F19) -> 0 | G16: =SUM(G17:G19) -> 0 | H16: =SUM(H17:H19) -> 0 | I16: =SUM(I17:I19) -> 0 | ... CS16: =SUM(CS17:CS19) -> 0
A17: Tax Recoverable | B17: 0 | D17: 0 | E17: 0 | F17: 0 | G17: 0 | H17: 0 | I17: 0 | J17: 0 | K17: 0 | L17: 0 | M17: 0 | N17: 0 | O17: 0 | P17: 0 | Q17: 0 | R17: 0 | S17: 0 | T17: 0 | U17: 0 | V17: 0 | W17: 0 | X17: 0 | AP17: 0 | AQ17: 0 | BR17: 450000 | BS17: 0 | BT17: 0 | BU17: 0 | BV17: 0 | BW17: 0 | BX17: 0 | BY17: 0 | BZ17: 0 | CA17: 0 | CB17: 0 | CF17: 0 | CG17: 0 | CH17: 0 | CI17: 0 | CJ17: 0 | CK17: 0 | CL17: 0 | CM17: 0 | CN17: 0 | CO17: 0 | CP17: 0 | CQ17: 0 | CR17: 0 | CS17: 0
A18: Deffered Tax Assets | B18: 0 | D18: 0 | E18: 0 | F18: 0 | G18: 0 | H18: 0 | I18: 0 | J18: 0 | K18: 0 | L18: 0 | M18: 0 | N18: 0 | O18: 0 | P18: 0 | Q18: 0 | R18: 0 | S18: 0 | T18: 0 | U18: 0 | V18: 0 | W18: 0 | X18: 0 | AP18: 0 | AQ18: 0 | BS18: 0 | BT18: 0 | BU18: 0 | BV18: 0 | BW18: 0 | BX18: 0 | BY18: 0 | BZ18: 0 | CA18: 0 | CB18: 0 | CF18: 0 | CG18: 0 | CH18: 0 | CI18: 0 | CJ18: 0 | CK18: 0 | CL18: 0 | CM18: 0 | CN18: 0 | CO18: 0 | CP18: 0 | CQ18: 0 | CR18: 0 | CS18: 0
A19: Retirement Benefit Assets | D19: 0 | E19: 0 | F19: 0 | G19: 0 | H19: 0 | I19: 0 | J19: 0 | K19: 0 | L19: 0 | M19: 0 | N19: 0 | O19: 0 | P19: 0 | Q19: 0 | R19: 0 | S19: 0 | T19: 0 | U19: 0 | V19: 0 | W19: 0 | X19: 0 | AP19: 0 | AQ19: 0 | BS19: 0 | BT19: 0 | BU19: 0 | BV19: 0 | BW19: 0 | BX19: 0 | BY19: 0 | BZ19: 0 | CA19: 0 | CB19: 0 | CF19: 0 | CG19: 0 | CH19: 0 | CI19: 0 | CJ19: 0 | CK19: 0 | CL19: 0 | CM19: 0 | CN19: 0 | CO19: 0 | CP19: 0 | CQ19: 0 | CR19: 0 | CS19: 0
A20: Property&Equipments&Other Assets | B20: =SUM(B21:B25) -> 86094595 | C20: =SUM(C21:C25) -> 89727059 | D20: =SUM(D21:D25) -> 85889859 | E20: =SUM(E21:E25) -> 1.8061909e+08 | F20: =SUM(F21:F25) -> 1.764405e+08 | G20: =SUM(G21:G25) -> 1.7609119e+08 | H20: =SUM(H21:H25) -> 1.757462e+08 | I20: =SUM(I21:I25) -> 3.5081089e+08 | ... CS20: =SUM(CS21:CS25) -> 1.1604624e+08 | CU20: 74026832 | CV20: =CU20-CR20 -> -2975742.2
A21: Investment Properties | D21: 0 | E21: 75930282 | F21: 74108533 | G21: 73959025 | H21: 73809828 | I21: 1.4732188e+08 | J21: 76266616 | K21: 76132571 | L21: 76278221 | M21: 76523359 | N21: 76128471 | O21: 75974755 | P21: 1.5164272e+08 | Q21: 75667324 | S21: 1.5102914e+08 | T21: 75362131 | U21: 75210011 | V21: 75058208 | W21: 75058208 | X21: 74906722 | Y21: 2.2426665e+08 | Z21: 1.4920939e+08 | AA21: 372270765 | AB21: 1.4860785e+08 | AC21: 2.2246203e+08 | AD21: 73834258 | AE21: 71489608 | AF21: 73685321 | AG21: 73536695 | AH21: 73388378 | AI21: 73240370 | AJ21: 73092671 | AK21: 72945279 | AL21: 72798194 | AM21: 72651416 | AN21: 72504944 | AO21: 72358777 | AP21: 72212914 | AQ21: 72047018 | AS21: 71901805 | AT21: 71756894 | AU21: 71612285 | AV21: 71467977 | AW21: 71323970 | AX21: 71180264 | AY21: 71036856 | AZ21: 70893747 | BA21: 70750937 | BB21: 70608424 | BC21: 70466207 | BD21: 70304459 | BF21: 70162876 | BG21: 70021588 | BH21: 69880594 | BI21: 69739894 | BJ21: 69599488 | BK21: 69459373 | BM21: 2.0754006e+08 | BN21: 69180020 | BO21: 69040780 | BP21: 140608916 | BQ21: 68605464 | BS21: 68605464 | BT21: 68605464 | BU21: 68605464 | BV21: 68053290 | BW21: 67915247 | BX21: 67779504 | BY21: 67643182 | BZ21: 67506859 | CA21: 67371105 | CB21: 67235633 | CF21: 66830628 | CG21: 66696282 | CH21: 66562216 | CI21: 66428150 | CJ21: 66562216 | CK21: 66160019 | CL21: 66027070 | CM21: 65894399 | CN21: 65762004 | CO21: 65629609 | CP21: 65497766 | CQ21: 65366197 | CR21: =63021547.15+2344650 -> 65366197 | CS21: 65234903 | CU21: 2344650
A22: Property and Equipment | B22: 84021813 | C22: 88181510 | D22: 84809160 | E22: 12175559 | F22: 10374562 | G22: 10201658 | H22: 10032024 | I22: 19731189 | J22: 9702302 | K22: 9542081.9 | L22: 10235386 | M22: 10911810 | N22: 10124623 | O22: 9965700.1 | P22: 20178833 | Q22: 9921377.4 | R22: 85588701 | S22: 19536076 | T22: 9978528.8 | U22: 11257647 | V22: 11078336 | W22: 11084136 | X22: 11308527 | Y22: 33413607 | Z22: 21918021 | AA22: 53917402 | AB22: 21222420 | AC22: 31326395 | AD22: 9577525.4 | AE22: =83411783-71489608 -> 11922175 | AF22: 9432667.7 | AG22: 9293059.1 | AH22: 9153190.8 | AI22: 9015771.7 | AJ22: 8880753.1 | AK22: 8748087.5 | AL22: 8617728.5 | AM22: 8489630.5 | AN22: 8363749.1 | AO22: 8320575.6 | AP22: 8196984.1 | AQ22: 7970556.4 | AR22: 80017575 | AS22: 7852994.2 | AT22: 7737453.9 | AU22: 7623896 | AV22: 7512281.7 | AW22: 7402573 | AX22: 7294732.7 | AY22: 7188724.7 | AZ22: 7084513.2 | BA22: 6982063.5 | BB22: 6911341.6 | BC22: 6811563.9 | BD22: 7542854.8 | BF22: 7438423.4 | BG22: 7337237 | BH22: 7236112 | BI22: 7136609.1 | BJ22: 7038699.9 | BK22: 6990645.9 | BM22: 22188494 | BN22: 7396164.5 | BO22: 7293883.5 | BP22: 16730466 | BQ22: 6942588.8 | BR22: 75544366 | BS22: 6944189.8 | BT22: 9256307.6 | BU22: 9391307.6 | BV22: 8898183.2 | BW22: 8777866.8 | BX22: 8666662.2 | BY22: 8778147.5 | BZ22: 8714498.2 | CA22: 8599916.7 | CB22: 8701620.3 | CE22: 75445572 | CF22: 8370765.6 | CG22: 8262848.7 | CH22: 8156541.8 | CI22: 8055208.1 | CJ22: 8158583 | CK22: 7837621.2 | CL22: 7739505.3 | CM22: 7642792.3 | CN22: 8207148.1 | CO22: 8630411.3 | CP22: 8764183.3 | CQ22: 8660632.3 | CR22: =7019373.03+494423.65+1011935.9+134901.77 -> 8660634.3 | CS22: 8551198.3 | CU22: 63021547
A23: Prepaid Lease Rentals | D23: 0 | E23: 0 | F23: 0 | G23: 0 | H23: 0 | I23: 0 | J23: 0 | K23: 0 | L23: 0 | M23: 0 | N23: 0 | O23: 0 | P23: 0 | Q23: 0 | S23: 0 | T23: 0 | U23: 0 | V23: 0 | W23: 0 | X23: 0 | Y23: 0 | Z23: 0 | AA23: 0 | AB23: 0 | AC23: 0 | AD23: 0 | AF23: 0 | AG23: 0 | AH23: 0 | AI23: 0 | AJ23: 0 | AK23: 0 | AL23: 0 | AM23: 0 | AN23: 0 | AO23: 0 | AP23: 0 | AQ23: 0 | AS23: 0 | AT23: 0 | AU23: 0 | AV23: 0 | AW23: 0 | AX23: 0 | AY23: 0 | AZ23: 0 | BA23: 0 | BB23: 0 | BC23: 0 | BD23: 0 | BF23: 0 | BG23: 0 | BH23: 0 | BI23: 0 | BJ23: 0 | BK23: 0 | BM23: 0 | BN23: 0 | BO23: 0 | BP23: 0 | BQ23: 0 | BR23: 0 | BS23: 0 | BT23: 0 | BU23: 0 | BV23: 0 | BW23: 0 | BX23: 0 | BY23: 0 | BZ23: 0 | CA23: 0 | CB23: 0 | CC23: 0 | CD23: 0 | CE23: 0 | CF23: 0 | CG23: 0 | CH23: 0 | CI23: 0 | CJ23: 0 | CK23: 0 | CL23: 0 | CM23: 0 | CN23: 0 | CO23: 0 | CP23: 0 | CQ23: 0 | CR23: 0 | CS23: 0 | CU23: 494423.65
A24: Intangible Assets | B24: 2028532 | C24: 1495168.6 | D24: 997278.55 | E24: 1453677.8 | F24: 969604.25 | G24: 942697.74 | H24: 916537.87 | I24: 1782207.9 | J24: 866375.81 | K24: 842333.88 | L24: 818959.12 | M24: 796233 | N24: 774136 | O24: 752653.73 | P24: 1463535.2 | Q24: 1032036.7 | R24: 1032036.6 | S24: 2006795.4 | T24: 975553.43 | U24: 948481.83 | V24: 922161.46 | W24: 922161.46 | X24: 920240.29 | Y24: 2684110.9 | Z24: 1739751.2 | AA24: 4228682.7 | AB24: 1644534.7 | AC24: 2398348.3 | AD24: 888469.74 | AE24: 888469.55 | AF24: 863814.7 | AG24: 839843.85 | AH24: 816538.18 | AI24: 793879.25 | AJ24: 771849.1 | AK24: 750430.28 | AL24: 729605.89 | AM24: 709359.28 | AN24: 689674.52 | AO24: 1629174.6 | AP24: 1583965 | AQ24: 1385005.7 | AR24: 1385005.7 | AS24: 1346571.8 | AT24: 1309204.5 | AU24: 1272874 | AV24: 1237551.8 | AW24: 1203209.7 | AX24: 1169820.6 | AY24: 1137358.1 | AZ24: 1105796.4 | BA24: 1075110.6 | BB24: 1045276.3 | BC24: 1016269.8 | BD24: 1394702.7 | BF24: 1355999.7 | BG24: 1318370.8 | BH24: 1281786 | BI24: 1246216.4 | BJ24: 1211633.9 | BK24: 1178011.1 | BM24: 3340615.7 | BN24: 1115730 | BO24: 1084768.5 | BP24: 2789400 | BQ24: 930266.74 | BR24: 930266.74 | BS24: 930266.74 | BT24: 930266.74 | BU24: 930266.74 | BV24: 827007.13 | BW24: 801192.25 | BX24: 4710781.8 | BY24: 4580057.6 | BZ24: 4449334.8 | CA24: 4325866 | CB24: 4205823.2 | CE24: 3889895.2 | CF24: 3781951.2 | CG24: 3677002 | CH24: 3574965.2 | CI24: 3472928.4 | CJ24: 3574965.2 | CK24: 3268854.9 | CL24: 3178144.1 | CM24: 3089951.2 | CN24: 3004205 | CO24: 2918459.1 | CP24: 2837472.1 | CQ24: 2758732.1 | CR24: 2758732.2 | CS24: 2682178.1 | CU24: 7019373
A25: Other Assets | B25: 44250 | C25: 50380 | D25: 83420 | E25: 91059570 | F25: 90987805 | G25: 90987805 | H25: 90987805 | I25: 1.8197561e+08 | J25: 90987805 | K25: 90987805 | L25: 90987805 | M25: 90987805 | N25: 90987805 | O25: 89985792 | P25: 1.7997158e+08 | Q25: 90789876 | R25: 48410 | S25: 1.8136536e+08 | T25: 90682678 | U25: 67395335 | V25: 67395335 | W25: 58298559 | X25: 44300598 | Y25: 1.3290179e+08 | Z25: 94601195 | AA25: 2.3650299e+08 | AB25: 94601195 | AC25: 1.7779709e+08 | AD25: 50903458 | AE25: 68210 | AF25: 50903458 | AG25: 53604357 | AH25: 53290172 | AI25: 53290172 | AJ25: 52209390 | AK25: 52933546 | AL25: 28377798 | AM25: 28377798 | AN25: 28377798 | AO25: 27377798 | AP25: 27980495 | AQ25: 33334808 | AR25: =162360 -> 162360 | AS25: 33954857 | AT25: 33954857 | AU25: 33954857 | AV25: 31818623 | AW25: 32561623 | AX25: 32561623 | AY25: 32561623 | AZ25: 32561623 | BA25: 32561623 | BB25: 32561623 | BC25: 37561623 | BD25: 33404752 | BF25: 34010024 | BG25: 28364844 | BH25: 31713069 | BI25: 28129548 | BJ25: 33639281 | BK25: 35639281 | BM25: 44122401 | BN25: 15406044 | BO25: 15841725 | BP25: 36012626 | BQ25: 17341163 | BR25: 173896 | BS25: 18576742 | BT25: 14125860 | BU25: 14314560 | BV25: 12314560 | BW25: 12314560 | BX25: 41734502 | BY25: 39298909 | BZ25: 45240296 | CA25: 45689994 | CB25: 49794673 | CE25: 194640 | CF25: 49403708 | CG25: 55606066 | CH25: 36192637 | CI25: 36237429 | CJ25: 35044985 | CK25: 31406508 | CL25: 30400911 | CM25: 39949904 | CN25: 39328224 | CO25: 34794856 | CP25: 34450699 | CQ25: 35040714 | CR25: =217010 -> 217010 | CS25: 39577964 | CU25: =SUM(CU21:CU24) -> 72879994
A26: Total Assets | B26: =B20+B16+B13+B8+B7+B4 -> 3.3049886e+08 | C26: =C20+C16+C13+C8+C7+C4 -> 3.482434e+08 | D26: =D20+D16+D13+D8+D7+D4 -> 3.8616078e+08 | E26: =E20+E16+E13+E8+E7+E4 -> 3.9634317e+08 | F26: =F20+F16+F13+F8+F7+F4 -> 3.7907267e+08 | G26: =G20+G16+G13+G8+G7+G4 -> 3.8462171e+08 | H26: =H20+H16+H13+H8+H7+H4 -> 3.7946308e+08 | I26: =I20+I16+I13+I8+I7+I4 -> 739043304 | ... CS26: =CS20+CS16+CS13+CS8+CS7+CS4 -> 5.193942e+08 | CU26: 74026832
A27: Savings and Deposits | B27: 82692444 | C27: 69746223 | D27: 73895934 | E27: 47198708 | F27: 58834512 | G27: 59495528 | H27: 57306603 | I27: 1.0587131e+08 | J27: 45155576 | K27: 42424116 | L27: 38679810 | M27: 37680125 | N27: 37316770 | O27: 2.6523954e+08 | P27: 2.4800679e+08 | Q27: 1.0057772e+08 | R27: =94675309.16+26659720.62 -> 1.2133503e+08 | S27: 1.6768347e+08 | T27: 56007213 | U27: 48529001 | V27: 42966080 | W27: 40687431 | X27: 29913667 | Y27: 1.1725551e+08 | Z27: 72167971 | AA27: 2.0241122e+08 | AB27: 8.0396263e+08 | AC27: 2.880481e+08 | AD27: 54827110 | AE27: =53098512.26+1728598 -> 54827110 | AF27: 58321987 | AG27: 46285448 | AH27: 44903297 | AI27: 42954956 | AJ27: 42218493 | AK27: 32482326 | AL27: 27693034 | AM27: 24434336 | AN27: 23346856 | AO27: 3.1349233e+08 | AP27: 1.1220255e+08 | AQ27: 62524528 | AR27: =58028228.87+4496299.19 -> 62524528 | AS27: 88759001 | AT27: 81521688 | AU27: 99525595 | AV27: 82913368 | AW27: 76055115 | AX27: 76159154 | AY27: 64929812 | AZ27: 58243476 | BA27: 57757115 | BB27: 1.1565401e+08 | BC27: 65905318 | BD27: 78956030 | BF27: 59729887 | BG27: 68821644 | BH27: 47212180 | BI27: 47201742 | BJ27: 48212478 | BK27: 46397911 | BM27: 1.3294717e+08 | BN27: 42322049 | BO27: 1.009443e+08 | BP27: 1.6012346e+08 | BQ27: 65981999 | BR27: =62170125+3811873 -> 65981998 | BS27: 55279905 | BT27: 55814151 | BU27: 40506033 | BV27: 55816435 | BW27: 36501602 | BX27: 35608052 | BY27: 31819466 | BZ27: 30702254 | CA27: 29479348 | CB27: 1.1239381e+08 | CE27: =41714696.89+2263091.16 -> 43977788 | CF27: 39686166 | CG27: 32456511 | CH27: 28856882 | CI27: 35676377 | CJ27: 28393785 | CK27: 28390409 | CL27: 1.2891751e+08 | CM27: 97121983 | CN27: 68574680 | CO27: 57295769 | CP27: 48789391 | CQ27: 43205527 | CR27: 43205527 | CS27: 47238311 | CU27: =CU26-CU25 -> 1146837.7
A28: Short Terrm Deposits | B28: 34007160 | C28: 9331500 | D28: 28342626 | E28: 35697740 | F28: 39980985 | G28: 40542035 | H28: 40767785 | I28: 79334970 | J28: 39048685 | K28: 38536826 | L28: 40109176 | M28: 40709970 | N28: 41492970 | O28: 43093370 | P28: 89083140 | Q28: 41945721 | R28: =15286000+5902412.8 -> 21188413 | S28: 89420841 | T28: 44042621 | U28: 36296012 | V28: 36296012 | W28: 36300962 | X28: 36005612 | Y28: 1.0822714e+08 | Z28: 72165624 | AA28: 1.8543056e+08 | AB28: 75288224 | AC28: 1.1893234e+08 | AD28: 38550412 | AE28: =18524711.85+20025700 -> 38550412 | AF28: 39557112 | AG28: 38996262 | AH28: 39380452 | AI28: 39393401 | AJ28: 40210951 | AK28: 42574748 | AL28: 20243000 | AM28: 20243000 | AN28: 20243000 | AO28: 24989800 | AP28: 25939000 | AQ28: 31271876 | AR28: 31271876 | AS28: 31278323 | AT28: 31231327 | AU28: 37231327 | AV28: 38213247 | AW28: 35659247 | AX28: 36885547 | AY28: 37806047 | AZ28: 40642997 | BA28: 40843947 | BB28: 42018247 | BC28: 44235947 | BD28: 45680597 | BF28: 48127497 | BG28: 50043197 | BH28: 46048454 | BI28: 47673680 | BJ28: 50255694 | BK28: 50692441 | BM28: 1.4997945e+08 | BN28: 49993148 | BO28: 59993148 | BP28: 1.199863e+08 | BQ28: 50011408 | BR28: 51084949 | BS28: 53307152 | BT28: 52473952 | BU28: 53433252 | BV28: 50306227 | BW28: 55739477 | BX28: 55029277 | BY28: 56777777 | BZ28: 57539577 | CA28: 55964777 | CB28: 58904152 | CE28: 57981352 | CF28: 59704696 | CG28: 63256052 | CH28: 71160652 | CI28: 72086048 | CJ28: 71307048 | CK28: 73678248 | CL28: 81278548 | CM28: 83661848 | CN28: 80153098 | CO28: 80738072 | CP28: 86147422 | CQ28: 86819922 | CR28: 86819922 | CS28: 87173222
A29: Non Withdrawable Deposits | B29: 47036877 | C29: 46620378 | D29: 46620379 | E29: 46706120 | F29: 47996421 | G29: 50229762 | H29: 46820378 | I29: 93240756 | J29: 44620378 | K29: 44620378 | L29: 45196388 | M29: 45235489 | N29: 45035489 | O29: 45150989 | P29: 90007010 | Q29: 60614386 | R29: 60614336 | S29: 1.2620243e+08 | T29: 63101214 | U29: 61101214 | V29: 61101214 | W29: 52608838 | X29: 53290738 | Y29: 162059493 | Z29: 109276662 | AA29: 278191655 | AB29: 115276662 | AC29: 172914993 | AD29: 59231544 | AE29: 59231544 | AF29: 60585214 | AG29: 61334423 | AH29: 60986895 | AI29: 61986895 | AJ29: 62986895 | AK29: 60719755 | AL29: 54719755 | AM29: 55306375 | AN29: 55806375 | AO29: 59806375 | AP29: 66634554 | AQ29: 65285855 | AR29: 65285855 | AS29: 67914531 | AT29: 67914531 | AU29: 68914531 | AV29: 70914531 | AW29: 69921687 | AX29: 69921687 | AY29: 69921687 | AZ29: 69918077 | BA29: 67284120 | BB29: 67284120 | BC29: 71365656 | BD29: 70701479 | BF29: 70701479 | BG29: 70701479 | BH29: 70701479 | BI29: 70701479 | BJ29: 70701479 | BK29: 70701479 | BM29: 1.5407184e+08 | BN29: 51357279 | BO29: 51357279 | BP29: 1.0271456e+08 | BQ29: 51313842 | BR29: 51313842 | BS29: 51294476 | BT29: 51364766 | BU29: 51547793 | BV29: 52112760 | BW29: 53047230 | BX29: 53810158 | BY29: 54515112 | BZ29: 55198467 | CA29: 55765306 | CB29: 56973192 | CE29: 51392305 | CF29: 52241662 | CG29: 53084535 | CH29: 53939057 | CI29: 55281779 | CJ29: 56264805 | CK29: 57348971 | CL29: 59069138 | CM29: 59553457 | CN29: 60342129 | CO29: 61293411 | CP29: 62175589 | CQ29: 61135400 | CR29: 59333400 | CS29: 60802471
