Workbook

Sheet Balance Sheet
B1: SIMBA CHAI SACCO SOCIETY | Q1: =+V:V -> 0
B2: STATEMENT OF FINANCIAL POSITION
B3: FINANCIAL YEAR 2020 | C3: 44197 | D3: 44228 | E3: 44256 | F3: 44287 | G3: 44317 | H3: 44348 | I3: 44378 | J3: 44409 | K3: 44440 | L3: 44470 | M3: 44501 | N3: 44531 | O3: AUDITED 2021 | P3: 44583 | Q3: 44614 | R3: 44642 | S3: 44673 | T3: 44703 | U3: 44734 | V3: 44764 | W3: 44795 | X3: 44826 | Y3: 44856 | Z3: 44887 | AA3: 44917 | AB3: AUDITED 2022
A4: 1 | B4: Cash & Cash Equivalent | C4: =C5+C6 -> 2.4118584e+08 | D4: =D5+D6 -> 1.741608e+08 | E4: =E5+E6 -> 1.6516793e+08 | F4: =F5+F6 -> 1.5698168e+08 | G4: =G5+G6 -> 1.4380931e+08 | H4: =H5+H6 -> 1.3198555e+08 | I4: =I5+I6 -> 1.2123049e+08 | J4: =J5+J6 -> 2.0061337e+08 | ... AB4: =AB5+AB6 -> 105994628
A5: 1.1 | B5: Cash in hand(both local and foreign notes and coins) | C5: 6244027.4 | D5: 5576721.4 | E5: 4095435.4 | F5: 3363769.4 | G5: 3289419.4 | H5: 3676026.4 | I5: 2613188.4 | J5: 7392361.4 | K5: 8112707.4 | L5: 3154227.4 | M5: 4546023.4 | N5: 6578073.4 | O5: 19850692 | P5: 7697796.4 | Q5: 5394118.4 | R5: 3393886.4 | S5: 3053092.4 | T5: 2871618.4 | U5: 6433966.4 | V5: 3164756.4 | W5: 2710930.4 | X5: 4970923.4 | Y5: 5875359.4 | Z5: 8792944.4 | AA5: 4280126.4 | AB5: 13433244
A6: 1.2 | B6: Cash at bank:(placement with financial institutions) | C6: 2.3494181e+08 | D6: 1.6858408e+08 | E6: 1.610725e+08 | F6: 1.5361791e+08 | G6: 1.4051989e+08 | H6: 1.2830952e+08 | I6: 1.186173e+08 | J6: 1.9322101e+08 | K6: 1.8200011e+08 | L6: 1.9584542e+08 | M6: 2.0051666e+08 | N6: 1.7113282e+08 | O6: 157860206 | P6: 1.7999262e+08 | Q6: 1.5775611e+08 | R6: 1.4469611e+08 | S6: 2.0568492e+08 | T6: 1.9474988e+08 | U6: 1.8732702e+08 | V6: 54801370 | W6: 54039177 | X6: 72331431 | Y6: 69977999 | Z6: 99235696 | AA6: 1.012145e+08 | AB6: =105994628-13433244 -> 92561384
A7: 2 | B7: Prepayments & Sundry Receivables | C7: 1.8058668e+08 | D7: 1.758654e+08 | E7: 1.8234428e+08 | F7: 1.7530377e+08 | G7: 1.7982798e+08 | H7: 1.8210666e+08 | I7: 1.8339992e+08 | J7: 1.7873175e+08 | K7: 1.8857193e+08 | L7: 1.8875939e+08 | M7: 2.9429773e+08 | N7: 1.7806293e+08 | O7: 178062928 | P7: 1.8683229e+08 | Q7: 1.7715296e+08 | R7: 1.7708437e+08 | S7: 1.7201933e+08 | T7: 1.7140153e+08 | U7: 1.7734396e+08 | V7: 1.7190259e+08 | W7: 1.7799783e+08 | X7: 1.7062134e+08 | Y7: 1.7634001e+08 | Z7: 1.7153378e+08 | AA7: 1.7201235e+08 | AB7: 172015235
A8: 3 | B8: Financial Investments | C8: =SUM(C9:C12) -> 21355306 | D8: =SUM(D9:D12) -> 21455306 | E8: =SUM(E9:E12) -> 21555306 | F8: =SUM(F9:F12) -> 21655306 | G8: =SUM(G9:G12) -> 22055306 | H8: =SUM(H9:H12) -> 22155306 | I8: =SUM(I9:I12) -> 22255306 | J8: =SUM(J9:J12) -> 22355306 | ... AB8: =SUM(AB9:AB12) -> 29582479 | AD8: =AB7+AB20 -> 339937582
A9: 3.1 | B9: Government Securities - Treasury Bills/bonds, | C9: 0 | D9: 0 | E9: 0 | F9: 0 | G9: 0 | H9: 0 | I9: 0 | J9: 0 | K9: 0 | L9: 0 | M9: 0 | N9: 0 | O9: 0 | P9: 0 | Q9: 0 | R9: 0 | S9: 0 | T9: 0 | U9: 0 | V9: 0 | W9: 0 | X9: 0 | Y9: 0 | Z9: 0 | AA9: 0 | AB9: 0 | AD9: =AD8/AB51 -> 0.17384799
A10: 3.2 | B10: Other Securities - Commercial papers/Bonds | C10: 0 | D10: 0 | E10: 0 | F10: 0 | G10: 0 | H10: 0 | I10: 0 | J10: 0 | K10: 0 | L10: 0 | M10: 0 | N10: 0 | O10: 22443306 | P10: 0 | Q10: 0 | R10: 0 | S10: 0 | T10: 0 | U10: 0 | V10: 0 | W10: 0 | X10: 0 | Y10: 0 | Z10: 0 | AA10: 0 | AB10: 2342400
A11: 3.3a | B11: Balances with other SACCO Societies | C11: 0 | D11: 0 | E11: 0 | F11: 0 | G11: 0 | H11: 0 | I11: 0 | J11: 0 | K11: 0 | L11: 0 | M11: 0 | N11: 0 | O11: 312000 | P11: 0 | Q11: 0 | R11: 0 | S11: 0 | T11: 0 | U11: 0 | V11: 0 | W11: 0 | X11: 0 | Y11: 0 | Z11: 0 | AA11: 0 | AB11: 27240079
A12: 3.3b | B12: Investments in companies - shares/stocks | C12: 21355306 | D12: 21455306 | E12: 21555306 | F12: 21655306 | G12: 22055306 | H12: 22155306 | I12: 22255306 | J12: 22355306 | K12: 22455306 | L12: 22555306 | M12: 22655306 | N12: 22755306 | O12: 0 | P12: 22855306 | Q12: 22955306 | R12: 23055306 | S12: 23155306 | T12: 23255306 | U12: 23355306 | V12: 23455306 | W12: 23555306 | X12: 23655306 | Y12: 23755306 | Z12: 23855306 | AA12: 23955306 | AB12: 0
A13: 4 | B13: Net Loan Portfolio | C13: =C14-C15 -> 9.9058452e+08 | D13: =D14-D15 -> 1.0043206e+09 | E13: =E14-E15 -> 1.0103717e+09 | F13: =F14-F15 -> 1.0301766e+09 | G13: =G14-G15 -> 1.0595091e+09 | H13: =H14-H15 -> 1.0827801e+09 | I13: =I14-I15 -> 1.1110403e+09 | J13: =J14-J15 -> 1.1370757e+09 | ... AB13: =AB14-AB15 -> 1479857871
A14: 4.1 | B14: Gross Loan Portfolio | C14: 1.0165845e+09 | D14: 1.0303206e+09 | E14: 1.0363717e+09 | F14: 1.0561766e+09 | G14: 1.0855091e+09 | H14: 1.1087801e+09 | I14: 1.1370403e+09 | J14: 1.1630757e+09 | K14: 1.1701639e+09 | L14: 1.1712948e+09 | M14: 1.1682237e+09 | N14: 1.2216161e+09 | O14: 1221616146 | P14: 1.2201231e+09 | Q14: 1.2229071e+09 | R14: 1.2304646e+09 | S14: 1.2669149e+09 | T14: 1.3787303e+09 | U14: 1.4466869e+09 | V14: 1.480201e+09 | W14: 1.4929449e+09 | X14: 1.5029281e+09 | Y14: 1.5169998e+09 | Z14: 1.5208237e+09 | AA14: 1.5158579e+09 | AB14: 1515857871
A15: 4.2 | B15: Allowance for Loan Loss | C15: 26000000 | D15: 26000000 | E15: 26000000 | F15: 26000000 | G15: 26000000 | H15: 26000000 | I15: 26000000 | J15: 26000000 | K15: 27000000 | L15: 34000000 | M15: 34000000 | N15: 30000000 | O15: 30000000 | P15: 31000000 | Q15: 30000000 | R15: 30000000 | S15: 32000000 | T15: 32000000 | U15: 33000000 | V15: 33000000 | W15: 33000000 | X15: 34000000 | Y15: 34000000 | Z15: 36000000 | AA15: 36000000 | AB15: 36000000
A16: 5 | B16: Accounts Receivables | C16: 0 | D16: 0 | E16: 0 | F16: 0 | G16: 0 | H16: 0 | I16: 0 | J16: 0 | K16: 0 | L16: =L17+L18+L19 -> 0 | M16: =M17+M18+M19 -> 0 | N16: =N17+N18+N19 -> 0 | O16: =O17+O18+O19 -> 0 | P16: =P17+P18+P19 -> 0 | Q16: =Q17+Q18+Q19 -> 0 | R16: =R17+R18+R19 -> 0 | S16: =S17+S18+S19 -> 0 | ... AB16: =AB17+AB18+AB19 -> 0
A17: 5.1 | B17: Tax Recoverable | C17: 0 | D17: 0 | E17: 0 | F17: 0 | G17: 0 | H17: 0 | I17: 0 | J17: 0 | K17: 0 | L17: 0 | M17: 0 | N17: 0 | O17: 0 | P17: 0 | Q17: 0 | R17: 0 | S17: 0 | T17: 0 | U17: 0 | V17: 0 | W17: 0 | X17: 0 | Y17: 0 | Z17: 0 | AA17: 0 | AB17: 0
A18: 5.2 | B18: Deferred Tax Assets | C18: 0 | D18: 0 | E18: 0 | F18: 0 | G18: 0 | H18: 0 | I18: 0 | J18: 0 | K18: 0 | L18: 0 | M18: 0 | N18: 0 | O18: 0 | P18: 0 | Q18: 0 | R18: 0 | S18: 0 | T18: 0 | U18: 0 | V18: 0 | W18: 0 | X18: 0 | Y18: 0 | Z18: 0 | AA18: 0 | AB18: 0
A19: 5.3 | B19: Retirement Benefit Assets | C19: 0 | D19: 0 | E19: 0 | F19: 0 | G19: 0 | H19: 0 | I19: 0 | J19: 0 | K19: 0 | L19: 0 | M19: 0 | N19: 0 | O19: 0 | P19: 0 | Q19: 0 | R19: 0 | S19: 0 | T19: 0 | U19: 0 | V19: 0 | W19: 0 | X19: 0 | Y19: 0 | Z19: 0 | AA19: 0 | AB19: 0
A20: 6 | B20: Property & Equipment & Other assets | C20: =SUM(C21:C25) -> 51933970 | D20: =SUM(D21:D25) -> 83938770 | E20: =SUM(E21:E25) -> 84101770 | F20: =SUM(F21:F25) -> 85972062 | G20: =SUM(G21:G25) -> 86228257 | H20: =SUM(H21:H25) -> 88041326 | I20: =SUM(I21:I25) -> 88321376 | J20: =SUM(J21:J25) -> 88475948 | ... AB20: =SUM(AB21:AB25) -> 167922347
A21: 6.1 | B21: Investment Properties | C21: 0 | D21: 0 | E21: 0 | F21: 0 | G21: 0 | H21: 0 | I21: 0 | J21: 0 | K21: 0 | L21: 0 | M21: 0 | N21: 0 | O21: 0 | P21: 0 | Q21: 0 | R21: 0 | S21: 0 | T21: 0 | U21: 0 | V21: 0 | W21: 0 | X21: 0 | Y21: 0 | Z21: 0 | AA21: 0 | AB21: 0
A22: 6.2 | B22: Property & Equipment | C22: 47172683 | D22: 79177483 | E22: 79340483 | F22: 81210775 | G22: 81466970 | H22: 83280039 | I22: 83560089 | J22: 83714661 | K22: 83799842 | L22: 83899742 | M22: 84039952 | N22: 90701339 | O22: 90701340 | P22: 91071480 | Q22: 98635106 | R22: 1.1154133e+08 | S22: 1.2660316e+08 | T22: 1.3403975e+08 | U22: 1.4064564e+08 | V22: 1.6676099e+08 | W22: 1.6676099e+08 | X22: 1.6760703e+08 | Y22: 1.6795728e+08 | Z22: 1.6799518e+08 | AA22: 1.6558932e+08 | AB22: 165589316
A23: 6.3 | B23: Prepaid Lease rentals | C23: 0 | D23: 0 | E23: 0 | F23: 0 | G23: 0 | H23: 0 | I23: 0 | J23: 0 | K23: 0 | L23: 0 | M23: 0 | N23: 0 | O23: 0 | P23: 0 | Q23: 0 | R23: 0 | S23: 0 | T23: 0 | U23: 0 | V23: 0 | W23: 0 | X23: 0 | Y23: 0 | Z23: 0 | AA23: 0 | AB23: 0
A24: 6.4 | B24: Intangible Assets | C24: 4761287.7 | D24: 4761287.7 | E24: 4761287.7 | F24: 4761287.7 | G24: 4761287.7 | H24: 4761287.7 | I24: 4761287.7 | J24: 4761287.7 | K24: 4761287.7 | L24: 4761287.7 | M24: 4761287.7 | N24: 3332901.4 | O24: 3332901 | P24: 3332901.4 | Q24: 3332901.4 | R24: 3332901.4 | S24: 3332901.4 | T24: 3332901.4 | U24: 3332901.4 | V24: 3332901.4 | W24: 3332901.4 | X24: 3332901.4 | Y24: 3332901.4 | Z24: 3332901.4 | AA24: 2333031 | AB24: 2333031
A25: 6.5 | B25: Other Assets | C25: 0 | D25: 0 | E25: 0 | F25: 0 | G25: 0 | H25: 0 | I25: 0 | J25: 0 | K25: 0 | L25: 0 | M25: 0 | N25: 0 | P25: 0 | Q25: 0 | R25: 0 | S25: 0 | T25: 0 | U25: 0 | V25: 0 | W25: 0 | X25: 0 | Y25: 0 | Z25: 0 | AA25: 0 | AB25: 0
B26: Total Assets | C26: =C4+C7+C8+C13+C16+C20 -> 1.4856463e+09 | D26: =D4+D7+D8+D13+D16+D20 -> 1.4597409e+09 | E26: =E4+E7+E8+E13+E16+E20 -> 1.463541e+09 | F26: =F4+F7+F8+F13+F16+F20 -> 1.4700895e+09 | G26: =G4+G7+G8+G13+G16+G20 -> 1.4914299e+09 | H26: =H4+H7+H8+H13+H16+H20 -> 1.5070689e+09 | I26: =I4+I7+I8+I13+I16+I20 -> 1.5262474e+09 | J26: =J4+J7+J8+J13+J16+J20 -> 1.627252e+09 | ... AB26: =AB4+AB7+AB8+AB13+AB16+AB20 -> 1955372560
A27: 7 | B27: Savings Deposits - Withdrawable deposits - FOSA) | C27: 1.2070476e+08 | D27: 86709347 | E27: 87280070 | F27: 81031983 | G27: 90181263 | H27: 91115968 | I27: 87486013 | J27: 81908706 | K27: 82594690 | L27: 81332570 | M27: 1.8053056e+08 | N27: 95430624 | O27: 95430624 | P27: 1.2958361e+08 | Q27: 94588989 | R27: 95665497 | S27: 92522739 | T27: 96194011 | U27: 91992513 | V27: 85716855 | W27: 86317250 | X27: 79682907 | Y27: 88808629 | Z27: 80809321 | AA27: 87055768 | AB27: 87058531
A28: 8 | B28: Short Term Deposits (e.g Fixed deposits, special savings) | C28: 5511362.5 | D28: 6907659.4 | E28: 8662909.7 | F28: 10119314 | G28: 11742283 | H28: 16908758 | I28: 19268497 | J28: 20940363 | K28: 21940930 | L28: 23580272 | M28: 25070441 | N28: 8612678.3 | O28: 8612678 | P28: 9440409 | Q28: 10982877 | R28: 11762675 | S28: 13986971 | T28: 20782851 | U28: 22346371 | V28: 24115325 | W28: 24963773 | X28: 27175217 | Y28: 30314101 | Z28: 35202519 | AA28: 17802865 | AB28: =4615537+13187328 -> 17802865 | AD28: -1906832
A29: 9 | B29: Non withdrawable deposits (BOSA member deposits) | C29: 6.5401113e+08 | D29: 6.6305658e+08 | E29: 6.6252983e+08 | F29: 6.6921464e+08 | G29: 6.7630342e+08 | H29: 6.8374153e+08 | I29: 6.9034687e+08 | J29: 6.9395618e+08 | K29: 7.0184621e+08 | L29: 7.0865414e+08 | M29: 7.1335848e+08 | N29: 7.3526889e+08 | O29: 735268886 | P29: 7.4178175e+08 | Q29: 7.5139299e+08 | R29: 7.5626878e+08 | S29: 7.5974625e+08 | T29: 7.8893368e+08 | U29: 8.0903485e+08 | V29: 8.2049305e+08 | W29: 8.2729409e+08 | X29: 8.3391871e+08 | Y29: 8.3606953e+08 | Z29: 8.4024278e+08 | AA29: 8.4691104e+08 | AB29: 846911037 | AD29: 77169655
B30: Total Deposit liabilities | C30: =SUM(C27:C29) -> 7.8022725e+08 | D30: =SUM(D27:D29) -> 7.5667359e+08 | E30: =SUM(E27:E29) -> 7.5847281e+08 | F30: =SUM(F27:F29) -> 7.6036594e+08 | G30: =SUM(G27:G29) -> 7.7822696e+08 | H30: =SUM(H27:H29) -> 7.9176626e+08 | I30: =SUM(I27:I29) -> 7.9710138e+08 | J30: =SUM(J27:J29) -> 7.9680525e+08 | ... AB30: =SUM(AB27:AB29) -> 951772433 | AD30: -15433931
A31: 10 | B31: Accounts Payable & Other Liabilities | C31: =SUM(C32:C37) -> 3.2704268e+08 | D31: =SUM(D32:D37) -> 3.2708049e+08 | E31: =SUM(E32:E37) -> 3.2433433e+08 | F31: =SUM(F32:F37) -> 3.2532155e+08 | G31: =SUM(G32:G37) -> 3.2573594e+08 | H31: =SUM(H32:H37) -> 3.2445731e+08 | I31: =SUM(I32:I37) -> 3.310584e+08 | J31: =SUM(J32:J37) -> 4.0916752e+08 | ... AB31: =SUM(AB32:AB37) -> 492332790 | AD31: -5502760
A32: 10.1 | B32: Tax Payable | C32: 4194575.8 | D32: 1427864 | E32: 699782.73 | F32: 644385.65 | G32: 455692.83 | H32: 471140.53 | I32: 482187.77 | J32: 511544.89 | K32: 474208.63 | L32: 488728.33 | M32: 696224.77 | N32: 882732 | O32: 341135 | P32: 4830872.4 | Q32: 5351802.6 | R32: 812517.74 | S32: 834412.02 | T32: 679023.77 | U32: 558080.24 | V32: 528631.66 | W32: 542210.31 | X32: 533672.47 | Y32: 546946.1 | Z32: 560860.19 | AA32: 783371.48 | AB32: 223472 | AD32: -1482094
A33: 10.2 | B33: Dividends Payable | C33: 695374.76 | D33: 11745454 | E33: 17257757 | F33: 23001666 | G33: 28873820 | H33: 34881588 | I33: 40871064 | J33: 46958256 | K33: 53332977 | L33: 59749023 | M33: 59749023 | N33: 74221400 | O33: 73526889 | P33: 6983085.3 | Q33: 6983085.3 | R33: 19708289 | S33: 19708289 | T33: 33673807 | U33: 41253313 | V33: 48663665 | W33: 55950343 | X33: 63345474 | Y33: 70697617 | Z33: 77822142 | AA33: 85491129 | AB33: 84691104 | AD33: -846911
A34: 10.3 | B34: Deferred Tax Liability | C34: 0 | D34: 0 | E34: 0 | F34: 0 | G34: 0 | H34: 0 | I34: 0 | J34: 0 | K34: 0 | L34: 0 | M34: 0 | N34: 0 | O34: 0 | P34: 0 | Q34: 0 | R34: 0 | S34: 0 | T34: 0 | U34: 0 | V34: 0 | W34: 0 | X34: 0 | Y34: 0 | Z34: 0 | AA34: 0 | AB34: 0 | AD34: =SUM(AD28:AD33) -> 51997127
A35: 10.4 | B35: Retirement Benefits Liability | C35: 0 | D35: 0 | E35: 0 | F35: 0 | G35: 0 | H35: 0 | I35: 0 | J35: 0 | K35: 0 | L35: 0 | M35: 0 | O35: 0 | P35: 0 | Q35: 0 | R35: 0 | S35: 0 | T35: 0 | U35: 0 | V35: 0 | W35: 0 | X35: 0 | Y35: 0 | Z35: 0 | AA35: 0 | AB35: 0
A36: 10.5 | B36: Other Liabilities | C36: 79531181 | D36: 80969130 | E36: 84404405 | F36: 88865284 | G36: 94628473 | H36: 98432311 | I36: 1.0381356e+08 | J36: 86163972 | K36: 88273116 | L36: 91826637 | M36: 95409793 | N36: 83612079 | O36: 82826199 | P36: 81825902 | Q36: 82672409 | R36: 87401261 | S36: 95903690 | T36: 84652745 | U36: 93296143 | V36: 91528700 | W36: 93548798 | X36: 98737072 | Y36: 1.0223257e+08 | Z36: 1.0545735e+08 | AA36: 92075974 | AB36: 91106941
A37: 10.6 | B37: External Borrowings | C37: 2.4262155e+08 | D37: 2.3293804e+08 | E37: 2.2197239e+08 | F37: 2.1281021e+08 | G37: 2.0177796e+08 | H37: 1.9067227e+08 | I37: 1.8589159e+08 | J37: 2.7553374e+08 | K37: 2.6024715e+08 | L37: 2.5077717e+08 | M37: 2.4120793e+08 | N37: 2.313444e+08 | O37: 231344401 | P37: 2.7165645e+08 | Q37: 2.6190838e+08 | R37: 2.5044948e+08 | S37: 3.4014325e+08 | T37: 3.808612e+08 | U37: 4.1821938e+08 | V37: 3.2122115e+08 | W37: 3.1154817e+08 | X37: 3.2200875e+08 | Y37: 3.1235606e+08 | Z37: 3.2976456e+08 | AA37: 3.1631127e+08 | AB37: 316311273
B38: Total Liabilities | C38: =C30+C31 -> 1.1072699e+09 | D38: =D30+D31 -> 1.0837541e+09 | E38: =E30+E31 -> 1.0828071e+09 | F38: =F30+F31 -> 1.0856875e+09 | G38: =G30+G31 -> 1.1039629e+09 | H38: =H30+H31 -> 1.1162236e+09 | I38: =I30+I31 -> 1.1281598e+09 | J38: =J30+J31 -> 1.2059728e+09 | ... AB38: =AB30+AB31 -> 1444105223
A39: 11 | B39: Share Capital (Members share capital per Bylaws) | C39: 52419678 | D39: 52552740 | E39: 52687971 | F39: 52830180 | G39: 52966730 | H39: 53104216 | I39: 53227743 | J39: 53340708 | K39: 53462508 | L39: 53560808 | M39: 53898894 | N39: 54051794 | O39: 54051794 | P39: 54227889 | Q39: 54303661 | R39: 54377671 | S39: 54452923 | T39: 54525403 | U39: 54592524 | V39: 54661645 | W39: 54731545 | X39: 54822146 | Y39: 54894147 | Z39: 54968651 | AA39: 55027598 | AB39: 55027598
A40: 12 | B40: Capital Grants | C40: 0 | D40: 0 | E40: 0 | F40: 0 | G40: 0 | H40: 0 | I40: 0 | J40: 0 | K40: 0 | L40: 0 | M40: 0 | N40: 0 | O40: 0 | P40: 0 | Q40: 0 | R40: 0 | S40: 0 | T40: 0 | U40: 0 | V40: 0 | W40: 0 | X40: 0 | Y40: 0 | Z40: 0 | AA40: 0 | AB40: 0
...

Sheet Income Stat.
A1: SIMBA CHAI SACCO SOCIETY
A2: STATEMENT OF COMPREHENSIVE INCOME
A3: FINANCIAL YEAR 2020 | C3: 44197 | D3: 44228 | E3: 44256 | F3: 44287 | G3: 44317 | H3: 44348 | I3: 44378 | J3: 44409 | K3: 44440 | L3: 44470 | M3: 44501 | N3: 44531 | O3: Aud-21 | P3: 44583 | Q3: 44614 | R3: 44642 | S3: 44673 | T3: 44703 | U3: 44734 | V3: 44764 | W3: 44795 | X3: 44826 | Y3: 44856 | Z3: 44887 | AA3: 44917 | AB3: AUDITED 2022
A4: 1 | B4: Financial Income | C4: 14471109 | D4: 28615378 | E4: 44269174 | F4: 58902230 | G4: 73068773 | H4: 87808119 | I4: 1.0423529e+08 | J4: 1.4789043e+08 | K4: 1.6593064e+08 | L4: 1.804831e+08 | M4: 1.9524895e+08 | N4: 2.2856074e+08 | O4: =O5+O8 -> 226923792 | P4: =P5+P8 -> 21341697 | Q4: =Q5+Q8 -> 36191424 | R4: =R5+R8 -> 51638520 | S4: =S5+S8 -> 68934120 | T4: =T5+T8 -> 1.1774566e+08 | U4: =U5+U8 -> 1.4247175e+08 | V4: =V5+V8 -> 1.6918649e+08 | ... AB4: =AB5+AB8 -> 273371575
A5: 2 | B5: Financial Income from Loans Portfolio | C5: 12658619 | D5: 25469318 | E5: 39204638 | F5: 51495041 | G5: 64385951 | H5: 77857554 | I5: 92499584 | J5: 1.3490693e+08 | K5: 1.5173945e+08 | L5: 1.6391908e+08 | M5: 1.7703621e+08 | N5: 2.0736624e+08 | O5: =SUM(O6:O7) -> 222413357 | P5: =SUM(P6:P7) -> 19326186 | Q5: =SUM(Q6:Q7) -> 32878482 | R5: =SUM(R6:R7) -> 47185956 | S5: =SUM(S6:S7) -> 62646035 | T5: =SUM(T6:T7) -> 1.1009749e+08 | U5: =SUM(U6:U7) -> 1.3221852e+08 | V5: =SUM(V6:V7) -> 1.5764498e+08 | ... AB5: =SUM(AB6:AB7) -> 269894583
A6: 2.1 | B6: Interest on Loan Portfolio | C6: 12527019 | D6: 25218828 | E6: 38820698 | F6: 50965201 | G6: 63692311 | H6: 77005164 | I6: 91456394 | J6: 1.3368729e+08 | K6: 1.5037811e+08 | L6: 1.6243609e+08 | M6: 1.7541562e+08 | N6: 2.055625e+08 | O6: 207366237 | P6: 19225236 | Q6: 32660532 | R6: 46828326 | S6: 62106905 | T6: 1.0923916e+08 | U6: 1.3116358e+08 | V6: 1.5642489e+08 | W6: 1.7270257e+08 | X6: 1.8862143e+08 | Y6: 2.0531429e+08 | Z6: 2.2124476e+08 | AA6: 2.5365112e+08 | AB6: 255622714
A7: 2.2 | B7: Fees & Commission on Loan Portfolio | C7: 131600 | D7: 250490 | E7: 383940 | F7: 529840 | G7: 693640 | H7: 852390 | I7: 1043190 | J7: 1219640 | K7: 1361340 | L7: 1482990 | M7: 1620590 | N7: 1803740 | O7: 15047120 | P7: 100950 | Q7: 217950 | R7: 357630 | S7: 539130 | T7: 858330 | U7: 1054945 | V7: 1220095 | W7: 1403845 | X7: 1564195 | Y7: 1715845 | Z7: 1847695 | AA7: 1971595 | AB7: 14271869
A8: 3 | B8: Financial Income from Investments in: | C8: 0 | D8: 0 | E8: 693880 | F8: 1826143.8 | G8: 1826143.8 | H8: 1826143.8 | I8: 2322505 | J8: 2322505 | K8: 2322505 | L8: 2848681.4 | M8: 2848681.4 | N8: 4005306.6 | O8: =SUM(O9:O12) -> 4510435 | P8: =SUM(P9:P12) -> 2015511.1 | Q8: =SUM(Q9:Q12) -> 3312942.7 | R8: =SUM(R9:R12) -> 4452564.7 | S8: =SUM(S9:S12) -> 6288085.2 | T8: =SUM(T9:T12) -> 7648164.7 | U8: =SUM(U9:U12) -> 10253224 | V8: =SUM(V9:V12) -> 11541512 | ... AB8: =SUM(AB9:AB12) -> 3476992
A9: 3.1 | B9: Government Securities | C9: 0 | D9: 0 | E9: 0 | F9: 0 | G9: 0 | H9: 0 | I9: 0 | J9: 0 | K9: 0 | L9: 0 | M9: 0 | N9: 0 | P9: 0 | Q9: 0 | R9: 0 | S9: 0 | T9: 0 | U9: 0 | V9: 0 | W9: 0 | X9: 0 | Y9: 0 | Z9: 0 | AA9: 0 | AB9: 0
A10: 3.2 | B10: Deposit with Banks and Other Financial Inst. | C10: 0 | D10: 0 | E10: 0 | F10: 0 | G10: 0 | H10: 0 | I10: 0 | J10: 0 | K10: 0 | L10: 0 | M10: 0 | N10: 0 | P10: 0 | Q10: 0 | R10: 0 | S10: 0 | T10: 0 | U10: 0 | V10: 0 | W10: 0 | X10: 0 | Y10: 0 | Z10: 0 | AA10: 0 | AB10: 0
A11: 3.3 | B11: Other Investments - dividend & Interest incomes from investments | C11: 0 | D11: 0 | E11: 693880 | F11: 1826143.8 | G11: 1826143.8 | H11: 1826143.8 | I11: 2322505 | J11: 2322505 | K11: 2322505 | L11: 2848681.4 | M11: 2848681.4 | N11: 4005306.6 | O11: 4005307 | P11: 0 | Q11: 0 | R11: 0 | S11: 607129.9 | T11: 607129.9 | U11: 1891091.2 | V11: 1891091.2 | W11: 1891091.2 | X11: 1891091.2 | Y11: 2082924.1 | Z11: 2082925.6 | AA11: 3222122.6 | AB11: 3222123
A12: 3.4 | B12: Other Operating Income- Salary processing fees, transaction fees, membership fees | C12: 1812490.1 | D12: 3146060.6 | E12: 4370656 | F12: 5581044.8 | G12: 6856678.4 | H12: 8124421.7 | I12: 9413201.1 | J12: 10660989 | K12: 11868677 | L12: 13715336 | M12: 15364053 | N12: 17189198 | O12: =448000+57128 -> 505128 | P12: 2015511.1 | Q12: 3312942.7 | R12: 4452564.7 | S12: 5680955.3 | T12: 7041034.8 | U12: 8362132.6 | V12: 9650420.4 | W12: 10931249 | X12: 12167069 | Y12: 13369706 | Z12: 14627421 | AA12: 16063106 | AB12: 254869
A13: 4 | B13: Financial Expense | C13: 1047077.6 | D13: 14817643 | E13: 23256209 | F13: 31669318 | G13: 40445389 | H13: 48899148 | I13: 55643982 | J13: 73769323 | K13: 84833581 | L13: 94133792 | M13: 97037734 | N13: 1.1862169e+08 | O13: =O14+O15+O16+O17+O19 -> 107621694 | P13: =P14+P15+P16+P17+P19 -> 11104591 | Q13: =Q14+Q15+Q16+Q17+Q19 -> 14237453 | R13: =R14+R15+R16+R17+R19 -> 30175296 | S13: =S14+S15+S16+S17+S19 -> 37138924 | T13: =T14+T15+T16+T17+T19 -> 58015312 | U13: =U14+U15+U16+U17+U19 -> 71546740 | V13: =V14+V15+V16+V17+V19 -> 92081584 | ... AB13: =AB14+AB15+AB16+AB17+AB19 -> 145053723
A14: 4.2 | B14: Interest Expense on Deposits | C14: 0 | D14: 11050943 | E14: 16563246 | F14: 22307155 | G14: 28179309 | H14: 34187077 | I14: 40176552 | J14: 46263745 | K14: 52638466 | L14: 59054512 | M14: 59054512 | N14: 73526889 | O14: =73526889+798119 -> 74325008 | P14: 6181514.5 | Q14: 6181514.5 | R14: 18906719 | S14: 18906719 | T14: 32872237 | U14: 40451742 | V14: 47862095 | W14: 55148773 | X14: 62543903 | Y14: 69896046 | Z14: 77022117 | AA14: 84691104 | AB14: =84961104+1275438 -> 86236542
A15: 4.3 | B15: Cost of External Borrowings | C15: 997467.57 | D15: 3722875.3 | E15: 6603350 | F15: 9235824.3 | G15: 12096451 | H15: 14515106 | I15: 15225388 | J15: 22178096 | K15: 24825075 | L15: 27686911 | M15: 30548780 | N15: 33016365 | O15: =32208666+807699 -> 33016365 | P15: 3873593.9 | Q15: 6480099.6 | R15: 9648057.7 | S15: 15944922 | T15: 19953391 | U15: 23859115 | V15: 34960645 | W15: 31589216 | X15: 36942232 | Y15: 40795312 | Z15: 45348796 | AA15: 47381758 | AB15: =934908+45946850 -> 46881758
A16: 4.4 | B16: Dividend Expenses (on member shares) | C16: 0 | D16: 0 | E16: 0 | F16: 0 | G16: 0 | H16: 0 | I16: 0 | J16: 0 | K16: 0 | L16: 0 | M16: 0 | N16: 0 | P16: 0 | Q16: 0 | R16: 0 | S16: 0 | T16: 0 | U16: 0 | V16: 0 | W16: 0 | X16: 0 | Y16: 0 | Z16: 0 | AA16: 0 | AB16: 0
A17: 4.5 | B17: Other Financial Expense | C17: 49609.98 | D17: 43825.08 | E17: 89613.07 | F17: 126339.37 | G17: 169629.2 | H17: 196964.68 | I17: 242041.77 | J17: 5327481.8 | K17: 7370040.8 | L17: 7392368.2 | M17: 7434442.2 | N17: 12078440 | O17: =280321 -> 280321 | P17: 1049482.3 | Q17: 1575838.6 | R17: 1620519.7 | S17: 2287283 | T17: 5189684.8 | U17: 7235882.3 | V17: 9258844.9 | W17: 9331881.8 | X17: 11393912 | Y17: 11427990 | Z17: 11515304 | AA17: 13210861 | AB17: =11500000+435423 -> 11935423
A18: 4.6 | B18: Fees & Commission Expense | C18: 0 | D18: 0 | E18: 0 | F18: 0 | G18: 0 | H18: 0 | I18: 0 | J18: 0 | K18: 0 | L18: 0 | M18: 0 | N18: 0 | P18: 0 | Q18: 0 | R18: 0 | S18: 0 | T18: 0 | U18: 0 | V18: 0 | W18: 0 | X18: 0 | Y18: 0 | Z18: 0 | AA18: 0 | AB18: 0
A19: 4.7 | B19: Other Expense | C19: 0 | D19: 0 | E19: 0 | F19: 0 | G19: 0 | H19: 0 | I19: 0 | J19: 0 | K19: 0 | L19: 0 | M19: 0 | N19: 0 | P19: 0 | Q19: 0 | R19: 0 | S19: 0 | T19: 0 | U19: 0 | V19: 0 | W19: 0 | X19: 0 | Y19: 0 | Z19: 0 | AA19: 0 | AB19: 0
A20: 5 | B20: Net Financial Income/(Loss) | C20: 13424032 | D20: 13797735 | E20: 21012965 | F20: 27232912 | G20: 32623384 | H20: 38908972 | I20: 48591307 | J20: 74121104 | K20: 81097055 | L20: 86349306 | M20: 98211214 | N20: 1.0993905e+08 | O20: =O4-O13 -> 119302098 | P20: =P4-P13 -> 10237107 | Q20: =Q4-Q13 -> 21953972 | R20: =R4-R13 -> 21463224 | S20: =S4-S13 -> 31795196 | T20: =T4-T13 -> 59730346 | U20: =U4-U13 -> 70925007 | V20: =V4-V13 -> 77104909 | ... AB20: =AB4-AB13 -> 128317852
A21: 6 | B21: Allowance for Loan Loss | C21: 0 | D21: 0 | E21: 0 | F21: 0 | G21: 0 | H21: 0 | I21: 0 | J21: 0 | K21: 1000000 | L21: 8000000 | M21: 8000000 | N21: 4000000 | O21: =O22-O23 -> 15000000 | P21: =P22-P23 -> 0 | Q21: =Q22-Q23 -> 0 | R21: =R22-R23 -> 0 | S21: =S22-S23 -> 2000000 | T21: =T22-T23 -> 2000000 | U21: =U22-U23 -> 3000000 | V21: =V22-V23 -> 3000000 | ... AB21: =AB22-AB23 -> 6000000
A22: 6.1 | B22: Provision for Loan Losses | C22: 0 | D22: 0 | E22: 0 | F22: 0 | G22: 0 | H22: 0 | I22: 0 | J22: 0 | K22: 1000000 | L22: 8000000 | M22: 8000000 | N22: 4000000 | O22: 15000000 | P22: 0 | Q22: 0 | R22: 0 | S22: 2000000 | T22: 2000000 | U22: 3000000 | V22: 3000000 | W22: 3000000 | X22: 4000000 | Y22: 4000000 | Z22: 6000000 | AA22: 6000000 | AB22: 6000000
A23: 6.2 | B23: Value of Loans Recovered | C23: 0 | D23: 0 | E23: 0 | F23: 0 | G23: 0 | H23: 0 | I23: 0 | J23: 0 | K23: 0 | L23: 0 | M23: 0 | N23: 0 | O23: 0 | P23: 0 | Q23: 0 | R23: 0 | S23: 0 | T23: 0 | U23: 0 | V23: 0 | W23: 0 | X23: 0 | Y23: 0 | Z23: 0 | AA23: 0 | AB23: 0
A24: 7 | B24: Operating Expenses | C24: 3816091.4 | D24: 6712424.7 | E24: 9315877.7 | F24: 12009879 | G24: 14471842 | H24: 17516565 | I24: 20080226 | J24: 22531302 | K24: 25752471 | L24: 28397265 | M24: 31440681 | N24: 39510890 | O24: =SUM(O25:O29) -> 36040806 | P24: =SUM(P25:P29) -> 5011320.8 | Q24: =SUM(Q25:Q29) -> 7354283.3 | R24: =SUM(R25:R29) -> 9690588.8 | S24: =SUM(S25:S29) -> 13679828 | T24: =SUM(T25:T29) -> 17001506 | U24: =SUM(U25:U29) -> 22442172 | V24: =SUM(V25:V29) -> 25764748 | ... AB24: =SUM(AB25:AB29) -> 43394725
A25: 7.1 | B25: Personnel Expenses | C25: 1372035.5 | D25: 2913996 | E25: 4594108.3 | F25: 6147810 | G25: 7712261.5 | H25: 9360889.3 | I25: 11126255 | J25: 12680515 | K25: 14284456 | L25: 15911632 | M25: 17499123 | N25: 19452626 | O25: 19452626 | P25: 1491867.5 | Q25: 3025935.8 | R25: 4496632.6 | S25: 7257734.6 | T25: 9214647.3 | U25: 11303492 | V25: 13507557 | W25: 15648345 | X25: 17444718 | Y25: 19577952 | Z25: 21512064 | AA25: 23343644 | AB25: 23366094
A26: 7.2 | B26: Governance Expenses | C26: 689225 | D26: 857415 | E26: 953184 | F26: 1035764 | G26: 1147568 | H26: 1257511 | I26: 1523887 | J26: 1533079 | K26: 1914761 | L26: 2026458 | M26: 2294463 | N26: 3900354 | O26: 4174324 | P26: 914221 | Q26: 1000501 | R26: 1195840 | S26: 1288499 | T26: 1602696 | U26: 1780796 | V26: 2024126 | W26: 2309523 | X26: 2541783 | Y26: 3365331 | Z26: 3518357 | AA26: 4713207 | AB26: 4963207
A27: 7.3 | B27: Marketing Expenses | C27: 0 | D27: 250000 | E27: 250000 | F27: 250000 | G27: 250000 | H27: 269600 | I27: 269600 | J27: 269600 | K27: 269600 | L27: 269600 | M27: 269600 | N27: 269600 | O27: 19600 | P27: 250000 | Q27: 250000 | R27: 250000 | S27: 250000 | T27: 339940 | U27: 429940 | V27: 429940 | W27: 429940 | X27: 429940 | Y27: 429940 | Z27: 462940 | AA27: 489440 | AB27: 239440
A28: 7.4 | B28: Depreciation and Amortization Charges | C28: 0 | D28: 0 | E28: 0 | F28: 0 | G28: 0 | H28: 0 | I28: 0 | J28: 0 | K28: 0 | L28: 0 | M28: 0 | N28: 2653502.7 | O28: 2653503 | P28: 0 | Q28: 0 | R28: 0 | S28: 0 | T28: 0 | U28: 0 | V28: 0 | W28: 0 | X28: 0 | Y28: 0 | Z28: 0 | AA28: 3512334.4 | AB28: 3512334
A29: 7.5 | B29: Administrative Expenses | C29: 1754830.9 | D29: 2691013.7 | E29: 3518585.4 | F29: 4576305.2 | G29: 5362012.3 | H29: 6628564.3 | I29: 7160483.3 | J29: 8048107.9 | K29: 9283654.3 | L29: 10189575 | M29: 11377495 | N29: 13234807 | O29: 9740753 | P29: 2355232.3 | Q29: 3077846.5 | R29: 3748116.1 | S29: 4883594.8 | T29: 5844222.3 | U29: 8927944.8 | V29: 9803124.8 | W29: 11374972 | X29: 13073986 | Y29: 14020922 | Z29: 15031611 | AA29: 16802845 | AB29: 11313650
A30: 8 | B30: Net Operating Income | C30: 9607940.5 | D30: 7085310.1 | E30: 11697087 | F30: 15223032 | G30: 18151542 | H30: 21392407 | I30: 28511082 | J30: 51589802 | K30: 54344584 | L30: 49952042 | M30: 58770533 | N30: 66428158 | O30: =O20-O21-O24 -> 68261292 | P30: =P20-P21-P24 -> 5225785.9 | Q30: =Q20-Q21-Q24 -> 14599688 | R30: =R20-R21-R24 -> 11772636 | S30: =S20-S21-S24 -> 16115368 | T30: =T20-T21-T24 -> 40728840 | U30: =U20-U21-U24 -> 45482834 | V30: =V20-V21-V24 -> 48340162 | ... AB30: =AB20-AB21-AB24 -> 78923127
A31: 9 | B31: Net Non- Operating Income/ (Expense) | C31: 0 | D31: 0 | E31: 0 | F31: 0 | G31: 0 | H31: 0 | I31: 0 | J31: 0 | K31: 0 | L31: 0 | M31: 0 | N31: 0 | P31: =P32+P33 -> 0 | Q31: =Q32+Q33 -> 0 | R31: =R32+R33 -> 0 | S31: =S32+S33 -> 0 | T31: =T32+T33 -> 0 | U31: =U32+U33 -> 0 | V31: =V32+V33 -> 0 | W31: =W32+W33 -> 0 | ... AB31: =AB32+AB33 -> 0
A32: 9.1 | B32: Non- Operating Income | C32: 0 | D32: 0 | E32: 0 | F32: 0 | G32: 0 | H32: 0 | I32: 0 | J32: 0 | K32: 0 | L32: 0 | M32: 0 | N32: 0 | O32: 0 | P32: 0 | Q32: 0 | R32: 0 | S32: 0 | T32: 0 | U32: 0 | V32: 0 | W32: 0 | X32: 0 | Y32: 0 | Z32: 0 | AA32: 0 | AB32: 0
A33: 9.2 | B33: Non- Operating Expense | C33: 0 | D33: 0 | E33: 0 | F33: 0 | G33: 0 | H33: 0 | I33: 0 | J33: 0 | K33: 0 | L33: 0 | M33: 0 | N33: 0 | O33: 0 | P33: 0 | Q33: 0 | R33: 0 | S33: 0 | T33: 0 | U33: 0 | V33: 0 | W33: 0 | X33: 0 | Y33: 0 | Z33: 0 | AA33: 0 | AB33: 0
A34: 10 | B34: Net Income (Before Taxes and Donations) | C34: 9607940.5 | D34: 7085310.1 | E34: 11697087 | F34: 15223032 | G34: 18151542 | H34: 21392407 | I34: 28511082 | J34: 51589802 | K34: 54344584 | L34: 49952042 | M34: 58770533 | N34: 66428158 | O34: =O30+O31 -> 68261292 | P34: =P30+P31 -> 5225785.9 | Q34: =Q30+Q31 -> 14599688 | R34: =R30+R31 -> 11772636 | S34: =S30+S31 -> 16115368 | T34: =T30+T31 -> 40728840 | U34: =U30+U31 -> 45482834 | V34: =V30+V31 -> 48340162 | ... AB34: =AB30+AB31 -> 78923127
A35: 11 | B35: Taxes (Incomes taxes & Other payable to KRA) | C35: 0 | D35: 0 | E35: 0 | F35: 0 | G35: 0 | H35: 0 | I35: 0 | J35: 0 | K35: 0 | L35: 0 | M35: 0 | N35: 0 | O35: 1833135 | P35: 0 | Q35: 0 | R35: 0 | S35: 0 | T35: 0 | U35: 0 | V35: 0 | W35: 0 | X35: 0 | Y35: 0 | Z35: 0 | AA35: 0 | AB35: 2023472
A36: 12 | B36: Net Income (After Taxes before Donations) | C36: 9607940.5 | D36: 7085310.1 | E36: 11697087 | F36: 15223032 | G36: 18151542 | H36: 21392407 | I36: 28511082 | J36: 51589802 | K36: 54344584 | L36: 49952042 | M36: 58770533 | N36: 66428158 | O36: =O34-O35 -> 66428157 | P36: =P34-P35 -> 5225785.9 | Q36: =Q34-Q35 -> 14599688 | R36: =R34-R35 -> 11772636 | S36: =S34-S35 -> 16115368 | T36: =T34-T35 -> 40728840 | U36: =U34-U35 -> 45482834 | V36: =V34-V35 -> 48340162 | ... AB36: =AB34-AB35 -> 76899655
A37: 13 | B37: Donations | C37: 0 | D37: 0 | E37: 0 | F37: 0 | G37: 0 | H37: 0 | I37: 0 | J37: 0 | K37: 0 | L37: 0 | M37: 0 | N37: 0 | P37: 0 | Q37: 0 | R37: 0 | S37: 0 | T37: 0 | U37: 0 | V37: 0 | W37: 0 | X37: 0 | Y37: 0 | Z37: 0 | AA37: 0
A38: 14 | B38: Net Income/(After Taxes and Donations) | C38: 9607940.5 | D38: 7085310.1 | E38: 11697087 | F38: 15223032 | G38: 18151542 | H38: 21392407 | I38: 28511082 | J38: 51589802 | K38: 54344584 | L38: 49952042 | M38: 58770533 | N38: 66428158 | O38: =O36-O37 -> 66428157 | P38: =P36-P37 -> 5225785.9 | Q38: =Q36-Q37 -> 14599688 | R38: =R36-R37 -> 11772636 | S38: =S36-S37 -> 16115368 | T38: =T36-T37 -> 40728840 | U38: =U36-U37 -> 45482834 | V38: =V36-V37 -> 48340162 | ... AB38: =AB36-AB37 -> 76899655

Sheet Form 4
C6: FORM 4
E7: Asili Dec 2020
C9: CLASSIFICATION | D9: NO. OF A/Cs | E9: OUTSTANDING LOAN PORTFOLIO(Kshs) | F9: REQUIRED PROVISION | G9: REQUIRED PROVISION AMOUNT(Kshs)
C10: Performing | D10: 5790 | E10: 1291907968 | F10: 0.01 | G10: 12919080
C11: Watch | D11: 187 | E11: 33942581 | F11: 0.05 | G11: 1697129.1
C12: Substandard | D12: 100 | E12: 8995683 | F12: 0.25 | G12: 2248920.8
C13: Doubtful | D13: 345 | E13: 18595817 | F13: 0.5 | G13: 9297908.5
C14: Loss | D14: 90 | E14: 7930218 | F14: 1 | G14: 7930218
C15: subtotal | D15: 6512 | E15: 1361372267 | F15: 1.81 | G15: 34093256
C17: Performing | F17: 0.01 | G17: -
C18: Watch | F18: 0.05 | G18: -
C19: Substandard | F19: 0.25 | G19: -
C20: Doubtful | F20: 0.5 | G20: -
C21: Loss | F21: 1 | G21: -
C22: subtotal | D22: 6512 | E22: 1361372267 | F22: 3.62 | G22: 34093256
D26: NPL | E26: 35521718
D27: PAR | E27: 0.03
E30: 44734
C31: CLASSIFICATION | D31: NO. OF A/Cs | E31: OUTSTANDING LOAN PORTFOLIO(Kshs) | F31: REQUIRED PROVISION | G31: REQUIRED PROVISION AMOUNT(Kshs)
C32: Performing | D32: 0 | E32: 1409610099 | F32: 0.01 | G32: =PRODUCT(F32,(E32)) -> 14096101
C33: Watch | D33: 0 | E33: 7309816 | F33: 0.05 | G33: =PRODUCT(F33,(E33)) -> 365490.8
C34: Substandard | D34: 0 | E34: 12853492 | F34: 0.25 | G34: =PRODUCT(F34,(E34)) -> 3213373
C35: Doubtful | D35: 0 | E35: 4231292 | F35: 0.5 | G35: =PRODUCT(F35,(E35)) -> 2115646
C36: Loss | D36: 0 | E36: 12682250 | F36: 1 | G36: =PRODUCT(F36,(E36)) -> 12682250
C37: subtotal | D37: =SUM(D32:D36) -> 0 | E37: =SUM(E32:E36) -> 1446686949 | F37: 1.81 | G37: =SUM(G32:G36) -> 32472861
C39: Performing | F39: 0.01 | G39: -
C40: Watch | F40: 0.05 | G40: -
C41: Substandard | F41: 0.25 | G41: -
C42: Doubtful | F42: 0.5 | G42: -
C43: Loss | F43: 1 | G43: -
C44: subtotal | D44: =SUM(D32:D36) -> 0 | E44: =SUM(E32:E36) -> 1446686949 | F44: 3.62 | G44: =SUM(G32:G36) -> 32472861
D48: NPL | E48: =SUM(E34:E36) -> 29767034
D49: PAR | E49: =E48/E44 -> 0.020576002

Sheet Financials
A1: SIMBA CHAI SACCO FINANCIALS
A3: Year/month | D3: 44256 | E3: 44287 | F3: 44317 | G3: 44348 | H3: 44378 | I3: 44409 | J3: 44440 | K3: 44470 | L3: 44501 | M3: 44531 | N3: AUDITED 2021 | O3: 44583 | P3: 44614 | Q3: 44642 | R3: 44673 | S3: 44703 | T3: 44734 | U3: 44764 | V3: 44795 | W3: 44826 | X3: 44856 | Y3: 44887 | Z3: 44917 | AA3: AUDITED 2022
A4: Membership | B4: 44197 | C4: 44228 | N4: 19469 | AA4: 20670
A5: Total Assets | B5: ='Balance Sheet'!C26 -> 1.4856463e+09 | C5: ='Balance Sheet'!D26 -> 1.4597409e+09 | D5: ='Balance Sheet'!E26 -> 1.463541e+09 | E5: ='Balance Sheet'!F26 -> 1.4700895e+09 | F5: ='Balance Sheet'!G26 -> 1.4914299e+09 | G5: ='Balance Sheet'!H26 -> 1.5070689e+09 | H5: ='Balance Sheet'!I26 -> 1.5262474e+09 | I5: ='Balance Sheet'!J26 -> 1.627252e+09 | ... AA5: ='Balance Sheet'!AB26 -> 1955372560
A6: Total Deposits | B6: =B7+B8 -> 7.7471589e+08 | C6: =C7+C8 -> 7.4976593e+08 | D6: =D7+D8 -> 7.498099e+08 | E6: =E7+E8 -> 7.5024663e+08 | F6: =F7+F8 -> 766484680 | G6: =G7+G8 -> 7.748575e+08 | H6: =H7+H8 -> 7.7783288e+08 | I6: =I7+I8 -> 7.7586489e+08 | ... AA6: =AA7+AA8 -> 933969568
A7: Deposits-Members(BOSA) | B7: ='Balance Sheet'!C29 -> 6.5401113e+08 | C7: ='Balance Sheet'!D29 -> 6.6305658e+08 | D7: ='Balance Sheet'!E29 -> 6.6252983e+08 | E7: ='Balance Sheet'!F29 -> 6.6921464e+08 | F7: ='Balance Sheet'!G29 -> 6.7630342e+08 | G7: ='Balance Sheet'!H29 -> 6.8374153e+08 | H7: ='Balance Sheet'!I29 -> 6.9034687e+08 | I7: ='Balance Sheet'!J29 -> 6.9395618e+08 | ... AA7: ='Balance Sheet'!AB29 -> 846911037
A8: Deposits-Customers(FOSA) | B8: ='Balance Sheet'!C27 -> 1.2070476e+08 | C8: ='Balance Sheet'!D27 -> 86709347 | D8: ='Balance Sheet'!E27 -> 87280070 | E8: ='Balance Sheet'!F27 -> 81031983 | F8: ='Balance Sheet'!G27 -> 90181263 | G8: ='Balance Sheet'!H27 -> 91115968 | H8: ='Balance Sheet'!I27 -> 87486013 | I8: ='Balance Sheet'!J27 -> 81908706 | ... AA8: ='Balance Sheet'!AB27 -> 87058531
A9: Deposits-Term | B9: ='Balance Sheet'!C28 -> 5511362.5 | C9: ='Balance Sheet'!D28 -> 6907659.4 | D9: ='Balance Sheet'!E28 -> 8662909.7 | E9: ='Balance Sheet'!F28 -> 10119314 | F9: ='Balance Sheet'!G28 -> 11742283 | G9: ='Balance Sheet'!H28 -> 16908758 | H9: ='Balance Sheet'!I28 -> 19268497 | I9: ='Balance Sheet'!J28 -> 20940363 | ... AA9: ='Balance Sheet'!AB28 -> 17802865
A10: External Borrowing | B10: ='Balance Sheet'!C38 -> 1.1072699e+09 | C10: ='Balance Sheet'!D38 -> 1.0837541e+09 | D10: ='Balance Sheet'!E38 -> 1.0828071e+09 | E10: ='Balance Sheet'!F38 -> 1.0856875e+09 | F10: ='Balance Sheet'!G38 -> 1.1039629e+09 | G10: ='Balance Sheet'!H38 -> 1.1162236e+09 | H10: ='Balance Sheet'!I38 -> 1.1281598e+09 | I10: ='Balance Sheet'!J38 -> 1.2059728e+09 | ... AA10: ='Balance Sheet'!AB38 -> 1444105223
A12: Share capital and Reserves
A13: Core Capital | B13: =B15-B28 -> 3.7837637e+08 | C13: =C15-C28 -> 3.7598681e+08 | D13: =D15-D28 -> 3.8073381e+08 | E13: =E15-E28 -> 3.8440197e+08 | F13: =F15-F28 -> 3.8746703e+08 | G13: =G15-G28 -> 3.9084538e+08 | H13: =H15-H28 -> 3.9808758e+08 | I13: =I15-I28 -> 4.2127927e+08 | ... AA13: =AA15-AA28 -> 5.0281109e+08
A14: Institutional Capital | B14: =B13-B16 -> 3.259567e+08 | C14: =C13-C16 -> 3.2343407e+08 | D14: =D13-D16 -> 3.2804584e+08 | E14: =E13-E16 -> 3.3157179e+08 | F14: =F13-F16 -> 3.345003e+08 | G14: =G13-G16 -> 3.3774116e+08 | H14: =H13-H16 -> 3.4485984e+08 | I14: =I13-I16 -> 3.6793856e+08 | ... AA14: =AA13-AA16 -> 4.4778349e+08
A15: Total Capital | B15: =B16+B17+B18+B19+B20+B21 -> 3.7837637e+08 | C15: =C16+C17+C18+C19+C20+C21 -> 3.7598681e+08 | D15: =D16+D17+D18+D19+D20+D21 -> 3.8073381e+08 | E15: =E16+E17+E18+E19+E20+E21 -> 3.8440197e+08 | F15: =F16+F17+F18+F19+F20+F21 -> 3.8746703e+08 | G15: =G16+G17+G18+G19+G20+G21 -> 3.9084538e+08 | H15: =H16+H17+H18+H19+H20+H21 -> 3.9808758e+08 | I15: =I16+I17+I18+I19+I20+I21 -> 4.2127927e+08 | ... AA15: =AA16+AA17+AA18+AA19+AA20+AA21 -> 5.0281109e+08
A16: Members Share Capital | B16: ='Balance Sheet'!C39 -> 52419678 | C16: ='Balance Sheet'!D39 -> 52552740 | D16: ='Balance Sheet'!E39 -> 52687971 | E16: ='Balance Sheet'!F39 -> 52830180 | F16: ='Balance Sheet'!G39 -> 52966730 | G16: ='Balance Sheet'!H39 -> 53104216 | H16: ='Balance Sheet'!I39 -> 53227743 | I16: ='Balance Sheet'!J39 -> 53340708 | ... V16: ='Balance Sheet'!W39 -> 54731545 | W16: ='Balance Sheet'!W39 -> 54731545 | X16: ='Balance Sheet'!X39 -> 54822146 | Y16: ='Balance Sheet'!Y39 -> 54894147 | Z16: ='Balance Sheet'!Z39 -> 54968651 | AA16: ='Balance Sheet'!AA39 -> 55027598
A17: Entrance Fees
A18: Retained Earnings | B18: ='Balance Sheet'!C41 -> 2.1953918e+08 | C18: ='Balance Sheet'!D41 -> 2.1701655e+08 | D18: ='Balance Sheet'!E41 -> 2.2162833e+08 | E18: ='Balance Sheet'!F41 -> 2.2515427e+08 | F18: ='Balance Sheet'!G41 -> 2.2808278e+08 | G18: ='Balance Sheet'!H41 -> 2.3132365e+08 | H18: ='Balance Sheet'!I41 -> 2.3844232e+08 | I18: ='Balance Sheet'!J41 -> 2.6152104e+08 | ... V18: ='Balance Sheet'!W41 -> 3.137427e+08 | W18: ='Balance Sheet'!W41 -> 3.137427e+08 | X18: ='Balance Sheet'!X41 -> 3.1151991e+08 | Y18: ='Balance Sheet'!Y41 -> 3.1461587e+08 | Z18: ='Balance Sheet'!Z41 -> 3.1503821e+08 | AA18: ='Balance Sheet'!AA41 -> 3.0762503e+08
A19: Appropriation Account | B19: ='Balance Sheet'!C48 -> 0 | C19: ='Balance Sheet'!D48 -> 0 | D19: ='Balance Sheet'!E48 -> 0 | E19: ='Balance Sheet'!F48 -> 0 | F19: ='Balance Sheet'!G48 -> 0 | G19: ='Balance Sheet'!H48 -> 0 | H19: ='Balance Sheet'!I48 -> 0 | I19: ='Balance Sheet'!J48 -> 0 | ... V19: ='Balance Sheet'!W48 -> 0 | W19: ='Balance Sheet'!W48 -> 0 | X19: ='Balance Sheet'!X48 -> 0 | Y19: ='Balance Sheet'!Y48 -> 0 | Z19: ='Balance Sheet'!Z48 -> 0 | AA19: ='Balance Sheet'!AA48 -> 5502759.8
A20: Statutory Reserves | B20: ='Balance Sheet'!C45 -> 77497515 | C20: ='Balance Sheet'!D45 -> 77497515 | D20: ='Balance Sheet'!E45 -> 77497515 | E20: ='Balance Sheet'!F45 -> 77497515 | F20: ='Balance Sheet'!G45 -> 77497515 | G20: ='Balance Sheet'!H45 -> 77497515 | H20: ='Balance Sheet'!I45 -> 77497515 | I20: ='Balance Sheet'!J45 -> 77497515 | ... V20: ='Balance Sheet'!W45 -> 90783147 | W20: ='Balance Sheet'!W45 -> 90783147 | X20: ='Balance Sheet'!X45 -> 90783147 | Y20: ='Balance Sheet'!Y45 -> 90783147 | Z20: ='Balance Sheet'!Z45 -> 90783147 | AA20: ='Balance Sheet'!AA45 -> 1.057357e+08
A21: Capital Reserves | B21: ='Balance Sheet'!C46 -> 28920000 | C21: ='Balance Sheet'!D46 -> 28920000 | D21: ='Balance Sheet'!E46 -> 28920000 | E21: ='Balance Sheet'!F46 -> 28920000 | F21: ='Balance Sheet'!G46 -> 28920000 | G21: ='Balance Sheet'!H46 -> 28920000 | H21: ='Balance Sheet'!I46 -> 28920000 | I21: ='Balance Sheet'!J46 -> 28920000 | ... V21: ='Balance Sheet'!W46 -> 28920000 | W21: ='Balance Sheet'!W46 -> 28920000 | X21: ='Balance Sheet'!X46 -> 28920000 | Y21: ='Balance Sheet'!Y46 -> 28920000 | Z21: ='Balance Sheet'!Z46 -> 28920000 | AA21: ='Balance Sheet'!AA46 -> 28920000
A22: Supplementary Capital & reserves
A23: Proposed Dividends
A24: Benevolent Fund
A25: Investments | B25: =B26+B27+B29 -> 21355306 | C25: =C26+C27+C29 -> 21455306 | D25: =D26+D27+D29 -> 21555306 | E25: =E26+E27+E29 -> 21655306 | F25: =F26+F27+F29 -> 22055306 | G25: =G26+G27+G29 -> 22155306 | H25: =H26+H27+H29 -> 22255306 | I25: =I26+I27+I29 -> 22355306 | ... AA25: =AA26+AA27+AA29 -> 59164958
A26: Govt bills | B26: ='Balance Sheet'!C8 -> 21355306 | C26: ='Balance Sheet'!D8 -> 21455306 | D26: ='Balance Sheet'!E8 -> 21555306 | E26: ='Balance Sheet'!F8 -> 21655306 | F26: ='Balance Sheet'!G8 -> 22055306 | G26: ='Balance Sheet'!H8 -> 22155306 | H26: ='Balance Sheet'!I8 -> 22255306 | I26: ='Balance Sheet'!J8 -> 22355306 | ... AA26: ='Balance Sheet'!AB8 -> 29582479
A27: Investments in naccos | B27: ='Balance Sheet'!C11 -> 0 | C27: ='Balance Sheet'!D11 -> 0 | D27: ='Balance Sheet'!E11 -> 0 | E27: ='Balance Sheet'!F11 -> 0 | F27: ='Balance Sheet'!G11 -> 0 | G27: ='Balance Sheet'!H11 -> 0 | H27: ='Balance Sheet'!I11 -> 0 | I27: ='Balance Sheet'!J11 -> 0 | ... AA27: ='Balance Sheet'!AB11 -> 27240079
A28: Equity Investments (at cost) | B28: ='Balance Sheet'!C9 -> 0 | C28: ='Balance Sheet'!D9 -> 0 | D28: ='Balance Sheet'!E9 -> 0 | E28: ='Balance Sheet'!F9 -> 0 | F28: ='Balance Sheet'!G9 -> 0 | G28: ='Balance Sheet'!H9 -> 0 | H28: ='Balance Sheet'!I9 -> 0 | I28: ='Balance Sheet'!J9 -> 0 | ... AA28: ='Balance Sheet'!AB9 -> 0
A29: Deposits in KUSCCO CFP | B29: ='Balance Sheet'!C10 -> 0 | C29: ='Balance Sheet'!D10 -> 0 | D29: ='Balance Sheet'!E10 -> 0 | E29: ='Balance Sheet'!F10 -> 0 | F29: ='Balance Sheet'!G10 -> 0 | G29: ='Balance Sheet'!H10 -> 0 | H29: ='Balance Sheet'!I10 -> 0 | I29: ='Balance Sheet'!J10 -> 0 | ... AA29: ='Balance Sheet'!AB10 -> 2342400
A30: Net Loans & Advances | B30: =B31-B32 -> -26000000 | C30: =C31-C32 -> -26000000 | D30: =D31-D32 -> -26000000 | E30: =E31-E32 -> -26000000 | F30: =F31-F32 -> -26000000 | G30: =G31-G32 -> -26000000 | H30: =H31-H32 -> -26000000 | I30: =I31-I32 -> -26000000 | ... AA30: =AA31-AA32 -> -36000000
A31: Gross Loans & advances | B31: ='Balance Sheet'!C13 -> 9.9058452e+08 | C31: ='Balance Sheet'!D13 -> 1.0043206e+09 | D31: ='Balance Sheet'!E13 -> 1.0103717e+09 | E31: ='Balance Sheet'!F13 -> 1.0301766e+09 | F31: ='Balance Sheet'!G13 -> 1.0595091e+09 | G31: ='Balance Sheet'!H13 -> 1.0827801e+09 | H31: ='Balance Sheet'!I13 -> 1.1110403e+09 | I31: ='Balance Sheet'!J13 -> 1.1370757e+09 | ... AA31: ='Balance Sheet'!AB13 -> 1479857871
A32: Allowance for loan losses | B32: ='Balance Sheet'!C14 -> 1.0165845e+09 | C32: ='Balance Sheet'!D14 -> 1.0303206e+09 | D32: ='Balance Sheet'!E14 -> 1.0363717e+09 | E32: ='Balance Sheet'!F14 -> 1.0561766e+09 | F32: ='Balance Sheet'!G14 -> 1.0855091e+09 | G32: ='Balance Sheet'!H14 -> 1.1087801e+09 | H32: ='Balance Sheet'!I14 -> 1.1370403e+09 | I32: ='Balance Sheet'!J14 -> 1.1630757e+09 | ... AA32: ='Balance Sheet'!AB14 -> 1515857871
A34: Non-Earning Assets | B34: ='Balance Sheet'!C6+'Balance Sheet'!C15+'Balance Sheet'!C19 -> 2.6094181e+08 | C34: ='Balance Sheet'!D6+'Balance Sheet'!D15+'Balance Sheet'!D19 -> 1.9458408e+08 | D34: ='Balance Sheet'!E6+'Balance Sheet'!E15+'Balance Sheet'!E19 -> 1.870725e+08 | E34: ='Balance Sheet'!F6+'Balance Sheet'!F15+'Balance Sheet'!F19 -> 1.7961791e+08 | F34: ='Balance Sheet'!G6+'Balance Sheet'!G15+'Balance Sheet'!G19 -> 1.6651989e+08 | G34: ='Balance Sheet'!H6+'Balance Sheet'!H15+'Balance Sheet'!H19 -> 1.5430952e+08 | H34: ='Balance Sheet'!I6+'Balance Sheet'!I15+'Balance Sheet'!I19 -> 1.446173e+08 | I34: ='Balance Sheet'!J6+'Balance Sheet'!J15+'Balance Sheet'!J19 -> 2.1922101e+08 | ... AA34: ='Balance Sheet'!AB6+'Balance Sheet'!AB15+'Balance Sheet'!AB19 -> 128561384
A35: Property and Equipment | B35: ='Balance Sheet'!C19 -> 0 | C35: ='Balance Sheet'!D19 -> 0 | D35: ='Balance Sheet'!E19 -> 0 | E35: ='Balance Sheet'!F19 -> 0 | F35: ='Balance Sheet'!G19 -> 0 | G35: ='Balance Sheet'!H19 -> 0 | H35: ='Balance Sheet'!I19 -> 0 | I35: ='Balance Sheet'!J19 -> 0 | ... AA35: ='Balance Sheet'!AB19 -> 0
A38: Turnover | B38: =B39+B41+B42 -> 12658619 | C38: =C39+C41+C42 -> 25469318 | D38: =D39+D41+D42 -> 39898518 | E38: =E39+E41+E42 -> 53321185 | F38: =F39+F41+F42 -> 66212095 | G38: =G39+G41+G42 -> 79683698 | H38: =H39+H41+H42 -> 94822089 | I38: =I39+I41+I42 -> 1.3722944e+08 | ... AA38: =AA39+AA41+AA42 -> 273371575
A39: Loan Interest | B39: ='Income Stat.'!C6 -> 12527019 | C39: ='Income Stat.'!D6 -> 25218828 | D39: ='Income Stat.'!E6 -> 38820698 | E39: ='Income Stat.'!F6 -> 50965201 | F39: ='Income Stat.'!G6 -> 63692311 | G39: ='Income Stat.'!H6 -> 77005164 | H39: ='Income Stat.'!I6 -> 91456394 | I39: ='Income Stat.'!J6 -> 1.3368729e+08 | ... AA39: ='Income Stat.'!AB6 -> 255622714
A40: Yield on loans | B40: ='Income Stat.'!C6/'Income Stat.'!C14 -> #DIV/0! | C40: ='Income Stat.'!D6/'Income Stat.'!D14 -> 2.2820521 | D40: ='Income Stat.'!E6/'Income Stat.'!E14 -> 2.3437857 | E40: ='Income Stat.'!F6/'Income Stat.'!F14 -> 2.284702 | F40: ='Income Stat.'!G6/'Income Stat.'!G14 -> 2.260251 | G40: ='Income Stat.'!H6/'Income Stat.'!H14 -> 2.2524641 | H40: ='Income Stat.'!I6/'Income Stat.'!I14 -> 2.2763624 | I40: ='Income Stat.'!J6/'Income Stat.'!J14 -> 2.8896773 | ... AA40: ='Income Stat.'!AB6/'Income Stat.'!AB14 -> 2.9642041
A41: Income from investments | B41: ='Income Stat.'!C8 -> 0 | C41: ='Income Stat.'!D8 -> 0 | D41: ='Income Stat.'!E8 -> 693880 | E41: ='Income Stat.'!F8 -> 1826143.8 | F41: ='Income Stat.'!G8 -> 1826143.8 | G41: ='Income Stat.'!H8 -> 1826143.8 | H41: ='Income Stat.'!I8 -> 2322505 | I41: ='Income Stat.'!J8 -> 2322505 | ... AA41: ='Income Stat.'!AB8 -> 3476992
A42: Fees & Commissions | B42: ='Income Stat.'!C7 -> 131600 | C42: ='Income Stat.'!D7 -> 250490 | D42: ='Income Stat.'!E7 -> 383940 | E42: ='Income Stat.'!F7 -> 529840 | F42: ='Income Stat.'!G7 -> 693640 | G42: ='Income Stat.'!H7 -> 852390 | H42: ='Income Stat.'!I7 -> 1043190 | I42: ='Income Stat.'!J7 -> 1219640 | ... AA42: ='Income Stat.'!AB7 -> 14271869
A44: Finanacial and Operating costs | B44: =B45+B46+B47+B48 -> 10605408 | C44: =C45+C46+C47+C48 -> 21859128 | D44: =D45+D46+D47+D48 -> 34863683 | E44: =E45+E46+E47+E48 -> 46766011 | F44: =F45+F46+F47+F48 -> 58427302 | G44: =G45+G46+G47+G48 -> 70094590 | H44: =H45+H46+H47+H48 -> 83913022 | I44: =I45+I46+I47+I48 -> 1.2003164e+08 | ... AA44: =AA45+AA46+AA47+AA48 -> 212041427
A45: Interest expense on deposits | B45: ='Income Stat.'!C14 -> 0 | C45: ='Income Stat.'!D14 -> 11050943 | D45: ='Income Stat.'!E14 -> 16563246 | E45: ='Income Stat.'!F14 -> 22307155 | F45: ='Income Stat.'!G14 -> 28179309 | G45: ='Income Stat.'!H14 -> 34187077 | H45: ='Income Stat.'!I14 -> 40176552 | I45: ='Income Stat.'!J14 -> 46263745 | ... AA45: ='Income Stat.'!AB14 -> 86236542
A46: Dividend expense on share capital | B46: ='Income Stat.'!C16 -> 0 | C46: ='Income Stat.'!D16 -> 0 | D46: ='Income Stat.'!E16 -> 0 | E46: ='Income Stat.'!F16 -> 0 | F46: ='Income Stat.'!G16 -> 0 | G46: ='Income Stat.'!H16 -> 0 | H46: ='Income Stat.'!I16 -> 0 | I46: ='Income Stat.'!J16 -> 0 | ... AA46: ='Income Stat.'!AB16 -> 0
...

Sheet CAEL
A1: SIMBA CHAI SACCO CAELS 2020
C2: Regulatory Stds | D2: 44197 | E2: 44228 | F2: 44256 | G2: 44287 | H2: 44317 | I2: 44348 | J2: 44378 | K2: 44409 | L2: 44440 | M2: 44470 | N2: 44501 | O2: 44531 | P2: AUDITED 2021 | Q2: 44583 | R2: 44614 | S2: 44642 | T2: 44673 | U2: 44703 | V2: 44734 | W2: 44764 | X2: 44795 | Y2: 44826 | Z2: 44856 | AA2: 44887 | AB2: 44917 | AC2: AUDITED 2022
A3: CAPITAL ADEQUACY | B3: Core Capital | C3: 10 M | D3: =Financials!B13 -> 3.7837637e+08 | E3: =Financials!C13 -> 3.7598681e+08 | F3: =Financials!D13 -> 3.8073381e+08 | G3: =Financials!E13 -> 3.8440197e+08 | H3: =Financials!F13 -> 3.8746703e+08 | I3: =Financials!G13 -> 3.9084538e+08 | J3: =Financials!H13 -> 3.9808758e+08 | K3: =Financials!I13 -> 4.2127927e+08 | ... AC3: =Financials!AA13 -> 5.0281109e+08
B4: CCA | C4: 0.1 | D4: =Financials!B13/Financials!B5 -> 0.25468806 | E4: =Financials!C13/Financials!C5 -> 0.25757092 | F4: =Financials!D13/Financials!D5 -> 0.26014565 | G4: =Financials!E13/Financials!E5 -> 0.26148202 | H4: =Financials!F13/Financials!F5 -> 0.25979566 | I4: =Financials!G13/Financials!G5 -> 0.2593414 | J4: =Financials!H13/Financials!H5 -> 0.26082769 | K4: =Financials!I13/Financials!I5 -> 0.25888999 | ... AC4: =Financials!AA13/Financials!AA5 -> 0.25714337
B5: CCD | C5: 0.08 | D5: =Financials!B13/Financials!B6 -> 0.48840663 | E5: =Financials!C13/Financials!C6 -> 0.50147225 | F5: =Financials!D13/Financials!D6 -> 0.50777379 | G5: =Financials!E13/Financials!E6 -> 0.51236747 | H5: =Financials!F13/Financials!F6 -> 0.50551177 | I5: =Financials!G13/Financials!G6 -> 0.50440936 | J5: =Financials!H13/Financials!H6 -> 0.51179063 | K5: =Financials!I13/Financials!I6 -> 0.54298019 | ... AC5: =Financials!AA13/Financials!AA6 -> 0.53835918
B6: ICA | C6: 0.08 | D6: =(Financials!B15-Financials!B16)/Financials!B5 -> 0.21940397 | E6: =(Financials!C15-Financials!C16)/Financials!C5 -> 0.22156951 | F6: =(Financials!D15-Financials!D16)/Financials!D5 -> 0.22414531 | G6: =(Financials!E15-Financials!E16)/Financials!E5 -> 0.22554531 | H6: =(Financials!F15-Financials!F16)/Financials!F5 -> 0.2242816 | I6: =(Financials!G15-Financials!G16)/Financials!G5 -> 0.22410465 | J6: =(Financials!H15-Financials!H16)/Financials!H5 -> 0.22595278 | K6: =(Financials!I15-Financials!I16)/Financials!I5 -> 0.22611037 | ... AC6: =(Financials!AA15-Financials!AA16)/Financials!AA5 -> 0.22900162
A7: ASSET QUALITY | B7: A/LNPL30
B8: NPL30 | D8: =6.5% -> 0.065 | E8: =6.5% -> 0.065 | F8: =6.5% -> 0.065 | G8: =6.5% -> 0.065 | H8: =6.5% -> 0.065 | I8: =6.5% -> 0.065 | J8: =6.5% -> 0.065 | K8: =6.5% -> 0.065 | ... AC8: =6.5% -> 0.065
B9: Non-earning Asset ratio | C9: Max 10% | D9: =('Balance Sheet'!C7+'Balance Sheet'!C20)/'Balance Sheet'!C26 -> 0.15651145 | E9: =('Balance Sheet'!D7+'Balance Sheet'!D20)/'Balance Sheet'!D26 -> 0.17797965 | F9: =('Balance Sheet'!E7+'Balance Sheet'!E20)/'Balance Sheet'!E26 -> 0.18205575 | G9: =('Balance Sheet'!F7+'Balance Sheet'!F20)/'Balance Sheet'!F26 -> 0.17772785 | H9: =('Balance Sheet'!G7+'Balance Sheet'!G20)/'Balance Sheet'!G26 -> 0.17839004 | I9: =('Balance Sheet'!H7+'Balance Sheet'!H20)/'Balance Sheet'!H26 -> 0.1792539 | J9: =('Balance Sheet'!I7+'Balance Sheet'!I20)/'Balance Sheet'!I26 -> 0.17803228 | K9: =('Balance Sheet'!J7+'Balance Sheet'!J20)/'Balance Sheet'!J26 -> 0.16420793 | ... AC9: =('Balance Sheet'!AB7+'Balance Sheet'!AB20)/'Balance Sheet'!AB26 -> 0.17384799
B10: Land and Building ratio | C10: Max 5% | D10: =('Balance Sheet'!C21+'Balance Sheet'!C22)/'Balance Sheet'!C26 -> 0.031752297 | E10: =('Balance Sheet'!D21+'Balance Sheet'!D22)/'Balance Sheet'!D26 -> 0.054240779 | F10: =('Balance Sheet'!E21+'Balance Sheet'!E22)/'Balance Sheet'!E26 -> 0.054211317 | G10: =('Balance Sheet'!F21+'Balance Sheet'!F22)/'Balance Sheet'!F26 -> 0.055242063 | H10: =('Balance Sheet'!G21+'Balance Sheet'!G22)/'Balance Sheet'!G26 -> 0.054623397 | I10: =('Balance Sheet'!H21+'Balance Sheet'!H22)/'Balance Sheet'!H26 -> 0.055259608 | J10: =('Balance Sheet'!I21+'Balance Sheet'!I22)/'Balance Sheet'!I26 -> 0.05474872 | K10: =('Balance Sheet'!J21+'Balance Sheet'!J22)/'Balance Sheet'!J26 -> 0.051445418 | ... P10: =('Balance Sheet'!O21+'Balance Sheet'!O22)/'Balance Sheet'!O26 -> 0.054502137 | Q10: =('Balance Sheet'!P17+'Balance Sheet'!P18)/'Balance Sheet'!P20 -> 0 | R10: =('Balance Sheet'!Q17+'Balance Sheet'!Q18)/'Balance Sheet'!Q20 -> 0 | S10: =('Balance Sheet'!R17+'Balance Sheet'!R18)/'Balance Sheet'!R20 -> 0 | T10: =('Balance Sheet'!S17+'Balance Sheet'!S18)/'Balance Sheet'!S20 -> 0 | U10: =('Balance Sheet'!T17+'Balance Sheet'!T18)/'Balance Sheet'!T20 -> 0 | V10: =('Balance Sheet'!U17+'Balance Sheet'!U18)/'Balance Sheet'!U20 -> 0 | W10: =('Balance Sheet'!V17+'Balance Sheet'!V18)/'Balance Sheet'!V20 -> 0 | X10: =('Balance Sheet'!W17+'Balance Sheet'!W18)/'Balance Sheet'!W20 -> 0 | ... AC10: =('Balance Sheet'!AB17+'Balance Sheet'!AB18)/'Balance Sheet'!AB20 -> 0
A11: EARNINGS | B11: Non-Government Investment to Deposit ratio | C11: Max 5% | D11: ='Balance Sheet'!C11/'Balance Sheet'!C29 -> 0 | E11: ='Balance Sheet'!D11/'Balance Sheet'!D29 -> 0 | F11: ='Balance Sheet'!E11/'Balance Sheet'!E29 -> 0 | G11: ='Balance Sheet'!F11/'Balance Sheet'!F29 -> 0 | H11: ='Balance Sheet'!G11/'Balance Sheet'!G29 -> 0 | I11: ='Balance Sheet'!H11/'Balance Sheet'!H29 -> 0 | J11: ='Balance Sheet'!I11/'Balance Sheet'!I29 -> 0 | K11: ='Balance Sheet'!J11/'Balance Sheet'!J29 -> 0 | ... P11: ='Balance Sheet'!O11/'Balance Sheet'!O29 -> 0.00042433456 | Q11: ='Balance Sheet'!P9/'Balance Sheet'!P23 -> #DIV/0! | R11: ='Balance Sheet'!Q9/'Balance Sheet'!Q23 -> #DIV/0! | S11: ='Balance Sheet'!R9/'Balance Sheet'!R23 -> #DIV/0! | T11: ='Balance Sheet'!S9/'Balance Sheet'!S23 -> #DIV/0! | U11: ='Balance Sheet'!T9/'Balance Sheet'!T23 -> #DIV/0! | V11: ='Balance Sheet'!U9/'Balance Sheet'!U23 -> #DIV/0! | W11: ='Balance Sheet'!V9/'Balance Sheet'!V23 -> #DIV/0! | X11: ='Balance Sheet'!W9/'Balance Sheet'!W23 -> #DIV/0! | ... AC11: ='Balance Sheet'!AB9/'Balance Sheet'!AB23 -> #DIV/0!
B12: Non-Government Investment to Core Capital ratio | C12: Max 40% | D12: ='Balance Sheet'!C11/Financials!B13 -> 0 | E12: ='Balance Sheet'!D11/Financials!C13 -> 0 | F12: ='Balance Sheet'!E11/Financials!D13 -> 0 | G12: ='Balance Sheet'!F11/Financials!E13 -> 0 | H12: ='Balance Sheet'!G11/Financials!F13 -> 0 | I12: ='Balance Sheet'!H11/Financials!G13 -> 0 | J12: ='Balance Sheet'!I11/Financials!H13 -> 0 | K12: ='Balance Sheet'!J11/Financials!I13 -> 0 | ... P12: ='Balance Sheet'!O11/Financials!N13 -> 0.00071423878 | Q12: ='Balance Sheet'!P9/Financials!O13 -> 0 | R12: ='Balance Sheet'!Q9/Financials!P13 -> 0 | S12: ='Balance Sheet'!R9/Financials!Q13 -> 0 | T12: ='Balance Sheet'!S9/Financials!R13 -> 0 | U12: ='Balance Sheet'!T9/Financials!S13 -> 0 | V12: ='Balance Sheet'!U9/Financials!T13 -> 0 | W12: ='Balance Sheet'!V9/Financials!U13 -> 0 | X12: ='Balance Sheet'!W9/Financials!V13 -> 0 | ... AC12: ='Balance Sheet'!AB9/Financials!AA13 -> 0
B13: Gross loans/TA | D13: =Financials!B31/Financials!B5 -> 0.66677008 | E13: =Financials!C31/Financials!C5 -> 0.68801293 | F13: =Financials!D31/Financials!D5 -> 0.69036105 | G13: =Financials!E31/Financials!E5 -> 0.70075779 | H13: =Financials!F31/Financials!F5 -> 0.71039816 | I13: =Financials!G31/Financials!G5 -> 0.71846753 | J13: =Financials!H31/Financials!H5 -> 0.72795557 | K13: =Financials!I31/Financials!I5 -> 0.69877047 | ... AC13: =Financials!AA31/Financials!AA5 -> 0.75681632
B14: ROA | D14: ='Income Stat.'!C38/Financials!B5 -> 0.0064671789 | E14: ='Income Stat.'!D38/Financials!C5 -> 0.0048538136 | F14: ='Income Stat.'!E38/Financials!D5 -> 0.0079923199 | G14: ='Income Stat.'!F38/Financials!E5 -> 0.010355174 | H14: ='Income Stat.'!G38/Financials!F5 -> 0.012170563 | I14: ='Income Stat.'!H38/Financials!G5 -> 0.01419471 | J14: ='Income Stat.'!I38/Financials!H5 -> 0.018680512 | K14: ='Income Stat.'!J38/Financials!I5 -> 0.031703634 | ... AB14: ='Income Stat.'!AA38/Financials!Z5 -> 0.038354771 | AC14: ='Income Stat.'!#REF!/Financials!AA5 -> #REF!
B15: Cost Income ratio | D15: ='Income Stat.'!C24/('Income Stat.'!C20-'Income Stat.'!C22) -> 0.28427312 | E15: ='Income Stat.'!D24/('Income Stat.'!D20-'Income Stat.'!D22) -> 0.48648744 | F15: ='Income Stat.'!E24/('Income Stat.'!E20-'Income Stat.'!E22) -> 0.44333951 | G15: ='Income Stat.'!F24/('Income Stat.'!F20-'Income Stat.'!F22) -> 0.44100607 | H15: ='Income Stat.'!G24/('Income Stat.'!G20-'Income Stat.'!G22) -> 0.44360333 | I15: ='Income Stat.'!H24/('Income Stat.'!H20-'Income Stat.'!H22) -> 0.45019346 | J15: ='Income Stat.'!I24/('Income Stat.'!I20-'Income Stat.'!I22) -> 0.41324728 | K15: ='Income Stat.'!J24/('Income Stat.'!J20-'Income Stat.'!J22) -> 0.30397958 | ... AB15: ='Income Stat.'!AA24/('Income Stat.'!AA20-'Income Stat.'!AA22) -> 0.39524188 | AC15: ='Income Stat.'!#REF!/('Income Stat.'!#REF!-'Income Stat.'!#REF!) -> #REF!
B16: Operating Expense ratio | D16: ='Income Stat.'!C24/'Income Stat.'!C4 -> 0.26370413 | E16: ='Income Stat.'!D24/'Income Stat.'!D4 -> 0.23457403 | F16: ='Income Stat.'!E24/'Income Stat.'!E4 -> 0.21043712 | G16: ='Income Stat.'!F24/'Income Stat.'!F4 -> 0.20389515 | H16: ='Income Stat.'!G24/'Income Stat.'!G4 -> 0.19805782 | I16: ='Income Stat.'!H24/'Income Stat.'!H4 -> 0.19948684 | J16: ='Income Stat.'!I24/'Income Stat.'!I4 -> 0.19264326 | K16: ='Income Stat.'!J24/'Income Stat.'!J4 -> 0.15235132 | ... P16: ='Income Stat.'!O24/'Income Stat.'!O4 -> 0.15882339 | Q16: ='Income Stat.'!P20/'Income Stat.'!P4 -> 0.47967631 | R16: ='Income Stat.'!Q20/'Income Stat.'!Q4 -> 0.60660701 | S16: ='Income Stat.'!R20/'Income Stat.'!R4 -> 0.41564368 | T16: ='Income Stat.'!S20/'Income Stat.'!S4 -> 0.46124033 | U16: ='Income Stat.'!T20/'Income Stat.'!T4 -> 0.50728279 | V16: ='Income Stat.'!U20/'Income Stat.'!U4 -> 0.49781805 | W16: ='Income Stat.'!V20/'Income Stat.'!V4 -> 0.45573915 | X16: ='Income Stat.'!W20/'Income Stat.'!W4 -> 0.48606158 | ... AB16: ='Income Stat.'!AA20/'Income Stat.'!AA4 -> 0.47151864 | AC16: ='Income Stat.'!#REF!/'Income Stat.'!#REF! -> #REF!
A17: LIQUIDITY | B17: MIN LIQ ratio | C17: Min 15% | D17: ='Balance Sheet'!C4/'Balance Sheet'!C27 -> 1.9981468 | E17: ='Balance Sheet'!D4/'Balance Sheet'!D27 -> 2.0085585 | F17: ='Balance Sheet'!E4/'Balance Sheet'!E27 -> 1.89239 | G17: ='Balance Sheet'!F4/'Balance Sheet'!F27 -> 1.9372805 | H17: ='Balance Sheet'!G4/'Balance Sheet'!G27 -> 1.5946695 | I17: ='Balance Sheet'!H4/'Balance Sheet'!H27 -> 1.4485447 | J17: ='Balance Sheet'!I4/'Balance Sheet'!I27 -> 1.3857128 | K17: ='Balance Sheet'!J4/'Balance Sheet'!J27 -> 2.4492313 | ... AC17: ='Balance Sheet'!AB4/'Balance Sheet'!AB27 -> 1.21751
B18: Technical LIQ ratio | D18: ='Balance Sheet'!C4/'Balance Sheet'!C29 -> 0.36877941 | E18: ='Balance Sheet'!D4/'Balance Sheet'!D29 -> 0.26266355 | F18: ='Balance Sheet'!E4/'Balance Sheet'!E29 -> 0.24929886 | G18: ='Balance Sheet'!F4/'Balance Sheet'!F29 -> 0.23457598 | H18: ='Balance Sheet'!G4/'Balance Sheet'!G29 -> 0.21264023 | I18: ='Balance Sheet'!H4/'Balance Sheet'!H29 -> 0.19303427 | J18: ='Balance Sheet'!I4/'Balance Sheet'!I29 -> 0.17560808 | K18: ='Balance Sheet'!J4/'Balance Sheet'!J29 -> 0.28908651 | ... AC18: ='Balance Sheet'!AB4/'Balance Sheet'!AB29 -> 0.12515438
B19: External Borrowing ratio | C19: Max 25% | D19: ='Balance Sheet'!C38/'Balance Sheet'!C26 -> 0.74531194 | E19: ='Balance Sheet'!D38/'Balance Sheet'!D26 -> 0.74242908 | F19: ='Balance Sheet'!E38/'Balance Sheet'!E26 -> 0.73985435 | G19: ='Balance Sheet'!F38/'Balance Sheet'!F26 -> 0.73851798 | H19: ='Balance Sheet'!G38/'Balance Sheet'!G26 -> 0.74020434 | I19: ='Balance Sheet'!H38/'Balance Sheet'!H26 -> 0.7406586 | J19: ='Balance Sheet'!I38/'Balance Sheet'!I26 -> 0.73917231 | K19: ='Balance Sheet'!J38/'Balance Sheet'!J26 -> 0.74111001 | ... P19: ='Balance Sheet'!O38/'Balance Sheet'!O26 -> 0.73751107 | Q19: ='Balance Sheet'!P27/'Balance Sheet'!P20 -> 1.372644 | R19: ='Balance Sheet'!Q27/'Balance Sheet'!Q20 -> 0.92763399 | S19: ='Balance Sheet'!R27/'Balance Sheet'!R20 -> 0.83278465 | T19: ='Balance Sheet'!S27/'Balance Sheet'!S20 -> 0.71206357 | U19: ='Balance Sheet'!T27/'Balance Sheet'!T20 -> 0.70024135 | V19: ='Balance Sheet'!U27/'Balance Sheet'!U20 -> 0.63893209 | W19: ='Balance Sheet'!V27/'Balance Sheet'!V20 -> 0.50393846 | X19: ='Balance Sheet'!W27/'Balance Sheet'!W20 -> 0.50746825 | ... AC19: ='Balance Sheet'!AB27/'Balance Sheet'!AB20 -> 0.51844518
