Workbook
Name BALANCE1_LDA01: '[1]Financial Statements'!$E$112
Name BALANCE1_LDA12: '[1]Financial Statements'!$E$123
Name BALANCE2_LDA01: '[1]Financial Statements'!$F$112
Name BALANCE2_LDA12: '[1]Financial Statements'!$F$123
Name BALANCE3_LDA01: '[1]Financial Statements'!$G$112
Name BALANCE3_LDA12: '[1]Financial Statements'!$G$123
Name BALANCE4_LDA01: '[1]Financial Statements'!$H$112
Name BALANCE4_LDA12: '[1]Financial Statements'!$H$123
Name BALANCE5_LDA01: '[1]Financial Statements'!$I$112
Name BALANCE5_LDA12: '[1]Financial Statements'!$I$123
Name BALANCE6_LDA01: '[1]Financial Statements'!$J$112
Name BALANCE6_LDA12: '[1]Financial Statements'!$J$123
Name NotApplicable: 'Prudential Ratios'!$B$76
Name PEARLS1_LA002: '[1]Financial Statements'!$E$280
Name PEARLS1_LE008: '[1]Financial Statements'!$E$275
Name PEARLS1_LE009: '[1]Financial Statements'!$E$276
Name PEARLS1_LR001: '[1]Financial Statements'!$E$282
Name PEARLS1_LR005: '[1]Financial Statements'!$E$286
Name PEARLS1_LR006: '[1]Financial Statements'!$E$287
Name PEARLS1_LR007: '[1]Financial Statements'!$E$288
Name PEARLS1_LR009: '[1]Financial Statements'!$E$290
Name PEARLS1_LS001: '[1]Financial Statements'!$E$298
Name PEARLS1_LS005: '[1]Financial Statements'!$E$302
Name PEARLS1_LS011: '[1]Financial Statements'!$E$308
Name PEARLS2_LA002: '[1]Financial Statements'!$F$280
Name PEARLS2_LE008: '[1]Financial Statements'!$F$275
Name PEARLS2_LE009: '[1]Financial Statements'!$F$276
Name PEARLS2_LR001: '[1]Financial Statements'!$F$282
Name PEARLS2_LR005: '[1]Financial Statements'!$F$286
Name PEARLS2_LR006: '[1]Financial Statements'!$F$287
Name PEARLS2_LR007: '[1]Financial Statements'!$F$288
Name PEARLS2_LR009: '[1]Financial Statements'!$F$290
Name PEARLS2_LS001: '[1]Financial Statements'!$F$298
Name PEARLS2_LS005: '[1]Financial Statements'!$F$302
Name PEARLS2_LS010: '[1]Financial Statements'!$F$307
Name PEARLS2_LS011: '[1]Financial Statements'!$F$308
Name PEARLS3_LA002: '[1]Financial Statements'!$G$280
Name PEARLS3_LE008: '[1]Financial Statements'!$G$275
Name PEARLS3_LE009: '[1]Financial Statements'!$G$276
Name PEARLS3_LR001: '[1]Financial Statements'!$G$282
Name PEARLS3_LR005: '[1]Financial Statements'!$G$286
Name PEARLS3_LR006: '[1]Financial Statements'!$G$287
Name PEARLS3_LR007: '[1]Financial Statements'!$G$288
Name PEARLS3_LR009: '[1]Financial Statements'!$G$290
Name PEARLS3_LS001: '[1]Financial Statements'!$G$298
Name PEARLS3_LS005: '[1]Financial Statements'!$G$302
Name PEARLS3_LS010: '[1]Financial Statements'!$G$307
Name PEARLS3_LS011: '[1]Financial Statements'!$G$308
Name PEARLS4_LA002: '[1]Financial Statements'!$H$280
Name PEARLS4_LE008: '[1]Financial Statements'!$H$275
Name PEARLS4_LE009: '[1]Financial Statements'!$H$276
Name PEARLS4_LR001: '[1]Financial Statements'!$H$282
Name PEARLS4_LR005: '[1]Financial Statements'!$H$286
Name PEARLS4_LR006: '[1]Financial Statements'!$H$287
Name PEARLS4_LR007: '[1]Financial Statements'!$H$288
Name PEARLS4_LR009: '[1]Financial Statements'!$H$290
Name PEARLS4_LS001: '[1]Financial Statements'!$H$298
Name PEARLS4_LS005: '[1]Financial Statements'!$H$302
Name PEARLS4_LS010: '[1]Financial Statements'!$H$307
Name PEARLS4_LS011: '[1]Financial Statements'!$H$308

Sheet compliance status
B2: audited2017 | C2: 43101 | D2: 43133 | E2: 43165 | F2: 43197 | G2: 43229 | H2: 43261 | I2: 43293 | J2: 43325 | K2: 43357 | L2: 43389 | M2: 43421 | N2: 43453
A3: CORE CAPITAL | B3: =IF('Prudential Ratios'!#REF!>10,"compliant","not compliant") -> #REF! | C3: =IF('Prudential Ratios'!#REF!>10,"compliant","not compliant") -> #REF! | D3: =IF('Prudential Ratios'!#REF!>10,"compliant","not compliant") -> #REF! | E3: =IF('Prudential Ratios'!#REF!>10,"compliant","not compliant") -> #REF! | F3: =IF('Prudential Ratios'!#REF!>10,"compliant","not compliant") -> #REF! | G3: =IF('Prudential Ratios'!#REF!>10,"compliant","not compliant") -> #REF! | H3: =IF('Prudential Ratios'!#REF!>10,"compliant","not compliant") -> #REF! | I3: =IF('Prudential Ratios'!#REF!>10,"compliant","not compliant") -> #REF! | ... N3: =IF('Prudential Ratios'!#REF!>10,"compliant","not compliant") -> #REF!
A4: CCA (Min 10%) | B4: =IF('Prudential Ratios'!#REF!>10%,"compliant","not compliant") -> #REF! | C4: =IF('Prudential Ratios'!#REF!>10%,"compliant","not compliant") -> #REF! | D4: =IF('Prudential Ratios'!#REF!>10%,"compliant","not compliant") -> #REF! | E4: =IF('Prudential Ratios'!#REF!>10%,"compliant","not compliant") -> #REF! | F4: =IF('Prudential Ratios'!#REF!>10%,"compliant","not compliant") -> #REF! | G4: =IF('Prudential Ratios'!#REF!>10%,"compliant","not compliant") -> #REF! | H4: =IF('Prudential Ratios'!#REF!>10%,"compliant","not compliant") -> #REF! | I4: =IF('Prudential Ratios'!#REF!>10%,"compliant","not compliant") -> #REF! | ... N4: =IF('Prudential Ratios'!#REF!>10%,"compliant","not compliant") -> #REF!
A5: ICA (Min 8%) | B5: =IF('Prudential Ratios'!#REF!>8%,"compliant","not compliant") -> #REF! | C5: =IF('Prudential Ratios'!#REF!>8%,"compliant","not compliant") -> #REF! | D5: =IF('Prudential Ratios'!#REF!>8%,"compliant","not compliant") -> #REF! | E5: =IF('Prudential Ratios'!#REF!>8%,"compliant","not compliant") -> #REF! | F5: =IF('Prudential Ratios'!#REF!>8%,"compliant","not compliant") -> #REF! | G5: =IF('Prudential Ratios'!#REF!>8%,"compliant","not compliant") -> #REF! | H5: =IF('Prudential Ratios'!#REF!>8%,"compliant","not compliant") -> #REF! | I5: =IF('Prudential Ratios'!#REF!>8%,"compliant","not compliant") -> #REF! | ... N5: =IF('Prudential Ratios'!#REF!>8%,"compliant","not compliant") -> #REF!
A6: CCD (Min 8%) | B6: =IF('Prudential Ratios'!#REF!>8%,"compliant","not compliant") -> #REF! | C6: =IF('Prudential Ratios'!#REF!>8%,"compliant","not compliant") -> #REF! | D6: =IF('Prudential Ratios'!#REF!>8%,"compliant","not compliant") -> #REF! | E6: =IF('Prudential Ratios'!#REF!>8%,"compliant","not compliant") -> #REF! | F6: =IF('Prudential Ratios'!#REF!>8%,"compliant","not compliant") -> #REF! | G6: =IF('Prudential Ratios'!#REF!>8%,"compliant","not compliant") -> #REF! | H6: =IF('Prudential Ratios'!#REF!>8%,"compliant","not compliant") -> #REF! | I6: =IF('Prudential Ratios'!#REF!>8%,"compliant","not compliant") -> #REF! | ... N6: =IF('Prudential Ratios'!#REF!>8%,"compliant","not compliant") -> #REF!
A7: NPL(5%)
A8: Liquidity(15%) | B8: =IF('Prudential Ratios'!#REF!>15%,"compliant","not compliant") -> #REF! | C8: =IF('Prudential Ratios'!#REF!>15%,"compliant","not compliant") -> #REF! | D8: =IF('Prudential Ratios'!#REF!>15%,"compliant","not compliant") -> #REF! | E8: =IF('Prudential Ratios'!#REF!>15%,"compliant","not compliant") -> #REF! | F8: =IF('Prudential Ratios'!#REF!>15%,"compliant","not compliant") -> #REF! | G8: =IF('Prudential Ratios'!#REF!>15%,"compliant","not compliant") -> #REF! | H8: =IF('Prudential Ratios'!#REF!>15%,"compliant","not compliant") -> #REF! | I8: =IF('Prudential Ratios'!#REF!>15%,"compliant","not compliant") -> #REF! | ... N8: =IF('Prudential Ratios'!#REF!>15%,"compliant","not compliant") -> #REF!
A9: NEA (Max 10%) | B9: =IF('Prudential Ratios'!#REF!<10%,"compliant","not compliant") -> #REF! | C9: =IF('Prudential Ratios'!#REF!<10%,"compliant","not compliant") -> #REF! | D9: =IF('Prudential Ratios'!#REF!<10%,"compliant","not compliant") -> #REF! | E9: =IF('Prudential Ratios'!#REF!<10%,"compliant","not compliant") -> #REF! | F9: =IF('Prudential Ratios'!#REF!<10%,"compliant","not compliant") -> #REF! | G9: =IF('Prudential Ratios'!#REF!<10%,"compliant","not compliant") -> #REF! | H9: =IF('Prudential Ratios'!#REF!<10%,"compliant","not compliant") -> #REF! | I9: =IF('Prudential Ratios'!#REF!<10%,"compliant","not compliant") -> #REF! | ... N9: =IF('Prudential Ratios'!#REF!<10%,"compliant","not compliant") -> #REF!
A10: LB ratio (Max 5%) | B10: =IF('Prudential Ratios'!#REF!<5%,"compliant","not compliant") -> #REF! | C10: =IF('Prudential Ratios'!#REF!<5%,"compliant","not compliant") -> #REF! | D10: =IF('Prudential Ratios'!#REF!<5%,"compliant","not compliant") -> #REF! | E10: =IF('Prudential Ratios'!#REF!<5%,"compliant","not compliant") -> #REF! | F10: =IF('Prudential Ratios'!#REF!<5%,"compliant","not compliant") -> #REF! | G10: =IF('Prudential Ratios'!#REF!<5%,"compliant","not compliant") -> #REF! | H10: =IF('Prudential Ratios'!#REF!<5%,"compliant","not compliant") -> #REF! | I10: =IF('Prudential Ratios'!#REF!<5%,"compliant","not compliant") -> #REF! | ... N10: =IF('Prudential Ratios'!#REF!<5%,"compliant","not compliant") -> #REF!
A11: FITD (Max 5%) | B11: =IF('Prudential Ratios'!#REF!<5%,"compliant","not compliant") -> #REF! | C11: =IF('Prudential Ratios'!#REF!<5%,"compliant","not compliant") -> #REF! | D11: =IF('Prudential Ratios'!#REF!<5%,"compliant","not compliant") -> #REF! | E11: =IF('Prudential Ratios'!#REF!<5%,"compliant","not compliant") -> #REF! | F11: =IF('Prudential Ratios'!#REF!<5%,"compliant","not compliant") -> #REF! | G11: =IF('Prudential Ratios'!#REF!<5%,"compliant","not compliant") -> #REF! | H11: =IF('Prudential Ratios'!#REF!<5%,"compliant","not compliant") -> #REF! | I11: =IF('Prudential Ratios'!#REF!<5%,"compliant","not compliant") -> #REF! | ... N11: =IF('Prudential Ratios'!#REF!<5%,"compliant","not compliant") -> #REF!
A12: FICC (Max 40%) | B12: =IF('Prudential Ratios'!#REF!<40%,"compliant","not compliant") -> #REF! | C12: =IF('Prudential Ratios'!#REF!<40%,"compliant","not compliant") -> #REF! | D12: =IF('Prudential Ratios'!#REF!<40%,"compliant","not compliant") -> #REF! | E12: =IF('Prudential Ratios'!#REF!<40%,"compliant","not compliant") -> #REF! | F12: =IF('Prudential Ratios'!#REF!<40%,"compliant","not compliant") -> #REF! | G12: =IF('Prudential Ratios'!#REF!<40%,"compliant","not compliant") -> #REF! | H12: =IF('Prudential Ratios'!#REF!<40%,"compliant","not compliant") -> #REF! | I12: =IF('Prudential Ratios'!#REF!<40%,"compliant","not compliant") -> #REF! | ... N12: =IF('Prudential Ratios'!#REF!<40%,"compliant","not compliant") -> #REF!
A13: EB ratio | B13: =IF('Prudential Ratios'!#REF!<25%,"compliant","not compliant") -> #REF! | C13: =IF('Prudential Ratios'!#REF!<25%,"compliant","not compliant") -> #REF! | D13: =IF('Prudential Ratios'!#REF!<25%,"compliant","not compliant") -> #REF! | E13: =IF('Prudential Ratios'!#REF!<25%,"compliant","not compliant") -> #REF! | F13: =IF('Prudential Ratios'!#REF!<25%,"compliant","not compliant") -> #REF! | G13: =IF('Prudential Ratios'!#REF!<25%,"compliant","not compliant") -> #REF! | H13: =IF('Prudential Ratios'!#REF!<25%,"compliant","not compliant") -> #REF! | I13: =IF('Prudential Ratios'!#REF!<25%,"compliant","not compliant") -> #REF! | ... N13: =IF('Prudential Ratios'!#REF!<25%,"compliant","not compliant") -> #REF!
A14: A=S+L | B14: =IF(SFP!#REF!=SFP!#REF!,"balancing","notbalancing") -> #REF! | C14: =IF(SFP!#REF!=SFP!#REF!,"balancing","notbalancing") -> #REF! | D14: =IF(SFP!#REF!=SFP!#REF!,"balancing","notbalancing") -> #REF! | E14: =IF(SFP!#REF!=SFP!#REF!,"balancing","notbalancing") -> #REF! | F14: =IF(SFP!#REF!=SFP!#REF!,"balancing","notbalancing") -> #REF! | G14: =IF(SFP!#REF!=SFP!#REF!,"balancing","notbalancing") -> #REF! | H14: =IF(SFP!#REF!=SFP!#REF!,"balancing","notbalancing") -> #REF! | I14: =IF(SFP!#REF!=SFP!#REF!,"balancing","notbalancing") -> #REF! | ... N14: =IF(SFP!#REF!=SFP!#REF!,"balancing","notbalancing") -> #REF!

Sheet Prudential Ratios
C1: SIRAJI SACCO SOCIETY LTD
C2: Sacco Financial Performance
C4: FINANCIAL SOUNDNESS INDICATORS | D4: Prude. Std | E4: Audited 2020 | F4: 44197 | G4: 44228 | H4: 44256 | I4: 44287 | J4: 44317 | K4: 44348 | L4: 44378 | M4: 44409 | N4: 44440 | O4: 44470 | P4: 44501 | Q4: 44531 | R4: Audited 2021 | S4: 44562 | T4: 44593 | U4: 44621 | V4: 44652 | W4: 44682 | X4: 44713 | Y4: 44743 | Z4: 44774 | AA4: 44805 | AB4: 44835 | AC4: 44866 | AD4: 44896 | AE4: Audited-2022 | AF4: 44949 | AG4: 44980 | AH4: 45008 | AI4: 45039 | AJ4: 45069 | AK4: 45100 | AL4: 45130
B5: 1 | C5: CAPITAL ADEQUACY REQUIREMENTS
B6: 1.1 | C6: Core capital | D6: ≥ Ksh.10M | E6: =Financials!C14/1000000 -> 82.86228 | F6: =Financials!D14/1000000 -> #REF! | G6: =Financials!E14/1000000 -> #REF! | H6: =Financials!F14/1000000 -> #REF! | I6: =Financials!G14/1000000 -> #REF! | J6: =Financials!H14/1000000 -> #REF! | K6: =Financials!I14/1000000 -> #REF! | L6: =Financials!J14/1000000 -> #REF! | ... AK6: =Financials!AI14/1000000 -> 110.76706
B7: 1.2 | C7: Core capital /Total Assets | D7: ≥ 10% | E7: =Financials!C14/Financials!C5 -> 0.18351443 | F7: =Financials!D14/Financials!D5 -> #REF! | G7: =Financials!E14/Financials!E5 -> #REF! | H7: =Financials!F14/Financials!F5 -> #REF! | I7: =Financials!G14/Financials!G5 -> #REF! | J7: =Financials!H14/Financials!H5 -> #REF! | K7: =Financials!I14/Financials!I5 -> #REF! | L7: =Financials!J14/Financials!J5 -> #REF! | ... AK7: =Financials!AI14/Financials!AI5 -> 0.18298427
B8: 1.3 | C8: Core capital /Total Deposits | D8: ≥ 10% | E8: =Financials!C14/Financials!C6 -> 0.23971315 | F8: =Financials!D14/Financials!D6 -> #REF! | G8: =Financials!E14/Financials!E6 -> #REF! | H8: =Financials!F14/Financials!F6 -> #REF! | I8: =Financials!G14/Financials!G6 -> #REF! | J8: =Financials!H14/Financials!H6 -> #REF! | K8: =Financials!I14/Financials!I6 -> #REF! | L8: =Financials!J14/Financials!J6 -> #REF! | ... AK8: =Financials!AI14/Financials!AI6 -> 0.23255829
B9: 1.4 | C9: Share Capital/Total Assets | D9: ≤2% | E9: =Financials!C18/Financials!C5 -> 0.11014337 | F9: =Financials!D18/Financials!D5 -> 0.23514028 | G9: =Financials!E18/Financials!E5 -> 0.21931147 | H9: =Financials!F18/Financials!F5 -> 0.2099177 | I9: =Financials!G18/Financials!G5 -> 0.23720838 | J9: =Financials!H18/Financials!H5 -> 0.22073574 | K9: =Financials!I18/Financials!I5 -> 0.22483873 | L9: =Financials!J18/Financials!J5 -> 0.24465651 | ... AK9: =Financials!AI18/Financials!AI5 -> 0.089128923
B10: 1.5 | C10: Institutional Capital/Total Assets | D10: ≥ 8% | E10: =Financials!C15/Financials!C5 -> 0.073371063 | F10: =Financials!D15/Financials!D5 -> #REF! | G10: =Financials!E15/Financials!E5 -> #REF! | H10: =Financials!F15/Financials!F5 -> #REF! | I10: =Financials!G15/Financials!G5 -> #REF! | J10: =Financials!H15/Financials!H5 -> #REF! | K10: =Financials!I15/Financials!I5 -> #REF! | L10: =Financials!J15/Financials!J5 -> #REF! | ... AK10: =Financials!AI15/Financials!AI5 -> 0.093855346
B12: 2 | C12: ASSET MIX AND QUALITY
B13: 2.1 | C13: Non Earning Assets
B14: 2.1.1 | C14: Non earning Assets/Total assets | D14: ≤ 10% | E14: =Financials!C38/Financials!C5 -> 0.12852222 | F14: =Financials!D38/Financials!D5 -> 10.384985 | G14: =Financials!E38/Financials!E5 -> 9.6357278 | H14: =Financials!F38/Financials!F5 -> 9.6793191 | I14: =Financials!G38/Financials!G5 -> 9.9006137 | J14: =Financials!H38/Financials!H5 -> 10.881615 | K14: =Financials!I38/Financials!I5 -> 10.188674 | L14: =Financials!J38/Financials!J5 -> 10.851818 | ... AK14: =Financials!AI38/Financials!AI5 -> 0.20864098
B15: 2.1.2 | C15: Property and Equipment/Total Assets | D15: ≤ 5% | E15: =Financials!C39/Financials!C5 -> 0.051737546 | F15: =Financials!D39/Financials!D5 -> 0 | G15: =Financials!E39/Financials!E5 -> 0 | H15: =Financials!F39/Financials!F5 -> 0 | I15: =Financials!G39/Financials!G5 -> 0 | J15: =Financials!H39/Financials!H5 -> 0 | K15: =Financials!I39/Financials!I5 -> 0 | L15: =Financials!J39/Financials!J5 -> 0 | ... AK15: =Financials!AI39/Financials!AI5 -> 0.10941436
B16: 2.1.3 | C16: Non Performing loans/Gross Loans | D16: ≤ 6%
B18: 2.2 | C18: Earning Assets
B19: 2.2.1 | C19: Equities & Investments/Deposits | D19: ≤ 5% | E19: =Financials!C26/Financials!C6 -> 0.00029466029 | F19: =Financials!D26/Financials!D6 -> 321254.66 | G19: =Financials!E26/Financials!E6 -> 322432.63 | H19: =Financials!F26/Financials!F6 -> -19.581498 | I19: =Financials!G26/Financials!G6 -> -19.442138 | J19: =Financials!H26/Financials!H6 -> #DIV/0! | K19: =Financials!I26/Financials!I6 -> -5172.7261 | L19: =Financials!J26/Financials!J6 -> -5075.8957 | ... AK19: =Financials!AI26/Financials!AI6 -> 0.00021384929
B20: 2.2.2 | C20: Equities & Investments/Core Capital | D20: ≤ 40% | E20: =Financials!C26/Financials!C14 -> 0.0012292203 | F20: =Financials!D26/Financials!D14 -> #REF! | G20: =Financials!E26/Financials!E14 -> #REF! | H20: =Financials!F26/Financials!F14 -> #REF! | I20: =Financials!G26/Financials!G14 -> #REF! | J20: =Financials!H26/Financials!H14 -> #REF! | K20: =Financials!I26/Financials!I14 -> #REF! | L20: =Financials!J26/Financials!J14 -> #REF! | ... AK20: =Financials!AI26/Financials!AI14 -> 0.00091955136
B21: 2.2.3 | C21: Net Loans & advances /Total assets | D21: NPR | E21: =Financials!C31/Financials!C5 -> 0.69107084 | F21: =Financials!D31/Financials!D5 -> 0.52803041 | G21: =Financials!E31/Financials!E5 -> 0.5035063 | H21: =Financials!F31/Financials!F5 -> 0.49248807 | I21: =Financials!G31/Financials!G5 -> 0.52312284 | J21: =Financials!H31/Financials!H5 -> 0.49704011 | K21: =Financials!I31/Financials!I5 -> 0.51688271 | L21: =Financials!J31/Financials!J5 -> 0.57427201 | ... AK21: =Financials!AI31/Financials!AI5 -> 0.60864165
B23: 3 | C23: FUNDING MIX
B24: 3.1 | C24: Total Deposits/Total Assets | D24: NPR | E24: =Financials!C6/Financials!C5 -> 0.76555846 | F24: =Financials!D6/Financials!D5 -> 2.0320892e-05 | G24: =Financials!E6/Financials!E5 -> 1.8952962e-05 | H24: =Financials!F6/Financials!F5 -> -0.29816243 | I24: =Financials!G6/Financials!G5 -> -0.31016953 | J24: =Financials!H6/Financials!H5 -> 0 | K24: =Financials!I6/Financials!I5 -> -0.0011302723 | L24: =Financials!J6/Financials!J5 -> -0.001285647 | ... AK24: =Financials!AI6/Financials!AI5 -> 0.78683185
B25: 3.1.1 | C25: BOSA Deposits/Total Assets | D25: NPR | E25: =Financials!C7/Financials!C5 -> 0.61077217 | F25: =Financials!D7/Financials!D5 -> -0.00024056007 | G25: =Financials!E7/Financials!E5 -> -0.00019788446 | H25: =Financials!F7/Financials!F5 -> 0.014840195 | I25: =Financials!G7/Financials!G5 -> 0.015450499 | J25: =Financials!H7/Financials!H5 -> -0.0030278266 | K25: =Financials!I7/Financials!I5 -> -0.002984841 | L25: =Financials!J7/Financials!J5 -> -0.0032456664 | ... AK25: =Financials!AI7/Financials!AI5 -> 0.68639561
B26: 3.1.2 | C26: FOSA Deposits/Total Assets | D26: NPR | E26: =Financials!C8/Financials!C5 -> 0.1547863 | F26: =Financials!D8/Financials!D5 -> 6.1771683 | G26: =Financials!E8/Financials!E5 -> 5.8692921 | H26: =Financials!F8/Financials!F5 -> 5.6961449 | I26: =Financials!G8/Financials!G5 -> 5.9791496 | J26: =Financials!H8/Financials!H5 -> 5.6213565 | K26: =Financials!I8/Financials!I5 -> 5.8201966 | L26: =Financials!J8/Financials!J5 -> 6.412814 | ... AK26: =Financials!AI8/Financials!AI5 -> 0.09066444
B27: 3.2 | C27: External Borrowing/Total assets | D27: ≤ 25% | E27: =Financials!C9/Financials!C5 -> 0 | F27: =Financials!D9/Financials!D5 -> 0 | G27: =Financials!E9/Financials!E5 -> 0 | H27: =Financials!F9/Financials!F5 -> 0 | I27: =Financials!G9/Financials!G5 -> 0 | J27: =Financials!H9/Financials!H5 -> 0 | K27: =Financials!I9/Financials!I5 -> 0 | L27: =Financials!J9/Financials!J5 -> 0 | ... AK27: =Financials!AI9/Financials!AI5 -> 0.05092209
B29: 4 | C29: GROWTH RATIOS
B30: 4.1 | C30: Total Assets | D30: NPR | E30: =Financials!C5/Financials!B5-1 -> #VALUE! | F30: =Financials!D5/Financials!C5-1 -> -0.89232186 | G30: =Financials!E5/Financials!D5-1 -> 0.072174986 | H30: =Financials!F5/Financials!E5-1 -> 0.044749802 | I30: =Financials!G5/Financials!F5-1 -> -0.038491617 | J30: =Financials!H5/Financials!G5-1 -> 0.074626111 | K30: =Financials!I5/Financials!H5-1 -> -0.018248613 | L30: =Financials!J5/Financials!I5-1 -> -0.081002464 | ... AK30: =Financials!AI5/Financials!AH5-1 -> 0.0064571113
B31: 4.2 | C31: Total Deposits | D31: NPR | E31: =Financials!C6/Financials!B6-1 -> #VALUE! | F31: =Financials!D6/Financials!C6-1 -> -0.99999714 | G31: =Financials!E6/Financials!D6-1 -> 0 | H31: =Financials!F6/Financials!E6-1 -> -16436.697 | I31: =Financials!G6/Financials!F6-1 -> 0.00022863917 | J31: =Financials!H6/Financials!G6-1 -> -1 | K31: =Financials!I6/Financials!H6-1 -> #DIV/0! | L31: =Financials!J6/Financials!I6-1 -> 0.045328977 | ... AK31: =Financials!AI6/Financials!AH6-1 -> 0.011176951
B32: 4.2.1 | C32: FOSA Deposits | D32: NPR | E32: =Financials!C8/Financials!B8-1 -> #VALUE! | F32: =Financials!D8/Financials!C8-1 -> 3.2971891 | G32: =Financials!E8/Financials!D8-1 -> 0.018736717 | H32: =Financials!F8/Financials!E8-1 -> 0.013929132 | I32: =Financials!G8/Financials!F8-1 -> 0.0092795398 | J32: =Financials!H8/Financials!G8-1 -> 0.010320342 | K32: =Financials!I8/Financials!H8-1 -> 0.016478149 | L32: =Financials!J8/Financials!I8-1 -> 0.01257066 | ... AK32: =Financials!AI8/Financials!AH8-1 -> -0.00066380237
B33: 4.2.2 | C33: BOSA Deposits | D33: NPR | E33: =Financials!C7/Financials!B7-1 -> #VALUE! | F33: =Financials!D7/Financials!C7-1 -> -1.0000424 | G33: =Financials!E7/Financials!D7-1 -> -0.11802999 | H33: =Financials!F7/Financials!E7-1 -> -79.35022 | I33: =Financials!G7/Financials!F7-1 -> 0.0010504884 | J33: =Financials!H7/Financials!G7-1 -> -1.2105939 | K33: =Financials!I7/Financials!H7-1 -> -0.032186409 | L33: =Financials!J7/Financials!I7-1 -> -0.00069738483 | ... AK33: =Financials!AI7/Financials!AH7-1 -> 0.0079402142
B34: 4.3 | C34: Net Loans & advances | D34: NPR | E34: =Financials!C31/Financials!B31-1 -> #VALUE! | F34: =Financials!D31/Financials!C31-1 -> -0.91772576 | G34: =Financials!E31/Financials!D31-1 -> 0.022378353 | H34: =Financials!F31/Financials!E31-1 -> 0.021887546 | I34: =Financials!G31/Financials!F31-1 -> 0.021318139 | J34: =Financials!H31/Financials!G31-1 -> 0.021045611 | K34: =Financials!I31/Financials!H31-1 -> 0.020944393 | L34: =Financials!J31/Financials!I31-1 -> 0.021033509 | ... AK34: =Financials!AI31/Financials!AH31-1 -> -0.0052444762
B35: 4.4 | C35: Core capital | D35: NPR | E35: =Financials!C14/Financials!B14-1 -> #VALUE! | F35: =Financials!D14/Financials!C14-1 -> #REF! | G35: =Financials!E14/Financials!D14-1 -> #REF! | H35: =Financials!F14/Financials!E14-1 -> #REF! | I35: =Financials!G14/Financials!F14-1 -> #REF! | J35: =Financials!H14/Financials!G14-1 -> #REF! | K35: =Financials!I14/Financials!H14-1 -> #REF! | L35: =Financials!J14/Financials!I14-1 -> #REF! | ... AK35: =Financials!AI14/Financials!AH14-1 -> 0.015820469
B36: 4.5 | C36: Total Gross Income | D36: NPR | E36: =Financials!C41/Financials!B41-1 -> #VALUE! | F36: =Financials!D41/Financials!C41-1 -> #REF! | G36: =Financials!E41/Financials!D41-1 -> #REF! | H36: =Financials!F41/Financials!E41-1 -> #REF! | I36: =Financials!G41/Financials!F41-1 -> #REF! | J36: =Financials!H41/Financials!G41-1 -> #REF! | K36: =Financials!I41/Financials!H41-1 -> #REF! | L36: =Financials!J41/Financials!I41-1 -> #REF! | ... AK36: =Financials!AI41/Financials!AH41-1 -> 0
B37: 4.6 | C37: Membership | D37: NPR
B39: 5 | C39: Efficiency Ratios
B40: 5.1 | C40: FinCost-Deposits/Average Deposits | D40: NPR | E40: =Financials!C48/((Financials!C6+Financials!B6)/2) -> #VALUE! | F40: =Financials!D48/((Financials!D6+Financials!C6)/2) -> 0 | G40: =Financials!E48/((Financials!E6+Financials!D6)/2) -> 0 | H40: =Financials!F48/((Financials!F6+Financials!E6)/2) -> 0 | I40: =Financials!G48/((Financials!G6+Financials!F6)/2) -> 0 | J40: =Financials!H48/((Financials!H6+Financials!G6)/2) -> 0 | K40: =Financials!I48/((Financials!I6+Financials!H6)/2) -> 0 | L40: =Financials!J48/((Financials!J6+Financials!I6)/2) -> 0 | ... AK40: =Financials!AI48/((Financials!AI6+Financials!AH6)/2) -> 5.9409834e-06
B41: 5.2 | C41: FinCost-Shares/Average Share capital | D41: NPR | E41: =Financials!C49/((Financials!C18+Financials!B18)/2) -> #VALUE! | F41: =Financials!D49/((Financials!D18+Financials!C18)/2) -> 0 | G41: =Financials!E49/((Financials!E18+Financials!D18)/2) -> 0 | H41: =Financials!F49/((Financials!F18+Financials!E18)/2) -> 0 | I41: =Financials!G49/((Financials!G18+Financials!F18)/2) -> 0 | J41: =Financials!H49/((Financials!H18+Financials!G18)/2) -> 0 | K41: =Financials!I49/((Financials!I18+Financials!H18)/2) -> 0 | L41: =Financials!J49/((Financials!J18+Financials!I18)/2) -> 0 | ... AK41: =Financials!AI49/((Financials!AI18+Financials!AH18)/2) -> 0
B42: 5.3 | C42: FinCost-Ext Loans/Average Ext Loans | D42: NPR | E42: =Financials!C50/((Financials!C9+Financials!B9)/2) -> #VALUE! | F42: =Financials!D50/((Financials!D9+Financials!C9)/2) -> #DIV/0! | G42: =Financials!E50/((Financials!E9+Financials!D9)/2) -> #DIV/0! | H42: =Financials!F50/((Financials!F9+Financials!E9)/2) -> #DIV/0! | I42: =Financials!G50/((Financials!G9+Financials!F9)/2) -> #DIV/0! | J42: =Financials!H50/((Financials!H9+Financials!G9)/2) -> #DIV/0! | K42: =Financials!I50/((Financials!I9+Financials!H9)/2) -> #DIV/0! | L42: =Financials!J50/((Financials!J9+Financials!I9)/2) -> #DIV/0! | ... AK42: =Financials!AI50/((Financials!AI9+Financials!AH9)/2) -> 0.041897038
B43: 5.4 | C43: OpEx/Average Total Assets | D43: NPR | E43: =(Financials!C52+Financials!C53)/((Financials!C5+Financials!B5)/2) -> #VALUE! | F43: =(Financials!D52+Financials!D53)/((Financials!D5+Financials!C5)/2) -> 0 | G43: =(Financials!E52+Financials!E53)/((Financials!E5+Financials!D5)/2) -> 0 | H43: =(Financials!F52+Financials!F53)/((Financials!F5+Financials!E5)/2) -> 0 | I43: =(Financials!G52+Financials!G53)/((Financials!G5+Financials!F5)/2) -> 0 | J43: =(Financials!H52+Financials!H53)/((Financials!H5+Financials!G5)/2) -> 0 | K43: =(Financials!I52+Financials!I53)/((Financials!I5+Financials!H5)/2) -> 0 | L43: =(Financials!J52+Financials!J53)/((Financials!J5+Financials!I5)/2) -> 0 | ... AK43: =(Financials!AI52+Financials!AI53)/((Financials!AI5+Financials!AH5)/2) -> 0.023646161
B44: 5.5 | C44: Avge yield on Net loans | D44: NPR | E44: =Financials!C42/((Financials!C31+Financials!B31)/2) -> #VALUE! | F44: =Financials!D42/((Financials!D31+Financials!C31)/2) -> #REF! | G44: =Financials!E42/((Financials!E31+Financials!D31)/2) -> #REF! | H44: =Financials!F42/((Financials!F31+Financials!E31)/2) -> #REF! | I44: =Financials!G42/((Financials!G31+Financials!F31)/2) -> #REF! | J44: =Financials!H42/((Financials!H31+Financials!G31)/2) -> #REF! | K44: =Financials!I42/((Financials!I31+Financials!H31)/2) -> #REF! | L44: =Financials!J42/((Financials!J31+Financials!I31)/2) -> #REF! | ... AK44: =Financials!AI42/((Financials!AI31+Financials!AH31)/2) -> 0.03832879
B46: 6 | C46: Liquidity Ratio
B47: 6.1 | C47: minimum Liquidity | D47: 0.15 | E47: =(SFP!B4+SFP!B11)/(SFP!B31+SFP!B34+SFP!B35+SFP!B36+SFP!B37+SFP!B38) -> 0.27500842 | F47: =(SFP!C4+SFP!C11)/(SFP!C34+SFP!C37+SFP!C38+SFP!C39+SFP!C40+SFP!C42) -> 0.17418078 | G47: =(SFP!D4+SFP!D11)/(SFP!D34+SFP!D37+SFP!D38+SFP!D39+SFP!D40+SFP!D42) -> 0.22560135 | H47: =(SFP!E4+SFP!E11)/(SFP!E34+SFP!E37+SFP!E38+SFP!E39+SFP!E40+SFP!E42) -> 0.14290454 | I47: =(SFP!F4+SFP!F11)/(SFP!F34+SFP!F37+SFP!F38+SFP!F39+SFP!F40+SFP!F42) -> 0.15814051 | J47: =(SFP!G4+SFP!G11)/(SFP!G34+SFP!G37+SFP!G38+SFP!G39+SFP!G40+SFP!G42) -> 0.15150019 | K47: =(SFP!H4+SFP!H11)/(SFP!H34+SFP!H37+SFP!H38+SFP!H39+SFP!H40+SFP!H42) -> 0.13049517 | L47: =(SFP!I4+SFP!I11)/(SFP!I34+SFP!I37+SFP!I38+SFP!I39+SFP!I40+SFP!I42) -> 0.14078519 | M47: =(SFP!J4+SFP!J11)/(SFP!J34+SFP!J37+SFP!J38+SFP!J39+SFP!J40+SFP!J42) -> 0.14569566 | ... Q47: =(SFP!N4+SFP!N11)/(SFP!N34+SFP!N37+SFP!N38+SFP!N39+SFP!N40+SFP!N42) -> #VALUE! | R47: =(SFP!O4+SFP!O11)/(SFP!O31+SFP!O34+SFP!O35+SFP!O36+SFP!O37+SFP!O38) -> 0.26414536 | S47: =(SFP!P4+SFP!P11)/(SFP!P31+SFP!P34+SFP!P35+SFP!P36+SFP!P37+SFP!P38) -> 0.24603496 | T47: =(SFP!Q4+SFP!Q11)/(SFP!Q31+SFP!Q34+SFP!Q35+SFP!Q36+SFP!Q37+SFP!Q38) -> 0.26302353 | U47: =(SFP!R4+SFP!R11)/(SFP!R31+SFP!R34+SFP!R35+SFP!R36+SFP!R37+SFP!R38) -> 0.23782716 | V47: =(SFP!S4+SFP!S11)/(SFP!S31+SFP!S34+SFP!S35+SFP!S36+SFP!S37+SFP!S38) -> 0.20603022 | W47: =(SFP!T4+SFP!T11)/(SFP!T31+SFP!T34+SFP!T35+SFP!T36+SFP!T37+SFP!T38) -> 0.19224947 | X47: =(SFP!U4+SFP!U11)/(SFP!U31+SFP!U34+SFP!U35+SFP!U36+SFP!U37+SFP!U38) -> 0.24560449 | Y47: =(SFP!V4+SFP!V11)/(SFP!V31+SFP!V34+SFP!V35+SFP!V36+SFP!V37+SFP!V38) -> 0.21240258 | ... AK47: =(SFP!AH4+SFP!AH11)/(SFP!AH31+SFP!AH34+SFP!AH35+SFP!AH36+SFP!AH37+SFP!AH38) -> 0.27423882
...

Sheet CAELS
B1: SIRAJI SACCO
B2: FINANCIAL SOUNDNESS INDICATORS | C2: Prude. Std | D2: AUDITED 2013 | E2: AUDITED 2014 | F2: AUDITED 2015 | G2: AUDITED 2016 | H2: AUDITED 2017 | I2: 43101 | J2: 43132 | K2: 43160 | L2: 43191 | M2: 43221 | N2: 43252 | O2: 43282 | P2: 43313 | Q2: 43344 | R2: 43374 | S2: 43405 | T2: 43435 | U2: AUDITED 2018 | V2: 43466 | W2: 43497 | X2: 43525 | Y2: 43556 | Z2: 43586 | AA2: 43617 | AB2: 43647 | AC2: 43678 | AD2: 43709 | AE2: 43739 | AF2: 43770 | AG2: 43800 | AH2: AUDITED 2019 | AI2: 43831 | AJ2: 43862 | AK2: 43891 | AL2: 43922 | AM2: 43952 | AN2: 43983 | AO2: 44013 | AP2: 44044 | AQ2: 44075 | AR2: 44105 | AS2: 44136 | AT2: 44166 | AU2: Audited 2020 | AV2: 44197 | AW2: 44228 | AX2: 44256 | AY2: 44287 | AZ2: 44317 | BA2: 44348 | BB2: 44378 | BC2: 44409 | BD2: 44440 | BE2: 44470 | BF2: 44501 | BG2: 44531 | BH2: Audited 2021 | BI2: 44562 | BJ2: 44593 | BK2: 44621 | BL2: 44652 | BM2: 44682 | BN2: 44713 | BO2: 44743 | BP2: 44774 | BQ2: 44805 | BR2: 44835 | BS2: 44866 | BT2: 44896 | BU2: Audited-2022 | BV2: 44949 | BW2: 44980 | BX2: 45008 | BY2: 45039 | BZ2: 45069 | CA2: 45100
B3: CAPITAL
B4: CORE CAPITAL | C4: ≥ Ksh.10M | D4: ='Prudential Ratios'!#REF! -> #REF! | E4: ='Prudential Ratios'!#REF! -> #REF! | F4: ='Prudential Ratios'!#REF! -> #REF! | G4: ='Prudential Ratios'!#REF! -> #REF! | H4: ='Prudential Ratios'!#REF! -> #REF! | I4: ='Prudential Ratios'!#REF! -> #REF! | J4: ='Prudential Ratios'!#REF! -> #REF! | K4: ='Prudential Ratios'!#REF! -> #REF! | ... AT4: ='Prudential Ratios'!#REF! -> #REF! | AU4: ='Prudential Ratios'!E6 -> 82.86228 | AV4: ='Prudential Ratios'!F6 -> #REF! | AW4: ='Prudential Ratios'!G6 -> #REF! | AX4: ='Prudential Ratios'!H6 -> #REF! | AY4: ='Prudential Ratios'!I6 -> #REF! | AZ4: ='Prudential Ratios'!J6 -> #REF! | BA4: ='Prudential Ratios'!K6 -> #REF! | BB4: ='Prudential Ratios'!L6 -> #REF! | ... CA4: ='Prudential Ratios'!AK6 -> 110.76706
B5: CCA | C5: ≥ 10% | D5: ='Prudential Ratios'!#REF! -> #REF! | E5: ='Prudential Ratios'!#REF! -> #REF! | F5: ='Prudential Ratios'!#REF! -> #REF! | G5: ='Prudential Ratios'!#REF! -> #REF! | H5: ='Prudential Ratios'!#REF! -> #REF! | I5: ='Prudential Ratios'!#REF! -> #REF! | J5: ='Prudential Ratios'!#REF! -> #REF! | K5: ='Prudential Ratios'!#REF! -> #REF! | ... AT5: ='Prudential Ratios'!#REF! -> #REF! | AU5: ='Prudential Ratios'!E7 -> 0.18351443 | AV5: ='Prudential Ratios'!F7 -> #REF! | AW5: ='Prudential Ratios'!G7 -> #REF! | AX5: ='Prudential Ratios'!H7 -> #REF! | AY5: ='Prudential Ratios'!I7 -> #REF! | AZ5: ='Prudential Ratios'!J7 -> #REF! | BA5: ='Prudential Ratios'!K7 -> #REF! | BB5: ='Prudential Ratios'!L7 -> #REF! | ... CA5: ='Prudential Ratios'!AK7 -> 0.18298427
B6: ICA | C6: ≥ 8% | D6: ='Prudential Ratios'!#REF! -> #REF! | E6: ='Prudential Ratios'!#REF! -> #REF! | F6: ='Prudential Ratios'!#REF! -> #REF! | G6: ='Prudential Ratios'!#REF! -> #REF! | H6: ='Prudential Ratios'!#REF! -> #REF! | I6: ='Prudential Ratios'!#REF! -> #REF! | J6: ='Prudential Ratios'!#REF! -> #REF! | K6: ='Prudential Ratios'!#REF! -> #REF! | ... AT6: ='Prudential Ratios'!#REF! -> #REF! | AU6: ='Prudential Ratios'!E10 -> 0.073371063 | AV6: ='Prudential Ratios'!F10 -> #REF! | AW6: ='Prudential Ratios'!G10 -> #REF! | AX6: ='Prudential Ratios'!H10 -> #REF! | AY6: ='Prudential Ratios'!I10 -> #REF! | AZ6: ='Prudential Ratios'!J10 -> #REF! | BA6: ='Prudential Ratios'!K10 -> #REF! | BB6: ='Prudential Ratios'!L10 -> #REF! | ... CA6: ='Prudential Ratios'!AK10 -> 0.093855346
B7: CCD | C7: ≥ 8% | D7: ='Prudential Ratios'!#REF! -> #REF! | E7: ='Prudential Ratios'!#REF! -> #REF! | F7: ='Prudential Ratios'!#REF! -> #REF! | G7: ='Prudential Ratios'!#REF! -> #REF! | H7: ='Prudential Ratios'!#REF! -> #REF! | I7: ='Prudential Ratios'!#REF! -> #REF! | J7: ='Prudential Ratios'!#REF! -> #REF! | K7: ='Prudential Ratios'!#REF! -> #REF! | ... AT7: ='Prudential Ratios'!#REF! -> #REF! | AU7: ='Prudential Ratios'!E8 -> 0.23971315 | AV7: ='Prudential Ratios'!F8 -> #REF! | AW7: ='Prudential Ratios'!G8 -> #REF! | AX7: ='Prudential Ratios'!H8 -> #REF! | AY7: ='Prudential Ratios'!I8 -> #REF! | AZ7: ='Prudential Ratios'!J8 -> #REF! | BA7: ='Prudential Ratios'!K8 -> #REF! | BB7: ='Prudential Ratios'!L8 -> #REF! | ... CA7: ='Prudential Ratios'!AK8 -> 0.23255829
B8: Asset Quality
B9: NPL | C9: ≤ 6% | Q9: =form4!#REF! -> #REF!
B10: Earnings
B11: ROA | D11: ='Prudential Ratios'!#REF! -> #REF! | E11: ='Prudential Ratios'!#REF! -> #REF! | F11: ='Prudential Ratios'!#REF! -> #REF! | G11: ='Prudential Ratios'!#REF! -> #REF! | H11: ='Prudential Ratios'!#REF! -> #REF! | I11: ='Prudential Ratios'!#REF! -> #REF! | J11: ='Prudential Ratios'!#REF! -> #REF! | K11: ='Prudential Ratios'!#REF! -> #REF! | ... AT11: ='Prudential Ratios'!#REF! -> #REF! | AU11: ='Prudential Ratios'!E55 -> #VALUE! | AV11: ='Prudential Ratios'!F55 -> 0 | AW11: ='Prudential Ratios'!G55 -> 0 | AX11: ='Prudential Ratios'!H55 -> 0 | AY11: ='Prudential Ratios'!I55 -> 0 | AZ11: ='Prudential Ratios'!J55 -> 0 | BA11: ='Prudential Ratios'!K55 -> 0 | BB11: ='Prudential Ratios'!L55 -> 0 | ... CA11: ='Prudential Ratios'!AK55 -> 0.041423167
B12: CIR | D12: ='Prudential Ratios'!#REF! -> #REF! | E12: ='Prudential Ratios'!#REF! -> #REF! | F12: ='Prudential Ratios'!#REF! -> #REF! | G12: ='Prudential Ratios'!#REF! -> #REF! | H12: ='Prudential Ratios'!#REF! -> #REF! | I12: ='Prudential Ratios'!#REF! -> #REF! | J12: ='Prudential Ratios'!#REF! -> #REF! | K12: ='Prudential Ratios'!#REF! -> #REF! | ... AT12: ='Prudential Ratios'!#REF! -> #REF! | AU12: ='Prudential Ratios'!E56 -> 0.72533782 | AV12: ='Prudential Ratios'!F56 -> #DIV/0! | AW12: ='Prudential Ratios'!G56 -> #DIV/0! | AX12: ='Prudential Ratios'!H56 -> #DIV/0! | AY12: ='Prudential Ratios'!I56 -> #DIV/0! | AZ12: ='Prudential Ratios'!J56 -> #DIV/0! | BA12: ='Prudential Ratios'!K56 -> #DIV/0! | BB12: ='Prudential Ratios'!L56 -> #DIV/0! | ... CA12: ='Prudential Ratios'!AK56 -> 0.62975189
B13: OER | D13: ='Prudential Ratios'!#REF! -> #REF! | E13: ='Prudential Ratios'!#REF! -> #REF! | F13: ='Prudential Ratios'!#REF! -> #REF! | G13: ='Prudential Ratios'!#REF! -> #REF! | H13: ='Prudential Ratios'!#REF! -> #REF! | I13: ='Prudential Ratios'!#REF! -> #REF! | J13: ='Prudential Ratios'!#REF! -> #REF! | K13: ='Prudential Ratios'!#REF! -> #REF! | ... AT13: ='Prudential Ratios'!#REF! -> #REF! | AU13: ='Prudential Ratios'!E57 -> 0.087127255 | AV13: ='Prudential Ratios'!F57 -> 0 | AW13: ='Prudential Ratios'!G57 -> 0 | AX13: ='Prudential Ratios'!H57 -> 0 | AY13: ='Prudential Ratios'!I57 -> 0 | AZ13: ='Prudential Ratios'!J57 -> 0 | BA13: ='Prudential Ratios'!K57 -> 0 | BB13: ='Prudential Ratios'!L57 -> 0 | ... CA13: ='Prudential Ratios'!AK57 -> 0.053021788
B14: LIQUIDITY
B15: MIN LIQ | C15: 0.15 | D15: ='Prudential Ratios'!#REF! -> #REF! | E15: ='Prudential Ratios'!#REF! -> #REF! | F15: ='Prudential Ratios'!#REF! -> #REF! | G15: ='Prudential Ratios'!#REF! -> #REF! | H15: ='Prudential Ratios'!#REF! -> #REF! | I15: ='Prudential Ratios'!#REF! -> #REF! | J15: ='Prudential Ratios'!#REF! -> #REF! | K15: ='Prudential Ratios'!#REF! -> #REF! | ... AT15: ='Prudential Ratios'!#REF! -> #REF! | AU15: ='Prudential Ratios'!E47 -> 0.27500842 | AV15: ='Prudential Ratios'!F47 -> 0.17418078 | AW15: ='Prudential Ratios'!G47 -> 0.22560135 | AX15: ='Prudential Ratios'!H47 -> 0.14290454 | AY15: ='Prudential Ratios'!I47 -> 0.15814051 | AZ15: ='Prudential Ratios'!J47 -> 0.15150019 | BA15: ='Prudential Ratios'!K47 -> 0.13049517 | BB15: ='Prudential Ratios'!L47 -> 0.14078519 | ... CA15: ='Prudential Ratios'!AK47 -> 0.27423882
B16: TEC LIQ | D16: ='Prudential Ratios'!#REF! -> #REF! | E16: ='Prudential Ratios'!#REF! -> #REF! | F16: ='Prudential Ratios'!#REF! -> #REF! | G16: ='Prudential Ratios'!#REF! -> #REF! | H16: ='Prudential Ratios'!#REF! -> #REF! | I16: ='Prudential Ratios'!#REF! -> #REF! | J16: ='Prudential Ratios'!#REF! -> #REF! | K16: ='Prudential Ratios'!#REF! -> #REF! | ... AT16: ='Prudential Ratios'!#REF! -> #REF! | AU16: ='Prudential Ratios'!E48 -> 0.22245404 | AV16: ='Prudential Ratios'!F48 -> 0.17417498 | AW16: ='Prudential Ratios'!G48 -> 0.22559478 | AX16: ='Prudential Ratios'!H48 -> 0.14954785 | AY16: ='Prudential Ratios'!I48 -> 0.16459833 | AZ16: ='Prudential Ratios'!J48 -> 0.15143913 | BA16: ='Prudential Ratios'!K48 -> 0.13046479 | BB16: ='Prudential Ratios'!L48 -> 0.14075303 | ... CA16: ='Prudential Ratios'!AK48 -> 0.23828562
B17: EB | C17: ≤ 25% | D17: ='Prudential Ratios'!#REF! -> #REF! | E17: ='Prudential Ratios'!#REF! -> #REF! | F17: ='Prudential Ratios'!#REF! -> #REF! | G17: ='Prudential Ratios'!#REF! -> #REF! | H17: ='Prudential Ratios'!#REF! -> #REF! | I17: ='Prudential Ratios'!#REF! -> #REF! | J17: ='Prudential Ratios'!#REF! -> #REF! | K17: ='Prudential Ratios'!#REF! -> #REF! | ... AT17: ='Prudential Ratios'!#REF! -> #REF! | AU17: ='Prudential Ratios'!E27 -> 0 | AV17: ='Prudential Ratios'!F27 -> 0 | AW17: ='Prudential Ratios'!G27 -> 0 | AX17: ='Prudential Ratios'!H27 -> 0 | AY17: ='Prudential Ratios'!I27 -> 0 | AZ17: ='Prudential Ratios'!J27 -> 0 | BA17: ='Prudential Ratios'!K27 -> 0 | BB17: ='Prudential Ratios'!L27 -> 0 | ... CA17: ='Prudential Ratios'!AK27 -> 0.05092209
B18: LIQ/TA | D18: ='Prudential Ratios'!#REF! -> #REF! | E18: ='Prudential Ratios'!#REF! -> #REF! | F18: ='Prudential Ratios'!#REF! -> #REF! | G18: ='Prudential Ratios'!#REF! -> #REF! | H18: ='Prudential Ratios'!#REF! -> #REF! | I18: ='Prudential Ratios'!#REF! -> #REF! | J18: ='Prudential Ratios'!#REF! -> #REF! | K18: ='Prudential Ratios'!#REF! -> #REF! | ... AT18: ='Prudential Ratios'!#REF! -> #REF! | AU18: ='Prudential Ratios'!E58 -> 0.18018136 | AV18: ='Prudential Ratios'!F58 -> 1.3642637 | AW18: ='Prudential Ratios'!G58 -> 1.6785874 | AX18: ='Prudential Ratios'!H58 -> 1.0069073 | AY18: ='Prudential Ratios'!I58 -> 1.3124841 | AZ18: ='Prudential Ratios'!J58 -> 1.1376105 | BA18: ='Prudential Ratios'!K58 -> 1.0389821 | BB18: ='Prudential Ratios'!L58 -> 1.2075787 | ... CA18: ='Prudential Ratios'!AK58 -> 0.1825491
B19: STRUCTURE
B20: NEA | C20: ≤ 10% | D20: ='Prudential Ratios'!#REF! -> #REF! | E20: ='Prudential Ratios'!#REF! -> #REF! | F20: ='Prudential Ratios'!#REF! -> #REF! | G20: ='Prudential Ratios'!#REF! -> #REF! | H20: ='Prudential Ratios'!#REF! -> #REF! | I20: ='Prudential Ratios'!#REF! -> #REF! | J20: ='Prudential Ratios'!#REF! -> #REF! | K20: ='Prudential Ratios'!#REF! -> #REF! | ... AT20: ='Prudential Ratios'!#REF! -> #REF! | AU20: ='Prudential Ratios'!E14 -> 0.12852222 | AV20: ='Prudential Ratios'!F14 -> 10.384985 | AW20: ='Prudential Ratios'!G14 -> 9.6357278 | AX20: ='Prudential Ratios'!H14 -> 9.6793191 | AY20: ='Prudential Ratios'!I14 -> 9.9006137 | AZ20: ='Prudential Ratios'!J14 -> 10.881615 | BA20: ='Prudential Ratios'!K14 -> 10.188674 | BB20: ='Prudential Ratios'!L14 -> 10.851818 | ... CA20: ='Prudential Ratios'!AK14 -> 0.20864098
B21: LB | C21: ≤ 5% | D21: ='Prudential Ratios'!#REF! -> #REF! | E21: ='Prudential Ratios'!#REF! -> #REF! | F21: ='Prudential Ratios'!#REF! -> #REF! | G21: ='Prudential Ratios'!#REF! -> #REF! | H21: ='Prudential Ratios'!#REF! -> #REF! | I21: ='Prudential Ratios'!#REF! -> #REF! | J21: ='Prudential Ratios'!#REF! -> #REF! | K21: ='Prudential Ratios'!#REF! -> #REF! | ... AT21: ='Prudential Ratios'!#REF! -> #REF! | AU21: ='Prudential Ratios'!E15 -> 0.051737546 | AV21: ='Prudential Ratios'!F15 -> 0 | AW21: ='Prudential Ratios'!G15 -> 0 | AX21: ='Prudential Ratios'!H15 -> 0 | AY21: ='Prudential Ratios'!I15 -> 0 | AZ21: ='Prudential Ratios'!J15 -> 0 | BA21: ='Prudential Ratios'!K15 -> 0 | BB21: ='Prudential Ratios'!L15 -> 0 | ... CA21: ='Prudential Ratios'!AK15 -> 0.10941436
B22: FITD | C22: ≤ 5% | D22: ='Prudential Ratios'!#REF! -> #REF! | E22: ='Prudential Ratios'!#REF! -> #REF! | F22: ='Prudential Ratios'!#REF! -> #REF! | G22: ='Prudential Ratios'!#REF! -> #REF! | H22: ='Prudential Ratios'!#REF! -> #REF! | I22: ='Prudential Ratios'!#REF! -> #REF! | J22: ='Prudential Ratios'!#REF! -> #REF! | K22: ='Prudential Ratios'!#REF! -> #REF! | ... AT22: ='Prudential Ratios'!#REF! -> #REF! | AU22: ='Prudential Ratios'!E19 -> 0.00029466029 | AV22: ='Prudential Ratios'!F19 -> 321254.66 | AW22: ='Prudential Ratios'!G19 -> 322432.63 | AX22: ='Prudential Ratios'!H19 -> -19.581498 | AY22: ='Prudential Ratios'!I19 -> -19.442138 | AZ22: ='Prudential Ratios'!J19 -> #DIV/0! | BA22: ='Prudential Ratios'!K19 -> -5172.7261 | BB22: ='Prudential Ratios'!L19 -> -5075.8957 | ... CA22: ='Prudential Ratios'!AK19 -> 0.00021384929
B23: FICC | C23: ≤ 40% | D23: ='Prudential Ratios'!#REF! -> #REF! | E23: ='Prudential Ratios'!#REF! -> #REF! | F23: ='Prudential Ratios'!#REF! -> #REF! | G23: ='Prudential Ratios'!#REF! -> #REF! | H23: ='Prudential Ratios'!#REF! -> #REF! | I23: ='Prudential Ratios'!#REF! -> #REF! | J23: ='Prudential Ratios'!#REF! -> #REF! | K23: ='Prudential Ratios'!#REF! -> #REF! | ... AT23: ='Prudential Ratios'!#REF! -> #REF! | AU23: ='Prudential Ratios'!E20 -> 0.0012292203 | AV23: ='Prudential Ratios'!F20 -> #REF! | AW23: ='Prudential Ratios'!G20 -> #REF! | AX23: ='Prudential Ratios'!H20 -> #REF! | AY23: ='Prudential Ratios'!I20 -> #REF! | AZ23: ='Prudential Ratios'!J20 -> #REF! | BA23: ='Prudential Ratios'!K20 -> #REF! | BB23: ='Prudential Ratios'!L20 -> #REF! | ... CA23: ='Prudential Ratios'!AK20 -> 0.00091955136

Sheet Financials
B1: SIRAJI SACCO SOCIETY
B3: Year | C3: AUDITED 2020 | D3: 44197 | E3: 44228 | F3: 44256 | G3: 44287 | H3: 44317 | I3: 44348 | J3: 44378 | K3: 44409 | L3: 44440 | M3: 44470 | N3: 44501 | O3: 44531 | P3: Audited 2021 | Q3: 44562 | R3: 44593 | S3: 44621 | T3: 44652 | U3: 44682 | V3: 44713 | W3: 44743 | X3: 44774 | Y3: 44805 | Z3: 44835 | AA3: 44866 | AB3: 44896 | AC3: Audited-2022 | AD3: 44949 | AE3: 44980 | AF3: 45008 | AG3: 45039 | AH3: 45069 | AI3: 45100
A4: 1 | B4: Membership
A5: 2 | B5: Total Assets | C5: =SFP!B27 -> 451530040 | D5: =SFP!C29 -> 48619914 | E5: =SFP!D29 -> 52129056 | F5: =SFP!E29 -> 54461821 | G5: =SFP!F29 -> 52365497 | H5: =SFP!G29 -> 56273331 | I5: =SFP!H29 -> 55246420 | J5: =SFP!I29 -> 50771324 | K5: =SFP!J29 -> 53762394 | ... O5: =SFP!N29 -> 53033455 | P5: =SFP!O27 -> 512833379 | Q5: =SFP!P27 -> 5.0843806e+08 | R5: =SFP!Q27 -> 5.1359248e+08 | S5: =SFP!R27 -> 5.0725105e+08 | T5: =SFP!S27 -> 5.0706242e+08 | U5: =SFP!T27 -> 5.1067156e+08 | V5: =SFP!U27 -> 5.4810082e+08 | W5: =SFP!V27 -> 5.5069305e+08 | ... AI5: =SFP!AH27 -> 6.0533651e+08
A6: 3 | B6: Total Deposits | C6: =SFP!B32 -> 345672644 | D6: =SFP!C35 -> 988 | E6: =SFP!D35 -> 988 | F6: =SFP!E35 -> -16238469 | G6: =SFP!F35 -> -16242182 | H6: =SFP!G35 -> 0 | I6: =SFP!H35 -> -62443.5 | J6: =SFP!I35 -> -65274 | K6: =SFP!J35 -> -67724 | ... O6: =SFP!N35 -> -73198 | P6: =SFP!O32 -> 393860322 | Q6: =SFP!P32 -> 4.0155356e+08 | R6: =SFP!Q32 -> 4.0567966e+08 | S6: =SFP!R32 -> 4.1469122e+08 | T6: =SFP!S32 -> 4.1603844e+08 | U6: =SFP!T32 -> 4.16693e+08 | V6: =SFP!U32 -> 4.223332e+08 | W6: =SFP!V32 -> 4.2260159e+08 | ... AI6: =SFP!AH32 -> 4.7629804e+08
A7: 3.1 | B7: Deposits-Members(BOSA) | C7: =SFP!B31 -> 275781981 | D7: =SFP!C34 -> -11696.01 | E7: =SFP!D34 -> -10315.53 | F7: =SFP!E34 -> 808224.05 | G7: =SFP!F34 -> 809073.08 | H7: =SFP!G34 -> -170385.89 | I7: =SFP!H34 -> -164901.78 | J7: =SFP!I34 -> -164786.78 | K7: =SFP!J34 -> -165862.78 | ... O7: =SFP!N34 -> -131899.24 | P7: =SFP!O31 -> 315654301 | Q7: =SFP!P31 -> 3.4355035e+08 | R7: =SFP!Q31 -> 3.4826146e+08 | S7: =SFP!R31 -> 3.5313295e+08 | T7: =SFP!S31 -> 3.5920512e+08 | U7: =SFP!T31 -> 3.6344925e+08 | V7: =SFP!U31 -> 3.6674926e+08 | W7: =SFP!V31 -> 3.7078928e+08 | ... AI7: =SFP!AH31 -> 4.1550032e+08
A8: 3.2 | B8: Deposits-Customers(FOSA) | C8: =SFP!B29 -> 69890663 | D8: =SFP!C31 -> 3.0033339e+08 | E8: =SFP!D31 -> 3.0596066e+08 | F8: =SFP!E31 -> 3.1022242e+08 | G8: =SFP!F31 -> 3.1310114e+08 | H8: =SFP!G31 -> 3.1633245e+08 | I8: =SFP!H31 -> 3.2154503e+08 | J8: =SFP!I31 -> 3.2558706e+08 | K8: =SFP!J31 -> 3.2888016e+08 | ... O8: =SFP!N31 -> ############ | P8: =SFP!O29 -> 78206021 | Q8: =SFP!P29 -> 54611474 | R8: =SFP!Q29 -> 53486462 | S8: =SFP!R29 -> 58088767 | T8: =SFP!S29 -> 53467624 | U8: =SFP!T29 -> 49573059 | V8: =SFP!U29 -> 51924404 | W8: =SFP!V29 -> 48308772 | ... AI8: =SFP!AH29 -> 54882496
A9: 4 | B9: External Borrowing | C9: =SFP!B39 -> 0 | D9: =SFP!C43 -> 0 | E9: =SFP!D43 -> 0 | F9: =SFP!E43 -> 0 | G9: =SFP!F43 -> 0 | H9: =SFP!G43 -> 0 | I9: =SFP!H43 -> 0 | J9: =SFP!I43 -> 0 | K9: =SFP!J43 -> 0 | ... O9: =SFP!N43 -> 0 | P9: =SFP!O39 -> 3750000 | Q9: =SFP!P39 -> 3125000 | R9: =SFP!Q39 -> 2500000 | S9: =SFP!R39 -> 1875000 | T9: =SFP!S39 -> 1250000 | U9: =SFP!T39 -> 587500 | V9: =SFP!U39 -> 30000000 | W9: =SFP!V39 -> 30145851 | ... AI9: =SFP!AH39 -> 30825000
A10: 4.1 | B10: Short term Liabilities | C10: =SFP!B34+SFP!B35+SFP!B36+SFP!B37+SFP!B38 -> 20053673 | D10: =SFP!C37+SFP!C38+SFP!C39+SFP!C40+SFP!C42 -> 3.8082514e+08 | E10: =SFP!D37+SFP!D38+SFP!D39+SFP!D40+SFP!D42 -> 3.8787667e+08 | F10: =SFP!E37+SFP!E38+SFP!E39+SFP!E40+SFP!E42 -> 3.8293052e+08 | G10: =SFP!F37+SFP!F38+SFP!F39+SFP!F40+SFP!F42 -> 4.3379736e+08 | H10: =SFP!G37+SFP!G38+SFP!G39+SFP!G40+SFP!G42 -> 4.2272516e+08 | I10: =SFP!H37+SFP!H38+SFP!H39+SFP!H40+SFP!H42 -> 4.4002822e+08 | J10: =SFP!I37+SFP!I38+SFP!I39+SFP!I40+SFP!I42 -> 4.3565356e+08 | K10: =SFP!J37+SFP!J38+SFP!J39+SFP!J40+SFP!J42 -> 4.4119219e+08 | ... O10: =SFP!N37+SFP!N38+SFP!N39+SFP!N40+SFP!N42 -> #VALUE! | P10: =SFP!O34+SFP!O35+SFP!O36+SFP!O37+SFP!O38 -> 22421347 | Q10: =SFP!P34+SFP!P35+SFP!P36+SFP!P37+SFP!P38 -> -6603381.5 | R10: =SFP!Q34+SFP!Q35+SFP!Q36+SFP!Q37+SFP!Q38 -> -6448228.2 | S10: =SFP!R34+SFP!R35+SFP!R36+SFP!R37+SFP!R38 -> -23975184 | T10: =SFP!S34+SFP!S35+SFP!S36+SFP!S37+SFP!S38 -> -3243878.3 | U10: =SFP!T34+SFP!T35+SFP!T36+SFP!T37+SFP!T38 -> -4004764.4 | V10: =SFP!U34+SFP!U35+SFP!U36+SFP!U37+SFP!U38 -> -4051046.1 | W10: =SFP!V34+SFP!V35+SFP!V36+SFP!V37+SFP!V38 -> -4106966.3 | ... AI10: =SFP!AH34+SFP!AH35+SFP!AH36+SFP!AH37+SFP!AH38 -> -12553593
A13: 5 | B13: Share capital and Reserves
A14: 5.1 | B14: Core Capital | C14: =C17 -> 82862280 | D14: =D17 -> #REF! | E14: =E17 -> #REF! | F14: =F17 -> #REF! | G14: =G17 -> #REF! | H14: =H17 -> #REF! | I14: =I17 -> #REF! | J14: =J17 -> #REF! | ... AI14: =AI17 -> 110767059
A15: 5.2 | B15: Institutional Capital | C15: =C14-C18 -> 33129239 | D15: =D14-D18 -> #REF! | E15: =E14-E18 -> #REF! | F15: =F14-F18 -> #REF! | G15: =G14-G18 -> #REF! | H15: =H14-H18 -> #REF! | I15: =I14-I18 -> #REF! | J15: =J14-J18 -> #REF! | ... AI15: =AI14-AI18 -> 56814067
A17: 5.3 | B17: Total Capital | C17: =SUM(C18:C21) -> 82862280 | D17: =SUM(D18:D21) -> #REF! | E17: =SUM(E18:E21) -> #REF! | F17: =SUM(F18:F21) -> #REF! | G17: =SUM(G18:G21) -> #REF! | H17: =SUM(H18:H21) -> #REF! | I17: =SUM(I18:I21) -> #REF! | J17: =SUM(J18:J21) -> #REF! | ... AI17: =SUM(AI18:AI21) -> 110767059
A18: 5.3.1 | B18: Members Share Capital | C18: =SFP!B42 -> 49733041 | D18: =SFP!C50 -> 11432500 | E18: =SFP!D50 -> 11432500 | F18: =SFP!E50 -> 11432500 | G18: =SFP!F50 -> 12421535 | H18: =SFP!G50 -> 12421535 | I18: =SFP!H50 -> 12421535 | J18: =SFP!I50 -> 12421535 | K18: =SFP!J50 -> 12421535 | ... O18: =SFP!N50 -> 12421535 | P18: =SFP!O42 -> 51874160 | Q18: =SFP!P42 -> 50143975 | R18: =SFP!Q42 -> 50273068 | S18: =SFP!R42 -> 50290425 | T18: =SFP!S42 -> 50290175 | U18: =SFP!T42 -> 51040285 | V18: =SFP!U42 -> 51303291 | W18: =SFP!V42 -> 51307235 | ... AI18: =SFP!AH42 -> 53952992
A19: 5.3.3 | B19: Retained Earnings | C19: =SFP!B45 -> 20707704 | D19: =SFP!C53 -> 0 | E19: =SFP!D53 -> 0 | F19: =SFP!E53 -> 0 | G19: =SFP!F53 -> 0 | H19: =SFP!G53 -> 0 | I19: =SFP!H53 -> 0 | J19: =SFP!I53 -> 0 | K19: =SFP!J53 -> 0 | ... O19: =SFP!N53 -> 0 | P19: =SFP!O45 -> 23827293 | Q19: =SFP!P45 -> 44855935 | R19: =SFP!Q45 -> 46225004 | S19: =SFP!R45 -> 49006618 | T19: =SFP!S45 -> 27364708 | U19: =SFP!T45 -> 31104762 | V19: =SFP!U45 -> 33152406 | W19: =SFP!V45 -> 35382362 | ... AI19: =SFP!AH45 -> 39713809
A20: 5.3.5 | B20: Statutory Reserves | C20: =SFP!B50 -> 12421535 | D20: =SFP!#REF! -> #REF! | E20: =SFP!#REF! -> #REF! | F20: =SFP!#REF! -> #REF! | G20: =SFP!#REF! -> #REF! | H20: =SFP!#REF! -> #REF! | I20: =SFP!#REF! -> #REF! | J20: =SFP!#REF! -> #REF! | K20: =SFP!#REF! -> #REF! | ... O20: =SFP!#REF! -> #REF! | P20: =SFP!O50 -> 14158817 | Q20: =SFP!P50 -> 12421535 | R20: =SFP!Q50 -> 12421535 | S20: =SFP!R50 -> 12421535 | T20: =SFP!S50 -> 12421535 | U20: =SFP!T50 -> 12421535 | V20: =SFP!U50 -> 12421535 | W20: =SFP!V50 -> 12421535 | ... AI20: =SFP!AH50 -> 14158817
A21: 5.3.6 | B21: Capital Reserve | C21: =SFP!B51 -> 0 | D21: =SFP!#REF! -> #REF! | E21: =SFP!#REF! -> #REF! | F21: =SFP!#REF! -> #REF! | G21: =SFP!#REF! -> #REF! | H21: =SFP!#REF! -> #REF! | I21: =SFP!#REF! -> #REF! | J21: =SFP!#REF! -> #REF! | K21: =SFP!#REF! -> #REF! | ... O21: =SFP!#REF! -> #REF! | P21: =SFP!O51 -> 2941441 | Q21: =SFP!P51 -> 2941441 | R21: =SFP!Q51 -> 2941441 | S21: =SFP!R51 -> 2941441 | T21: =SFP!S51 -> 2941441 | U21: =SFP!T51 -> 2941441 | V21: =SFP!U51 -> 2941441 | W21: =SFP!V51 -> 2941441 | ... AI21: =SFP!AH51 -> 2941441
A22: 5.3.7 | B22: Supplementary Capital & reserves
A23: a | B23: Proposed Dividends | C23: =SFP!B53 -> 0 | D23: =SFP!#REF! -> #REF! | E23: =SFP!#REF! -> #REF! | F23: =SFP!#REF! -> #REF! | G23: =SFP!#REF! -> #REF! | H23: =SFP!#REF! -> #REF! | I23: =SFP!#REF! -> #REF! | J23: =SFP!#REF! -> #REF! | K23: =SFP!#REF! -> #REF! | ... O23: =SFP!#REF! -> #REF! | P23: =SFP!O53 -> 0 | Q23: =SFP!P53 -> 0 | R23: =SFP!Q53 -> 0 | S23: =SFP!R53 -> 0 | T23: =SFP!S53 -> 0 | U23: =SFP!T53 -> 0 | V23: =SFP!U53 -> 0 | W23: =SFP!V53 -> 0 | ... AI23: =SFP!AH53 -> 0
A24: b
A26: 6 | B26: Investments | C26: =C27+C28+C29 -> 101856 | D26: =D27+D28+D29 -> 3.173996e+08 | E26: =E27+E28+E29 -> 3.1856344e+08 | F26: =F27+F28+F29 -> 3.1797356e+08 | G26: =G27+G28+G29 -> 3.1578275e+08 | H26: =H27+H28+H29 -> 3.1804063e+08 | I26: =I27+I28+I29 -> 3.2300312e+08 | J26: =J27+J28+J29 -> 3.3132402e+08 | ... AI26: =AI27+AI28+AI29 -> 101856
A27: 6.1 | B27: Investments in Coop bank, CIC, Kuscco, Kerussu & Codic | C27: =SFP!B12 -> 101856 | D27: =SFP!C12 -> 101856 | E27: =SFP!D12 -> 101856 | F27: =SFP!E12 -> 101856 | G27: =SFP!F12 -> 101856 | H27: =SFP!G12 -> 101856 | I27: =SFP!H12 -> 101856 | J27: =SFP!I12 -> 101856 | ... AI27: =SFP!AH12 -> 101856
A28: 6.2 | B28: Equity Investments (at cost) | C28: =SFP!B13 -> 0 | D28: =SFP!C14 -> 3.1729775e+08 | E28: =SFP!D14 -> 3.1846159e+08 | F28: =SFP!E14 -> 3.178717e+08 | G28: =SFP!F14 -> 3.1568089e+08 | H28: =SFP!G14 -> 3.1793877e+08 | I28: =SFP!H14 -> 3.2290127e+08 | J28: =SFP!I14 -> 3.3122216e+08 | K28: =SFP!J14 -> 3.3725988e+08 | ... O28: =SFP!N14 -> ############ | P28: =SFP!O13 -> 0 | Q28: =SFP!P13 -> 0 | R28: =SFP!Q13 -> 0 | S28: =SFP!R13 -> 0 | T28: =SFP!S13 -> 0 | U28: =SFP!T13 -> 0 | V28: =SFP!U13 -> 0 | W28: =SFP!V13 -> 0 | ... AI28: =SFP!AH13 -> 0
A29: 6.3 | B29: Deposits in KUSCCO CFP | C29: =SFP!B11 -> 0 | D29: =SFP!C11 -> 0 | E29: =SFP!D11 -> 0 | F29: =SFP!E11 -> 0 | G29: =SFP!F11 -> 0 | H29: =SFP!G11 -> 0 | I29: =SFP!H11 -> 0 | J29: =SFP!I11 -> 0 | ... AI29: =SFP!AH11 -> 0
A31: 7 | B31: Net Loans & advances | C31: =C32-C33 -> 312039246 | D31: =D32-D33 -> 25672793 | E31: =E32-E33 -> 26247308 | F31: =F32-F33 -> 26821797 | G31: =G32-G33 -> 27393588 | H31: =H32-H33 -> 27970103 | I31: =I32-I33 -> 28555919 | J31: =J32-J33 -> 29156551 | ... AI31: =AI32-AI33 -> 3.6843301e+08
A32: 7.1 | B32: Gross Loans & advances | C32: =SFP!B15 -> 337140421 | D32: =SFP!C16 -> 25672793 | E32: =SFP!D16 -> 26247308 | F32: =SFP!E16 -> 26821797 | G32: =SFP!F16 -> 27393588 | H32: =SFP!G16 -> 27970103 | I32: =SFP!H16 -> 28555919 | J32: =SFP!I16 -> 29156551 | K32: =SFP!J16 -> 29768264 | ... O32: =SFP!N16 -> 32223482 | P32: =SFP!O15 -> 366288454 | Q32: =SFP!P15 -> 3.682312e+08 | R32: =SFP!Q15 -> 3.6710059e+08 | S32: =SFP!R15 -> 3.7447956e+08 | T32: =SFP!S15 -> 3.7427044e+08 | U32: =SFP!T15 -> 3.8128241e+08 | V32: =SFP!U15 -> 3.8413625e+08 | W32: =SFP!V15 -> 3.8457727e+08 | ... AI32: =SFP!AH15 -> 4.1244701e+08
A33: 7.3 | B33: Allowance for loan losses | C33: =SFP!B16 -> 25101175 | D33: =SFP!C17 -> 0 | E33: =SFP!D17 -> 0 | F33: =SFP!E17 -> 0 | G33: =SFP!F17 -> 0 | H33: =SFP!G17 -> 0 | I33: =SFP!H17 -> 0 | J33: =SFP!I17 -> 0 | K33: =SFP!J17 -> 0 | ... O33: =SFP!N17 -> 0 | P33: =SFP!O16 -> 32223482 | Q33: =SFP!P16 -> 32839426 | R33: =SFP!Q16 -> 33451276 | S33: =SFP!R16 -> 34075409 | T33: =SFP!S16 -> 34699193 | U33: =SFP!T16 -> 35334830 | V33: =SFP!U16 -> 35975058 | W33: =SFP!V16 -> 36616020 | ... AI33: =SFP!AH16 -> 44013998
A34: 7.4 | B34: Non Performing Loans | C34: =(#REF!+#REF!+#REF!) -> #REF! | D34: =(#REF!+#REF!+#REF!) -> #REF! | E34: =(#REF!+#REF!+#REF!) -> #REF! | F34: =(#REF!+#REF!+#REF!) -> #REF! | G34: =(#REF!+#REF!+#REF!) -> #REF! | H34: =(#REF!+#REF!+#REF!) -> #REF! | I34: =(#REF!+#REF!+#REF!) -> #REF! | J34: =(#REF!+#REF!+#REF!) -> #REF! | ... AI34: =(#REF!+#REF!+#REF!) -> #REF!
A35: 7.5 | B35: Required loan loss provision | C35: =#REF! -> #REF! | D35: =#REF! -> #REF! | E35: =#REF! -> #REF! | F35: =#REF! -> #REF! | G35: =#REF! -> #REF! | H35: =#REF! -> #REF! | I35: =#REF! -> #REF! | J35: =#REF! -> #REF! | ... AI35: =#REF! -> #REF!
A36: 7.6 | B36: Cash and Cash equipments | C36: =SFP!B4 -> 81357297 | D36: =SFP!C4 -> 66330383 | E36: =SFP!D4 -> 87503175 | F36: =SFP!E4 -> 54838007 | G36: =SFP!F4 -> 68728884 | H36: =SFP!G4 -> 64017130 | I36: =SFP!H4 -> 57400041 | J36: =SFP!I4 -> 61310370 | ... AI36: =SFP!AH4 -> 1.1050364e+08
A38: 8 | B38: Non-Earning Assets | C38: =SFP!B7+SFP!B17+SFP!B23+SFP!B24+SFP!B25+SFP!B26 -> 58031641 | D38: =SFP!C7+SFP!C18+SFP!C24+SFP!C25+SFP!C26+SFP!C27 -> 5.0491706e+08 | E38: =SFP!D7+SFP!D18+SFP!D24+SFP!D25+SFP!D26+SFP!D27 -> 5.0230139e+08 | F38: =SFP!E7+SFP!E18+SFP!E24+SFP!E25+SFP!E26+SFP!E27 -> 5.2715334e+08 | G38: =SFP!F7+SFP!F18+SFP!F24+SFP!F25+SFP!F26+SFP!F27 -> 5.1845056e+08 | H38: =SFP!G7+SFP!G18+SFP!G24+SFP!G25+SFP!G26+SFP!G27 -> 6.1234474e+08 | I38: =SFP!H7+SFP!H18+SFP!H24+SFP!H25+SFP!H26+SFP!H27 -> 5.6288775e+08 | J38: =SFP!I7+SFP!I18+SFP!I24+SFP!I25+SFP!I26+SFP!I27 -> 5.5096119e+08 | K38: =SFP!J7+SFP!J18+SFP!J24+SFP!J25+SFP!J26+SFP!J27 -> 5.5999342e+08 | ... O38: =SFP!N7+SFP!N18+SFP!N24+SFP!N25+SFP!N26+SFP!N27 -> #VALUE! | P38: =SFP!O7+SFP!O17+SFP!O23+SFP!O24+SFP!O25+SFP!O26 -> 89365438 | Q38: =SFP!P7+SFP!P17+SFP!P23+SFP!P24+SFP!P25+SFP!P26 -> 90043699 | R38: =SFP!Q7+SFP!Q17+SFP!Q23+SFP!Q24+SFP!Q25+SFP!Q26 -> 89936379 | S38: =SFP!R7+SFP!R17+SFP!R23+SFP!R24+SFP!R25+SFP!R26 -> 88462382 | T38: =SFP!S7+SFP!S17+SFP!S23+SFP!S24+SFP!S25+SFP!S26 -> 94050549 | U38: =SFP!T7+SFP!T17+SFP!T23+SFP!T24+SFP!T25+SFP!T26 -> 95519116 | V38: =SFP!U7+SFP!U17+SFP!U23+SFP!U24+SFP!U25+SFP!U26 -> 1.1075746e+08 | W38: =SFP!V7+SFP!V17+SFP!V23+SFP!V24+SFP!V25+SFP!V26 -> 1.2474568e+08 | ... AI38: =SFP!AH7+SFP!AH17+SFP!AH23+SFP!AH24+SFP!AH25+SFP!AH26 -> 1.2629801e+08
A39: 8.1 | B39: Property and Equipment | C39: =SFP!B23 -> 23361056 | D39: =SFP!C24 -> 0 | E39: =SFP!D24 -> 0 | F39: =SFP!E24 -> 0 | G39: =SFP!F24 -> 0 | H39: =SFP!G24 -> 0 | I39: =SFP!H24 -> 0 | J39: =SFP!I24 -> 0 | K39: =SFP!J24 -> 0 | ... O39: =SFP!N24 -> 0 | P39: =SFP!O23 -> 47318410 | Q39: =SFP!P23 -> 46928203 | R39: =SFP!Q23 -> 46733595 | S39: =SFP!R23 -> 47654032 | T39: =SFP!S23 -> 51129629 | U39: =SFP!T23 -> 52253602 | V39: =SFP!U23 -> 57196693 | W39: =SFP!V23 -> 60277774 | ... AI39: =SFP!AH23 -> 66232504
A41: 9 | B41: Turnover | C41: =C42+C43+C44 -> 12421535 | D41: =D42+D43+D44 -> #REF! | E41: =E42+E43+E44 -> #REF! | F41: =F42+F43+F44 -> #REF! | G41: =G42+G43+G44 -> #REF! | H41: =H42+H43+H44 -> #REF! | I41: =I42+I43+I44 -> #REF! | J41: =J42+J43+J44 -> #REF! | ... AI41: =AI42+AI43+AI44 -> 17100258
A42: 9.1 | B42: Loan Interest | C42: =SFP!B50 -> 12421535 | D42: =SFP!#REF! -> #REF! | E42: =SFP!#REF! -> #REF! | F42: =SFP!#REF! -> #REF! | G42: =SFP!#REF! -> #REF! | H42: =SFP!#REF! -> #REF! | I42: =SFP!#REF! -> #REF! | J42: =SFP!#REF! -> #REF! | K42: =SFP!#REF! -> #REF! | ... O42: =SFP!#REF! -> #REF! | P42: =SFP!O50 -> 14158817 | Q42: =SFP!P50 -> 12421535 | R42: =SFP!Q50 -> 12421535 | S42: =SFP!R50 -> 12421535 | T42: =SFP!S50 -> 12421535 | U42: =SFP!T50 -> 12421535 | V42: =SFP!U50 -> 12421535 | W42: =SFP!V50 -> 12421535 | ... AI42: =SFP!AH50 -> 14158817
B43: Income from investments | C43: =SFP!B51 -> 0 | D43: =SFP!#REF! -> #REF! | E43: =SFP!#REF! -> #REF! | F43: =SFP!#REF! -> #REF! | G43: =SFP!#REF! -> #REF! | H43: =SFP!#REF! -> #REF! | I43: =SFP!#REF! -> #REF! | J43: =SFP!#REF! -> #REF! | K43: =SFP!#REF! -> #REF! | ... O43: =SFP!#REF! -> #REF! | P43: =SFP!O51 -> 2941441 | Q43: =SFP!P51 -> 2941441 | R43: =SFP!Q51 -> 2941441 | S43: =SFP!R51 -> 2941441 | T43: =SFP!S51 -> 2941441 | U43: =SFP!T51 -> 2941441 | V43: =SFP!U51 -> 2941441 | W43: =SFP!V51 -> 2941441 | ... AI43: =SFP!AH51 -> 2941441
A44: 9.2 | B44: Fees & Commissions | C44: =SFP!B52 -> 0 | D44: =SFP!#REF! -> #REF! | E44: =SFP!#REF! -> #REF! | F44: =SFP!#REF! -> #REF! | G44: =SFP!#REF! -> #REF! | H44: =SFP!#REF! -> #REF! | I44: =SFP!#REF! -> #REF! | J44: =SFP!#REF! -> #REF! | K44: =SFP!#REF! -> #REF! | ... O44: =SFP!#REF! -> #REF! | P44: =SFP!O52 -> 0 | Q44: =SFP!P52 -> 0 | R44: =SFP!Q52 -> 0 | S44: =SFP!R52 -> 0 | T44: =SFP!S52 -> 0 | U44: =SFP!T52 -> 0 | V44: =SFP!U52 -> 0 | W44: =SFP!V52 -> 0 | ... AI44: =SFP!AH52 -> 0
B45: Average yield on loans
A47: 10 | B47: Total Expenses (FinCosts + OpEx) | C47: =SUM(C48:C53) -> 36889168 | D47: =SUM(D48:D53) -> 0 | E47: =SUM(E48:E53) -> 0 | F47: =SUM(F48:F53) -> 0 | G47: =SUM(G48:G53) -> 0 | H47: =SUM(H48:H53) -> 0 | I47: =SUM(I48:I53) -> 0 | J47: =SUM(J48:J53) -> 0 | ... AJ47: =SUM(AJ48:AJ53) -> 0
A48: 10.1 | B48: Financial Exp. (Interest on deposits) | C48: =SCI!B13 -> 13316672 | D48: =SCI!C13 -> 0 | E48: =SCI!D13 -> 0 | F48: =SCI!E13 -> 0 | G48: =SCI!F13 -> 0 | H48: =SCI!G13 -> 0 | I48: =SCI!H13 -> 0 | J48: =SCI!I13 -> 0 | ... AJ48: =SCI!AI13 -> 0
A49: 10.2 | B49: Financial Exp. (Dividends) | C49: =SCI!B15 -> 0 | D49: =SCI!C15 -> 0 | E49: =SCI!D15 -> 0 | F49: =SCI!E15 -> 0 | G49: =SCI!F15 -> 0 | H49: =SCI!G15 -> 0 | I49: =SCI!H15 -> 0 | J49: =SCI!I15 -> 0 | ... AJ49: =SCI!AI15 -> 0
...

Sheet form4
D3: RISK CLASSIFICATION OF ASSETS AND PROVISIONING | L3: RISK CLASSIFICATION OF ASSETS AND PROVISIONING
D4: SACCO SOCIETY CS NUMBER | L4: SACCO SOCIETY CS NUMBER
D5: FINANCIAL YEAR | L5: FINANCIAL YEAR
D6: START DATE: | L6: START DATE:
D7: END DATE: | L7: END DATE:
D8: PORTFOLIO AGEING REPORT | L8: PORTFOLIO AGEING REPORT
E9: A | F9: B | G9: C | H9: D | M9: A | N9: B | O9: C | P9: D
C10: NO. | D10: CLASSIFICATION | E10: NO. OF A/Cs | F10: OUTSTANDING LOAN PORTFOLIO(Kshs) | G10: REQUIRED PROVISION | H10: REQUIRED PROVISION AMOUNT(Kshs) | K10: NO. | L10: CLASSIFICATION | M10: NO. OF A/Cs | N10: OUTSTANDING LOAN PORTFOLIO(Kshs) | O10: REQUIRED PROVISION | P10: REQUIRED PROVISION AMOUNT(Kshs)
C11: 1 | D11: Performing | K11: 1 | L11: Performing
C12: 2 | D12: Watch | K12: 2 | L12: Watch
C13: 3 | D13: Substandard | K13: 3 | L13: Substandard
C14: 4 | D14: Doubtful | K14: 4 | L14: Doubtful
C15: 5 | D15: Loss | K15: 5 | L15: Loss
D16: subtotal | L16: subtotal | M16: =SUM(M11:M15) -> 0 | N16: =SUM(N11:N15) -> 0 | P16: =SUM(P11:P15) -> 0
D17: Reschedule/Renegotiated loans | L17: Reschedule/Renegotiated loans
C18: 1 | D18: Performing | K18: 1 | L18: Performing | M18: 0 | N18: 0 | O18: 0.01 | P18: =N18*O18 -> 0
C19: 2 | D19: Watch | K19: 2 | L19: Watch | M19: 0 | N19: 0 | O19: 0.05 | P19: =N19*O19 -> 0
C20: 3 | D20: Substandard | K20: 3 | L20: Substandard | M20: 0 | N20: 0 | O20: 0.25 | P20: =N20*O20 -> 0
C21: 4 | D21: Doubtful | K21: 4 | L21: Doubtful | M21: 0 | N21: 0 | O21: 0.5 | P21: =N21*O21 -> 0
C22: 5 | D22: Loss | K22: 5 | L22: Loss | M22: 0 | N22: 0 | O22: 1 | P22: =N22*O22 -> 0
D23: subtotal | E23: =SUM(E17:E22) -> 0 | F23: =SUM(F17:F22) -> 0 | H23: =SUM(H17:H22) -> 0 | L23: subtotal | M23: =SUM(M17:M22) -> 0 | N23: =SUM(N17:N22) -> 0 | P23: =SUM(P17:P22) -> 0
D24: GRAND TOTAL | E24: =E16+E23 -> 0 | F24: =F16+F23 -> 0 | H24: =H16+H23 -> 0 | L24: GRAND TOTAL | M24: =M16+M23 -> 0 | N24: =N16+N23 -> 0 | P24: =P16+P23 -> 0
F26: =F13+F14+F15 -> 0 | N26: =N13+N14+N15 -> 0
F27: =F26/F24 -> #DIV/0! | N27: =N26/N24 -> #DIV/0!
D30: RISK CLASSIFICATION OF ASSETS AND PROVISIONING
