Workbook
Name BALANCE1_LDA01: '[1]Financial Statements'!$E$112
Name BALANCE1_LDA12: '[1]Financial Statements'!$E$123
Name BALANCE2_LDA01: '[1]Financial Statements'!$F$112
Name BALANCE2_LDA12: '[1]Financial Statements'!$F$123
Name BALANCE3_LDA01: '[1]Financial Statements'!$G$112
Name BALANCE3_LDA12: '[1]Financial Statements'!$G$123
Name BALANCE4_LDA01: '[1]Financial Statements'!$H$112
Name BALANCE4_LDA12: '[1]Financial Statements'!$H$123
Name BALANCE5_LDA01: '[1]Financial Statements'!$I$112
Name BALANCE5_LDA12: '[1]Financial Statements'!$I$123
Name BALANCE6_LDA01: '[1]Financial Statements'!$J$112
Name BALANCE6_LDA12: '[1]Financial Statements'!$J$123
Name NotApplicable: 'Prudential Ratios'!$A$76
Name PEARLS1_LA002: '[1]Financial Statements'!$E$280
Name PEARLS1_LE008: '[1]Financial Statements'!$E$275
Name PEARLS1_LE009: '[1]Financial Statements'!$E$276
Name PEARLS1_LR001: '[1]Financial Statements'!$E$282
Name PEARLS1_LR005: '[1]Financial Statements'!$E$286
Name PEARLS1_LR006: '[1]Financial Statements'!$E$287
Name PEARLS1_LR007: '[1]Financial Statements'!$E$288
Name PEARLS1_LR009: '[1]Financial Statements'!$E$290
Name PEARLS1_LS001: '[1]Financial Statements'!$E$298
Name PEARLS1_LS005: '[1]Financial Statements'!$E$302
Name PEARLS1_LS011: '[1]Financial Statements'!$E$308
Name PEARLS2_LA002: '[1]Financial Statements'!$F$280
Name PEARLS2_LE008: '[1]Financial Statements'!$F$275
Name PEARLS2_LE009: '[1]Financial Statements'!$F$276
Name PEARLS2_LR001: '[1]Financial Statements'!$F$282
Name PEARLS2_LR005: '[1]Financial Statements'!$F$286
Name PEARLS2_LR006: '[1]Financial Statements'!$F$287
Name PEARLS2_LR007: '[1]Financial Statements'!$F$288
Name PEARLS2_LR009: '[1]Financial Statements'!$F$290
Name PEARLS2_LS001: '[1]Financial Statements'!$F$298
Name PEARLS2_LS005: '[1]Financial Statements'!$F$302
Name PEARLS2_LS010: '[1]Financial Statements'!$F$307
Name PEARLS2_LS011: '[1]Financial Statements'!$F$308
Name PEARLS3_LA002: '[1]Financial Statements'!$G$280
Name PEARLS3_LE008: '[1]Financial Statements'!$G$275
Name PEARLS3_LE009: '[1]Financial Statements'!$G$276
Name PEARLS3_LR001: '[1]Financial Statements'!$G$282
Name PEARLS3_LR005: '[1]Financial Statements'!$G$286
Name PEARLS3_LR006: '[1]Financial Statements'!$G$287
Name PEARLS3_LR007: '[1]Financial Statements'!$G$288
Name PEARLS3_LR009: '[1]Financial Statements'!$G$290
Name PEARLS3_LS001: '[1]Financial Statements'!$G$298
Name PEARLS3_LS005: '[1]Financial Statements'!$G$302
Name PEARLS3_LS010: '[1]Financial Statements'!$G$307
Name PEARLS3_LS011: '[1]Financial Statements'!$G$308
Name PEARLS4_LA002: '[1]Financial Statements'!$H$280
Name PEARLS4_LE008: '[1]Financial Statements'!$H$275
Name PEARLS4_LE009: '[1]Financial Statements'!$H$276
Name PEARLS4_LR001: '[1]Financial Statements'!$H$282
Name PEARLS4_LR005: '[1]Financial Statements'!$H$286
Name PEARLS4_LR006: '[1]Financial Statements'!$H$287
Name PEARLS4_LR007: '[1]Financial Statements'!$H$288
Name PEARLS4_LR009: '[1]Financial Statements'!$H$290
Name PEARLS4_LS001: '[1]Financial Statements'!$H$298
Name PEARLS4_LS005: '[1]Financial Statements'!$H$302
Name PEARLS4_LS010: '[1]Financial Statements'!$H$307
Name PEARLS4_LS011: '[1]Financial Statements'!$H$308

Sheet compliance status
B2: audited2017 | C2: 43101 | D2: 43133 | E2: 43165 | F2: 43197 | G2: 43229 | H2: 43261 | I2: 43293 | J2: 43325 | K2: 43357 | L2: 43389 | M2: 43421 | N2: 43453
A3: CORE CAPITAL | B3: =IF('Prudential Ratios'!#REF!>10,"compliant","not compliant") -> #REF! | C3: =IF('Prudential Ratios'!#REF!>10,"compliant","not compliant") -> #REF! | D3: =IF('Prudential Ratios'!#REF!>10,"compliant","not compliant") -> #REF! | E3: =IF('Prudential Ratios'!#REF!>10,"compliant","not compliant") -> #REF! | F3: =IF('Prudential Ratios'!#REF!>10,"compliant","not compliant") -> #REF! | G3: =IF('Prudential Ratios'!#REF!>10,"compliant","not compliant") -> #REF! | H3: =IF('Prudential Ratios'!#REF!>10,"compliant","not compliant") -> #REF! | I3: =IF('Prudential Ratios'!#REF!>10,"compliant","not compliant") -> #REF! | ... N3: =IF('Prudential Ratios'!#REF!>10,"compliant","not compliant") -> #REF!
A4: CCA (Min 10%) | B4: =IF('Prudential Ratios'!#REF!>10%,"compliant","not compliant") -> #REF! | C4: =IF('Prudential Ratios'!#REF!>10%,"compliant","not compliant") -> #REF! | D4: =IF('Prudential Ratios'!#REF!>10%,"compliant","not compliant") -> #REF! | E4: =IF('Prudential Ratios'!#REF!>10%,"compliant","not compliant") -> #REF! | F4: =IF('Prudential Ratios'!#REF!>10%,"compliant","not compliant") -> #REF! | G4: =IF('Prudential Ratios'!#REF!>10%,"compliant","not compliant") -> #REF! | H4: =IF('Prudential Ratios'!#REF!>10%,"compliant","not compliant") -> #REF! | I4: =IF('Prudential Ratios'!#REF!>10%,"compliant","not compliant") -> #REF! | ... N4: =IF('Prudential Ratios'!#REF!>10%,"compliant","not compliant") -> #REF!
A5: ICA (Min 8%) | B5: =IF('Prudential Ratios'!#REF!>8%,"compliant","not compliant") -> #REF! | C5: =IF('Prudential Ratios'!#REF!>8%,"compliant","not compliant") -> #REF! | D5: =IF('Prudential Ratios'!#REF!>8%,"compliant","not compliant") -> #REF! | E5: =IF('Prudential Ratios'!#REF!>8%,"compliant","not compliant") -> #REF! | F5: =IF('Prudential Ratios'!#REF!>8%,"compliant","not compliant") -> #REF! | G5: =IF('Prudential Ratios'!#REF!>8%,"compliant","not compliant") -> #REF! | H5: =IF('Prudential Ratios'!#REF!>8%,"compliant","not compliant") -> #REF! | I5: =IF('Prudential Ratios'!#REF!>8%,"compliant","not compliant") -> #REF! | ... N5: =IF('Prudential Ratios'!#REF!>8%,"compliant","not compliant") -> #REF!
A6: CCD (Min 8%) | B6: =IF('Prudential Ratios'!#REF!>8%,"compliant","not compliant") -> #REF! | C6: =IF('Prudential Ratios'!#REF!>8%,"compliant","not compliant") -> #REF! | D6: =IF('Prudential Ratios'!#REF!>8%,"compliant","not compliant") -> #REF! | E6: =IF('Prudential Ratios'!#REF!>8%,"compliant","not compliant") -> #REF! | F6: =IF('Prudential Ratios'!#REF!>8%,"compliant","not compliant") -> #REF! | G6: =IF('Prudential Ratios'!#REF!>8%,"compliant","not compliant") -> #REF! | H6: =IF('Prudential Ratios'!#REF!>8%,"compliant","not compliant") -> #REF! | I6: =IF('Prudential Ratios'!#REF!>8%,"compliant","not compliant") -> #REF! | ... N6: =IF('Prudential Ratios'!#REF!>8%,"compliant","not compliant") -> #REF!
A7: NPL(5%)
A8: Liquidity(15%) | B8: =IF('Prudential Ratios'!#REF!>15%,"compliant","not compliant") -> #REF! | C8: =IF('Prudential Ratios'!#REF!>15%,"compliant","not compliant") -> #REF! | D8: =IF('Prudential Ratios'!#REF!>15%,"compliant","not compliant") -> #REF! | E8: =IF('Prudential Ratios'!#REF!>15%,"compliant","not compliant") -> #REF! | F8: =IF('Prudential Ratios'!#REF!>15%,"compliant","not compliant") -> #REF! | G8: =IF('Prudential Ratios'!#REF!>15%,"compliant","not compliant") -> #REF! | H8: =IF('Prudential Ratios'!#REF!>15%,"compliant","not compliant") -> #REF! | I8: =IF('Prudential Ratios'!#REF!>15%,"compliant","not compliant") -> #REF! | ... N8: =IF('Prudential Ratios'!#REF!>15%,"compliant","not compliant") -> #REF!
A9: NEA (Max 10%) | B9: =IF('Prudential Ratios'!#REF!<10%,"compliant","not compliant") -> #REF! | C9: =IF('Prudential Ratios'!#REF!<10%,"compliant","not compliant") -> #REF! | D9: =IF('Prudential Ratios'!#REF!<10%,"compliant","not compliant") -> #REF! | E9: =IF('Prudential Ratios'!#REF!<10%,"compliant","not compliant") -> #REF! | F9: =IF('Prudential Ratios'!#REF!<10%,"compliant","not compliant") -> #REF! | G9: =IF('Prudential Ratios'!#REF!<10%,"compliant","not compliant") -> #REF! | H9: =IF('Prudential Ratios'!#REF!<10%,"compliant","not compliant") -> #REF! | I9: =IF('Prudential Ratios'!#REF!<10%,"compliant","not compliant") -> #REF! | ... N9: =IF('Prudential Ratios'!#REF!<10%,"compliant","not compliant") -> #REF!
A10: LB ratio (Max 5%) | B10: =IF('Prudential Ratios'!#REF!<5%,"compliant","not compliant") -> #REF! | C10: =IF('Prudential Ratios'!#REF!<5%,"compliant","not compliant") -> #REF! | D10: =IF('Prudential Ratios'!#REF!<5%,"compliant","not compliant") -> #REF! | E10: =IF('Prudential Ratios'!#REF!<5%,"compliant","not compliant") -> #REF! | F10: =IF('Prudential Ratios'!#REF!<5%,"compliant","not compliant") -> #REF! | G10: =IF('Prudential Ratios'!#REF!<5%,"compliant","not compliant") -> #REF! | H10: =IF('Prudential Ratios'!#REF!<5%,"compliant","not compliant") -> #REF! | I10: =IF('Prudential Ratios'!#REF!<5%,"compliant","not compliant") -> #REF! | ... N10: =IF('Prudential Ratios'!#REF!<5%,"compliant","not compliant") -> #REF!
A11: FITD (Max 5%) | B11: =IF('Prudential Ratios'!#REF!<5%,"compliant","not compliant") -> #REF! | C11: =IF('Prudential Ratios'!#REF!<5%,"compliant","not compliant") -> #REF! | D11: =IF('Prudential Ratios'!#REF!<5%,"compliant","not compliant") -> #REF! | E11: =IF('Prudential Ratios'!#REF!<5%,"compliant","not compliant") -> #REF! | F11: =IF('Prudential Ratios'!#REF!<5%,"compliant","not compliant") -> #REF! | G11: =IF('Prudential Ratios'!#REF!<5%,"compliant","not compliant") -> #REF! | H11: =IF('Prudential Ratios'!#REF!<5%,"compliant","not compliant") -> #REF! | I11: =IF('Prudential Ratios'!#REF!<5%,"compliant","not compliant") -> #REF! | ... N11: =IF('Prudential Ratios'!#REF!<5%,"compliant","not compliant") -> #REF!
A12: FICC (Max 40%) | B12: =IF('Prudential Ratios'!#REF!<40%,"compliant","not compliant") -> #REF! | C12: =IF('Prudential Ratios'!#REF!<40%,"compliant","not compliant") -> #REF! | D12: =IF('Prudential Ratios'!#REF!<40%,"compliant","not compliant") -> #REF! | E12: =IF('Prudential Ratios'!#REF!<40%,"compliant","not compliant") -> #REF! | F12: =IF('Prudential Ratios'!#REF!<40%,"compliant","not compliant") -> #REF! | G12: =IF('Prudential Ratios'!#REF!<40%,"compliant","not compliant") -> #REF! | H12: =IF('Prudential Ratios'!#REF!<40%,"compliant","not compliant") -> #REF! | I12: =IF('Prudential Ratios'!#REF!<40%,"compliant","not compliant") -> #REF! | ... N12: =IF('Prudential Ratios'!#REF!<40%,"compliant","not compliant") -> #REF!
A13: EB ratio | B13: =IF('Prudential Ratios'!#REF!<25%,"compliant","not compliant") -> #REF! | C13: =IF('Prudential Ratios'!#REF!<25%,"compliant","not compliant") -> #REF! | D13: =IF('Prudential Ratios'!#REF!<25%,"compliant","not compliant") -> #REF! | E13: =IF('Prudential Ratios'!#REF!<25%,"compliant","not compliant") -> #REF! | F13: =IF('Prudential Ratios'!#REF!<25%,"compliant","not compliant") -> #REF! | G13: =IF('Prudential Ratios'!#REF!<25%,"compliant","not compliant") -> #REF! | H13: =IF('Prudential Ratios'!#REF!<25%,"compliant","not compliant") -> #REF! | I13: =IF('Prudential Ratios'!#REF!<25%,"compliant","not compliant") -> #REF! | ... N13: =IF('Prudential Ratios'!#REF!<25%,"compliant","not compliant") -> #REF!
A14: A=S+L | B14: =IF(SFP!#REF!=SFP!#REF!,"balancing","notbalancing") -> #REF! | C14: =IF(SFP!#REF!=SFP!#REF!,"balancing","notbalancing") -> #REF! | D14: =IF(SFP!#REF!=SFP!#REF!,"balancing","notbalancing") -> #REF! | E14: =IF(SFP!#REF!=SFP!#REF!,"balancing","notbalancing") -> #REF! | F14: =IF(SFP!#REF!=SFP!#REF!,"balancing","notbalancing") -> #REF! | G14: =IF(SFP!#REF!=SFP!#REF!,"balancing","notbalancing") -> #REF! | H14: =IF(SFP!#REF!=SFP!#REF!,"balancing","notbalancing") -> #REF! | I14: =IF(SFP!#REF!=SFP!#REF!,"balancing","notbalancing") -> #REF! | ... N14: =IF(SFP!#REF!=SFP!#REF!,"balancing","notbalancing") -> #REF!

Sheet Prudential Ratios
B1: STIMA SACCO SOCIETY LTD
B2: Sacco Financial Performance
B4: FINANCIAL SOUNDNESS INDICATORS | C4: Prude. Std | D4: 44197 | E4: 44197 | F4: 44228 | G4: 44256 | H4: 44287 | I4: 44317 | J4: 44348 | K4: 44378 | L4: 44409 | M4: 44440 | N4: 44470 | O4: 44501 | P4: 44531 | Q4: Audited 2021 | R4: 44562 | S4: 44593 | T4: 44621 | U4: 44652 | V4: 44682 | W4: 44713 | X4: 44743 | Y4: 44774 | Z4: 44805 | AA4: 44835 | AB4: 44866 | AC4: 44896 | AD4: Audited-2022 | AE4: 44949 | AF4: 44980 | AG4: 45008 | AH4: 45039 | AI4: 45069 | AJ4: 45100
A5: 1 | B5: CAPITAL ADEQUACY REQUIREMENTS
A6: 1.1 | B6: Core capital | C6: ≥ Ksh.10M | E6: =Financials!D14/1000000 -> 6578.7089 | F6: =Financials!E14/1000000 -> 6664.0025 | G6: =Financials!F14/1000000 -> 6555.7887 | H6: =Financials!G14/1000000 -> 6722.7782 | I6: =Financials!H14/1000000 -> 6916.5815 | J6: =Financials!I14/1000000 -> 6899.1975 | K6: =Financials!J14/1000000 -> 7079.1033 | L6: =Financials!K14/1000000 -> 7230.3262 | ... AJ6: =Financials!AI14/1000000 -> 8931.2173
A7: 1.2 | B7: Core capital /Total Assets | C7: ≥ 10% | E7: =Financials!D14/Financials!D5 -> 0.15865783 | F7: =Financials!E14/Financials!E5 -> 0.15884834 | G7: =Financials!F14/Financials!F5 -> 0.15934179 | H7: =Financials!G14/Financials!G5 -> 0.16194356 | I7: =Financials!H14/Financials!H5 -> 0.16491152 | J7: =Financials!I14/Financials!I5 -> 0.16266766 | K7: =Financials!J14/Financials!J5 -> 0.16547489 | L7: =Financials!K14/Financials!K5 -> 0.16552831 | ... AJ7: =Financials!AI14/Financials!AI5 -> 0.16449256
A8: 1.3 | B8: Core capital /Total Deposits | C8: ≥ 8% | E8: =Financials!D14/Financials!D6 -> 0.21071153 | F8: =Financials!E14/Financials!E6 -> 0.21273766 | G8: =Financials!F14/Financials!F6 -> 0.2008079 | H8: =Financials!G14/Financials!G6 -> 0.20518068 | I8: =Financials!H14/Financials!H6 -> 0.21123958 | J8: =Financials!I14/Financials!I6 -> 0.20953859 | K8: =Financials!J14/Financials!J6 -> 0.21630414 | L8: =Financials!K14/Financials!K6 -> 0.21829935 | ... AJ8: =Financials!AI14/Financials!AI6 -> 0.21805422
A9: 1.4 | B9: Share Capital/Total Assets | C9: ≤2% | E9: =Financials!D18/Financials!D5 -> 0.049260175 | F9: =Financials!E18/Financials!E5 -> 0.049200162 | G9: =Financials!F18/Financials!F5 -> 0.051796069 | H9: =Financials!G18/Financials!G5 -> 0.051999452 | I9: =Financials!H18/Financials!H5 -> 0.052001158 | J9: =Financials!I18/Financials!I5 -> 0.051987667 | K9: =Financials!J18/Financials!J5 -> 0.052398016 | L9: =Financials!K18/Financials!K5 -> 0.052011355 | ... AJ9: =Financials!AI18/Financials!AI5 -> 0.06010375
A10: 1.5 | B10: Institutional Capital/Total Assets | C10: ≥ 8% | E10: =Financials!D15/Financials!D5 -> 0.10939766 | F10: =Financials!E15/Financials!E5 -> 0.10964818 | G10: =Financials!F15/Financials!F5 -> 0.10754573 | H10: =Financials!G15/Financials!G5 -> 0.10994411 | I10: =Financials!H15/Financials!H5 -> 0.11291037 | J10: =Financials!I15/Financials!I5 -> 0.11067999 | K10: =Financials!J15/Financials!J5 -> 0.11307688 | L10: =Financials!K15/Financials!K5 -> 0.11351696 | ... AJ10: =Financials!AI15/Financials!AI5 -> 0.10438881
A12: 2 | B12: ASSET MIX AND QUALITY
A13: 2.1 | B13: Non Earning Assets
A14: 2.1.1 | B14: Non earning Assets/Total assets | C14: ≤ 10% | E14: =Financials!D38/Financials!D5 -> 0.035368553 | F14: =Financials!E38/Financials!E5 -> 0.040774312 | G14: =Financials!F38/Financials!F5 -> 0.033083895 | H14: =Financials!G38/Financials!G5 -> 0.040344571 | I14: =Financials!H38/Financials!H5 -> 0.039739294 | J14: =Financials!I38/Financials!I5 -> 0.040677021 | K14: =Financials!J38/Financials!J5 -> 0.045702627 | L14: =Financials!K38/Financials!K5 -> 0.045025494 | ... AJ14: =Financials!AI38/Financials!AI5 -> 0.04876996
A15: 2.1.2 | B15: Property and Equipment/Total Assets | C15: ≤ 5% | E15: =Financials!D39/Financials!D5 -> 0.0055126393 | F15: =Financials!E39/Financials!E5 -> 0.0054400205 | G15: =Financials!F39/Financials!F5 -> 0.0055423733 | H15: =Financials!G39/Financials!G5 -> 0.0054591737 | I15: =Financials!H39/Financials!H5 -> 0.0053447843 | J15: =Financials!I39/Financials!I5 -> 0.0052457843 | K15: =Financials!J39/Financials!J5 -> 0.0051669335 | L15: =Financials!K39/Financials!K5 -> 0.0050875012 | ... AJ15: =Financials!AI39/Financials!AI5 -> 0.0081536805
A16: 2.1.3 | B16: Non Performing loans/Gross Loans | C16: ≤ 6%
A18: 2.2 | B18: Earning Assets
A19: 2.2.1 | B19: Equities & Investments/Deposits | C19: ≤ 5% | E19: =Financials!D26/Financials!D6 -> 0.01849949 | F19: =Financials!E26/Financials!E6 -> 0.018438608 | G19: =Financials!F26/Financials!F6 -> 0.01769188 | H19: =Financials!G26/Financials!G6 -> 0.017628083 | I19: =Financials!H26/Financials!H6 -> 0.017640198 | J19: =Financials!I26/Financials!I6 -> 0.017542212 | K19: =Financials!J26/Financials!J6 -> 0.017648467 | L19: =Financials!K26/Financials!K6 -> 0.017438765 | ... AJ19: =Financials!AI26/Financials!AI6 -> 0.01363028
A20: 2.2.2 | B20: Equities & Investments/Core Capital | C20: ≤ 40% | E20: =Financials!D26/Financials!D14 -> 0.087795341 | F20: =Financials!E26/Financials!E14 -> 0.086672984 | G20: =Financials!F26/Financials!F14 -> 0.088103509 | H20: =Financials!G26/Financials!G14 -> 0.085914926 | I20: =Financials!H26/Financials!H14 -> 0.083508014 | J20: =Financials!I26/Financials!I14 -> 0.083718286 | K20: =Financials!J26/Financials!J14 -> 0.081590981 | L20: =Financials!K26/Financials!K14 -> 0.079884637 | ... AJ20: =Financials!AI26/Financials!AI14 -> 0.062508674
A21: 2.2.3 | B21: Net Loans & advances /Total assets | C21: NPR | E21: =Financials!D31/Financials!D5 -> 0.80199739 | F21: =Financials!E31/Financials!E5 -> 0.7958464 | G21: =Financials!F31/Financials!F5 -> 0.80629712 | H21: =Financials!G31/Financials!G5 -> 0.80254472 | I21: =Financials!H31/Financials!H5 -> 0.8008076 | J21: =Financials!I31/Financials!I5 -> 0.79273101 | K21: =Financials!J31/Financials!J5 -> 0.78306191 | L21: =Financials!K31/Financials!K5 -> 0.77305813 | ... AJ21: =Financials!AI31/Financials!AI5 -> 0.76435026
A23: 3 | B23: FUNDING MIX
A24: 3.1 | B24: Total Deposits/Total Assets | C24: NPR | E24: =Financials!D6/Financials!D5 -> 0.75296229 | F24: =Financials!E6/Financials!E5 -> 0.74668653 | G24: =Financials!F6/Financials!F5 -> 0.79350362 | H24: =Financials!G6/Financials!G5 -> 0.78927292 | I24: =Financials!H6/Financials!H5 -> 0.78068477 | J24: =Financials!I6/Financials!I5 -> 0.77631361 | K24: =Financials!J6/Financials!J5 -> 0.76501029 | L24: =Financials!K6/Financials!K5 -> 0.75826294 | ... AJ24: =Financials!AI6/Financials!AI5 -> 0.7543654
A25: 3.1.1 | B25: BOSA Deposits/Total Assets | C25: NPR | E25: =Financials!D7/Financials!D5 -> 0.57644424 | F25: =Financials!E7/Financials!E5 -> 0.57372279 | G25: =Financials!F7/Financials!F5 -> 0.59590923 | H25: =Financials!G7/Financials!G5 -> 0.5961339 | I25: =Financials!H7/Financials!H5 -> 0.59407402 | J25: =Financials!I7/Financials!I5 -> 0.59000274 | K25: =Financials!J7/Financials!J5 -> 0.59246095 | L25: =Financials!K7/Financials!K5 -> 0.58524308 | ... AJ25: =Financials!AI7/Financials!AI5 -> 0.59905723
A26: 3.1.2 | B26: FOSA Deposits/Total Assets | C26: NPR | E26: =Financials!D8/Financials!D5 -> 0.074901097 | F26: =Financials!E8/Financials!E5 -> 0.072759204 | G26: =Financials!F8/Financials!F5 -> 0.09246145 | H26: =Financials!G8/Financials!G5 -> 0.087136285 | I26: =Financials!H8/Financials!H5 -> 0.081448834 | J26: =Financials!I8/Financials!I5 -> 0.082411516 | K26: =Financials!J8/Financials!J5 -> 0.065010692 | L26: =Financials!K8/Financials!K5 -> 0.067431729 | ... AJ26: =Financials!AI8/Financials!AI5 -> 0.067300177
A27: 3.2 | B27: External Borrowing/Total assets | C27: ≤ 25% | E27: =Financials!D9/Financials!D5 -> 0 | F27: =Financials!E9/Financials!E5 -> 0 | G27: =Financials!F9/Financials!F5 -> 0 | H27: =Financials!G9/Financials!G5 -> 0 | I27: =Financials!H9/Financials!H5 -> 0 | J27: =Financials!I9/Financials!I5 -> 0 | K27: =Financials!J9/Financials!J5 -> 0 | L27: =Financials!K9/Financials!K5 -> 0.0015803761 | ... AJ27: =Financials!AI9/Financials!AI5 -> 0.0049804887
A29: 4 | B29: GROWTH RATIOS
A30: 4.1 | B30: Total Assets | C30: NPR | E30: =Financials!D5/Financials!C5-1 -> -0.013550629 | F30: =Financials!E5/Financials!D5-1 -> 0.011750238 | G30: =Financials!F5/Financials!E5-1 -> -0.019285087 | H30: =Financials!G5/Financials!F5-1 -> 0.0089969759 | I30: =Financials!H5/Financials!G5-1 -> 0.010311717 | J30: =Financials!I5/Financials!H5-1 -> 0.011246093 | K30: =Financials!J5/Financials!I5-1 -> 0.0086692807 | L30: =Financials!K5/Financials!J5-1 -> 0.021032264 | ... AJ30: =Financials!AI5/Financials!AH5-1 -> 0.0064651801
A31: 4.2 | B31: Total Deposits | C31: NPR | E31: =Financials!D6/Financials!C6-1 -> 0.0010624492 | F31: =Financials!E6/Financials!D6-1 -> 0.0033175391 | G31: =Financials!F6/Financials!E6-1 -> 0.042205543 | H31: =Financials!G6/Financials!F6-1 -> 0.0036173272 | I31: =Financials!H6/Financials!G6-1 -> -0.00068156983 | J31: =Financials!I6/Financials!H6-1 -> 0.0055839815 | K31: =Financials!J6/Financials!I6-1 -> -0.0060171913 | L31: =Financials!K6/Financials!J6-1 -> 0.01202681 | ... AJ31: =Financials!AI6/Financials!AH6-1 -> -0.00047226909
A32: 4.2.1 | B32: FOSA Deposits | C32: NPR | E32: =Financials!D8/Financials!C8-1 -> -0.19911087 | F32: =Financials!E8/Financials!D8-1 -> -0.01718206 | G32: =Financials!F8/Financials!E8-1 -> 0.24627975 | H32: =Financials!G8/Financials!F8-1 -> -0.049114546 | I32: =Financials!H8/Financials!G8-1 -> -0.055632091 | J32: =Financials!I8/Financials!H8-1 -> 0.023198492 | K32: =Financials!J8/Financials!I8-1 -> -0.20430674 | L32: =Financials!K8/Financials!J8-1 -> 0.059056123 | ... AJ32: =Financials!AI8/Financials!AH8-1 -> -0.003904156
A33: 4.2.2 | B33: BOSA Deposits | C33: NPR | E33: =Financials!D7/Financials!C7-1 -> 0.0080039667 | F33: =Financials!E7/Financials!D7-1 -> 0.0069736637 | G33: =Financials!F7/Financials!E7-1 -> 0.018640146 | H33: =Financials!G7/Financials!F7-1 -> 0.0093773869 | I33: =Financials!H7/Financials!G7-1 -> 0.0068206902 | J33: =Financials!I7/Financials!H7-1 -> 0.0043158649 | K33: =Financials!J7/Financials!I7-1 -> 0.012871849 | L33: =Financials!K7/Financials!J7-1 -> 0.0085931635 | ... AJ33: =Financials!AI7/Financials!AH7-1 -> 0.0032929638
A34: 4.3 | B34: Net Loans & advances | C34: NPR | E34: =Financials!D31/Financials!C31-1 -> -0.088263435 | F34: =Financials!E31/Financials!D31-1 -> 0.0039905402 | G34: =Financials!F31/Financials!E31-1 -> -0.0064067518 | H34: =Financials!G31/Financials!F31-1 -> 0.0043012314 | I34: =Financials!H31/Financials!G31-1 -> 0.0081248777 | J34: =Financials!I31/Financials!H31-1 -> 0.0010471168 | K34: =Financials!J31/Financials!I31-1 -> -0.0036336569 | L34: =Financials!K31/Financials!J31-1 -> 0.0079883641 | ... AJ34: =Financials!AI31/Financials!AH31-1 -> -0.0074728419
A35: 4.4 | B35: Core capital | C35: NPR | E35: =Financials!D14/Financials!C14-1 -> 0.079311473 | F35: =Financials!E14/Financials!D14-1 -> 0.012965105 | G35: =Financials!F14/Financials!E14-1 -> -0.016238569 | H35: =Financials!G14/Financials!F14-1 -> 0.025472071 | I35: =Financials!H14/Financials!G14-1 -> 0.028827866 | J35: =Financials!I14/Financials!H14-1 -> -0.0025133867 | K35: =Financials!J14/Financials!I14-1 -> 0.026076344 | L35: =Financials!K14/Financials!J14-1 -> 0.021361872 | ... AJ35: =Financials!AI14/Financials!AH14-1 -> -0.022885244
A36: 4.5 | B36: Total Gross Income | C36: NPR | E36: =Financials!D41/Financials!C41-1 -> 0.0070642437 | F36: =Financials!E41/Financials!D41-1 -> -0.0070144429 | G36: =Financials!F41/Financials!E41-1 -> 0 | H36: =Financials!G41/Financials!F41-1 -> 0 | I36: =Financials!H41/Financials!G41-1 -> 0 | J36: =Financials!I41/Financials!H41-1 -> 0 | K36: =Financials!J41/Financials!I41-1 -> 0 | L36: =Financials!K41/Financials!J41-1 -> 0 | ... AJ36: =Financials!AI41/Financials!AH41-1 -> 0
A37: 4.6 | B37: Membership | C37: NPR
A39: 5 | B39: Efficiency Ratios
A40: 5.1 | B40: FinCost-Deposits/Average Deposits | C40: NPR | E40: =Financials!D48/((Financials!D6+Financials!C6)/2) -> 0 | F40: =Financials!E48/((Financials!E6+Financials!D6)/2) -> 0 | G40: =Financials!F48/((Financials!F6+Financials!E6)/2) -> 0 | H40: =Financials!G48/((Financials!G6+Financials!F6)/2) -> 0 | I40: =Financials!H48/((Financials!H6+Financials!G6)/2) -> 0 | J40: =Financials!I48/((Financials!I6+Financials!H6)/2) -> 0 | K40: =Financials!J48/((Financials!J6+Financials!I6)/2) -> 0 | L40: =Financials!K48/((Financials!K6+Financials!J6)/2) -> 0 | ... AJ40: =Financials!AI48/((Financials!AI6+Financials!AH6)/2) -> 0.0044478241
A41: 5.2 | B41: FinCost-Shares/Average Share capital | C41: NPR | E41: =Financials!D49/((Financials!D18+Financials!C18)/2) -> 0 | F41: =Financials!E49/((Financials!E18+Financials!D18)/2) -> 0 | G41: =Financials!F49/((Financials!F18+Financials!E18)/2) -> 0 | H41: =Financials!G49/((Financials!G18+Financials!F18)/2) -> 0 | I41: =Financials!H49/((Financials!H18+Financials!G18)/2) -> 0 | J41: =Financials!I49/((Financials!I18+Financials!H18)/2) -> 0 | K41: =Financials!J49/((Financials!J18+Financials!I18)/2) -> 0 | L41: =Financials!K49/((Financials!K18+Financials!J18)/2) -> 0 | ... AJ41: =Financials!AI49/((Financials!AI18+Financials!AH18)/2) -> 0.52278999
A42: 5.3 | B42: FinCost-Ext Loans/Average Ext Loans | C42: NPR | E42: =Financials!D50/((Financials!D9+Financials!C9)/2) -> #DIV/0! | F42: =Financials!E50/((Financials!E9+Financials!D9)/2) -> #DIV/0! | G42: =Financials!F50/((Financials!F9+Financials!E9)/2) -> #DIV/0! | H42: =Financials!G50/((Financials!G9+Financials!F9)/2) -> #DIV/0! | I42: =Financials!H50/((Financials!H9+Financials!G9)/2) -> #DIV/0! | J42: =Financials!I50/((Financials!I9+Financials!H9)/2) -> #DIV/0! | K42: =Financials!J50/((Financials!J9+Financials!I9)/2) -> #DIV/0! | L42: =Financials!K50/((Financials!K9+Financials!J9)/2) -> 0 | ... AJ42: =Financials!AI50/((Financials!AI9+Financials!AH9)/2) -> 0.026946091
A43: 5.4 | B43: OpEx/Average Total Assets | C43: NPR | E43: =(Financials!D52+Financials!D53)/((Financials!D5+Financials!C5)/2) -> 0 | F43: =(Financials!E52+Financials!E53)/((Financials!E5+Financials!D5)/2) -> 0 | G43: =(Financials!F52+Financials!F53)/((Financials!F5+Financials!E5)/2) -> 0 | H43: =(Financials!G52+Financials!G53)/((Financials!G5+Financials!F5)/2) -> 0 | I43: =(Financials!H52+Financials!H53)/((Financials!H5+Financials!G5)/2) -> 0 | J43: =(Financials!I52+Financials!I53)/((Financials!I5+Financials!H5)/2) -> 0 | K43: =(Financials!J52+Financials!J53)/((Financials!J5+Financials!I5)/2) -> 0 | L43: =(Financials!K52+Financials!K53)/((Financials!K5+Financials!J5)/2) -> 0 | ... AJ43: =(Financials!AI52+Financials!AI53)/((Financials!AI5+Financials!AH5)/2) -> 0.0076891635
A44: 5.5 | B44: Avge yield on Net loans | C44: NPR | E44: =Financials!D42/((Financials!D31+Financials!C31)/2) -> 0.033985925 | F44: =Financials!E42/((Financials!E31+Financials!D31)/2) -> 0.035305748 | G44: =Financials!F42/((Financials!F31+Financials!E31)/2) -> 0.035348819 | H44: =Financials!G42/((Financials!G31+Financials!F31)/2) -> 0.035386682 | I44: =Financials!H42/((Financials!H31+Financials!G31)/2) -> 0.035168037 | J44: =Financials!I42/((Financials!I31+Financials!H31)/2) -> 0.035007992 | K44: =Financials!J42/((Financials!J31+Financials!I31)/2) -> 0.035053368 | L44: =Financials!K42/((Financials!K31+Financials!J31)/2) -> 0.034977579 | ... AJ44: =Financials!AI42/((Financials!AI31+Financials!AH31)/2) -> 0.039795862
A46: 6 | B46: Liquidity Ratio
A47: 6.1 | B47: minimum Liquidity | C47: 0.15 | E47: =(SFP!C4+SFP!C11)/(SFP!C31+SFP!C34+SFP!C35+SFP!C36+SFP!C37+SFP!C38) -> 0.1920364 | F47: =(SFP!D4+SFP!D11)/(SFP!D31+SFP!D34+SFP!D35+SFP!D36+SFP!D37+SFP!D38) -> 0.19261706 | G47: =(SFP!E4+SFP!E11)/(SFP!E31+SFP!E34+SFP!E35+SFP!E36+SFP!E37+SFP!E38) -> 0.19469053 | H47: =(SFP!F4+SFP!F11)/(SFP!F31+SFP!F34+SFP!F35+SFP!F36+SFP!F37+SFP!F38) -> 0.17994745 | I47: =(SFP!G4+SFP!G11)/(SFP!G31+SFP!G34+SFP!G35+SFP!G36+SFP!G37+SFP!G38) -> 0.18302274 | J47: =(SFP!H4+SFP!H11)/(SFP!H31+SFP!H34+SFP!H35+SFP!H36+SFP!H37+SFP!H38) -> 0.18969881 | K47: =(SFP!I4+SFP!I11)/(SFP!I31+SFP!I34+SFP!I35+SFP!I36+SFP!I37+SFP!I38) -> 0.19398708 | L47: =(SFP!J4+SFP!J11)/(SFP!J31+SFP!J34+SFP!J35+SFP!J36+SFP!J37+SFP!J38) -> 0.21202262 | ... AJ47: =(SFP!AH4+SFP!AH11)/(SFP!AH31+SFP!AH34+SFP!AH35+SFP!AH36+SFP!AH37+SFP!AH38) -> 0.176209
...

Sheet CAELS
B1: STIMA SACCO
B2: FINANCIAL SOUNDNESS INDICATORS | C2: Prude. Std | D2: 44136 | E2: 44166 | F2: Audited 2020 | G2: 44197 | H2: 44228 | I2: 44256 | J2: 44287 | K2: 44317 | L2: 44348 | M2: 44378 | N2: 44409 | O2: 44440 | P2: 44470 | Q2: 44501 | R2: 44531 | S2: Audited 2021 | T2: 44562 | U2: 44593 | V2: 44621 | W2: 44652 | X2: 44682 | Y2: 44713 | Z2: 44743 | AA2: 44774 | AB2: 44805 | AC2: 44835 | AD2: 44866 | AE2: 44896 | AF2: Audited-2022 | AG2: 44949 | AH2: 44980 | AI2: 45008 | AJ2: 45039 | AK2: 45069 | AL2: 45100 | AM2: 45130 | AN2: 45161
B3: CAPITAL
B4: CORE CAPITAL | C4: ≥ Ksh.10M | D4: ='Prudential Ratios'!#REF! -> #REF! | E4: ='Prudential Ratios'!#REF! -> #REF! | F4: ='Prudential Ratios'!D6 -> 0 | G4: ='Prudential Ratios'!E6 -> 6578.7089 | H4: ='Prudential Ratios'!F6 -> 6664.0025 | I4: ='Prudential Ratios'!G6 -> 6555.7887 | J4: ='Prudential Ratios'!H6 -> 6722.7782 | K4: ='Prudential Ratios'!I6 -> 6916.5815 | L4: ='Prudential Ratios'!J6 -> 6899.1975 | M4: ='Prudential Ratios'!K6 -> 7079.1033 | ... AL4: ='Prudential Ratios'!AJ6 -> 8931.2173
B5: CCA | C5: ≥ 10% | D5: ='Prudential Ratios'!#REF! -> #REF! | E5: ='Prudential Ratios'!#REF! -> #REF! | F5: ='Prudential Ratios'!D7 -> 0 | G5: ='Prudential Ratios'!E7 -> 0.15865783 | H5: ='Prudential Ratios'!F7 -> 0.15884834 | I5: ='Prudential Ratios'!G7 -> 0.15934179 | J5: ='Prudential Ratios'!H7 -> 0.16194356 | K5: ='Prudential Ratios'!I7 -> 0.16491152 | L5: ='Prudential Ratios'!J7 -> 0.16266766 | M5: ='Prudential Ratios'!K7 -> 0.16547489 | ... AL5: ='Prudential Ratios'!AJ7 -> 0.16449256
B6: ICA | C6: ≥ 8% | D6: ='Prudential Ratios'!#REF! -> #REF! | E6: ='Prudential Ratios'!#REF! -> #REF! | F6: ='Prudential Ratios'!D10 -> 0 | G6: ='Prudential Ratios'!E10 -> 0.10939766 | H6: ='Prudential Ratios'!F10 -> 0.10964818 | I6: ='Prudential Ratios'!G10 -> 0.10754573 | J6: ='Prudential Ratios'!H10 -> 0.10994411 | K6: ='Prudential Ratios'!I10 -> 0.11291037 | L6: ='Prudential Ratios'!J10 -> 0.11067999 | M6: ='Prudential Ratios'!K10 -> 0.11307688 | ... AL6: ='Prudential Ratios'!AJ10 -> 0.10438881
B7: CCD | C7: ≥ 8% | D7: ='Prudential Ratios'!#REF! -> #REF! | E7: ='Prudential Ratios'!#REF! -> #REF! | F7: ='Prudential Ratios'!D8 -> 0 | G7: ='Prudential Ratios'!E8 -> 0.21071153 | H7: ='Prudential Ratios'!F8 -> 0.21273766 | I7: ='Prudential Ratios'!G8 -> 0.2008079 | J7: ='Prudential Ratios'!H8 -> 0.20518068 | K7: ='Prudential Ratios'!I8 -> 0.21123958 | L7: ='Prudential Ratios'!J8 -> 0.20953859 | M7: ='Prudential Ratios'!K8 -> 0.21630414 | ... AL7: ='Prudential Ratios'!AJ8 -> 0.21805422
B8: Asset Quality
B9: NPL | C9: ≤ 6%
B10: Earnings
B11: ROA | D11: ='Prudential Ratios'!#REF! -> #REF! | E11: ='Prudential Ratios'!#REF! -> #REF! | F11: ='Prudential Ratios'!D55 -> 0 | G11: ='Prudential Ratios'!E55 -> -1.9118409e-10 | H11: ='Prudential Ratios'!F55 -> -1.7616701e-10 | I11: ='Prudential Ratios'!G55 -> -1.5994e-10 | J11: ='Prudential Ratios'!H55 -> -1.4539702e-10 | K11: ='Prudential Ratios'!I55 -> -1.2803344e-10 | L11: ='Prudential Ratios'!J55 -> -1.1085143e-10 | M11: ='Prudential Ratios'!K55 -> -9.4039312e-11 | ... AL11: ='Prudential Ratios'!AJ55 -> -0.0019981104
B12: CIR | D12: ='Prudential Ratios'!#REF! -> #REF! | E12: ='Prudential Ratios'!#REF! -> #REF! | F12: ='Prudential Ratios'!D56 -> 0 | G12: ='Prudential Ratios'!E56 -> #DIV/0! | H12: ='Prudential Ratios'!F56 -> #DIV/0! | I12: ='Prudential Ratios'!G56 -> #DIV/0! | J12: ='Prudential Ratios'!H56 -> #DIV/0! | K12: ='Prudential Ratios'!I56 -> #DIV/0! | L12: ='Prudential Ratios'!J56 -> #DIV/0! | M12: ='Prudential Ratios'!K56 -> #DIV/0! | ... AL12: ='Prudential Ratios'!AJ56 -> 0.48272104
B13: OER | D13: ='Prudential Ratios'!#REF! -> #REF! | E13: ='Prudential Ratios'!#REF! -> #REF! | F13: ='Prudential Ratios'!D57 -> 0 | G13: ='Prudential Ratios'!E57 -> 0 | H13: ='Prudential Ratios'!F57 -> 0 | I13: ='Prudential Ratios'!G57 -> 0 | J13: ='Prudential Ratios'!H57 -> 0 | K13: ='Prudential Ratios'!I57 -> 0 | L13: ='Prudential Ratios'!J57 -> 0 | M13: ='Prudential Ratios'!K57 -> 0 | ... AL13: ='Prudential Ratios'!AJ57 -> 0.018698524
B14: LIQUIDITY
B15: MIN LIQ | C15: 0.15 | D15: ='Prudential Ratios'!#REF! -> #REF! | E15: ='Prudential Ratios'!#REF! -> #REF! | F15: ='Prudential Ratios'!D47 -> 0 | G15: ='Prudential Ratios'!E47 -> 0.1920364 | H15: ='Prudential Ratios'!F47 -> 0.19261706 | I15: ='Prudential Ratios'!G47 -> 0.19469053 | J15: ='Prudential Ratios'!H47 -> 0.17994745 | K15: ='Prudential Ratios'!I47 -> 0.18302274 | L15: ='Prudential Ratios'!J47 -> 0.18969881 | M15: ='Prudential Ratios'!K47 -> 0.19398708 | ... AL15: ='Prudential Ratios'!AJ47 -> 0.176209
B16: TEC LIQ | D16: ='Prudential Ratios'!#REF! -> #REF! | E16: ='Prudential Ratios'!#REF! -> #REF! | F16: ='Prudential Ratios'!D48 -> 0 | G16: ='Prudential Ratios'!E48 -> 0.15173396 | H16: ='Prudential Ratios'!F48 -> 0.15299789 | I16: ='Prudential Ratios'!G48 -> 0.1489151 | J16: ='Prudential Ratios'!H48 -> 0.13846407 | K16: ='Prudential Ratios'!I48 -> 0.14211175 | L16: ='Prudential Ratios'!J48 -> 0.14747728 | M16: ='Prudential Ratios'!K48 -> 0.15386578 | ... AL16: ='Prudential Ratios'!AJ48 -> 0.14323737
B17: EB | C17: ≤ 25% | D17: ='Prudential Ratios'!#REF! -> #REF! | E17: ='Prudential Ratios'!#REF! -> #REF! | F17: ='Prudential Ratios'!D27 -> 0 | G17: ='Prudential Ratios'!E27 -> 0 | H17: ='Prudential Ratios'!F27 -> 0 | I17: ='Prudential Ratios'!G27 -> 0 | J17: ='Prudential Ratios'!H27 -> 0 | K17: ='Prudential Ratios'!I27 -> 0 | L17: ='Prudential Ratios'!J27 -> 0 | M17: ='Prudential Ratios'!K27 -> 0 | ... AL17: ='Prudential Ratios'!AJ27 -> 0.0049804887
B18: LIQ/TA | D18: ='Prudential Ratios'!#REF! -> #REF! | E18: ='Prudential Ratios'!#REF! -> #REF! | F18: ='Prudential Ratios'!D58 -> 0.12148195 | G18: ='Prudential Ratios'!E58 -> 0.12762157 | H18: ='Prudential Ratios'!F58 -> 0.12865596 | I18: ='Prudential Ratios'!G58 -> 0.12514852 | J18: ='Prudential Ratios'!H58 -> 0.11600552 | K18: ='Prudential Ratios'!I58 -> 0.11864014 | L18: ='Prudential Ratios'!J58 -> 0.12345082 | M18: ='Prudential Ratios'!K58 -> 0.12836691 | ... AL18: ='Prudential Ratios'!AJ58 -> 0.11888809
B19: STRUCTURE
B20: NEA | C20: ≤ 10% | D20: ='Prudential Ratios'!#REF! -> #REF! | E20: ='Prudential Ratios'!#REF! -> #REF! | F20: ='Prudential Ratios'!D14 -> 0 | G20: ='Prudential Ratios'!E14 -> 0.035368553 | H20: ='Prudential Ratios'!F14 -> 0.040774312 | I20: ='Prudential Ratios'!G14 -> 0.033083895 | J20: ='Prudential Ratios'!H14 -> 0.040344571 | K20: ='Prudential Ratios'!I14 -> 0.039739294 | L20: ='Prudential Ratios'!J14 -> 0.040677021 | M20: ='Prudential Ratios'!K14 -> 0.045702627 | ... AL20: ='Prudential Ratios'!AJ14 -> 0.04876996
B21: LB | C21: ≤ 5% | D21: ='Prudential Ratios'!#REF! -> #REF! | E21: ='Prudential Ratios'!#REF! -> #REF! | F21: ='Prudential Ratios'!D15 -> 0 | G21: ='Prudential Ratios'!E15 -> 0.0055126393 | H21: ='Prudential Ratios'!F15 -> 0.0054400205 | I21: ='Prudential Ratios'!G15 -> 0.0055423733 | J21: ='Prudential Ratios'!H15 -> 0.0054591737 | K21: ='Prudential Ratios'!I15 -> 0.0053447843 | L21: ='Prudential Ratios'!J15 -> 0.0052457843 | M21: ='Prudential Ratios'!K15 -> 0.0051669335 | ... AL21: ='Prudential Ratios'!AJ15 -> 0.0081536805
B22: FITD | C22: ≤ 5% | D22: ='Prudential Ratios'!#REF! -> #REF! | E22: ='Prudential Ratios'!#REF! -> #REF! | F22: ='Prudential Ratios'!D19 -> 0 | G22: ='Prudential Ratios'!E19 -> 0.01849949 | H22: ='Prudential Ratios'!F19 -> 0.018438608 | I22: ='Prudential Ratios'!G19 -> 0.01769188 | J22: ='Prudential Ratios'!H19 -> 0.017628083 | K22: ='Prudential Ratios'!I19 -> 0.017640198 | L22: ='Prudential Ratios'!J19 -> 0.017542212 | M22: ='Prudential Ratios'!K19 -> 0.017648467 | ... AL22: ='Prudential Ratios'!AJ19 -> 0.01363028
B23: FICC | C23: ≤ 40% | D23: ='Prudential Ratios'!#REF! -> #REF! | E23: ='Prudential Ratios'!#REF! -> #REF! | F23: ='Prudential Ratios'!D20 -> 0 | G23: ='Prudential Ratios'!E20 -> 0.087795341 | H23: ='Prudential Ratios'!F20 -> 0.086672984 | I23: ='Prudential Ratios'!G20 -> 0.088103509 | J23: ='Prudential Ratios'!H20 -> 0.085914926 | K23: ='Prudential Ratios'!I20 -> 0.083508014 | L23: ='Prudential Ratios'!J20 -> 0.083718286 | M23: ='Prudential Ratios'!K20 -> 0.081590981 | ... AL23: ='Prudential Ratios'!AJ20 -> 0.062508674

Sheet Financials
B1: STIMA SACCO SOCIETY
B3: Year | C3: AUDITED 2020 | D3: 44197 | E3: 44228 | F3: 44256 | G3: 44287 | H3: 44317 | I3: 44348 | J3: 44378 | K3: 44409 | L3: 44440 | M3: 44470 | N3: 44501 | O3: 44531 | P3: Audited 2021 | Q3: 44562 | R3: 44593 | S3: 44621 | T3: 44652 | U3: 44682 | V3: 44713 | W3: 44743 | X3: 44774 | Y3: 44805 | Z3: 44835 | AA3: 44866 | AB3: 44896 | AC3: Audited-2022 | AD3: 44949 | AE3: 44980 | AF3: 45008 | AG3: 45039 | AH3: 45069 | AI3: 45100 | AJ3: 45130 | AK3: 45161
A4: 1 | B4: Membership
A5: 2 | B5: Total Assets | C5: =SFP!B27 -> 42034351000 | D5: =SFP!C27 -> 4.1464759e+10 | E5: =SFP!D27 -> 4.195198e+10 | F5: =SFP!E27 -> 4.1142932e+10 | G5: =SFP!F27 -> 4.1513094e+10 | H5: =SFP!G27 -> 4.1941166e+10 | I5: =SFP!H27 -> 4.241284e+10 | J5: =SFP!I27 -> 4.2780529e+10 | ... AI5: =SFP!AH27 -> 5.4295569e+10
A6: 3 | B6: Total Deposits | C6: =SFP!B32 -> 31188264000 | D6: =SFP!C32 -> 3.12214e+10 | E6: =SFP!D32 -> 3.1324978e+10 | F6: =SFP!E32 -> 3.2647066e+10 | G6: =SFP!F32 -> 3.2765161e+10 | H6: =SFP!G32 -> 3.2742829e+10 | I6: =SFP!H32 -> 3.2925665e+10 | J6: =SFP!I32 -> 3.2727545e+10 | ... AI6: =SFP!AH32 -> 4.0958699e+10
A7: 3.1 | B7: Deposits-Members(BOSA) | C7: =SFP!B31 -> 23712329000 | D7: =SFP!C31 -> 2.3902122e+10 | E7: =SFP!D31 -> 2.4068807e+10 | F7: =SFP!E31 -> 2.4517453e+10 | G7: =SFP!F31 -> 2.4747363e+10 | H7: =SFP!G31 -> 2.4916157e+10 | I7: =SFP!H31 -> 2.5023692e+10 | J7: =SFP!I31 -> 2.5345793e+10 | ... AI7: =SFP!AH31 -> 3.2526154e+10
A8: 3.2 | B8: Deposits-Customers(FOSA) | C8: =SFP!B29 -> 3877885000 | D8: =SFP!C29 -> 3.105756e+09 | E8: =SFP!D29 -> 3.0523927e+09 | F8: =SFP!E29 -> 3.8041352e+09 | G8: =SFP!F29 -> 3.6172968e+09 | H8: =SFP!G29 -> 3.416059e+09 | I8: =SFP!H29 -> 3.4953064e+09 | J8: =SFP!I29 -> 2.7811918e+09 | ... AI8: =SFP!AH29 -> 3.6541014e+09
A9: 4 | B9: External Borrowing | C9: =SFP!B39 -> 0 | D9: =SFP!C39 -> 0 | E9: =SFP!D39 -> 0 | F9: =SFP!E39 -> 0 | G9: =SFP!F39 -> 0 | H9: =SFP!G39 -> 0 | I9: =SFP!H39 -> 0 | J9: =SFP!I39 -> 0 | ... AI9: =SFP!AH39 -> 2.7041847e+08
A10: 4.1 | B10: Short term Liabilities | C10: =SFP!B34+SFP!B35+SFP!B36+SFP!B37+SFP!B38 -> 3486231000 | D10: =SFP!C34+SFP!C35+SFP!C36+SFP!C37+SFP!C38 -> 3.6541015e+09 | E10: =SFP!D34+SFP!D35+SFP!D36+SFP!D37+SFP!D38 -> 3.9524504e+09 | F10: =SFP!E34+SFP!E35+SFP!E36+SFP!E37+SFP!E38 -> 1.929529e+09 | G10: =SFP!F34+SFP!F35+SFP!F36+SFP!F37+SFP!F38 -> 2.0146064e+09 | H10: =SFP!G34+SFP!G35+SFP!G36+SFP!G37+SFP!G38 -> 2.271206e+09 | I10: =SFP!H34+SFP!H35+SFP!H36+SFP!H37+SFP!H38 -> 2.577429e+09 | J10: =SFP!I34+SFP!I35+SFP!I36+SFP!I37+SFP!I38 -> 2.963332e+09 | ... AI10: =SFP!AH34+SFP!AH35+SFP!AH36+SFP!AH37+SFP!AH38 -> 4.1070282e+09
A13: 5 | B13: Share capital and Reserves
A14: 5.1 | B14: Core Capital | C14: =C17 -> 6095283000 | D14: =D17 -> 6.5787089e+09 | E14: =E17 -> 6.6640025e+09 | F14: =F17 -> 6.5557887e+09 | G14: =G17 -> 6.7227782e+09 | H14: =H17 -> 6.9165815e+09 | I14: =I17 -> 6.8991975e+09 | J14: =J17 -> 7.0791033e+09 | ... AI14: =AI17 -> 8.9312173e+09
A15: 5.2 | B15: Institutional Capital | C15: =C14-C18 -> 4072845000 | D15: =D14-D18 -> 4.5361476e+09 | E15: =E14-E18 -> 4.5999583e+09 | F15: =F14-F18 -> 4.4247465e+09 | G15: =G14-G18 -> 4.56412e+09 | H15: =H14-H18 -> 4.7355924e+09 | I15: =I14-I18 -> 4.6942529e+09 | J15: =J14-J18 -> 4.8374885e+09 | ... AI15: =AI14-AI18 -> 5.6678499e+09
A17: 5.3 | B17: Total Capital | C17: =SUM(C18:C21) -> 6095283000 | D17: =SUM(D18:D21) -> 6.5787089e+09 | E17: =SUM(E18:E21) -> 6.6640025e+09 | F17: =SUM(F18:F21) -> 6.5557887e+09 | G17: =SUM(G18:G21) -> 6.7227782e+09 | H17: =SUM(H18:H21) -> 6.9165815e+09 | I17: =SUM(I18:I21) -> 6.8991975e+09 | J17: =SUM(J18:J21) -> 7.0791033e+09 | ... AI17: =SUM(AI18:AI21) -> 8.9312173e+09
A18: 5.3.1 | B18: Members Share Capital | C18: =SFP!B42 -> 2022438000 | D18: =SFP!C42 -> 2.0425613e+09 | E18: =SFP!D42 -> 2.0640442e+09 | F18: =SFP!E42 -> 2.1310422e+09 | G18: =SFP!F42 -> 2.1586581e+09 | H18: =SFP!G42 -> 2.1809892e+09 | I18: =SFP!H42 -> 2.2049446e+09 | J18: =SFP!I42 -> 2.2416148e+09 | ... AI18: =SFP!AH42 -> 3.2633674e+09
A19: 5.3.3 | B19: Retained Earnings | C19: =SFP!B45 -> 2883949000 | D19: =SFP!C45 -> 3.3387782e+09 | E19: =SFP!D45 -> 3.4110617e+09 | F19: =SFP!E45 -> 3.2358499e+09 | G19: =SFP!F45 -> 3.3752235e+09 | H19: =SFP!G45 -> 3.5466958e+09 | I19: =SFP!H45 -> 3.5053563e+09 | J19: =SFP!I45 -> 3.6485919e+09 | ... AI19: =SFP!AH45 -> 3.9975967e+09
A20: 5.3.5 | B20: Statutory Reserves | C20: =SFP!B50 -> 1188896000 | D20: =SFP!C50 -> 1.184895e+09 | E20: =SFP!D50 -> 1.1764222e+09 | F20: =SFP!E50 -> 1.1764222e+09 | G20: =SFP!F50 -> 1.1764222e+09 | H20: =SFP!G50 -> 1.1764222e+09 | I20: =SFP!H50 -> 1.1764222e+09 | J20: =SFP!I50 -> 1.1764222e+09 | ... AI20: =SFP!AH50 -> 1.6577788e+09
A21: 5.3.6 | B21: Capital Reserve | C21: =SFP!B51 -> 0 | D21: =SFP!C51 -> 12474413 | E21: =SFP!D51 -> 12474413 | F21: =SFP!E51 -> 12474413 | G21: =SFP!F51 -> 12474413 | H21: =SFP!G51 -> 12474413 | I21: =SFP!H51 -> 12474413 | J21: =SFP!I51 -> 12474413 | ... AI21: =SFP!AH51 -> 12474413
A22: 5.3.7 | B22: Supplementary Capital & reserves
A23: a | B23: Proposed Dividends | C23: =SFP!B53 -> 280921000 | D23: =SFP!C53 -> 0 | E23: =SFP!D53 -> 0 | F23: =SFP!E53 -> 0 | G23: =SFP!F53 -> 0 | H23: =SFP!G53 -> 0 | I23: =SFP!H53 -> 0 | J23: =SFP!I53 -> 0 | ... AI23: =SFP!AH53 -> 0
A24: b
A26: 6 | B26: Investments | C26: =C27+C28+C29 -> 1962102000 | D26: =D27+D28+D29 -> 5.7757999e+08 | E26: =E27+E28+E29 -> 5.7758899e+08 | F26: =F27+F28+F29 -> 5.7758799e+08 | G26: =G27+G28+G29 -> 5.7758699e+08 | H26: =H27+H28+H29 -> 5.7758999e+08 | I26: =I27+I28+I29 -> 5.7758899e+08 | J26: =J27+J28+J29 -> 5.7759099e+08 | ... AI26: =AI27+AI28+AI29 -> 5.5827855e+08
A27: 6.1 | B27: Investments in Coop bank, CIC, Kuscco, Kerussu & Codic | C27: =SFP!B12 -> 924989000 | D27: =SFP!C12 -> 5.6111111e+08 | E27: =SFP!D12 -> 5.6112011e+08 | F27: =SFP!E12 -> 5.6111911e+08 | G27: =SFP!F12 -> 5.6111811e+08 | H27: =SFP!G12 -> 5.6112111e+08 | I27: =SFP!H12 -> 5.6112011e+08 | J27: =SFP!I12 -> 5.6112211e+08 | ... AI27: =SFP!AH12 -> 5.4460263e+08
A28: 6.2 | B28: Equity Investments (at cost) | C28: =SFP!B13 -> 1037113000 | D28: =SFP!C13 -> 0 | E28: =SFP!D13 -> 0 | F28: =SFP!E13 -> 0 | G28: =SFP!F13 -> 0 | H28: =SFP!G13 -> 0 | I28: =SFP!H13 -> 0 | J28: =SFP!I13 -> 0 | ... AI28: =SFP!AH13 -> 0
A29: 6.3 | B29: Deposits in KUSCCO CFP | C29: =SFP!B11 -> 0 | D29: =SFP!C11 -> 16468881 | E29: =SFP!D11 -> 16468881 | F29: =SFP!E11 -> 16468881 | G29: =SFP!F11 -> 16468881 | H29: =SFP!G11 -> 16468881 | I29: =SFP!H11 -> 16468881 | J29: =SFP!I11 -> 16468881 | ... AI29: =SFP!AH11 -> 13675921
A31: 7 | B31: Net Loans & advances | C31: =C32-C33 -> 36473944000 | D31: =D32-D33 -> 3.3254628e+10 | E31: =E32-E33 -> 3.3387332e+10 | F31: =F32-F33 -> 3.3173428e+10 | G31: =G32-G33 -> 3.3316115e+10 | H31: =H32-H33 -> 3.3586804e+10 | I31: =I32-I33 -> 3.3621973e+10 | J31: =J32-J33 -> 3.3499803e+10 | ... AI31: =AI32-AI33 -> 4.1500832e+10
A32: 7.1 | B32: Gross Loans & advances | C32: =SFP!B15 -> 38804173000 | D32: =SFP!C15 -> 3.5584857e+10 | E32: =SFP!D15 -> 3.5717561e+10 | F32: =SFP!E15 -> 3.5639734e+10 | G32: =SFP!F15 -> 3.5782421e+10 | H32: =SFP!G15 -> 3.605311e+10 | I32: =SFP!H15 -> 3.6224357e+10 | J32: =SFP!I15 -> 3.6102187e+10 | ... AI32: =SFP!AH15 -> 4.6508103e+10
A33: 7.3 | B33: Allowance for loan losses | C33: =SFP!B16 -> 2330229000 | D33: =SFP!C16 -> 2330229000 | E33: =SFP!D16 -> 2330229000 | F33: =SFP!E16 -> 2466306500 | G33: =SFP!F16 -> 2466306500 | H33: =SFP!G16 -> 2466306500 | I33: =SFP!H16 -> 2602384000 | J33: =SFP!I16 -> 2602384000 | ... AI33: =SFP!AH16 -> 5007270624
A34: 7.4 | B34: Non Performing Loans | C34: =(#REF!+#REF!+#REF!) -> #REF! | D34: =(#REF!+#REF!+#REF!) -> #REF! | E34: =(#REF!+#REF!+#REF!) -> #REF! | F34: =(#REF!+#REF!+#REF!) -> #REF! | G34: =(#REF!+#REF!+#REF!) -> #REF! | H34: =(#REF!+#REF!+#REF!) -> #REF! | I34: =(#REF!+#REF!+#REF!) -> #REF! | J34: =(#REF!+#REF!+#REF!) -> #REF! | ... AI34: =(#REF!+#REF!+#REF!) -> #REF!
A35: 7.5 | B35: Required loan loss provision | C35: =#REF! -> #REF! | D35: =#REF! -> #REF! | E35: =#REF! -> #REF! | F35: =#REF! -> #REF! | G35: =#REF! -> #REF! | H35: =#REF! -> #REF! | I35: =#REF! -> #REF! | J35: =#REF! -> #REF! | ... AI35: =#REF! -> #REF!
A36: 7.6 | B36: Cash and Cash equipments | C36: =SFP!B4 -> 5106415000 | D36: =SFP!C4 -> 5.2753289e+09 | E36: =SFP!D4 -> 5.3809033e+09 | F36: =SFP!E4 -> 5.1325082e+09 | G36: =SFP!F4 -> 4.7992793e+09 | H36: =SFP!G4 -> 4.9594368e+09 | I36: =SFP!H4 -> 5219430959 | J36: =SFP!I4 -> 5.4751356e+09 | ... AI36: =SFP!AH4 -> 6.4414204e+09
A38: 8 | B38: Non-Earning Assets | C38: =SFP!B7+SFP!B17+SFP!B23+SFP!B24+SFP!B25+SFP!B26 -> 2167040000 | D38: =SFP!C7+SFP!C17+SFP!C23+SFP!C24+SFP!C25+SFP!C26 -> 1.4665485e+09 | E38: =SFP!D7+SFP!D17+SFP!D23+SFP!D24+SFP!D25+SFP!D26 -> 1.7105631e+09 | F38: =SFP!E7+SFP!E17+SFP!E23+SFP!E24+SFP!E25+SFP!E26 -> 1.3611685e+09 | G38: =SFP!F7+SFP!F17+SFP!F23+SFP!F24+SFP!F25+SFP!F26 -> 1.674828e+09 | H38: =SFP!G7+SFP!G17+SFP!G23+SFP!G24+SFP!G25+SFP!G26 -> 1.6667123e+09 | I38: =SFP!H7+SFP!H17+SFP!H23+SFP!H24+SFP!H25+SFP!H26 -> 1725227976 | J38: =SFP!I7+SFP!I17+SFP!I23+SFP!I24+SFP!I25+SFP!I26 -> 1.9551825e+09 | ... AI38: =SFP!AH7+SFP!AH17+SFP!AH23+SFP!AH24+SFP!AH25+SFP!AH26 -> 2.6479928e+09
A39: 8.1 | B39: Property and Equipment | C39: =SFP!B23 -> 223605000 | D39: =SFP!C23 -> 2.2858026e+08 | E39: =SFP!D23 -> 2.2821963e+08 | F39: =SFP!E23 -> 2.2802949e+08 | G39: =SFP!F23 -> 2.2662719e+08 | H39: =SFP!G23 -> 2.2416648e+08 | I39: =SFP!H23 -> 2.2248861e+08 | J39: =SFP!I23 -> 2.2104414e+08 | ... AI39: =SFP!AH23 -> 4.4270872e+08
A41: 9 | B41: Turnover | C41: =C42+C43+C44 -> 1199445000 | D41: =D42+D43+D44 -> 1.2079182e+09 | E41: =E42+E43+E44 -> 1.1994453e+09 | F41: =F42+F43+F44 -> 1.1994453e+09 | G41: =G42+G43+G44 -> 1.1994453e+09 | H41: =H42+H43+H44 -> 1.1994453e+09 | I41: =I42+I43+I44 -> 1.1994453e+09 | J41: =J42+J43+J44 -> 1.1994453e+09 | ... AI41: =AI42+AI43+AI44 -> 1.6984598e+09
A42: 9.1 | B42: Loan Interest | C42: =SFP!B50 -> 1188896000 | D42: =SFP!C50 -> 1.184895e+09 | E42: =SFP!D50 -> 1.1764222e+09 | F42: =SFP!E50 -> 1.1764222e+09 | G42: =SFP!F50 -> 1.1764222e+09 | H42: =SFP!G50 -> 1.1764222e+09 | I42: =SFP!H50 -> 1.1764222e+09 | J42: =SFP!I50 -> 1.1764222e+09 | ... AI42: =SFP!AH50 -> 1.6577788e+09
B43: Income from investments | C43: =SFP!B51 -> 0 | D43: =SFP!C51 -> 12474413 | E43: =SFP!D51 -> 12474413 | F43: =SFP!E51 -> 12474413 | G43: =SFP!F51 -> 12474413 | H43: =SFP!G51 -> 12474413 | I43: =SFP!H51 -> 12474413 | J43: =SFP!I51 -> 12474413 | ... AI43: =SFP!AH51 -> 12474413
A44: 9.2 | B44: Fees & Commissions | C44: =SFP!B52 -> 10549000 | D44: =SFP!C52 -> 10548735 | E44: =SFP!D52 -> 10548735 | F44: =SFP!E52 -> 10548735 | G44: =SFP!F52 -> 10548735 | H44: =SFP!G52 -> 10548735 | I44: =SFP!H52 -> 10548735 | J44: =SFP!I52 -> 10548735 | ... AI44: =SFP!AH52 -> 28206616
B45: Average yield on loans
A47: 10 | B47: Total Expenses (FinCosts + OpEx) | C47: =SUM(C48:C53) -> 3620405000 | D47: =SUM(D48:D53) -> 0 | E47: =SUM(E48:E53) -> 0 | F47: =SUM(F48:F53) -> 0 | G47: =SUM(G48:G53) -> 0 | H47: =SUM(H48:H53) -> 0 | I47: =SUM(I48:I53) -> 0 | J47: =SUM(J48:J53) -> 0 | ... AI47: =SUM(AI48:AI53) -> 2.3185099e+09
A48: 10.1 | B48: Financial Exp. (Interest on deposits) | C48: =SCI!B13 -> 2826735000 | D48: =SCI!C13 -> 0 | E48: =SCI!D13 -> 0 | F48: =SCI!E13 -> 0 | G48: =SCI!F13 -> 0 | H48: =SCI!G13 -> 0 | I48: =SCI!H13 -> 0 | J48: =SCI!I13 -> 0 | ... AI48: =SCI!AH13 -> 1.8222013e+08
A49: 10.2 | B49: Financial Exp. (Dividends) | C49: =SCI!B15 -> 0 | D49: =SCI!C15 -> 0 | E49: =SCI!D15 -> 0 | F49: =SCI!E15 -> 0 | G49: =SCI!F15 -> 0 | H49: =SCI!G15 -> 0 | I49: =SCI!H15 -> 0 | J49: =SCI!I15 -> 0 | ... AI49: =SCI!AH15 -> 1.6955508e+09
...

Sheet form4
D3: RISK CLASSIFICATION OF ASSETS AND PROVISIONING | L3: RISK CLASSIFICATION OF ASSETS AND PROVISIONING
D4: SACCO SOCIETY CS NUMBER | L4: SACCO SOCIETY CS NUMBER
D5: FINANCIAL YEAR | L5: FINANCIAL YEAR
D6: START DATE: | L6: START DATE:
D7: END DATE: | L7: END DATE:
D8: PORTFOLIO AGEING REPORT | L8: PORTFOLIO AGEING REPORT
E9: A | F9: B | G9: C | H9: D | M9: A | N9: B | O9: C | P9: D
C10: NO. | D10: CLASSIFICATION | E10: NO. OF A/Cs | F10: OUTSTANDING LOAN PORTFOLIO(Kshs) | G10: REQUIRED PROVISION | H10: REQUIRED PROVISION AMOUNT(Kshs) | K10: NO. | L10: CLASSIFICATION | M10: NO. OF A/Cs | N10: OUTSTANDING LOAN PORTFOLIO(Kshs) | O10: REQUIRED PROVISION | P10: REQUIRED PROVISION AMOUNT(Kshs)
C11: 1 | D11: Performing | K11: 1 | L11: Performing
C12: 2 | D12: Watch | K12: 2 | L12: Watch
C13: 3 | D13: Substandard | K13: 3 | L13: Substandard
C14: 4 | D14: Doubtful | K14: 4 | L14: Doubtful
C15: 5 | D15: Loss | K15: 5 | L15: Loss
D16: subtotal | L16: subtotal | M16: =SUM(M11:M15) -> 0 | N16: =SUM(N11:N15) -> 0 | P16: =SUM(P11:P15) -> 0
D17: Reschedule/Renegotiated loans | L17: Reschedule/Renegotiated loans
C18: 1 | D18: Performing | K18: 1 | L18: Performing | M18: 0 | N18: 0 | O18: 0.01 | P18: =N18*O18 -> 0
C19: 2 | D19: Watch | K19: 2 | L19: Watch | M19: 0 | N19: 0 | O19: 0.05 | P19: =N19*O19 -> 0
C20: 3 | D20: Substandard | K20: 3 | L20: Substandard | M20: 0 | N20: 0 | O20: 0.25 | P20: =N20*O20 -> 0
C21: 4 | D21: Doubtful | K21: 4 | L21: Doubtful | M21: 0 | N21: 0 | O21: 0.5 | P21: =N21*O21 -> 0
C22: 5 | D22: Loss | K22: 5 | L22: Loss | M22: 0 | N22: 0 | O22: 1 | P22: =N22*O22 -> 0
D23: subtotal | E23: =SUM(E17:E22) -> 0 | F23: =SUM(F17:F22) -> 0 | H23: =SUM(H17:H22) -> 0 | L23: subtotal | M23: =SUM(M17:M22) -> 0 | N23: =SUM(N17:N22) -> 0 | P23: =SUM(P17:P22) -> 0
D24: GRAND TOTAL | E24: =E16+E23 -> 0 | F24: =F16+F23 -> 0 | H24: =H16+H23 -> 0 | L24: GRAND TOTAL | M24: =M16+M23 -> 0 | N24: =N16+N23 -> 0 | P24: =P16+P23 -> 0
F26: =F13+F14+F15 -> 0 | N26: =N13+N14+N15 -> 0
F27: =F26/F24 -> #DIV/0! | N27: =N26/N24 -> #DIV/0!
D30: RISK CLASSIFICATION OF ASSETS AND PROVISIONING
D31: SACCO SOCIETY CS NUMBER
D32: FINANCIAL YEAR
D33: START DATE:
D34: END DATE:
D35: PORTFOLIO AGEING REPORT
E36: A | F36: B | G36: C | H36: D
C37: NO. | D37: CLASSIFICATION | E37: NO. OF A/Cs | F37: OUTSTANDING LOAN PORTFOLIO(Kshs) | G37: REQUIRED PROVISION | H37: REQUIRED PROVISION AMOUNT(Kshs)
C38: 1 | D38: Performing
C39: 2 | D39: Watch
C40: 3 | D40: Substandard
C41: 4 | D41: Doubtful
C42: 5 | D42: Loss
D43: subtotal
D44: Reschedule/Renegotiated loans
C45: 1 | D45: Performing | H45: =F45*G45 -> 0
...

Sheet SFP
A1: STIMA SACCO SOCIETY LTD
A2: STATEMENT OF FINANCIAL POSITION
B3: AUDITED 2020 | C3: 44197 | D3: 44228 | E3: 44256 | F3: 44287 | G3: 44317 | H3: 44348 | I3: 44378 | J3: 44409 | K3: 44440 | L3: 44470 | M3: 44501 | N3: 44531 | O3: AUDITED 2021 | P3: 44562 | Q3: 44593 | R3: 44621 | S3: 44652 | T3: 44682 | U3: 44713 | V3: 44743 | W3: 44774 | X3: 44805 | Y3: 44835 | Z3: 44866 | AA3: 44896 | AB3: Audited -22 | AC3: 44949 | AD3: 44980 | AE3: 45008 | AF3: 45039 | AG3: 45069 | AH3: 45100
A4: Cash & Cash Equivalent | B4: =SUM(B5:B6) -> 5106415000 | C4: =SUM(C5:C6) -> 5.2753289e+09 | D4: =SUM(D5:D6) -> 5.3809033e+09 | E4: =SUM(E5:E6) -> 5.1325082e+09 | F4: =SUM(F5:F6) -> 4.7992793e+09 | G4: =SUM(G5:G6) -> 4.9594368e+09 | H4: =SUM(H5:H6) -> 5219430959 | I4: =SUM(I5:I6) -> 5.4751356e+09 | ... AH4: =SUM(AH5:AH6) -> 6.4414204e+09
A5: Cash in hand | B5: 115892000 | C5: 1.2857947e+08 | D5: 1.4539753e+08 | E5: 1.0764315e+08 | F5: 1.2684321e+08 | G5: 1.2715288e+08 | H5: 1.2741211e+08 | I5: 1.290845e+08 | J5: 1.1183393e+08 | K5: 1.2843841e+08 | L5: 92938974 | M5: 1.2180419e+08 | N5: 1.1512263e+08 | O5: 115123000 | P5: 1.2455236e+08 | Q5: 1.3098178e+08 | R5: 99421740 | S5: 1.2105228e+08 | T5: 1.3777943e+08 | U5: 1.5470299e+08 | V5: 1.0156356e+08 | W5: 1.1877878e+08 | X5: 1.1681214e+08 | Y5: 1.1187792e+08 | Z5: 1.2039432e+08 | AA5: 1.0461845e+08 | AB5: 104618000 | AC5: 1.0521098e+08 | AD5: 69241337 | AE5: 1.5946773e+08 | AF5: 33049673 | AG5: 1.0279947e+08 | AH5: 1.0152892e+08
A6: Cash at bank | B6: =5106415000-115892000 -> 4990523000 | C6: 5.1467494e+09 | D6: 5.2355058e+09 | E6: 5.024865e+09 | F6: 4.6724361e+09 | G6: 4.8322839e+09 | H6: 5.0920188e+09 | I6: 5.3460511e+09 | J6: 5.9806698e+09 | K6: 5.7526138e+09 | L6: 5.0572624e+09 | M6: 5.1602138e+09 | N6: 4.9851885e+09 | O6: =5248820000-115123000 -> 5133697000 | P6: 5.4495063e+09 | Q6: 5.484205e+09 | R6: 5.0250617e+09 | S6: 5.1299777e+09 | T6: 4.7500073e+09 | U6: 5.2939674e+09 | V6: 5.5052828e+09 | W6: 5.4253844e+09 | X6: 5.8645242e+09 | Y6: 6.2292458e+09 | Z6: 6.5652845e+09 | AA6: 6.8228885e+09 | AB6: =94752000+588343000+10715000+8254000+2203000+588000-83000 -> 704772000 | AC6: 6.2410809e+09 | AD6: 7.2221189e+09 | AE6: 5.8632351e+09 | AF6: 5.5734798e+09 | AG6: 6.3907114e+09 | AH6: 6.3398915e+09
A7: Prepayments & Sundry Receivables | B7: 1156972000 | C7: 1.0200832e+09 | D7: 1.2543818e+09 | E7: 9.1428282e+08 | F7: 1.2226418e+09 | G7: 1.2262497e+09 | H7: 1.1420761e+09 | I7: 1.2819257e+09 | J7: 1.2483361e+09 | K7: 1.2901823e+09 | L7: 1.4158393e+09 | M7: 1.4645113e+09 | N7: 1.4535664e+09 | O7: 1377736000 | P7: 1.5514241e+09 | Q7: 1.7013963e+09 | R7: 1.5219573e+09 | S7: 1.6257412e+09 | T7: 1.6863316e+09 | U7: 1.6144922e+09 | V7: 1.6497037e+09 | W7: 1.6645516e+09 | X7: 1.6258434e+09 | Y7: 1853990948 | Z7: 1.807304e+09 | AA7: 1.7059784e+09 | AB7: 1036206000 | AC7: 1.9178279e+09 | AD7: 1.7504475e+09 | AE7: 1.3604844e+09 | AF7: 1.3109253e+09 | AG7: 1.0200696e+09 | AH7: 1.685916e+09
A8: Financial Investments | B8: =SUM(B9:B13) -> 1962102000 | C8: =SUM(C9:C13) -> 9.8105109e+08 | D8: =SUM(D9:D13) -> 9.8597887e+08 | E8: =SUM(E9:E13) -> 9.8862547e+08 | F8: =SUM(F9:F13) -> 1.2356702e+09 | G8: =SUM(G9:G13) -> 1.2410103e+09 | H8: =SUM(H9:H13) -> 1.3590054e+09 | I8: =SUM(I9:I13) -> 1.3623358e+09 | ... AH8: =SUM(AH9:AH13) -> 3.2149851e+09
A9: Government Securities - Treasury Bills/bonds, | C9: 0 | D9: 0 | E9: 0 | F9: 303108000 | G9: 303108000 | H9: 3.48308e+08 | I9: 3.48308e+08 | J9: 3.48308e+08 | K9: 5.2506809e+08 | L9: 1.0615231e+09 | M9: 1.0171573e+09 | N9: 1.0263505e+09 | O9: 1003586000 | P9: 1.003586e+09 | Q9: 1.0097287e+09 | R9: 1.0129561e+09 | S9: 9.9713107e+08 | T9: 1.4968042e+09 | U9: 1.5071375e+09 | V9: 1.5178153e+09 | W9: 2.0534723e+09 | X9: 2.0638056e+09 | Y9: 2.0289286e+09 | Z9: 2.0058347e+09 | AA9: 2.0458448e+09 | AB9: 1967562000 | AC9: 2.0671796e+09 | AD9: 2.0081672e+09 | AE9: 2.0295021e+09 | AF9: 1.9686331e+09 | AG9: 1.9486215e+09 | AH9: 1.9692668e+09
A10: Other Securities - Commercial papers/Bonds | C10: 4.034711e+08 | D10: 4.0838988e+08 | E10: 4.1103748e+08 | F10: 3.5497523e+08 | G10: 3.6031231e+08 | H10: 4.3310845e+08 | I10: 4.364368e+08 | J10: 4.3968587e+08 | K10: 4.8802929e+08 | L10: 4.9130687e+08 | M10: 4.9454073e+08 | N10: 4.980682e+08 | P10: 5.0149874e+08 | Q10: 5.0429854e+08 | R10: 5.0809669e+08 | S10: 5.1183239e+08 | T10: 6.1601819e+08 | U10: 6.1800901e+08 | V10: 6.2564911e+08 | W10: 6.2734547e+08 | X10: 6.5193995e+08 | Y10: 6.5672389e+08 | Z10: 6.6139289e+08 | AA10: 6.6613926e+08 | AB10: 45462000 | AC10: 6.6656346e+08 | AD10: 6.743477e+08 | AE10: 6.7925418e+08 | AF10: 6.844069e+08 | AG10: 6.896248e+08 | AH10: 6.8743978e+08
A11: Balances in NACCOS (E.g Jungu Kuu, ESS, Savings,Money Market,Coop FD, CFP) | C11: 16468881 | D11: 16468881 | E11: 16468881 | F11: 16468881 | G11: 16468881 | H11: 16468881 | I11: 16468881 | J11: 16468881 | K11: 16468881 | L11: 16468881 | M11: 16468881 | N11: 16468881 | O11: 10000 | P11: 12702354 | Q11: 12702354 | R11: 12702354 | S11: 12702354 | T11: 12702354 | U11: 12702354 | V11: 12702354 | W11: 12702354 | X11: 12702354 | Y11: 12702354 | Z11: 12702354 | AA11: 13675921 | AB11: 6085171000 | AC11: 13675921 | AD11: 13675921 | AE11: 13675921 | AF11: 13675921 | AG11: 13675921 | AH11: 13675921
A12: Equity Investments in NACCOs(Shares in- CIC, KUSCCO, COOP BANK,CAK, KERUSSU) | B12: =577580000+347409000 -> 924989000 | C12: 5.6111111e+08 | D12: 5.6112011e+08 | E12: 5.6111911e+08 | F12: 5.6111811e+08 | G12: 5.6112111e+08 | H12: 5.6112011e+08 | I12: 5.6112211e+08 | J12: 5.6112311e+08 | K12: 5.6112311e+08 | L12: 5.6112311e+08 | M12: 5.6112111e+08 | N12: 5.7999758e+08 | O12: =589890000+452762000 -> 1042652000 | AB12: =453035000+13676000+20000000+91568000+599452000 -> 1177731000 | AC12: 5.4460263e+08 | AD12: 5.4460263e+08 | AE12: 5.4460263e+08 | AF12: 5.4460263e+08 | AG12: 5.4460263e+08 | AH12: 5.4460263e+08
A13: Equity Investments in companies - shares/stocks | B13: =56062000+981051000 -> 1037113000 | O13: =44302000+1086954000 -> 1131256000 | P13: 5.7719795e+08 | Q13: 5.7719795e+08 | R13: 5.7719695e+08 | S13: 5.7719645e+08 | T13: 5.7719595e+08 | U13: 5.7719895e+08 | V13: 5.7719495e+08 | W13: 5.7719795e+08 | X13: 5.5718795e+08 | Y13: 5.5718595e+08 | Z13: 5.5718295e+08 | AA13: 5.4460363e+08
A14: Net Loan Portfolio | B14: 32798794000 | C14: =C15-C16 -> 3.3254628e+10 | D14: =D15-D16 -> 3.3387332e+10 | E14: =E15-E16 -> 3.3173428e+10 | F14: =F15-F16 -> 3.3316115e+10 | G14: =G15-G16 -> 3.3586804e+10 | H14: =H15-H16 -> 3.3621973e+10 | I14: =I15-I16 -> 3.3499803e+10 | J14: =J15-J16 -> 3.3767411e+10 | ... AH14: =AH15-AH16 -> 4.1500832e+10
A15: Gross Loan Portfolio | B15: 38804173000 | C15: 3.5584857e+10 | D15: 3.5717561e+10 | E15: 3.5639734e+10 | F15: 3.5782421e+10 | G15: 3.605311e+10 | H15: 3.6224357e+10 | I15: 3.6102187e+10 | J15: 3.6369795e+10 | K15: 3.7405147e+10 | L15: 3.822606e+10 | M15: 3.8822364e+10 | N15: 3.9378377e+10 | O15: 39378377000 | P15: 3.9737589e+10 | Q15: 3.9729955e+10 | R15: 4.0167638e+10 | S15: 4.0630238e+10 | T15: 4.1039026e+10 | U15: 4.1295258e+10 | V15: 4.1720723e+10 | W15: 4.2008374e+10 | X15: 4.2449225e+10 | Y15: 4.317657e+10 | Z15: 4.3801547e+10 | AA15: 4.4495267e+10 | AB15: 45074284000 | AC15: 4.5587899e+10 | AD15: 4.5807592e+10 | AE15: 4.5927722e+10 | AF15: 4.6366126e+10 | AG15: 4.6318317e+10 | AH15: 4.6508103e+10
A16: Allowance for Loan Loss | B16: 2330229000 | C16: 2330229000 | D16: 2330229000 | E16: 2466306500 | F16: 2466306500 | G16: 2466306500 | H16: 2602384000 | I16: 2602384000 | J16: 2602384000 | K16: 2602384000 | L16: 2602384000 | M16: 2602384000 | N16: 2602384000 | O16: 3026922000 | P16: 3.026922e+09 | Q16: 3.026922e+09 | R16: 3.026922e+09 | S16: 2.776922e+09 | T16: 2.776922e+09 | U16: 3.069077e+09 | V16: 3.069077e+09 | W16: 3.069077e+09 | X16: 3.069077e+09 | Y16: 3314707132 | Z16: 3314707132 | AA16: 3314707132 | AB16: 3757306000 | AC16: 3721489293 | AD16: 3757306340 | AE16: 4505020512 | AF16: 4505020512 | AG16: 4505020512 | AH16: 5007270624
A17: Accounts Receivables | B17: =SUM(B18:B20) -> 56052000 | C17: =SUM(C18:C20) -> 0 | D17: =SUM(D18:D20) -> 0 | E17: =SUM(E18:E20) -> 0 | F17: =SUM(F18:F20) -> 0 | G17: =SUM(G18:G20) -> 0 | H17: =SUM(H18:H20) -> 0 | I17: =SUM(I18:I20) -> 0 | ... AH17: =SUM(AH18:AH20) -> 1.1614682e+08
A18: Tax Recoverable | C18: 0 | D18: 0 | E18: 0 | F18: 0 | G18: 0 | H18: 0 | I18: 0 | J18: 0 | K18: 0 | L18: 0 | M18: 0 | N18: 0 | O18: 5768000 | P18: 0 | Q18: 0 | R18: 0 | S18: 0 | T18: 0 | U18: 0 | V18: 0 | W18: 0 | X18: 0 | Y18: 0 | Z18: 0 | AA18: 0 | AB18: 4393000 | AC18: 0 | AD18: 19393041 | AE18: 19393041 | AF18: 40561795 | AG18: 40561795 | AH18: 67662224
A19: Deferred Tax Assets | B19: 56052000 | C19: 0 | D19: 0 | E19: 0 | F19: 0 | G19: 0 | H19: 0 | I19: 0 | J19: 0 | K19: 0 | L19: 0 | M19: 0 | N19: 0 | O19: 50390000 | P19: 0 | Q19: 0 | R19: 0 | S19: 0 | T19: 0 | U19: 0 | V19: 0 | W19: 0 | X19: 0 | Y19: 0 | Z19: 0 | AA19: 0 | AB19: 48485000 | AC19: 0 | AD19: 48484600 | AE19: 48484600 | AF19: 48484600 | AG19: 48484600 | AH19: 48484600
A20: Retirement Benefit Assets | C20: 0 | D20: 0 | E20: 0 | F20: 0 | G20: 0 | H20: 0 | I20: 0 | J20: 0 | K20: 0 | L20: 0 | M20: 0 | N20: 0 | P20: 0 | Q20: 0 | R20: 0 | S20: 0 | T20: 0 | U20: 0 | V20: 0 | W20: 0 | X20: 0 | Y20: 0 | Z20: 0 | AA20: 0 | AC20: 0 | AD20: 0 | AE20: 0 | AF20: 0 | AG20: 0 | AH20: 0
A21: Property & Equipment & Other assets | B21: =SUM(B22:B26) -> 954016000 | C21: =SUM(C22:C26) -> 9.3366748e+08 | D21: =SUM(D22:D26) -> 9.4338353e+08 | E21: =SUM(E22:E26) -> 9.3408781e+08 | F21: =SUM(F22:F26) -> 9.3938837e+08 | G21: =SUM(G22:G26) -> 9.2766476e+08 | H21: =SUM(H22:H26) -> 1.070354e+09 | I21: =SUM(I22:I26) -> 1.161329e+09 | ... AH21: =SUM(AH22:AH26) -> 1.3362687e+09
