Workbook

Sheet Evolutive SFP
B3: audited-18 | C3: audited-19 | D3: audited-20 | E3: Audited 2021 | F3: 44562 | G3: 44593 | H3: 44621 | I3: 44652 | J3: 44682 | K3: 44713 | L3: 44743 | M3: 44774 | N3: 44805 | O3: 44835 | P3: 44866 | Q3: 44896 | R3: Audited 2022 | S3: 44927 | T3: 44958 | U3: 44986 | V3: 45017
A4: Cash & cash Equivalent | B4: =SUM(B5:B6) -> 5868125.8 | C4: =SUM(C5:C6) -> 1234979 | D4: =SUM(D5:D6) -> 1043286 | E4: =SUM(E5:E6) -> 30124363 | F4: =SUM(F5:F6) -> 40657637 | G4: =SUM(G5:G6) -> 46805516 | H4: =SUM(H5:H6) -> 47044839 | I4: =SUM(I5:I6) -> 3886065 | ... U4: =SUM(U5:U6) -> 0
A5: Cash In Hand | F5: 4283259 | G5: 5100800 | H5: 4039323 | I5: 3291760 | J5: 1367523 | K5: 1960209 | L5: 3836371 | M5: 3520515 | N5: 2558686 | O5: 4787981 | P5: 2713475 | Q5: 4330885 | R5: 4324245 | S5: 2851070 | T5: 3907656
A6: Cash at Bank | B6: 5868125.8 | C6: 1234979 | D6: 1043286 | E6: =26917487.4+5000+5315+12746+1703812+1480002.8 -> 30124363 | F6: 36374378 | G6: 41704716 | H6: 43005516 | I6: 594305 | J6: 9946872.1 | K6: 14546778 | L6: 8185316.2 | M6: 6196907.7 | N6: 5680378.3 | O6: 3726626.3 | P6: 10848331 | Q6: 11070322 | R6: =8471796.79+5000+5315+10826.24+219916+1807178.2 -> 10520032 | S6: 4346459.1 | T6: 10885370
A7: Prepayment and Sundry | B7: 8797645.2 | C7: 36925582 | D7: 37280987 | E7: 42014210 | F7: 37540861 | G7: 40064322 | H7: 42968831 | I7: 53782958 | J7: 55268956 | K7: 55585579 | L7: 57301540 | M7: 57289863 | N7: 42102580 | O7: 52670808 | P7: 50321655 | Q7: 44340046 | R7: 43538535 | S7: 46175743 | T7: 47181747
A8: Financial Investment | B8: =SUM(B9:B12) -> 10619076 | C8: =SUM(C9:C12) -> 10004941 | D8: =SUM(D9:D12) -> 33592821 | E8: =SUM(E9:E12) -> 7484698.8 | F8: =SUM(F9:F12) -> 7486115.8 | G8: =SUM(G9:G12) -> 7486115.8 | H8: =SUM(H9:H12) -> 7486115.8 | I8: =SUM(I9:I12) -> 27486116 | ... U8: =SUM(U9:U12) -> 0
A9: Government Security | F9: 0 | G9: 0 | H9: 0 | I9: 0 | J9: 0 | K9: 0 | L9: 0 | M9: 0 | N9: 0 | O9: 15749971 | P9: 20749971 | Q9: 28064116 | R9: 28064115 | S9: 28064116 | T9: 23064116
A10: Other Securities | F10: 188418.73 | G10: 188418.73 | H10: 188418.73 | I10: 10188419 | J10: 10188419 | K10: 10417298 | L10: 10417298 | M10: 10571038 | N10: 10646826 | O10: 0 | P10: 0 | Q10: 0 | R10: 0 | S10: 0 | T10: 0
A11: Balances with Other Saccos | B11: =10619075.54-B12 -> 10452546 | C11: =10004941-C12 -> 9838411 | D11: =33592821-D12 -> 33426291 | E11: =6403100+187001.83+727567 -> 7317668.8 | F11: 7130667 | G11: 7130667 | H11: 7130667 | I11: 17130667 | J11: 17130667 | K11: 17130667 | L11: 17130667 | M11: 17630667 | N11: 18089455 | O11: 18593034 | P11: 18871750 | Q11: 18871750 | R11: =1939339.13+17236748+10500 -> 19186587 | S11: 18871750 | T11: 18871750 | X11: =30496614-21102731 -> 9393883
A12: Investment In Companies | B12: =21530+10000+135000 -> 166530 | C12: =21530+10000+135000 -> 166530 | D12: =21530+10000+135000 -> 166530 | E12: =21530+135000+10500 -> 167030 | F12: 167030 | G12: 167030 | H12: 167030 | I12: 167030 | J12: 167030 | K12: 167030 | L12: 167030 | M12: 167030 | N12: 167030 | O12: 167030 | P12: 167030 | Q12: 167030 | R12: =135000+21530 -> 156530 | S12: 167030 | T12: 167030
A13: Net Loan Portfolio | B13: =B14-B15 -> 220553979 | C13: =C14-C15 -> 2.2629459e+08 | D13: =D14-D15 -> 227332655 | E13: =E14-E15 -> 2.6369074e+08 | F13: =F14-F15 -> 2.74068e+08 | G13: =G14-G15 -> 2.7474351e+08 | H13: =H14-H15 -> 2.6811788e+08 | I13: =I14-I15 -> 2.8904992e+08 | ... U13: =U14-U15 -> 0
A14: Gross Loan Portfolio | B14: =222853979 -> 222853979 | C14: =228694587.21 -> 2.2869459e+08 | D14: =231258250 -> 231258250 | E14: 2.7781358e+08 | F14: 2.7799359e+08 | G14: 2.786691e+08 | H14: 2.8224072e+08 | I14: 303172758 | J14: 3.0260043e+08 | K14: 2.9666988e+08 | L14: 3.055134e+08 | M14: 3.1574111e+08 | N14: 3.2873753e+08 | O14: 3.3157066e+08 | P14: 3.3697233e+08 | Q14: 3.2445441e+08 | R14: 3.1371334e+08 | S14: 3.2951874e+08 | T14: 3.294927e+08
A15: Allowance For Loan Loss | B15: 2300000 | C15: 2400000 | D15: 3925595 | E15: 14122841 | F15: 3925595 | G15: 3925595 | H15: 14122841 | I15: 14122841 | J15: 14122841 | K15: 14122841 | L15: 14122841 | M15: 14122841 | N15: 0 | O15: 0 | P15: 0 | Q15: 0 | R15: 17658284 | S15: 0 | T15: 0
A16: Accounts Recievables | B16: 0 | C16: 0 | D16: 0 | E16: 0 | F16: 0 | G16: 0 | H16: 0 | I16: 0 | J16: 0 | K16: 0 | L16: 0 | M16: 0 | N16: 0 | O16: 0 | P16: 0 | Q16: 0 | R16: 0 | S16: 0 | T16: 0 | U16: 0 | W16: =R15-'[1]note 8-10'!$C$38 -> 28189.86
A17: Tax Recoverable | F17: 0 | G17: 0 | H17: 0 | I17: 0 | J17: 0 | K17: 0 | L17: 0 | M17: 0 | N17: 0 | O17: 0 | P17: 0 | Q17: 0 | S17: 0 | T17: 0
A18: Deffered Tax Assets | F18: 0 | G18: 0 | H18: 0 | I18: 0 | J18: 0 | K18: 0 | L18: 0 | M18: 0 | N18: 0 | O18: 0 | P18: 0 | Q18: 0 | S18: 0 | T18: 0
A19: Retirement Benefit Assets | F19: 0 | G19: 0 | H19: 0 | I19: 0 | J19: 0 | K19: 0 | L19: 0 | M19: 0 | N19: 0 | O19: 0 | P19: 0 | Q19: 0 | S19: 0 | T19: 0
A20: Property&Equipments&Other Assets | B20: =SUM(B21:B25) -> 20493086 | C20: =SUM(C21:C25) -> 20920446 | D20: =SUM(D21:D25) -> 22397895 | E20: =SUM(E21:E25) -> 20974222 | F20: =SUM(F21:F25) -> 24340509 | G20: =SUM(G21:G25) -> 24518502 | H20: =SUM(H21:H25) -> 23189546 | I20: =SUM(I21:I25) -> 23200829 | ... V20: =SUM(V21:V25) -> 0
A21: Investment Properties | F21: 0 | G21: 0 | H21: 0 | I21: 0 | J21: 0 | K21: 0 | L21: 0 | M21: 0 | N21: 0 | O21: 0 | P21: 0 | Q21: 0 | R21: 14460283 | S21: 0 | T21: 0
A22: Property and Equipment | B22: 20215736 | C22: 20219796 | D22: 21989873 | E22: =22597281-1651234 -> 20946047 | F22: 23433592 | G22: 23681922 | H22: 22159563 | I22: 22168563 | J22: 22458563 | K22: 22458563 | L22: 22458563 | M22: 22460563 | N22: 20241805 | O22: 20320805 | P22: 20320805 | Q22: 19350630 | R22: =610233+504374+634195+696102 -> 2444904 | S22: 19350630 | T22: 19350630
A23: Prepaid Lease Rentals | F23: 0 | G23: 0 | H23: 0 | I23: 0 | J23: 0 | K23: 0 | L23: 0 | M23: 0 | N23: 0 | O23: 0 | P23: 438379 | Q23: 438379 | S23: 438379 | T23: 438379
A24: Intangible Assets | F24: 0 | G24: 0 | H24: 0 | I24: 0 | J24: 0 | K24: 0 | L24: 0 | M24: 0 | N24: 2218757.7 | O24: 2218757.7 | P24: 2218757.7 | Q24: 1775005.7 | R24: =2422538+1775006 -> 4197544 | S24: 0 | T24: 0
A25: Other Assets | B25: 277350 | C25: 700650 | D25: 408022 | E25: =28175.18 -> 28175.18 | F25: 906916.59 | G25: 836580.09 | H25: 1029983.1 | I25: 1032266.2 | J25: 1107618.1 | K25: 940428.15 | L25: 1007999.2 | M25: 948951.15 | N25: 438379 | O25: 725397.15 | P25: 779887.15 | Q25: 794104.15 | R25: =66130.18 -> 66130.18 | S25: 2640921 | T25: 907020.15 | U25: =5700000/N26 -> 0.013228697 | W25: =423042153.88-R26 -> 28190.81
A26: Total Assets | B26: =B20+B16+B13+B8+B7+B4 -> 2.6633191e+08 | C26: =C20+C16+C13+C8+C7+C4 -> 2.9538054e+08 | D26: =D20+D16+D13+D8+D7+D4 -> 321647644 | E26: =E20+E16+E13+E8+E7+E4 -> 3.6428823e+08 | F26: =F20+F16+F13+F8+F7+F4 -> 3.8409312e+08 | G26: =G20+G16+G13+G8+G7+G4 -> 3.9361796e+08 | H26: =H20+H16+H13+H8+H7+H4 -> 3.8880721e+08 | I26: =I20+I16+I13+I8+I7+I4 -> 3.9740588e+08 | ... V26: =V20+V16+V13+V8+V7+V4 -> 0 | X26: 4.320145e+08
A27: Savings and Deposits | F27: 4366133.7 | G27: 5241591.4 | H27: 11405694 | I27: 13825248 | J27: 14757631 | K27: 8101147.2 | L27: 8562298.1 | M27: 11900390 | N27: 11455964 | O27: 10350409 | P27: 11083718 | Q27: 8088637.3 | R27: =7469086.85 -> 7469086.8 | S27: 10554910 | T27: 9793243.1 | X27: =X26-R26 -> 9000532.2
A28: Short Terrm Deposits | H28: 0 | I28: 0 | J28: 0 | K28: 0 | L28: 0 | M28: 0 | N28: 0 | O28: 0 | P28: 0 | Q28: 0 | S28: 0 | T28: 0
A29: Non Withdrawable Deposits | B29: =225331694.99+710517 -> 2.2604221e+08 | C29: =244550254.46+2435 -> 2.4455269e+08 | D29: =269114517 -> 269114517 | E29: 3.0763979e+08 | F29: 3.1156526e+08 | G29: 3.1813761e+08 | H29: 3.2220274e+08 | I29: 3.2538749e+08 | J29: 3.3059345e+08 | K29: 3.3152995e+08 | L29: 3.3508467e+08 | M29: 3.3712327e+08 | N29: 3.4364895e+08 | O29: 3.4816879e+08 | P29: 351981501 | Q29: 3.4422279e+08 | R29: 3.4092468e+08 | S29: 3.4981492e+08 | T29: 3.5553041e+08
A30: Total Deposit Liabilities | B30: =B27+B29 -> 2.2604221e+08 | C30: =C27+C29 -> 2.4455269e+08 | D30: =D27+D29 -> 269114517 | E30: =E27+E29 -> 3.0763979e+08 | F30: =F27+F29 -> 3.1593139e+08 | G30: =G27+G29 -> 3.233792e+08 | H30: =H27+H29 -> 3.3360844e+08 | I30: =I27+I29 -> 3.3921273e+08 | ... V30: =V27+V29 -> 0
A31: Tax Payable | E31: 367892 | F31: 973207.76 | G31: 1002357.3 | H31: 842144.36 | I31: 902359.56 | J31: 961903.72 | K31: 906271.64 | L31: 1024261.1 | M31: 1017308.2 | N31: 725368.84 | O31: 269494.34 | P31: 313413.18 | Q31: 413222.52 | S31: 493721.81 | T31: 229287.18 | X31: 3.4092468e+08
A32: Dividends Payable | B32: 7794707 | C32: 11716152 | D32: 3533393 | E32: 145186 | F32: 0 | G32: 0 | H32: 0 | I32: 0 | J32: 0 | K32: 0 | L32: 0 | M32: 0 | N32: 0 | O32: 0 | P32: 0 | Q32: 0 | S32: 0 | T32: 0 | U32: =U30/N26 -> 0 | X32: 14113778
A33: Deferred Tax Liability | F33: 0 | G33: 0 | H33: 0 | I33: 0 | J33: 0 | K33: 0 | L33: 0 | M33: 0 | N33: 0 | O33: 0 | P33: 0 | Q33: 0 | S33: 0 | T33: 0 | X33: 14000000
A34: Retirement Benefits Liabilty | F34: 0 | G34: 0 | H34: 0 | I34: 0 | J34: 0 | K34: 0 | L34: 0 | M34: 0 | N34: 0 | O34: 0 | P34: 0 | Q34: 0 | S34: 0 | T34: 0 | X34: 2539742.8
A35: Other Liabilities | B35: 2185052.4 | C35: 3492826 | D35: 3604098 | E35: =3909715.31-E32-E31+434478.8+4614596.91 -> 8445713 | F35: 1536334.5 | G35: 1767026 | H35: 1059065.5 | I35: 783149 | J35: 831369.5 | K35: 1085500 | L35: 1761345.5 | M35: 1495522.5 | N35: 1644735 | O35: 4083198.6 | P35: 9851371.6 | Q35: 11724782 | R35: =2197283.92+10500000+2539742.8+380742.28 -> 15617769 | S35: 2386521.1 | T35: 1604797.6 | X35: 380742.28
A36: External Borrowings | F36: 0 | G36: 0 | H36: 0 | I36: 0 | J36: 0 | K36: 0 | L36: 0 | M36: 0 | N36: 0 | O36: 0 | P36: 0 | Q36: 0 | S36: 0 | T36: 0 | X36: 5437632.1
A37: Total Liabilities | B37: =SUM(B30:B36) -> 2.3602197e+08 | C37: =SUM(C30:C36) -> 2.5976167e+08 | D37: =SUM(D30:D36) -> 276252008 | E37: =SUM(E30:E36) -> 3.1659859e+08 | F37: =SUM(F30:F36) -> 3.1844094e+08 | G37: =SUM(G30:G36) -> 3.2614858e+08 | H37: =SUM(H30:H36) -> 3.3550965e+08 | I37: =SUM(I30:I36) -> 3.4089824e+08 | ... V37: =SUM(V30:V36) -> 0 | W37: =367511532.48-R37 -> 3500000
A38: Share Capital | B38: =28963365 -> 28963365 | C38: =34068869 -> 34068869 | D38: =39441838 -> 39441838 | E38: 45111736 | F38: 45593393 | G38: 46116606 | H38: 46606748 | I38: 47039143 | J38: 47462665 | K38: 47835352 | L38: 48255445 | M38: 48611567 | N38: 49059693 | O38: 49492753 | P38: 49908726 | Q38: 50319795 | R38: 50296794 | S38: 50626600 | T38: 50998897 | W38: =W37-R37 -> -3.6051153e+08 | Y38: =41797996.21/R48 -> 0.098809968
A39: Capital Grants | F39: 0 | G39: 0 | H39: 0 | I39: 0 | J39: 0 | K39: 0 | L39: 0 | M39: 0 | N39: 0 | O39: 0 | P39: 0 | Q39: 0 | S39: 0 | T39: 0 | AD39: =3539923.32-912196.8-531183.11 -> 2096543.4
A40: Prior Year Retained Earnigs | B40: 439143.86 | C40: 463042.58 | D40: 528042 | E40: =4051080-6197245.84-466005.14-564272 -> -3176443 | F40: 4078143.6 | G40: 4078143.6 | H40: -2119102.2 | I40: -2119102.2 | J40: -2119102.2 | K40: -2119102.2 | L40: 4225455.2 | M40: 4225455.2 | N40: 4225455.2 | O40: 11059367 | P40: 11059367 | Q40: 11059367 | R40: 110923.02 | S40: 11059367 | T40: 11059367
A41: Current Year Surplus | B41: =408259.56-B40 -> -30884.3 | C41: =528042.32-C40 -> 64999.74 | D41: =4051081-D40 -> 3523039 | E41: 3287365.2 | F41: 13778517 | G41: 14640927 | H41: 4319042.5 | I41: 6355828.2 | J41: 8040737.8 | K41: 10935222 | L41: 7501341.9 | M41: 10231580 | N41: 13764878 | O41: 10517230 | P41: 13614444 | Q41: 11238248 | R41: =7039923.32-912196.8-1225545.3 -> 4902181.2 | S41: 10898970 | T41: 1695842.3
A42: Statutory Reserves | B42: 938315.3 | C42: 1021957 | D42: 1902716 | E42: 2466988 | F42: 1902716.7 | G42: 1902716.7 | H42: 2466988.7 | I42: 2466988.7 | J42: 2466988.7 | K42: 2466988.7 | L42: 2466988.7 | M42: 2466988.7 | N42: 2466988.7 | O42: 2466988.7 | P42: 2466988.7 | Q42: 2466988.7 | R42: 3692533.3 | S42: 2466988.7 | T42: 2466988.7
...

Sheet KPIs
B1: Item | C1: Audited 2021 | D1: 44805 | E1: Verified September 2022
B2: Membership: Active | C2: 5252 | D2: - | E2: 3954
B3: Dormant | C3: 1357 | D3: - | E3: 782
B4: Total Membership | C4: =SUM(C2:C3) -> 6609 | D4: - | E4: 4736
B5: No. of Staff- Female | C5: 6 | D5: 7 | E5: 7
B6: Male | C6: 8 | D6: 6 | E6: 6
B7: Total Staff | C7: =C5+C6 -> 14 | D7: =D5+D6 -> 13 | E7: 13
B8: Total Assets | C8: 3.6428823e+08 | D8: 4.3088142e+08 | E8: 397013048
B9: Core Capital | C9: =C12-C20-C23 -> 2577910.2 | D9: 73239376 | E9: 51832291
B10: Institutional Capital | C10: 3952190 | D10: 24179684 | E10: 2761098.3
B11: Share Capital | C11: 45111736 | D11: 49059693 | E11: 49071193
B12: Reserves | C12: 2577910.2 | D12: 2466988.7 | E12: 2782628
B13: Gross Loan Portfolio | C13: 2.7781358e+08 | D13: 3.2873753e+08 | E13: 316554476
B14: Non-Performing Loans | C14: 16739913 | D14: 44296098 | E14: 47731317 | L14: 49071193
B15: FOSA Deposits | C15: - | D15: 11455964 | E15: 10354304 | L15: 110922
B16: BOSA Deposits | C16: 3.0763979e+08 | D16: 3.4364895e+08 | E16: 357317608 | L16: 204717
B17: Cash and cash Equivalent | C17: 30124363 | D17: 8239064.3 | E17: 10078050 | L17: 2466989
H18: =9855872+498432 -> 10354304 | L18: =SUM(L14:L17) -> 51853821 | M18: =L18-L20 -> 51832291 | N18: =M18-L14 -> 2761098
N19: =N18/E8 -> 0.0069546782
L20: 21530
H22: =110922+204717+2466989 -> 2782628 | L22: =L18-L20 -> 51832291 | N22: =L22/E8 -> 0.13055564
D23: 300844 | E23: 104870
D24: 915327.68 | E24: 228898.17 | L24: =L22-L14 -> 2761098
D25: =SUM(D23:D24) -> 1216171.7 | E25: =SUM(E23:E24) -> 333768.17 | N25: =L24/E8 -> 0.0069546782
L26: =L24/E8 -> 0.0069546782

Sheet Evolutitve SCI
B2: 2018 Audited | C2: 2019 Audited | D2: 2020 Audited | E2: 2021 Audited | F2: 44562 | G2: 44593 | H2: 44621 | I2: 44652 | J2: 44682 | K2: 44713 | L2: 44743 | M2: 44774 | N2: 44805 | O2: 44835 | P2: 44866 | Q2: 44896 | R2: Audited 2022 | S2: 44927 | T2: 44958 | U2: 44986 | V2: 45017 | W2: 45047 | X2: 45078 | Y2: 45108 | Z2: 45139 | AA2: 45170 | AB2: 45200 | AC2: 45231 | AD2: 45261 | AE2: 45292
A3: Financial Income | B3: =B4+B7 -> 27924758 | C3: =C4+C7 -> 31056565 | D3: =D4+D7 -> 33729012 | E3: =E4+E7 -> 43660139 | F3: =F4+F7 -> 3218151.1 | G3: =G4+G7 -> 6487458.5 | H3: =H4+H7 -> 10158879 | I3: =I4+I7 -> 14446048 | ... U3: =U4+U7 -> 0
A4: Financial Income From Loans Portfolio | B4: =SUM(B5:B6) -> 27559538 | C4: =SUM(C5:C6) -> 30039528 | D4: =SUM(D5:D6) -> 31341132 | E4: =SUM(E5:E6) -> 39582274 | F4: =SUM(F5:F6) -> 3119827.2 | G4: =SUM(G5:G6) -> 6290038.2 | H4: =SUM(H5:H6) -> 9714142.8 | I4: =SUM(I5:I6) -> 13672972 | ... U4: =SUM(U5:U6) -> 0
A5: Interest from Loans Portfolio | B5: =25619020.2 -> 25619020 | C5: =27662882.94 -> 27662883 | D5: =28349719 -> 28349719 | E5: 36589547 | F5: 2907480.2 | G5: 5838944.2 | H5: 8899845.8 | I5: 12370112 | J5: 15936829 | K5: 19679155 | L5: 23769335 | M5: 28433685 | N5: 32909925 | O5: 37305043 | P5: 41640877 | Q5: 45776852 | R5: 45782378 | S5: 4191918.5 | T5: 8192553.8
A6: Fees&Commision on Loan Portfolio | B6: =1940517.6 -> 1940517.6 | C6: =2376645 -> 2376645 | D6: =2991413 -> 2991413 | E6: =818163+2174564.3 -> 2992727.3 | F6: 212347 | G6: 451094 | H6: 814297 | I6: 1302860 | J6: 1567125 | K6: 1845204 | L6: 2298310 | M6: 2657815 | N6: 3039439 | O6: 3364720 | P6: 3700062 | Q6: 3887770 | R6: =848761+3074319 -> 3923080 | S6: =848761+3074319 -> 3923080 | T6: 667688
A7: Financial Income from Investments | B7: =SUM(B8:B11) -> 365220.12 | C7: =SUM(C8:C11) -> 1017036.6 | D7: =SUM(D8:D11) -> 2387880 | E7: =SUM(E8:E11) -> 4077865 | F7: =SUM(F8:F11) -> 98323.9 | G7: =SUM(G8:G11) -> 197420.3 | H7: =SUM(H8:H11) -> 444735.76 | I7: =SUM(I8:I11) -> 773076.24 | ... T7: =SUM(T8:T11) -> 636708.88
A8: Government Securities | F8: 0 | G8: 0 | H8: 0 | I8: 0 | J8: 0 | K8: 0 | L8: 0 | M8: 0 | N8: 0 | O8: 0 | P8: 0 | Q8: 0 | S8: 0 | T8: 0
A9: Deposits with Banks & other Financial Institutions | B9: =365220.12 -> 365220.12 | C9: =1017036.64 -> 1017036.6 | D9: =2387880 -> 2387880 | E9: 3106701 | F9: 1416.9 | G9: 1416.9 | H9: 1416.9 | I9: 1416.9 | J9: 1416.9 | K9: 230295.7 | L9: 230295.7 | M9: 384036.2 | N9: 618612.37 | O9: 1113835.4 | P9: 1392551.4 | Q9: 1706696.7 | R9: 1718196.7 | S9: 6212 | T9: 0
A10: Other Investments | F10: 0 | G10: 0 | H10: 0 | I10: 0 | J10: 0 | K10: 0 | L10: 0 | M10: 0 | N10: 0 | O10: 0 | P10: 0 | Q10: 0 | S10: 0 | T10: 0 | V10: 44307736.15-
A11: Other Operating Income | E11: =500+970664 -> 971164 | F11: 96907 | G11: 196003.4 | H11: 443318.86 | I11: 771659.34 | J11: 1010182.5 | K11: 1372696.1 | L11: 1756469 | M11: 2079822.1 | N11: 2423187.8 | O11: 2769693 | P11: 3103233.3 | Q11: 3380741.3 | R11: =3380781.34+3300 -> 3384081.3 | S11: 333910.42 | T11: 636708.88
A12: Financial Expenses | B12: =SUM(B13:B18) -> 7450000 | C12: =SUM(C13:C18) -> 15500000 | D12: =SUM(D13:D18) -> 3000000 | E12: =SUM(E13:E18) -> 4645087.7 | F12: =SUM(F13:F18) -> 18541.34 | G12: =SUM(G13:G18) -> 20053.34 | H12: =SUM(H13:H18) -> 24698.34 | I12: =SUM(I13:I18) -> 25609.34 | ... T12: =SUM(T13:T18) -> -4895 | V12: =V10-R19 -> #VALUE!
A13: Interest Expense on Deposits | B13: 7450000 | C13: 15500000 | D13: 3000000 | E13: 4514596.9 | F13: 0 | G13: 0 | H13: 0 | I13: 0 | J13: 152358.97 | K13: 154114.27 | L13: 154114.27 | M13: 154114.27 | N13: 154114.27 | O13: 154114.27 | P13: 154114.27 | Q13: 154114.27 | R13: 10500000 | S13: 0 | T13: 0 | V13: =V10-R19 -> #VALUE!
A14: Cost of External Borrowings | F14: 0 | G14: 0 | H14: 0 | I14: 0 | J14: 0 | K14: 0 | L14: 0 | M14: 0 | N14: 0 | O14: 0 | P14: 0 | Q14: 0 | S14: 0 | T14: 0
A15: Dividend Expenses | F15: 0 | G15: 0 | H15: 0 | I15: 0 | J15: 0 | K15: 0 | L15: 0 | M15: 0 | N15: 0 | O15: 0 | P15: 0 | Q15: 0 | S15: 0 | T15: 0
A16: Other Financial Expense | E16: =79120.8+46222+5148 -> 130490.8 | F16: 18541.34 | G16: 0 | H16: 0 | I16: 0 | J16: 0 | K16: 0 | L16: 0 | M16: 0 | N16: 0 | O16: 0 | P16: 0 | Q16: 0 | R16: =82073.54+10411+178804.27 -> 271288.81 | S16: 0 | T16: -4895 | W16: 40807736
A17: Fees & Commision Expense | F17: 0 | G17: 0 | H17: 0 | I17: 0 | J17: 0 | K17: 0 | L17: 0 | M17: 0 | N17: 0 | O17: 0 | P17: 0 | Q17: 0 | S17: 0 | T17: 0 | W17: =W16-R19 -> -3228711.2
A18: Other Expenses | F18: 0 | G18: 20053.34 | H18: 24698.34 | I18: 25609.34 | J18: 31369.54 | K18: 31621.54 | L18: 32436.54 | M18: 34258.54 | N18: 35602.54 | O18: 37437.54 | P18: 43081.54 | Q18: 45114.54 | S18: 0 | T18: 0 | V18: =44307736.15-R19 -> 271288.81
A19: Net Financial Income | B19: =B3-B12 -> 20474758 | C19: =C3-C12 -> 15556565 | D19: =D3-D12 -> 30729012 | E19: =E3-E12 -> 39015051 | F19: =F3-F12 -> 3199609.8 | G19: =G3-G12 -> 6467405.2 | H19: =H3-H12 -> 10134180 | I19: =I3-I12 -> 14420439 | ... T19: =T3-T12 -> 9501845.7
A20: Allowance for Loan Loss | B20: =B21-B22 -> 2300000 | C20: =C21-C22 -> 100000 | D20: =D21-D22 -> 1525595 | E20: =E21-E22 -> 4000000 | F20: =F21-F22 -> 0 | G20: =G21-G22 -> 0 | H20: =H21-H22 -> 0 | I20: =I21-I22 -> 0 | ... T20: =T21-T22 -> 0
A21: Provision for Loan Losses | B21: 2300000 | C21: 100000 | D21: 1525595 | E21: 4000000 | F21: 0 | G21: 0 | H21: 0 | I21: 0 | J21: 0 | K21: 0 | L21: 0 | M21: 0 | N21: 0 | O21: 0 | P21: 0 | Q21: 0 | R21: 3507254 | S21: 0 | T21: 0
A22: Value of Loans Recovered | F22: 0 | G22: 0 | H22: 0 | I22: 0 | J22: 0 | K22: 0 | L22: 0 | M22: 0 | N22: 0 | O22: 0 | P22: 0 | Q22: 0 | S22: 0 | T22: 0
A23: Operating Expeses | B23: =SUM(B24:B28) -> 17846076 | C23: =SUM(C24:C28) -> 18885802 | D23: =SUM(D24:D28) -> 24441436 | E23: =SUM(E24:E28) -> 31557185 | F23: =SUM(F24:F28) -> 3118301 | G23: =SUM(G24:G28) -> 5557125 | H23: =SUM(H24:H28) -> 8957090 | I23: =SUM(I24:I28) -> 11187396 | ... T23: =SUM(T24:T28) -> 6110161 | V23: =R21+R24+R25+R26+R27+R28 -> 36968335
A24: Personel Expenses | B24: 5228400 | C24: 7221252 | D24: 7985695 | E24: 10713396 | F24: 820784 | G24: 1537498 | H24: 2802913 | I24: 3107968 | J24: 3878252 | K24: 4813056 | L24: 5747860 | M24: 6665273 | N24: 7772776 | O24: 8663529 | P24: 9548282 | Q24: 12615317 | R24: 12615317 | S24: 2040095 | T24: 2936288 | V24: 37267813
A25: Governance Expenses | B25: =7974778+13691 -> 7988469 | C25: 4256810 | D25: 5308214 | E25: 12394785 | F25: 459644 | G25: 1276658 | H25: 2616041 | I25: 3313701 | J25: 3828549 | K25: 4213320 | L25: 4579340 | M25: 4724340 | N25: 5095476 | O25: 5624472 | P25: 5861682 | Q25: 8158590 | R25: 8158590 | S25: 223610 | T25: 1010696 | V25: =V24-V23 -> 299477.83
A26: Marketing Expenses | B26: 667652.4 | C26: 670780 | D26: 748486 | E26: 1293300 | F26: 832200 | G26: 999960 | H26: 1293413 | I26: 1355913 | J26: 1447465 | K26: 1529365 | L26: 1666935 | M26: 1710184 | N26: 1994171 | O26: 2015821 | P26: 2054201 | Q26: 2061721 | R26: 1887234 | S26: 631000 | T26: 725610 | V26: =33500574.81+7307161.34 -> 40807736
A27: Depreciation and Amortization | B27: 1581628 | C27: 1567160.4 | D27: 1549567 | E27: 1209375 | F27: 0 | G27: 0 | H27: 0 | I27: 0 | J27: 0 | K27: 0 | L27: 0 | M27: 0 | N27: 0 | O27: 0 | P27: 0 | Q27: 1413927 | R27: 1446026 | S27: 0 | T27: 0 | V27: =V26-R19 -> -3228711.2
A28: Administrative Expenses | B28: =4562372.02+58020.5+8814-B27-B26 -> 2379926.1 | C28: =7065896.16-C26-C27+62879.5+10188+268776 -> 5169799.3 | D28: =11061848+55110+30569-D27-D26 -> 8849474 | E28: =7226204.01-E27-E36 -> 5946329 | F28: 1005673 | G28: 1743009 | H28: 2244723 | I28: 3409814 | J28: 4259606 | K28: 4580984 | L28: 5158157 | M28: 6851382 | N28: 6915731 | O28: 7448446 | P28: 8468678 | Q28: 8766748 | R28: =10799940-R27 -> 9353914 | S28: 367376 | T28: 1437567
A29: Net Operating Income | B29: =B19-B20-B23 -> 328682.4 | C29: =C19-C20-C23 -> -3429237.1 | D29: =D19-D20-D23 -> 4761981 | E29: =E19-E20-E23 -> 3457866.2 | F29: =F19-F20-F23 -> 81308.76 | G29: =G19-G20-G23 -> 910280.16 | H29: =H19-H20-H23 -> 1177090.2 | I29: =I19-I20-I23 -> 3233042.9 | ... T29: =T19-T20-T23 -> 3391684.7
A30: Net Non operating Income/Expense | B30: =B31-B32 -> 0 | C30: =C31-C32 -> 0 | D30: =D31-D32 -> 0 | E30: =E31-E32 -> 0 | F30: =F31-F32 -> 0 | G30: =G31-G32 -> 0 | H30: =H31-H32 -> 0 | I30: =I31-I32 -> 0 | ... T30: =T31-T32 -> 0
A31: Non Operating Income | F31: 0 | G31: 0 | H31: 0 | I31: 0 | J31: 0 | K31: 0 | L31: 0 | M31: 0 | N31: 0 | O31: 0 | P31: 0 | Q31: 0 | R31: 0 | S31: 0 | T31: 0
A32: Non Operating Expense | F32: 0 | G32: 0 | H32: 0 | I32: 0 | J32: 0 | K32: 0 | L32: 0 | M32: 0 | N32: 0 | O32: 0 | P32: 0 | Q32: 0 | R32: 0 | S32: 0 | T32: 0
A33: Net Income(Before Tax & Donations) | B33: =B29+B30 -> 328682.4 | C33: =C29+C30 -> -3429237.1 | D33: =D29+D30 -> 4761981 | E33: =E29+E30 -> 3457866.2 | F33: =F29+F30 -> 81308.76 | G33: =G29+G30 -> 910280.16 | H33: =H29+H30 -> 1177090.2 | I33: =I29+I30 -> 3233042.9 | ... T33: =T29+T30 -> 3391684.7
A34: Taxes | B34: =54783.02 -> 54783.02 | C34: =152555.5 -> 152555.5 | D34: =358182 -> 358182 | E34: 912196.8 | F34: 0 | G34: 0 | H34: 0 | I34: 0 | J34: 0 | K34: 0 | L34: 0 | M34: 0 | N34: 0 | O34: 0 | P34: 0 | Q34: 0 | R34: 912196.8 | S34: 0 | T34: 0
A35: Net Income(After Tax Before Donations) | B35: =B33-B34 -> 273899.38 | C35: =C33-C34 -> -3581792.6 | D35: =D33-D34 -> 4403799 | E35: =E33-E34 -> 2545669.4 | F35: =F33-F34 -> 81308.76 | G35: =G33-G34 -> 910280.16 | H35: =H33-H34 -> 1177090.2 | I35: =I33-I34 -> 3233042.9 | ... T35: =T33-T34 -> 3391684.7
A36: Donations | E36: 70500 | F36: 0 | G36: 0 | H36: 0 | I36: 0 | J36: 0 | K36: 0 | L36: 0 | M36: 0 | N36: 0 | O36: 0 | P36: 0 | Q36: 0 | S36: 0 | T36: 0
A37: Net Income/(After Tax & Donations) | B37: =B35-B36 -> 273899.38 | C37: =C35-C36 -> -3581792.6 | D37: =D35-D36 -> 4403799 | E37: =E35-E36 -> 2475169.4 | F37: =F35-F36 -> 81308.76 | G37: =G35-G36 -> 910280.16 | H37: =H35-H36 -> 1177090.2 | I37: =I35-I36 -> 3233042.9 | ... T37: =T35-T36 -> 3391684.7
A38: 20% transfer to statutory | R38: =20/100*R37 -> 1231183.1
A39: Surplus
E40: 2655915.5 | S40: 6127726.5
S41: =R35-S40 -> 28189.02

Sheet compliance report
A1: STRATEGIC UREMBO SACCO SOCIETY LIMITED
A2: PERFORMANCE AND COMPLIANCE REPORT AS AT : 31st December , 2020
B3: Prudential Standard | C3: Audited | D3: Audited | E3: audited-2020
C4: 2018 | D4: 2019 | F4: Audited 2021 | G4: 44562 | H4: 44593 | I4: 44621 | J4: 44652 | K4: 44682 | L4: 44713 | M4: 44743 | N4: 44774 | O4: 44805 | P4: 44835 | Q4: 44866 | R4: 44896 | S4: Audited 2022 | T4: 44927 | U4: 44958
A5: A. CAPITAL ADEQUACY
A6: Core Capital | B6: ≥10M | C6: =C34 -> 30143410 | D6: =D34 -> 35452338 | E6: =E34 -> 45229105 | F6: =F34 -> 47522616 | G6: =G34 -> 65485154 | H6: =H34 -> 67302350 | I6: =I34 -> 53130534 | J6: =J34 -> 56340613 | ... U6: =U34 -> 86941636
A7: Core Capital/Total Assets | B7: ≥10% | C7: =C34/C30 -> 0.11317987 | D7: =D34/D30 -> 0.12002259 | E7: =E34/E30 -> 0.14061693 | F7: =F34/F30 -> 0.13045334 | G7: =G34/G30 -> 0.17049291 | H7: =H34/H30 -> 0.17098394 | I7: =I34/I30 -> 0.13665007 | J7: =J34/J30 -> 0.14177096 | ... U7: =U34/U30 -> 0.1913891
A8: Core Capital/Total Deposits | B8: ≥10% | C8: =C34/C32 -> 0.13335301 | D8: =D34/D32 -> 0.1449681 | E8: =E34/E32 -> 0.16806639 | F8: =F34/F32 -> 0.15447487 | G8: =G34/G32 -> 0.2072765 | H8: =H34/H32 -> 0.20812207 | I8: =I34/I32 -> 0.15926016 | J8: =J34/J32 -> 0.16609227 | ... U8: =U34/U32 -> 0.23798524
A9: Institutional Capital/Total Assets | B9: ≥8% | C9: =C35/C30 -> -0.014738974 | D9: =D35/D30 -> -0.013506305 | E9: =E35/E30 -> 0.00036490042 | F9: =F35/F30 -> 0.0052958679 | G9: =G35/G30 -> 0.050426698 | H9: =H35/H30 -> 0.052577889 | I9: =I35/I30 -> 0.015666866 | J9: =J35/J30 -> 0.02233975 | ... U9: =U35/U30 -> 0.1913891
A10: B. ASSET QUALITY
A11: NPL (Substandard+Doubtful+Loss) | B11: <5% | C11: =C36/C33 -> 0 | D11: =D36/D33 -> 0 | E11: =E36/E33 -> 0 | F11: =F36/F33 -> 0 | G11: =G36/G33 -> 0 | H11: =H36/H33 -> 0 | I11: =I36/I33 -> 0 | J11: =J36/J33 -> 0 | ... U11: =U36/U33 -> 0
A12: Non-Earning Assets | B12: <10% | C12: =C37/C30 -> 0.1099783 | D12: =D37/D30 -> 0.19583561 | E12: =E37/E30 -> 0.18554118 | F12: =F37/F30 -> 0.17290823 | G12: =G37/G30 -> 0.16111033 | H12: =H37/H30 -> 0.16407489 | I12: =I37/I30 -> 0.17015728 | J12: =J37/J30 -> 0.19371577 | ... U12: =U37/U30 -> 0.14942284
A13: Equity investments/Deposits | B13: <5% | C13: =C39/C32 -> 0.0007367208 | D13: =D39/D32 -> 0.00068095755 | E13: =E39/E32 -> 0.0006188072 | F13: =F39/F32 -> 0.00054294016 | G13: =G39/G32 -> 0.00052869073 | H13: =H39/H32 -> 0.00051651436 | I13: =I39/I32 -> 0.00050067679 | J13: =J39/J32 -> 0.00049240486 | ... U13: =U39/U32 -> 0.00045721103
A14: Equity investments/Core capital | B14: <40% | C14: =C39/C34 -> 0.0055245906 | D14: =D39/D34 -> 0.0046972924 | E14: =E39/E34 -> 0.0036819212 | F14: =F39/F34 -> 0.0035147476 | G14: =G39/G34 -> 0.0025506545 | H14: =H39/H34 -> 0.0024817856 | I14: =I39/I34 -> 0.0031437666 | J14: =J39/J34 -> 0.0029646465 | ... U14: =U39/U34 -> 0.0019211739
A15: C. EARNINGS RATING
A16: Yield on Gross Loans | C16: =C49/C33 -> 0.12366635 | D16: =D49/D33 -> 0.13135216 | E16: =E49/E33 -> 0.13552438 | F16: =F49/F33 -> 0.14247782 | G16: =G49/G33 -> 0.011222659 | H16: =H49/H33 -> 0.02257171 | I16: =I49/I33 -> 0.034417935 | J16: =J49/J33 -> 0.045099606 | ... U16: =U49/U33 -> 0.026890556
A17: Total Expense/Total Income | C17: =C50/C45 -> 0.90586553 | D17: =D50/D45 -> 1.1071991 | E17: =E50/E45 -> 0.81358553 | F17: =F50/F45 -> 0.82918364 | G17: =G50/G45 -> 0.97473432 | H17: =H50/H45 -> 0.85968617 | I17: =I50/I45 -> 0.88413187 | J17: =J50/J45 -> 0.7761988 | ... U17: =U50/U45 -> 0.64286593
A18: Net Income/Average Assets (ROA) | C18: =C51/C31 -> #DIV/0! | D18: =D51/D31 -> -0.012753118 | E18: =E51/E31 -> 0.014274223 | F18: =F51/F31 -> 0.0072169119 | G18: =G51/G31 -> 0.00021729232 | H18: =H51/H31 -> 0.0023409211 | I18: =I51/I31 -> 0.003008825 | J18: =J51/J31 -> 0.0082243425 | ... U18: =U51/U31 -> 0.0074814546
A19: Operating Expenses/Financial Income (OPEX) | C19: =C48/C45 -> 0.63907718 | D19: =D48/D45 -> 0.60810981 | E19: =E48/E45 -> 0.72464133 | F19: =F48/F45 -> 0.72279168 | G19: =G48/G45 -> 0.96897284 | H19: =H48/H45 -> 0.85659507 | I19: =I48/I45 -> 0.88170067 | J19: =J48/J45 -> 0.77442604 | ... U19: =U48/U45 -> 0.64338136
A20: D. LIQUIDITY
A21: Liquid Assets/Short-term Liabilities | B21: >15% | C21: =C41/C42 -> 0.58800273 | D21: =D41/D42 -> 0.081200657 | E21: =E41/E42 -> 0.14616985 | F21: =F41/F42 -> 3.3625478 | G21: =G41/G42 -> 5.9132567 | H21: =H41/H42 -> 5.8426743 | I21: =I41/I42 -> 3.5353708 | J21: =J41/J42 -> 0.25054001 | ... U21: =U41/U42 -> 1.2722636
A22: External Borrowing/Total Assets | B22: <25% | C22: =C43/C30 -> 0 | D22: =D43/D30 -> 0 | E22: =E43/E30 -> 0 | F22: =F43/F30 -> 0 | G22: =G43/G30 -> 0 | H22: =H43/H30 -> 0 | I22: =I43/I30 -> 0 | J22: =J43/J30 -> 0 | ... U22: =U43/U30 -> 0
A23: Liquid Assets/Total Assets | C23: =C41/C30 -> 0.022033131 | D23: =D41/D30 -> 0.0041809762 | E23: =E41/E30 -> 0.003243568 | F23: =F41/F30 -> 0.082693759 | G23: =G41/G30 -> 0.10585359 | H23: =H41/H30 -> 0.11891103 | I23: =I41/I30 -> 0.12099786 | J23: =J41/J30 -> 0.0097785794 | ... U23: =U41/U30 -> 0.03256465
A24: E. STRUCTURE/SENSITIVITY TO RISK
A25: Gross loans /Total Assets | B25: 70-80 | C25: =C33/C30 -> 0.83675282 | D25: =D33/D30 -> 0.77423716 | E25: =E33/E30 -> 0.71898008 | F25: =F33/F30 -> 0.76262024 | G25: =G33/G30 -> 0.72376613 | H25: =H33/H30 -> 0.70796846 | I25: =I33/I30 -> 0.72591431 | J25: =J33/J30 -> 0.76287939 | ... U25: =U33/U30 -> 0.72532924
A26: Gross loans/Deposits | B26: >100% | C26: =C33/C32 -> 0.98589541 | D26: =D33/D32 -> 0.93515466 | E26: =E33/E32 -> 0.85933027 | F26: =F33/F32 -> 0.90304825 | G26: =G33/G32 -> 0.8799176 | H26: =H33/H32 -> 0.86174096 | I26: =I33/I32 -> 0.84602392 | J26: =J33/J32 -> 0.89375406 | ... U26: =U33/U32 -> 0.90191999
A27: Financial Investments/Total Assets | C27: =C40/C32 -> 0.046978285 | D27: =D40/D32 -> 0.040911188 | E27: =E40/E32 -> 0.12482723 | F27: =F40/F32 -> 0.024329423 | G27: =G40/G32 -> 0.023695384 | H27: =H40/H32 -> 0.023149651 | I27: =I40/I32 -> 0.022439827 | J27: =J40/J32 -> 0.081029139 | ... U27: =U40/U32 -> 0.11524821
A28: Dividends+Interest on Deposits/Total Income | C28: =C47/C45 -> 0.54592083 | D28: =D47/D45 -> 0.87634136 | E28: =E47/E45 -> 0.19370247 | F28: =F47/F45 -> 0.10672854 | G28: =G47/G45 -> 0 | H28: =H47/H45 -> 0 | I28: =I47/I45 -> 0 | J28: =J47/J45 -> 0 | ... U28: =U47/U45 -> 0
A29: F. KEY FINANCIAL STATISTICS | C29: 2015 | D29: 2016
A30: Total Assets | C30: ='Evolutive SFP'!B26 -> 2.6633191e+08 | D30: ='Evolutive SFP'!C26 -> 2.9538054e+08 | E30: ='Evolutive SFP'!D26 -> 321647644 | F30: ='Evolutive SFP'!E26 -> 3.6428823e+08 | G30: ='Evolutive SFP'!F26 -> 3.8409312e+08 | H30: ='Evolutive SFP'!G26 -> 3.9361796e+08 | I30: ='Evolutive SFP'!H26 -> 3.8880721e+08 | J30: ='Evolutive SFP'!I26 -> 3.9740588e+08 | ... U30: ='Evolutive SFP'!T26 -> 4.542664e+08
A31: Average Assets | D31: =(D30+C30)/2 -> 2.8085622e+08 | E31: =(E30+D30)/2 -> 3.0851409e+08 | F31: =(F30+E30)/2 -> 3.4296794e+08 | G31: =(G30+F30)/2 -> 3.7419068e+08 | H31: =(H30+G30)/2 -> 3.8885554e+08 | I31: =(I30+H30)/2 -> 3.9121259e+08 | J31: =(J30+I30)/2 -> 3.9310655e+08 | K31: =(K30+J30)/2 -> 4.0175956e+08 | ... U31: =(U30+T30)/2 -> 4.5334562e+08
A32: Total Deposits | C32: ='Evolutive SFP'!B30 -> 2.2604221e+08 | D32: ='Evolutive SFP'!C30 -> 2.4455269e+08 | E32: ='Evolutive SFP'!D30 -> 269114517 | F32: ='Evolutive SFP'!E30 -> 3.0763979e+08 | G32: ='Evolutive SFP'!F30 -> 3.1593139e+08 | H32: ='Evolutive SFP'!G30 -> 3.233792e+08 | I32: ='Evolutive SFP'!H30 -> 3.3360844e+08 | J32: ='Evolutive SFP'!I30 -> 3.3921273e+08 | ... U32: ='Evolutive SFP'!T30 -> 3.6532365e+08
A33: Gross Loans | C33: ='Evolutive SFP'!B14 -> 222853979 | D33: ='Evolutive SFP'!C14 -> 2.2869459e+08 | E33: ='Evolutive SFP'!D14 -> 231258250 | F33: ='Evolutive SFP'!E14 -> 2.7781358e+08 | G33: ='Evolutive SFP'!F14 -> 2.7799359e+08 | H33: ='Evolutive SFP'!G14 -> 2.786691e+08 | I33: ='Evolutive SFP'!H14 -> 2.8224072e+08 | J33: ='Evolutive SFP'!I14 -> 303172758 | ... U33: ='Evolutive SFP'!T14 -> 3.294927e+08
A34: Core Capital | C34: =('Evolutive SFP'!B38+'Evolutive SFP'!B39+'Evolutive SFP'!B40+'Evolutive SFP'!B41+'Evolutive SFP'!B42+'Evolutive SFP'!B43)-'Evolutive SFP'!B12 -> 30143410 | D34: =('Evolutive SFP'!C38+'Evolutive SFP'!C39+'Evolutive SFP'!C40+'Evolutive SFP'!C41+'Evolutive SFP'!C42+'Evolutive SFP'!C43)-'Evolutive SFP'!C12 -> 35452338 | E34: =('Evolutive SFP'!D38+'Evolutive SFP'!D39+'Evolutive SFP'!D40+'Evolutive SFP'!D41+'Evolutive SFP'!D42+'Evolutive SFP'!D43)-'Evolutive SFP'!D12 -> 45229105 | F34: =('Evolutive SFP'!E38+'Evolutive SFP'!E39+'Evolutive SFP'!E40+'Evolutive SFP'!E41+'Evolutive SFP'!E42+'Evolutive SFP'!E43)-'Evolutive SFP'!E12 -> 47522616 | G34: =('Evolutive SFP'!F38+'Evolutive SFP'!F39+'Evolutive SFP'!F40+'Evolutive SFP'!F41+'Evolutive SFP'!F42+'Evolutive SFP'!F43)-'Evolutive SFP'!F12 -> 65485154 | H34: =('Evolutive SFP'!G38+'Evolutive SFP'!G39+'Evolutive SFP'!G40+'Evolutive SFP'!G41+'Evolutive SFP'!G42+'Evolutive SFP'!G43)-'Evolutive SFP'!G12 -> 67302350 | I34: =('Evolutive SFP'!H38+'Evolutive SFP'!H39+'Evolutive SFP'!H40+'Evolutive SFP'!H41+'Evolutive SFP'!H42+'Evolutive SFP'!H43)-'Evolutive SFP'!H12 -> 53130534 | J34: =('Evolutive SFP'!I38+'Evolutive SFP'!I39+'Evolutive SFP'!I40+'Evolutive SFP'!I41+'Evolutive SFP'!I42+'Evolutive SFP'!I43)-'Evolutive SFP'!I12 -> 56340613 | ... U34: =('Evolutive SFP'!T38+'Evolutive SFP'!T39+'Evolutive SFP'!T40+'Evolutive SFP'!T41+'Evolutive SFP'!T42+'Evolutive SFP'!T43)-'Evolutive SFP'!T12 -> 86941636
A35: Institutional Capital | C35: =C34-'Evolutive SFP'!C38 -> -3925459.1 | D35: =D34-'Evolutive SFP'!D38 -> -3989499.7 | E35: =E34-'Evolutive SFP'!E38 -> 117369.36 | F35: =F34-'Evolutive SFP'!F38 -> 1929222.4 | G35: =G34-'Evolutive SFP'!G38 -> 19368548 | H35: =H34-'Evolutive SFP'!H38 -> 20695602 | I35: =I34-'Evolutive SFP'!I38 -> 6091390.6 | J35: =J34-'Evolutive SFP'!J38 -> 8877947.9 | ... U35: =U34-'Evolutive SFP'!U38 -> 86941636
A36: Non-performing Loans
A37: Non-Earning Assets | C37: ='Evolutive SFP'!B7+'Evolutive SFP'!B16+'Evolutive SFP'!B20 -> 29290731 | D37: ='Evolutive SFP'!C7+'Evolutive SFP'!C16+'Evolutive SFP'!C20 -> 57846028 | E37: ='Evolutive SFP'!D7+'Evolutive SFP'!D16+'Evolutive SFP'!D20 -> 59678882 | F37: ='Evolutive SFP'!E7+'Evolutive SFP'!E16+'Evolutive SFP'!E20 -> 62988432 | G37: ='Evolutive SFP'!F7+'Evolutive SFP'!F16+'Evolutive SFP'!F20 -> 61881369 | H37: ='Evolutive SFP'!G7+'Evolutive SFP'!G16+'Evolutive SFP'!G20 -> 64582824 | I37: ='Evolutive SFP'!H7+'Evolutive SFP'!H16+'Evolutive SFP'!H20 -> 66158377 | J37: ='Evolutive SFP'!I7+'Evolutive SFP'!I16+'Evolutive SFP'!I20 -> 76983787 | ... U37: ='Evolutive SFP'!T7+'Evolutive SFP'!T16+'Evolutive SFP'!T20 -> 67877777
A38: Property and Equipment | C38: ='Evolutive SFP'!B20 -> 20493086 | D38: ='Evolutive SFP'!C20 -> 20920446 | E38: ='Evolutive SFP'!D20 -> 22397895 | F38: ='Evolutive SFP'!E20 -> 20974222 | G38: ='Evolutive SFP'!F20 -> 24340509 | H38: ='Evolutive SFP'!G20 -> 24518502 | I38: ='Evolutive SFP'!H20 -> 23189546 | J38: ='Evolutive SFP'!I20 -> 23200829 | ... U38: ='Evolutive SFP'!T20 -> 20696029
A39: Equity Investments | C39: ='Evolutive SFP'!B12 -> 166530 | D39: ='Evolutive SFP'!C12 -> 166530 | E39: ='Evolutive SFP'!D12 -> 166530 | F39: ='Evolutive SFP'!E12 -> 167030 | G39: ='Evolutive SFP'!F12 -> 167030 | H39: ='Evolutive SFP'!G12 -> 167030 | I39: ='Evolutive SFP'!H12 -> 167030 | J39: ='Evolutive SFP'!I12 -> 167030 | ... U39: ='Evolutive SFP'!T12 -> 167030
A40: Financial Investments | C40: ='Evolutive SFP'!B8 -> 10619076 | D40: ='Evolutive SFP'!C8 -> 10004941 | E40: ='Evolutive SFP'!D8 -> 33592821 | F40: ='Evolutive SFP'!E8 -> 7484698.8 | G40: ='Evolutive SFP'!F8 -> 7486115.8 | H40: ='Evolutive SFP'!G8 -> 7486115.8 | I40: ='Evolutive SFP'!H8 -> 7486115.8 | J40: ='Evolutive SFP'!I8 -> 27486116 | ... U40: ='Evolutive SFP'!T8 -> 42102896
...

Sheet Caels
A1: STRATEGIC DT SACCO CAELS
A3: CAPITAL ADEQUACY | B3: Core Capital | C3: 10 M
B4: CCA | C4: Min 10%
B5: CCD | C5: Min 8%
B6: ICA | C6: Min 8%
A7: ASSET QUALITY | B7: A/LNPL30
B8: NPL30
A9: EARNINGS | B9: ROA
B10: Cost Income ratio
B11: Operating Expense ratio
A12: LIQUIDITY | B12: MIN LIQ ratio | C12: Min 15%
B13: T/LIQ ratio
B14: EB ratio | C14: Max 25%
B15: LA to TA ratio
A16: STRUCTURE | B16: NEA ratio | C16: Max 10%
B17: LB ratio | C17: Max 5%
B18: PI to Deposit ratio | C18: Max 5%
B19: PI to CC ratio | C19: Max 40%
B20: Gross loans/TA
A21: FUNDING MIX | B21: Total Deposits/Total Assets
B22: BOSA Deposits/Total Assets
B23: FOSA Deposits/Total Assets
A24: GROWTH RATIOS | B24: Total Assets
B25: Total Deposits
B26: BOSA Deposits
B27: FOSA Deposits
B28: Total Loans & advances
B29: Core capital
B30: Turnover
B31: Membership
B32: Expenses
A33: Efficiency Ratios | B33: FinCost-Deposits/Avg Deposits
B34: FinCost-Shares/Avg Share capital
B35: FinCost-Ext Loans/Avg Ext Loans
B36: OpEx/Average Total Assets
B37: Opex/Turnover
B38: Avge yield on Net loans
B39: Avge yield on Gross loans
A41: ALL/Average Gross Loan portfolio

Sheet Financials
B1: STRATEGIC DT Sacco Financial Performance
B2: Year | C2: Audited 2018 | D2: Audited 2019 | E2: Audited 2020 | F2: Audited 2021 | G2: 44562 | H2: 44593 | I2: 44621 | J2: 44652 | K2: 44682 | L2: 44713 | M2: 44743 | N2: 44774 | O2: 44805 | P2: 44835 | Q2: 44866 | R2: 44896 | S2: 44927 | T2: 44958 | U2: 44986 | V2: 45017 | W2: 45047 | X2: 45078 | Y2: 45108 | Z2: 45139 | AA2: 45261 | AB2: Audited 2022
A3: 1 | B3: Membership
A4: 2 | B4: Total Assets | C4: ='[2]Evolutive SFP'!B27 -> 151015729 | D4: ='[2]Evolutive SFP'!C27 -> 1148549670 | E4: ='[2]Evolutive SFP'!D27 -> 1.1154921e+09 | F4: ='[2]Evolutive SFP'!E27 -> 1.0974736e+09 | G4: ='[2]Evolutive SFP'!F27 -> 1.0753473e+09 | H4: ='[2]Evolutive SFP'!G27 -> 1.1377121e+09 | I4: ='[2]Evolutive SFP'!H27 -> 1.1320997e+09 | J4: ='[2]Evolutive SFP'!I27 -> 1.1435398e+09 | ... CS4: ='[2]Evolutive SFP'!CR27 -> 0
A5: 3 | B5: Total Deposits | C5: ='[2]Evolutive SFP'!B31 -> 128604214 | D5: ='[2]Evolutive SFP'!C31 -> 852237862 | E5: ='[2]Evolutive SFP'!D31 -> 8.1086231e+08 | F5: ='[2]Evolutive SFP'!E31 -> 7.9473586e+08 | G5: ='[2]Evolutive SFP'!F31 -> 7.8189137e+08 | H5: ='[2]Evolutive SFP'!G31 -> 7.9755631e+08 | I5: ='[2]Evolutive SFP'!H31 -> 7.8718275e+08 | J5: ='[2]Evolutive SFP'!I31 -> 7.9521626e+08 | ... CS5: ='[2]Evolutive SFP'!CR31 -> 0
A6: 3.1 | B6: Deposits-Members(BOSA) | C6: ='[2]Evolutive SFP'!B30 -> 112140909 | D6: ='[2]Evolutive SFP'!C30 -> 271523495 | E6: ='[2]Evolutive SFP'!D30 -> 2.7144038e+08 | F6: ='[2]Evolutive SFP'!E30 -> 2.7210236e+08 | G6: ='[2]Evolutive SFP'!F30 -> 2.7521591e+08 | H6: ='[2]Evolutive SFP'!G30 -> 2.7594244e+08 | I6: ='[2]Evolutive SFP'!H30 -> 2.7855421e+08 | J6: ='[2]Evolutive SFP'!I30 -> 2.7998002e+08 | ... CS6: ='[2]Evolutive SFP'!CR30 -> 0
A7: 3.2 | B7: Deposits-Customers(FOSA) | C7: =('[2]Evolutive SFP'!B28+'[2]Evolutive SFP'!B29) -> 16463305 | D7: =('[2]Evolutive SFP'!C28+'[2]Evolutive SFP'!C29) -> 580714367 | E7: =('[2]Evolutive SFP'!D28+'[2]Evolutive SFP'!D29) -> 5.3942193e+08 | F7: =('[2]Evolutive SFP'!E28+'[2]Evolutive SFP'!E29) -> 5.226335e+08 | G7: =('[2]Evolutive SFP'!F28+'[2]Evolutive SFP'!F29) -> 5.0667546e+08 | H7: =('[2]Evolutive SFP'!G28+'[2]Evolutive SFP'!G29) -> 5.2161387e+08 | I7: =('[2]Evolutive SFP'!H28+'[2]Evolutive SFP'!H29) -> 5.0862854e+08 | J7: =('[2]Evolutive SFP'!I28+'[2]Evolutive SFP'!I29) -> 5.1523624e+08 | ... CS7: =('[2]Evolutive SFP'!CR28+'[2]Evolutive SFP'!CR29) -> 0
A8: 4 | B8: External Borrowing | C8: ='[2]Evolutive SFP'!B37 -> 2291669 | D8: ='[2]Evolutive SFP'!C37 -> 0 | E8: ='[2]Evolutive SFP'!D37 -> 0 | F8: ='[2]Evolutive SFP'!E37 -> 0 | G8: ='[2]Evolutive SFP'!F37 -> 0 | H8: ='[2]Evolutive SFP'!G37 -> 50000000 | I8: ='[2]Evolutive SFP'!H37 -> 50000000 | J8: ='[2]Evolutive SFP'!I37 -> 50000000 | ... CS8: ='[2]Evolutive SFP'!CR37 -> 0
A10: 5 | B10: Share capital and Reserves
A11: 5.1 | B11: Core Capital | C11: =C14-C22-C25 -> 14446887 | D11: =D14-D22-D25 -> 206304838 | E11: =E14-E22-E25 -> 1.7962494e+08 | F11: =F14-F22-F25 -> 1.7297331e+08 | G11: =G14-G22-G25 -> 1.7446985e+08 | H11: =H14-H22-H25 -> 1.7363965e+08 | I11: =I14-I22-I25 -> 1.7253443e+08 | J11: =J14-J22-J25 -> 1.7337882e+08 | ... CS11: =CS14-CS22-CS25 -> 0
A12: 5.2 | B12: Institutional Capital | C12: =C11-C15 -> 3952190 | D12: =D11-D15 -> 65639391 | E12: =E11-E15 -> 38370554 | F12: =F11-F15 -> 31174581 | G12: =G11-G15 -> 32057095 | H12: =H11-H15 -> 30642037 | I12: =I11-I15 -> 28886699 | J12: =J11-J15 -> 29134083 | ... CS12: =CS11-CS15 -> 0
A14: 5.3 | B14: Total Capital | C14: =C15+C16+C17+C18+C19+C20+C21 -> 14919147 | D14: =D15+D16+D17+D18+D19+D20+D21 -> 256104993 | E14: =E15+E16+E17+E18+E19+E20+E21 -> 2.2846032e+08 | F14: =F15+F16+F17+F18+F19+F20+F21 -> 2.2617193e+08 | G14: =G15+G16+G17+G18+G19+G20+G21 -> 2.2340524e+08 | H14: =H15+H16+H17+H18+H19+H20+H21 -> 2.2262504e+08 | I14: =I15+I16+I17+I18+I19+I20+I21 -> 2.2156982e+08 | J14: =J15+J16+J17+J18+J19+J20+J21 -> 2.2246421e+08 | ... CS14: =CS15+CS16+CS17+CS18+CS19+CS20+CS21 -> 0
A15: 5.3.1 | B15: Members Share Capital | C15: ='[2]Evolutive SFP'!B39 -> 10494697 | D15: ='[2]Evolutive SFP'!C39 -> 140665447 | E15: ='[2]Evolutive SFP'!D39 -> 1.4125438e+08 | F15: ='[2]Evolutive SFP'!E39 -> 1.4179872e+08 | G15: ='[2]Evolutive SFP'!F39 -> 1.4241276e+08 | H15: ='[2]Evolutive SFP'!G39 -> 1.4299761e+08 | I15: ='[2]Evolutive SFP'!H39 -> 1.4364773e+08 | J15: ='[2]Evolutive SFP'!I39 -> 1.4424474e+08 | ... CS15: ='[2]Evolutive SFP'!CR39 -> 0
A16: 5.3.2 | B16: Entrance Fees
A17: 5.3.3 | B17: Retained Earnings | C17: ='[2]Evolutive SFP'!B41 -> 351220 | D17: ='[2]Evolutive SFP'!C41 -> 14978344 | E17: ='[2]Evolutive SFP'!D41 -> 27664229 | F17: ='[2]Evolutive SFP'!E41 -> 20813817 | G17: ='[2]Evolutive SFP'!F41 -> 20813817 | H17: ='[2]Evolutive SFP'!G41 -> 20813817 | I17: ='[2]Evolutive SFP'!H41 -> 20813817 | J17: ='[2]Evolutive SFP'!I41 -> 20813817 | ... CS17: ='[2]Evolutive SFP'!CR41 -> 0
A18: 5.3.4 | B18: Appropriation Account | C18: ='[2]Evolutive SFP'!B42 -> 3541956 | D18: ='[2]Evolutive SFP'!C42 -> 5835476 | E18: ='[2]Evolutive SFP'!D42 -> 9337095 | F18: ='[2]Evolutive SFP'!E42 -> 6504356.7 | G18: ='[2]Evolutive SFP'!F42 -> 7436870.6 | H18: ='[2]Evolutive SFP'!G42 -> 6071812 | I18: ='[2]Evolutive SFP'!H42 -> 4366474.7 | J18: ='[2]Evolutive SFP'!I42 -> 4663858 | ... CS18: ='[2]Evolutive SFP'!CR42 -> 0
A19: 5.3.5 | B19: Statutory Reserves | C19: ='[2]Evolutive SFP'!B43 -> 531274 | D19: ='[2]Evolutive SFP'!C43 -> 31870722 | E19: ='[2]Evolutive SFP'!D43 -> 29333544 | F19: ='[2]Evolutive SFP'!E43 -> 31870722 | G19: ='[2]Evolutive SFP'!F43 -> 31870722 | H19: ='[2]Evolutive SFP'!G43 -> 31870722 | I19: ='[2]Evolutive SFP'!H43 -> 31870722 | J19: ='[2]Evolutive SFP'!I43 -> 31870722 | ... CS19: ='[2]Evolutive SFP'!CR43 -> 0
A20: 5.3.6 | B20: Capital Reserves | C20: =('[2]Evolutive SFP'!B44) -> 0 | D20: =('[2]Evolutive SFP'!C44) -> 58441770 | E20: =('[2]Evolutive SFP'!D44) -> 20871074 | F20: =('[2]Evolutive SFP'!E44) -> 20871074 | G20: =('[2]Evolutive SFP'!F44) -> 20871074 | H20: =('[2]Evolutive SFP'!G44) -> 20871074 | I20: =('[2]Evolutive SFP'!H44) -> 20871074 | J20: =('[2]Evolutive SFP'!I44) -> 20871074 | ... CS20: =('[2]Evolutive SFP'!CR44) -> 0
A21: 5.3.7 | B21: Supplementary Capital & reserves | C21: =C22+C23 -> 0 | D21: =D22+D23 -> 4313234 | E21: =E22+E23 -> 0 | F21: =F22+F23 -> 4313234 | G21: =G22+G23 -> 0 | H21: =H22+H23 -> 0 | I21: =I22+I23 -> 0 | J21: =J22+J23 -> 0 | ... CS21: =CS22+CS23 -> 0
A22: a | B22: Proposed Dividends | C22: ='[2]Evolutive SFP'!B46 -> 0 | D22: ='[2]Evolutive SFP'!C46 -> 4313234 | E22: ='[2]Evolutive SFP'!D46 -> 0 | F22: ='[2]Evolutive SFP'!E46 -> 4313234 | G22: ='[2]Evolutive SFP'!F46 -> 0 | H22: ='[2]Evolutive SFP'!G46 -> 0 | I22: ='[2]Evolutive SFP'!H46 -> 0 | J22: ='[2]Evolutive SFP'!I46 -> 0 | ... CS22: ='[2]Evolutive SFP'!CR46 -> 0
A23: b | B23: Risk Mgt Fund
A25: 6 | B25: Investments | C25: =C26+C27+C28 -> 472260 | D25: =D26+D27+D28 -> 45486921 | E25: =E26+E27+E28 -> 48835388 | F25: =F26+F27+F28 -> 48885388 | G25: =G26+G27+G28 -> 48935388 | H25: =H26+H27+H28 -> 48985388 | I25: =I26+I27+I28 -> 49035388 | J25: =J26+J27+J28 -> 49085388 | ... CS25: =CS26+CS27+CS28 -> 0
A26: 6.1 | B26: Shares in Kusco,CIC,Coop Bank | C26: ='[2]Evolutive SFP'!B13 -> 472260 | D26: ='[2]Evolutive SFP'!C13 -> 32948533 | E26: ='[2]Evolutive SFP'!D13 -> 48835388 | F26: ='[2]Evolutive SFP'!E13 -> 48885388 | G26: ='[2]Evolutive SFP'!F13 -> 48935388 | H26: ='[2]Evolutive SFP'!G13 -> 48985388 | I26: ='[2]Evolutive SFP'!H13 -> 49035388 | J26: ='[2]Evolutive SFP'!I13 -> 49085388 | ... CS26: ='[2]Evolutive SFP'!CR13 -> 0
A27: 6.2 | B27: Equity Investments (at cost) | C27: ='[2]Evolutive SFP'!B10 -> 0 | D27: ='[2]Evolutive SFP'!C10 -> 0 | E27: ='[2]Evolutive SFP'!D10 -> 0 | F27: ='[2]Evolutive SFP'!E10 -> 0 | G27: ='[2]Evolutive SFP'!F10 -> 0 | H27: ='[2]Evolutive SFP'!G10 -> 0 | I27: ='[2]Evolutive SFP'!H10 -> 0 | J27: ='[2]Evolutive SFP'!I10 -> 0 | ... CS27: ='[2]Evolutive SFP'!CR10 -> 0
A28: 6.3 | B28: Deposits in KUSCCO CFP | C28: ='[2]Evolutive SFP'!B11 -> 0 | D28: ='[2]Evolutive SFP'!C11 -> 12538388 | E28: ='[2]Evolutive SFP'!D11 -> 0 | F28: ='[2]Evolutive SFP'!E11 -> 0 | G28: ='[2]Evolutive SFP'!F11 -> 0 | H28: ='[2]Evolutive SFP'!G11 -> 0 | I28: ='[2]Evolutive SFP'!H11 -> 0 | J28: ='[2]Evolutive SFP'!I11 -> 0 | ... CS28: ='[2]Evolutive SFP'!CR11 -> 0
A30: 7 | B30: Net Loans & Advances | C30: ='[2]Evolutive SFP'!B14 -> 112905266 | D30: ='[2]Evolutive SFP'!C14 -> 685110959 | E30: ='[2]Evolutive SFP'!D14 -> 6.7256688e+08 | F30: ='[2]Evolutive SFP'!E14 -> 6.7384917e+08 | G30: ='[2]Evolutive SFP'!F14 -> 6.77628e+08 | H30: ='[2]Evolutive SFP'!G14 -> 6.7837707e+08 | I30: ='[2]Evolutive SFP'!H14 -> 6.8226734e+08 | J30: ='[2]Evolutive SFP'!I14 -> 6.8266836e+08 | ... CS30: ='[2]Evolutive SFP'!CR14 -> 0
A31: 7.1 | B31: Gross Loans & advances | C31: ='[2]Evolutive SFP'!B15 -> 112905266 | D31: ='[2]Evolutive SFP'!C15 -> 832525078 | E31: ='[2]Evolutive SFP'!D15 -> 8.2189998e+08 | F31: ='[2]Evolutive SFP'!E15 -> 8.2510161e+08 | G31: ='[2]Evolutive SFP'!F15 -> 8.307998e+08 | H31: ='[2]Evolutive SFP'!G15 -> 8.3346822e+08 | I31: ='[2]Evolutive SFP'!H15 -> 8.3927821e+08 | J31: ='[2]Evolutive SFP'!I15 -> 8.4159859e+08 | ... CS31: ='[2]Evolutive SFP'!CR15 -> 0
A32: 7.2 | B32: Allowance for loan losses | C32: ='[2]Evolutive SFP'!B16 -> 0 | D32: ='[2]Evolutive SFP'!C16 -> 147414119 | E32: ='[2]Evolutive SFP'!D16 -> 1.493331e+08 | F32: ='[2]Evolutive SFP'!E16 -> 1.5125245e+08 | G32: ='[2]Evolutive SFP'!F16 -> 1.531718e+08 | H32: ='[2]Evolutive SFP'!G16 -> 1.5509115e+08 | I32: ='[2]Evolutive SFP'!H16 -> 1.5701087e+08 | J32: ='[2]Evolutive SFP'!I16 -> 1.5893023e+08 | ... CS32: ='[2]Evolutive SFP'!CR16 -> 0
A34: 8 | B34: Non-Earning Assets | C34: ='[2]Evolutive SFP'!B21+'[2]Evolutive SFP'!B7 -> 18274979 | D34: ='[2]Evolutive SFP'!C21+'[2]Evolutive SFP'!C7 -> 108312001 | E34: ='[2]Evolutive SFP'!D21+'[2]Evolutive SFP'!D7 -> 1.6586609e+08 | F34: ='[2]Evolutive SFP'!E21+'[2]Evolutive SFP'!E7 -> 1.6316829e+08 | G34: ='[2]Evolutive SFP'!F21+'[2]Evolutive SFP'!F7 -> 1.6614459e+08 | H34: ='[2]Evolutive SFP'!G21+'[2]Evolutive SFP'!G7 -> 1.5874024e+08 | I34: ='[2]Evolutive SFP'!H21+'[2]Evolutive SFP'!H7 -> 1.6037412e+08 | J34: ='[2]Evolutive SFP'!I21+'[2]Evolutive SFP'!I7 -> 1.4885113e+08 | ... CS34: ='[2]Evolutive SFP'!CR21+'[2]Evolutive SFP'!CR7 -> 0
A35: 8.1 | B35: Property and Equipment | C35: ='[2]Evolutive SFP'!B23 -> 4123114 | D35: ='[2]Evolutive SFP'!C23 -> 67228532 | E35: ='[2]Evolutive SFP'!D23 -> 16506538 | F35: ='[2]Evolutive SFP'!E23 -> 26113023 | G35: ='[2]Evolutive SFP'!F23 -> 25596868 | H35: ='[2]Evolutive SFP'!G23 -> 25080713 | I35: ='[2]Evolutive SFP'!H23 -> 26464472 | J35: ='[2]Evolutive SFP'!I23 -> 26486317 | ... CS35: ='[2]Evolutive SFP'!CR23 -> 0
A37: 9 | B37: Turnover | C37: =C38+C39+C40+C41 -> 14599.248 | D37: =D38+D39+D40+D41 -> 196687961 | E37: =E38+E39+E40+E41 -> 20632764 | F37: =F38+F39+F40+F41 -> 33797993 | G37: =G38+G39+G40+G41 -> 49279715 | H37: =H38+H39+H40+H41 -> 63359741 | I37: =I38+I39+I40+I41 -> 76929656 | J37: =J38+J39+J40+J41 -> 92872973 | ... CS37: =CS38+CS39+CS40+CS41 -> 0
A38: 9.1 | B38: Loan Interest | C38: ='[2]Evolutitve SCI'!B5 -> 11945.435 | D38: ='[2]Evolutitve SCI'!C5 -> 101379709 | E38: ='[2]Evolutitve SCI'!D5 -> 8717884.7 | F38: ='[2]Evolutitve SCI'!E5 -> 16536521 | G38: ='[2]Evolutitve SCI'!F5 -> 24769552 | H38: ='[2]Evolutitve SCI'!G5 -> 33029523 | I38: ='[2]Evolutitve SCI'!H5 -> 41174093 | J38: ='[2]Evolutitve SCI'!I5 -> 49592524 | ... CS38: ='[2]Evolutitve SCI'!CR5 -> 0
A39: 9.2 | B39: Income from investments | C39: ='[2]Evolutitve SCI'!B7 -> 1743.4416 | D39: ='[2]Evolutitve SCI'!C7 -> 95308252 | E39: ='[2]Evolutitve SCI'!D7 -> 5930081.5 | F39: ='[2]Evolutitve SCI'!E7 -> 8931664 | G39: ='[2]Evolutitve SCI'!F7 -> 14342069 | H39: ='[2]Evolutitve SCI'!G7 -> 18749494 | I39: ='[2]Evolutitve SCI'!H7 -> 22435087 | J39: ='[2]Evolutitve SCI'!I7 -> 28316851 | ... CS39: ='[2]Evolutitve SCI'!CR7 -> 0
A40: 9.3 | B40: Fees & Commissions | C40: ='[2]Evolutitve SCI'!B6 -> 910.371 | D40: ='[2]Evolutitve SCI'!C6 -> 0 | E40: ='[2]Evolutitve SCI'!D6 -> 5984797.8 | F40: ='[2]Evolutitve SCI'!E6 -> 8329807.6 | G40: ='[2]Evolutitve SCI'!F6 -> 10168094 | H40: ='[2]Evolutitve SCI'!G6 -> 11580725 | I40: ='[2]Evolutitve SCI'!H6 -> 13320476 | J40: ='[2]Evolutitve SCI'!I6 -> 14963597 | ... CS40: ='[2]Evolutitve SCI'!CR6 -> 0
A41: 9.4 | B41: Average yield on loans
A43: 10 | B43: Financial and Operating costs | C43: =SUM(C44:C47) -> 11568.465 | D43: =SUM(D44:D47) -> 167267134 | E43: =SUM(E44:E47) -> 9281060.7 | F43: =SUM(F44:F47) -> 21824284 | G43: =SUM(G44:G47) -> 34191269 | H43: =SUM(H44:H47) -> 47440792 | I43: =SUM(I44:I47) -> 61774113 | J43: =SUM(J44:J47) -> 75070600 | ... CS43: =SUM(CS44:CS47) -> 0
A44: 10.1 | B44: Interest expense on deposits | C44: ='[2]Evolutitve SCI'!B13+'[2]Evolutitve SCI'!B16 -> 185.36 | D44: ='[2]Evolutitve SCI'!C13+'[2]Evolutitve SCI'!C16 -> 18907802 | E44: ='[2]Evolutitve SCI'!D13+'[2]Evolutitve SCI'!D16 -> 588165.55 | F44: ='[2]Evolutitve SCI'!E13+'[2]Evolutitve SCI'!E16 -> 1014759.5 | G44: ='[2]Evolutitve SCI'!F13+'[2]Evolutitve SCI'!F16 -> 1486405.9 | H44: ='[2]Evolutitve SCI'!G13+'[2]Evolutitve SCI'!G16 -> 2076187.8 | I44: ='[2]Evolutitve SCI'!H13+'[2]Evolutitve SCI'!H16 -> 6320227.6 | J44: ='[2]Evolutitve SCI'!I13+'[2]Evolutitve SCI'!I16 -> 8020486.7 | ... CS44: ='[2]Evolutitve SCI'!CR13+'[2]Evolutitve SCI'!CR16 -> 0
A45: 10.2 | B45: Dividend expense on share capital | C45: ='[2]Evolutitve SCI'!B15 -> 0 | D45: ='[2]Evolutitve SCI'!C15 -> 0 | E45: ='[2]Evolutitve SCI'!D15 -> 0 | F45: ='[2]Evolutitve SCI'!E15 -> 0 | G45: ='[2]Evolutitve SCI'!F15 -> 0 | H45: ='[2]Evolutitve SCI'!G15 -> 0 | I45: ='[2]Evolutitve SCI'!H15 -> 0 | J45: ='[2]Evolutitve SCI'!I15 -> 0 | ... CS45: ='[2]Evolutitve SCI'!CR15 -> 0
A46: 10.3 | B46: Interest expense on borrowed funds | C46: ='[2]Evolutitve SCI'!B14 -> 363.7247 | D46: ='[2]Evolutitve SCI'!C14 -> 17546381 | E46: ='[2]Evolutitve SCI'!D14 -> 0 | F46: ='[2]Evolutitve SCI'!E14 -> 0 | G46: ='[2]Evolutitve SCI'!F14 -> 0 | H46: ='[2]Evolutitve SCI'!G14 -> 500000 | I46: ='[2]Evolutitve SCI'!H14 -> 1289041.1 | J46: ='[2]Evolutitve SCI'!I14 -> 1798630.2 | ... CS46: ='[2]Evolutitve SCI'!CR14 -> 0
A47: 10.4 | B47: Opperating expenses | C47: ='[2]Evolutitve SCI'!B23 -> 11019.38 | D47: ='[2]Evolutitve SCI'!C23 -> 130812951 | E47: ='[2]Evolutitve SCI'!D23 -> 8692895.2 | F47: ='[2]Evolutitve SCI'!E23 -> 20809524 | G47: ='[2]Evolutitve SCI'!F23 -> 32704863 | H47: ='[2]Evolutitve SCI'!G23 -> 44864604 | I47: ='[2]Evolutitve SCI'!H23 -> 54164844 | J47: ='[2]Evolutitve SCI'!I23 -> 65251484 | ... CS47: ='[2]Evolutitve SCI'!CR23 -> 0
