Workbook

Sheet sofp
A1: FUNDILIMA SACCO
B2: 43831 | C2: 43862 | D2: 43891 | E2: 43922 | F2: 43952 | G2: 43983 | H2: 44044 | I2: 44075 | J2: 44105 | K2: 44136 | L2: 44166 | M2: AUDITED 2020 | N2: 44197 | O2: 44228 | P2: 44256 | Q2: 44287 | R2: 44317 | S2: 44348 | T2: 44378 | U2: 44409 | V2: 44440 | W2: 44470 | X2: 44501 | Y2: 44531 | Z2: Aud-21 | AA2: Jan | AB2: Feb | AC2: Mar | AD2: Apr | AE2: May | AF2: Jun | AG2: Jul | AH2: Aug | AI2: Sep | AJ2: Oct | AK2: Nov | AL2: Dec | AM2: Aud-22
A3: Cash & cash Equivalent | B3: =SUM(B4:B5) -> 1.0674812e+08 | C3: =SUM(C4:C5) -> 1.1511345e+08 | D3: =SUM(D4:D5) -> 1.1088763e+08 | E3: =SUM(E4:E5) -> 1.3694146e+08 | F3: =SUM(F4:F5) -> 1.5464545e+08 | G3: =SUM(G4:G5) -> 1.6130515e+08 | I3: =SUM(I4:I5) -> 1.2268365e+08 | J3: =SUM(J4:J5) -> 1.1239786e+08 | K3: =SUM(K4:K5) -> 1.1937893e+08 | L3: =SUM(L4:L5) -> 1.3005592e+08 | M3: =SUM(M4:M5) -> 130055917 | N3: =SUM(N4:N5) -> 1.2234466e+08 | O3: =SUM(O4:O5) -> 1.0497662e+08 | P3: =SUM(P4:P5) -> 95234315 | ... AM3: =SUM(AM4:AM5) -> 99095632
A4: Cash In Hand | B4: 28479625 | C4: 28293090 | D4: 18548813 | E4: 24899295 | F4: 21775817 | G4: 23739305 | H4: 19540552 | I4: 40614993 | J4: 38159405 | K4: 30052441 | L4: 36090180 | M4: 14412643 | N4: 30223271 | O4: 46584890 | P4: 26543325 | Q4: 33060568 | R4: 33032073 | S4: 38549731 | T4: 27415969 | U4: 26583807 | V4: 34510861 | W4: 36381769 | X4: 36798501 | Y4: 26862481 | Z4: 12694621 | AA4: 28449394 | AB4: 33590090 | AC4: 30593085 | AD4: 37100434 | AE4: 32627724 | AF4: 31838149 | AG4: 37083295 | AH4: 44756624 | AI4: 48059262 | AJ4: 32695888 | AK4: 37249109 | AL4: 29387235 | AM4: 9790249
A5: Cash at Bank | B5: 78268497 | C5: 86820356 | D5: 92338814 | E5: 1.1204217e+08 | F5: 1.3286963e+08 | G5: 1.3756584e+08 | H5: 1.1300472e+08 | I5: 82068658 | J5: 74238456 | K5: 89326487 | L5: 93965736 | M5: =88668058+8300011+234554+35360+18394291+11000 -> 115643274 | N5: 92121388 | O5: 58391727 | P5: 68690990 | Q5: 65242036 | R5: 68612743 | S5: 56323118 | T5: 76266813 | U5: 77364055 | V5: 59988106 | W5: 63487974 | X5: 87334896 | Y5: 99083783 | Z5: 113251644 | AA5: 84912099 | AB5: 78476926 | AC5: 74567940 | AD5: 36230467 | AE5: 31513017 | AF5: 73175814 | AG5: 52830485 | AH5: 70500326 | AI5: 65888506 | AJ5: 72758854 | AK5: 91903375 | AL5: 69708397 | AM5: =99095632-9790249 -> 89305383
A6: Prepayment and Sundry | B6: 259686.35 | C6: 475152.8 | D6: 475813.1 | E6: 367269.3 | F6: -4513719.6 | G6: -18124613 | H6: 14324897 | I6: 17653073 | J6: 30923105 | K6: 30526646 | L6: 17906521 | M6: 17906521 | N6: 30228642 | O6: 32991100 | P6: 20302604 | Q6: 28811800 | R6: 20620992 | S6: 29715481 | T6: 28407948 | U6: 16257052 | V6: 29108124 | W6: 34571434 | X6: 21384327 | Y6: 16993326 | Z6: 16993326 | AA6: 35794133 | AB6: 35926765 | AC6: 16784018 | AD6: 35409504 | AE6: 37706122 | AF6: 9871621.3 | AG6: 44794354 | AH6: 28404141 | AI6: 23662512 | AJ6: 37982205 | AK6: 29259633 | AL6: 18046372 | AM6: 18046372
A7: Financial Investment | B7: =B9+B11 -> 25632908 | C7: =C9+C11 -> 25982908 | D7: =D9+D11 -> 13228435 | E7: =E9+E11 -> 13228435 | F7: =F9+F11 -> 13228435 | G7: =G9+G11 -> 13228435 | I7: =I9+I11 -> 13228435 | J7: =J9+J11 -> 13228435 | K7: =K9+K11 -> 13228435 | L7: =L9+L11 -> 13228435 | M7: =M8+M9+M10+M11 -> 83556241 | N7: =N8+N9+N10+N11 -> 83906241 | O7: =O8+O9+O10+O11 -> 104577506 | P7: =P8+P9+P10+P11 -> 1.050787e+08 | Q7: =Q8+Q9+Q10+Q11 -> 1.0557732e+08 | R7: =R8+R9+R10+R11 -> 1.1615013e+08 | S7: =S8+S9+S10+S11 -> 1.1684513e+08 | T7: =T8+T9+T10+T11 -> 1.1745628e+08 | ... AN7: =AN8+AN9+AN10+AN11 -> 0
A8: Government Security | N8: 0 | O8: 0 | P8: 0 | Q8: 0 | R8: 0 | S8: 0 | T8: 0 | U8: 0 | V8: 0 | W8: 0 | X8: 0 | Y8: 0 | AA8: 0 | AB8: 0 | AC8: 0 | AD8: 0 | AE8: 0 | AF8: 0 | AG8: 0 | AH8: 0 | AI8: 0 | AJ8: 0 | AK8: 0 | AL8: 0
A9: Other Securities | N9: 0 | O9: 0 | P9: 0 | Q9: 0 | R9: 0 | S9: 0 | T9: 0 | U9: 0 | V9: 0 | W9: 0 | X9: 0 | Y9: 0 | AA9: 0 | AB9: 0 | AC9: 0 | AD9: 0 | AE9: 0 | AF9: 0 | AG9: 0 | AH9: 0 | AI9: 0 | AJ9: 0 | AK9: 0 | AL9: 0 | AM9: =35205607+20086759 -> 55292366
A10: Balances with Other Saccos | B10: 0 | C10: 0 | D10: 13172819 | E10: 13522819 | F10: 13872819 | G10: 14222819 | H10: 14922819 | I10: 15288362 | J10: 15710956 | K10: 16060956 | L10: 16469004 | M10: 16474943 | N10: 16824943 | O10: 37294601 | P10: 37795792 | Q10: 38294419 | R10: 48867226 | S10: 49562227 | T10: 50173377 | U10: 50760905 | V10: 51410945 | W10: 51995759 | X10: 52576263 | Y10: 53247310 | Z10: 21052036 | AA10: 53918623 | AB10: 54489844 | AC10: 55073118 | AD10: 55660131 | AE10: 56257762 | AF10: 57032374 | AG10: 57630267 | AH10: 58230873 | AI10: 58918777 | AJ10: 59589297 | AK10: 60189396 | AL10: 81029109 | AM10: 25736744
A11: Investment In Companies | B11: 25632908 | C11: 25982908 | D11: 13228435 | E11: 13228435 | F11: 13228435 | G11: 13228435 | H11: 13228435 | I11: 13228435 | J11: 13228435 | K11: 13228435 | L11: 13228435 | M11: 67081298 | N11: 67081298 | O11: 67282905 | P11: 67282905 | Q11: 67282905 | R11: 67282905 | S11: 67282905 | T11: 67282905 | U11: 67282905 | V11: 67282905 | W11: 67282905 | X11: 67282905 | Y11: 67443405 | Z11: =67443405+32272064 -> 99715469 | AA11: 67443405 | AB11: 67443405 | AC11: 67443405 | AD11: 67443405 | AE11: 67443405 | AF11: 67443405 | AG11: 67443405 | AH11: 67443405 | AI11: 67618451 | AJ11: 67618451 | AK11: 67618451 | AL11: 67618451 | AM11: 67618451
A12: Net Loan Portfolio | B12: =B13-B14 -> 3.0628885e+08 | C12: =C13-C14 -> 3.0062531e+08 | D12: =D13-D14 -> 2.9905464e+08 | E12: =E13-E14 -> 2.9281998e+08 | F12: =F13-F14 -> 2.88687e+08 | G12: =G13-G14 -> 3.0592353e+08 | I12: =I13-I14 -> 3.365163e+08 | J12: =J13-J14 -> 3.5013328e+08 | K12: =K13-K14 -> 3.520117e+08 | L12: =L13-L14 -> 3.6303885e+08 | M12: =M13-M14 -> 363038850 | N12: =N13-N14 -> 3.7020252e+08 | O12: =O13-O14 -> 3.7686303e+08 | P12: =P13-P14 -> 3.7748977e+08 | ... AM12: =AM13-AM14 -> 534200521
A13: Gross Loan Portfolio | B13: 3.2801976e+08 | C13: 3.2260622e+08 | D13: 3.2128555e+08 | E13: 3.1530089e+08 | F13: 3.1141792e+08 | G13: 3.2890444e+08 | H13: 3.4911976e+08 | I13: 3.6024721e+08 | J13: 3.741142e+08 | K13: 3.7624262e+08 | L13: 3.8751976e+08 | M13: 387519764 | N13: 3.9501677e+08 | O13: 4.0201061e+08 | P13: 4.0297069e+08 | Q13: 4.0951633e+08 | R13: 4.0961956e+08 | S13: 4.103095e+08 | T13: 4.4625435e+08 | U13: 4.6296447e+08 | V13: 4.5944626e+08 | W13: 4.6201938e+08 | X13: 4.5814154e+08 | Y13: 4.5380671e+08 | Z13: 4.5380671e+08 | AA13: 4.4991221e+08 | AB13: 4.5266822e+08 | AC13: 4.7180505e+08 | AD13: 5.0108788e+08 | AE13: 5.1442218e+08 | AF13: 5.130722e+08 | AG13: 5.1300412e+08 | AH13: 5.1293018e+08 | AI13: 5.1781002e+08 | AJ13: 5.2262374e+08 | AK13: 5.3621053e+08 | AL13: 5.6069567e+08 | AM13: 560695671
A14: Allowance For Loan Loss | B14: 21730915 | C14: 21980915 | D14: 22230915 | E14: 22480915 | F14: 22730915 | G14: 22980915 | H14: 23480915 | I14: 23730915 | J14: 23980915 | K14: 24230915 | L14: 24480915 | M14: 24480914 | N14: 24814249 | O14: 25147582 | P14: 25480915 | Q14: 25814248 | R14: 26147581 | S14: 26480915 | T14: 26814248 | U14: 27147581 | V14: 27480915 | W14: 27814248 | X14: 28161816 | Y14: 25495150 | Z14: 25495150 | AA14: 25911816 | AB14: 26328483 | AC14: 26745150 | AD14: 27161816 | AE14: 27578483 | AF14: 27995150 | AG14: 28411816 | AH14: 28828483 | AI14: 29245150 | AJ14: 29661816 | AK14: 30078483 | AL14: 26495150 | AM14: 26495150
A15: Accounts Recievables | B15: =SUM(B16:B18) -> 0 | C15: =SUM(C16:C18) -> 0 | D15: =SUM(D16:D18) -> 0 | E15: =SUM(E16:E18) -> 0 | F15: =SUM(F16:F18) -> 0 | G15: =SUM(G16:G18) -> 0 | I15: =SUM(I16:I18) -> 0 | J15: =SUM(J16:J18) -> 0 | K15: =SUM(K16:K18) -> 0 | L15: =SUM(L16:L18) -> 0 | M15: =SUM(M16:M18) -> 0 | N15: 0 | O15: 0 | P15: 0 | Q15: 0 | R15: 0 | S15: 0 | T15: 0 | U15: 0 | V15: 0 | W15: 0 | X15: 0 | Y15: 0 | AA15: 0 | AB15: 0 | AC15: 0 | AD15: 0 | AE15: 0 | AF15: 0 | AG15: 0 | AH15: 0 | AI15: 0 | AJ15: 0 | AK15: 0 | AL15: 0
A16: Tax Recoverable | N16: 0 | O16: 0 | P16: 0 | Q16: 0 | R16: 0 | S16: 0 | T16: 0 | U16: 0 | V16: 0 | W16: 0 | X16: 0 | Y16: 0 | AA16: 0 | AB16: 0 | AC16: 0 | AD16: 0 | AE16: 0 | AF16: 0 | AG16: 0 | AH16: 0 | AI16: 0 | AJ16: 0 | AK16: 0 | AL16: 0
A17: Deffered Tax Assets | N17: 0 | O17: 0 | P17: 0 | Q17: 0 | R17: 0 | S17: 0 | T17: 0 | U17: 0 | V17: 0 | W17: 0 | X17: 0 | Y17: 0 | AA17: 0 | AB17: 0 | AC17: 0 | AD17: 0 | AE17: 0 | AF17: 0 | AG17: 0 | AH17: 0 | AI17: 0 | AJ17: 0 | AK17: 0 | AL17: 0
A18: Retirement Benefit Assets | N18: 0 | O18: 0 | P18: 0 | Q18: 0 | R18: 0 | S18: 0 | T18: 0 | U18: 0 | V18: 0 | W18: 0 | X18: 0 | Y18: 0 | AA18: 0 | AB18: 0 | AC18: 0 | AD18: 0 | AE18: 0 | AF18: 0 | AG18: 0 | AH18: 0 | AI18: 0 | AJ18: 0 | AK18: 0 | AL18: 0
A19: Property&Equipments&Other Assets | B19: =SUM(B20:B24) -> 2.8753482e+08 | C19: =SUM(C20:C24) -> 2.8653298e+08 | D19: =SUM(D20:D24) -> 2.8551307e+08 | E19: =SUM(E20:E24) -> 2.8449919e+08 | F19: =SUM(F20:F24) -> 2.8657786e+08 | G19: =SUM(G20:G24) -> 2.8747619e+08 | I19: =SUM(I20:I24) -> 2.8603336e+08 | J19: =SUM(J20:J24) -> 2.8489877e+08 | K19: =SUM(K20:K24) -> 2.8377926e+08 | L19: =SUM(L20:L24) -> 2.8327811e+08 | M19: =SUM(M20:M24) -> 283278107 | N19: =SUM(N20:N24) -> 282159018 | O19: =SUM(O20:O24) -> 2.8197641e+08 | P19: =SUM(P20:P24) -> 2.8408032e+08 | ... AM19: =SUM(AM20:AM24) -> 252091666
A20: Investment Properties | N20: 0 | O20: 0 | P20: 0 | Q20: 0 | R20: 0 | S20: 0 | T20: 0 | U20: 0 | V20: 0 | W20: 0 | X20: 0 | Y20: 0 | AA20: 0 | AB20: 0 | AC20: 0 | AD20: 0 | AE20: 0 | AF20: 0 | AG20: 0 | AH20: 0 | AI20: 0 | AJ20: 0 | AK20: 0 | AL20: 0
A21: Property and Equipment | B21: 41840594 | C21: 41696082 | D21: 41536086 | E21: 41381252 | F21: 42142694 | G21: 44074482 | H21: 44796534 | I21: 44718933 | J21: 44527594 | K21: 44344598 | L21: 44937061 | M21: 44937061 | N21: 44748659 | O21: 46318077 | P21: 49763738 | Q21: 49763690 | R21: 49488501 | S21: 49253740 | T21: 48986511 | U21: 48723354 | V21: 48827834 | W21: 48783455 | X21: 48527558 | Y21: 48952367 | Z21: 48952367 | AA21: 48688210 | AB21: 48453047 | AC21: 48196408 | AD21: 48061600 | AE21: 47811175 | AF21: 47572335 | AG21: 47329081 | AH21: 47422312 | AI21: 48692097 | AJ21: 48742681 | AK21: 49483239 | AL21: 50524503 | AM21: 50599324
A22: Prepaid Lease Rentals | B22: 0 | C22: 0 | D22: 0 | E22: 0 | F22: 0 | G22: 0 | H22: 0 | I22: 0 | J22: 0 | K22: 0 | L22: 0 | N22: 0 | O22: 0 | P22: 0 | Q22: 0 | R22: 0 | S22: 0 | T22: 0 | U22: 0 | V22: 0 | W22: 0 | X22: 0 | Y22: 0 | AA22: 0 | AB22: 0 | AC22: 0 | AD22: 0 | AE22: 0 | AF22: 0 | AG22: 0 | AH22: 0 | AI22: 0 | AJ22: 0 | AK22: 0 | AL22: 0
A23: Intangible Assets | B23: 1527558.6 | C23: 1503559.3 | D23: 1476988.6 | E23: 1451275 | F23: 3601834.5 | G23: 3401709.1 | H23: 3924089.7 | I23: 3814430.4 | J23: 3704512.5 | K23: 3601326 | L23: 3341045.2 | M23: 3341046 | N23: 3243692.5 | O23: 3158330.1 | P23: 3066578.4 | Q23: 2980460.8 | R23: 2894149.7 | S23: 2813133 | T23: 2731928.5 | U23: 2653197.9 | V23: 2579288.9 | W23: 2505200.5 | X23: 2435644.4 | Y23: 2227375.3 | Z23: 2227376.1 | AA23: 2155258.3 | AB23: 2092157.2 | AC23: 2024478.1 | AD23: 1961097.1 | AE23: 1897717.2 | AF23: 1838361.2 | AG23: 1779005.1 | AH23: 1721594.2 | AI23: 1667826.7 | AJ23: 1614057.5 | AK23: 1563699.6 | AL23: 1492341.6 | AM23: 1492342
A24: Other Assets | B24: 244166667 | C24: 243333334 | D24: 242500000 | E24: 241666667 | F24: 240833334 | G24: 240000000 | H24: 238333333 | I24: 237500000 | J24: 236666667 | K24: 235833333 | L24: 235000000 | M24: 235000000 | N24: 234166666 | O24: 232500000 | P24: 231250000 | Q24: 230000000 | R24: 228750000 | S24: 227500000 | T24: 226250000 | U24: 225000000 | V24: 223750000 | W24: 222500000 | X24: 221250000 | Y24: 220000000 | Z24: 220000000 | AA24: 2.1833333e+08 | AB24: 2.1666667e+08 | AC24: 215000000 | AD24: 2.1333333e+08 | AE24: 2.1166667e+08 | AF24: 210000000 | AG24: 2.0833333e+08 | AH24: 2.0666667e+08 | AI24: 205000000 | AJ24: 2.0333333e+08 | AK24: 2.0166667e+08 | AL24: 200000000 | AM24: 200000000
A25: Total Assets | B25: =B19+B15+B12+B7+B6+B3 -> 7.2646438e+08 | C25: =C19+C15+C12+C7+C6+C3 -> 7.2872979e+08 | D25: =D19+D15+D12+D7+D6+D3 -> 7.0915959e+08 | E25: =E19+E15+E12+E7+E6+E3 -> 7.2785634e+08 | F25: =F19+F15+F12+F7+F6+F3 -> 7.3862503e+08 | G25: =G19+G15+G12+G7+G6+G3 -> 7.4980869e+08 | I25: =I19+I15+I12+I7+I6+I3 -> 7.7611482e+08 | J25: =J19+J15+J12+J7+J6+J3 -> 7.9158146e+08 | K25: =K19+K15+K12+K7+K6+K3 -> 7.9892497e+08 | L25: =L19+L15+L12+L7+L6+L3 -> 8.0750783e+08 | M25: =M19+M15+M12+M7+M6+M3 -> 877835636 | N25: =N19+N15+N12+N7+N6+N3 -> 8.8884108e+08 | O25: =O19+O15+O12+O7+O6+O3 -> 9.0138466e+08 | P25: =P19+P15+P12+P7+P6+P3 -> 8.821857e+08 | ... AM25: =AM19+AM15+AM12+AM7+AM6+AM3 -> 1052081752
A26: Savings and Deposits | B26: 81530884 | C26: 93872598 | D26: 83775399 | E26: 87436093 | F26: 88635662 | G26: 89228517 | H26: 87312372 | I26: 83477172 | J26: 88674962 | K26: 89688720 | L26: 93160861 | M26: 95029651 | N26: 96389834 | O26: 1.2340648e+08 | P26: 1.0216156e+08 | Q26: 1.0408167e+08 | R26: 1.0047457e+08 | S26: 92236203 | T26: 1.1785067e+08 | U26: 1.1287864e+08 | V26: 1.0574473e+08 | W26: 1.0877152e+08 | X26: 1.0565617e+08 | Y26: 98874480 | Z26: 1.0093719e+08 | AA26: 96647756 | AB26: 1.1471707e+08 | AC26: 99730852 | AD26: 1.0323855e+08 | AE26: 97776016 | AF26: 92894531 | AG26: 1.0425134e+08 | AH26: 1.0131617e+08 | AI26: 97873677 | AJ26: 96254635 | AK26: 1.1256686e+08 | AL26: 1.0736754e+08 | AM26: 17246892
A27: Short Terrm Deposits | B27: 9377402.3 | C27: 9629856.7 | D27: 10135035 | E27: 10769136 | F27: 13449939 | G27: 13606868 | H27: 11956238 | I27: 12344391 | J27: 13575691 | K27: 11822777 | L27: 10349990 | M27: 8481200 | N27: 12107432 | O27: 13840462 | P27: 14520918 | Q27: 13592883 | R27: 13520757 | S27: 17179201 | T27: 21926408 | U27: 22224584 | V27: 21422594 | W27: 22145564 | X27: 24208468 | Y27: 21512929 | Z27: 19450223 | AA27: 19331074 | AB27: 20621028 | AC27: 20604955 | AD27: 19655602 | AE27: 19282510 | AF27: 18469531 | AG27: 18067309 | AH27: 18868950 | AI27: 20056192 | AJ27: 20140450 | AK27: 19836553 | AL27: 19936566 | AM27: 110057210
A28: Non Withdrawable Deposits | B28: 3.9392435e+08 | C28: 3.9767028e+08 | D28: 4.0155285e+08 | E28: 404779275 | F28: 4.0825488e+08 | G28: 4.1213396e+08 | H28: 4.2245455e+08 | I28: 4.2519846e+08 | J28: 4.2913779e+08 | K28: 4.3252892e+08 | L28: 4.3312882e+08 | M28: 433128824 | N28: 4.3599073e+08 | O28: 4.389635e+08 | P28: 4.410315e+08 | Q28: 4.4400451e+08 | R28: 4.4701479e+08 | S28: 4.5017334e+08 | T28: 4.5469611e+08 | U28: 459341679 | V28: 4.6315746e+08 | W28: 4.6719493e+08 | X28: 4.7051241e+08 | Y28: 4.6399813e+08 | Z28: 4.6399813e+08 | AA28: 4.6848128e+08 | AB28: 4.7306048e+08 | AC28: 4.7813777e+08 | AD28: 4.8398484e+08 | AE28: 4.8937614e+08 | AF28: 4.9404442e+08 | AG28: 4.9725705e+08 | AH28: 5.0083321e+08 | AI28: 4.9802335e+08 | AJ28: 5.0160582e+08 | AK28: 5.0456636e+08 | AL28: 4.9359459e+08 | AM28: 493594586
A29: Total Deposit Liabilities | B29: =SUM(B26:B28) -> 4.8483264e+08 | C29: =SUM(C26:C28) -> 5.0117274e+08 | D29: =SUM(D26:D28) -> 4.9546328e+08 | E29: =SUM(E26:E28) -> 5.029845e+08 | F29: =SUM(F26:F28) -> 5.1034049e+08 | G29: =SUM(G26:G28) -> 5.1496934e+08 | I29: =SUM(I26:I28) -> 5.2102002e+08 | J29: =SUM(J26:J28) -> 5.3138845e+08 | K29: =SUM(K26:K28) -> 5.3404042e+08 | L29: =SUM(L26:L28) -> 5.3663968e+08 | M29: =SUM(M26:M28) -> 536639675 | N29: =SUM(N26:N28) -> 5.44488e+08 | O29: =SUM(O26:O28) -> 5.7621044e+08 | P29: =SUM(P26:P28) -> 5.5771398e+08 | ... AM29: =SUM(AM26:AM28) -> 620898688
A30: Tax Payable | M30: 156662 | N30: -100000 | O30: 156662 | P30: 0 | Q30: -50000 | R30: -50000 | S30: -100000 | T30: -100000 | U30: -100000 | V30: -150000 | W30: -150000 | X30: -150000 | Y30: -200000 | Z30: 508264 | AA30: -200000 | AB30: 508264 | AC30: 0 | AD30: -80000 | AE30: -80000 | AF30: -160000 | AG30: -160000 | AH30: -160000 | AI30: -240000 | AJ30: -247469 | AK30: -247469 | AL30: -349550 | AM30: 438611
A31: Dividends Payable | B31: 268427 | C31: 1244192.8 | D31: 574364.99 | E31: 574364.99 | F31: 574364.99 | G31: 574364.99 | H31: 566473.99 | I31: 566473.99 | J31: 566473.99 | K31: 566473.99 | L31: 566473.99 | M31: 16000000 | N31: 566473.99 | O31: 566473.99 | P31: 565873.99 | Q31: 565873.99 | R31: 565873.99 | S31: 132095.99 | T31: 128447.99 | U31: 128447.99 | V31: 0 | W31: 0 | X31: 0 | Y31: 0 | Z31: 18775154 | AA31: 0 | AB31: 0 | AC31: 0 | AD31: 0 | AE31: 0 | AF31: 0 | AG31: 0 | AH31: 0 | AI31: 0 | AJ31: 0 | AK31: 0 | AL31: 0
A32: Deferred Tax Liability | B32: 0 | C32: 0 | D32: 0 | E32: 0 | F32: 0 | G32: 0 | H32: 0 | I32: 0 | J32: 0 | K32: 0 | L32: 0 | N32: 0 | O32: 0 | P32: 0 | Q32: 0 | R32: 0 | S32: 0 | T32: 0 | U32: 0 | V32: 0 | W32: 0 | X32: 0 | Y32: 0 | AA32: 0 | AB32: 0 | AC32: 0 | AD32: 0 | AE32: 0 | AF32: 0 | AG32: 0 | AH32: 0 | AI32: 0 | AJ32: 0 | AK32: 0 | AL32: 0
A33: Retirement Benefits Liabilty | B33: 0 | C33: 0 | D33: 0 | E33: 0 | F33: 0 | G33: 0 | H33: 0 | I33: 0 | J33: 0 | K33: 0 | L33: 0 | N33: 0 | O33: 0 | P33: 0 | Q33: 0 | R33: 0 | S33: 0 | T33: 0 | U33: 0 | V33: 0 | W33: 0 | X33: 0 | Y33: 0 | AA33: 0 | AB33: 0 | AC33: 0 | AD33: 0 | AE33: 0 | AF33: 0 | AG33: 0 | AH33: 0 | AI33: 0 | AJ33: 0 | AK33: 0 | AL33: 0
A34: Other Liabilities | B34: 11859346 | C34: 14728862 | D34: 15800225 | E34: 17827191 | F34: 19849601 | G34: 23566527 | H34: 26273020 | I34: 26797820 | J34: 28701815 | K34: 31261141 | L34: 36424269 | M34: 20990742 | N34: 39319062 | O34: 24066075 | P34: 22603809 | Q34: 24756951 | R34: 27207149 | S34: 28165059 | T34: 32122134 | U34: 33966451 | V34: 36232697 | W34: 38600528 | X34: 40587413 | Y34: 40098415 | Z34: 22854591 | AA34: 44515667 | AB34: 26116414 | AC34: 23589375 | AD34: 26786015 | AE34: 31026421 | AF34: 34283099 | AG34: 35837225 | AH34: 38480418 | AI34: 40914224 | AJ34: 47061622 | AK34: 51138511 | AL34: 54599604 | AM34: 22329916
A35: External Borrowings | B35: 41250000 | C35: 40000000 | D35: 38750000 | E35: 37500000 | F35: 36250000 | G35: 35000000 | H35: 32500000 | I35: 31250000 | J35: 30000000 | K35: 28750000 | L35: 27500000 | M35: 27500000 | N35: 26250000 | O35: 25000000 | P35: 23750000 | Q35: 22500000 | R35: 21250000 | S35: 20000000 | T35: 18750000 | U35: 17500000 | V35: 16250000 | W35: 15000000 | X35: 13750000 | Y35: 12500000 | Z35: 12500000 | AA35: 11250000 | AB35: 10000000 | AC35: 8750000 | AD35: 7500000 | AE35: 6250000 | AF35: 5000000 | AG35: 3750000 | AH35: 2500000 | AI35: 1250000 | AJ35: 0 | AK35: 0 | AL35: 0 | AM35: 32269688
A36: Total Liabilities | B36: =SUM(B29:B35) -> 5.3821041e+08 | C36: =SUM(C29:C35) -> 5.5714579e+08 | D36: =SUM(D29:D35) -> 5.5058787e+08 | E36: =SUM(E29:E35) -> 5.5888606e+08 | F36: =SUM(F29:F35) -> 5.6701445e+08 | G36: =SUM(G29:G35) -> 5.7411024e+08 | I36: =SUM(I29:I35) -> 5.7963432e+08 | J36: =SUM(J29:J35) -> 5.9065674e+08 | K36: =SUM(K29:K35) -> 5.9461803e+08 | L36: =SUM(L29:L35) -> 6.0113042e+08 | M36: =SUM(M29:M35) -> 601287079 | N36: =SUM(N29:N35) -> 6.1052353e+08 | O36: =SUM(O29:O35) -> 6.2599965e+08 | P36: =SUM(P29:P35) -> 6.0463367e+08 | ... AM36: =SUM(AM29:AM35) -> 675936903
A37: Share Capital | B37: 40255131 | C37: 40259131 | D37: 40269131 | E37: 40278631 | F37: 40278631 | G37: 40348613 | H37: 40405113 | I37: 40415613 | J37: 40424113 | K37: 40438613 | L37: 43405773 | M37: 43405773 | N37: 43417973 | O37: 43441473 | P37: 43823017 | Q37: 43848017 | R37: 43862017 | S37: 43870017 | T37: 43908070 | U37: 44156220 | V37: 44535220 | W37: 44920600 | X37: 45864870 | Y37: 56958594 | Z37: 56958594 | AA37: 57195994 | AB37: 59056295 | AC37: 61768521 | AD37: 61868360 | AE37: 61948364 | AF37: 62193868 | AG37: 62430372 | AH37: 62683057 | AI37: 63112257 | AJ37: 63249184 | AK37: 63453084 | AL37: 77650776 | AM37: 77650776
A38: Capital Grants | N38: 0 | O38: 0 | P38: 0 | Q38: 0 | R38: 0 | S38: 0 | T38: 0 | U38: 0 | V38: 0 | W38: 0 | X38: 0 | Y38: 0 | AA38: 0 | AB38: 0 | AC38: 0 | AD38: 0 | AE38: 0 | AF38: 0 | AG38: 0 | AH38: 0 | AI38: 0 | AJ38: 0 | AK38: 0 | AL38: 0
A39: Prior Year Retained Earnigs | B39: 62168209 | C39: 79949462 | D39: 79429462 | E39: 79429462 | F39: 79429462 | G39: 79429462 | H39: 79429462 | I39: 79429462 | J39: 79429462 | K39: 79429462 | L39: 79429462 | M39: 79429462 | N39: 79429462 | O39: 1.1135585e+08 | P39: 1.097824e+08 | Q39: 1.097824e+08 | R39: 1.097824e+08 | S39: 1.097824e+08 | T39: 1.097824e+08 | U39: 1.097824e+08 | V39: 1.097824e+08 | W39: 1.097824e+08 | X39: 1.097824e+08 | Y39: 1.097824e+08 | Z39: =109782396-5695860 -> 104086536 | AA39: 1.097824e+08 | AB39: 1.349417e+08 | AC39: 1.349417e+08 | AD39: 1.3484097e+08 | AE39: 1.3484097e+08 | AF39: 1.3484097e+08 | AG39: 1.3484097e+08 | AH39: 1.3484097e+08 | AI39: 1.3484097e+08 | AJ39: 1.3484097e+08 | AK39: 1.3484097e+08 | AL39: 1.3484097e+08
A40: Current Year Surplus | B40: 30378199 | C40: -344696.99 | D40: 3060095.8 | E40: 13799159 | F40: 16789457 | G40: 21157351 | H40: 31433262 | I40: 36535171 | J40: 41383482 | K40: 45097500 | L40: 44673862 | M40: =109782396-M39 -> 30352934 | N40: 46169769 | O40: 2370418.3 | P40: 5697480.5 | Q40: 17772520 | R40: 21083870 | S40: 24563817 | T40: 28990666 | U40: 31652194 | V40: 33518060 | W40: 36494340 | X40: 38389334 | Y40: 40605850 | Z40: 30754436 | AA40: 37686861 | AB40: -2254042.3 | AC40: 483742.19 | AD40: 4580273 | AE40: 6587426.8 | AF40: 15497256 | AG40: 18740834 | AH40: 23068065 | AI40: 25415826 | AJ40: 27557674 | AK40: 32059951 | AL40: 36947637
...

Sheet soci
B2: 43831 | C2: 43862 | D2: 43891 | E2: 43922 | F2: 43952 | G2: 43983 | H2: 44044 | I2: 44075 | J2: 44105 | K2: 44136 | L2: 44166 | M2: AUDITED 2020 | N2: 44197 | O2: 44228 | P2: 44256 | Q2: 44287 | R2: 44317 | S2: 44348 | T2: 44378 | U2: 44409 | V2: 44440 | W2: 44470 | X2: 44501 | Y2: 44531 | Z2: Aud-21 | AA2: Jan | AB2: Feb | AC2: Mar | AD2: Apr | AE2: May | AF2: Jun | AG2: Jul | AH2: Aug | AI2: Sep | AJ2: Oct | AK2: Nov | AL2: Dec | AM2: Audi-22
A3: Financial Income | B3: =B7+B4 -> 1.2749939e+08 | C3: =C7+C4 -> 18709458 | D3: =D7+D4 -> 29770576 | E3: =E7+E4 -> 47209864 | F3: =F7+F4 -> 56502020 | G3: =G7+G4 -> 67232797 | H3: =H7+H4 -> 91477430 | I3: =I7+I4 -> 1.0267462e+08 | ... AM3: =AM7+AM4 -> 173635517
A4: Financial Income From Loans Portfolio | B4: =B5+B6 -> 1.1897583e+08 | C4: =C5+C6 -> 18709458 | D4: =D5+D6 -> 29687266 | E4: =E5+E6 -> 39026778 | F4: =F5+F6 -> 48318933 | G4: =G5+G6 -> 59049710 | H4: =H5+H6 -> 83248919 | I4: =I5+I6 -> 94430563 | ... AM4: =AM5+AM6 -> 161359018
A5: Interest from Loans Portfolio | B5: 88237053 | C5: 14256551 | D5: 22404470 | E5: 29546756 | F5: 36573295 | G5: 43954479 | H5: 62610917 | I5: 70976749 | J5: 79577788 | K5: 87908946 | L5: 96841536 | M5: =87972218+44825041 -> 132797259 | N5: 1.0510922e+08 | O5: 16932015 | P5: 25733637 | Q5: 34755046 | R5: 42943231 | S5: 51226749 | T5: 59832116 | U5: 67751694 | V5: 76257528 | W5: 84604290 | X5: 92751956 | Y5: 1.0071229e+08 | Z5: 1.4108534e+08 | AA5: 108603722 | AB5: 16141894 | AC5: 25147322 | AD5: 33748990 | AE5: 42293580 | AF5: 51323276 | AG5: 60375856 | AH5: 69738875 | AI5: 79024500 | AJ5: 88113736 | AK5: 1.1701963e+08 | AL5: 1.2974892e+08 | AM5: =91634438+69724580 -> 161359018
A6: Fees&Commision on Loan Portfolio | B6: 30738774 | C6: 4452907.1 | D6: 7282796.4 | E6: 9480022.1 | F6: 11745639 | G6: 15095232 | H6: 20638002 | I6: 23453815 | J6: 26291666 | K6: 28742111 | L6: 31696708 | M6: 8380653 | N6: 34363263 | O6: 4555864.6 | P6: 7175537.3 | Q6: 9829944.7 | R6: 12150690 | S6: 14791836 | T6: 19326042 | U6: 22613841 | V6: 25234306 | W6: 28342590 | X6: 31175578 | Y6: 34394069 | AA6: 37264091 | AB6: 5856630.6 | AC6: 10076542 | AD6: 14877867 | AE6: 18877696 | AF6: 22480959 | AG6: 25970432 | AH6: 30078146 | AI6: 34114566 | AJ6: 37906039 | AK6: 23264618 | AL6: 25934003
A7: Financial Income from Investments | B7: =SUM(B8:B11) -> 8523562.9 | C7: =SUM(C8:C11) -> 0 | D7: =SUM(D8:D11) -> 83309.86 | E7: =SUM(E8:E11) -> 8183086.5 | F7: =SUM(F8:F11) -> 8183086.5 | G7: =SUM(G8:G11) -> 8183086.5 | H7: =SUM(H8:H11) -> 8228510.7 | I7: =SUM(I8:I11) -> 8244053.4 | ... AM7: =SUM(AM8:AM11) -> 12276499
A8: Government Securities | N8: 0 | O8: 0 | P8: 0 | Q8: 0 | R8: 0 | S8: 0 | T8: 0 | U8: 0 | V8: 0 | W8: 0 | X8: 0 | Y8: 0 | AA8: 0 | AB8: 0 | AC8: 0 | AD8: 0 | AE8: 0 | AF8: 0 | AG8: 0 | AH8: 0 | AI8: 0 | AJ8: 0 | AK8: 0 | AL8: 0
A9: Deposits with Banks & other Financial Institutions | N9: 0 | O9: 0 | P9: 0 | Q9: 0 | R9: 0 | S9: 0 | T9: 0 | U9: 1485962.4 | V9: 1786002.1 | W9: 2020816.4 | X9: 2251320.2 | Y9: 2572367.5 | Z9: 11011358 | AA9: 2893680 | AB9: 465743.74 | AC9: 699018 | AD9: 936031.32 | AE9: 1183662.4 | AF9: 1608274.6 | AG9: 1856167.6 | AH9: 2106773.1 | AI9: 2444676.9 | AJ9: 2765197.1 | AK9: 3015296.1 | AL9: 3505009.6 | AM9: 11401799
A10: Other Investments | B10: 8523562.9 | C10: 0 | D10: 83309.86 | E10: 8183086.5 | F10: 8183086.5 | G10: 8183086.5 | H10: 8228510.7 | I10: 8244053.4 | J10: 8316647.3 | K10: 8316647.3 | L10: 8374696.2 | N10: 8380634.7 | O10: 321265.08 | P10: 505122.61 | Q10: 8625644.2 | R10: 8843984.5 | S10: 9188985.1 | T10: 9450134.8 | U10: 8201701.1 | V10: 8201701.1 | W10: 8201701.1 | X10: 8201701.1 | Y10: 8362201.1 | AA10: 8362201.1 | AB10: 0 | AC10: 0 | AD10: 0 | AE10: 0 | AF10: 7685404.2 | AG10: 7685404.2 | AH10: 7685404.2 | AI10: 7860450.2 | AJ10: 7860450.2 | AK10: 7860450.2 | AL10: 7896789.6
A11: Other Operating Income | M11: 855540 | N11: 4980195.7 | O11: 813962.65 | P11: 1356335.4 | Q11: 2164928.7 | R11: 2757333.9 | S11: 3306073 | T11: 3874533.8 | U11: 4202951.7 | V11: 4833630.5 | W11: 5517172 | X11: 6476104.4 | Y11: 7015278.3 | Z11: 1036300 | AA11: 7417565.5 | AB11: 916598.12 | AC11: 1437393.4 | AD11: 1905536.8 | AE11: 2207377.8 | AF11: 2659700.5 | AG11: 3136188.7 | AH11: 3981992.1 | AI11: 4378446.5 | AJ11: 4842374.1 | AK11: 5530745.2 | AL11: 6550799.1 | AM11: 874700
A12: Financial Expenses | B12: =SUM(B13:B18) -> 33561451 | C12: =SUM(C13:C18) -> 5320579 | D12: =SUM(D13:D18) -> 7886293.3 | E12: =SUM(E13:E18) -> 10583400 | F12: =SUM(F13:F18) -> 13187437 | G12: =SUM(G13:G18) -> 15897676 | H12: =SUM(H13:H18) -> 21126564 | I12: =SUM(I13:I18) -> 23793606 | ... AM12: =SUM(AM13:AM18) -> 46903530
A13: Interest Expense on Deposits | B13: 620032.92 | C13: 118114.13 | D13: 3850646.1 | E13: 5144823.1 | F13: 6394001.1 | G13: 7708178.1 | H13: 10341033 | I13: 11752928 | J13: 13040881 | K13: 14360059 | L13: 16919679 | M13: =16000000+919679 -> 16919679 | N13: 18502069 | O13: 3363360 | P13: 4993589.4 | Q13: 6679018.8 | R13: 8289448.2 | S13: 9937377.6 | T13: 11646232 | U13: 13444416 | V13: 15230820 | W13: 16937972 | X13: 18730852 | Y13: 20067226 | Z13: 18775154 | AA13: 22253712 | AB13: 4176916 | AC13: 6127634.9 | AD13: 8087128.9 | AE13: 10157074 | AF13: 12181899 | AG13: 14303015 | AH13: 16420723 | AI13: 18581608 | AJ13: 20743551 | AK13: 22861349 | AL13: 24247139 | AM13: =22329916+1917223 -> 24247139
A14: Cost of External Borrowings | B14: 7044143.9 | C14: 901934.95 | D14: 1299195.2 | E14: 1710582.2 | F14: 2095856.2 | G14: 2480702.1 | H14: 3198596 | I14: 3543630.2 | J14: 3864691.9 | K14: 4183009 | L14: 4478385.8 | M14: 4478386 | N14: 4770337.8 | O14: 570633.57 | P14: 810359.6 | Q14: 1062500 | R14: 1293664.4 | S14: 1519263.7 | T14: 1724743.2 | U14: 1923801.4 | V14: 2109589.1 | W14: 2276541.1 | X14: 2435787.7 | Y14: 2577054.9 | Z14: 3869126.4 | AA14: 2709760.3 | AB14: 252140.42 | AC14: 348030.84 | AD14: 440924.68 | AE14: 517979.48 | AF14: 584332.22 | AG14: 635702.09 | AH14: 675513.74 | AI14: 702054.84 | AJ14: 714897.31 | AK14: 714897.31 | AL14: 714897.31 | AM14: 714897
A15: Dividend Expenses | B15: 13780000 | C15: 2488354 | D15: 0 | E15: 0 | F15: 0 | G15: 0 | H15: 0 | I15: 0 | J15: 0 | K15: 0 | L15: 0 | M15: 4025113 | N15: 0 | O15: 0 | P15: 0 | Q15: 0 | R15: 0 | S15: 0 | T15: 0 | U15: 0 | V15: 0 | W15: 0 | X15: 0 | Y15: 0 | AA15: 0 | AB15: 0 | AC15: 0 | AD15: 0 | AE15: 0 | AF15: 0 | AG15: 0 | AH15: 0 | AI15: 0 | AJ15: 0 | AK15: 0 | AL15: 0
A16: Other Financial Expense | B16: 12117274 | C16: 1812175.9 | D16: 2736451.9 | E16: 3727994.4 | F16: 4697579.2 | G16: 5708796 | H16: 7586935 | I16: 8497048 | J16: 9449505.8 | K16: 10462780 | L16: 11463012 | N16: 12386402 | O16: 2729483.9 | P16: 4109019.9 | Q16: 5512833.9 | R16: 6898805.9 | S16: 8306150.5 | T16: 9708036.9 | U16: 11148887 | V16: 12545093 | W16: 13908809 | X16: 15358107 | Y16: 16748043 | AA16: 18497130 | AB16: 3571773.3 | AC16: 5490604 | AD16: 7250470.7 | AE16: 9180747.3 | AF16: 11004712 | AG16: 12711581 | AH16: 14589931 | AI16: 16416600 | AJ16: 18244557 | AK16: 20060914 | AL16: 21941494 | AM16: 1941494
A17: Fees & Commision Expense | N17: 0 | O17: 0 | P17: 0 | Q17: 0 | R17: 0 | S17: 0 | T17: 0 | U17: 0 | V17: 0 | W17: 0 | X17: 0 | Y17: 0 | AA17: 0 | AB17: 0 | AC17: 0 | AD17: 0 | AE17: 0 | AF17: 0 | AG17: 0 | AH17: 0 | AI17: 0 | AJ17: 0 | AK17: 0 | AL17: 0
A18: Other Expenses | M18: 10000000 | N18: 0 | O18: 0 | P18: 0 | Q18: 0 | R18: 0 | S18: 0 | T18: 0 | U18: 0 | V18: 0 | W18: 0 | X18: 0 | Y18: 0 | Z18: =1733808.34+15000000 -> 16733808 | AA18: 0 | AB18: 0 | AC18: 0 | AD18: 0 | AE18: 0 | AF18: 0 | AG18: 0 | AH18: 0 | AI18: 0 | AJ18: 0 | AK18: 0 | AL18: 0 | AM18: =20000000 -> 20000000
A19: Net Financial Income | B19: =B3-B12 -> 93937939 | C19: =C3-C12 -> 13388880 | D19: =D3-D12 -> 21884283 | E19: =E3-E12 -> 36626465 | F19: =F3-F12 -> 43314583 | G19: =G3-G12 -> 51335121 | H19: =H3-H12 -> 70350866 | I19: =I3-I12 -> 78881010 | ... AM19: =AM3-AM12 -> 126731987
A20: Allowance for Loan Loss | N20: 3333334 | O20: 666667 | P20: 1000000 | Q20: 1333333.3 | R20: 1666666.7 | S20: 2000000 | T20: 2333333.3 | U20: 2666666.7 | V20: 3000000 | W20: 3333333.3 | X20: 3666666.7 | Y20: 1000000 | Z20: 1014235 | AA20: 1430902.7 | AB20: 833333.3 | AC20: 1250000 | AD20: 1666666.7 | AE20: 2083333.3 | AF20: 2500000 | AG20: 2916666.7 | AH20: 3333333.3 | AI20: 3750000 | AJ20: 4166666.7 | AK20: 4583333.3 | AL20: 1000000 | AM20: 1000000
A21: Provision for Loan Losses | B21: 5730914.5 | C21: 500000 | D21: 750000 | E21: 1000000 | F21: 1250000 | G21: 1500000 | H21: 2000000 | I21: 2250000 | J21: 2500000 | K21: 2750000 | L21: 3000000 | M21: 3000000 | N21: 3333334 | O21: 666667 | P21: 1000000 | Q21: 1333333.3 | R21: 1666666.7 | S21: 2000000 | T21: 2333333.3 | U21: 2666666.7 | V21: 3000000 | W21: 3333333.3 | X21: 3666666.7 | Y21: 1000000 | AA21: 1430902.7 | AB21: 833333.3 | AC21: 1250000 | AD21: 1666666.7 | AE21: 2083333.3 | AF21: 2500000 | AG21: 2916666.7 | AH21: 3333333.3 | AI21: 3750000 | AJ21: 4166666.7 | AK21: 4583333.3 | AL21: 1000000 | AM21: 1000000
A22: Value of Loans Recovered | N22: 0 | O22: 0 | P22: 0 | Q22: 0 | R22: 0 | S22: 0 | T22: 0 | U22: 0 | V22: 0 | W22: 0 | X22: 0 | Y22: 0 | AA22: 0 | AB22: 0 | AC22: 0 | AD22: 0 | AE22: 0 | AF22: 0 | AG22: 0 | AH22: 0 | AI22: 0 | AJ22: 0 | AK22: 0 | AL22: 0
A23: Operating Expeses | B23: =SUM(B24:B28) -> 59562291 | C23: =SUM(C24:C28) -> 13406496 | D23: =SUM(D24:D28) -> 18216700 | E23: =SUM(E24:E28) -> 22074219 | F23: =SUM(F24:F28) -> 25567959 | G23: =SUM(G24:G28) -> 29021623 | H23: =SUM(H24:H28) -> 38762092 | I23: =SUM(I24:I28) -> 42971738 | ... AM23: =SUM(AM24:AM28) -> 88709537
A24: Personel Expenses | B24: 22551834 | C24: 5681491.3 | D24: 7854858.2 | E24: 10466624 | F24: 12155740 | G24: 14002226 | H24: 17705295 | I24: 19480934 | J24: 21499057 | K24: 23598113 | L24: 25685540 | M24: 25685540 | N24: 28278998 | O24: 4623062.1 | P24: 7080393.3 | Q24: 9044738.5 | R24: 11263503 | S24: 13539838 | T24: 16030978 | U24: 18241066 | V24: 20711659 | W24: 22979553 | X24: 25051707 | Y24: 27457140 | Z24: 27457140 | AA24: 30131588 | AB24: 5332397 | AC24: 7921822.2 | AD24: 10556415 | AE24: 13073228 | AF24: 16099020 | AG24: 18691493 | AH24: 20948306 | AI24: 23556899 | AJ24: 26105086 | AK24: 28510029 | AL24: 31986086 | AM24: 31986086
A25: Governance Expenses | B25: 7708207.6 | C25: 2236952.9 | D25: 2524491.6 | E25: 2606424.9 | F25: 2777624.9 | G25: 2939339.2 | H25: 3597881.2 | I25: 4089465.2 | J25: 5367042.2 | K25: 6180083.2 | L25: 7102724.5 | M25: 7102725 | N25: 7330668.5 | O25: 2622301.8 | P25: 2978613.8 | Q25: 3588307.3 | R25: 3937914.3 | S25: 4452448 | T25: 5171231 | U25: 5958872 | V25: 6361683 | W25: 7139187 | X25: 9512727 | Y25: 10625484 | Z25: 12156814 | AA25: 12384351 | AB25: 3806569.6 | AC25: 4168985.8 | AD25: 4961210.2 | AE25: 5725299.2 | AF25: 6755879.2 | AG25: 7419672.2 | AH25: 8891151.2 | AI25: 11332979 | AJ25: 12227232 | AK25: 13640174 | AL25: 14569510 | AM25: 14569510
A26: Marketing Expenses | B26: 2214232 | C26: 520470 | D26: 747346 | E26: 752546 | F26: 770246 | G26: 833446 | H26: 1066715 | I26: 1104025 | J26: 1152675 | K26: 1187975 | L26: 2580891 | M26: 2580891 | N26: 2662101 | O26: 138905 | P26: 645765 | Q26: 804470 | R26: 968410 | S26: 1146180 | T26: 1333325 | U26: 1693100 | V26: 2054440 | W26: 2323905 | X26: 2821237 | Y26: 4623127 | Z26: 4623127 | AA26: 4872901 | AB26: 669034 | AC26: 893409 | AD26: 1623919 | AE26: 2230144 | AF26: 2479562 | AG26: 2644950 | AH26: 3105131 | AI26: 3313451 | AJ26: 4236966 | AK26: 4413021 | AL26: 5801064 | AM26: 5801064
A27: Depreciation and Amortization | B27: 2881794 | C27: 387364.4 | D27: 573830.63 | E27: 754378.55 | F27: 1335408.4 | G27: 1747846.5 | H27: 2634462.5 | I27: 2941707.7 | J27: 3242964.5 | K27: 3529147.2 | L27: 4068009.7 | M27: 4068010 | N27: 4353764.2 | O27: 545099.26 | P27: 1091190.4 | Q27: 1467629.3 | R27: 1829129.9 | S27: 2174297.3 | T27: 2522731.5 | U27: 2864619 | V27: 3298047.4 | W27: 3664204.7 | X27: 3989658.5 | Y27: 4556234.5 | Z27: 4556234.5 | AA27: 4892508.2 | AB27: 634537.31 | AC27: 958855.68 | AD27: 1271884.8 | AE27: 1585690 | AF27: 1883886 | AG27: 2186495.6 | AH27: 2521073.7 | AI27: 2894122.2 | AJ27: 3228203.2 | AK27: 3539792.6 | AL27: 4124286.9 | AM27: 4049466
A28: Administrative Expenses | B28: 24206223 | C28: 4580217.9 | D28: 6516173.6 | E28: 7494244.9 | F28: 8528939.9 | G28: 9498765.8 | H28: 13757738 | I28: 15355606 | J28: 16562470 | K28: 18243861 | L28: 21919592 | M28: =22055392+1463012 -> 23518404 | N28: 24910067 | O28: 4993176.2 | P28: 6364220.4 | Q28: 8168296 | R28: 9463827.2 | S28: 10872271 | T28: 13019550 | U28: 14660528 | V28: 17481775 | W28: 19626724 | X28: 20898584 | Y28: 24794047 | Z28: 24796047 | AA28: 29679545 | AB28: 6358207.5 | AC28: 9717191.1 | AD28: 11029532 | AE28: 13418394 | AF28: 16762068 | AG28: 18761640 | AH28: 20022962 | AI28: 21842099 | AJ28: 24245963 | AK28: 25923387 | AL28: 31919521 | AM28: 32303411
A29: Net Operating Income | B29: =B19-B21-B23 -> 28644734 | C29: =C19-C21-C23 -> -517616.97 | D29: =D19-D21-D23 -> 2917583.1 | E29: =E19-E21-E23 -> 13552246 | F29: =F19-F21-F23 -> 16496625 | G29: =G19-G21-G23 -> 20813497 | H29: =H19-H21-H23 -> 29588774 | I29: =I19-I21-I23 -> 33659273 | ... Y29: =Y19-Y21-Y23 -> 40607850 | Z29: =Z19-Z20-Z23 -> 39151309 | AA29: =AA19-AA20-AA23 -> 37688861 | AB29: =AB19-AB20-AB23 -> -2254042.2 | AC29: =AC19-AC20-AC23 -> 483742.23 | AD29: =AD19-AD20-AD23 -> 4580273.1 | AE29: =AE19-AE20-AE23 -> 6590426.8 | AF29: =AF19-AF20-AF23 -> 15506256 | AG29: =AG19-AG20-AG23 -> 18752833 | ... AM29: =AM19-AM20-AM23 -> 37022450
A30: Net Non operating Income/Expense | B30: =B31-B32 -> 0 | C30: =C31-C32 -> 0 | D30: =D31-D32 -> 0 | E30: =E31-E32 -> 0 | F30: =F31-F32 -> 0 | G30: =G31-G32 -> 0 | H30: =H31-H32 -> 0 | I30: =I31-I32 -> 0 | ... AM30: =AM31-AM32 -> 0
A31: Non Operating Income | N31: 0 | O31: 0 | P31: 0 | Q31: 0 | R31: 0 | S31: 0 | T31: 0 | U31: 0 | V31: 0 | W31: 0 | X31: 0 | Y31: 0 | AA31: 0 | AB31: 0 | AC31: 0 | AD31: 0 | AE31: 0 | AF31: 0 | AG31: 0 | AH31: 0 | AI31: 0 | AJ31: 0 | AK31: 0 | AL31: 0
A32: Non Operating Expense | N32: 0 | O32: 0 | P32: 0 | Q32: 0 | R32: 0 | S32: 0 | T32: 0 | U32: 0 | V32: 0 | W32: 0 | X32: 0 | Y32: 0 | AA32: 0 | AB32: 0 | AC32: 0 | AD32: 0 | AE32: 0 | AF32: 0 | AG32: 0 | AH32: 0 | AI32: 0 | AJ32: 0 | AK32: 0 | AL32: 0
A33: Net Income(Before Tax & Donations) | B33: =B29+B30 -> 28644734 | C33: =C29+C30 -> -517616.97 | D33: =D29+D30 -> 2917583.1 | E33: =E29+E30 -> 13552246 | F33: =F29+F30 -> 16496625 | G33: =G29+G30 -> 20813497 | H33: =H29+H30 -> 29588774 | I33: =I29+I30 -> 33659273 | ... AM33: =AM29+AM30 -> 37022450
A34: Taxes | M34: 256662 | N34: 0 | O34: 0 | P34: 0 | Q34: 0 | R34: 0 | S34: 0 | T34: 0 | U34: 0 | V34: 0 | W34: 0 | X34: 0 | Y34: 0 | Z34: 708263.53 | AA34: 0 | AB34: 0 | AC34: 0 | AD34: 0 | AE34: 0 | AF34: 0 | AG34: 0 | AH34: 0 | AI34: 0 | AJ34: 0 | AK34: 0 | AL34: 0 | AM34: 788161
A35: Net Income(After Tax Before Donations) | B35: =B33-B34 -> 28644734 | C35: =C33-C34 -> -517616.97 | D35: =D33-D34 -> 2917583.1 | E35: =E33-E34 -> 13552246 | F35: =F33-F34 -> 16496625 | G35: =G33-G34 -> 20813497 | H35: =H33-H34 -> 29588774 | I35: =I33-I34 -> 33659273 | ... AM35: =AM33-AM34 -> 36234289
A36: Donations | B36: 0 | C36: 0 | D36: 135800 | E36: 135800 | F36: 135800 | G36: 135800 | H36: 135800 | I36: 135800 | J36: 135800 | K36: 135800 | L36: 135800 | N36: -135800 | O36: 0 | P36: 0 | Q36: 0 | R36: 0 | S36: -2000 | T36: -2000 | U36: -2000 | V36: -2000 | W36: -2000 | X36: -2000 | Y36: -2000 | AA36: -2000 | AB36: 0 | AC36: 0 | AD36: 0 | AE36: -3000 | AF36: -9000 | AG36: -12000 | AH36: -15000 | AI36: -17000 | AJ36: -17000 | AK36: -383890 | AL36: -383890
A37: Net Income/(After Tax & Donations) | B37: =B35-B36 -> 28644734 | C37: =C35-C36 -> -517616.97 | D37: =D35-D36 -> 2781783.1 | E37: =E35-E36 -> 13416446 | F37: =F35-F36 -> 16360825 | G37: =G35-G36 -> 20677697 | H37: =H35-H36 -> 29452974 | I37: =I35-I36 -> 33523473 | ... AM37: =AM35-AM36 -> 36234289
AM39: =37022458-AM29 -> 8
N73: 7

Sheet financials
B1: 43831 | C1: 43862 | D1: 43891 | E1: 43922 | F1: 43952 | G1: 43983 | H1: 44044 | I1: 44075 | J1: 44105 | K1: 44136 | L1: 44166 | M1: AUDITED 2020 | N1: 44197 | O1: 44228 | P1: 44256 | Q1: 44287 | R1: 44317 | S1: 44348 | T1: 44378 | U1: 44409 | V1: 44440 | W1: 44470 | X1: 44501 | Y1: 44531 | Z1: Aud-21 | AA1: 44562 | AB1: Feb | AC1: Mar | AD1: Apr | AE1: May | AF1: Jun | AG1: Jul | AH1: Aug | AI1: Sep | AJ1: Oct | AK1: Nov | AL1: Dec | AM1: Aud-22
A2: Membership
A3: Total Assets | B3: =sofp!B25 -> 7.2646438e+08 | C3: =sofp!C25 -> 7.2872979e+08 | D3: =sofp!D25 -> 7.0915959e+08 | E3: =sofp!E25 -> 7.2785634e+08 | F3: =sofp!F25 -> 7.3862503e+08 | G3: =sofp!G25 -> 7.4980869e+08 | H3: =sofp!H25 -> 0 | I3: =sofp!I25 -> 7.7611482e+08 | ... AS3: =sofp!AS25 -> 0
A4: Total Deposits | B4: =sofp!B29 -> 4.8483264e+08 | C4: =sofp!C29 -> 5.0117274e+08 | D4: =sofp!D29 -> 4.9546328e+08 | E4: =sofp!E29 -> 5.029845e+08 | F4: =sofp!F29 -> 5.1034049e+08 | G4: =sofp!G29 -> 5.1496934e+08 | H4: =sofp!H29 -> 0 | I4: =sofp!I29 -> 5.2102002e+08 | ... AS4: =sofp!AS29 -> 0
A5: Deposits-Members(BOSA) | B5: =sofp!B28 -> 3.9392435e+08 | C5: =sofp!C28 -> 3.9767028e+08 | D5: =sofp!D28 -> 4.0155285e+08 | E5: =sofp!E28 -> 404779275 | F5: =sofp!F28 -> 4.0825488e+08 | G5: =sofp!G28 -> 4.1213396e+08 | H5: =sofp!H28 -> 4.2245455e+08 | I5: =sofp!I28 -> 4.2519846e+08 | ... AS5: =sofp!AS28 -> 0
A6: Deposits-Customers(FOSA) | B6: =sofp!B26 + sofp!B28 -> 4.7545523e+08 | C6: =sofp!C26 + sofp!C28 -> 4.9154288e+08 | D6: =sofp!D26 + sofp!D28 -> 4.8532825e+08 | E6: =sofp!E26 + sofp!E28 -> 4.9221537e+08 | F6: =sofp!F26 + sofp!F28 -> 4.9689055e+08 | G6: =sofp!G26 + sofp!G28 -> 5.0136248e+08 | H6: =sofp!H26 + sofp!H28 -> 5.0976692e+08 | I6: =sofp!I26 + sofp!I28 -> 5.0867563e+08 | ... AS6: =sofp!AS26 + sofp!AS28 -> 0
A7: External Borrowing | B7: =sofp!B35 -> 41250000 | C7: =sofp!C35 -> 40000000 | D7: =sofp!D35 -> 38750000 | E7: =sofp!E35 -> 37500000 | F7: =sofp!F35 -> 36250000 | G7: =sofp!G35 -> 35000000 | H7: =sofp!H35 -> 32500000 | I7: =sofp!I35 -> 31250000 | ... AS7: =sofp!AS35 -> 0
A8: Short term liabilities | B8: =SUM(sofp!B30:B34) -> 12127773 | C8: =SUM(sofp!C30:C34) -> 15973055 | D8: =SUM(sofp!D30:D34) -> 16374590 | E8: =SUM(sofp!E30:E34) -> 18401556 | F8: =SUM(sofp!F30:F34) -> 20423966 | G8: =SUM(sofp!G30:G34) -> 24140892 | H8: =SUM(sofp!H30:H34) -> 26839494 | I8: =SUM(sofp!I30:I34) -> 27364294 | ... AS8: =SUM(sofp!AS30:AS34) -> 0
A10: Share Capital and Reserves
A11: Core Capital | B11: =B14 -> 1.7447397e+08 | C11: =C14 -> 1.6884974e+08 | D11: =D14 -> 1.7174454e+08 | E11: =E14 -> 1.824931e+08 | F11: =F14 -> 1.854834e+08 | G11: =G14 -> 1.8992127e+08 | H11: =H14 -> 2.0665158e+08 | I11: =I14 -> 2.1176886e+08 | ... AS11: =AS14 -> 0
A12: Institutional Capital | B12: =B11 - B15 -> 1.3421884e+08 | C12: =C11 - C15 -> 1.2859061e+08 | D12: =D11 - D15 -> 1.314754e+08 | E12: =E11 - E15 -> 1.4221447e+08 | F12: =F11 - F15 -> 1.4520477e+08 | G12: =G11 - G15 -> 1.4957266e+08 | H12: =H11 - H15 -> 1.6624646e+08 | I12: =I11 - I15 -> 1.7135325e+08 | ... AS12: =AS11 - AS15 -> 0
A14: Total Capital | B14: =SUM(B15:B17) + B19 -> 1.7447397e+08 | C14: =SUM(C15:C17) + C19 -> 1.6884974e+08 | D14: =SUM(D15:D17) + D19 -> 1.7174454e+08 | E14: =SUM(E15:E17) + E19 -> 1.824931e+08 | F14: =SUM(F15:F17) + F19 -> 1.854834e+08 | G14: =SUM(G15:G17) + G19 -> 1.8992127e+08 | H14: =SUM(H15:H17) + H19 -> 2.0665158e+08 | I14: =SUM(I15:I17) + I19 -> 2.1176886e+08 | ... AS14: =SUM(AS15:AS17) + AS19 -> 0
A15: Members Share Capital | B15: =sofp!B37 -> 40255131 | C15: =sofp!C37 -> 40259131 | D15: =sofp!D37 -> 40269131 | E15: =sofp!E37 -> 40278631 | F15: =sofp!F37 -> 40278631 | G15: =sofp!G37 -> 40348613 | H15: =sofp!H37 -> 40405113 | I15: =sofp!I37 -> 40415613 | ... AS15: =sofp!AS37 -> 0
A16: Retained Earnings | B16: =sofp!B39 + sofp!B40 -> 92546408 | C16: =sofp!C39 + sofp!C40 -> 79604765 | D16: =sofp!D39 + sofp!D40 -> 82489558 | E16: =sofp!E39 + sofp!E40 -> 93228621 | F16: =sofp!F39 + sofp!F40 -> 96218919 | G16: =sofp!G39 + sofp!G40 -> 1.0058681e+08 | H16: =sofp!H39 + sofp!H40 -> 1.1086272e+08 | I16: =sofp!I39 + sofp!I40 -> 1.1596463e+08 | ... AS16: =sofp!AS39 + sofp!AS40 -> 0
A17: Statutory Reserves | B17: =sofp!B41 -> 31319332 | C17: =sofp!C41 -> 38632745 | D17: =sofp!D41 -> 38632745 | E17: =sofp!E41 -> 38632745 | F17: =sofp!F41 -> 38632745 | G17: =sofp!G41 -> 38632745 | H17: =sofp!H41 -> 38632745 | I17: =sofp!I41 -> 38632745 | ... AS17: =sofp!AS41 -> 0
A18: Supplementary Capital & Reserves
A19: Capital Reserves | B19: =sofp!B42 -> 10353102 | C19: =sofp!C42 -> 10353102 | D19: =sofp!D42 -> 10353102 | E19: =sofp!E42 -> 10353102 | F19: =sofp!F42 -> 10353102 | G19: =sofp!G42 -> 10353102 | H19: =sofp!H42 -> 16750995 | I19: =sofp!I42 -> 16755875 | ... AS19: =sofp!AS42 -> 0
A20: Proposed Dividends | B20: =sofp!B44 -> 13780000 | C20: =sofp!C44 -> 2488354 | D20: =sofp!D44 -> 0 | E20: =sofp!E44 -> 0 | F20: =sofp!F44 -> 0 | G20: =sofp!G44 -> 0 | H20: =sofp!H44 -> 0 | I20: =sofp!I44 -> 0 | ... AS20: =sofp!AS44 -> 0
A22: Investments | B22: =SUM(B23:B24) -> 25632908 | C22: =SUM(C23:C24) -> 25982908 | D22: =SUM(D23:D24) -> 26401254 | E22: =SUM(E23:E24) -> 26751254 | F22: =SUM(F23:F24) -> 27101254 | G22: =SUM(G23:G24) -> 27451254 | H22: =SUM(H23:H24) -> 28151254 | I22: =SUM(I23:I24) -> 28516797 | ... AS22: =SUM(AS23:AS24) -> 0
A23: Investment in Coop Bank, Kuscco | B23: =sofp!B10 -> 0 | C23: =sofp!C10 -> 0 | D23: =sofp!D10 -> 13172819 | E23: =sofp!E10 -> 13522819 | F23: =sofp!F10 -> 13872819 | G23: =sofp!G10 -> 14222819 | H23: =sofp!H10 -> 14922819 | I23: =sofp!I10 -> 15288362 | ... AS23: =sofp!AS10 -> 0
A24: Equity investments (at Cost) | B24: =sofp!B9 + sofp!B11 -> 25632908 | C24: =sofp!C9 + sofp!C11 -> 25982908 | D24: =sofp!D9 + sofp!D11 -> 13228435 | E24: =sofp!E9 + sofp!E11 -> 13228435 | F24: =sofp!F9 + sofp!F11 -> 13228435 | G24: =sofp!G9 + sofp!G11 -> 13228435 | H24: =sofp!H9 + sofp!H11 -> 13228435 | I24: =sofp!I9 + sofp!I11 -> 13228435 | ... AS24: =sofp!AS9 + sofp!AS11 -> 0
A26: Net Loans & Advances | B26: =B27 - B28 -> 3.0628885e+08 | C26: =C27 - C28 -> 3.0062531e+08 | D26: =D27 - D28 -> 2.9905464e+08 | E26: =E27 - E28 -> 2.9281998e+08 | F26: =F27 - F28 -> 2.88687e+08 | G26: =G27 - G28 -> 3.0592353e+08 | H26: =H27 - H28 -> 3.2563884e+08 | I26: =I27 - I28 -> 3.365163e+08 | ... AS26: =AS27 - AS28 -> 0
A27: Gross Loans & Advances | B27: =sofp!B13 -> 3.2801976e+08 | C27: =sofp!C13 -> 3.2260622e+08 | D27: =sofp!D13 -> 3.2128555e+08 | E27: =sofp!E13 -> 3.1530089e+08 | F27: =sofp!F13 -> 3.1141792e+08 | G27: =sofp!G13 -> 3.2890444e+08 | H27: =sofp!H13 -> 3.4911976e+08 | I27: =sofp!I13 -> 3.6024721e+08 | ... AS27: =sofp!AS13 -> 0
A28: Allowance for loan loss | B28: =sofp!B14 -> 21730915 | C28: =sofp!C14 -> 21980915 | D28: =sofp!D14 -> 22230915 | E28: =sofp!E14 -> 22480915 | F28: =sofp!F14 -> 22730915 | G28: =sofp!G14 -> 22980915 | H28: =sofp!H14 -> 23480915 | I28: =sofp!I14 -> 23730915 | ... AS28: =sofp!AS14 -> 0
A30: Non-Performing loans
A31: Renegotiated loans
A32: Required Loan loss provision
A33: Cash and cash equivalents | B33: =sofp!B3 -> 1.0674812e+08 | C33: =sofp!C3 -> 1.1511345e+08 | D33: =sofp!D3 -> 1.1088763e+08 | E33: =sofp!E3 -> 1.3694146e+08 | F33: =sofp!F3 -> 1.5464545e+08 | G33: =sofp!G3 -> 1.6130515e+08 | H33: =sofp!H3 -> 0 | I33: =sofp!I3 -> 1.2268365e+08 | ... AS33: =sofp!AS3 -> 0
A35: Non-Earning Assets | B35: =sofp!B19 + sofp!B6 -> 2.8779451e+08 | C35: =sofp!C19 + sofp!C6 -> 2.8700813e+08 | D35: =sofp!D19 + sofp!D6 -> 2.8598889e+08 | E35: =sofp!E19 + sofp!E6 -> 2.8486646e+08 | F35: =sofp!F19 + sofp!F6 -> 2.8206414e+08 | G35: =sofp!G19 + sofp!G6 -> 2.6935158e+08 | H35: =sofp!H19 + sofp!H6 -> 14324897 | I35: =sofp!I19 + sofp!I6 -> 3.0368644e+08 | ... AS35: =sofp!AS19 + sofp!AS6 -> 0
A36: Property and Equipment | B36: =sofp!B21 -> 41840594 | C36: =sofp!C21 -> 41696082 | D36: =sofp!D21 -> 41536086 | E36: =sofp!E21 -> 41381252 | F36: =sofp!F21 -> 42142694 | G36: =sofp!G21 -> 44074482 | H36: =sofp!H21 -> 44796534 | I36: =sofp!I21 -> 44718933 | ... AS36: =sofp!AS21 -> 0
A37: Land and Building
A39: Turnover | B39: =SUM(B40:B42) -> 1.2749939e+08 | C39: =SUM(C40:C42) -> 18709458 | D39: =SUM(D40:D42) -> 29770576 | E39: =SUM(E40:E42) -> 47209864 | F39: =SUM(F40:F42) -> 56502020 | G39: =SUM(G40:G42) -> 67232797 | H39: =SUM(H40:H42) -> 91477430 | I39: =SUM(I40:I42) -> 1.0267462e+08 | ... AS39: =SUM(AS40:AS42) -> 0
A40: Loan Interest | B40: =soci!B5 -> 88237053 | C40: =soci!C5 -> 14256551 | D40: =soci!D5 -> 22404470 | E40: =soci!E5 -> 29546756 | F40: =soci!F5 -> 36573295 | G40: =soci!G5 -> 43954479 | H40: =soci!H5 -> 62610917 | I40: =soci!I5 -> 70976749 | ... AM40: =soci!AM5 -> 161359018 | AN40: =soci!AO5 -> 0 | AO40: =soci!AP5 -> 0 | AP40: =soci!AQ5 -> 0 | AQ40: =soci!AR5 -> 0 | AR40: =soci!AS5 -> 0 | AS40: =soci!AT5 -> 0
A41: Income from Investments | B41: =soci!B7 -> 8523562.9 | C41: =soci!C7 -> 0 | D41: =soci!D7 -> 83309.86 | E41: =soci!E7 -> 8183086.5 | F41: =soci!F7 -> 8183086.5 | G41: =soci!G7 -> 8183086.5 | H41: =soci!H7 -> 8228510.7 | I41: =soci!I7 -> 8244053.4 | ... AM41: =soci!AM7 -> 12276499 | AN41: =soci!AO7 -> 0 | AO41: =soci!AP7 -> 0 | AP41: =soci!AQ7 -> 0 | AQ41: =soci!AR7 -> 0 | AR41: =soci!AS7 -> 0 | AS41: =soci!AT7 -> 0
A42: Fees & Commissions | B42: =soci!B6 -> 30738774 | C42: =soci!C6 -> 4452907.1 | D42: =soci!D6 -> 7282796.4 | E42: =soci!E6 -> 9480022.1 | F42: =soci!F6 -> 11745639 | G42: =soci!G6 -> 15095232 | H42: =soci!H6 -> 20638002 | I42: =soci!I6 -> 23453815 | ... AM42: =soci!AM6 -> 0 | AN42: =soci!AO6 -> 0 | AO42: =soci!AP6 -> 0 | AP42: =soci!AQ6 -> 0 | AQ42: =soci!AR6 -> 0 | AR42: =soci!AS6 -> 0 | AS42: =soci!AT6 -> 0
A43: Average yield on loans | B43: =B40/B27 -> 0.2689992 | C43: =C40/C27 -> 0.044191805 | D43: =D40/D27 -> 0.069733824 | E43: =E40/E27 -> 0.093709711 | F43: =F40/F27 -> 0.1174412 | G43: =G40/G27 -> 0.13363905 | H43: =H40/H27 -> 0.17933937 | I43: =I40/I27 -> 0.19702234 | ... AS43: =AS40/AS27 -> #DIV/0!
A45: Financial and operating Costs
A46: Interest expense on deposits | B46: =soci!B13 + soci!B16 -> 12737307 | C46: =soci!C13 + soci!C16 -> 1930290 | D46: =soci!D13 + soci!D16 -> 6587098 | E46: =soci!E13 + soci!E16 -> 8872817.5 | F46: =soci!F13 + soci!F16 -> 11091580 | G46: =soci!G13 + soci!G16 -> 13416974 | H46: =soci!H13 + soci!H16 -> 17927968 | I46: =soci!I13 + soci!I16 -> 20249976 | ... AM46: =soci!AM13 + soci!AM16 -> 26188633 | AN46: =soci!AO13 + soci!AO16 -> 0 | AO46: =soci!AP13 + soci!AP16 -> 0 | AP46: =soci!AQ13 + soci!AQ16 -> 0 | AQ46: =soci!AR13 + soci!AR16 -> 0 | AR46: =soci!AS13 + soci!AS16 -> 0 | AS46: =soci!AT13 + soci!AT16 -> 0
A47: Dividend expense on share capital | B47: =soci!B15 -> 13780000 | C47: =soci!C15 -> 2488354 | D47: =soci!D15 -> 0 | E47: =soci!E15 -> 0 | F47: =soci!F15 -> 0 | G47: =soci!G15 -> 0 | H47: =soci!H15 -> 0 | I47: =soci!I15 -> 0 | ... AM47: =soci!AM15 -> 0 | AN47: =soci!AO15 -> 0 | AO47: =soci!AP15 -> 0 | AP47: =soci!AQ15 -> 0 | AQ47: =soci!AR15 -> 0 | AR47: =soci!AS15 -> 0 | AS47: =soci!AT15 -> 0
A48: Interest expense on borrowed funds | B48: =soci!B14 -> 7044143.9 | C48: =soci!C14 -> 901934.95 | D48: =soci!D14 -> 1299195.2 | E48: =soci!E14 -> 1710582.2 | F48: =soci!F14 -> 2095856.2 | G48: =soci!G14 -> 2480702.1 | H48: =soci!H14 -> 3198596 | I48: =soci!I14 -> 3543630.2 | ... AM48: =soci!AM14 -> 714897 | AN48: =soci!AO14 -> 0 | AO48: =soci!AP14 -> 0 | AP48: =soci!AQ14 -> 0 | AQ48: =soci!AR14 -> 0 | AR48: =soci!AS14 -> 0 | AS48: =soci!AT14 -> 0
...

Sheet caels
A1: TABASAMU SACCO SOCIETY | C1: 43831 | D1: 43862 | E1: 43891 | F1: 43922 | G1: 43952 | H1: 43983 | I1: 44044 | J1: 44075 | K1: 44105 | L1: 44136 | M1: 44166 | N1: AUDITED 2020 | O1: 44197 | P1: 44228 | Q1: 44256 | R1: 44287 | S1: 44317 | T1: 44348 | U1: 44378 | V1: 44409 | W1: 44440 | X1: 44470 | Y1: 44501 | Z1: 44531 | AA1: Aud-21 | AB1: 44562 | AC1: Feb | AD1: Mar | AE1: Apr | AF1: May | AG1: Jun | AH1: Jul | AI1: Aug | AJ1: Sep | AK1: Oct | AL1: Nov | AM1: Dec | AN1: Aud-22
A2: CAPITAL ADEQUACY
A3: Core Capital | B3: > Kshs. 10 Million | C3: =financials!B11 -> 1.7447397e+08 | D3: =financials!C11 -> 1.6884974e+08 | E3: =financials!D11 -> 1.7174454e+08 | F3: =financials!E11 -> 1.824931e+08 | G3: =financials!F11 -> 1.854834e+08 | H3: =financials!G11 -> 1.8992127e+08 | I3: =financials!H11 -> 2.0665158e+08 | J3: =financials!I11 -> 2.1176886e+08 | ... AN3: =financials!AM11 -> 158463575 | AO3: =financials!#REF! -> #REF! | AP3: =financials!AN11 -> 0 | AQ3: =financials!AO11 -> 0 | AR3: =financials!AP11 -> 0 | AS3: =financials!AQ11 -> 0 | AT3: =financials!AR11 -> 0 | AU3: =financials!AS11 -> 0 | AV3: =financials!AT11 -> 0 | AW3: =financials!AU11 -> 0 | AX3: =financials!AV11 -> 0
A4: Core Capital to Total Assets | B4: Min. 10% | C4: =financials!B11 /financials!B3 -> 0.24016865 | D4: =financials!C11 /financials!C3 -> 0.23170419 | E4: =financials!D11 /financials!D3 -> 0.24218038 | F4: =financials!E11 /financials!E3 -> 0.25072681 | G4: =financials!F11 /financials!F3 -> 0.25111984 | H4: =financials!G11 /financials!G3 -> 0.25329297 | I4: =financials!H11 /financials!H3 -> #DIV/0! | J4: =financials!I11 /financials!I3 -> 0.27285765 | ... AN4: =financials!AM11 /financials!AM3 -> 0.15061907 | AO4: =financials!#REF! /financials!#REF! -> #REF! | AP4: =financials!AN11 /financials!AN3 -> #DIV/0! | AQ4: =financials!AO11 /financials!AO3 -> #DIV/0! | AR4: =financials!AP11 /financials!AP3 -> #DIV/0! | AS4: =financials!AQ11 /financials!AQ3 -> #DIV/0! | AT4: =financials!AR11 /financials!AR3 -> #DIV/0! | AU4: =financials!AS11 /financials!AS3 -> #DIV/0! | AV4: =financials!AT11 /financials!AT3 -> #DIV/0! | AW4: =financials!AU11 /financials!AU3 -> #DIV/0! | AX4: =financials!AV11 /financials!AV3 -> #DIV/0!
A5: Core Capital to Total Deposits | B5: Min. 8% | C5: =financials!B11 /financials!B4 -> 0.35986433 | D5: =financials!C11 /financials!C4 -> 0.33690927 | E5: =financials!D11 /financials!D4 -> 0.34663424 | F5: =financials!E11 /financials!E4 -> 0.36282052 | G5: =financials!F11 /financials!F4 -> 0.36345029 | H5: =financials!G11 /financials!G4 -> 0.36880112 | I5: =financials!H11 /financials!H4 -> #DIV/0! | J5: =financials!I11 /financials!I4 -> 0.40645053 | ... AN5: =financials!AM11 /financials!AM4 -> 0.25521648 | AO5: =financials!#REF! /financials!#REF! -> #REF! | AP5: =financials!AN11 /financials!AN4 -> #DIV/0! | AQ5: =financials!AO11 /financials!AO4 -> #DIV/0! | AR5: =financials!AP11 /financials!AP4 -> #DIV/0! | AS5: =financials!AQ11 /financials!AQ4 -> #DIV/0! | AT5: =financials!AR11 /financials!AR4 -> #DIV/0! | AU5: =financials!AS11 /financials!AS4 -> #DIV/0! | AV5: =financials!AT11 /financials!AT4 -> #DIV/0! | AW5: =financials!AU11 /financials!AU4 -> #DIV/0! | AX5: =financials!AV11 /financials!AV4 -> #DIV/0!
A6: Institutional Capital to Total Assets | B6: Min 8% | C6: =financials!B12 /financials!B4 -> 0.27683541 | D6: =financials!C12 /financials!C4 -> 0.25657942 | E6: =financials!D12 /financials!D4 -> 0.26535852 | F6: =financials!E12 /financials!E4 -> 0.28274125 | G6: =financials!F12 /financials!F4 -> 0.28452527 | H6: =financials!G12 /financials!G4 -> 0.29044964 | I6: =financials!H12 /financials!H4 -> #DIV/0! | J6: =financials!I12 /financials!I4 -> 0.32888036 | ... AN6: =financials!AM12 /financials!AM4 -> 0.13015457 | AO6: =financials!#REF! /financials!#REF! -> #REF! | AP6: =financials!AN12 /financials!AN4 -> #DIV/0! | AQ6: =financials!AO12 /financials!AO4 -> #DIV/0! | AR6: =financials!AP12 /financials!AP4 -> #DIV/0! | AS6: =financials!AQ12 /financials!AQ4 -> #DIV/0! | AT6: =financials!AR12 /financials!AR4 -> #DIV/0! | AU6: =financials!AS12 /financials!AS4 -> #DIV/0! | AV6: =financials!AT12 /financials!AT4 -> #DIV/0! | AW6: =financials!AU12 /financials!AU4 -> #DIV/0! | AX6: =financials!AV12 /financials!AV4 -> #DIV/0!
A7: ASSET QUALITY
A8: A/LNPL30
A9: NPL30
A10: EARNINGS
A11: ROA | C11: =soci!B33 /sofp!B25 -> 0.039430335 | D11: =soci!C33 /sofp!C25 -> -0.00071030027 | E11: =soci!D33 /sofp!D25 -> 0.0041141418 | F11: =soci!E33 /sofp!E25 -> 0.018619397 | G11: =soci!F33 /sofp!F25 -> 0.022334234 | H11: =soci!G33 /sofp!G25 -> 0.027758411 | I11: =soci!H33 /sofp!H25 -> #DIV/0! | J11: =soci!I33 /sofp!I25 -> 0.043368934 | ... AX11: =soci!AW33 /sofp!AW25 -> #DIV/0!
A12: Cost Income Ratio | C12: =soci!B23 /sofp!B19 -> 0.2071481 | D12: =soci!C23 /sofp!C19 -> 0.046788669 | E12: =soci!D23 /sofp!D19 -> 0.063803383 | F12: =soci!E23 /sofp!E19 -> 0.077589741 | G12: =soci!F23 /sofp!F19 -> 0.089218192 | H12: =soci!G23 /sofp!G19 -> 0.10095314 | I12: =soci!H23 /sofp!H19 -> #DIV/0! | J12: =soci!I23 /sofp!I19 -> 0.15023331 | ... AX12: =soci!AW23 /sofp!AW19 -> #DIV/0!
A13: Operating Expense Ratio | C13: =(soci!B12 + soci!B23) / ((sofp!B25 + sofp!C25)/2) -> 0.12798806 | D13: =(soci!C12 + soci!C23) / ((sofp!C25 + sofp!D25)/2) -> 0.026048006 | E13: =(soci!D12 + soci!D23) / ((sofp!D25 + sofp!E25)/2) -> 0.036329442 | F13: =(soci!E12 + soci!E23) / ((sofp!E25 + sofp!F25)/2) -> 0.044538743 | G13: =(soci!F12 + soci!F23) / ((sofp!F25 + sofp!G25)/2) -> 0.052075406 | H13: =(soci!G12 + soci!G23) / ((sofp!G25 + sofp!H25)/2) -> 0.11981536 | I13: =(soci!H12 + soci!H23) / ((sofp!H25 + sofp!I25)/2) -> 0.15432937 | J13: =(soci!I12 + soci!I23) / ((sofp!I25 + sofp!J25)/2) -> 0.085176377 | ... AX13: =(soci!AW12 + soci!AW23) / ((sofp!AW25 + sofp!AX25)/2) -> #DIV/0!
A14: LIQUIDITY
A15: Min Liquidity Ratio | B15: Min 15% | C15: =financials!B33/(financials!B8+financials!B6) -> 0.21893323 | D15: =financials!C33/(financials!C8+financials!C6) -> 0.2268174 | E15: =financials!D33/(financials!D8+financials!D6) -> 0.22102252 | F15: =financials!E33/(financials!E8+financials!E6) -> 0.26818826 | G15: =financials!F33/(financials!F8+financials!F6) -> 0.29893893 | H15: =financials!G33/(financials!G8+financials!G6) -> 0.3069536 | I15: =financials!H33/(financials!H8+financials!H6) -> 0 | J15: =financials!I33/(financials!I8+financials!I6) -> 0.22887036 | ... AN15: =financials!AM33/(financials!AM8+financials!AM6) -> 0.18570797 | AO15: =financials!#REF!/(financials!#REF!+financials!#REF!) -> #REF! | AP15: =financials!AN33/(financials!AN8+financials!AN6) -> #DIV/0! | AQ15: =financials!AO33/(financials!AO8+financials!AO6) -> #DIV/0! | AR15: =financials!AP33/(financials!AP8+financials!AP6) -> #DIV/0! | AS15: =financials!AQ33/(financials!AQ8+financials!AQ6) -> #DIV/0! | AT15: =financials!AR33/(financials!AR8+financials!AR6) -> #DIV/0! | AU15: =financials!AS33/(financials!AS8+financials!AS6) -> #DIV/0! | AV15: =financials!AT33/(financials!AT8+financials!AT6) -> #DIV/0! | AW15: =financials!AU33/(financials!AU8+financials!AU6) -> #DIV/0! | AX15: =financials!AV33/(financials!AV8+financials!AV6) -> #DIV/0!
A16: T/LIQ Ratio | C16: =financials!B33/financials!B3 -> 0.14694199 | D16: =financials!C33/financials!C3 -> 0.15796451 | E16: =financials!D33/financials!D3 -> 0.15636484 | F16: =financials!E33/financials!E3 -> 0.18814353 | G16: =financials!F33/financials!F3 -> 0.20936936 | H16: =financials!G33/financials!G3 -> 0.21512841 | I16: =financials!H33/financials!H3 -> #DIV/0! | J16: =financials!I33/financials!I3 -> 0.1580741 | ... AN16: =financials!AM33/financials!AM3 -> 0.094190049 | AO16: =financials!#REF!/financials!#REF! -> #REF! | AP16: =financials!AN33/financials!AN3 -> #DIV/0! | AQ16: =financials!AO33/financials!AO3 -> #DIV/0! | AR16: =financials!AP33/financials!AP3 -> #DIV/0! | AS16: =financials!AQ33/financials!AQ3 -> #DIV/0! | AT16: =financials!AR33/financials!AR3 -> #DIV/0! | AU16: =financials!AS33/financials!AS3 -> #DIV/0! | AV16: =financials!AT33/financials!AT3 -> #DIV/0! | AW16: =financials!AU33/financials!AU3 -> #DIV/0! | AX16: =financials!AV33/financials!AV3 -> #DIV/0!
A17: External Borrowing to TA Ratio | B17: Max 25% | C17: =sofp!B35 / sofp!B25 -> 0.056781862 | D17: =sofp!C35 / sofp!C25 -> 0.05489003 | E17: =sofp!D35 / sofp!D25 -> 0.054642144 | F17: =sofp!E35 / sofp!E25 -> 0.051521156 | G17: =sofp!F35 / sofp!F25 -> 0.049077676 | H17: =sofp!G35 / sofp!G25 -> 0.046678573 | I17: =sofp!H35 / sofp!H25 -> #DIV/0! | J17: =sofp!I35 / sofp!I25 -> 0.040264661 | ... AX17: =sofp!AW35 / sofp!AW25 -> #DIV/0!
A18: Liquid Assets to TA Ratio | C18: =financials!B33 / financials!B3 -> 0.14694199 | D18: =financials!C33 / financials!C3 -> 0.15796451 | E18: =financials!D33 / financials!D3 -> 0.15636484 | F18: =financials!E33 / financials!E3 -> 0.18814353 | G18: =financials!F33 / financials!F3 -> 0.20936936 | H18: =financials!G33 / financials!G3 -> 0.21512841 | I18: =financials!H33 / financials!H3 -> #DIV/0! | J18: =financials!I33 / financials!I3 -> 0.1580741 | ... AN18: =financials!AM33 / financials!AM3 -> 0.094190049 | AO18: =financials!#REF! / financials!#REF! -> #REF! | AP18: =financials!AN33 / financials!AN3 -> #DIV/0! | AQ18: =financials!AO33 / financials!AO3 -> #DIV/0! | AR18: =financials!AP33 / financials!AP3 -> #DIV/0! | AS18: =financials!AQ33 / financials!AQ3 -> #DIV/0! | AT18: =financials!AR33 / financials!AR3 -> #DIV/0! | AU18: =financials!AS33 / financials!AS3 -> #DIV/0! | AV18: =financials!AT33 / financials!AT3 -> #DIV/0! | AW18: =financials!AU33 / financials!AU3 -> #DIV/0! | AX18: =financials!AV33 / financials!AV3 -> #DIV/0!
A19: STRUCTURE
A20: Non-Earning to TA Ratio | B20: Max 10% | C20: =financials!B35 / financials!B3 -> 0.39615777 | D20: =financials!C35 / financials!C3 -> 0.39384712 | E20: =financials!D35 / financials!D3 -> 0.4032786 | F20: =financials!E35 / financials!E3 -> 0.39137732 | G20: =financials!F35 / financials!F3 -> 0.38187732 | H20: =financials!G35 / financials!G3 -> 0.35922707 | I20: =financials!H35 / financials!H3 -> #DIV/0! | J20: =financials!I35 / financials!I3 -> 0.3912906 | ... AN20: =financials!AM35 / financials!AM3 -> 0.25676525 | AO20: =financials!#REF! / financials!#REF! -> #REF! | AP20: =financials!AN35 / financials!AN3 -> #DIV/0! | AQ20: =financials!AO35 / financials!AO3 -> #DIV/0! | AR20: =financials!AP35 / financials!AP3 -> #DIV/0! | AS20: =financials!AQ35 / financials!AQ3 -> #DIV/0! | AT20: =financials!AR35 / financials!AR3 -> #DIV/0! | AU20: =financials!AS35 / financials!AS3 -> #DIV/0! | AV20: =financials!AT35 / financials!AT3 -> #DIV/0! | AW20: =financials!AU35 / financials!AU3 -> #DIV/0! | AX20: =financials!AV35 / financials!AV3 -> #DIV/0!
