Workbook
Name BALANCE1_LDA01: '[1]Financial Statements'!$E$112
Name BALANCE1_LDA12: '[1]Financial Statements'!$E$123
Name BALANCE2_LDA01: '[1]Financial Statements'!$F$112
Name BALANCE2_LDA12: '[1]Financial Statements'!$F$123
Name BALANCE3_LDA01: '[1]Financial Statements'!$G$112
Name BALANCE3_LDA12: '[1]Financial Statements'!$G$123
Name BALANCE4_LDA01: '[1]Financial Statements'!$H$112
Name BALANCE4_LDA12: '[1]Financial Statements'!$H$123
Name BALANCE5_LDA01: '[1]Financial Statements'!$I$112
Name BALANCE5_LDA12: '[1]Financial Statements'!$I$123
Name BALANCE6_LDA01: '[1]Financial Statements'!$J$112
Name BALANCE6_LDA12: '[1]Financial Statements'!$J$123
Name PEARLS1_LA002: '[1]Financial Statements'!$E$280
Name PEARLS1_LE008: '[1]Financial Statements'!$E$275
Name PEARLS1_LE009: '[1]Financial Statements'!$E$276
Name PEARLS1_LR001: '[1]Financial Statements'!$E$282
Name PEARLS1_LR005: '[1]Financial Statements'!$E$286
Name PEARLS1_LR006: '[1]Financial Statements'!$E$287
Name PEARLS1_LR007: '[1]Financial Statements'!$E$288
Name PEARLS1_LR009: '[1]Financial Statements'!$E$290
Name PEARLS1_LS001: '[1]Financial Statements'!$E$298
Name PEARLS1_LS005: '[1]Financial Statements'!$E$302
Name PEARLS1_LS011: '[1]Financial Statements'!$E$308
Name PEARLS2_LA002: '[1]Financial Statements'!$F$280
Name PEARLS2_LE008: '[1]Financial Statements'!$F$275
Name PEARLS2_LE009: '[1]Financial Statements'!$F$276
Name PEARLS2_LR001: '[1]Financial Statements'!$F$282
Name PEARLS2_LR005: '[1]Financial Statements'!$F$286
Name PEARLS2_LR006: '[1]Financial Statements'!$F$287
Name PEARLS2_LR007: '[1]Financial Statements'!$F$288
Name PEARLS2_LR009: '[1]Financial Statements'!$F$290
Name PEARLS2_LS001: '[1]Financial Statements'!$F$298
Name PEARLS2_LS005: '[1]Financial Statements'!$F$302
Name PEARLS2_LS010: '[1]Financial Statements'!$F$307
Name PEARLS2_LS011: '[1]Financial Statements'!$F$308
Name PEARLS3_LA002: '[1]Financial Statements'!$G$280
Name PEARLS3_LE008: '[1]Financial Statements'!$G$275
Name PEARLS3_LE009: '[1]Financial Statements'!$G$276
Name PEARLS3_LR001: '[1]Financial Statements'!$G$282
Name PEARLS3_LR005: '[1]Financial Statements'!$G$286
Name PEARLS3_LR006: '[1]Financial Statements'!$G$287
Name PEARLS3_LR007: '[1]Financial Statements'!$G$288
Name PEARLS3_LR009: '[1]Financial Statements'!$G$290
Name PEARLS3_LS001: '[1]Financial Statements'!$G$298
Name PEARLS3_LS005: '[1]Financial Statements'!$G$302
Name PEARLS3_LS010: '[1]Financial Statements'!$G$307
Name PEARLS3_LS011: '[1]Financial Statements'!$G$308
Name PEARLS4_LA002: '[1]Financial Statements'!$H$280
Name PEARLS4_LE008: '[1]Financial Statements'!$H$275
Name PEARLS4_LE009: '[1]Financial Statements'!$H$276
Name PEARLS4_LR001: '[1]Financial Statements'!$H$282
Name PEARLS4_LR005: '[1]Financial Statements'!$H$286
Name PEARLS4_LR006: '[1]Financial Statements'!$H$287
Name PEARLS4_LR007: '[1]Financial Statements'!$H$288
Name PEARLS4_LR009: '[1]Financial Statements'!$H$290
Name PEARLS4_LS001: '[1]Financial Statements'!$H$298
Name PEARLS4_LS005: '[1]Financial Statements'!$H$302
Name PEARLS4_LS010: '[1]Financial Statements'!$H$307
Name PEARLS4_LS011: '[1]Financial Statements'!$H$308
Name PEARLS5_LA002: '[1]Financial Statements'!$I$280

Sheet Evolutive SFP
B3: AUDITED 2019 | C3: 43831 | D3: 43862 | E3: 43891 | F3: 43922 | G3: 43952 | H3: 43983 | I3: 44044 | J3: 44075 | K3: 44105 | L3: 44136 | M3: 44166 | N3: Audited 2020 | O3: 44197 | P3: 44228 | Q3: 44256 | R3: 44287 | S3: 44317 | T3: 44348 | U3: 44378 | V3: 44409 | W3: 44440 | X3: 44470 | Y3: 44501 | Z3: 44531 | AA3: AUDITED 2021 | AB3: 44562 | AC3: 44593 | AD3: 44621 | AE3: 44652 | AF3: 44682 | AG3: 44713 | AH3: 44743 | AI3: 44774 | AJ3: 44805 | AK3: 44835 | AL3: 44866 | AM3: 44896 | AN3: AUDITED 2022 | AO3: 44927 | AP3: 44958 | AQ3: 44986 | AR3: 45017 | AS3: 45047 | AT3: 45078 | AU3: 45108 | AV3: 45139
A4: Cash & cash Equivalent | B4: =(B5+B6) -> 60942574 | C4: =(C5+C6) -> 561024.02 | D4: =(D5+D6) -> 611197.36 | E4: =(E5+E6) -> 606233.06 | F4: =(F5+F6) -> 675951.44 | G4: =(G5+G6) -> 807920.76 | H4: =(H5+H6) -> 874010.45 | I4: =(I5+I6) -> 813996.37 | ... AV4: =(AV5+AV6) -> 7.5559238e+08
A5: Cash In Hand | B5: =1162643.9+734230 -> 1896873.9 | C5: 8563.6 | D5: 3071.76 | E5: 4222.11 | F5: 3757.31 | G5: 2627.48 | H5: 818.9 | I5: 235.72 | J5: 1089.42 | K5: 857.98 | L5: 1286.58 | M5: 307.54 | N5: =307542 -> 307542 | O5: 2093.34 | P5: 3397.41 | Q5: 3247.9 | R5: 1321.57 | S5: 2447.67 | T5: 3347.33 | U5: 1517.75 | V5: 608.93 | W5: 1257.06 | X5: 2537.21 | Y5: 3164.44 | Z5: 4092.18 | AA5: 4092180 | AB5: 2218350 | AC5: 2406493 | AD5: 3885985 | AE5: 1832448 | AF5: 4398483 | AG5: 2003607 | AH5: 3395790 | AI5: 1437868 | AJ5: 1981939 | AK5: 2234037 | AL5: 2635973 | AM5: 1113513 | AN5: =1137278+1804064+47533789+15376525+19583 -> 65871239 | AO5: 2612139 | AP5: 1820465 | AQ5: 1513765 | AR5: 837550 | AS5: 1582832 | AT5: 1959660 | AU5: 3347156 | AV5: 1466424
A6: Cash at Bank | B6: =15822167+4245336+223711.48+118700+34335785.65+4300000 -> 59045700 | C6: 552460.42 | D6: 608125.6 | E6: 602010.95 | F6: 672194.13 | G6: 805293.28 | H6: 873191.55 | I6: 813760.65 | J6: 762569.29 | K6: 747062.31 | L6: 783261.38 | M6: 781259.81 | N6: =783294992-N5 -> 782987450 | O6: 812649.63 | P6: 832063.54 | Q6: 783482.37 | R6: 799991.6 | S6: 803861.63 | T6: 803938.96 | U6: 819617.7 | V6: 819738.05 | W6: 835448.09 | X6: 919272.4 | Y6: 967121.33 | Z6: 1014635.1 | AA6: =1021706818-AA5 -> 1017614638 | AB6: 1.0334949e+09 | AC6: 1.0716266e+09 | AD6: 1.0184484e+09 | AE6: 1.0130524e+09 | AF6: 1.0425861e+09 | AG6: 1.0943449e+09 | AH6: 1.0902105e+09 | AI6: 1.2022465e+09 | AJ6: 1.26715e+09 | AK6: 1.2993252e+09 | AL6: 1.3471162e+09 | AM6: 1.3641671e+09 | AN6: =1366906242-AN5 -> 1301035003 | AO6: 1.3650328e+09 | AP6: 1.4371146e+09 | AQ6: 1.3491084e+09 | AR6: 1.3444305e+09 | AS6: 1364318038 | AT6: 1.0546844e+09 | AU6: 9.2487427e+08 | AV6: 7.5412596e+08
A7: Prepayment and Sundry | B7: =734299+7607765+1608382+1262141+451626 -> 11664213 | C7: 0 | D7: 0 | E7: 0 | F7: 0 | G7: 0 | H7: 0 | I7: 0 | J7: 0 | K7: 0 | L7: 0 | M7: 0 | N7: =16398297+1605749+10000+4475468+806444 -> 23295958 | O7: 0 | P7: 0 | Q7: 0 | R7: 0 | S7: 0 | T7: 0 | U7: 0 | V7: 0 | W7: 0 | X7: 0 | Y7: 0 | Z7: 0 | AA7: 43313613 | AB7: 0 | AC7: 0 | AD7: 0 | AE7: 0 | AF7: 0 | AG7: 0 | AH7: 0 | AI7: 0 | AJ7: 0 | AK7: 0 | AL7: 0 | AM7: 0 | AN7: 75065390 | AO7: 0 | AP7: 0 | AQ7: 0 | AR7: 0 | AS7: 0 | AT7: 0 | AU7: 0 | AV7: 0
A8: Financial Investment | B8: =(B9+B10+B11+B13+B12) -> 115855 | C8: =(C9+C10+C11+C13+C12) -> 213810.42 | D8: =(D9+D10+D11+D13+D12) -> 213810.42 | E8: =(E9+E10+E11+E13+E12) -> 216168.92 | F8: =(F9+F10+F11+F13+F12) -> 216168.92 | G8: =(G9+G10+G11+G13+G12) -> 216168.92 | H8: =(H9+H10+H11+H13+H12) -> 216168.92 | I8: =(I9+I10+I11+I13+I12) -> 216418.92 | ... AV8: =(AV9+AV10+AV11+AV13+AV12) -> 7.9164262e+08
A9: Government Security | C9: 0 | D9: 0 | E9: 0 | F9: 0 | G9: 0 | H9: 0 | I9: 0 | J9: 0 | K9: 0 | L9: 0 | M9: 0 | O9: 0 | P9: 0 | Q9: 0 | R9: 0 | S9: 0 | U9: 0 | V9: 0 | AB9: 0 | AC9: 0 | AD9: 0 | AE9: 0 | AF9: 0 | AG9: 0 | AH9: 0 | AI9: 0 | AJ9: 0 | AK9: 0 | AL9: 0 | AM9: 0 | AO9: 0 | AP9: 0 | AQ9: 0 | AR9: 0 | AS9: 0 | AT9: 350000000 | AU9: 507249295 | AV9: 5.6950697e+08
A10: Other Securities | C10: 0 | D10: 0 | E10: 0 | F10: 0 | G10: 0 | H10: 0 | I10: 0 | J10: 0 | K10: 0 | L10: 0 | M10: 0 | O10: 0 | P10: 0 | Q10: 0 | R10: 0 | S10: 0 | U10: 0 | V10: 0 | W10: 0 | X10: 0 | Y10: 0 | Z10: 0 | AB10: 0 | AC10: 0 | AD10: 0 | AE10: 0 | AF10: 0 | AG10: 0 | AH10: 0 | AI10: 0 | AJ10: 0 | AK10: 0 | AL10: 0 | AM10: 0 | AO10: 0 | AP10: 0 | AQ10: 0 | AR10: 0 | AS10: 0 | AT10: 0 | AU10: 0 | AV10: 0
A11: Balances in NACCOS (E.g Jungu Kuu, ESS, Savings,Money Market,Coop FD, CFP) | B11: =115855 -> 115855 | C11: 8093.93 | D11: 8093.93 | E11: 10452.43 | F11: 10452.43 | G11: 10452.43 | H11: 10452.43 | I11: 10702.43 | J11: 10764.36 | K11: 10764.36 | L11: 10920.91 | M11: 10970.91 | O11: 10970.91 | P11: 10977.85 | Q11: 11027.85 | R11: 11177.85 | S11: 11177.85 | T11: 11177.85 | W11: 0 | X11: 0 | Y11: 0 | Z11: 0 | AB11: 11651040 | AC11: 11701040 | AD11: 11701040 | AE11: 11801040 | AF11: 11801040 | AG11: 11918472 | AH11: 11918472 | AI11: 12018472 | AJ11: 12068472 | AK11: 12118472 | AL11: 12168472 | AM11: 12218472 | AO11: 12297602 | AP11: 12347602 | AQ11: 12347602 | AR11: 12447602 | AS11: 12447602 | AT11: 12547602 | AU11: 12547602 | AV11: 12547602
A12: Equity Investments in NACCOs(Shares in- CIC, KUSCCO, COOP BANK,CAK, KERUSSU) | C12: 205716.49 | D12: 205716.49 | E12: 205716.49 | F12: 205716.49 | G12: 205716.49 | H12: 205716.49 | I12: 205716.49 | J12: 205716.49 | K12: 205716.49 | L12: 205716.49 | M12: 205716.49 | N12: =53232144+895992+8093928 -> 62222064 | U12: 11342.92 | V12: 11392.92 | W12: 11442.92 | X12: 11501.04 | Y12: 11551.04 | Z12: 11601.04 | AA12: =53232144+895992+8093928 -> 62222064 | AB12: 2.0627727e+08 | AC12: 2.0627727e+08 | AD12: 2.0627727e+08 | AE12: 2.0627727e+08 | AF12: 2.0627727e+08 | AG12: 2.0627727e+08 | AH12: 2.0627727e+08 | AI12: 2.0627727e+08 | AJ12: 2.0627727e+08 | AK12: 2.0627727e+08 | AL12: 2.0627727e+08 | AM12: 2.0627727e+08 | AN12: =53232144+895992+8093928 -> 62222064 | AO12: 2.0627727e+08 | AP12: 2.0542227e+08 | AQ12: 2.0542227e+08 | AR12: 2.0542227e+08 | AS12: 2.0542227e+08 | AT12: 2.0958805e+08 | AU12: 2.0958805e+08 | AV12: 2.0958805e+08
A13: Equity Investments in companies - shares/stocks | N13: =4339+25001118+126582900 -> 151588357 | O13: 205716.49 | P13: 205716.49 | Q13: 205716.49 | R13: 205716.49 | S13: 205716.49 | T13: 205716.49 | U13: 205716.49 | V13: 205716.49 | W13: 206277.27 | X13: 206277.27 | Y13: 206277.27 | Z13: 206277.27 | AA13: =4339+25001118+127143680 -> 152149137 | AB13: 0 | AC13: 0 | AD13: 0 | AE13: 0 | AF13: 0 | AG13: 0 | AH13: 0 | AI13: 0 | AJ13: 0 | AK13: 0 | AL13: 0 | AM13: 0 | AN13: =126288680+25001144+4339 -> 151294163
A14: Net Loan Portfolio | B14: =(B15-B16) -> 216882733 | C14: =(C15-C16) -> 2218881.5 | D14: =(D15-D16) -> 2194730.5 | E14: =(E15-E16) -> 2142502.8 | F14: =(F15-F16) -> 2083076.2 | G14: =(G15-G16) -> 2085200.9 | H14: =(H15-H16) -> 2041178.1 | I14: =(I15-I16) -> 2220959.6 | ... AV14: =(AV15-AV16) -> 3.615259e+09
A15: Gross Loan Portfolio | B15: 238201977 | C15: 2254469.6 | D15: 2281291.9 | E15: 2236181.1 | F15: 2187772 | G15: 2148831.4 | H15: 2152614.9 | I15: 2334271.6 | J15: 2423796.5 | K15: 2482872.8 | L15: 2516422.2 | M15: 2564682.8 | N15: 2564485165 | O15: 2578503.4 | P15: 2602511.1 | Q15: 2595432.2 | R15: 2656255.8 | S15: 2698251.6 | T15: 2757238.4 | U15: 2792413.3 | V15: 2817998.9 | W15: 2816968.3 | X15: 2834290.1 | Y15: 2851108.5 | Z15: 2876131.2 | AA15: =2800698147+75353662 -> 2876051809 | AB15: 2.9031672e+09 | AC15: 2.9126159e+09 | AD15: 2.8807684e+09 | AE15: 2.9029136e+09 | AF15: 2.940416e+09 | AG15: 3.0248702e+09 | AH15: 3.0395705e+09 | AI15: 3.0685491e+09 | AJ15: 3.0779728e+09 | AK15: 3.1243903e+09 | AL15: 3.1446427e+09 | AM15: 3.2164272e+09 | AN15: =535593771+796044441+196669398+17584351+59907125+43671628+45944280+924150+2980750+39500+9731035+6426737+1280530506+225500+3338973+190127173+26490921 -> 3216230239 | AO15: 3.3045163e+09 | AP15: 3.3387625e+09 | AQ15: 3.3257418e+09 | AR15: 3.3656027e+09 | AS15: 3.4175862e+09 | AT15: 3.5386404e+09 | AU15: 3.6148066e+09 | AV15: 3.7167025e+09
A16: Allowance For Loan Loss | B16: 21319244 | C16: 35588.07 | D16: 86561.44 | E16: 93678.35 | F16: 104695.77 | G16: 63630.49 | H16: 111436.78 | I16: 113312 | J16: 114071.49 | K16: 103511.29 | L16: 111435.61 | M16: 85987.1 | N16: 85903641 | O16: 99014.08 | P16: 120641.95 | Q16: 106261.39 | R16: 111017.86 | S16: 110627.56 | T16: 115170.15 | U16: 114891.84 | V16: 105537.78 | W16: 93116.44 | X16: 88087.98 | Y16: 83155.08 | Z16: 75326.59 | AA16: 75353662 | AB16: 75326586 | AC16: 68721030 | AD16: 71173495 | AE16: 73096033 | AF16: 74387282 | AG16: 82500293 | AH16: 87734372 | AI16: 87658260 | AJ16: 82875504 | AK16: 82900121 | AL16: 87868954 | AM16: 64619598 | AN16: 64617629 | AO16: 72025254 | AP16: 73129447 | AQ16: 69450211 | AR16: 69796664 | AS16: 70210239 | AT16: 80153645 | AU16: 94182368 | AV16: 101443565
A17: Accounts Recievables | B17: =(B18+B19+B20) -> 0 | C17: =(C18+C19+C20) -> 6806.19 | D17: =(D18+D19+D20) -> -428.76 | E17: =(E18+E19+E20) -> -428.76 | F17: =(F18+F19+F20) -> 4501.59 | G17: =(G18+G19+G20) -> 4501.59 | H17: =(H18+H19+H20) -> 7698.28 | I17: =(I18+I19+I20) -> 7698.28 | ... AV17: =(AV18+AV19+AV20) -> 120186.72
A18: Tax Recoverable | C18: 6806.19 | D18: -428.76 | E18: -428.76 | F18: 4501.59 | G18: 4501.59 | H18: 7698.28 | I18: 7698.28 | J18: 10845.55 | K18: 10845.55 | L18: 10845.55 | M18: 13947.5 | N18: 5044613 | O18: 13947.5 | P18: 5044.61 | Q18: 5044.61 | R18: 7960.02 | S18: 7960.02 | T18: 4258.4 | U18: 4258.4 | V18: 4258.4 | W18: 2915.41 | X18: 2915.41 | Y18: 7173.82 | Z18: 10089.23 | AA18: 5044614 | AB18: 5044613.7 | AC18: 5044613.7 | AD18: 5044613.7 | AE18: 3986441.3 | AF18: 0 | AG18: 329986.72 | AH18: 329986.72 | AI18: 329986.72 | AJ18: 4626676.7 | AK18: 4626676.7 | AL18: 4626676.7 | AM18: 8923366.7 | AO18: 8923366.7 | AP18: 0 | AQ18: 0 | AR18: 0 | AS18: 0 | AT18: 0 | AU18: 120186.72 | AV18: 120186.72
A19: Deffered Tax Assets | C19: 0 | D19: 0 | E19: 0 | F19: 0 | G19: 0 | H19: 0 | I19: 0 | J19: 0 | K19: 0 | L19: 0 | M19: 0 | O19: 0 | P19: 0 | Q19: 0 | R19: 0 | S19: 0 | T19: 0 | U19: 0 | V19: 0 | W19: 0 | X19: 0 | Y19: 0 | Z19: 0 | AB19: 0 | AC19: 0 | AD19: 0 | AE19: 0 | AF19: 0 | AG19: 0 | AH19: 0 | AI19: 0 | AJ19: 0 | AK19: 0 | AL19: 0 | AM19: 0 | AO19: 0 | AP19: 0 | AQ19: 0 | AR19: 0 | AS19: 0 | AT19: 0 | AU19: 0 | AV19: 0
A20: Retirement Benefit Assets | C20: 0 | D20: 0 | E20: 0 | F20: 0 | G20: 0 | H20: 0 | I20: 0 | J20: 0 | K20: 0 | L20: 0 | M20: 0 | O20: 0 | P20: 0 | Q20: 0 | R20: 0 | S20: 0 | T20: 0 | U20: 0 | V20: 0 | W20: 0 | X20: 0 | Y20: 0 | Z20: 0 | AB20: 0 | AC20: 0 | AD20: 0 | AE20: 0 | AF20: 0 | AG20: 0 | AH20: 0 | AI20: 0 | AJ20: 0 | AK20: 0 | AL20: 0 | AM20: 0 | AO20: 0 | AP20: 0 | AQ20: 0 | AR20: 0 | AS20: 0 | AT20: 0 | AU20: 0 | AV20: 0
A21: Property&Equipments&Other Assets | B21: =(B22+B23+B24+B25+B26) -> 3806303 | C21: =(C22+C23+C24+C25+C26) -> 165873.14 | D21: =(D22+D23+D24+D25+D26) -> 139478.98 | E21: =(E22+E23+E24+E25+E26) -> 134978.1 | F21: =(F22+F23+F24+F25+F26) -> 188305.43 | G21: =(G22+G23+G24+G25+G26) -> 136868.63 | H21: =(H22+H23+H24+H25+H26) -> 138808.23 | I21: =(I22+I23+I24+I25+I26) -> 137972.94 | ... AV21: =(AV22+AV23+AV24+AV25+AV26) -> 2.2707614e+08
A22: Investment Properties | C22: 0 | D22: 0 | E22: 0 | F22: 0 | G22: 0 | H22: 0 | I22: 0 | J22: 0 | K22: 0 | L22: 0 | M22: 0 | O22: 0 | P22: 0 | Q22: 0 | R22: 0 | S22: 0 | T22: 0 | U22: 0 | V22: 0 | W22: 0 | X22: 0 | Y22: 0 | Z22: 0 | AB22: 0 | AC22: 0 | AD22: 0 | AE22: 0 | AF22: 0 | AG22: 0 | AH22: 0 | AI22: 0 | AJ22: 0 | AK22: 0 | AL22: 0 | AM22: 0 | AO22: 0 | AP22: 0 | AQ22: 0 | AR22: 0 | AS22: 0 | AT22: 0 | AU22: 0 | AV22: 0
A23: Property and Equipment | B23: 3806303 | C23: 109066.07 | D23: 108792.8 | E23: 108491.82 | F23: 108202.08 | G23: 108014.06 | H23: 107724.2 | I23: 109023.81 | J23: 111726.02 | K23: 111386.02 | L23: 111058.25 | M23: 110720.85 | N23: =110878048 -> 110878048 | O23: 110558.85 | P23: 110271.65 | Q23: 110081.29 | R23: 109775.86 | S23: 109461.41 | T23: 111584.85 | U23: 112504.36 | V23: 111877.42 | W23: 111526.01 | X23: 111311.28 | Y23: 110961.91 | Z23: 110601.93 | AA23: 110601955 | AB23: 1.1027097e+08 | AC23: 1.0997291e+08 | AD23: 1.0964385e+08 | AE23: 1.0933462e+08 | AF23: 1.100231e+08 | AG23: 1.1217761e+08 | AH23: 1.1220486e+08 | AI23: 1.1192003e+08 | AJ23: 1.1158541e+08 | AK23: 1.112405e+08 | AL23: 1.1172903e+08 | AM23: 1.1018137e+08 | AN23: 110181392 | AO23: 1.0966489e+08 | AP23: 1.0919909e+08 | AQ23: 1.0943138e+08 | AR23: 1.0936253e+08 | AS23: 1.0884716e+08 | AT23: 1.1000761e+08 | AU23: 1.1014786e+08 | AV23: 1.1003592e+08
A24: Prepaid Lease Rentals | C24: 0 | D24: 0 | E24: 0 | F24: 0 | G24: 0 | H24: 0 | I24: 0 | J24: 0 | K24: 0 | L24: 0 | M24: 0 | O24: 0 | P24: 0 | Q24: 0 | R24: 0 | S24: 0 | T24: 0 | U24: 0 | V24: 0 | W24: 0 | X24: 0 | Y24: 0 | Z24: 0 | AB24: 0 | AC24: 0 | AD24: 0 | AE24: 0 | AF24: 0 | AG24: 0 | AH24: 0 | AI24: 0 | AJ24: 0 | AK24: 0 | AL24: 0 | AM24: 0 | AO24: 0 | AP24: 0 | AQ24: 0 | AR24: 0 | AS24: 0 | AT24: 0 | AU24: 0 | AV24: 0
A25: Intangible Assets | C25: 4451.05 | D25: 4372.52 | E25: 4293.99 | F25: 4215.47 | G25: 4136.94 | H25: 3884.8 | I25: 3363.7 | J25: 3111.56 | K25: 2851.02 | L25: 2642.93 | M25: 2642.93 | N25: =2642935 -> 2642935 | O25: 2642.93 | P25: 2642.93 | Q25: 2642.93 | R25: 2642.93 | S25: 2642.93 | T25: 4320.67 | U25: 4320.67 | V25: 4320.67 | W25: 4320.67 | X25: 4053.38 | Y25: 4027 | Z25: 3999.75 | AA25: 3999746 | AB25: 3972489.3 | AC25: 3947870.2 | AD25: 3920613.4 | AE25: 3894235.9 | AF25: 3866979 | AG25: 3840601.5 | AH25: 3813344.7 | AI25: 3786087.9 | AJ25: 3759710 | AK25: 4124638.3 | AL25: 3626547.9 | AM25: 3473383.1 | AN25: 3473383 | AO25: 3446126.3 | AP25: 3421507.3 | AQ25: 4601748.6 | AR25: 4541360.1 | AS25: 6263969.4 | AT25: 6153303.4 | AU25: 6038948.6 | AV25: 5924593.7
A26: Other Assets | C26: 52356.02 | D26: 26313.66 | E26: 22192.29 | F26: 75887.88 | G26: 24717.63 | H26: 27199.23 | I26: 25585.43 | J26: 23008.49 | K26: 27642.83 | L26: 24541.89 | M26: 23989.72 | O26: 26575.07 | P26: 30370.36 | Q26: 29088.12 | R26: 26474.01 | S26: 28579.35 | T26: 35216.58 | U26: 36558.79 | V26: 34230.01 | W26: 93711.04 | X26: 43605 | Y26: 41374.17 | Z26: 53457.54 | AB26: 51094552 | AC26: 56087448 | AD26: 61706771 | AE26: 45109413 | AF26: 50824107 | AG26: 61727035 | AH26: 1.0717167e+08 | AI26: 49962054 | AJ26: 58822117 | AK26: 66090539 | AL26: 81203521 | AM26: 69816798 | AO26: 84571319 | AP26: 95168223 | AQ26: 87127046 | AR26: 69346508 | AS26: 92458202 | AT26: 85201085 | AU26: 62988298 | AV26: 1.1111563e+08
A27: Total Assets | B27: =(B21+B17+B14+B8+B7+B4) -> 2.9341168e+08 | C27: =(C21+C17+C14+C8+C7+C4) -> 3166395.3 | D27: =(D21+D17+D14+D8+D7+D4) -> 3158788.5 | E27: =(E21+E17+E14+E8+E7+E4) -> 3099454.1 | F27: =(F21+F17+F14+F8+F7+F4) -> 3168003.6 | G27: =(G21+G17+G14+G8+G7+G4) -> 3250660.8 | H27: =(H21+H17+H14+H8+H7+H4) -> 3277864 | I27: =(I21+I17+I14+I8+I7+I4) -> 3397046.1 | ... AV27: =(AV21+AV17+AV14+AV8+AV7+AV4) -> 5.3896903e+09
A28: Savings and Deposits | B28: =779515+307095 -> 1086610 | C28: 193470.46 | D28: 186159.48 | E28: 254375.76 | F28: 293204.33 | G28: 237548.07 | H28: 240820.5 | I28: 258173.25 | J28: 249034.45 | K28: 230501.03 | L28: 225764.21 | M28: 216919.81 | N28: =240216344 -> 240216344 | O28: 237906.65 | P28: 244165.3 | Q28: 363250.51 | R28: 335920.07 | S28: 302635.39 | T28: 296376.24 | U28: 296183.6 | V28: 264760.15 | W28: 266605.84 | X28: 257457.54 | Y28: 251394.13 | Z28: 256477.4 | AA28: 264135882 | AB28: 264135882 | AC28: 264135882 | AD28: 264135882 | AE28: 264135882 | AF28: 264135882 | AG28: 264135882 | AH28: 264135882 | AI28: 264135882 | AJ28: 264135882 | AK28: 264135882 | AL28: 264135882 | AM28: 264135882 | AN28: 272831599 | AO28: 2.9743839e+08 | AP28: 2.9890028e+08 | AQ28: 4.351719e+08 | AR28: 3.7422596e+08 | AS28: 3.774042e+08 | AT28: 3.7495113e+08 | AU28: 3.7244122e+08 | AV28: 3.4328912e+08
A29: Short Terrm Deposits | B29: =257941+920333.21+11500+708204 -> 1897978.2 | C29: 40185.32 | D29: 40369.84 | E29: 40369.84 | F29: 6526.47 | G29: 42141.29 | H29: 42141.29 | I29: 31714.15 | J29: 33185 | K29: 33185 | L29: 33185 | M29: 33185 | N29: 33185000 | O29: 29000 | P29: 29000 | Q29: 29000 | R29: 25650 | S29: 25650 | T29: 25650 | U29: 19073.89 | V29: 19073.89 | W29: 19073.89 | X29: 9300 | Y29: 9300 | Z29: 9300 | AO29: 0 | AP29: 0 | AQ29: 0 | AR29: 0 | AS29: 0 | AT29: 0 | AU29: 0 | AV29: 0
A30: Non Withdrawable Deposits | B30: =254720687 -> 254720687 | C30: 1945035.4 | D30: 1977350.3 | E30: 2031574.3 | F30: 2045230 | G30: 2077883.4 | H30: 2112548 | I30: 2167038.2 | J30: 2178440.6 | K30: 2210562.7 | L30: 2242846.7 | M30: 2264393.9 | N30: =2251239383+13294425 -> 2264533808 | O30: 2286736.1 | P30: 2314451.3 | Q30: 2362532.9 | R30: 2404573 | S30: 2456518.2 | T30: 2498819.3 | U30: 2526891.5 | V30: 2556991.1 | W30: 2590046.2 | X30: 2628051.8 | Y30: 2653805 | Z30: 2694159.3 | AA30: 2694094259 | AB30: 2694094259 | AC30: 2694094259 | AD30: 2694094259 | AE30: 2694094259 | AF30: 2694094259 | AG30: 2694094259 | AH30: 2694094259 | AI30: 2694094259 | AJ30: 2694094259 | AK30: 2694094259 | AL30: 2694094259 | AM30: 2694094259 | AN30: 3251984807 | AO30: 3.2939133e+09 | AP30: 3.362329e+09 | AQ30: 3.4387689e+09 | AR30: 3.5016863e+09 | AS30: 3.5511053e+09 | AT30: 3.5977609e+09 | AU30: 3.649411e+09 | AV30: 3.6912037e+09
A31: Total Deposit Liabilities | B31: =SUM(B28:B30) -> 2.5770528e+08 | C31: =SUM(C28:C30) -> 2178691.2 | D31: =SUM(D28:D30) -> 2203879.6 | E31: =SUM(E28:E30) -> 2326319.9 | F31: =SUM(F28:F30) -> 2344960.8 | G31: =SUM(G28:G30) -> 2357572.7 | H31: =SUM(H28:H30) -> 2395509.8 | I31: =SUM(I28:I30) -> 2456925.6 | ... AV31: =SUM(AV28:AV30) -> 4.0344928e+09
A32: Tax Payable | B32: 14602 | C32: 0 | D32: 0 | E32: 0 | F32: 0 | G32: 0 | H32: 0 | I32: 0 | J32: 0 | K32: 0 | L32: 0 | M32: 0 | O32: 0 | P32: 0 | Q32: 0 | R32: 0 | S32: 0 | T32: 0 | U32: 0 | V32: 0 | W32: 0 | X32: 0 | Y32: 0 | Z32: 0 | AD32: 0 | AE32: 0 | AF32: 0 | AG32: 0 | AH32: 3966703.3 | AI32: 0 | AJ32: 0 | AK32: 0 | AL32: 0 | AM32: 0 | AN32: 5221111 | AO32: 0 | AP32: 0 | AQ32: 0 | AR32: 0 | AS32: 0 | AT32: 0 | AU32: 0 | AV32: 0
A33: Dividends Payable | C33: 0 | D33: 0 | E33: 0 | F33: 0 | G33: 0 | H33: 0 | I33: 0 | J33: 0 | K33: 0 | L33: 0 | M33: 0 | N33: =233587603+13868910+2413564 -> 249870077 | O33: 0 | P33: 0 | Q33: 0 | R33: 0 | S33: 0 | T33: 0 | U33: 0 | V33: 224885.07 | W33: 213050.42 | X33: 238508.38 | Y33: 275168.39 | Z33: 280308.32 | AA33: 287852165 | AB33: 287852166 | AC33: 287852167 | AD33: 3.1791429e+08 | AE33: 3.7828525e+08 | AF33: 82018662 | AG33: 173759.36 | AH33: 1.7724943e+08 | AI33: 161383260 | AJ33: 184461930 | AK33: 234092200 | AL33: 270460340 | AM33: 3.0807989e+08 | AN33: =344439618+42749380 -> 387188998 | AO33: 3.6557808e+08 | AP33: 3.9891973e+08 | AQ33: 1.0032708e+08 | AR33: 1.3834822e+08 | AS33: 1.7508835e+08 | AT33: 2.1804705e+08 | AU33: 2.4658673e+08 | AV33: 2.7595401e+08
A34: Deferred Tax Liability | C34: 0 | D34: 0 | E34: 0 | F34: 0 | G34: 0 | H34: 0 | I34: 0 | J34: 0 | K34: 0 | L34: 0 | M34: 0 | O34: 0 | P34: 0 | Q34: 0 | R34: 0 | S34: 0 | T34: 0 | U34: 0 | V34: 0 | W34: 0 | X34: 0 | Y34: 0 | Z34: 0 | AD34: 0 | AE34: 0 | AF34: 0 | AG34: 0 | AH34: 0 | AI34: 0 | AJ34: 0 | AK34: 0 | AL34: 0 | AM34: 0 | AO34: 0 | AP34: 0 | AQ34: 0 | AR34: 0 | AS34: 0 | AT34: 0 | AU34: 0 | AV34: 0
A35: Retirement Benefits Liabilty | C35: 0 | D35: 0 | E35: 0 | F35: 0 | G35: 0 | H35: 0 | I35: 0 | J35: 0 | K35: 0 | L35: 0 | M35: 0 | O35: 0 | P35: 0 | Q35: 0 | R35: 0 | S35: 0 | T35: 0 | U35: 0 | V35: 0 | W35: 0 | X35: 0 | Y35: 0 | Z35: 0 | AD35: 0 | AE35: 0 | AF35: 0 | AG35: 0 | AH35: 0 | AI35: 0 | AJ35: 0 | AK35: 0 | AL35: 0 | AM35: 0 | AO35: 0 | AP35: 0 | AQ35: 0 | AR35: 0 | AS35: 0 | AT35: 0 | AU35: 0 | AV35: 0
A36: Other Liabilities | B36: =348519+50000 -> 398519 | C36: 296589.86 | D36: 312712.62 | E36: 132547.52 | F36: 131340.2 | G36: 153270.03 | H36: 184267.37 | I36: 222326.61 | J36: 247837.32 | K36: 276810.27 | L36: 309841.09 | M36: 334588.4 | N36: =8987436+7593662+1429711+3383752+(22529647) -> 43924208 | O36: 366554.49 | P36: 367425.41 | Q36: 143958.96 | R36: 146538.2 | S36: 172038.61 | T36: 171532.99 | U36: 221259.99 | V36: 35163.28 | W36: 39835.68 | X36: 41817.26 | Y36: 41991.36 | Z36: 50581.09 | AA36: =23307476+16247642 -> 39555118 | AB36: =23307476+16247642 -> 39555118 | AC36: =23307476+16247642 -> 39555118 | AD36: 60216648 | AE36: 42686351 | AF36: 69061236 | AG36: 152654546 | AH36: 0 | AI36: 51531221 | AJ36: 57841412 | AK36: 55314342 | AL36: 38865029 | AM36: 38179297 | AN36: =23413633+24422444 -> 47836077 | AO36: 49316020 | AP36: 54416902 | AQ36: 61008874 | AR36: 32350329 | AS36: 29754894 | AT36: 33607793 | AU36: 14028019 | AV36: 16055590
A37: External Borrowings | C37: 0 | D37: 0 | E37: 0 | F37: 0 | G37: 0 | H37: 0 | I37: 0 | J37: 0 | K37: 0 | L37: 0 | M37: 0 | O37: 0 | P37: 0 | Q37: 0 | R37: 0 | S37: 0 | T37: 0 | U37: 0 | V37: 0 | W37: 0 | X37: 0 | Y37: 0 | Z37: 0 | AD37: 0 | AE37: 0 | AF37: 0 | AG37: 0 | AH37: 0 | AI37: 0 | AJ37: 0 | AK37: 0 | AL37: 0 | AM37: 0 | AO37: 0 | AP37: 0 | AQ37: 0 | AR37: 0 | AS37: 0 | AT37: 0 | AU37: 0 | AV37: 0
A38: Total Liabilities | B38: =SUM(B31:B37) -> 2.581184e+08 | C38: =SUM(C31:C37) -> 2475281.1 | D38: =SUM(D31:D37) -> 2516592.2 | E38: =SUM(E31:E37) -> 2458867.4 | F38: =SUM(F31:F37) -> 2476301 | G38: =SUM(G31:G37) -> 2510842.8 | H38: =SUM(H31:H37) -> 2579777.2 | I38: =SUM(I31:I37) -> 2679252.2 | ... AV38: =SUM(AV31:AV37) -> 4.3265024e+09
A39: Share Capital | B39: =7840346+11129788 -> 18970134 | C39: 182486.39 | D39: 183425.59 | E39: 184649.41 | F39: 184691.41 | G39: 185829 | H39: 186876.42 | I39: 188826.42 | J39: 189342.42 | K39: 190311.74 | L39: 190771.94 | M39: 191310.14 | N39: =181839389+9448550 -> 191287939 | O39: 192296.14 | P39: 192676.34 | Q39: 193182.94 | R39: 194221.94 | S39: 195341.47 | T39: 196489.31 | U39: 197709.31 | V39: 198169.31 | W39: 200492.12 | X39: 201143.69 | Y39: 202339.19 | Z39: 204354.23 | AA39: 204354229 | AB39: 204394229 | AC39: 205224229 | AD39: 208952661 | AE39: 210951661 | AF39: 2.1131438e+08 | AG39: 2.1131438e+08 | AH39: 2.1439877e+08 | AI39: 2.1594627e+08 | AJ39: 2.1711901e+08 | AK39: 2.1839841e+08 | AL39: 2.1936741e+08 | AM39: 2.2087941e+08 | AN39: 220601770 | AO39: 2.2184141e+08 | AP39: 2.2346577e+08 | AQ39: 2.2724738e+08 | AR39: 2.2817728e+08 | AS39: 2.2995828e+08 | AT39: 2.3102896e+08 | AU39: 2.3310239e+08 | AV39: 2.3391689e+08
A40: Capital Grants | C40: 0 | D40: 0 | E40: 0 | F40: 0 | G40: 0 | H40: 0 | I40: 0 | J40: 0 | K40: 0 | L40: 0 | M40: 0 | O40: 0 | P40: 0 | Q40: 0 | R40: 0 | S40: 0 | T40: 0 | U40: 0 | V40: 0 | W40: 0 | X40: 0 | Y40: 0 | Z40: 0 | AB40: 0 | AC40: 0 | AD40: 0 | AE40: 0 | AF40: 0 | AG40: 0 | AH40: 0 | AI40: 0 | AJ40: 0 | AK40: 0 | AL40: 0 | AM40: 0 | AO40: 0 | AP40: 0 | AQ40: 0 | AR40: 0 | AS40: 0 | AT40: 0 | AU40: 0 | AV40: 0
A41: Prior Year Retained Earnigs | B41: 10520537 | C41: 361564.84 | D41: 274938.86 | E41: 274938.86 | F41: 274938.86 | G41: 274938.86 | H41: 274938.86 | I41: 274938.86 | J41: 274938.86 | K41: 274938.86 | L41: 274938.86 | M41: 274938.86 | N41: 274955772 | O41: 401563.2 | P41: 361219.33 | Q41: 361219.33 | R41: 361219.33 | S41: 361219.33 | T41: 361219.33 | U41: 361219.33 | V41: 361219.33 | W41: 361219.33 | X41: 361219.33 | Y41: 361219.33 | Z41: 361219.33 | AA41: 361237243 | AB41: 4.7721447e+08 | AC41: 442110065 | AD41: 442110065 | AE41: 442110065 | AF41: 442110065 | AG41: 442110065 | AH41: 442110065 | AI41: 4.2449384e+08 | AJ41: 4.2449384e+08 | AK41: 4.2449384e+08 | AL41: 4.2449384e+08 | AM41: 3.817791e+08 | AN41: =442110173-9866173 -> 432244000 | AO41: 5.1464148e+08 | AP41: 4.6674494e+08 | AQ41: 4.6674494e+08 | AR41: 4.6674494e+08 | AS41: 4.6674494e+08 | AT41: 4.6674494e+08 | AU41: 4.6674494e+08 | AV41: 4.6674494e+08
A42: Current Year Surplus | B42: 17320 | C42: -929.2 | D42: 16583.6 | E42: 10631.9 | F42: 58625.5 | G42: 102430.4 | H42: 56449.79 | I42: 67717.8 | J42: 76242.2 | K42: 87325.8 | L42: 81803.9 | M42: 113519.3 | N42: =157859891-(31571978+37440175+2574774+16879) -> 86256085 | O42: -13751.5 | P42: -25718.6 | Q42: -12777.2 | R42: 36515.3 | S42: 37077.6 | T42: 59180.9 | U42: 35242.5 | V42: 25206.89 | W42: 77640.7 | X42: 83940.8 | Y42: 94579.2 | Z42: 126955.31 | AA42: =159056344-31811269-39505233-3261503 -> 84478339 | AB42: 15529500 | AC42: 16361200 | AD42: 6339279.3 | AE42: 5871320 | AF42: -2066494.3 | AG42: 43633198 | AH42: 37091553 | AI42: 43141259 | AJ42: 48515771 | AK42: 46993755 | AL42: 42563466 | AM42: 1.0554661e+08 | AN42: =121663493-24332699-4074234-5864891-42749380 -> 44642289 | AO42: 12122.9 | AP42: 16148758 | AQ42: 23907360 | AR42: 24144811 | AS42: 28192041 | AT42: 82080067 | AU42: 77451672 | AV42: 77160421
...

Sheet Evolutitve SCI
B1: "000"
B2: Audited 2019 | C2: 43831 | D2: 43862 | E2: 43891 | F2: 43922 | G2: 43952 | H2: 43983 | I2: 44044 | J2: 44075 | K2: 44105 | L2: 44136 | M2: 44166 | N2: Audited 2020 | O2: 44197 | P2: 44228 | Q2: 44256 | R2: 44287 | S2: 44317 | T2: 44348 | U2: 44378 | V2: 44409 | W2: 44440 | X2: 44470 | Y2: 44501 | Z2: 44531 | AA2: AUDITED 2021 | AB2: 44562 | AC2: 44593 | AD2: 44621 | AE2: 44652 | AF2: 44682 | AG2: 44713 | AH2: 44743 | AI2: 44774 | AJ2: 44805 | AK2: 44835 | AL2: 44866 | AM2: 44896 | AN2: AUDITED 2022 | AO2: 44927 | AP2: 44958 | AQ2: 44986 | AR2: 45017 | AS2: 45047 | AT2: 45078 | AU2: 45108 | AV2: 45139
A3: Financial Income | B3: =B4+B7 -> 34090071 | C3: =C4+C7 -> 29420.2 | D3: =D4+D7 -> 61985.58 | E3: =E4+E7 -> 97033.22 | F3: =F4+F7 -> 186241.79 | G3: =G4+G7 -> 219204.82 | H3: =H4+H7 -> 251569.3 | I3: =I4+I7 -> 331911.58 | ... AV3: =AV4+AV7 -> 4.9090132e+08
A4: Financial Income From Loans Portfolio | B4: =SUM(B5:B6) -> 30319703 | C4: =SUM(C5:C6) -> 27930.98 | D4: =SUM(D5:D6) -> 54999.58 | E4: =SUM(E5:E6) -> 84817.46 | F4: =SUM(F5:F6) -> 112824.84 | G4: =SUM(G5:G6) -> 138803.67 | H4: =SUM(H5:H6) -> 164850.92 | I4: =SUM(I5:I6) -> 218686.3 | ... AV4: =SUM(AV5:AV6) -> 3.1602035e+08
A5: Interest from Loans Portfolio | B5: 29009435 | C5: 27556.48 | D5: 52711.18 | E5: 80152.96 | F5: 107236.44 | G5: 132726.17 | H5: 158047.62 | I5: 210504.7 | J5: 239816.08 | K5: 270226.24 | L5: 298209.19 | M5: 329605.24 | N5: =313623358+15818648 -> 329442006 | O5: 29095.27 | P5: 56168.57 | Q5: 87302.88 | R5: 118136.3 | S5: 147823.89 | T5: 178267.76 | U5: 208794.15 | V5: 208794.15 | W5: 276987.24 | X5: 308149.63 | Y5: 342176.15 | Z5: 372917.87 | AA5: 31487658 | AB5: 31487658 | AC5: 63529.73 | AD5: 95819982 | AE5: 1.2801487e+08 | AF5: 1.6100454e+08 | AG5: 1.9598459e+08 | AH5: 231577996 | AI5: 2.6667779e+08 | AJ5: 3.0230107e+08 | AK5: 3.3654439e+08 | AL5: 3.7183863e+08 | AM5: 4.079927e+08 | AN5: 408125862 | AO5: 35529348 | AP5: 71630081 | AQ5: 1.0984821e+08 | AR5: 1.4542265e+08 | AS5: 1.8481578e+08 | AT5: 2.2142798e+08 | AU5: 2.6430095e+08 | AV5: 3.069356e+08
A6: Fees&Commision on Loan Portfolio | B6: =623888+686380 -> 1310268 | C6: 374.5 | D6: 2288.4 | E6: 4664.5 | F6: 5588.4 | G6: 6077.5 | H6: 6803.3 | I6: 8181.6 | J6: 8674.4 | K6: 9282.2 | L6: 9987.1 | M6: 10897.5 | N6: =10964559+20806578 -> 31771137 | O6: 817.2 | P6: 1646.2 | Q6: 4076.3 | R6: 5087.5 | S6: 5869.9 | T6: 6638.6 | U6: 7737.3 | V6: 8312.6 | W6: 8950.4 | X6: 9743.8 | Y6: 10775.3 | Z6: 11630.3 | AA6: 1178205.6 | AB6: 1178205.6 | AC6: 1788.1 | AD6: 4236571 | AE6: 5203429.3 | AF6: 5871896.5 | AG6: 6578538.2 | AH6: 7363378.8 | AI6: 8274196.8 | AJ6: 9085881.5 | AK6: 10359564 | AL6: 12137161 | AM6: 14467436 | AO6: 1468499 | AP6: 2733633.8 | AQ6: 3098251 | AR6: 4083034.1 | AS6: 5119772.2 | AT6: 6650726.1 | AU6: 7689683.4 | AV6: 9084749.8
A7: Financial Income from Investments | B7: =SUM(B8:B11) -> 3770368 | C7: =SUM(C8:C11) -> 1489.22 | D7: =SUM(D8:D11) -> 6986 | E7: =SUM(E8:E11) -> 12215.76 | F7: =SUM(F8:F11) -> 73416.95 | G7: =SUM(G8:G11) -> 80401.15 | H7: =SUM(H8:H11) -> 86718.38 | I7: =SUM(I8:I11) -> 113225.28 | ... AV7: =SUM(AV8:AV11) -> 1.7488096e+08
A8: Government Securities | C8: 0 | D8: 0 | E8: 0 | F8: 0 | G8: 0 | H8: 0 | I8: 0 | J8: 0 | K8: 0 | L8: 0 | M8: 0 | N8: 0 | O8: 0 | P8: 0 | Q8: 0 | R8: 0 | S8: 0 | T8: 0 | U8: 0 | V8: 0 | W8: 0 | X8: 0 | Y8: 0 | Z8: 0 | AB8: 0 | AC8: 0 | AD8: 0 | AE8: 0 | AF8: 0 | AG8: 0 | AH8: 0 | AI8: 0 | AJ8: 0 | AK8: 0 | AL8: 0 | AM8: 0 | AO8: 0 | AP8: 0 | AQ8: 0 | AR8: 0 | AS8: 0 | AT8: 0 | AU8: 0 | AV8: 0
A9: Deposits with Banks & other Financial Institutions | C9: 0 | D9: 0 | E9: 0 | F9: 0 | G9: 0 | H9: 0 | I9: 0 | J9: 0 | K9: 0 | L9: 0 | M9: 0 | N9: 0 | O9: 0 | P9: 0 | Q9: 0 | R9: 0 | S9: 0 | T9: 0 | U9: 0 | V9: 0 | W9: 0 | X9: 0 | Y9: 0 | Z9: 0 | AA9: =67087378+47961448 -> 115048826 | AB9: 0 | AC9: 0 | AD9: 0 | AE9: 0 | AF9: 0 | AG9: 0 | AH9: 0 | AI9: 0 | AJ9: 0 | AK9: 0 | AL9: 0 | AM9: 0 | AN9: =96765393+50042492 -> 146807885 | AO9: 0 | AP9: 0 | AQ9: 0 | AR9: 0 | AS9: 0 | AT9: 0 | AU9: 0 | AV9: 0
A10: Other Investments | B10: 1255802 | C10: 0 | D10: 5776.27 | E10: 9523.11 | F10: 69979.97 | G10: 74865.62 | H10: 80146.73 | I10: 91534.75 | J10: 96736.99 | K10: 101839.05 | L10: 105888.06 | M10: 109457.8 | N10: =48056583+25426+5057818+56353713 -> 109493540 | O10: 0 | P10: 10524.62 | Q10: 15195.45 | R10: 67539.8 | S10: 72727.87 | T10: 78247.02 | U10: 83611.62 | V10: 89299.33 | W10: 94653.74 | X10: 100448.13 | Y10: 107094.59 | Z10: 115048.83 | AB10: 7388347.1 | AC10: 14514.92 | AD10: 21875757 | AE10: 29441494 | AF10: 30648930 | AG10: 93957764 | AH10: 1.0150256e+08 | AI10: 1.0958698e+08 | AJ10: 1.1804885e+08 | AK10: 1.2754967e+08 | AL10: 1.3659422e+08 | AM10: 1.4677876e+08 | AO10: 10202579 | AP10: 19575990 | AQ10: 30235184 | AR10: 40802577 | AS10: 51202678 | AT10: 1.2853841e+08 | AU10: 1.4394338e+08 | AV10: 1.5794439e+08
A11: Other Operating Income | B11: =231000+2283566 -> 2514566 | C11: 1489.22 | D11: 1209.73 | E11: 2692.65 | F11: 3436.98 | G11: 5535.53 | H11: 6571.65 | I11: 21690.53 | J11: 22924.03 | K11: 24304.62 | L11: 25469.13 | M11: 32005.59 | N11: =2779021+1042767+3905955+104297+455629 -> 8287669 | O11: 876.43 | P11: 2926.32 | Q11: 6699.94 | R11: 8270.3 | S11: 9883.55 | T11: 11193.31 | U11: 12651.87 | V11: 22995.27 | W11: 24813.78 | X11: 26130.32 | Y11: 27747.54 | Z11: 29486.94 | AA11: =90017405-47961448 -> 42055957 | AB11: 552855.63 | AC11: 1957.51 | AD11: 2951912.7 | AE11: 3635563.6 | AF11: 5661977.7 | AG11: 6807840.2 | AH11: 7756174.8 | AI11: 8857340.3 | AJ11: 10479402 | AK11: 11550490 | AL11: 12705533 | AM11: 18852621 | AN11: 45873121 | AO11: 1746220.9 | AP11: 3551220.4 | AQ11: 7682085.7 | AR11: 9539708.3 | AS11: 11970768 | AT11: 11911048 | AU11: 15656451 | AV11: 16936576
A12: Financial Expenses | B12: =SUM(B13:B18) -> 138384 | C12: =SUM(C13:C18) -> 23525.59 | D12: =SUM(D13:D18) -> 45462.8 | E12: =SUM(E13:E18) -> 69909.76 | F12: =SUM(F13:F18) -> 92941.56 | G12: =SUM(G13:G18) -> 119422.38 | H12: =SUM(H13:H18) -> 145581.66 | I12: =SUM(I13:I18) -> 199320.28 | ... AV12: =SUM(AV13:AV18) -> 3.1751517e+08
A13: Interest Expense on Deposits | C13: 20484.15 | D13: 39348.61 | E13: 60677.29 | F13: 80628.8 | G13: 103936.6 | H13: 126894.02 | I13: 174143.42 | J13: 193015.06 | K13: 221026.63 | L13: 246299.48 | M13: 273668.94 | N13: =233587603+13868910+2628623+4796304 -> 254881440 | O13: 23108.37 | P13: 45962.63 | Q13: 69987.94 | R13: 94619.13 | S13: 120511.16 | T13: 123741.87 | U13: 174070.54 | V13: 201215.55 | W13: 228913.75 | X13: 257774.86 | Y13: 286245.52 | Z13: 292462.95 | AA13: 292462951 | AB13: 26601299 | AC13: 53530.55 | AD13: 82320061 | AE13: 1.1074201e+08 | AF13: 1.4101066e+08 | AG13: 1.7267667e+08 | AH13: 2.0380943e+08 | AI13: 2.362702e+08 | AJ13: 2.7083582e+08 | AK13: 3.0642597e+08 | AL13: 3.4196366e+08 | AM13: 3.4607061e+08 | AN13: 346443817 | AO13: 32058914 | AP13: 65400568 | AQ13: 1.0032708e+08 | AR13: 1.3618518e+08 | AS13: 1.7245004e+08 | AT13: 2.0947263e+08 | AU13: 2.4634636e+08 | AV13: 2.8558766e+08
A14: Cost of External Borrowings | C14: 0 | D14: 0 | E14: 0 | F14: 0 | G14: 0 | H14: 0 | I14: 0 | J14: 0 | K14: 0 | L14: 0 | M14: 0 | N14: 0 | O14: 0 | P14: 0 | Q14: 0 | R14: 0 | S14: 0 | T14: 0 | U14: 0 | V14: 0 | W14: 0 | X14: 0 | Y14: 0 | Z14: 0 | AB14: 0 | AC14: 0 | AD14: 0 | AE14: 0 | AF14: 0 | AG14: 0 | AH14: 0 | AI14: 0 | AJ14: 0 | AK14: 0 | AL14: 0 | AM14: 0 | AO14: 0 | AP14: 0 | AQ14: 0 | AR14: 0 | AS14: 0 | AT14: 0 | AU14: 0 | AV14: 0
A15: Dividend Expenses | C15: 3041.44 | D15: 6114.19 | E15: 9232.47 | F15: 12312.76 | G15: 15485.78 | H15: 18687.64 | I15: 25176.86 | J15: 28401.36 | K15: 31721.96 | L15: 34974.86 | M15: 38262.03 | N15: 0 | O15: 3204.94 | P15: 6422.54 | Q15: 9659.15 | R15: 12948.13 | S15: 16278.46 | T15: 19648.93 | U15: 23066.09 | V15: 26422.58 | W15: 30073.82 | X15: 33523.95 | Y15: 37095.52 | Z15: 39491.27 | AB15: 3406570.5 | AC15: 6840.81 | AD15: 10447633 | AE15: 14063444 | AF15: 17609532 | AG15: 21332877 | AH15: 25013190 | AI15: 28792836 | AJ15: 32567851 | AK15: 36399734 | AL15: 40217358 | AM15: 42749380 | AO15: 3697356.8 | AP15: 7448859 | AQ15: 11362369 | AR15: 15211819 | AS15: 19163190 | AT15: 23102896 | AU15: 27195279 | AV15: 31188919
A16: Other Financial Expense | C16: 0 | D16: 0 | E16: 0 | F16: 0 | G16: 0 | H16: 0 | I16: 0 | J16: 0 | K16: 0 | L16: 0 | M16: 0 | N16: 0 | O16: 0 | P16: 0 | Q16: 0 | R16: 0 | S16: 0 | T16: 0 | U16: 0 | V16: 0 | W16: 0 | X16: 0 | Y16: 0 | Z16: 884.79 | AB16: 45465.96 | AC16: 106.22 | AD16: 97109.79 | AE16: 237261.39 | AF16: 317953.45 | AG16: 386008.75 | AH16: 453370.75 | AI16: 556946.25 | AJ16: 623675.53 | AK16: 694617.19 | AL16: 752969.19 | AM16: 860813.15 | AN16: 888057 | AO16: 90702 | AP16: 235502.35 | AQ16: 121836.35 | AR16: 315536.63 | AS16: 348005.08 | AT16: 531072.93 | AU16: 600408.93 | AV16: 738584.11
A17: Fees & Commision Expense | B17: =109986+28398 -> 138384 | C17: 0 | D17: 0 | E17: 0 | F17: 0 | G17: 0 | H17: 0 | I17: 0 | J17: 0 | K17: 0 | L17: 0 | M17: 0 | N17: 0 | O17: 0 | P17: 0 | Q17: 0 | R17: 0 | S17: 0 | T17: 0 | U17: 0 | V17: 0 | W17: 0 | X17: 0 | Y17: 0 | Z17: 0 | AB17: 0 | AC17: 0 | AD17: 0 | AE17: 0 | AF17: 0 | AG17: 0 | AH17: 0 | AI17: 0 | AJ17: 0 | AK17: 0 | AL17: 0 | AM17: 0 | AO17: 0 | AP17: 0 | AQ17: 0 | AR17: 0 | AS17: 0 | AT17: 0 | AU17: 0 | AV17: 0
A18: Other Expenses | C18: 0 | D18: 0 | E18: 0 | F18: 0 | G18: 0 | H18: 0 | I18: 0 | J18: 0 | K18: 0 | L18: 0 | M18: 0 | N18: 0 | O18: 0 | P18: 0 | Q18: 0 | R18: 0 | S18: 0 | T18: 0 | U18: 0 | V18: 0 | W18: 0 | X18: 0 | Y18: 0 | Z18: 0 | AB18: 0 | AC18: 0 | AD18: 0 | AE18: 0 | AF18: 0 | AG18: 0 | AH18: 0 | AI18: 0 | AJ18: 0 | AK18: 0 | AL18: 0 | AM18: 0 | AO18: 0 | AP18: 0 | AQ18: 0 | AR18: 0 | AS18: 0 | AT18: 0 | AU18: 0 | AV18: 0
A19: Net Financial Income | B19: =B3-B12 -> 33951687 | C19: =C3-C12 -> 5894.61 | D19: =D3-D12 -> 16522.78 | E19: =E3-E12 -> 27123.46 | F19: =F3-F12 -> 93300.23 | G19: =G3-G12 -> 99782.44 | H19: =H3-H12 -> 105987.64 | I19: =I3-I12 -> 132591.3 | ... AV19: =AV3-AV12 -> 1.7338615e+08
A20: Allowance for Loan Loss | B20: =B21-B22 -> 19858888 | C20: =C21-C22 -> 1974 | D20: =D21-D22 -> -9320.6 | E20: =E21-E22 -> -2203.7 | F20: =F21-F22 -> 7950.9 | G20: =G21-G22 -> -33114.4 | H20: =H21-H22 -> 14691.9 | I20: =I21-I22 -> 16567.1 | ... AV20: =AV21-AV22 -> 26089903
A21: Provision for Loan Losses | B21: 19858888 | C21: 1974 | D21: 0 | E21: 0 | F21: 7950.9 | G21: 0 | H21: 14691.9 | I21: 16567.1 | J21: 17326.6 | K21: 6766.4 | L21: 14690.7 | M21: -10757.8 | N21: -10841221 | O21: 13027 | P21: 34770 | Q21: 20389.5 | R21: 25146 | S21: 24755.6 | T21: 24755.6 | U21: 29019.9 | V21: 19665.9 | W21: 7244.5 | X21: 2216.1 | Y21: -2716.8 | Z21: -10545.3 | AA21: -10518248 | AB21: -10545310 | AC21: -6605.6 | AD21: -4153090.9 | AE21: -2230552.6 | AF21: -939303.4 | AG21: 7173707.5 | AH21: 12407786 | AI21: 12331674 | AJ21: 7548918.1 | AK21: 7573535.4 | AL21: 12542368 | AM21: -10706988 | AO21: 7405655.6 | AP21: 7405655.6 | AQ21: -5903451.3 | AR21: -5556997.7 | AS21: -5143422.8 | AT21: 4799982.7 | AU21: 18828706 | AV21: 26089903
A22: Value of Loans Recovered | C22: 0 | D22: 9320.6 | E22: 2203.7 | F22: 0 | G22: 33114.4 | H22: 0 | I22: 0 | J22: 0 | K22: 0 | L22: 0 | M22: 0 | N22: 0 | O22: 0 | P22: 0 | Q22: 0 | R22: 0 | S22: 0 | T22: 0 | U22: 0 | V22: 0 | W22: 0 | X22: 0 | Y22: 0 | Z22: 0 | AB22: 0 | AC22: 0 | AD22: 0 | AE22: 0 | AF22: 0 | AG22: 0 | AH22: 0 | AI22: 0 | AJ22: 0 | AK22: 0 | AL22: 0 | AM22: 0 | AO22: 0 | AP22: 0 | AQ22: 0 | AR22: 0 | AS22: 0 | AT22: 0 | AU22: 0 | AV22: 0
A23: Operating Expeses | B23: =SUM(B24:B28) -> 14056548 | C23: =SUM(C24:C28) -> 4849.74 | D23: =SUM(D24:D28) -> 9259.8 | E23: =SUM(E24:E28) -> 18695.19 | F23: =SUM(F24:F28) -> 26723.84 | G23: =SUM(G24:G28) -> 30466.41 | H23: =SUM(H24:H28) -> 34845.96 | I23: =SUM(I24:I28) -> 48306.38 | ... AV23: =SUM(AV24:AV28) -> 70135827
A24: Personel Expenses | B24: =5461132+192375+127300 -> 5780807 | C24: 1702 | D24: 3752.1 | E24: 6141 | F24: 12427.9 | G24: 14214.6 | H24: 16329.7 | I24: 22415.8 | J24: 24701.8 | K24: 26974.9 | L24: 28377.2 | M24: 31011.4 | N24: =22423701+1890459+969721+18680+2077296+32200+3599332+818200 -> 31829589 | O24: 2138.6 | P24: 4491.5 | Q24: 11730.7 | R24: 14274.7 | S24: 18170.7 | T24: 21148.3 | U24: 24084.4 | V24: 26668.3 | W24: 29258.7 | X24: 31829.3 | Y24: 34238.7 | Z24: 37473.8 | AA24: 39627677 | AB24: 2620938 | AC24: 5201.7 | AD24: 13757819 | AE24: 18483484 | AF24: 21461384 | AG24: 24548611 | AH24: 28492716 | AI24: 31715516 | AJ24: 35576164 | AK24: 38702340 | AL24: 42794064 | AM24: 46791541 | AN24: 53961102 | AO24: 3086648.5 | AP24: 6760836 | AQ24: 11247666 | AR24: 15109860 | AS24: 19005634 | AT24: 23909127 | AU24: 27415375 | AV24: 31419810
A25: Governance Expenses | B25: =133506+438192+683920+1371094 -> 2626712 | C25: 165 | D25: 1040.6 | E25: 5565.93 | F25: 5715.93 | G25: 5985.93 | H25: 6315.11 | I25: 6709.11 | J25: 7378.11 | K25: 7714.11 | L25: 8165.71 | M25: 9210.51 | N25: =2243174+2634000+1160217 -> 6037391 | O25: 429.63 | P25: 477 | Q25: 6036.25 | R25: 6232.25 | S25: 6588.25 | T25: 6814.25 | U25: 7121.86 | V25: 8391.86 | W25: 9086.36 | X25: 9329.36 | Y25: 10145.91 | Z25: 10769.47 | AA25: 6427970 | AB25: 120000 | AC25: 515.3 | AD25: 6421123 | AE25: 6829389.8 | AF25: 7321847 | AG25: 7853647 | AH25: 9090640 | AI25: 6102737 | AJ25: 7506487 | AK25: 10081787 | AL25: 10400850 | AM25: 11314010 | AN25: 10121714 | AO25: 343800 | AP25: 718600 | AQ25: 3642301 | AR25: 4528076 | AS25: 4966076 | AT25: 5318076 | AU25: 5807076 | AV25: 6270278
A26: Marketing Expenses | B26: =90080 -> 90080 | C26: 152.86 | D26: 161.36 | E26: 301.16 | F26: 311.16 | G26: 411.16 | H26: 501.16 | I26: 442.36 | J26: 745.36 | K26: 785.36 | L26: 785.36 | M26: 836.79 | N26: 0 | O26: 246.95 | P26: 278.95 | Q26: 533.88 | R26: 533.88 | S26: 563.88 | T26: 563.88 | U26: 573.88 | V26: 965.34 | W26: 982.84 | X26: 1102.84 | Y26: 1102.84 | Z26: 1703.09 | AA26: =532748+763294 -> 1296042 | AB26: 229000 | AC26: 617.99 | AD26: 1367630 | AE26: 1373630 | AF26: 4575426 | AG26: 8391294.9 | AH26: 8460334.9 | AI26: 9048734.9 | AJ26: 9450984.9 | AK26: 9677484.9 | AL26: 9682383.9 | AM26: 10285884 | AN26: 8306151 | AO26: 483060 | AP26: 497060 | AQ26: 1238690 | AR26: 1446690 | AS26: 1692330 | AT26: 1711330 | AU26: 1846330 | AV26: 1962480
A27: Depreciation and Amortization | B27: =543202.33 -> 543202.33 | C27: 525.66 | D27: 877.45 | E27: 1256.96 | F27: 1625.23 | G27: 2017.17 | H27: 2559.18 | I27: 4050.65 | J27: 4633.13 | K27: 5233.68 | L27: 5769.53 | M27: 6106.93 | N27: 0 | O27: 319.17 | P27: 606.37 | Q27: 923.17 | R27: 1228.61 | S27: 1543.05 | T27: 1798.93 | U27: 2128.09 | V27: 2785.02 | W27: 3136.42 | X27: 3765.77 | Y27: 4141.51 | Z27: 4528.76 | AA27: =320927+4207829 -> 4528756 | AB27: 358210.84 | AC27: 680.89 | AD27: 1037211.9 | AE27: 1372815.2 | AF27: 1743849.1 | AG27: 2106710.5 | AH27: 2480764.3 | AI27: 2807748.2 | AJ27: 3168741.1 | AK27: 3665171.3 | AL27: 4636658.2 | AM27: 5337679.2 | AN27: 5337678 | AO27: 543761.2 | AP27: 1034181.9 | AQ27: 1612792.9 | AR27: 2172680.8 | AS27: 2802398.3 | AT27: 3501761.4 | AU27: 4231605.4 | AV27: 4960686.9
A28: Administrative Expenses | B28: =49200+61443+67825+177326+79656+59878+190056.14+30096+50000+85000+137100+427336+143797+15000+53172.19+1793226+29000+259063.86+47571+1260000 -> 5015746.2 | C28: 2304.22 | D28: 3428.29 | E28: 5430.14 | F28: 6643.62 | G28: 7837.55 | H28: 9140.81 | I28: 14688.46 | J28: 15707.73 | K28: 18103.23 | L28: 18686.76 | M28: 23089.71 | N28: =30429990 -> 30429990 | O28: 2065.75 | P28: 3975.29 | Q28: 6791.22 | R28: 7535.88 | S28: 10816.43 | T28: 12151.47 | U28: 17487.64 | V28: 18080.01 | W28: 19067.96 | X28: 20988.86 | Y28: 22961.15 | Z28: 25359.78 | AA28: =31314924-AA27-AA26 -> 25490126 | AB28: 2241391.8 | AC28: 4541.15 | AD28: 7249445.7 | AE28: 9552546.4 | AF28: 12152491 | AG28: 15226013 | AH28: 20900327 | AI28: 22628646 | AJ28: 24120787 | AK28: 25789715 | AL28: 27721778 | AM28: 29841976 | AN28: =39949285-AN26 -> 31643134 | AO28: 1224625.6 | AP28: 1470775.2 | AQ28: 3307083 | AR28: 6290312.6 | AS28: 9632702.9 | AT28: 14101223 | AU28: 21867653 | AV28: 25522572
A29: Net Operating Income | B29: =B19-B20-B23 -> 36251.48 | C29: =C19-C20-C23 -> -929.13 | D29: =D19-D20-D23 -> 16583.58 | E29: =E19-E20-E23 -> 10631.97 | F29: =F19-F20-F23 -> 58625.49 | G29: =G19-G20-G23 -> 102430.43 | H29: =H19-H20-H23 -> 56449.78 | I29: =I19-I20-I23 -> 67717.82 | ... AV29: =AV19-AV20-AV23 -> 77160421
A30: Net Non operating Income/Expense | B30: =B31-B32 -> 0 | C30: =C31-C32 -> 0 | D30: =D31-D32 -> 0 | E30: =E31-E32 -> 0 | F30: =F31-F32 -> 0 | G30: =G31-G32 -> 0 | H30: =H31-H32 -> 0 | I30: =I31-I32 -> 0 | ... AV30: =AV31-AV32 -> 0
A31: Non Operating Income | C31: 0 | D31: 0 | E31: 0 | F31: 0 | G31: 0 | H31: 0 | I31: 0 | J31: 0 | K31: 0 | L31: 0 | M31: 0 | N31: 0 | O31: 0 | P31: 0 | Q31: 0 | R31: 0 | S31: 0 | T31: 0 | U31: 0 | V31: 0 | W31: 0 | X31: 0 | Y31: 0 | Z31: 0 | AA31: 0 | AB31: 0 | AC31: 0 | AD31: 0 | AE31: 0 | AF31: 0 | AG31: 0 | AH31: 0 | AI31: 0 | AJ31: 0 | AK31: 0 | AL31: 0 | AM31: 0 | AN31: 0 | AO31: 0 | AP31: 0 | AQ31: 0 | AR31: 0 | AS31: 0 | AT31: 0 | AU31: 0 | AV31: 0
A32: Non Operating Expense | C32: 0 | D32: 0 | E32: 0 | F32: 0 | G32: 0 | H32: 0 | I32: 0 | J32: 0 | K32: 0 | L32: 0 | M32: 0 | N32: 0 | O32: 0 | P32: 0 | Q32: 0 | R32: 0 | S32: 0 | T32: 0 | U32: 0 | V32: 0 | W32: 0 | X32: 0 | Y32: 0 | Z32: 0 | AA32: 0 | AB32: 0 | AC32: 0 | AD32: 0 | AE32: 0 | AF32: 0 | AG32: 0 | AH32: 0 | AI32: 0 | AJ32: 0 | AK32: 0 | AL32: 0 | AM32: 0 | AN32: 0 | AO32: 0 | AP32: 0 | AQ32: 0 | AR32: 0 | AS32: 0 | AT32: 0 | AU32: 0 | AV32: 0
A33: Net Income(Before Tax & Donations) | B33: =B29+B30 -> 36251.48 | C33: =C29+C30 -> -929.13 | D33: =D29+D30 -> 16583.58 | E33: =E29+E30 -> 10631.97 | F33: =F29+F30 -> 58625.49 | G33: =G29+G30 -> 102430.43 | H33: =H29+H30 -> 56449.78 | I33: =I29+I30 -> 67717.82 | ... AV33: =AV29+AV30 -> 77160421
A34: Taxes | B34: 14602 | C34: 0 | D34: 0 | E34: 0 | F34: 0 | G34: 0 | H34: 0 | I34: 0 | J34: 0 | K34: 0 | L34: 0 | M34: 0 | N34: 8797271 | O34: 0 | P34: 0 | Q34: 0 | R34: 0 | S34: 0 | T34: 0 | U34: 0 | V34: 0 | AA34: 11661643 | AB34: 0 | AC34: 0 | AD34: 0 | AE34: 0 | AF34: 0 | AG34: 0 | AH34: 0 | AI34: 0 | AJ34: 0 | AK34: 0 | AL34: 0 | AM34: 0 | AN34: 22441722 | AO34: 0 | AP34: 0 | AQ34: 0 | AR34: 0 | AS34: 0 | AT34: 0 | AU34: 0 | AV34: 0
A35: Net Income(After Tax Before Donations) | B35: =B33-B34 -> 21649.48 | C35: =C33-C34 -> -929.13 | D35: =D33-D34 -> 16583.58 | E35: =E33-E34 -> 10631.97 | F35: =F33-F34 -> 58625.49 | G35: =G33-G34 -> 102430.43 | H35: =H33-H34 -> 56449.78 | I35: =I33-I34 -> 67717.82 | ... AV35: =AV33-AV34 -> 77160421
A36: Donations | C36: 0 | D36: 0 | E36: 0 | F36: 0 | G36: 0 | H36: 0 | I36: 0 | J36: 0 | K36: 0 | L36: 0 | M36: 0 | N36: 0 | O36: 0 | P36: 0 | Q36: 0 | R36: 0 | S36: 0 | T36: 0 | U36: 0 | V36: 0 | AO36: 0 | AP36: 0 | AQ36: 0 | AR36: 0 | AS36: 0 | AT36: 0 | AU36: 0 | AV36: 0
A37: Net Income/(After Tax & Donations) | B37: =B35-B36 -> 21649.48 | C37: =C35-C36 -> -929.13 | D37: =D35-D36 -> 16583.58 | E37: =E35-E36 -> 10631.97 | F37: =F35-F36 -> 58625.49 | G37: =G35-G36 -> 102430.43 | H37: =H35-H36 -> 56449.78 | I37: =I35-I36 -> 67717.82 | ... AV37: =AV35-AV36 -> 77160421
A39: Total Expenses | B39: =B12+B23 -> 14194932 | C39: =C12+C23 -> 28375.33 | D39: =D12+D23 -> 54722.6 | E39: =E12+E23 -> 88604.95 | F39: =F12+F23 -> 119665.4 | G39: =G12+G23 -> 149888.79 | H39: =H12+H23 -> 180427.62 | I39: =I12+I23 -> 247626.66 | ... AV39: =AV12+AV23 -> 3.8765099e+08
O44: =O37-164292468.04 -> -1.6430622e+08

Sheet Dec 2019 report
A1: STIMA SACCO SOCIETY LIMITED
A2: PERFORMANCE AND COMPLIANCE REPORT AS AT : 31st December , 2019
B3: Prudential Standard | C3: Audited | D3: Returns | F3: Audited 2019 | G3: Aggregate for all Licensed Saccos
C4: 2018 | D4: 30th September , 2019 | E4: 31st December , 2019
A5: A. CAPITAL ADEQUACY
A6: Core Capital | B6: ≥10M | C6: 4057843000 | D6: 3.9340926e+09 | E6: 4.252452e+09 | F6: =F33 -> 35293281 | G6: 8.5755077e+10
A7: Core Capital/Total Assets | B7: ≥10% | C7: 0.12567652 | D7: 0.11408248 | E7: 0.11481094 | F7: =F6/F29 -> 0.12028588 | G7: 0.15609442
A8: Institutional Capital/Total Assets | B8: ≥8% | C8: 0.079393471 | D8: 0.064591681 | E8: 0.067244176 | F8: =F34/F29 -> 0.055632234 | G8: 0.091531093
A9: B. ASSET QUALITY
A10: NPL (Substandard+Doubtful+Loss) | B10: <5% | C10: 0 | D10: 0.054329847 | E10: 0.047637752 | F10: =F35/F32 -> 0 | G10: 0.07434801
A11: Non-Earning Assets | B11: <10% | C11: 0.035863732 | D11: 0.035724114 | E11: 0.037274684 | F11: =F36/F29 -> 0.052726313 | G11: 0.10558073
A12: Equity investments/Deposits | B12: <5% | C12: 0 | D12: 0.024842844 | E12: 0.023590605 | F12: =F38/F31 -> 0 | G12: 0.034793574
A13: Equity investments/Core capital | B13: <40% | C13: 0 | D13: 0.16950928 | E13: 0.1568204 | F13: =F38/F33 -> 0 | G13: 0.15319582
A14: C. EARNINGS RATING
A15: Yield on Gross Loans | C15: 0.15191121 | D15: 0.11822952 | E15: 0.1455451 | F15: =F48/F32 -> 0.12728569 | G15: 0.16355249
A16: Total Expense/Total Income | C16: 0.75439892 | D16: 0.75528666 | E16: 0.7186639 | F16: =F49/F44 -> 0.41639489 | G16: 0.70158636
A17: Net Income/Average Assets (ROA) | C17: 0.0278967 | D17: 0.020089744 | E17: 0.031914696 | F17: =F50/F30 -> 1.3289469e-06 | G17: 0.038444702
A18: Operating Expenses/Financial Income (OPEX) | C18: 0.25221239 | D18: 0.25235898 | E18: 0.24257735 | F18: =F47/F45 -> 0.41401617 | G18: 0.31925833
A19: D. LIQUIDITY
A20: Liquid Assets/Short-term Liabilities | B20: >15% | C20: 0.22714378 | D20: 0.72775006 | E20: 0.53145529 | F20: =F40/F41 -> 0.23756555 | G20: 0.5504023
A21: External Borrowing/Total Assets | B21: <25% | C21: 0.01020404 | D21: 0 | E21: 0 | F21: =F42/F29 -> 0 | G21: 0.03910423
A22: Liquid Assets/Total Assets | C22: 0.060313562 | D22: 0.18011196 | E22: 0.14005067 | F22: =F40/F29 -> 0.20809816 | G22: 0.11043073
A23: E. STRUCTURE/SENSITIVITY TO RISK
A24: Gross loans /Total Assets | B24: 70-80 | C24: 0.79999743 | D24: 0.7800437 | E24: 0.82085193 | F24: =F32/F29 -> 0.81183537 | G24: 0.75950448
A25: Gross loans/Deposits | B25: >100% | C25: 1.0373556 | D25: 1.0020925 | E25: 1.0755191 | F25: =F32/F31 -> 0.92431937 | G25: 1.1050835
A26: Financial Investments/Total Assets | C26: 0.18797701 | D26: 0.034489796 | E26: 0.033529934 | F26: =F38/F29 -> 0 | G26: 0.059615079
A27: Dividends+Interest on Deposits/Total Income | C27: 0.49156615 | D27: 0.49594541 | E27: 0.47078017 | F27: =F46/F44 -> 0 | G27: 0.3152237
A28: F. KEY FINANCIAL STATISTICS | C28: 2015 | D28: 2016 | E28: 2017 | G28: AGGREGATE
A29: Total Assets | C29: 32287995000 | D29: 3.4484633e+10 | E29: 3.7038736e+10 | F29: ='Evolutive SFP'!B27 -> 2.9341168e+08 | G29: 5.4937953e+11
A30: Average Assets | C30: 30426610000 | D30: 3.2935177e+10 | E30: 3.4818536e+10 | F30: =(C29+F29)/2 -> 1.6290703e+10 | G30: 5.2175164e+11
A31: Total Deposits | C31: 24900152000 | D31: 2.6843352e+10 | E31: 2.8268507e+10 | F31: ='Evolutive SFP'!B31 -> 2.5770528e+08 | G31: 3.775789e+11
A32: Gross Loans | C32: 25830313000 | D32: 2.6899521e+10 | E32: 3.0403318e+10 | F32: ='Evolutive SFP'!B15 -> 238201977 | G32: 4.1725622e+11
A33: Core Capital | C33: 4057843000 | D33: 3.9340926e+09 | E33: 4.252452e+09 | F33: =Financials!AS11 -> 35293281 | G33: 8.5755077e+10
A34: Institutional Capital | C34: 2563456000 | D34: 2.2274204e+09 | E34: 2.4906393e+09 | F34: =Financials!AS12 -> 16323147 | G34: 5.0285309e+10
A35: Non-performing Loans | C35: 0 | D35: 1.4614469e+09 | E35: 1.4483457e+09 | G35: 3.1022169e+10
A36: Non-Earning Assets | C36: 1157968000 | D36: 1.231933e+09 | E36: 1.3806072e+09 | F36: =Financials!AS34 -> 15470516 | G36: 5.8003891e+10
A37: Property and Equipment | C37: 320370000 | D37: 3.0385145e+08 | E37: 3.017075e+08 | F37: =Financials!AS35 -> 3806303 | G37: 1.780879e+10
A38: Equity Investments | C38: 0 | D38: 6.6686521e+08 | E38: 6.6687121e+08 | F38: ='Evolutive SFP'!B12+'Evolutive SFP'!B13 -> 0 | G38: 1.3137319e+10
A39: Financial Investments | C39: 4680656000 | D39: 9.2582174e+08 | E39: 9.4784119e+08 | F39: ='Evolutive SFP'!B8 -> 115855 | G39: 2.2509396e+10
A40: Liquid Assets | C40: 1947404000 | D40: 6.2110949e+09 | E40: 5.1872997e+09 | F40: ='Evolutive SFP'!B4+'Evolutive SFP'!B11+'Evolutive SFP'!B10+'Evolutive SFP'!B9 -> 61058429 | G40: 6.0668383e+10
...

Sheet FORM 4
D1: 42795
B2: CLASSIFICATION | C2: NO. OF A/Cs | D2: OUTSTANDING LOAN PORTFOLIO(Kshs) | E2: REQUIRED PROVISION | F2: REQUIRED PROVISION AMOUNT(Kshs)
B3: Performing | C3: 56175 | D3: 1.993701e+10 | E3: 0 | F3: =D3*E3 -> 0
B4: Watch | C4: 342 | D4: 6.0964609e+08 | E4: 0.05 | F4: =D4*E4 -> 30482304
B5: Substandard | C5: 721 | D5: 5.3176756e+08 | E5: 0.25 | F5: =D5*E5 -> 1.3294189e+08
B6: Doubtful | C6: 182 | D6: 1.3302199e+08 | E6: 0.5 | F6: =D6*E6 -> 66510994
B7: Loss | C7: 285 | D7: 53640300 | E7: 1 | F7: =D7*E7 -> 53640300
B8: subtotal | C8: =SUM(C3:C7) -> 57705 | D8: =SUM(D3:D7) -> 2.1265086e+10 | F8: =SUM(F3:F7) -> 2.8357549e+08
D10: 42887
B11: CLASSIFICATION | C11: NO. OF A/Cs | D11: OUTSTANDING LOAN PORTFOLIO(Kshs) | E11: REQUIRED PROVISION | F11: REQUIRED PROVISION AMOUNT(Kshs)
B12: Performing | C12: 52931 | D12: 2.0932769e+10 | E12: 0.01 | F12: =D12*E12 -> 2.0932769e+08
B13: Watch | C13: 1072 | D13: 6.9302846e+08 | E13: 0.05 | F13: =D13*E13 -> 34651423
B14: Substandard | C14: 237 | D14: 2.1101418e+08 | E14: 0.25 | F14: =D14*E14 -> 52753546
B15: Doubtful | C15: 75 | D15: 31560414 | E15: 0.5 | F15: =D15*E15 -> 15780207
B16: Loss | C16: 16 | D16: 4449341.3 | E16: 1 | F16: =D16*E16 -> 4449341.3
B17: subtotal | C17: =SUM(C12:C16) -> 54331 | D17: =SUM(D12:D16) -> 2.1872821e+10 | E17: 1.81 | F17: =SUM(F12:F16) -> 3.169622e+08
C18: NPL | D18: =SUM(D14:D16) -> 2.4702394e+08
C19: PAR | D19: =D18/D17 -> 0.011293648
D21: 42979
B22: CLASSIFICATION | C22: NO. OF A/Cs | D22: OUTSTANDING LOAN PORTFOLIO(Kshs) | E22: REQUIRED PROVISION | F22: REQUIRED PROVISION AMOUNT(Kshs)
B23: Performing | C23: 48840 | D23: 19551006671 | E23: 0.01
B24: Watch | C24: 2088 | D24: 1.0437061e+09 | E24: 0.05 | F24: =D24*E24 -> 52185307
B25: Substandard | C25: 4389 | D25: 1.5125185e+09 | E25: 0.25 | F25: =D25*E25 -> 3.7812962e+08
B26: Doubtful | C26: 927 | D26: 4.2115024e+08 | E26: 0.5 | F26: =D26*E26 -> 2.1057512e+08
B27: Loss | C27: 1102 | D27: 229316298 | E27: 1 | F27: =D27*E27 -> 229316298
B28: subtotal | C28: =SUM(C23:C27) -> 57346 | D28: =SUM(D23:D27) -> 2.2757698e+10 | F28: =SUM(F23:F27) -> 8.7020635e+08
C29: NPL | D29: =SUM(D25:D27) -> 2.162985e+09
C30: PAR | D30: =D29/D28 -> 0.095044105
D32: 43070
B33: CLASSIFICATION | C33: NO. OF A/Cs | D33: OUTSTANDING LOAN PORTFOLIO(Kshs) | E33: REQUIRED PROVISION | F33: REQUIRED PROVISION AMOUNT(Kshs)
B34: Performing | C34: 50625 | D34: 2.0056569e+10 | E34: 0 | F34: =D34*E34 -> 0
B35: Watch | C35: 1985 | D35: 817339191 | E35: 0.05 | F35: =D35*E35 -> 40866960
B36: Substandard | C36: 4389 | D36: 1.2107046e+09 | E36: 0.25 | F36: =D36*E36 -> 3.0267616e+08
B37: Doubtful | C37: 1012 | D37: 6.4041824e+08 | E37: 0.5 | F37: =D37*E37 -> 3.2020912e+08
B38: Loss | C38: 1121 | D38: 4.8124864e+08 | E38: 1 | F38: =D38*E38 -> 4.8124864e+08
B39: subtotal | C39: =SUM(C34:C38) -> 59132 | D39: =SUM(D34:D38) -> 2.320628e+10 | E39: 1.81 | F39: =SUM(F34:F38) -> 1.1450009e+09
C40: NPL | D40: =SUM(D36:D38) -> 2.3323715e+09
C41: PAR | D41: =D40/D39 -> 0.10050605
D43: Audited 2017
B44: CLASSIFICATION | C44: NO. OF A/Cs | D44: OUTSTANDING LOAN PORTFOLIO(Kshs) | E44: REQUIRED PROVISION | F44: REQUIRED PROVISION AMOUNT(Kshs)
...

Sheet CAELS
A1: STIMA SACCO 2017 CAELS
D2: 2013 Audited | E2: 2014 Audited | F2: 2015 Audited | G2: 2016 Audited | H2: 42736 | I2: 42767 | J2: 42795 | K2: 42826 | L2: 42856 | M2: 42887 | N2: 42917 | O2: 42948 | P2: 42979 | Q2: 43009 | R2: 43040 | S2: 43070 | T2: Audited 2017 | U2: 43101 | V2: 43132 | W2: 43160 | X2: 43191 | Y2: 43221 | Z2: 43252 | AA2: 43282 | AB2: 43313 | AC2: 43344 | AD2: 43374 | AE2: 43405 | AF2: 43435 | AG2: Audited 2018 | AH2: 43466 | AI2: 43497 | AJ2: 43525 | AK2: 43556 | AL2: 43586 | AM2: 43617 | AN2: 43647 | AO2: 43678 | AP2: 43709 | AQ2: 43739 | AR2: 43770 | AS2: 43800 | AT2: Audited 2019 | AU2: 43831 | AV2: 43862 | AW2: 43891 | AX2: 43922 | AY2: 43952 | AZ2: 43983 | BA2: 44013 | BB2: 44044 | BC2: 44075 | BD2: 44105 | BE2: 44136 | BF2: 44166 | BG2: Audited 2020 | BH2: 44197 | BI2: 44228 | BJ2: 44256 | BK2: 44287 | BL2: 44317 | BM2: 44348 | BN2: 44378 | BO2: 44409 | BP2: 44440 | BQ2: 44470 | BR2: 44501 | BS2: 44531 | BT2: Audited 2021 | BU2: 44562 | BV2: 44593 | BW2: 44621 | BX2: 44652 | BY2: 44682 | BZ2: 44713 | CA2: 44743 | CB2: 44774 | CC2: 44805 | CD2: 44835 | CE2: 44866 | CF2: 44896 | CG2: Audited 2022 | CH2: 44927 | CI2: 44958 | CJ2: 44986 | CK2: 45017 | CL2: 45047 | CM2: 45078 | CN2: 45108 | CO2: 45139
