Workbook
Name BALANCE1_LDA01: '[1]Financial Statements'!$E$112
Name BALANCE1_LDA12: '[1]Financial Statements'!$E$123
Name BALANCE2_LDA01: '[1]Financial Statements'!$F$112
Name BALANCE2_LDA12: '[1]Financial Statements'!$F$123
Name BALANCE3_LDA01: '[1]Financial Statements'!$G$112
Name BALANCE3_LDA12: '[1]Financial Statements'!$G$123
Name BALANCE4_LDA01: '[1]Financial Statements'!$H$112
Name BALANCE4_LDA12: '[1]Financial Statements'!$H$123
Name BALANCE5_LDA01: '[1]Financial Statements'!$I$112
Name BALANCE5_LDA12: '[1]Financial Statements'!$I$123
Name BALANCE6_LDA01: '[1]Financial Statements'!$J$112
Name BALANCE6_LDA12: '[1]Financial Statements'!$J$123
Name PEARLS1_LA002: '[1]Financial Statements'!$E$280
Name PEARLS1_LE008: '[1]Financial Statements'!$E$275
Name PEARLS1_LE009: '[1]Financial Statements'!$E$276
Name PEARLS1_LR001: '[1]Financial Statements'!$E$282
Name PEARLS1_LR005: '[1]Financial Statements'!$E$286
Name PEARLS1_LR006: '[1]Financial Statements'!$E$287
Name PEARLS1_LR007: '[1]Financial Statements'!$E$288
Name PEARLS1_LR009: '[1]Financial Statements'!$E$290
Name PEARLS1_LS001: '[1]Financial Statements'!$E$298
Name PEARLS1_LS005: '[1]Financial Statements'!$E$302
Name PEARLS1_LS011: '[1]Financial Statements'!$E$308
Name PEARLS2_LA002: '[1]Financial Statements'!$F$280
Name PEARLS2_LE008: '[1]Financial Statements'!$F$275
Name PEARLS2_LE009: '[1]Financial Statements'!$F$276
Name PEARLS2_LR001: '[1]Financial Statements'!$F$282
Name PEARLS2_LR005: '[1]Financial Statements'!$F$286
Name PEARLS2_LR006: '[1]Financial Statements'!$F$287
Name PEARLS2_LR007: '[1]Financial Statements'!$F$288
Name PEARLS2_LR009: '[1]Financial Statements'!$F$290
Name PEARLS2_LS001: '[1]Financial Statements'!$F$298
Name PEARLS2_LS005: '[1]Financial Statements'!$F$302
Name PEARLS2_LS010: '[1]Financial Statements'!$F$307
Name PEARLS2_LS011: '[1]Financial Statements'!$F$308
Name PEARLS3_LA002: '[1]Financial Statements'!$G$280
Name PEARLS3_LE008: '[1]Financial Statements'!$G$275
Name PEARLS3_LE009: '[1]Financial Statements'!$G$276
Name PEARLS3_LR001: '[1]Financial Statements'!$G$282
Name PEARLS3_LR005: '[1]Financial Statements'!$G$286
Name PEARLS3_LR006: '[1]Financial Statements'!$G$287
Name PEARLS3_LR007: '[1]Financial Statements'!$G$288
Name PEARLS3_LR009: '[1]Financial Statements'!$G$290
Name PEARLS3_LS001: '[1]Financial Statements'!$G$298
Name PEARLS3_LS005: '[1]Financial Statements'!$G$302
Name PEARLS3_LS010: '[1]Financial Statements'!$G$307
Name PEARLS3_LS011: '[1]Financial Statements'!$G$308
Name PEARLS4_LA002: '[1]Financial Statements'!$H$280
Name PEARLS4_LE008: '[1]Financial Statements'!$H$275
Name PEARLS4_LE009: '[1]Financial Statements'!$H$276
Name PEARLS4_LR001: '[1]Financial Statements'!$H$282
Name PEARLS4_LR005: '[1]Financial Statements'!$H$286
Name PEARLS4_LR006: '[1]Financial Statements'!$H$287
Name PEARLS4_LR007: '[1]Financial Statements'!$H$288
Name PEARLS4_LR009: '[1]Financial Statements'!$H$290
Name PEARLS4_LS001: '[1]Financial Statements'!$H$298
Name PEARLS4_LS005: '[1]Financial Statements'!$H$302
Name PEARLS4_LS010: '[1]Financial Statements'!$H$307
Name PEARLS4_LS011: '[1]Financial Statements'!$H$308
Name PEARLS5_LA002: '[1]Financial Statements'!$I$280

Sheet Evolutive SFP
B3: AUDITED 2018 | C3: AUDITED 2019 | D3: Audited 2020 | E3: Audited 2021 | F3: 44562 | G3: 44593 | H3: 44621 | I3: 44652 | J3: 44682 | K3: 44713 | L3: 44743 | M3: 44774 | N3: 44805 | O3: 44835 | P3: 44866 | Q3: AUDITED 2022 | R3: 45139 | S3: 45170
A4: Cash & cash Equivalent | B4: =(B5+B6) -> 3387311998 | C4: =(C5+C6) -> 3991429849 | D4: =(D5+D6) -> 5290319261 | E4: =(E5+E6) -> 5829694681 | F4: =(F5+F6) -> 5829694682 | G4: =(G5+G6) -> 5829694683 | H4: =(H5+H6) -> 5829694684 | I4: =(I5+I6) -> 5829694685 | ... S4: =(S5+S6) -> 0
A5: Cash In Hand | B5: 26512495 | C5: 30233907 | D5: 20406118 | E5: 25710890 | F5: 25710891 | G5: 25710892 | H5: 25710893 | I5: 25710894 | J5: 25710895 | K5: 25710896 | L5: 25710897 | M5: 25710898 | N5: 25710899 | O5: 25710900 | P5: 25710901 | Q5: 27832547 | R5: 22400060
A6: Cash at Bank | B6: 3360799503 | C6: =271341785+3689854157 -> 3961195942 | D6: =273200652+4996712491 -> 5269913143 | E6: =505109219+5298874572 -> 5803983791 | F6: =505109219+5298874572 -> 5803983791 | G6: =505109219+5298874572 -> 5803983791 | H6: =505109219+5298874572 -> 5803983791 | I6: =505109219+5298874572 -> 5803983791 | J6: =505109219+5298874572 -> 5803983791 | K6: =505109219+5298874572 -> 5803983791 | L6: =505109219+5298874572 -> 5803983791 | ... P6: =505109219+5298874572 -> 5803983791 | Q6: =383228584+4461761686 -> 4844990270 | R6: 4.7055721e+09
A7: Prepayment and Sundry | B7: =67100147+7781378 -> 74881525 | C7: 116005407 | D7: 28470745 | E7: =28153319 -> 28153319 | F7: =28153319 -> 28153319 | G7: =28153319 -> 28153319 | H7: =28153319 -> 28153319 | I7: =28153319 -> 28153319 | J7: =28153319 -> 28153319 | K7: =28153319 -> 28153319 | L7: =28153319 -> 28153319 | ... P7: =28153319 -> 28153319 | Q7: 40260053 | R7: 0
A8: Financial Investment | B8: =(B9+B10+B11+B13+B12) -> 425967642 | C8: =(C9+C10+C11+C13+C12) -> 420181668 | D8: =(D9+D10+D11+D13+D12) -> 472356221 | E8: =(E9+E10+E11+E13+E12) -> 539708642 | F8: =(F9+F10+F11+F13+F12) -> 539708642 | G8: =(G9+G10+G11+G13+G12) -> 539708642 | H8: =(H9+H10+H11+H13+H12) -> 539708642 | I8: =(I9+I10+I11+I13+I12) -> 539708642 | ... S8: =(S9+S10+S11+S13+S12) -> 0
A9: Government Security | Q9: 1135666564 | R9: 1.2669177e+09
A10: Other Securities | B10: 411814027 | R10: 0
A11: Balances in NACCOS (E.g Jungu Kuu, ESS, Savings,Money Market,Coop FD, CFP) | B11: 14153615 | C11: 397200000 | E11: 503122146 | F11: 503122146 | G11: 503122146 | H11: 503122146 | I11: 503122146 | J11: 503122146 | K11: 503122146 | L11: 503122146 | M11: 503122146 | N11: 503122146 | O11: 503122146 | P11: 503122146 | R11: 0
A12: Equity Investments in NACCOs(Shares in- CIC, KUSCCO, COOP BANK,CAK, KERUSSU) | C12: 22981668 | D12: 449810772 | E12: 22717497 | F12: 22717497 | G12: 22717497 | H12: 22717497 | I12: 22717497 | J12: 22717497 | K12: 22717497 | L12: 22717497 | M12: 22717497 | N12: 22717497 | O12: 22717497 | P12: 22717497 | Q12: 52354142 | R12: 53354142
A13: Equity Investments in companies - shares/stocks | D13: 22545449 | E13: 13868999 | F13: 13868999 | G13: 13868999 | H13: 13868999 | I13: 13868999 | J13: 13868999 | K13: 13868999 | L13: 13868999 | M13: 13868999 | N13: 13868999 | O13: 13868999 | P13: 13868999
A14: Net Loan Portfolio | B14: =(B15-B16) -> 8297125538 | C14: =(C15-C16) -> 8313754552 | D14: =(D15-D16) -> 8241685920 | E14: =(E15-E16) -> 8686477474 | F14: =(F15-F16) -> 8686477474 | G14: =(G15-G16) -> 8686477474 | H14: =(H15-H16) -> 8686477474 | I14: =(I15-I16) -> 8686477474 | ... S14: =(S15-S16) -> 0
A15: Gross Loan Portfolio | B15: 8320111836 | C15: 8414359918 | D15: 8419219143 | E15: 8851981817 | F15: 8851981817 | G15: 8851981817 | H15: 8851981817 | I15: 8851981817 | J15: 8851981817 | K15: 8851981817 | L15: 8851981817 | M15: 8851981817 | N15: 8851981817 | O15: 8851981817 | P15: 8851981817 | Q15: 10274952287 | R15: 1.0791116e+10
A16: Allowance For Loan Loss | B16: 22986298 | C16: 100605366 | D16: 177533223 | E16: 165504343 | F16: 165504343 | G16: 165504343 | H16: 165504343 | I16: 165504343 | J16: 165504343 | K16: 165504343 | L16: 165504343 | M16: 165504343 | N16: 165504343 | O16: 165504343 | P16: 165504343 | Q16: 240746432 | R16: 3.3771336e+08
A17: Accounts Recievables | B17: =(B18+B19+B20) -> 0 | C17: =(C18+C19+C20) -> 0 | D17: =(D18+D19+D20) -> 0 | E17: =(E18+E19+E20) -> 0 | F17: =(F18+F19+F20) -> 0 | G17: =(G18+G19+G20) -> 0 | H17: =(H18+H19+H20) -> 0 | I17: =(I18+I19+I20) -> 0 | ... S17: =(S18+S19+S20) -> 0
A18: Tax Recoverable | E18: 0 | F18: 0 | G18: 0 | H18: 0 | I18: 0 | J18: 0 | K18: 0 | L18: 0 | M18: 0 | N18: 0 | O18: 0 | P18: 0 | Q18: 0 | R18: 62421034
A19: Deffered Tax Assets | E19: 0 | F19: 0 | G19: 0 | H19: 0 | I19: 0 | J19: 0 | K19: 0 | L19: 0 | M19: 0 | N19: 0 | O19: 0 | P19: 0 | Q19: 0 | R19: 0
A20: Retirement Benefit Assets | E20: 0 | F20: 0 | G20: 0 | H20: 0 | I20: 0 | J20: 0 | K20: 0 | L20: 0 | M20: 0 | N20: 0 | O20: 0 | P20: 0 | Q20: 0 | R20: 0
A21: Property&Equipments&Other Assets | B21: =(B22+B23+B24+B25+B26) -> 12402140 | C21: =(C22+C23+C24+C25+C26) -> 26273280 | D21: =(D22+D23+D24+D25+D26) -> 51134051 | E21: =(E22+E23+E24+E25+E26) -> 68749288 | F21: =(F22+F23+F24+F25+F26) -> 68749288 | G21: =(G22+G23+G24+G25+G26) -> 68749288 | H21: =(H22+H23+H24+H25+H26) -> 68749288 | I21: =(I22+I23+I24+I25+I26) -> 68749288 | ... S21: =(S22+S23+S24+S25+S26) -> 0
A22: Investment Properties | C22: 1000000 | D22: 1000000 | R22: 3.7571879e+08
A23: Property and Equipment | B23: 10067211 | C23: 9366513 | D23: 8550088 | Q23: =27609942+350796340 -> 378406282 | R23: 27401522
A24: Prepaid Lease Rentals | E24: 58874493 | F24: 58874493 | G24: 58874493 | H24: 58874493 | I24: 58874493 | J24: 58874493 | K24: 58874493 | L24: 58874493 | M24: 58874493 | N24: 58874493 | O24: 58874493 | P24: 58874493 | Q24: 41708474 | R24: 30389122
A25: Intangible Assets | B25: 2334929 | C25: 1111966 | D25: 112832 | E25: 58645 | F25: 58645 | G25: 58645 | H25: 58645 | I25: 58645 | J25: 58645 | K25: 58645 | L25: 58645 | M25: 58645 | N25: 58645 | O25: 58645 | P25: 58645 | Q25: 52542674 | R25: 45740734
A26: Other Assets | C26: 14794801 | D26: 41471131 | E26: =9816150 -> 9816150 | F26: =9816150 -> 9816150 | G26: =9816150 -> 9816150 | H26: =9816150 -> 9816150 | I26: =9816150 -> 9816150 | J26: =9816150 -> 9816150 | K26: =9816150 -> 9816150 | L26: =9816150 -> 9816150 | ... P26: =9816150 -> 9816150 | Q26: 94209223 | R26: 1.0537769e+08
A27: Total Assets | B27: =(B21+B17+B14+B8+B7+B4) -> 12197688843 | C27: =(C21+C17+C14+C8+C7+C4) -> 12867644756 | D27: =(D21+D17+D14+D8+D7+D4) -> 14083966198 | E27: =(E21+E17+E14+E8+E7+E4) -> 15152783404 | F27: =(F21+F17+F14+F8+F7+F4) -> 15152783405 | G27: =(G21+G17+G14+G8+G7+G4) -> 15152783406 | H27: =(H21+H17+H14+H8+H7+H4) -> 15152783407 | I27: =(I21+I17+I14+I8+I7+I4) -> 15152783408 | ... S27: =(S21+S17+S14+S8+S7+S4) -> 0
A28: Savings and Deposits | B28: 669387541 | C28: 8936866630 | D28: 9738071329 | E28: 955717508 | F28: 8.2007483e+08 | G28: 8.4882926e+08 | H28: 1.3853177e+09 | I28: 1.2095437e+09 | J28: 1.0577397e+09 | K28: 1.0438933e+09 | L28: 9.424943e+08 | M28: 9.5528428e+08 | N28: 9.306902e+08 | O28: 8.8139279e+08 | P28: 7.8922387e+08 | Q28: 977454308 | R28: 1.0856122e+09
A29: Short Terrm Deposits | B29: 37030746 | C29: 44689618 | D29: 55179722 | E29: 35020812 | F29: 1.5141911e+08 | G29: 1.5992418e+08 | H29: 1.722585e+08 | I29: 1.7132939e+08 | J29: 1.8513601e+08 | K29: 183549218 | L29: 1.7859957e+08 | M29: 1.8837368e+08 | N29: 1.7746497e+08 | O29: 1.7887935e+08 | P29: 1.6984982e+08 | Q29: 51428193 | R29: 79920311
A30: Non Withdrawable Deposits | B30: 8601823903 | C30: 716184437 | D30: 921136038 | E30: 10447124598 | F30: 1.0493305e+10 | G30: 1.0588787e+10 | H30: 1.0713084e+10 | I30: 1.0781779e+10 | J30: 1.0880497e+10 | K30: 1.0981808e+10 | L30: 1.1082492e+10 | M30: 1.1188046e+10 | N30: 1.1270514e+10 | O30: 1.1330424e+10 | P30: 1.1401787e+10 | Q30: 11531580790 | R30: 1.2243745e+10
A31: Total Deposit Liabilities | B31: =SUM(B28:B30) -> 9308242190 | C31: =SUM(C28:C30) -> 9697740685 | D31: =SUM(D28:D30) -> 10714387089 | E31: =SUM(E28:E30) -> 11437862918 | F31: =SUM(F28:F30) -> 1.1464799e+10 | G31: =SUM(G28:G30) -> 1.159754e+10 | H31: =SUM(H28:H30) -> 1.227066e+10 | I31: =SUM(I28:I30) -> 1.2162652e+10 | ... S31: =SUM(S28:S30) -> 0
A32: Tax Payable | B32: 13412873 | C32: 6790930 | D32: 9238767 | E32: 7010097 | F32: 0 | G32: 0 | H32: 0 | I32: 0 | J32: 0 | K32: 0 | L32: 0 | M32: 0 | N32: 0 | O32: 0 | P32: 0 | Q32: 14633980 | R32: 0
A33: Dividends Payable | B33: 753948943 | C33: 871105917 | D33: 935280520 | E33: 1053233129 | F33: 0 | G33: 0 | H33: 0 | I33: 0 | J33: 0 | K33: 0 | L33: 0 | M33: 0 | N33: 0 | O33: 0 | P33: 0 | Q33: =1147653622 -> 1147653622 | R33: 0
A34: Deferred Tax Liability | F34: 0 | G34: 0 | H34: 0 | I34: 0 | J34: 0 | K34: 0 | L34: 0 | M34: 0 | N34: 0 | O34: 0 | P34: 0 | R34: 0
A35: Retirement Benefits Liabilty | F35: 0 | G35: 0 | H35: 0 | I35: 0 | J35: 0 | K35: 0 | L35: 0 | M35: 0 | N35: 0 | O35: 0 | P35: 0 | R35: 0
A36: Other Liabilities | B36: 108916861 | C36: =118731668+16987099 -> 135718767 | D36: =53319087+43355476 -> 96674563 | E36: =67853413+62347109 -> 130200522 | F36: 1.266397e+09 | G36: 1.3586763e+09 | H36: 4.6049707e+08 | I36: 4.882898e+08 | J36: 5.8394356e+08 | K36: 6.8697451e+08 | L36: 7.814157e+08 | M36: 8.8050761e+08 | N36: 8.7930666e+08 | O36: 1.0720213e+09 | P36: 1.2018901e+09 | Q36: =182014292-9877853+46923520 -> 219059959 | R36: 1.0409233e+09
A37: External Borrowings | F37: 0 | G37: 0 | H37: 0 | I37: 0 | J37: 0 | K37: 0 | L37: 0 | M37: 0 | N37: 0 | O37: 0 | P37: 0 | Q37: 9877853 | R37: 0
A38: Total Liabilities | B38: =SUM(B31:B37) -> 10184520867 | C38: =SUM(C31:C37) -> 10711356299 | D38: =SUM(D31:D37) -> 11755580939 | E38: =SUM(E31:E37) -> 12628306666 | F38: =SUM(F31:F37) -> 1.2731196e+10 | G38: =SUM(G31:G37) -> 1.2956217e+10 | H38: =SUM(H31:H37) -> 1.2731157e+10 | I38: =SUM(I31:I37) -> 1.2650942e+10 | ... S38: =SUM(S31:S37) -> 0
A39: Share Capital | B39: 888741501 | C39: 937694856 | D39: 985832180 | E39: 1023469537 | F39: 1.0255684e+09 | G39: 1.0275182e+09 | H39: 1.0339484e+09 | I39: 1.0450399e+09 | J39: 1.0486187e+09 | K39: 1.0523908e+09 | L39: 1.0565591e+09 | M39: 1.0597216e+09 | N39: 1.063647e+09 | O39: 1.0725266e+09 | P39: 1.0814334e+09 | Q39: 1131426707 | R39: 1.1788112e+09
A40: Capital Grants | C40: 0 | D40: 0 | F40: 0 | G40: 0 | H40: 0 | I40: 0 | J40: 0 | K40: 0 | L40: 0 | M40: 0 | N40: 0 | O40: 0 | P40: 0 | R40: 0
A41: Prior Year Retained Earnigs | B41: 452216551 | C41: =549784126-204601235 -> 345182891 | D41: 549784126 | E41: 701193835 | F41: 7.4092098e+08 | G41: 7.4092098e+08 | H41: 7.2136203e+08 | I41: 7.217895e+08 | J41: 7.217895e+08 | K41: 7.2177702e+08 | L41: 7.2177702e+08 | M41: 7.2177052e+08 | N41: 7.2177052e+08 | O41: 7.2177052e+08 | P41: 7.2177052e+08 | Q41: 743034807 | R41: 7.9575563e+08
A42: Current Year Surplus | B42: 178836162 | C42: 204601235 | D42: =237873427-47574685+77281934+3592442-118299662 -> 152873456 | E42: =282162157-84872599+5547798+2929260-131538561-32387083 -> 41840972 | F42: -22872670 | G42: 34487572 | H42: 58026055 | I42: 73172849 | J42: 79585357 | K42: 1.1393696e+08 | L42: 1.423852e+08 | M42: 1.7567236e+08 | N42: 2.9338063e+08 | O42: 2.6295687e+08 | P42: 2.9300895e+08 | Q42: =268824654-363355-75767647+64056798+431521-147085472-53542-19610412 -> 90432545 | R42: 85419638
...

Sheet Evolutitve SCI
B2: AUDITED 2018 | C2: AUDITED 2019 | D2: Audited 2020 | E2: Audited 2021 | F2: 44562 | G2: 44593 | H2: 44621 | I2: 44652 | J2: 44682 | K2: 44713 | L2: 44743 | M2: 44774 | N2: 44805 | O2: 44835 | P2: 44866 | Q2: 2022 AUDITED | R2: 45139 | S2: 45170
A3: Financial Income | B3: =B4+B7 -> 1382591516 | C3: =C4+C7 -> 1519207861 | D3: =D4+D7 -> 1612162599 | E3: =E4+E7 -> 1732727468 | F3: =F4+F7 -> 62269618 | G3: =G4+G7 -> 1.244535e+08 | H3: =H4+H7 -> 1.8367883e+08 | I3: =I4+I7 -> 2.4756874e+08 | ... S3: =S4+S7 -> 0
A4: Financial Income From Loans Portfolio | B4: =SUM(B5:B6) -> 1100100081 | C4: =SUM(C5:C6) -> 1159274700 | D4: =SUM(D5:D6) -> 1143786806 | E4: =SUM(E5:E6) -> 1185431762 | F4: =SUM(F5:F6) -> 49722341 | G4: =SUM(G5:G6) -> 1.0039039e+08 | H4: =SUM(H5:H6) -> 1.4763011e+08 | I4: =SUM(I5:I6) -> 1.9746138e+08 | ... S4: =SUM(S5:S6) -> 0
A5: Interest from Loans Portfolio | B5: 1091195937 | C5: 1149461775 | D5: 1133667494 | E5: 1172851375 | F5: 46083978 | G5: 93927489 | H5: 1.3763516e+08 | I5: 1.8477391e+08 | J5: 2.2998747e+08 | K5: 2.7791072e+08 | L5: 3.2569583e+08 | M5: 3.7395755e+08 | N5: 4.2176126e+08 | O5: 4.7068465e+08 | P5: 5.2137262e+08 | Q5: 1319035009 | R5: 9.3744458e+08
A6: Fees&Commision on Loan Portfolio | B6: 8904144 | C6: 9812925 | D6: 10119312 | E6: 12580387 | F6: 3638363.1 | G6: 6462900.9 | H6: 9994953.2 | I6: 12687466 | J6: 14997147 | K6: 17599939 | L6: 22629585 | M6: 26291445 | N6: 28761828 | O6: 32619320 | P6: 35510404 | R6: 0
A7: Financial Income from Investments | B7: =SUM(B8:B11) -> 282491435 | C7: =SUM(C8:C11) -> 359933161 | D7: =SUM(D8:D11) -> 468375793 | E7: =SUM(E8:E11) -> 547295706 | F7: =SUM(F8:F11) -> 12547277 | G7: =SUM(G8:G11) -> 24063110 | H7: =SUM(H8:H11) -> 36048721 | I7: =SUM(I8:I11) -> 50107365 | ... S7: =SUM(S8:S11) -> 0
A8: Government Securities | F8: 2244360.2 | G8: 4508530.1 | H8: 6733080.7 | I8: 8977440.1 | J8: 11241610 | K8: 12444304 | L8: 13646997 | M8: 14849691 | N8: 16052385 | O8: 17255077 | P8: 18449597 | R8: 96541213
A9: Deposits with Banks & other Financial Institutions | B9: 261527907 | C9: 338021618 | D9: 420560697 | E9: 493222076 | F9: 1571471.4 | G9: 2255863.1 | H9: 2952545 | I9: 5802776.7 | J9: 7240307.9 | K9: 9902181.9 | L9: 13172312 | M9: 15317305 | N9: 17262845 | O9: 18874194 | P9: 22150245 | Q9: =589388439 -> 589388439 | R9: 3.339139e+08
A10: Other Investments | E10: 980416 | F10: 980416 | G10: 1960832 | H10: 3898930 | I10: 4879346 | J10: 5859762 | K10: 88001316 | L10: 88981732 | M10: 90299279 | N10: 91279695 | O10: 92260111 | P10: 93864805 | R10: 10381.12
A11: Other Operating Income | B11: 20963528 | C11: 21911543 | D11: 47815096 | E11: =43132854+9960360 -> 53093214 | F11: 7751029.6 | G11: 15337885 | H11: 22464165 | I11: 30447802 | J11: 37953489 | K11: 45488048 | L11: 53696975 | M11: 60950967 | N11: 68614834 | O11: 76273241 | P11: 84167146 | Q11: =13064462+117966026 -> 131030488 | R11: 23539895
A12: Financial Expenses | B12: =SUM(B13:B18) -> 843953446 | C12: =SUM(C13:C18) -> 958406856 | D12: =SUM(D13:D18) -> 977959024 | E12: =SUM(E13:E18) -> 1073121422 | F12: =SUM(F13:F18) -> 9483463.2 | G12: =SUM(G13:G18) -> 18638196 | H12: =SUM(H13:H18) -> 29421078 | I12: =SUM(I13:I18) -> 40254496 | ... S12: =SUM(S13:S18) -> 0
A13: Interest Expense on Deposits | B13: 753948946 | C13: 901581980 | D13: 973128864 | E13: 1073121422 | F13: 8094950.3 | G13: 15691200 | H13: 24144198 | I13: 32447058 | J13: 41002069 | K13: 49618865 | L13: 58787501 | M13: 68098226 | N13: 77149835 | O13: 86658820 | P13: 96015043 | Q13: 1169211689 | R13: 9.3726663e+08
A14: Cost of External Borrowings | C14: 0 | D14: 0 | F14: 0 | G14: 0 | H14: 0 | I14: 0 | J14: 0 | K14: 0 | L14: 0 | M14: 0 | N14: 0 | O14: 0 | P14: 0 | R14: 0
A15: Dividend Expenses | F15: 0 | G15: 0 | H15: 0 | I15: 0 | J15: 0 | K15: 0 | L15: 0 | M15: 0 | N15: 0 | O15: 0 | P15: 0 | R15: 0
A16: Other Financial Expense | B16: 13048759 | C16: 56330097 | D16: 4830160 | F16: 0 | G16: 0 | H16: 0 | I16: 0 | J16: 0 | K16: 0 | L16: 0 | M16: 0 | N16: 0 | O16: 0 | P16: 0 | R16: 0
A17: Fees & Commision Expense | F17: 1376472.9 | G17: 2924815.8 | H17: 5243139.8 | I17: 7764907.9 | J17: 10315880 | K17: 15894037 | L17: 18447299 | M17: 20752996 | N17: 23190293 | O17: 25795836 | P17: 28327970 | R17: 0
A18: Other Expenses | B18: 76955741 | C18: 494779 | F18: 12040 | G18: 22180 | H18: 33740 | I18: 42530 | J18: 65130 | K18: 100320 | L18: 154370 | M18: 256020 | N18: 271530 | O18: 287120 | P18: 306240 | R18: 0
A19: Net Financial Income | B19: =B3-B12 -> 538638070 | C19: =C3-C12 -> 560801005 | D19: =D3-D12 -> 634203575 | E19: =E3-E12 -> 659606046 | F19: =F3-F12 -> 52786155 | G19: =G3-G12 -> 1.058153e+08 | H19: =H3-H12 -> 1.5425775e+08 | I19: =I3-I12 -> 2.0731424e+08 | ... S19: =S3-S12 -> 0
A20: Allowance for Loan Loss | B20: =B21-B22 -> 10794159 | C20: =C21-C22 -> 77619068 | D20: =D21-D22 -> 82224569 | E20: =E21-E22 -> -12028880 | F20: =F21-F22 -> 5922516.7 | G20: =G21-G22 -> 12573579 | H20: =H21-H22 -> 12633947 | I20: =I21-I22 -> 16809754 | ... S20: =S21-S22 -> 0
A21: Provision for Loan Losses | B21: 10794159 | C21: 77619068 | D21: =76927858+5296711 -> 82224569 | F21: 5922516.7 | G21: 12573579 | H21: 12633947 | I21: 16809754 | J21: 23086594 | K21: 20258445 | L21: 29026560 | M21: 37649612 | N21: 38729577 | O21: 42090850 | P21: 24115849 | Q21: 75242089 | R21: 92292444
A22: Value of Loans Recovered | E22: 12028880 | F22: 0 | G22: 0 | H22: 0 | I22: 0 | J22: 0 | K22: 0 | L22: 0 | M22: 0 | N22: 0 | O22: 0 | P22: 0 | R22: 0
A23: Operating Expeses | B23: =SUM(B24:B28) -> 256052185 | C23: =SUM(C24:C28) -> 225515632 | D23: =SUM(D24:D28) -> 246706882 | E23: =SUM(E24:E28) -> 283394414 | F23: =SUM(F24:F28) -> 35026107 | G23: =SUM(G24:G28) -> 69256070 | H23: =SUM(H24:H28) -> 1.0399113e+08 | I23: =SUM(I24:I28) -> 1.4061036e+08 | ... S23: =SUM(S24:S28) -> 0
A24: Personel Expenses | B24: 116310633 | C24: 141612202 | D24: 131142601 | E24: 139929140 | F24: 19252023 | G24: 40059700 | H24: 60733589 | I24: 80581384 | J24: 1.0055183e+08 | K24: 1.210746e+08 | L24: 1.4162625e+08 | M24: 1.6169789e+08 | N24: 1.8731175e+08 | O24: 2.1010649e+08 | P24: 2.3224238e+08 | Q24: 180726290 | R24: 1.2925581e+08
A25: Governance Expenses | B25: =27447551+8911264 -> 36358815 | C25: 52063562 | D25: 28484915 | E25: 54936479 | F25: 2879549 | G25: 5297205.8 | H25: 9879450.8 | I25: 13273930 | J25: 15472657 | K25: 20133789 | L25: 23422475 | M25: 26308013 | N25: 31672495 | O25: 34381656 | P25: 38231086 | Q25: 77402061 | R25: 49487709
A26: Marketing Expenses | B26: 4949334 | C26: 5857222 | D26: 1004033 | E26: =209280+997132 -> 1206412 | F26: 1196345 | G26: 1485437 | H26: 1694127 | I26: 1803415 | J26: 2297725 | K26: 2700414.2 | L26: 2830302.2 | M26: 2864202.2 | N26: 3145138.2 | O26: 3783126.8 | P26: 4878726.8 | R26: 4997081.3
A27: Depreciation and Amortization | B27: =6686832+1385960 -> 8072792 | D27: =10460179+3228985 -> 13689164 | E27: =2512705+11601121+54187 -> 14168013 | F27: 1115954.6 | G27: 2239030.3 | H27: 3409783 | I27: 4560826.2 | J27: 5929143.6 | K27: 7106195.2 | L27: 8283246.7 | M27: 9460298.3 | N27: 10654794 | O27: 11953029 | P27: 13114603 | Q27: =3532739+17166019 -> 20698758 | R27: 24110446
A28: Administrative Expenses | B28: =23652930+14163845+901520+19361211+841673+1425058+10000000+294500+4339934+1697975+3906699+9775266 -> 90360611 | C28: =31839868-5857222 -> 25982646 | D28: =24317261-1004033+62762105-13689164 -> 72386169 | E28: =31546034+56982761-E27-E26 -> 73154370 | F28: 10582236 | G28: 20174696 | H28: 28274184 | I28: 40390807 | J28: 50695917 | K28: 60921243 | L28: 70953848 | M28: 81652814 | N28: 92809266 | O28: 1.0345355e+08 | P28: 1.1418307e+08 | Q28: =-25873262+119382944+3506637+9998561+2833407+179407+858834+32172064+1294251+10050000 -> 154402843 | R28: 68620212
A29: Net Operating Income | B29: =B19-B20-B23 -> 271791726 | C29: =C19-C20-C23 -> 257666305 | D29: =D19-D20-D23 -> 305272124 | E29: =E19-E20-E23 -> 388240512 | F29: =F19-F20-F23 -> 11837531 | G29: =G19-G20-G23 -> 23985655 | H29: =H19-H20-H23 -> 37632675 | I29: =I19-I20-I23 -> 49894128 | ... S29: =S19-S20-S23 -> 0
A30: Net Non operating Income/Expense | B30: =B31-B32 -> 0 | C30: =C31-C32 -> 0 | D30: =D31-D32 -> 0 | E30: =E31-E32 -> 0 | F30: =F31-F32 -> 3278853 | G30: =G31-G32 -> 5933775.8 | H30: =H31-H32 -> 10156526 | I30: =I31-I32 -> 13749493 | ... S30: =S31-S32 -> 0
A31: Non Operating Income | E31: 0 | F31: 3928411.1 | G31: 6880814.7 | H31: 11458404 | I31: 15330563 | J31: 18552042 | K31: 21497967 | L31: 24474094 | M31: 29111588 | N31: 32666453 | O31: 36467262 | P31: 41334289 | R31: 0
A32: Non Operating Expense | E32: 0 | F32: 649558.11 | G32: 947038.88 | H32: 1301877.3 | I32: 1581069.4 | J32: 1961202.6 | K32: 2320369.6 | L32: 2640905.8 | M32: 3299507.4 | N32: 3784598.5 | O32: 4228240.7 | P32: 4818515.8 | R32: 0
A33: Net Income(Before Tax & Donations) | B33: =B29+B30 -> 271791726 | C33: =C29+C30 -> 257666305 | D33: =D29+D30 -> 305272124 | E33: =E29+E30 -> 388240512 | F33: =F29+F30 -> 15116384 | G33: =G29+G30 -> 29919430 | H33: =H29+H30 -> 47789201 | I33: =I29+I30 -> 63643622 | ... S33: =S29+S30 -> 0
A34: Taxes | C34: 54054628 | D34: 67398695 | F34: 0 | G34: 0 | H34: 0 | I34: 0 | J34: 0 | K34: 0 | L34: 0 | M34: 0 | N34: 0 | O34: 0 | P34: 0 | Q34: 92945552 | R34: 0
A35: Net Income(After Tax Before Donations) | B35: =B33-B34 -> 271791726 | C35: =C33-C34 -> 203611677 | D35: =D33-D34 -> 237873429 | E35: =E33-E34 -> 388240512 | F35: =F33-F34 -> 15116384 | G35: =G33-G34 -> 29919430 | H35: =H33-H34 -> 47789201 | I35: =I33-I34 -> 63643622 | ... S35: =S33-S34 -> 0
A36: Donations | E36: 83908629 | F36: 0 | G36: 0 | H36: 0 | I36: 0 | J36: 0 | K36: 0 | L36: 0 | M36: 0 | N36: 0 | O36: 0 | P36: 0 | R36: 0
A37: Net Income/(After Tax & Donations) | B37: =B35-B36 -> 271791726 | C37: =C35-C36 -> 203611677 | D37: =D35-D36 -> 237873429 | E37: =E35-E36 -> 304331883 | F37: =F35-F36 -> 15116384 | G37: =G35-G36 -> 29919430 | H37: =H35-H36 -> 47789201 | I37: =I35-I36 -> 63643622 | ... S37: =S35-S36 -> 0
A39: Total Expenses | B39: =B12+B23 -> 1100005631 | C39: =C12+C23 -> 1183922488 | D39: =D12+D23 -> 1224665906 | E39: =E12+E23 -> 1356515836 | F39: =F12+F23 -> 44509571 | G39: =G12+G23 -> 87894266 | H39: =H12+H23 -> 1.3341221e+08 | I39: =I12+I23 -> 1.8086486e+08 | ... S39: =S12+S23 -> 0

Sheet CAELS
A1: STIMA SACCO 2017 CAELS
D2: 2013 Audited | E2: 2014 Audited | F2: 2015 Audited | G2: 2016 Audited | H2: 42736 | I2: 42767 | J2: 42795 | K2: 42826 | L2: 42856 | M2: 42887 | N2: 42917 | O2: 42948 | P2: 42979 | Q2: 43009 | R2: 43040 | S2: 43070 | T2: Audited 2017 | U2: 43101 | V2: 43132 | W2: 43160 | X2: 43191 | Y2: 43221 | Z2: 43252 | AA2: 43282 | AB2: 43313 | AC2: 43344 | AD2: 43374 | AE2: 43405 | AF2: 43435 | AG2: Audited 2018 | AH2: 43466 | AI2: 43497 | AJ2: 43525 | AK2: 43556 | AL2: 43586 | AM2: 43617 | AN2: 43647 | AO2: 43678 | AP2: 43709 | AQ2: 43739 | AR2: 43770 | AS2: 43800 | AT2: Audited 2019 | AU2: 43831 | AV2: 43862 | AW2: 43891 | AX2: 43922 | AY2: 43952 | AZ2: 43983 | BA2: 44013 | BB2: 44044 | BC2: 44075
A3: CAPITAL ADEQUACY | B3: Core Capital | C3: 10 M | D3: =(('Evolutive SFP'!#REF!+'Evolutive SFP'!#REF!+'Evolutive SFP'!#REF!+'Evolutive SFP'!#REF!+'Evolutive SFP'!#REF!+'Evolutive SFP'!#REF!)-'Evolutive SFP'!#REF!)/1000000 -> #REF! | E3: =(('Evolutive SFP'!#REF!+'Evolutive SFP'!#REF!+'Evolutive SFP'!#REF!+'Evolutive SFP'!#REF!+'Evolutive SFP'!#REF!+'Evolutive SFP'!#REF!)-'Evolutive SFP'!#REF!)/1000000 -> #REF! | F3: =(('Evolutive SFP'!#REF!+'Evolutive SFP'!#REF!+'Evolutive SFP'!#REF!+'Evolutive SFP'!#REF!+'Evolutive SFP'!#REF!+'Evolutive SFP'!#REF!)-'Evolutive SFP'!#REF!)/1000000 -> #REF! | G3: =(('Evolutive SFP'!#REF!+'Evolutive SFP'!#REF!+'Evolutive SFP'!#REF!+'Evolutive SFP'!#REF!+'Evolutive SFP'!#REF!+'Evolutive SFP'!#REF!)-'Evolutive SFP'!#REF!)/1000000 -> #REF! | H3: =(('Evolutive SFP'!#REF!+'Evolutive SFP'!#REF!+'Evolutive SFP'!#REF!+'Evolutive SFP'!#REF!+'Evolutive SFP'!#REF!+'Evolutive SFP'!#REF!)-'Evolutive SFP'!#REF!)/1000000 -> #REF! | I3: =(('Evolutive SFP'!#REF!+'Evolutive SFP'!#REF!+'Evolutive SFP'!#REF!+'Evolutive SFP'!#REF!+'Evolutive SFP'!#REF!+'Evolutive SFP'!#REF!)-'Evolutive SFP'!#REF!)/1000000 -> #REF! | J3: =(('Evolutive SFP'!#REF!+'Evolutive SFP'!#REF!+'Evolutive SFP'!#REF!+'Evolutive SFP'!#REF!+'Evolutive SFP'!#REF!+'Evolutive SFP'!#REF!)-'Evolutive SFP'!#REF!)/1000000 -> #REF! | K3: =(('Evolutive SFP'!#REF!+'Evolutive SFP'!#REF!+'Evolutive SFP'!#REF!+'Evolutive SFP'!#REF!+'Evolutive SFP'!#REF!+'Evolutive SFP'!#REF!)-'Evolutive SFP'!#REF!)/1000000 -> #REF! | ... AS3: =(('Evolutive SFP'!#REF!+'Evolutive SFP'!#REF!+'Evolutive SFP'!#REF!+'Evolutive SFP'!#REF!+'Evolutive SFP'!#REF!+'Evolutive SFP'!#REF!)-'Evolutive SFP'!#REF!)/1000000 -> #REF! | AT3: =(('Evolutive SFP'!C39+'Evolutive SFP'!C40+'Evolutive SFP'!C41+'Evolutive SFP'!C42+'Evolutive SFP'!C43+'Evolutive SFP'!C44)-'Evolutive SFP'!C10)/1000000 -> 2037.4694 | AU3: =(('Evolutive SFP'!#REF!+'Evolutive SFP'!#REF!+'Evolutive SFP'!#REF!+'Evolutive SFP'!#REF!+'Evolutive SFP'!#REF!+'Evolutive SFP'!#REF!)-'Evolutive SFP'!#REF!)/1000000 -> #REF! | AV3: =(('Evolutive SFP'!#REF!+'Evolutive SFP'!#REF!+'Evolutive SFP'!#REF!+'Evolutive SFP'!#REF!+'Evolutive SFP'!#REF!+'Evolutive SFP'!#REF!)-'Evolutive SFP'!#REF!)/1000000 -> #REF! | AW3: =(('Evolutive SFP'!#REF!+'Evolutive SFP'!#REF!+'Evolutive SFP'!#REF!+'Evolutive SFP'!#REF!+'Evolutive SFP'!#REF!+'Evolutive SFP'!#REF!)-'Evolutive SFP'!#REF!)/1000000 -> #REF! | AX3: =(('Evolutive SFP'!#REF!+'Evolutive SFP'!#REF!+'Evolutive SFP'!#REF!+'Evolutive SFP'!#REF!+'Evolutive SFP'!#REF!+'Evolutive SFP'!#REF!)-'Evolutive SFP'!#REF!)/1000000 -> #REF! | AY3: =(('Evolutive SFP'!#REF!+'Evolutive SFP'!#REF!+'Evolutive SFP'!#REF!+'Evolutive SFP'!#REF!+'Evolutive SFP'!#REF!+'Evolutive SFP'!#REF!)-'Evolutive SFP'!#REF!)/1000000 -> #REF! | AZ3: =(('Evolutive SFP'!#REF!+'Evolutive SFP'!#REF!+'Evolutive SFP'!#REF!+'Evolutive SFP'!#REF!+'Evolutive SFP'!#REF!+'Evolutive SFP'!#REF!)-'Evolutive SFP'!#REF!)/1000000 -> #REF! | BA3: =(('Evolutive SFP'!#REF!+'Evolutive SFP'!#REF!+'Evolutive SFP'!#REF!+'Evolutive SFP'!#REF!+'Evolutive SFP'!#REF!+'Evolutive SFP'!#REF!)-'Evolutive SFP'!#REF!)/1000000 -> #REF! | BB3: =(('Evolutive SFP'!#REF!+'Evolutive SFP'!#REF!+'Evolutive SFP'!#REF!+'Evolutive SFP'!#REF!+'Evolutive SFP'!#REF!+'Evolutive SFP'!#REF!)-'Evolutive SFP'!#REF!)/1000000 -> #REF! | BC3: =(('Evolutive SFP'!#REF!+'Evolutive SFP'!#REF!+'Evolutive SFP'!#REF!+'Evolutive SFP'!#REF!+'Evolutive SFP'!#REF!+'Evolutive SFP'!#REF!)-'Evolutive SFP'!#REF!)/1000000 -> #REF!
B4: CCA | C4: Min 10% | D4: =D3/(('Evolutive SFP'!#REF!)/1000000) -> #REF! | E4: =E3/(('Evolutive SFP'!#REF!)/1000000) -> #REF! | F4: =F3/(('Evolutive SFP'!#REF!)/1000000) -> #REF! | G4: =G3/(('Evolutive SFP'!#REF!)/1000000) -> #REF! | H4: =H3/(('Evolutive SFP'!#REF!)/1000000) -> #REF! | I4: =I3/(('Evolutive SFP'!#REF!)/1000000) -> #REF! | J4: =J3/(('Evolutive SFP'!#REF!)/1000000) -> #REF! | K4: =K3/(('Evolutive SFP'!#REF!)/1000000) -> #REF! | ... AS4: =AS3/(('Evolutive SFP'!#REF!)/1000000) -> #REF! | AT4: =AT3/(('Evolutive SFP'!C27)/1000000) -> 0.15834051 | AU4: =AU3/(('Evolutive SFP'!#REF!)/1000000) -> #REF! | AV4: =AV3/(('Evolutive SFP'!#REF!)/1000000) -> #REF! | AW4: =AW3/(('Evolutive SFP'!#REF!)/1000000) -> #REF! | AX4: =AX3/(('Evolutive SFP'!#REF!)/1000000) -> #REF! | AY4: =AY3/(('Evolutive SFP'!#REF!)/1000000) -> #REF! | AZ4: =AZ3/(('Evolutive SFP'!#REF!)/1000000) -> #REF! | BA4: =BA3/(('Evolutive SFP'!#REF!)/1000000) -> #REF! | BB4: =BB3/(('Evolutive SFP'!#REF!)/1000000) -> #REF! | BC4: =BC3/(('Evolutive SFP'!#REF!)/1000000) -> #REF!
B5: CCD | C5: Min 8% | D5: =D3/('Evolutive SFP'!#REF!/1000000) -> #REF! | E5: =E3/('Evolutive SFP'!#REF!/1000000) -> #REF! | F5: =F3/('Evolutive SFP'!#REF!/1000000) -> #REF! | G5: =G3/('Evolutive SFP'!#REF!/1000000) -> #REF! | H5: =H3/('Evolutive SFP'!#REF!/1000000) -> #REF! | I5: =I3/('Evolutive SFP'!#REF!/1000000) -> #REF! | J5: =J3/('Evolutive SFP'!#REF!/1000000) -> #REF! | K5: =K3/('Evolutive SFP'!#REF!/1000000) -> #REF! | ... AS5: =AS3/('Evolutive SFP'!#REF!/1000000) -> #REF! | AT5: =AT3/('Evolutive SFP'!C31/1000000) -> 0.21009733 | AU5: =AU3/('Evolutive SFP'!#REF!/1000000) -> #REF! | AV5: =AV3/('Evolutive SFP'!#REF!/1000000) -> #REF! | AW5: =AW3/('Evolutive SFP'!#REF!/1000000) -> #REF! | AX5: =AX3/('Evolutive SFP'!#REF!/1000000) -> #REF! | AY5: =AY3/('Evolutive SFP'!#REF!/1000000) -> #REF! | AZ5: =AZ3/('Evolutive SFP'!#REF!/1000000) -> #REF! | BA5: =BA3/('Evolutive SFP'!#REF!/1000000) -> #REF! | BB5: =BB3/('Evolutive SFP'!#REF!/1000000) -> #REF! | BC5: =BC3/('Evolutive SFP'!#REF!/1000000) -> #REF!
B6: ICA | C6: Min 8% | D6: =((D3*1000000)-'Evolutive SFP'!#REF!)/'Evolutive SFP'!#REF! -> #REF! | E6: =((E3*1000000)-'Evolutive SFP'!#REF!)/'Evolutive SFP'!#REF! -> #REF! | F6: =((F3*1000000)-'Evolutive SFP'!#REF!)/'Evolutive SFP'!#REF! -> #REF! | G6: =((G3*1000000)-'Evolutive SFP'!#REF!)/'Evolutive SFP'!#REF! -> #REF! | H6: =((H3*1000000)-'Evolutive SFP'!#REF!)/'Evolutive SFP'!#REF! -> #REF! | I6: =((I3*1000000)-'Evolutive SFP'!#REF!)/'Evolutive SFP'!#REF! -> #REF! | J6: =((J3*1000000)-'Evolutive SFP'!#REF!)/'Evolutive SFP'!#REF! -> #REF! | K6: =((K3*1000000)-'Evolutive SFP'!#REF!)/'Evolutive SFP'!#REF! -> #REF! | ... AS6: =((AS3*1000000)-'Evolutive SFP'!#REF!)/'Evolutive SFP'!#REF! -> #REF! | AT6: =((AT3*1000000)-'Evolutive SFP'!C39)/'Evolutive SFP'!C27 -> 0.085468207 | AU6: =((AU3*1000000)-'Evolutive SFP'!#REF!)/'Evolutive SFP'!#REF! -> #REF! | AV6: =((AV3*1000000)-'Evolutive SFP'!#REF!)/'Evolutive SFP'!#REF! -> #REF! | AW6: =((AW3*1000000)-'Evolutive SFP'!#REF!)/'Evolutive SFP'!#REF! -> #REF! | AX6: =((AX3*1000000)-'Evolutive SFP'!#REF!)/'Evolutive SFP'!#REF! -> #REF! | AY6: =((AY3*1000000)-'Evolutive SFP'!#REF!)/'Evolutive SFP'!#REF! -> #REF! | AZ6: =((AZ3*1000000)-'Evolutive SFP'!#REF!)/'Evolutive SFP'!#REF! -> #REF! | BA6: =((BA3*1000000)-'Evolutive SFP'!#REF!)/'Evolutive SFP'!#REF! -> #REF! | BB6: =((BB3*1000000)-'Evolutive SFP'!#REF!)/'Evolutive SFP'!#REF! -> #REF! | BC6: =((BC3*1000000)-'Evolutive SFP'!#REF!)/'Evolutive SFP'!#REF! -> #REF!
A7: ASSET QUALITY | B7: A/LNPL30 | F7: 0.36 | G7: 0.52149977 | J7: ='Evolutive SFP'!#REF!/(#REF!+#REF!+#REF!) -> #REF! | M7: ='Evolutive SFP'!#REF!/(#REF!+#REF!+#REF!) -> #REF! | P7: ='Evolutive SFP'!#REF!/(#REF!+#REF!+#REF!) -> #REF! | S7: ='Evolutive SFP'!#REF!/(#REF!+#REF!+#REF!) -> #REF! | T7: ='Evolutive SFP'!#REF!/(#REF!+#REF!+#REF!) -> #REF! | U7: ='Evolutive SFP'!#REF!/(#REF!+#REF!+#REF!) -> #REF! | V7: ='Evolutive SFP'!#REF!/(#REF!+#REF!+#REF!) -> #REF! | W7: ='Evolutive SFP'!#REF!/(#REF!+#REF!+#REF!) -> #REF! | X7: ='Evolutive SFP'!#REF!/(#REF!+#REF!+#REF!) -> #REF! | Y7: ='Evolutive SFP'!#REF!/(#REF!+#REF!+#REF!) -> #REF! | Z7: ='Evolutive SFP'!#REF!/(#REF!+#REF!+#REF!) -> #REF! | ... AP7: ='Evolutive SFP'!#REF!/(#REF!+#REF!+#REF!) -> #REF!
B8: NPL30 | F8: 0.02 | G8: 0.051294614 | J8: =(#REF!+#REF!+#REF!)/'Evolutive SFP'!#REF! -> #REF! | M8: =(#REF!+#REF!+#REF!)/'Evolutive SFP'!#REF! -> #REF! | P8: =(#REF!+#REF!+#REF!)/'Evolutive SFP'!#REF! -> #REF! | S8: =(#REF!+#REF!+#REF!)/'Evolutive SFP'!#REF! -> #REF! | T8: =(#REF!+#REF!+#REF!)/'Evolutive SFP'!#REF! -> #REF! | U8: =(#REF!+#REF!+#REF!)/'Evolutive SFP'!#REF! -> #REF! | V8: =(#REF!+#REF!+#REF!)/'Evolutive SFP'!#REF! -> #REF! | W8: =(#REF!+#REF!+#REF!)/'Evolutive SFP'!#REF! -> #REF! | X8: =(#REF!+#REF!+#REF!)/'Evolutive SFP'!#REF! -> #REF! | Y8: =(#REF!+#REF!+#REF!)/'Evolutive SFP'!#REF! -> #REF! | Z8: =(#REF!+#REF!+#REF!)/'Evolutive SFP'!#REF! -> #REF! | ... AS8: =(#REF!+#REF!+#REF!)/'Evolutive SFP'!#REF! -> #REF! | AT8: =(#REF!+#REF!+#REF!)/'Evolutive SFP'!C15 -> #REF! | AU8: =(#REF!+#REF!+#REF!)/'Evolutive SFP'!#REF! -> #REF! | AV8: =(#REF!+#REF!+#REF!)/'Evolutive SFP'!#REF! -> #REF! | AW8: =(#REF!+#REF!+#REF!)/'Evolutive SFP'!#REF! -> #REF! | AX8: =(#REF!+#REF!+#REF!)/'Evolutive SFP'!#REF! -> #REF! | AY8: =(#REF!+#REF!+#REF!)/'Evolutive SFP'!#REF! -> #REF! | AZ8: =(#REF!+#REF!+#REF!)/'Evolutive SFP'!#REF! -> #REF! | BA8: =(#REF!+#REF!+#REF!)/'Evolutive SFP'!#REF! -> #REF! | BB8: =(#REF!+#REF!+#REF!)/'Evolutive SFP'!#REF! -> #REF! | BC8: =(#REF!+#REF!+#REF!)/'Evolutive SFP'!#REF! -> #REF!
A9: EARNINGS | B9: ROA | E9: ='Evolutitve SCI'!#REF!/(('Evolutive SFP'!#REF!+'Evolutive SFP'!#REF!)/2) -> #REF! | H9: ='Evolutitve SCI'!#REF!/(('Evolutive SFP'!#REF!+'Evolutive SFP'!#REF!)/2) -> #REF! | I9: ='Evolutitve SCI'!#REF!/(('Evolutive SFP'!#REF!+'Evolutive SFP'!#REF!)/2) -> #REF! | J9: ='Evolutitve SCI'!#REF!/(('Evolutive SFP'!#REF!+'Evolutive SFP'!#REF!)/2) -> #REF! | K9: ='Evolutitve SCI'!#REF!/(('Evolutive SFP'!#REF!+'Evolutive SFP'!#REF!)/2) -> #REF! | L9: ='Evolutitve SCI'!#REF!/(('Evolutive SFP'!#REF!+'Evolutive SFP'!#REF!)/2) -> #REF! | M9: ='Evolutitve SCI'!#REF!/(('Evolutive SFP'!#REF!+'Evolutive SFP'!#REF!)/2) -> #REF! | N9: ='Evolutitve SCI'!#REF!/(('Evolutive SFP'!#REF!+'Evolutive SFP'!#REF!)/2) -> #REF! | O9: ='Evolutitve SCI'!#REF!/(('Evolutive SFP'!#REF!+'Evolutive SFP'!#REF!)/2) -> #REF! | ... AS9: ='Evolutitve SCI'!#REF!/(('Evolutive SFP'!#REF!+'Evolutive SFP'!#REF!)/2) -> #REF! | AT9: ='Evolutitve SCI'!#REF!/(('Evolutive SFP'!#REF!+'Evolutive SFP'!C27)/2) -> #REF! | AU9: ='Evolutitve SCI'!#REF!/(('Evolutive SFP'!C27+'Evolutive SFP'!#REF!)/2) -> #REF! | AV9: ='Evolutitve SCI'!#REF!/(('Evolutive SFP'!#REF!+'Evolutive SFP'!#REF!)/2) -> #REF! | AW9: ='Evolutitve SCI'!#REF!/(('Evolutive SFP'!#REF!+'Evolutive SFP'!#REF!)/2) -> #REF! | AX9: ='Evolutitve SCI'!#REF!/(('Evolutive SFP'!#REF!+'Evolutive SFP'!#REF!)/2) -> #REF! | AY9: ='Evolutitve SCI'!#REF!/(('Evolutive SFP'!#REF!+'Evolutive SFP'!#REF!)/2) -> #REF! | AZ9: ='Evolutitve SCI'!#REF!/(('Evolutive SFP'!#REF!+'Evolutive SFP'!#REF!)/2) -> #REF! | BA9: ='Evolutitve SCI'!#REF!/(('Evolutive SFP'!#REF!+'Evolutive SFP'!#REF!)/2) -> #REF! | BB9: ='Evolutitve SCI'!#REF!/(('Evolutive SFP'!#REF!+'Evolutive SFP'!#REF!)/2) -> #REF! | BC9: ='Evolutitve SCI'!#REF!/(('Evolutive SFP'!#REF!+'Evolutive SFP'!#REF!)/2) -> #REF!
B10: Cost Income ratio | D10: ='Evolutitve SCI'!#REF!/'Evolutitve SCI'!#REF! -> #REF! | E10: ='Evolutitve SCI'!#REF!/'Evolutitve SCI'!#REF! -> #REF! | F10: ='Evolutitve SCI'!#REF!/'Evolutitve SCI'!#REF! -> #REF! | G10: ='Evolutitve SCI'!#REF!/'Evolutitve SCI'!#REF! -> #REF! | H10: ='Evolutitve SCI'!#REF!/'Evolutitve SCI'!#REF! -> #REF! | I10: ='Evolutitve SCI'!#REF!/'Evolutitve SCI'!#REF! -> #REF! | J10: ='Evolutitve SCI'!#REF!/'Evolutitve SCI'!#REF! -> #REF! | K10: ='Evolutitve SCI'!#REF!/'Evolutitve SCI'!#REF! -> #REF! | ... BC10: ='Evolutitve SCI'!#REF!/'Evolutitve SCI'!#REF! -> #REF!
B11: Operating Expense ratio | D11: =('Evolutitve SCI'!#REF!+'Evolutitve SCI'!#REF!)/(('Evolutive SFP'!#REF!+'Evolutive SFP'!#REF!)/2) -> #REF! | E11: =('Evolutitve SCI'!#REF!+'Evolutitve SCI'!#REF!)/(('Evolutive SFP'!#REF!+'Evolutive SFP'!#REF!)/2) -> #REF! | F11: =('Evolutitve SCI'!#REF!+'Evolutitve SCI'!#REF!)/(('Evolutive SFP'!#REF!+'Evolutive SFP'!#REF!)/2) -> #REF! | G11: =('Evolutitve SCI'!#REF!+'Evolutitve SCI'!#REF!)/(('Evolutive SFP'!#REF!+'Evolutive SFP'!#REF!)/2) -> #REF! | H11: =('Evolutitve SCI'!#REF!+'Evolutitve SCI'!#REF!)/(('Evolutive SFP'!#REF!+'Evolutive SFP'!#REF!)/2) -> #REF! | I11: =('Evolutitve SCI'!#REF!+'Evolutitve SCI'!#REF!)/(('Evolutive SFP'!#REF!+'Evolutive SFP'!#REF!)/2) -> #REF! | J11: =('Evolutitve SCI'!#REF!+'Evolutitve SCI'!#REF!)/(('Evolutive SFP'!#REF!+'Evolutive SFP'!#REF!)/2) -> #REF! | K11: =('Evolutitve SCI'!#REF!+'Evolutitve SCI'!#REF!)/(('Evolutive SFP'!#REF!+'Evolutive SFP'!#REF!)/2) -> #REF! | ... AQ11: =('Evolutitve SCI'!#REF!+'Evolutitve SCI'!#REF!)/(('Evolutive SFP'!#REF!+'Evolutive SFP'!#REF!)/2) -> #REF! | AR11: =('Evolutitve SCI'!#REF!+'Evolutitve SCI'!#REF!)/(('Evolutive SFP'!#REF!+'Evolutive SFP'!C27)/2) -> #REF! | AS11: =('Evolutitve SCI'!#REF!+'Evolutitve SCI'!#REF!)/(('Evolutive SFP'!#REF!+'Evolutive SFP'!#REF!)/2) -> #REF! | AT11: =('Evolutitve SCI'!#REF!+'Evolutitve SCI'!#REF!)/(('Evolutive SFP'!C27+'Evolutive SFP'!#REF!)/2) -> #REF! | AU11: =('Evolutitve SCI'!#REF!+'Evolutitve SCI'!#REF!)/(('Evolutive SFP'!#REF!+'Evolutive SFP'!#REF!)/2) -> #REF! | AV11: =('Evolutitve SCI'!#REF!+'Evolutitve SCI'!#REF!)/(('Evolutive SFP'!#REF!+'Evolutive SFP'!#REF!)/2) -> #REF! | AW11: =('Evolutitve SCI'!#REF!+'Evolutitve SCI'!#REF!)/(('Evolutive SFP'!#REF!+'Evolutive SFP'!#REF!)/2) -> #REF! | AX11: =('Evolutitve SCI'!#REF!+'Evolutitve SCI'!#REF!)/(('Evolutive SFP'!#REF!+'Evolutive SFP'!#REF!)/2) -> #REF! | AY11: =('Evolutitve SCI'!#REF!+'Evolutitve SCI'!#REF!)/(('Evolutive SFP'!#REF!+'Evolutive SFP'!#REF!)/2) -> #REF! | AZ11: =('Evolutitve SCI'!#REF!+'Evolutitve SCI'!#REF!)/(('Evolutive SFP'!#REF!+'Evolutive SFP'!#REF!)/2) -> #REF! | BA11: =('Evolutitve SCI'!#REF!+'Evolutitve SCI'!#REF!)/(('Evolutive SFP'!#REF!+'Evolutive SFP'!#REF!)/2) -> #REF! | BB11: =('Evolutitve SCI'!#REF!+'Evolutitve SCI'!#REF!)/(('Evolutive SFP'!#REF!+'Evolutive SFP'!#REF!)/2) -> #REF! | BC11: =('Evolutitve SCI'!#REF!+'Evolutitve SCI'!#REF!)/(('Evolutive SFP'!#REF!+'Evolutive SFP'!#REF!)/2) -> #REF!
A12: LIQUIDITY | B12: MIN LIQ ratio | C12: Min 15% | D12: =('Evolutive SFP'!#REF!)/('Evolutive SFP'!#REF!+'Evolutive SFP'!#REF!+'Evolutive SFP'!#REF!+'Evolutive SFP'!#REF!+'Evolutive SFP'!#REF!+'Evolutive SFP'!#REF!+'Evolutive SFP'!#REF!) -> #REF! | E12: =('Evolutive SFP'!#REF!)/('Evolutive SFP'!#REF!+'Evolutive SFP'!#REF!+'Evolutive SFP'!#REF!+'Evolutive SFP'!#REF!+'Evolutive SFP'!#REF!+'Evolutive SFP'!#REF!+'Evolutive SFP'!#REF!) -> #REF! | F12: =('Evolutive SFP'!#REF!)/('Evolutive SFP'!#REF!+'Evolutive SFP'!#REF!+'Evolutive SFP'!#REF!+'Evolutive SFP'!#REF!+'Evolutive SFP'!#REF!+'Evolutive SFP'!#REF!+'Evolutive SFP'!#REF!) -> #REF! | G12: =('Evolutive SFP'!#REF!)/('Evolutive SFP'!#REF!+'Evolutive SFP'!#REF!+'Evolutive SFP'!#REF!+'Evolutive SFP'!#REF!+'Evolutive SFP'!#REF!+'Evolutive SFP'!#REF!+'Evolutive SFP'!#REF!) -> #REF! | H12: =('Evolutive SFP'!#REF!)/('Evolutive SFP'!#REF!+'Evolutive SFP'!#REF!+'Evolutive SFP'!#REF!+'Evolutive SFP'!#REF!+'Evolutive SFP'!#REF!+'Evolutive SFP'!#REF!+'Evolutive SFP'!#REF!) -> #REF! | I12: =('Evolutive SFP'!#REF!)/('Evolutive SFP'!#REF!+'Evolutive SFP'!#REF!+'Evolutive SFP'!#REF!+'Evolutive SFP'!#REF!+'Evolutive SFP'!#REF!+'Evolutive SFP'!#REF!+'Evolutive SFP'!#REF!) -> #REF! | J12: =('Evolutive SFP'!#REF!)/('Evolutive SFP'!#REF!+'Evolutive SFP'!#REF!+'Evolutive SFP'!#REF!+'Evolutive SFP'!#REF!+'Evolutive SFP'!#REF!+'Evolutive SFP'!#REF!+'Evolutive SFP'!#REF!) -> #REF! | K12: =('Evolutive SFP'!#REF!)/('Evolutive SFP'!#REF!+'Evolutive SFP'!#REF!+'Evolutive SFP'!#REF!+'Evolutive SFP'!#REF!+'Evolutive SFP'!#REF!+'Evolutive SFP'!#REF!+'Evolutive SFP'!#REF!) -> #REF! | ... AS12: =('Evolutive SFP'!#REF!)/('Evolutive SFP'!#REF!+'Evolutive SFP'!#REF!+'Evolutive SFP'!#REF!+'Evolutive SFP'!#REF!+'Evolutive SFP'!#REF!+'Evolutive SFP'!#REF!+'Evolutive SFP'!#REF!) -> #REF! | AT12: =('Evolutive SFP'!C4)/('Evolutive SFP'!C28+'Evolutive SFP'!C29+'Evolutive SFP'!C32+'Evolutive SFP'!C33+'Evolutive SFP'!C34+'Evolutive SFP'!C35+'Evolutive SFP'!C36) -> 0.39933579 | AU12: =('Evolutive SFP'!#REF!)/('Evolutive SFP'!#REF!+'Evolutive SFP'!#REF!+'Evolutive SFP'!#REF!+'Evolutive SFP'!#REF!+'Evolutive SFP'!#REF!+'Evolutive SFP'!#REF!+'Evolutive SFP'!#REF!) -> #REF! | AV12: =('Evolutive SFP'!#REF!)/('Evolutive SFP'!#REF!+'Evolutive SFP'!#REF!+'Evolutive SFP'!#REF!+'Evolutive SFP'!#REF!+'Evolutive SFP'!#REF!+'Evolutive SFP'!#REF!+'Evolutive SFP'!#REF!) -> #REF! | AW12: =('Evolutive SFP'!#REF!)/('Evolutive SFP'!#REF!+'Evolutive SFP'!#REF!+'Evolutive SFP'!#REF!+'Evolutive SFP'!#REF!+'Evolutive SFP'!#REF!+'Evolutive SFP'!#REF!+'Evolutive SFP'!#REF!) -> #REF! | AX12: =('Evolutive SFP'!#REF!)/('Evolutive SFP'!#REF!+'Evolutive SFP'!#REF!+'Evolutive SFP'!#REF!+'Evolutive SFP'!#REF!+'Evolutive SFP'!#REF!+'Evolutive SFP'!#REF!+'Evolutive SFP'!#REF!) -> #REF! | AY12: =('Evolutive SFP'!#REF!)/('Evolutive SFP'!#REF!+'Evolutive SFP'!#REF!+'Evolutive SFP'!#REF!+'Evolutive SFP'!#REF!+'Evolutive SFP'!#REF!+'Evolutive SFP'!#REF!+'Evolutive SFP'!#REF!) -> #REF! | AZ12: =('Evolutive SFP'!#REF!)/('Evolutive SFP'!#REF!+'Evolutive SFP'!#REF!+'Evolutive SFP'!#REF!+'Evolutive SFP'!#REF!+'Evolutive SFP'!#REF!+'Evolutive SFP'!#REF!+'Evolutive SFP'!#REF!) -> #REF! | BA12: =('Evolutive SFP'!#REF!)/('Evolutive SFP'!#REF!+'Evolutive SFP'!#REF!+'Evolutive SFP'!#REF!+'Evolutive SFP'!#REF!+'Evolutive SFP'!#REF!+'Evolutive SFP'!#REF!+'Evolutive SFP'!#REF!) -> #REF! | BB12: =('Evolutive SFP'!#REF!)/('Evolutive SFP'!#REF!+'Evolutive SFP'!#REF!+'Evolutive SFP'!#REF!+'Evolutive SFP'!#REF!+'Evolutive SFP'!#REF!+'Evolutive SFP'!#REF!+'Evolutive SFP'!#REF!) -> #REF! | BC12: =('Evolutive SFP'!#REF!)/('Evolutive SFP'!#REF!+'Evolutive SFP'!#REF!+'Evolutive SFP'!#REF!+'Evolutive SFP'!#REF!+'Evolutive SFP'!#REF!+'Evolutive SFP'!#REF!+'Evolutive SFP'!#REF!) -> #REF!
B13: T/LIQ ratio | D13: =('Evolutive SFP'!#REF!+'Evolutive SFP'!#REF!)/('Evolutive SFP'!#REF!+'Evolutive SFP'!#REF!+'Evolutive SFP'!#REF!+'Evolutive SFP'!#REF!+'Evolutive SFP'!#REF!+'Evolutive SFP'!#REF!) -> #REF! | E13: =('Evolutive SFP'!#REF!+'Evolutive SFP'!#REF!)/('Evolutive SFP'!#REF!+'Evolutive SFP'!#REF!+'Evolutive SFP'!#REF!+'Evolutive SFP'!#REF!+'Evolutive SFP'!#REF!+'Evolutive SFP'!#REF!) -> #REF! | F13: =('Evolutive SFP'!#REF!+'Evolutive SFP'!#REF!)/('Evolutive SFP'!#REF!+'Evolutive SFP'!#REF!+'Evolutive SFP'!#REF!+'Evolutive SFP'!#REF!+'Evolutive SFP'!#REF!+'Evolutive SFP'!#REF!) -> #REF! | G13: =('Evolutive SFP'!#REF!+'Evolutive SFP'!#REF!)/('Evolutive SFP'!#REF!+'Evolutive SFP'!#REF!+'Evolutive SFP'!#REF!+'Evolutive SFP'!#REF!+'Evolutive SFP'!#REF!+'Evolutive SFP'!#REF!) -> #REF! | H13: =('Evolutive SFP'!#REF!+'Evolutive SFP'!#REF!)/('Evolutive SFP'!#REF!+'Evolutive SFP'!#REF!+'Evolutive SFP'!#REF!+'Evolutive SFP'!#REF!+'Evolutive SFP'!#REF!+'Evolutive SFP'!#REF!) -> #REF! | I13: =('Evolutive SFP'!#REF!+'Evolutive SFP'!#REF!)/('Evolutive SFP'!#REF!+'Evolutive SFP'!#REF!+'Evolutive SFP'!#REF!+'Evolutive SFP'!#REF!+'Evolutive SFP'!#REF!+'Evolutive SFP'!#REF!) -> #REF! | J13: =('Evolutive SFP'!#REF!+'Evolutive SFP'!#REF!)/('Evolutive SFP'!#REF!+'Evolutive SFP'!#REF!+'Evolutive SFP'!#REF!+'Evolutive SFP'!#REF!+'Evolutive SFP'!#REF!+'Evolutive SFP'!#REF!) -> #REF! | K13: =('Evolutive SFP'!#REF!+'Evolutive SFP'!#REF!)/('Evolutive SFP'!#REF!+'Evolutive SFP'!#REF!+'Evolutive SFP'!#REF!+'Evolutive SFP'!#REF!+'Evolutive SFP'!#REF!+'Evolutive SFP'!#REF!) -> #REF! | ... O13: =('Evolutive SFP'!#REF!+'Evolutive SFP'!#REF!)/('Evolutive SFP'!#REF!+'Evolutive SFP'!#REF!+'Evolutive SFP'!#REF!+'Evolutive SFP'!#REF!+'Evolutive SFP'!#REF!+'Evolutive SFP'!#REF!) -> #REF! | P13: ='Evolutive SFP'!#REF!/('Evolutive SFP'!#REF!+'Evolutive SFP'!#REF!) -> #REF! | Q13: ='Evolutive SFP'!#REF!/('Evolutive SFP'!#REF!+'Evolutive SFP'!#REF!) -> #REF! | R13: ='Evolutive SFP'!#REF!/('Evolutive SFP'!#REF!+'Evolutive SFP'!#REF!) -> #REF! | S13: ='Evolutive SFP'!#REF!/('Evolutive SFP'!#REF!+'Evolutive SFP'!#REF!) -> #REF! | T13: ='Evolutive SFP'!#REF!/('Evolutive SFP'!#REF!+'Evolutive SFP'!#REF!) -> #REF! | U13: ='Evolutive SFP'!#REF!/('Evolutive SFP'!#REF!+'Evolutive SFP'!#REF!) -> #REF! | V13: ='Evolutive SFP'!#REF!/('Evolutive SFP'!#REF!+'Evolutive SFP'!#REF!) -> #REF! | W13: ='Evolutive SFP'!#REF!/('Evolutive SFP'!#REF!+'Evolutive SFP'!#REF!) -> #REF! | ... AS13: ='Evolutive SFP'!#REF!/('Evolutive SFP'!#REF!+'Evolutive SFP'!#REF!) -> #REF! | AT13: ='Evolutive SFP'!C4/('Evolutive SFP'!C31+'Evolutive SFP'!C36) -> 0.40590291 | AU13: ='Evolutive SFP'!#REF!/('Evolutive SFP'!#REF!+'Evolutive SFP'!#REF!) -> #REF! | AV13: ='Evolutive SFP'!#REF!/('Evolutive SFP'!#REF!+'Evolutive SFP'!#REF!) -> #REF! | AW13: ='Evolutive SFP'!#REF!/('Evolutive SFP'!#REF!+'Evolutive SFP'!#REF!) -> #REF! | AX13: ='Evolutive SFP'!#REF!/('Evolutive SFP'!#REF!+'Evolutive SFP'!#REF!) -> #REF! | AY13: ='Evolutive SFP'!#REF!/('Evolutive SFP'!#REF!+'Evolutive SFP'!#REF!) -> #REF! | AZ13: ='Evolutive SFP'!#REF!/('Evolutive SFP'!#REF!+'Evolutive SFP'!#REF!) -> #REF! | BA13: ='Evolutive SFP'!#REF!/('Evolutive SFP'!#REF!+'Evolutive SFP'!#REF!) -> #REF! | BB13: ='Evolutive SFP'!#REF!/('Evolutive SFP'!#REF!+'Evolutive SFP'!#REF!) -> #REF! | BC13: ='Evolutive SFP'!#REF!/('Evolutive SFP'!#REF!+'Evolutive SFP'!#REF!) -> #REF!
B14: EB ratio | C14: Max 25% | D14: ='Evolutive SFP'!#REF!/'Evolutive SFP'!#REF! -> #REF! | E14: ='Evolutive SFP'!#REF!/'Evolutive SFP'!#REF! -> #REF! | F14: ='Evolutive SFP'!#REF!/'Evolutive SFP'!#REF! -> #REF! | G14: ='Evolutive SFP'!#REF!/'Evolutive SFP'!#REF! -> #REF! | H14: ='Evolutive SFP'!#REF!/'Evolutive SFP'!#REF! -> #REF! | I14: ='Evolutive SFP'!#REF!/'Evolutive SFP'!#REF! -> #REF! | J14: ='Evolutive SFP'!#REF!/'Evolutive SFP'!#REF! -> #REF! | K14: ='Evolutive SFP'!#REF!/'Evolutive SFP'!#REF! -> #REF! | ... AS14: ='Evolutive SFP'!#REF!/'Evolutive SFP'!#REF! -> #REF! | AT14: ='Evolutive SFP'!C37/'Evolutive SFP'!C27 -> 0 | AU14: ='Evolutive SFP'!#REF!/'Evolutive SFP'!#REF! -> #REF! | AV14: ='Evolutive SFP'!#REF!/'Evolutive SFP'!#REF! -> #REF! | AW14: ='Evolutive SFP'!#REF!/'Evolutive SFP'!#REF! -> #REF! | AX14: ='Evolutive SFP'!#REF!/'Evolutive SFP'!#REF! -> #REF! | AY14: ='Evolutive SFP'!#REF!/'Evolutive SFP'!#REF! -> #REF! | AZ14: ='Evolutive SFP'!#REF!/'Evolutive SFP'!#REF! -> #REF! | BA14: ='Evolutive SFP'!#REF!/'Evolutive SFP'!#REF! -> #REF! | BB14: ='Evolutive SFP'!#REF!/'Evolutive SFP'!#REF! -> #REF! | BC14: ='Evolutive SFP'!#REF!/'Evolutive SFP'!#REF! -> #REF!
B15: LA to TA ratio | D15: ='Evolutive SFP'!#REF!/'Evolutive SFP'!#REF! -> #REF! | E15: ='Evolutive SFP'!#REF!/'Evolutive SFP'!#REF! -> #REF! | F15: ='Evolutive SFP'!#REF!/'Evolutive SFP'!#REF! -> #REF! | G15: ='Evolutive SFP'!#REF!/'Evolutive SFP'!#REF! -> #REF! | H15: ='Evolutive SFP'!#REF!/'Evolutive SFP'!#REF! -> #REF! | I15: ='Evolutive SFP'!#REF!/'Evolutive SFP'!#REF! -> #REF! | J15: ='Evolutive SFP'!#REF!/'Evolutive SFP'!#REF! -> #REF! | K15: ='Evolutive SFP'!#REF!/'Evolutive SFP'!#REF! -> #REF! | ... AS15: ='Evolutive SFP'!#REF!/'Evolutive SFP'!#REF! -> #REF! | AT15: ='Evolutive SFP'!C4/'Evolutive SFP'!C27 -> 0.31019118 | AU15: ='Evolutive SFP'!#REF!/'Evolutive SFP'!#REF! -> #REF! | AV15: ='Evolutive SFP'!#REF!/'Evolutive SFP'!#REF! -> #REF! | AW15: ='Evolutive SFP'!#REF!/'Evolutive SFP'!#REF! -> #REF! | AX15: ='Evolutive SFP'!#REF!/'Evolutive SFP'!#REF! -> #REF! | AY15: ='Evolutive SFP'!#REF!/'Evolutive SFP'!#REF! -> #REF! | AZ15: ='Evolutive SFP'!#REF!/'Evolutive SFP'!#REF! -> #REF! | BA15: ='Evolutive SFP'!#REF!/'Evolutive SFP'!#REF! -> #REF! | BB15: ='Evolutive SFP'!#REF!/'Evolutive SFP'!#REF! -> #REF! | BC15: ='Evolutive SFP'!#REF!/'Evolutive SFP'!#REF! -> #REF!
A16: STRUCTURE | B16: NEA ratio | C16: Max 10% | D16: =('Evolutive SFP'!#REF!+'Evolutive SFP'!#REF!)/'Evolutive SFP'!#REF! -> #REF! | E16: =('Evolutive SFP'!#REF!+'Evolutive SFP'!#REF!)/'Evolutive SFP'!#REF! -> #REF! | F16: =('Evolutive SFP'!#REF!+'Evolutive SFP'!#REF!)/'Evolutive SFP'!#REF! -> #REF! | G16: =('Evolutive SFP'!#REF!+'Evolutive SFP'!#REF!)/'Evolutive SFP'!#REF! -> #REF! | H16: =('Evolutive SFP'!#REF!+'Evolutive SFP'!#REF!)/'Evolutive SFP'!#REF! -> #REF! | I16: =('Evolutive SFP'!#REF!+'Evolutive SFP'!#REF!)/'Evolutive SFP'!#REF! -> #REF! | J16: =('Evolutive SFP'!#REF!+'Evolutive SFP'!#REF!)/'Evolutive SFP'!#REF! -> #REF! | K16: =('Evolutive SFP'!#REF!+'Evolutive SFP'!#REF!)/'Evolutive SFP'!#REF! -> #REF! | ... AS16: =('Evolutive SFP'!#REF!+'Evolutive SFP'!#REF!)/'Evolutive SFP'!#REF! -> #REF! | AT16: =('Evolutive SFP'!C7+'Evolutive SFP'!C21)/'Evolutive SFP'!C27 -> 0.011057089 | AU16: =('Evolutive SFP'!#REF!+'Evolutive SFP'!#REF!)/'Evolutive SFP'!#REF! -> #REF! | AV16: =('Evolutive SFP'!#REF!+'Evolutive SFP'!#REF!)/'Evolutive SFP'!#REF! -> #REF! | AW16: =('Evolutive SFP'!#REF!+'Evolutive SFP'!#REF!)/'Evolutive SFP'!#REF! -> #REF! | AX16: =('Evolutive SFP'!#REF!+'Evolutive SFP'!#REF!)/'Evolutive SFP'!#REF! -> #REF! | AY16: =('Evolutive SFP'!#REF!+'Evolutive SFP'!#REF!)/'Evolutive SFP'!#REF! -> #REF! | AZ16: =('Evolutive SFP'!#REF!+'Evolutive SFP'!#REF!)/'Evolutive SFP'!#REF! -> #REF! | BA16: =('Evolutive SFP'!#REF!+'Evolutive SFP'!#REF!)/'Evolutive SFP'!#REF! -> #REF! | BB16: =('Evolutive SFP'!#REF!+'Evolutive SFP'!#REF!)/'Evolutive SFP'!#REF! -> #REF! | BC16: =('Evolutive SFP'!#REF!+'Evolutive SFP'!#REF!)/'Evolutive SFP'!#REF! -> #REF!
B17: LB ratio | C17: Max 5% | D17: ='Evolutive SFP'!#REF!/'Evolutive SFP'!#REF! -> #REF! | E17: ='Evolutive SFP'!#REF!/'Evolutive SFP'!#REF! -> #REF! | F17: ='Evolutive SFP'!#REF!/'Evolutive SFP'!#REF! -> #REF! | G17: ='Evolutive SFP'!#REF!/'Evolutive SFP'!#REF! -> #REF! | H17: ='Evolutive SFP'!#REF!/'Evolutive SFP'!#REF! -> #REF! | I17: ='Evolutive SFP'!#REF!/'Evolutive SFP'!#REF! -> #REF! | J17: ='Evolutive SFP'!#REF!/'Evolutive SFP'!#REF! -> #REF! | K17: ='Evolutive SFP'!#REF!/'Evolutive SFP'!#REF! -> #REF! | ... AS17: ='Evolutive SFP'!#REF!/'Evolutive SFP'!#REF! -> #REF! | AT17: ='Evolutive SFP'!C21/'Evolutive SFP'!C27 -> 0.0020418096 | AU17: ='Evolutive SFP'!#REF!/'Evolutive SFP'!#REF! -> #REF! | AV17: ='Evolutive SFP'!#REF!/'Evolutive SFP'!#REF! -> #REF! | AW17: ='Evolutive SFP'!#REF!/'Evolutive SFP'!#REF! -> #REF! | AX17: ='Evolutive SFP'!#REF!/'Evolutive SFP'!#REF! -> #REF! | AY17: ='Evolutive SFP'!#REF!/'Evolutive SFP'!#REF! -> #REF! | AZ17: ='Evolutive SFP'!#REF!/'Evolutive SFP'!#REF! -> #REF! | BA17: ='Evolutive SFP'!#REF!/'Evolutive SFP'!#REF! -> #REF! | BB17: ='Evolutive SFP'!#REF!/'Evolutive SFP'!#REF! -> #REF! | BC17: ='Evolutive SFP'!#REF!/'Evolutive SFP'!#REF! -> #REF!
B18: PI to Deposit ratio | C18: Max 5% | D18: ='Evolutive SFP'!#REF!/'Evolutive SFP'!#REF! -> #REF! | E18: ='Evolutive SFP'!#REF!/'Evolutive SFP'!#REF! -> #REF! | F18: ='Evolutive SFP'!#REF!/'Evolutive SFP'!#REF! -> #REF! | G18: ='Evolutive SFP'!#REF!/'Evolutive SFP'!#REF! -> #REF! | H18: ='Evolutive SFP'!#REF!/'Evolutive SFP'!#REF! -> #REF! | I18: ='Evolutive SFP'!#REF!/'Evolutive SFP'!#REF! -> #REF! | J18: ='Evolutive SFP'!#REF!/'Evolutive SFP'!#REF! -> #REF! | K18: ='Evolutive SFP'!#REF!/'Evolutive SFP'!#REF! -> #REF! | ... AS18: ='Evolutive SFP'!#REF!/'Evolutive SFP'!#REF! -> #REF! | AT18: ='Evolutive SFP'!C13/'Evolutive SFP'!C31 -> 0 | AU18: ='Evolutive SFP'!#REF!/'Evolutive SFP'!#REF! -> #REF! | AV18: ='Evolutive SFP'!#REF!/'Evolutive SFP'!#REF! -> #REF! | AW18: ='Evolutive SFP'!#REF!/'Evolutive SFP'!#REF! -> #REF! | AX18: ='Evolutive SFP'!#REF!/'Evolutive SFP'!#REF! -> #REF! | AY18: ='Evolutive SFP'!#REF!/'Evolutive SFP'!#REF! -> #REF! | AZ18: ='Evolutive SFP'!#REF!/'Evolutive SFP'!#REF! -> #REF! | BA18: ='Evolutive SFP'!#REF!/'Evolutive SFP'!#REF! -> #REF! | BB18: ='Evolutive SFP'!#REF!/'Evolutive SFP'!#REF! -> #REF! | BC18: ='Evolutive SFP'!#REF!/'Evolutive SFP'!#REF! -> #REF!
B19: PI to CC ratio | C19: Max 40% | D19: ='Evolutive SFP'!#REF!/(CAELS!D3*1000000) -> #REF! | E19: ='Evolutive SFP'!#REF!/(CAELS!E3*1000000) -> #REF! | F19: ='Evolutive SFP'!#REF!/(CAELS!F3*1000000) -> #REF! | G19: ='Evolutive SFP'!#REF!/(CAELS!G3*1000000) -> #REF! | H19: ='Evolutive SFP'!#REF!/(CAELS!H3*1000000) -> #REF! | I19: ='Evolutive SFP'!#REF!/(CAELS!I3*1000000) -> #REF! | J19: ='Evolutive SFP'!#REF!/(CAELS!J3*1000000) -> #REF! | K19: ='Evolutive SFP'!#REF!/(CAELS!K3*1000000) -> #REF! | ... AS19: ='Evolutive SFP'!#REF!/(CAELS!AS3*1000000) -> #REF! | AT19: ='Evolutive SFP'!C13/(CAELS!AT3*1000000) -> 0 | AU19: ='Evolutive SFP'!#REF!/(CAELS!AU3*1000000) -> #REF! | AV19: ='Evolutive SFP'!#REF!/(CAELS!AV3*1000000) -> #REF! | AW19: ='Evolutive SFP'!#REF!/(CAELS!AW3*1000000) -> #REF! | AX19: ='Evolutive SFP'!#REF!/(CAELS!AX3*1000000) -> #REF! | AY19: ='Evolutive SFP'!#REF!/(CAELS!AY3*1000000) -> #REF! | AZ19: ='Evolutive SFP'!#REF!/(CAELS!AZ3*1000000) -> #REF! | BA19: ='Evolutive SFP'!#REF!/(CAELS!BA3*1000000) -> #REF! | BB19: ='Evolutive SFP'!#REF!/(CAELS!BB3*1000000) -> #REF! | BC19: ='Evolutive SFP'!#REF!/(CAELS!BC3*1000000) -> #REF!
B20: Gross loans/TA | D20: ='Evolutive SFP'!#REF!/'Evolutive SFP'!#REF! -> #REF! | E20: ='Evolutive SFP'!#REF!/'Evolutive SFP'!#REF! -> #REF! | F20: ='Evolutive SFP'!#REF!/'Evolutive SFP'!#REF! -> #REF! | G20: ='Evolutive SFP'!#REF!/'Evolutive SFP'!#REF! -> #REF! | H20: ='Evolutive SFP'!#REF!/'Evolutive SFP'!#REF! -> #REF! | I20: ='Evolutive SFP'!#REF!/'Evolutive SFP'!#REF! -> #REF! | J20: ='Evolutive SFP'!#REF!/'Evolutive SFP'!#REF! -> #REF! | K20: ='Evolutive SFP'!#REF!/'Evolutive SFP'!#REF! -> #REF! | ... AS20: ='Evolutive SFP'!#REF!/'Evolutive SFP'!#REF! -> #REF! | AT20: ='Evolutive SFP'!C15/'Evolutive SFP'!C27 -> 0.65391609 | AU20: ='Evolutive SFP'!#REF!/'Evolutive SFP'!#REF! -> #REF! | AV20: ='Evolutive SFP'!#REF!/'Evolutive SFP'!#REF! -> #REF! | AW20: ='Evolutive SFP'!#REF!/'Evolutive SFP'!#REF! -> #REF! | AX20: ='Evolutive SFP'!#REF!/'Evolutive SFP'!#REF! -> #REF! | AY20: ='Evolutive SFP'!#REF!/'Evolutive SFP'!#REF! -> #REF! | AZ20: ='Evolutive SFP'!#REF!/'Evolutive SFP'!#REF! -> #REF! | BA20: ='Evolutive SFP'!#REF!/'Evolutive SFP'!#REF! -> #REF! | BB20: ='Evolutive SFP'!#REF!/'Evolutive SFP'!#REF! -> #REF! | BC20: ='Evolutive SFP'!#REF!/'Evolutive SFP'!#REF! -> #REF!
A21: FUNDING MIX | B21: Total Deposits/Total Assets | D21: ='Evolutive SFP'!#REF!/'Evolutive SFP'!#REF! -> #REF! | E21: ='Evolutive SFP'!#REF!/'Evolutive SFP'!#REF! -> #REF! | F21: ='Evolutive SFP'!#REF!/'Evolutive SFP'!#REF! -> #REF! | G21: ='Evolutive SFP'!#REF!/'Evolutive SFP'!#REF! -> #REF! | H21: ='Evolutive SFP'!#REF!/'Evolutive SFP'!#REF! -> #REF! | I21: ='Evolutive SFP'!#REF!/'Evolutive SFP'!#REF! -> #REF! | J21: ='Evolutive SFP'!#REF!/'Evolutive SFP'!#REF! -> #REF! | K21: ='Evolutive SFP'!#REF!/'Evolutive SFP'!#REF! -> #REF! | ... AS21: ='Evolutive SFP'!#REF!/'Evolutive SFP'!#REF! -> #REF! | AT21: ='Evolutive SFP'!C31/'Evolutive SFP'!C27 -> 0.75365313 | AU21: ='Evolutive SFP'!#REF!/'Evolutive SFP'!#REF! -> #REF! | AV21: ='Evolutive SFP'!#REF!/'Evolutive SFP'!#REF! -> #REF! | AW21: ='Evolutive SFP'!#REF!/'Evolutive SFP'!#REF! -> #REF! | AX21: ='Evolutive SFP'!#REF!/'Evolutive SFP'!#REF! -> #REF! | AY21: ='Evolutive SFP'!#REF!/'Evolutive SFP'!#REF! -> #REF! | AZ21: ='Evolutive SFP'!#REF!/'Evolutive SFP'!#REF! -> #REF! | BA21: ='Evolutive SFP'!#REF!/'Evolutive SFP'!#REF! -> #REF! | BB21: ='Evolutive SFP'!#REF!/'Evolutive SFP'!#REF! -> #REF! | BC21: ='Evolutive SFP'!#REF!/'Evolutive SFP'!#REF! -> #REF!
B22: BOSA Deposits/Total Assets | D22: ='Evolutive SFP'!#REF!/'Evolutive SFP'!#REF! -> #REF! | E22: ='Evolutive SFP'!#REF!/'Evolutive SFP'!#REF! -> #REF! | F22: ='Evolutive SFP'!#REF!/'Evolutive SFP'!#REF! -> #REF! | G22: ='Evolutive SFP'!#REF!/'Evolutive SFP'!#REF! -> #REF! | H22: ='Evolutive SFP'!#REF!/'Evolutive SFP'!#REF! -> #REF! | I22: ='Evolutive SFP'!#REF!/'Evolutive SFP'!#REF! -> #REF! | J22: ='Evolutive SFP'!#REF!/'Evolutive SFP'!#REF! -> #REF! | K22: ='Evolutive SFP'!#REF!/'Evolutive SFP'!#REF! -> #REF! | ... AS22: ='Evolutive SFP'!#REF!/'Evolutive SFP'!#REF! -> #REF! | AT22: ='Evolutive SFP'!C30/'Evolutive SFP'!C27 -> 0.055657772 | AU22: ='Evolutive SFP'!#REF!/'Evolutive SFP'!#REF! -> #REF! | AV22: ='Evolutive SFP'!#REF!/'Evolutive SFP'!#REF! -> #REF! | AW22: ='Evolutive SFP'!#REF!/'Evolutive SFP'!#REF! -> #REF! | AX22: ='Evolutive SFP'!#REF!/'Evolutive SFP'!#REF! -> #REF! | AY22: ='Evolutive SFP'!#REF!/'Evolutive SFP'!#REF! -> #REF! | AZ22: ='Evolutive SFP'!#REF!/'Evolutive SFP'!#REF! -> #REF! | BA22: ='Evolutive SFP'!#REF!/'Evolutive SFP'!#REF! -> #REF! | BB22: ='Evolutive SFP'!#REF!/'Evolutive SFP'!#REF! -> #REF! | BC22: ='Evolutive SFP'!#REF!/'Evolutive SFP'!#REF! -> #REF!
B23: FOSA Deposits/Total Assets | D23: =('Evolutive SFP'!#REF!+'Evolutive SFP'!#REF!)/'Evolutive SFP'!#REF! -> #REF! | E23: =('Evolutive SFP'!#REF!+'Evolutive SFP'!#REF!)/'Evolutive SFP'!#REF! -> #REF! | F23: =('Evolutive SFP'!#REF!+'Evolutive SFP'!#REF!)/'Evolutive SFP'!#REF! -> #REF! | G23: =('Evolutive SFP'!#REF!+'Evolutive SFP'!#REF!)/'Evolutive SFP'!#REF! -> #REF! | H23: =('Evolutive SFP'!#REF!+'Evolutive SFP'!#REF!)/'Evolutive SFP'!#REF! -> #REF! | I23: =('Evolutive SFP'!#REF!+'Evolutive SFP'!#REF!)/'Evolutive SFP'!#REF! -> #REF! | J23: =('Evolutive SFP'!#REF!+'Evolutive SFP'!#REF!)/'Evolutive SFP'!#REF! -> #REF! | K23: =('Evolutive SFP'!#REF!+'Evolutive SFP'!#REF!)/'Evolutive SFP'!#REF! -> #REF! | ... AS23: =('Evolutive SFP'!#REF!+'Evolutive SFP'!#REF!)/'Evolutive SFP'!#REF! -> #REF! | AT23: =('Evolutive SFP'!C28+'Evolutive SFP'!C29)/'Evolutive SFP'!C27 -> 0.69799535 | AU23: =('Evolutive SFP'!#REF!+'Evolutive SFP'!#REF!)/'Evolutive SFP'!#REF! -> #REF! | AV23: =('Evolutive SFP'!#REF!+'Evolutive SFP'!#REF!)/'Evolutive SFP'!#REF! -> #REF! | AW23: =('Evolutive SFP'!#REF!+'Evolutive SFP'!#REF!)/'Evolutive SFP'!#REF! -> #REF! | AX23: =('Evolutive SFP'!#REF!+'Evolutive SFP'!#REF!)/'Evolutive SFP'!#REF! -> #REF! | AY23: =('Evolutive SFP'!#REF!+'Evolutive SFP'!#REF!)/'Evolutive SFP'!#REF! -> #REF! | AZ23: =('Evolutive SFP'!#REF!+'Evolutive SFP'!#REF!)/'Evolutive SFP'!#REF! -> #REF! | BA23: =('Evolutive SFP'!#REF!+'Evolutive SFP'!#REF!)/'Evolutive SFP'!#REF! -> #REF! | BB23: =('Evolutive SFP'!#REF!+'Evolutive SFP'!#REF!)/'Evolutive SFP'!#REF! -> #REF! | BC23: =('Evolutive SFP'!#REF!+'Evolutive SFP'!#REF!)/'Evolutive SFP'!#REF! -> #REF!
