Workbook
Name BALANCE1_LDA01: '[1]Financial Statements'!$E$112
Name BALANCE1_LDA12: '[1]Financial Statements'!$E$123
Name BALANCE2_LDA01: '[1]Financial Statements'!$F$112
Name BALANCE2_LDA12: '[1]Financial Statements'!$F$123
Name BALANCE3_LDA01: '[1]Financial Statements'!$G$112
Name BALANCE3_LDA12: '[1]Financial Statements'!$G$123
Name BALANCE4_LDA01: '[1]Financial Statements'!$H$112
Name BALANCE4_LDA12: '[1]Financial Statements'!$H$123
Name BALANCE5_LDA01: '[1]Financial Statements'!$I$112
Name BALANCE5_LDA12: '[1]Financial Statements'!$I$123
Name BALANCE6_LDA01: '[1]Financial Statements'!$J$112
Name BALANCE6_LDA12: '[1]Financial Statements'!$J$123
Name PEARLS1_LA002: '[1]Financial Statements'!$E$280
Name PEARLS1_LE008: '[1]Financial Statements'!$E$275
Name PEARLS1_LE009: '[1]Financial Statements'!$E$276
Name PEARLS1_LR001: '[1]Financial Statements'!$E$282
Name PEARLS1_LR005: '[1]Financial Statements'!$E$286
Name PEARLS1_LR006: '[1]Financial Statements'!$E$287
Name PEARLS1_LR007: '[1]Financial Statements'!$E$288
Name PEARLS1_LR009: '[1]Financial Statements'!$E$290
Name PEARLS1_LS001: '[1]Financial Statements'!$E$298
Name PEARLS1_LS005: '[1]Financial Statements'!$E$302
Name PEARLS1_LS011: '[1]Financial Statements'!$E$308
Name PEARLS2_LA002: '[1]Financial Statements'!$F$280
Name PEARLS2_LE008: '[1]Financial Statements'!$F$275
Name PEARLS2_LE009: '[1]Financial Statements'!$F$276
Name PEARLS2_LR001: '[1]Financial Statements'!$F$282
Name PEARLS2_LR005: '[1]Financial Statements'!$F$286
Name PEARLS2_LR006: '[1]Financial Statements'!$F$287
Name PEARLS2_LR007: '[1]Financial Statements'!$F$288
Name PEARLS2_LR009: '[1]Financial Statements'!$F$290
Name PEARLS2_LS001: '[1]Financial Statements'!$F$298
Name PEARLS2_LS005: '[1]Financial Statements'!$F$302
Name PEARLS2_LS010: '[1]Financial Statements'!$F$307
Name PEARLS2_LS011: '[1]Financial Statements'!$F$308
Name PEARLS3_LA002: '[1]Financial Statements'!$G$280
Name PEARLS3_LE008: '[1]Financial Statements'!$G$275
Name PEARLS3_LE009: '[1]Financial Statements'!$G$276
Name PEARLS3_LR001: '[1]Financial Statements'!$G$282
Name PEARLS3_LR005: '[1]Financial Statements'!$G$286
Name PEARLS3_LR006: '[1]Financial Statements'!$G$287
Name PEARLS3_LR007: '[1]Financial Statements'!$G$288
Name PEARLS3_LR009: '[1]Financial Statements'!$G$290
Name PEARLS3_LS001: '[1]Financial Statements'!$G$298
Name PEARLS3_LS005: '[1]Financial Statements'!$G$302
Name PEARLS3_LS010: '[1]Financial Statements'!$G$307
Name PEARLS3_LS011: '[1]Financial Statements'!$G$308
Name PEARLS4_LA002: '[1]Financial Statements'!$H$280
Name PEARLS4_LE008: '[1]Financial Statements'!$H$275
Name PEARLS4_LE009: '[1]Financial Statements'!$H$276
Name PEARLS4_LR001: '[1]Financial Statements'!$H$282
Name PEARLS4_LR005: '[1]Financial Statements'!$H$286
Name PEARLS4_LR006: '[1]Financial Statements'!$H$287
Name PEARLS4_LR007: '[1]Financial Statements'!$H$288
Name PEARLS4_LR009: '[1]Financial Statements'!$H$290
Name PEARLS4_LS001: '[1]Financial Statements'!$H$298
Name PEARLS4_LS005: '[1]Financial Statements'!$H$302
Name PEARLS4_LS010: '[1]Financial Statements'!$H$307
Name PEARLS4_LS011: '[1]Financial Statements'!$H$308
Name PEARLS5_LA002: '[1]Financial Statements'!$I$280

Sheet Evolutive SFP
B3: AUDITED 2019 | C3: 43831 | D3: 43862 | E3: 43891 | F3: 43922 | G3: 43952 | H3: 43983 | I3: 44044 | J3: 44075 | K3: 44105 | L3: 44136 | M3: 44166 | N3: AUDITED 2020 | O3: 44197 | P3: 44228 | Q3: 44256 | R3: 44287 | S3: 44317 | T3: 44348 | U3: 44378 | V3: 44409 | W3: 44440 | X3: 44470 | Y3: 44501 | Z3: 44531 | AA3: AUDITED 2021 | AB3: 44562 | AC3: 44593 | AD3: 44621 | AE3: 44652 | AF3: 44682 | AG3: 44713 | AH3: 44743 | AI3: 44774 | AJ3: 44805 | AK3: 44835 | AL3: 44866 | AM3: 44896 | AN3: Aud-22
A4: Cash & cash Equivalent | B4: =(B5+B6) -> 148765355 | C4: =(C5+C6) -> 1.6942504e+08 | D4: =(D5+D6) -> 1.5465799e+08 | E4: =(E5+E6) -> 1.5991676e+08 | F4: =(F5+F6) -> 1.6912865e+08 | G4: =(G5+G6) -> 1.63116e+08 | H4: =(H5+H6) -> 1.9589141e+08 | I4: =(I5+I6) -> 1.4474477e+08 | ... AO4: =(AO5+AO6) -> 1.6155884e+08
A5: Cash In Hand | B5: 56668327 | C5: 54686356 | D5: 65092907 | E5: 66278010 | F5: 72608113 | G5: 74455909 | H5: 63416961 | I5: 50261999 | J5: 46137000 | K5: 85166758 | L5: 60912461 | M5: 52690089 | N5: 52690089 | O5: 57959846 | P5: 69955932 | Q5: 53392309 | R5: 66213614 | S5: 54511748 | T5: 43780040 | U5: 61592007 | AA5: 29937101 | AB5: 36707692 | AC5: 38696413 | AD5: 37431678 | AE5: 44995263 | AF5: 40174314 | AG5: 41708091 | AH5: 84538193 | AI5: 47385459 | AJ5: 50881493 | AK5: 53494807 | AL5: 56184108 | AM5: 55472272 | AN5: 55472272 | AO5: 93147932
A6: Cash at Bank | B6: 92097028 | C6: 1.1473869e+08 | D6: 89565084 | E6: 93638745 | F6: 96520538 | G6: 88660088 | H6: 1.3247445e+08 | I6: 94482767 | J6: 99548792 | K6: 2.922263e+08 | L6: 1.9165739e+08 | M6: 1.5017839e+08 | N6: 150178391 | O6: 1.4803653e+08 | P6: 1.6828695e+08 | Q6: 1.2917837e+08 | R6: 1.5043648e+08 | S6: 1.0734968e+08 | T6: 1.0627063e+08 | U6: 83693053 | AA6: 89518374 | AB6: 78602368 | AC6: 86242051 | AD6: 74496288 | AE6: 75057936 | AF6: 77281142 | AG6: 83368774 | AH6: 1.9339914e+08 | AI6: 1.6917111e+08 | AJ6: 1.3738455e+08 | AK6: 1.4069936e+08 | AL6: 1.2654917e+08 | AM6: 1.0292981e+08 | AN6: 102929814 | AO6: 68410908
A7: Prepayment and Sundry | B7: 49478228 | C7: 2780591 | D7: 2968292 | E7: 2735993 | F7: 2485694 | G7: 2235395 | H7: 2690807.9 | I7: 2752374.6 | J7: 2552158 | K7: 2360591.4 | L7: 2774666.8 | M7: 2873200.2 | N7: 43203284 | O7: 2645887 | P7: 2886573.8 | Q7: 3447411.1 | R7: 3219097.9 | S7: 2978784.7 | T7: 2744471.5 | U7: 2510158.3 | AA7: 33262886 | AB7: 2086137.2 | AC7: 2506492.5 | AD7: 2245305.8 | AE7: 2428992.6 | AF7: 2483279.4 | AG7: 2307488.2 | AH7: 2267575 | AI7: 2241661.8 | AJ7: 2592773.6 | AK7: 3331289.2 | AL7: 3428145 | AM7: 3136091.7 | AN7: 38977465 | AO7: 2180436.4
A8: Financial Investment | B8: =(B9+B10+B11+B12+B13) -> 26606944 | C8: =(C9+C10+C11+C13+C12) -> 26606944 | D8: =(D9+D10+D11+D13+D12) -> 26606944 | E8: =(E9+E10+E11+E13+E12) -> 26606944 | F8: =(F9+F10+F11+F13+F12) -> 26606944 | G8: =(G9+G10+G11+G13+G12) -> 26606944 | H8: =(H9+H10+H11+H13+H12) -> 26606944 | I8: =(I9+I10+I11+I13+I12) -> 26606944 | J8: =(J9+J10+J11+J13+J12) -> 26606944 | ... AO8: =(AO9+AO10+AO11+AO13+AO12) -> 26606944
A9: Government Security | B9: 0 | C9: 0 | D9: 0 | E9: 0 | F9: 0 | G9: 0 | H9: 0 | I9: 0 | J9: 0 | K9: 0 | L9: 0 | M9: 0 | N9: 0 | O9: 0 | P9: 0 | Q9: 0 | R9: 0 | S9: 0 | T9: 0 | U9: 0 | V9: 0 | W9: 0 | X9: 0 | Y9: 0 | Z9: 0 | AA9: 0 | AB9: 0 | AC9: 0 | AD9: 0 | AE9: 0 | AF9: 0 | AG9: 0 | AH9: 0 | AI9: 0 | AJ9: 0 | AK9: 0 | AL9: 0 | AM9: 0 | AN9: 0 | AO9: 0
A10: Other Securities | B10: 0 | C10: 0 | D10: 0 | E10: 0 | F10: 0 | G10: 0 | H10: 0 | I10: 0 | J10: 0 | K10: 0 | L10: 0 | M10: 0 | N10: 0 | O10: 0 | P10: 0 | Q10: 0 | R10: 0 | S10: 0 | T10: 0 | U10: 0 | V10: 0 | W10: 0 | X10: 0 | Y10: 0 | Z10: 0 | AA10: 0 | AB10: 0 | AC10: 0 | AD10: 0 | AE10: 0 | AF10: 0 | AG10: 0 | AH10: 0 | AI10: 0 | AJ10: 0 | AK10: 0 | AL10: 0 | AM10: 0 | AN10: 0 | AO10: 0
A11: Balances in NACCOS (E.g Jungu Kuu, ESS, Savings,Money Market,Coop FD, CFP) | B11: 0 | C11: 0 | D11: 0 | E11: 0 | F11: 0 | G11: 0 | H11: 0 | I11: 0 | J11: 0 | K11: 0 | L11: 0 | M11: 0 | N11: 0 | O11: 0 | P11: 0 | Q11: 0 | R11: 0 | S11: 0 | T11: 0 | U11: 0 | V11: 0 | W11: 0 | X11: 0 | Y11: 0 | Z11: 0 | AA11: 0 | AB11: 0 | AC11: 0 | AD11: 0 | AE11: 0 | AF11: 0 | AG11: 0 | AH11: 0 | AI11: 0 | AJ11: 0 | AK11: 0 | AL11: 0 | AM11: 0 | AN11: 0 | AO11: 0
A12: Equity Investments in NACCOs(Shares in- CIC, KUSCCO, COOP BANK,CAK, KERUSSU) | B12: =1453400+950000+100010+3790368 -> 6293778 | C12: 0 | D12: 0 | E12: 0 | F12: 0 | G12: 0 | H12: 0 | I12: 0 | J12: 0 | K12: 0 | L12: 0 | M12: 0 | N12: =1453400+950000+100010+3790368 -> 6293778 | AA12: 6293778 | AB12: 26606944 | AC12: 26606944 | AD12: 26606944 | AE12: 26606944 | AF12: 26606944 | AG12: 26606944 | AH12: 26606944 | AI12: 26606944 | AJ12: 26606944 | AK12: 26606944 | AL12: 26606944 | AM12: 26606944 | AN12: 26606944 | AO12: 26606944
A13: Equity Investments in companies - shares/stocks | B13: =61666+20145000+106500 -> 20313166 | C13: 26606944 | D13: 26606944 | E13: 26606944 | F13: 26606944 | G13: 26606944 | H13: 26606944 | I13: 26606944 | J13: 26606944 | K13: 26606944 | L13: 26606944 | M13: 26606944 | N13: =61666+20145000+106500 -> 20313166 | O13: 26606944 | P13: 26606944 | Q13: 26606944 | R13: 26606944 | S13: 26606944 | T13: 26606944 | U13: 26606944 | AA13: 20313166
A14: Net Loan Portfolio | B14: =(B15-B16) -> 255665887 | C14: =(C15-C16) -> 2.5789802e+08 | D14: =(D15-D16) -> 2.4613266e+08 | E14: =(E15-E16) -> 2.4210956e+08 | F14: =(F15-F16) -> 2.4443235e+08 | G14: =(G15-G16) -> 2.4540906e+08 | H14: =(H15-H16) -> 2.4132219e+08 | I14: =(I15-I16) -> 2.3631348e+08 | ... AO14: =(AO15-AO16) -> 2.9624209e+08
A15: Gross Loan Portfolio | B15: 284130439 | C15: 2.8529802e+08 | D15: 2.7358266e+08 | E15: 2.6960956e+08 | F15: 2.7198235e+08 | G15: 2.7300906e+08 | H15: 2.7008674e+08 | I15: 2.6517803e+08 | J15: 2.7666628e+08 | K15: 2.532884e+08 | L15: 2.5434535e+08 | M15: 2.5740575e+08 | N15: 257405749 | O15: 2.5687384e+08 | P15: 2.6374038e+08 | Q15: 2.6052956e+08 | R15: 2.6819503e+08 | S15: 2.910809e+08 | T15: 3.0090038e+08 | U15: 3.1291865e+08 | AA15: 338459421 | AB15: 3.5704707e+08 | AC15: 3.4439896e+08 | AD15: 3.3155461e+08 | AE15: 3.3293216e+08 | AF15: 3.4367336e+08 | AG15: 3.2715119e+08 | AH15: 3.1373814e+08 | AI15: 3.1576471e+08 | AJ15: 3.2561202e+08 | AK15: 3.2961716e+08 | AL15: 3.4213928e+08 | AM15: 3.4115198e+08 | AN15: 3.4115198e+08 | AO15: 3.2690664e+08
A16: Allowance For Loan Loss | B16: =27350000+1114552 -> 28464552 | C16: 27400000 | D16: 27450000 | E16: 27500000 | F16: 27550000 | G16: 27600000 | H16: 28764552 | I16: 28864552 | J16: 28914552 | K16: 28964552 | L16: 29014552 | M16: 29064552 | N16: 29064552 | O16: 29114552 | P16: 29164552 | Q16: 29214552 | R16: 29264552 | S16: 29314552 | T16: 29364552 | U16: 29414552 | AA16: 29664552 | AB16: 29714552 | AC16: 29764552 | AD16: 29814552 | AE16: 29864552 | AF16: 29914552 | AG16: 29964552 | AH16: 30014552 | AI16: 30064552 | AJ16: 30114552 | AK16: 30164552 | AL16: 30214552 | AM16: 30264552 | AN16: 30264552 | AO16: 30664552
A17: Accounts Recievables | B17: =(B18+B19+B20) -> 0 | C17: =(C18+C19+C20) -> 0 | D17: =(D18+D19+D20) -> 0 | E17: =(E18+E19+E20) -> 0 | F17: =(F18+F19+F20) -> 0 | G17: =(G18+G19+G20) -> 0 | H17: =(H18+H19+H20) -> 0 | I17: =(I18+I19+I20) -> 0 | ... AA17: =(AA18+AA19+AA20) -> 0 | AB17: 0 | AC17: 0 | AD17: 0 | AE17: 0 | AF17: 0 | AG17: 0 | AH17: 0 | AI17: 0 | AJ17: 0 | AK17: 0 | AL17: 0 | AM17: 0 | AN17: 0 | AO17: 0
A18: Tax Recoverable | B18: 0 | C18: 0 | D18: 0 | E18: 0 | F18: 0 | G18: 0 | H18: 0 | I18: 0 | J18: 0 | K18: 0 | L18: 0 | M18: 0 | N18: 0 | O18: 0 | P18: 0 | Q18: 0 | R18: 0 | S18: 0 | T18: 0 | U18: 0 | V18: 0 | W18: 0 | X18: 0 | Y18: 0 | Z18: 0 | AA18: 0 | AB18: 0 | AC18: 0 | AD18: 0 | AE18: 0 | AF18: 0 | AG18: 0 | AH18: 0 | AI18: 0 | AJ18: 0 | AK18: 0 | AL18: 0 | AM18: 0 | AN18: 0 | AO18: 0
A19: Deffered Tax Assets | B19: 0 | C19: 0 | D19: 0 | E19: 0 | F19: 0 | G19: 0 | H19: 0 | I19: 0 | J19: 0 | K19: 0 | L19: 0 | M19: 0 | N19: 0 | O19: 0 | P19: 0 | Q19: 0 | R19: 0 | S19: 0 | T19: 0 | U19: 0 | V19: 0 | W19: 0 | X19: 0 | Y19: 0 | Z19: 0 | AA19: 0 | AB19: 0 | AC19: 0 | AD19: 0 | AE19: 0 | AF19: 0 | AG19: 0 | AH19: 0 | AI19: 0 | AJ19: 0 | AK19: 0 | AL19: 0 | AM19: 0 | AN19: 0 | AO19: 0
A20: Retirement Benefit Assets | B20: 0 | C20: 0 | D20: 0 | E20: 0 | F20: 0 | G20: 0 | H20: 0 | I20: 0 | J20: 0 | K20: 0 | L20: 0 | M20: 0 | N20: 0 | O20: 0 | P20: 0 | Q20: 0 | R20: 0 | S20: 0 | T20: 0 | U20: 0 | V20: 0 | W20: 0 | X20: 0 | Y20: 0 | Z20: 0 | AA20: 0 | AB20: 0 | AC20: 0 | AD20: 0 | AE20: 0 | AF20: 0 | AG20: 0 | AH20: 0 | AI20: 0 | AJ20: 0 | AK20: 0 | AL20: 0 | AM20: 0 | AN20: 0 | AO20: 0
A21: Property&Equipments&Other Assets | B21: =(B22+B23+B24+B25+B26) -> 60146266 | C21: =(C22+C23+C24+C25+C26) -> 51857559 | D21: =(D22+D23+D24+D25+D26) -> 51131692 | E21: =(E22+E23+E24+E25+E26) -> 50946361 | F21: =(F22+F23+F24+F25+F26) -> 51244610 | G21: =(G22+G23+G24+G25+G26) -> 50754508 | H21: =(H22+H23+H24+H25+H26) -> 60090479 | I21: =(I22+I23+I24+I25+I26) -> 61794874 | ... AO21: =(AO22+AO23+AO24+AO25+AO26) -> 1.0064786e+08
A22: Investment Properties | B22: 0 | C22: 0 | D22: 0 | E22: 0 | F22: 0 | G22: 0 | H22: 0 | I22: 0 | J22: 0 | K22: 0 | L22: 0 | M22: 0 | N22: 0 | O22: 0 | P22: 0 | Q22: 0 | R22: 0 | S22: 0 | T22: 0 | U22: 0 | V22: 0 | W22: 0 | X22: 0 | Y22: 0 | Z22: 0 | AA22: 22416108 | AB22: 0 | AC22: 0 | AD22: 0 | AE22: 0 | AF22: 0 | AG22: 0 | AH22: 0 | AI22: 0 | AJ22: 0 | AK22: 0 | AL22: 0 | AM22: 0 | AN22: 0 | AO22: 0
A23: Property and Equipment | B23: 60146266 | C23: 51857559 | D23: 51131692 | E23: 50946361 | F23: 51244610 | G23: 50754508 | H23: 60090479 | I23: 61794874 | J23: 62042420 | K23: 63663012 | L23: 63180962 | M23: 62729248 | N23: 73169435 | O23: 62116369 | P23: 61536870 | Q23: 60903584 | R23: 61543741 | S23: 61325766 | T23: 60773778 | U23: 60428316 | AA23: 46273620 | AB23: 59127422 | AC23: 58619421 | AD23: 57648201 | AE23: 57899591 | AF23: 57412034 | AG23: 57080099 | AH23: 58150528 | AI23: 57974744 | AJ23: 58150586 | AK23: 57652433 | AL23: 57162977 | AM23: 56682625 | AN23: 63880596 | AO23: 65480831
A24: Prepaid Lease Rentals | B24: 0 | C24: 0 | D24: 0 | E24: 0 | F24: 0 | G24: 0 | H24: 0 | I24: 0 | J24: 0 | K24: 0 | L24: 0 | M24: 0 | N24: 0 | O24: 0 | P24: 0 | Q24: 0 | R24: 0 | S24: 0 | T24: 0 | U24: 0 | V24: 0 | W24: 0 | X24: 0 | Y24: 0 | Z24: 0 | AA24: 0 | AB24: 0 | AC24: 0 | AD24: 0 | AE24: 0 | AF24: 0 | AG24: 0 | AH24: 0 | AI24: 0 | AJ24: 0 | AK24: 0 | AL24: 0 | AM24: 0 | AN24: 0 | AO24: 0
A25: Intangible Assets | B25: 0 | C25: 0 | D25: 0 | E25: 0 | F25: 0 | G25: 0 | H25: 0 | I25: 0 | J25: 0 | K25: 0 | L25: 0 | M25: 0 | N25: 0 | O25: 0 | P25: 0 | Q25: 0 | R25: 0 | S25: 0 | T25: 0 | U25: 0 | V25: 0 | W25: 0 | X25: 0 | Y25: 0 | Z25: 0 | AA25: 0 | AB25: 7396114.5 | AC25: 7300778.8 | AD25: 7108655.2 | AE25: 6960558.2 | AF25: 6954118.3 | AG25: 6809240.8 | AH25: 7059048.3 | AI25: 7107818.1 | AJ25: 7087030.2 | AK25: 7037300.4 | AL25: 7086523.3 | AM25: 7197970.8 | AN25: 0 | AO25: 6938587.5
A26: Other Assets | B26: 0 | C26: 0 | D26: 0 | E26: 0 | F26: 0 | G26: 0 | H26: 0 | I26: 0 | J26: 0 | K26: 0 | L26: 0 | M26: 0 | N26: 0 | O26: 0 | P26: 0 | Q26: 0 | R26: 0 | S26: 0 | T26: 0 | U26: 0 | V26: 0 | W26: 0 | X26: 0 | Y26: 0 | Z26: 0 | AA26: 252895 | AB26: 30519616 | AC26: 32921827 | AD26: 39686419 | AE26: 43236368 | AF26: 46980202 | AG26: 47603878 | AH26: 44287907 | AI26: 44240795 | AJ26: 42750017 | AK26: 40660701 | AL26: 29021342 | AM26: 35841374 | AN26: 0 | AO26: 28228441
A27: Total Assets | B27: =(B21+B17+B14+B8+B7+B4) -> 540662680 | C27: =(C21+C17+C14+C8+C7+C4) -> 5.0856816e+08 | D27: =(D21+D17+D14+D8+D7+D4) -> 4.8149758e+08 | E27: =(E21+E17+E14+E8+E7+E4) -> 4.8231562e+08 | F27: =(F21+F17+F14+F8+F7+F4) -> 4.9389825e+08 | G27: =(G21+G17+G14+G8+G7+G4) -> 4.881219e+08 | H27: =(H21+H17+H14+H8+H7+H4) -> 5.2660183e+08 | I27: =(I21+I17+I14+I8+I7+I4) -> 4.7221244e+08 | ... AO27: =(AO21+AO17+AO14+AO8+AO7+AO4) -> 5.8723617e+08
A28: Savings and Deposits | B28: 208553605 | C28: 1.9394146e+08 | D28: 1.8432906e+08 | E28: 1.8458571e+08 | F28: 1.8684759e+08 | G28: 1.8163796e+08 | H28: 1.9665044e+08 | I28: 1.8200647e+08 | J28: 1.9436477e+08 | K28: 3.9168293e+08 | L28: 2.7079944e+08 | M28: 2.3226059e+08 | N28: 251772590 | O28: 2.3486797e+08 | P28: 2.6084984e+08 | Q28: 2.2436123e+08 | R28: 2.4991936e+08 | S28: 2.2203741e+08 | T28: 2.1648378e+08 | U28: 2.2261307e+08 | AA28: 228670040 | AB28: 2.1471167e+08 | AC28: 2.1145963e+08 | AD28: 2.0175013e+08 | AE28: 2.2124569e+08 | AF28: 2.1798048e+08 | AG28: 2.0327801e+08 | AH28: 3.1904635e+08 | AI28: 2.6407672e+08 | AJ28: 2.4453425e+08 | AK28: 2.4544178e+08 | AL28: 2.4545631e+08 | AM28: 2.1192032e+08 | AN28: 211920316 | AO28: 2.0606894e+08
A29: Short Terrm Deposits | C29: 20270500 | D29: 20044000 | E29: 11910000 | F29: 18605000 | G29: 18505000 | H29: 18882000 | I29: 20257000 | J29: 22562000 | K29: 22612000 | L29: 22167000 | M29: 19512000 | O29: 21212000 | P29: 21631000 | Q29: 20713000 | R29: 21713000 | S29: 22093770 | T29: 23428770 | U29: 24250270 | AB29: 24746336 | AC29: 28734000 | AD29: 27885000 | AE29: 20395000 | AF29: 29468000 | AG29: 28708000 | AH29: 27808000 | AI29: 29603800 | AJ29: 29653800 | AK29: 32973800 | AL29: 23173800 | AM29: 33873800 | AN29: 33873800 | AO29: 36128600
A30: Non Withdrawable Deposits | B30: 157808397 | C30: 1.5756806e+08 | D30: 1.5798718e+08 | E30: 1.5876701e+08 | F30: 1.5824209e+08 | G30: 1.5859242e+08 | H30: 1.6008245e+08 | I30: 1.6031634e+08 | J30: 1.5972418e+08 | K30: 1.5996651e+08 | L30: 1.6050013e+08 | M30: 1.6089183e+08 | N30: 160891830 | O30: 1.6054869e+08 | P30: 1.6098763e+08 | Q30: 1.6051491e+08 | R30: 1.6167337e+08 | S30: 1.6373952e+08 | T30: 1.6450855e+08 | U30: 1.651588e+08 | AA30: 168763483 | AB30: 1.6938136e+08 | AC30: 1.6936137e+08 | AD30: 1.6960632e+08 | AE30: 1.6966937e+08 | AF30: 1.7214117e+08 | AG30: 1.7192689e+08 | AH30: 1.7273893e+08 | AI30: 1.7248303e+08 | AJ30: 1.7323267e+08 | AK30: 1.7375071e+08 | AL30: 1.7296754e+08 | AM30: 1.7406519e+08 | AN30: 1.7406519e+08 | AO30: 1.7747094e+08
A31: Total Deposit Liabilities | B31: =SUM(B28:B30) -> 366362002 | C31: =SUM(C28:C30) -> 3.7178002e+08 | D31: =SUM(D28:D30) -> 3.6236024e+08 | E31: =SUM(E28:E30) -> 3.5526273e+08 | F31: =SUM(F28:F30) -> 3.6369468e+08 | G31: =SUM(G28:G30) -> 3.5873538e+08 | H31: =SUM(H28:H30) -> 3.7561489e+08 | I31: =SUM(I28:I30) -> 3.6257981e+08 | ... AO31: =SUM(AO28:AO30) -> 4.1966848e+08
A32: Tax Payable | B32: 0 | C32: 0 | D32: 0 | E32: 0 | F32: 0 | G32: 0 | H32: 0 | I32: 0 | J32: 0 | K32: 0 | L32: 0 | M32: 0 | N32: 0 | O32: 0 | P32: 0 | Q32: 0 | R32: 0 | S32: 0 | T32: 0 | U32: 0 | V32: 0 | W32: 0 | X32: 0 | Y32: 0 | Z32: 0 | AA32: 150000 | AB32: 0 | AC32: 0 | AD32: 0 | AE32: 0 | AF32: 0 | AG32: 0 | AH32: 0 | AI32: 0 | AJ32: 0 | AK32: 0 | AL32: 0 | AM32: 0 | AN32: 3723476.8 | AO32: 0
A33: Dividends Payable | B33: =1706274+6047587 -> 7753861 | C33: 7737289.3 | D33: 7712209.3 | E33: 25759163 | F33: 13948556 | G33: 12410890 | H33: 11508125 | I33: 10981976 | J33: 10806135 | K33: 10758040 | L33: 10668160 | M33: 10506256 | N33: =3052686+7453370 -> 10506056 | O33: 10232720 | P33: 28305701 | Q33: 9836865.5 | R33: 5878966.5 | S33: 5210385.5 | T33: 4205323.5 | U33: 4047378.5 | AA33: 2959673 | AB33: 2915438.5 | AC33: 16463144 | AD33: 8400823.2 | AE33: 6658189.2 | AF33: 5934559.2 | AG33: 5714482.2 | AH33: 5457819.2 | AI33: 5241428.2 | AJ33: 5104696.2 | AK33: 5023561.2 | AL33: 4855706.2 | AM33: 2323162.7 | AN33: 17192689 | AO33: 4791505.2
A34: Deferred Tax Liability | B34: 0 | C34: 0 | D34: 0 | E34: 0 | F34: 0 | G34: 0 | H34: 0 | I34: 0 | J34: 0 | K34: 0 | L34: 0 | M34: 0 | N34: 0 | O34: 0 | P34: 0 | Q34: 0 | R34: 0 | S34: 0 | T34: 0 | U34: 0 | V34: 0 | W34: 0 | X34: 0 | Y34: 0 | Z34: 0 | AA34: 0 | AB34: 0 | AC34: 0 | AD34: 0 | AE34: 0 | AF34: 0 | AG34: 0 | AH34: 0 | AI34: 0 | AJ34: 0 | AK34: 0 | AL34: 0 | AM34: 0 | AO34: 0
A35: Retirement Benefits Liabilty | B35: 0 | C35: 0 | D35: 0 | E35: 0 | F35: 0 | G35: 0 | H35: 0 | I35: 0 | J35: 0 | K35: 0 | L35: 0 | M35: 0 | N35: 0 | O35: 0 | P35: 0 | Q35: 0 | R35: 0 | S35: 0 | T35: 0 | U35: 0 | V35: 0 | W35: 0 | X35: 0 | Y35: 0 | Z35: 0 | AA35: 0 | AB35: 0 | AC35: 0 | AD35: 0 | AE35: 0 | AF35: 0 | AG35: 0 | AH35: 0 | AI35: 0 | AJ35: 0 | AK35: 0 | AL35: 0 | AM35: 0 | AO35: 0
A36: Other Liabilities | B36: =37823892+15780840+376422+4902255 -> 58883409 | C36: 32018949 | D36: 23503524 | E36: 33843646 | F36: 39597375 | G36: 36903863 | H36: 67488075 | I36: 25043412 | J36: 11497579 | K36: 17637978 | L36: 16909987 | M36: 16672721 | N36: =10255348+16089183+716987+26214+8120476 -> 35208208 | O36: 19668522 | P36: 21828372 | Q36: 23463231 | R36: 21775267 | S36: 21299814 | T36: 18667262 | U36: 17426764 | AA36: =10768819+13501079+25087+12536249+3695140 -> 40526374 | AB36: 16170353 | AC36: 23197464 | AD36: 17164809 | AE36: 15554081 | AF36: 13983433 | AG36: 15938250 | AH36: 27590110 | AI36: 20894200 | AJ36: 18668554 | AK36: 21194238 | AL36: 20175957 | AM36: 21237647 | AN36: 20418290 | AO36: 13325829
A37: External Borrowings | C37: 0 | D37: 0 | E37: 0 | F37: 0 | G37: 0 | H37: 0 | I37: 0 | J37: 0 | K37: 0 | L37: 0 | M37: 0 | O37: 0 | P37: 0 | Q37: 0 | R37: 0 | S37: 0 | T37: 0 | U37: 0 | AB37: 0 | AC37: 0 | AD37: 0 | AE37: 0 | AF37: 0 | AG37: 0 | AH37: 0 | AI37: 0 | AJ37: 0 | AK37: 0 | AL37: 0 | AM37: 0 | AO37: 0
A38: Total Liabilities | B38: =SUM(B31:B37) -> 432999272 | C38: =SUM(C31:C37) -> 4.1153626e+08 | D38: =SUM(D31:D37) -> 3.9357598e+08 | E38: =SUM(E31:E37) -> 4.1486554e+08 | F38: =SUM(F31:F37) -> 4.1724061e+08 | G38: =SUM(G31:G37) -> 4.0805014e+08 | H38: =SUM(H31:H37) -> 4.5461109e+08 | I38: =SUM(I31:I37) -> 3.986052e+08 | ... AO38: =SUM(AO31:AO37) -> 4.3778581e+08
A39: Share Capital | B39: 33761298 | C39: 33938428 | D39: 34105718 | E39: 34254183 | F39: 34465203 | G39: 34623120 | H39: 34960120 | I39: 35225381 | J39: 35382986 | K39: 35561469 | L39: 35752819 | M39: 35934679 | N39: 35934679 | O39: 36092644 | P39: 36308273 | Q39: 36634495 | R39: 37048255 | S39: 37506560 | T39: 37871932 | U39: 38219322 | AA39: 39985399 | AB39: 40315279 | AC39: 40683826 | AD39: 41075758 | AE39: 41474586 | AF39: 42086673 | AG39: 42675268 | AH39: 43131101 | AI39: 43531181 | AJ39: 43965056 | AK39: 44276199 | AL39: 44713929 | AM39: 45226241 | AN39: 45226241 | AO39: 49319355
A40: Capital Grants | B40: 0 | C40: 0 | D40: 0 | E40: 0 | F40: 0 | G40: 0 | H40: 0 | I40: 0 | J40: 0 | K40: 0 | L40: 0 | M40: 0 | N40: 0 | O40: 0 | P40: 0 | Q40: 0 | R40: 0 | S40: 0 | T40: 0 | U40: 0 | V40: 0 | W40: 0 | X40: 0 | Y40: 0 | Z40: 0 | AA40: 0 | AB40: 0 | AC40: 0 | AD40: 0 | AE40: 0 | AF40: 0 | AG40: 0 | AH40: 0 | AI40: 0 | AJ40: 0 | AK40: 0 | AL40: 0 | AM40: 0 | AO40: 0
A41: Prior Year Retained Earnigs | B41: 22108664 | C41: 46919814 | D41: 46919814 | E41: 24114145 | F41: 24114145 | G41: 24114145 | H41: 24114145 | I41: 24114145 | J41: 24114145 | K41: 24114145 | L41: 24114145 | M41: 24114145 | N41: 23064003 | O41: 53208039 | P41: 31928093 | Q41: 31928093 | R41: 31928093 | S41: 31928093 | T41: 31928093 | U41: 31928093 | AA41: 26822653 | AB41: 56158710 | AC41: 26003107 | AD41: 26003107 | AE41: 26003107 | AF41: 26003107 | AG41: 26003107 | AH41: 26003107 | AI41: 26003107 | AJ41: 26003107 | AK41: 26003107 | AL41: 26003107 | AM41: 26003107 | AN41: 26003107 | AO41: 34949046
A42: Current Year Surplus | B42: =5414336-1082867-3376130 -> 955339 | C42: 3735002.2 | D42: 8390013.5 | E42: 8387848.5 | F42: 11070288 | G42: 13615720 | H42: 14614562 | I42: 16619334 | J42: 17388496 | K42: 27390330 | L42: 28214330 | M42: 29093894 | N42: =9113112-1822622-3593468 -> 3697022 | O42: 2070138.3 | P42: 2662456.1 | Q42: 4628497.3 | R42: 7780319.9 | S42: 9059006.3 | T42: 10266738 | U42: 12044780 | AA42: =2972569-594514+1231-3198832 -> -819546 | AB42: 4910659.6 | AC42: 8541350 | AD42: 11984242 | AE42: 16150659 | AF42: 20940282 | AG42: 25310555 | AH42: 35135870 | AI42: 35465582 | AJ42: 36645648 | AK42: 37116370 | AL42: 37456031 | AM42: 40935410 | AN42: 8607115 | AO42: 11664715
...

Sheet Evolutitve SCI
B2: AUDITED 2019 | C2: 43862 | D2: 43891 | E2: 43922 | F2: 43952 | G2: 43983 | H2: 44044 | I2: 44075 | J2: 44105 | K2: 44136 | L2: 44166 | M2: AUDITED 2020 | N2: 44197 | O2: 44228 | P2: 44256 | Q2: 44287 | R2: 44317 | S2: 44348 | T2: 44378 | U2: 44409 | V2: 44440 | W2: 44470 | X2: 44501 | Y2: 44531 | Z2: AUDITED 2021 | AA2: 44562 | AB2: 44593 | AC2: 44621 | AD2: 44652 | AE2: 44682 | AF2: 44713 | AG2: 44743 | AH2: 44774 | AI2: 44805 | AJ2: 44835 | AK2: 44866 | AL2: 44896 | AM2: Aud-2022
A3: Financial Income | B3: =B4+B7 -> 118115242 | C3: =C4+C7 -> 24737092 | D3: =D4+D7 -> 34809075 | E3: =E4+E7 -> 46481721 | F3: =F4+F7 -> 57155395 | G3: =G4+G7 -> 67416164 | H3: =H4+H7 -> 86865864 | I3: =I4+I7 -> 95604289 | ... AN3: =AN4+AN7 -> 91342636
A4: Financial Income From Loans Portfolio | B4: =SUM(B5:B6) -> 110721274 | C4: =SUM(C5:C6) -> 18910047 | D4: =SUM(D5:D6) -> 25956456 | E4: =SUM(E5:E6) -> 33369543 | F4: =SUM(F5:F6) -> 41645761 | G4: =SUM(G5:G6) -> 49283771 | H4: =SUM(H5:H6) -> 63345430 | I4: =SUM(I5:I6) -> 69206276 | ... AN4: =SUM(AN5:AN6) -> 55790908
A5: Interest from Loans Portfolio | B5: 98893476 | C5: 18580842 | D5: 25555836 | E5: 32939596 | F5: 41120484 | G5: 48690329 | H5: 62496293 | I5: 68281454 | J5: 77074369 | K5: 82047206 | L5: 87624938 | M5: =15116030+88911220 -> 104027250 | N5: 6896212 | O5: 13069919 | P5: 19598046 | Q5: 25928690 | R5: 31203282 | S5: 37389014 | T5: 43935383 | Z5: =80844263+15956673 -> 96800936 | AA5: 8712481 | AB5: 18178151 | AC5: 27450968 | AD5: 37534875 | AE5: 48008643 | AF5: 55621822 | AG5: 66252222 | AH5: 72353237 | AI5: 78203162 | AJ5: 83398787 | AK5: 88856447 | AL5: 98264175 | AM5: 114466828 | AN5: 54432858
A6: Fees&Commision on Loan Portfolio | B6: 11827798 | C6: 329205 | D6: 400620 | E6: 429947.04 | F6: 525277.04 | G6: 593442.04 | H6: 849137.04 | I6: 924822.04 | J6: 999347.04 | K6: 1109002 | L6: 1279542 | M6: 18499500 | N6: 166815 | O6: 371090 | P6: 469540 | Q6: 558862.5 | R6: 1048052.5 | S6: 1237992.5 | T6: 1426402.5 | Z6: =23273176+952600 -> 24225776 | AA6: 164480 | AB6: 267715 | AC6: 438750 | AD6: 646900 | AE6: 824650 | AF6: 896805 | AG6: 1012770 | AH6: 1190370 | AI6: 1435625 | AJ6: 1634185 | AK6: 1764905 | AL6: 1900375 | AM6: 24754505 | AN6: 1358050
A7: Financial Income from Investments | B7: =SUM(B8:B11) -> 7393968 | C7: =SUM(C8:C11) -> 5827044.4 | D7: =SUM(D8:D11) -> 8852619.6 | E7: =SUM(E8:E11) -> 13112178 | F7: =SUM(F8:F11) -> 15509634 | G7: =SUM(G8:G11) -> 18132393 | H7: =SUM(H8:H11) -> 23520434 | I7: =SUM(I8:I11) -> 26398013 | ... AN7: =SUM(AN8:AN11) -> 35551728
A8: Government Securities | B8: 0 | C8: 0 | D8: 0 | E8: 0 | F8: 0 | G8: 0 | H8: 0 | I8: 0 | J8: 0 | K8: 0 | L8: 0 | N8: 0 | O8: 0 | P8: 0 | Q8: 0 | R8: 0 | S8: 0 | T8: 0 | AA8: 0 | AB8: 0 | AC8: 0 | AD8: 0 | AE8: 0 | AF8: 0 | AG8: 0 | AH8: 0 | AI8: 0 | AJ8: 0 | AK8: 0 | AL8: 0 | AN8: 0
A9: Deposits with Banks & other Financial Institutions | B9: 5131404 | C9: 1542740 | D9: 1542740 | E9: 2190045 | F9: 2745661.9 | G9: 3314153.6 | H9: 4431917.2 | I9: 4997601.1 | J9: 5548129.5 | K9: 6154207.6 | L9: 7065770.9 | M9: 7065771 | N9: 943148.6 | O9: 1859037.7 | P9: 3035792 | Q9: 3894833.8 | R9: 4657451.5 | S9: 5373798.8 | T9: 6017478.2 | Z9: 8926445 | AA9: 674409.09 | AB9: 674409.09 | AC9: 1749555.5 | AD9: 1749555.5 | AE9: 2781363 | AF9: 3287227.5 | AG9: 3775612.9 | AH9: 4685841.3 | AI9: 5905720.6 | AJ9: 6944811.6 | AK9: 8241058.6 | AL9: 9178026.8 | AN9: 4667168.3
A10: Other Investments | B10: 2262564 | C10: 180042 | D10: 217881.45 | E10: 2480445 | F10: 2480445 | G10: 2480445 | H10: 2480445 | I10: 2480445 | J10: 2480445 | K10: 2660487 | L10: 2688816 | M10: 2688816 | N10: 0 | O10: 0 | P10: 0 | Q10: 2226841.3 | R10: 2237177.8 | S10: 2237177.8 | T10: 2238654.6 | Z10: 2256040 | AA10: 136832 | AB10: 138308.85 | AC10: 138308.85 | AD10: 138308.85 | AE10: 151259.25 | AF10: 2298073.5 | AG10: 2298073.5 | AH10: 2298073.5 | AI10: 2298073.5 | AJ10: 2313249.8 | AK10: 2313249.8 | AL10: 2814878.5 | AM10: 2480234.8 | AN10: 3239784
A11: Other Operating Income | C11: 4104262.4 | D11: 7091998.1 | E11: 8441688.2 | F11: 10283527 | G11: 12337795 | H11: 16608072 | I11: 18919967 | J11: 27927829 | K11: 30632685 | L11: 33622269 | N11: 2825732.3 | O11: 5550086.8 | P11: 9072347.8 | Q11: 12664008 | R11: 15930022 | S11: 18762601 | T11: 21891226 | AA11: 3070402.6 | AB11: 6041980.1 | AC11: 9218954 | AD11: 11576009 | AE11: 14050586 | AF11: 16914322 | AG11: 25830057 | AH11: 28751044 | AI11: 31809454 | AJ11: 34815509 | AK11: 38025703 | AL11: 39895584 | AM11: =838800+9178027 -> 10016827 | AN11: 27644776
A12: Financial Expenses | B12: =SUM(B13:B18) -> 21842490 | C12: =SUM(C13:C18) -> 0 | D12: =SUM(D13:D18) -> 0 | E12: =SUM(E13:E18) -> 0 | F12: =SUM(F13:F18) -> 0 | G12: =SUM(G13:G18) -> 0 | H12: =SUM(H13:H18) -> 0 | I12: =SUM(I13:I18) -> 0 | ... AN12: =SUM(AN13:AN18) -> 3270818.7
A13: Interest Expense on Deposits | B13: 15780840 | C13: 0 | D13: 0 | E13: 0 | F13: 0 | G13: 0 | H13: 0 | I13: 0 | J13: 0 | K13: 0 | L13: 0 | M13: 16089183 | N13: 0 | O13: 0 | P13: 0 | Q13: 0 | R13: 0 | S13: 0 | T13: 0 | Z13: =13501079+1636747 -> 15137826 | AA13: 0 | AB13: 0 | AC13: 0 | AD13: 0 | AE13: 0 | AF13: 0 | AG13: 0 | AH13: 0 | AI13: 0 | AJ13: 0 | AK13: 0 | AL13: 0 | AM13: 17192689 | AN13: 0
A14: Cost of External Borrowings | B14: 0 | C14: 0 | D14: 0 | E14: 0 | F14: 0 | G14: 0 | H14: 0 | I14: 0 | J14: 0 | K14: 0 | L14: 0 | AA14: 0 | AB14: 0 | AC14: 0 | AD14: 0 | AE14: 0 | AF14: 0 | AG14: 0 | AH14: 0 | AI14: 0 | AJ14: 0 | AK14: 0 | AL14: 0 | AN14: 0
A15: Dividend Expenses | B15: 0 | C15: 0 | D15: 0 | E15: 0 | F15: 0 | G15: 0 | H15: 0 | I15: 0 | J15: 0 | K15: 0 | L15: 0 | AA15: 0 | AB15: 0 | AC15: 0 | AD15: 0 | AE15: 0 | AF15: 0 | AG15: 0 | AH15: 0 | AI15: 0 | AJ15: 0 | AK15: 0 | AL15: 0 | AN15: 0
A16: Other Financial Expense | B16: 0 | C16: 0 | D16: 0 | E16: 0 | F16: 0 | G16: 0 | H16: 0 | I16: 0 | J16: 0 | K16: 0 | L16: 0 | Z16: =1571388 -> 1571388 | AA16: 0 | AB16: 0 | AC16: 0 | AD16: 0 | AE16: 0 | AF16: 0 | AG16: 0 | AH16: 0 | AI16: 4149041.5 | AJ16: 4458621.4 | AK16: 5382389.3 | AL16: 5669792.7 | AM16: 1656418 | AN16: 3270818.7
A17: Fees & Commision Expense | B17: 0 | C17: 0 | D17: 0 | E17: 0 | F17: 0 | G17: 0 | H17: 0 | I17: 0 | J17: 0 | K17: 0 | L17: 0 | AA17: 0 | AB17: 0 | AC17: 0 | AD17: 0 | AE17: 0 | AF17: 0 | AG17: 0 | AH17: 0 | AI17: 0 | AJ17: 0 | AK17: 0 | AL17: 0 | AN17: 0
A18: Other Expenses | B18: =4947098+1114552 -> 6061650 | C18: 0 | D18: 0 | E18: 0 | F18: 0 | G18: 0 | H18: 0 | I18: 0 | J18: 0 | K18: 0 | L18: 0 | M18: =5640788+729326 -> 6370114 | N18: 0 | O18: 0 | P18: 0 | Q18: 0 | R18: 0 | S18: 0 | T18: 0 | AA18: 0 | AB18: 0 | AC18: 0 | AD18: 0 | AE18: 0 | AF18: 0 | AG18: 0 | AH18: 0 | AI18: 0 | AJ18: 0 | AK18: 0 | AL18: 0 | AM18: 2158117 | AN18: 0
A19: Net Financial Income | B19: =B3-B12 -> 96272752 | C19: =C3-C12 -> 24737092 | D19: =D3-D12 -> 34809075 | E19: =E3-E12 -> 46481721 | F19: =F3-F12 -> 57155395 | G19: =G3-G12 -> 67416164 | H19: =H3-H12 -> 86865864 | I19: =I3-I12 -> 95604289 | ... AN19: =AN3-AN12 -> 88071817
A20: Allowance for Loan Loss | B20: =B21-B22 -> 600000 | C20: =C21-C22 -> 0 | D20: =D21-D22 -> 0 | E20: =E21-E22 -> 0 | F20: =F21-F22 -> 0 | G20: =G21-G22 -> 0 | H20: =H21-H22 -> 0 | I20: =I21-I22 -> 0 | ... AN20: =AN21-AN22 -> 400000
A21: Provision for Loan Losses | B21: 600000 | C21: 100000 | D21: 150000 | E21: 200000 | F21: 250000 | G21: 1414552 | H21: 1514552 | I21: 1564552 | J21: 1614552 | K21: 1664552 | L21: 1714552 | M21: 1714552 | N21: 50000 | O21: 100000 | P21: 150000 | Q21: 200000 | R21: 250000 | S21: 300000 | T21: 350000 | Z21: 600000 | AA21: 50000 | AB21: 100000 | AC21: 150000 | AD21: 200000 | AE21: 250000 | AF21: 300000 | AG21: 350000 | AH21: 400000 | AI21: 450000 | AJ21: 500000 | AK21: 550000 | AL21: 600000 | AM21: 600000 | AN21: 400000
A22: Value of Loans Recovered | B22: 0 | C22: 100000 | D22: 150000 | E22: 200000 | F22: 250000 | G22: 1414552 | H22: 1514552 | I22: 1564552 | J22: 1614552 | K22: 1664552 | L22: 1714552 | N22: 50000 | O22: 100000 | P22: 150000 | Q22: 200000 | R22: 250000 | S22: 300000 | T22: 350000 | AA22: 50000 | AB22: 100000 | AC22: 150000 | AD22: 200000 | AE22: 250000 | AF22: 300000 | AG22: 350000 | AH22: 400000 | AI22: 0 | AJ22: 0 | AK22: 0 | AL22: 0 | AN22: 0
A23: Operating Expeses | B23: =SUM(B24:B28) -> 88069006 | C23: =SUM(C24:C28) -> 27078036 | D23: =SUM(D24:D28) -> 42542742 | E23: =SUM(E24:E28) -> 56991417 | F23: =SUM(F24:F28) -> 70406675 | G23: =SUM(G24:G28) -> 84310189 | H23: =SUM(H24:H28) -> 1.1254434e+08 | I23: =SUM(I24:I28) -> 1.2562057e+08 | ... AN23: =SUM(AN24:AN28) -> 76007102
A24: Personel Expenses | B24: 54737957 | C24: 15557412 | D24: 24657242 | E24: 33178463 | F24: 40911852 | G24: 48700216 | H24: 65039484 | I24: 72717596 | J24: 80564396 | K24: 87639366 | L24: 95832103 | M24: 56759311 | N24: 8423424.4 | O24: 17400477 | P24: 26382036 | Q24: 35557501 | R24: 43605640 | S24: 52015569 | T24: 60427243 | Z24: 66747293 | AA24: 7420774.1 | AB24: 15877315 | AC24: 25765611 | AD24: 33758358 | AE24: 42627878 | AF24: 51094122 | AG24: 60522108 | AH24: 69568582 | AI24: 51720180 | AJ24: 57736174 | AK24: 63821286 | AL24: 69914688 | AM24: 69914688 | AN24: 50016815
A25: Governance Expenses | B25: 338700 | C25: 9162732 | D25: 14127756 | E25: 18999835 | F25: 23587827 | G25: 28508544 | H25: 38113399 | I25: 42461030 | J25: 47214030 | K25: 51689354 | L25: 56759311 | M25: 278700 | N25: 5543644.7 | O25: 11095153 | P25: 16444486 | Q25: 22268170 | R25: 27967597 | S25: 33740540 | T25: 39233719 | Z25: 255700 | AA25: 5470554.5 | AB25: 10951365 | AC25: 16483643 | AD25: 22479173 | AE25: 28344693 | AF25: 34406923 | AG25: 40295589 | AH25: 46143701 | AI25: 158500 | AJ25: 158500 | AK25: 158500 | AL25: 258700 | AM25: 258700 | AN25: 206200
A26: Marketing Expenses | B26: 3842531 | C26: 41400 | D26: 41400 | E26: 41400 | F26: 58000 | G26: 74600 | H26: 124400 | I26: 124400 | J26: 191900 | K26: 208500 | L26: 278700 | M26: 3770715 | N26: 19300 | O26: 38600 | P26: 100700 | Q26: 130800 | R26: 130800 | S26: 158200 | T26: 158200 | Z26: 4609186 | AA26: 0 | AB26: 0 | AC26: 75600 | AD26: 75600 | AE26: 75600 | AF26: 109300 | AG26: 133900 | AH26: 158500 | AI26: 3199231 | AJ26: 3435861 | AK26: 3719085 | AL26: 4137910 | AM26: 4137910 | AN26: 3666205
A27: Depreciation and Amortization | B27: 6437685 | C27: 965310 | D27: 1504660 | E27: 1706625 | F27: 1944515 | G27: 2270835 | H27: 2833895 | I27: 3046745 | J27: 3305555 | K27: 3480165 | L27: 3770715 | M27: 6391440 | N27: 459001 | O27: 1097691 | P27: 1499346 | Q27: 1844866 | R27: 2146166 | S27: 2444496 | T27: 3034956 | Z27: 8656068 | AA27: 500530 | AB27: 857340 | AC27: 1348070 | AD27: 1587230 | AE27: 1921460 | AF27: 2279180 | AG27: 2541270 | AH27: 2936520 | AI27: 5837841.2 | AJ27: 6486524.2 | AK27: 7126857.2 | AL27: 7759761.6 | AM27: 7759762 | AN27: 4905829.5
A28: Administrative Expenses | B28: 22712133 | C28: 1351182.6 | D28: 2211684.4 | E28: 3065093.4 | F28: 3904480.9 | G28: 4755993.7 | H28: 6433157.7 | I28: 7270802 | J28: 8102828.6 | K28: 8923182.4 | L28: 9734684.7 | M28: 25288692 | N28: 795290.85 | O28: 1577586.6 | P28: 2344283.8 | Q28: 3064324.3 | R28: 3777708.6 | S28: 4490201.8 | T28: 5193194.8 | Z28: 23954428 | AA28: 0 | AB28: 665796.98 | AC28: 1961640.3 | AD28: 2608347.7 | AE28: 3245577.3 | AF28: 3873688.7 | AG28: 4523537.1 | AH28: 5178531.4 | AI28: 17491593 | AJ28: 19214491 | AK28: 20987215 | AL28: 22776777 | AM28: 24632036 | AN28: 17212053
A29: Net Operating Income | B29: =B19-B20-B23 -> 7603746 | C29: =C19-C20-C23 -> -2340944.8 | D29: =D19-D20-D23 -> -7733666.9 | E29: =E19-E20-E23 -> -10509695 | F29: =F19-F20-F23 -> -13251279 | G29: =G19-G20-G23 -> -16894025 | H29: =H19-H20-H23 -> -25678472 | I29: =I19-I20-I23 -> -30016284 | ... AN29: =AN19-AN20-AN23 -> 11664715
A30: Net Non operating Income/Expense | B30: =B31-B32 -> 0 | C30: =C31-C32 -> 0 | D30: =D31-D32 -> 0 | E30: =E31-E32 -> 0 | F30: =F31-F32 -> 0 | G30: =G31-G32 -> 0 | H30: =H31-H32 -> 0 | I30: =I31-I32 -> 0 | ... AN30: =AN31-AN32 -> 0
A31: Non Operating Income | B31: 0 | C31: 0 | D31: 0 | E31: 0 | F31: 0 | G31: 0 | H31: 0 | I31: 0 | J31: 0 | K31: 0 | L31: 0 | N31: 0 | O31: 0 | P31: 0 | Q31: 0 | R31: 0 | S31: 0 | T31: 0 | AA31: 0 | AB31: 0 | AC31: 0 | AD31: 0 | AE31: 0 | AF31: 0 | AG31: 0 | AH31: 0 | AI31: 0 | AJ31: 0 | AK31: 0 | AL31: 0 | AM31: 0 | AN31: 0
A32: Non Operating Expense | B32: 0 | C32: 0 | D32: 0 | E32: 0 | F32: 0 | G32: 0 | H32: 0 | I32: 0 | J32: 0 | K32: 0 | L32: 0 | N32: 0 | O32: 0 | P32: 0 | Q32: 0 | R32: 0 | S32: 0 | T32: 0 | AA32: 0 | AB32: 0 | AC32: 0 | AD32: 0 | AE32: 0 | AF32: 0 | AG32: 0 | AH32: 0 | AI32: 0 | AJ32: 0 | AK32: 0 | AL32: 0 | AM32: 0 | AN32: 0
A33: Net Income(Before Tax & Donations) | B33: =B29+B30 -> 7603746 | C33: =C29+C30 -> -2340944.8 | D33: =D29+D30 -> -7733666.9 | E33: =E29+E30 -> -10509695 | F33: =F29+F30 -> -13251279 | G33: =G29+G30 -> -16894025 | H33: =H29+H30 -> -25678472 | I33: =I29+I30 -> -30016284 | ... AN33: =AN29+AN30 -> 11664715
A34: Taxes | B34: 2189409.6 | C34: 0 | D34: 0 | E34: 0 | F34: 0 | G34: 0 | H34: 0 | I34: 0 | J34: 0 | K34: 0 | L34: 0 | M34: 6505518 | N34: 0 | O34: 0 | P34: 0 | Q34: 0 | R34: 0 | S34: 0 | T34: 0 | Z34: 7704740 | AA34: 0 | AB34: 0 | AC34: 0 | AD34: 0 | AE34: 0 | AF34: 0 | AG34: 0 | AH34: 0 | AI34: 0 | AJ34: 0 | AK34: 0 | AL34: 0 | AM34: 7733076.8 | AN34: 0
A35: Net Income(After Tax Before Donations) | B35: =B33-B34 -> 5414336.4 | C35: =C33-C34 -> -2340944.8 | D35: =D33-D34 -> -7733666.9 | E35: =E33-E34 -> -10509695 | F35: =F33-F34 -> -13251279 | G35: =G33-G34 -> -16894025 | H35: =H33-H34 -> -25678472 | I35: =I33-I34 -> -30016284 | ... AN35: =AN33-AN34 -> 11664715
A36: Donations | B36: 0 | C36: 8390013.5 | D36: 8387848.5 | E36: 11070288 | F36: 13615720 | G36: 14614562 | H36: 16619334 | I36: 17388496 | J36: 27390330 | K36: 28214330 | L36: 29093894 | N36: 2070138.3 | O36: 2662456.1 | P36: 4628497.3 | Q36: 7780319.9 | R36: 9059006.3 | S36: 10266738 | T36: 12044780 | AA36: 4910659.6 | AB36: 8541350 | AC36: 11984242 | AD36: 16150659 | AE36: 20940282 | AF36: 25310555 | AG36: 35135870 | AH36: 35465582 | AI36: 0 | AJ36: 0 | AK36: 0 | AL36: 0 | AM36: 0 | AN36: 0
A37: Net Income/(After Tax & Donations) | B37: =B35-B36 -> 5414336.4 | C37: =C35-C36 -> -10730958 | D37: =D35-D36 -> -16121515 | E37: =E35-E36 -> -21579983 | F37: =F35-F36 -> -26867000 | G37: =G35-G36 -> -31508587 | H37: =H35-H36 -> -42297806 | I37: =I35-I36 -> -47404779 | ... AN37: =AN35-AN36 -> 11664715
A39: Total Expenses | B39: =B12+B23 -> 109911496 | C39: =C12+C23 -> 27078036 | D39: =D12+D23 -> 42542742 | E39: =E12+E23 -> 56991417 | F39: =F12+F23 -> 70406675 | G39: =G12+G23 -> 84310189 | H39: =H12+H23 -> 1.1254434e+08 | I39: =I12+I23 -> 1.2562057e+08 | ... Z39: =Z12+Z23 -> 120931889

Sheet FORM 4
D2: 43891
B3: CLASSIFICATION | C3: NO. OF A/Cs | D3: OUTSTANDING LOAN PORTFOLIO(Kshs) | E3: REQUIRED PROVISION | F3: REQUIRED PROVISION AMOUNT(Kshs)
B4: Performing | C4: 11812 | D4: 7.6526299e+09 | E4: 0.01 | F4: =D4*E4 -> 76526299
B5: Watch | C5: 3404 | D5: 2.188066e+09 | E5: 0.05 | F5: =D5*E5 -> 1.094033e+08
B6: Substandard | C6: 1506 | D6: 6.8259044e+08 | E6: 0.25 | F6: =D6*E6 -> 1.7064761e+08
B7: Doubtful | C7: 508 | D7: 1.4039815e+08 | E7: 0.5 | F7: =D7*E7 -> 70199075
B8: Loss | C8: 1206 | D8: 1.3261675e+08 | E8: 1 | F8: =D8*E8 -> 1.3261675e+08
B9: Sub-total | C9: =SUM(C4:C8) -> 18436 | D9: =SUM(D4:D8) -> 1.0796301e+10 | E9: 1.81 | F9: =SUM(F4:F8) -> 5.5939303e+08
C10: NPL | D10: =SUM(D6:D8) -> 9.5560534e+08
C11: PAR | D11: =D10/D9 -> 0.088512289
D14: 43983
B15: CLASSIFICATION | C15: NO. OF A/Cs | D15: OUTSTANDING LOAN PORTFOLIO(Kshs) | E15: REQUIRED PROVISION | F15: REQUIRED PROVISION AMOUNT(Kshs)
B16: Performing | C16: 5661 | D16: 3.5091131e+09 | E16: 0.01 | F16: =D16*E16 -> 35091131
B17: Watch | C17: 1712 | D17: 1.1514882e+09 | E17: 0.05 | F17: =D17*E17 -> 57574410 | H17: 11812
B18: Substandard | C18: 1187 | D18: 5.5435741e+08 | E18: 0.25 | F18: =D18*E18 -> 1.3858935e+08 | H18: 3404
B19: Doubtful | C19: 246 | D19: 62601627 | E19: 0.5 | F19: =D19*E19 -> 31300813 | H19: 1506
B20: Loss | C20: 670 | D20: 72780269 | E20: 1 | F20: =D20*E20 -> 72780269 | H20: 508
B21: Sub-total | C21: =SUM(C16:C20) -> 9476 | D21: =SUM(D16:D20) -> 5.3503406e+09 | E21: 1.81 | F21: =SUM(F16:F20) -> 3.3533598e+08 | H21: 1206
C22: NPL | D22: =SUM(D18:D20) -> 6.897393e+08 | H22: KIMISITU
C23: PAR | D23: =D22/D21 -> 0.12891503 | H23: 7.6526299e+09
H24: 2.188066e+09
H25: 6.8259044e+08
H26: 1.4039815e+08
D27: 44075 | H27: 1.3261675e+08
B28: CLASSIFICATION | C28: NO. OF A/Cs | D28: OUTSTANDING LOAN PORTFOLIO(Kshs) | E28: REQUIRED PROVISION | F28: REQUIRED PROVISION AMOUNT(Kshs)
B29: Performing | C29: 5914 | D29: 3.5082788e+09 | E29: 0.01 | F29: =D29*E29 -> 35082788
B30: Watch | C30: 2272 | D30: 1.3035993e+09 | E30: 0.05 | F30: =D30*E30 -> 65179965
B31: Substandard | C31: 1287 | D31: 6.4721095e+08 | E31: 0.25 | F31: =D31*E31 -> 1.6180274e+08
B32: Doubtful | C32: 210 | D32: 56010066 | E32: 0.5 | F32: =D32*E32 -> 28005033
B33: Loss | C33: 754 | D33: 80879265 | E33: 1 | F33: =D33*E33 -> 80879265
B34: Sub-total | C34: =SUM(C29:C33) -> 10437 | D34: =SUM(D29:D33) -> 5.5959784e+09 | E34: 1.81 | F34: =SUM(F29:F33) -> 3.7094979e+08
C35: NPL | D35: =SUM(D31:D33) -> 7.8410028e+08
C36: PAR | D36: =D35/D34 -> 0.14011853
D40: Aud-22
B41: CLASSIFICATION | C41: NO. OF A/Cs | D41: OUTSTANDING LOAN PORTFOLIO(Kshs) | E41: REQUIRED PROVISION | F41: REQUIRED PROVISION AMOUNT(Kshs)
B42: Performing | C42: 6819 | D42: 315571054 | E42: 0.01 | F42: =D42*E42 -> 3155710.5
B43: Watch | C43: 17 | D43: 8989799 | E43: 0.05 | F43: =D43*E43 -> 449489.95
B44: Substandard | C44: 12 | D44: 3165931 | E44: 0.25 | F44: =D44*E44 -> 791482.75
B45: Doubtful | C45: 7 | D45: 1084464 | E45: 0.5 | F45: =D45*E45 -> 542232
B46: Loss | C46: 27 | D46: 12340733 | E46: 1 | F46: =D46*E46 -> 12340733
...

Sheet CAELS
A1: VISION POINT SACCO 2022 CAELS
D2: 43831 | E2: 43862 | F2: 43891 | G2: 43922 | H2: 43952 | I2: 43983 | J2: 44013 | K2: 44044 | L2: 44075 | M2: 44105 | N2: 44136 | O2: 44166 | P2: Aud-2020 | Q2: 44197 | R2: 44228 | S2: 44256 | T2: 44287 | U2: 44317 | V2: 44348 | W2: 44378 | X2: 44409 | Y2: 44440 | Z2: 44470 | AA2: 44501 | AB2: 44531 | AC2: Aud- 2021 | AD2: 44562 | AE2: 44593 | AF2: 44621 | AG2: 44652 | AH2: 44682 | AI2: 44713 | AJ2: 44743 | AK2: 44774 | AL2: 44805 | AM2: 44835 | AN2: 44866 | AO2: 44896 | AP2: Aud-2022 | AQ2: 45161
A3: CAPITAL ADEQUACY | B3: Core Capital | C3: 10 M | D3: =(('Evolutive SFP'!C39+'Evolutive SFP'!C40+'Evolutive SFP'!C41+'Evolutive SFP'!C42+'Evolutive SFP'!C43+'Evolutive SFP'!C44)-'Evolutive SFP'!C10)/1000000 -> 123.94751 | E3: =(('Evolutive SFP'!D39+'Evolutive SFP'!D40+'Evolutive SFP'!D41+'Evolutive SFP'!D42+'Evolutive SFP'!D43+'Evolutive SFP'!D44)-'Evolutive SFP'!D10)/1000000 -> 128.83519 | F3: =(('Evolutive SFP'!E39+'Evolutive SFP'!E40+'Evolutive SFP'!E41+'Evolutive SFP'!E42+'Evolutive SFP'!E43+'Evolutive SFP'!E44)-'Evolutive SFP'!E10)/1000000 -> 107.26187 | G3: =(('Evolutive SFP'!F39+'Evolutive SFP'!F40+'Evolutive SFP'!F41+'Evolutive SFP'!F42+'Evolutive SFP'!F43+'Evolutive SFP'!F44)-'Evolutive SFP'!F10)/1000000 -> 110.15678 | H3: =(('Evolutive SFP'!G39+'Evolutive SFP'!G40+'Evolutive SFP'!G41+'Evolutive SFP'!G42+'Evolutive SFP'!G43+'Evolutive SFP'!G44)-'Evolutive SFP'!G10)/1000000 -> 112.86529 | I3: =(('Evolutive SFP'!H39+'Evolutive SFP'!H40+'Evolutive SFP'!H41+'Evolutive SFP'!H42+'Evolutive SFP'!H43+'Evolutive SFP'!H44)-'Evolutive SFP'!H10)/1000000 -> 114.20483 | J3: =(('Evolutive SFP'!I39+'Evolutive SFP'!I40+'Evolutive SFP'!I41+'Evolutive SFP'!I42+'Evolutive SFP'!I43+'Evolutive SFP'!I44)-'Evolutive SFP'!I10)/1000000 -> 116.48718 | K3: =(('Evolutive SFP'!J39+'Evolutive SFP'!J40+'Evolutive SFP'!J41+'Evolutive SFP'!J42+'Evolutive SFP'!J43+'Evolutive SFP'!J44)-'Evolutive SFP'!J10)/1000000 -> 117.418 | ... AC3: =(('Evolutive SFP'!AB39+'Evolutive SFP'!AB40+'Evolutive SFP'!AB41+'Evolutive SFP'!AB42+'Evolutive SFP'!AB43+'Evolutive SFP'!AB44)-'Evolutive SFP'!AB10)/1000000 -> 140.45366 | AD3: =(('Evolutive SFP'!AB39+'Evolutive SFP'!AB40+'Evolutive SFP'!AB41+'Evolutive SFP'!AB42+'Evolutive SFP'!AB43+'Evolutive SFP'!AB44)-'Evolutive SFP'!AB10)/1000000 -> 140.45366 | AE3: =(('Evolutive SFP'!AC39+'Evolutive SFP'!AC40+'Evolutive SFP'!AC41+'Evolutive SFP'!AC42+'Evolutive SFP'!AC43+'Evolutive SFP'!AC44)-'Evolutive SFP'!AC10)/1000000 -> 118.31273 | AF3: =(('Evolutive SFP'!AD39+'Evolutive SFP'!AD40+'Evolutive SFP'!AD41+'Evolutive SFP'!AD42+'Evolutive SFP'!AD43+'Evolutive SFP'!AD44)-'Evolutive SFP'!AD10)/1000000 -> 122.15647 | AG3: =(('Evolutive SFP'!AE39+'Evolutive SFP'!AE40+'Evolutive SFP'!AE41+'Evolutive SFP'!AE42+'Evolutive SFP'!AE43+'Evolutive SFP'!AE44)-'Evolutive SFP'!AE10)/1000000 -> 126.73093 | AH3: =(('Evolutive SFP'!AF39+'Evolutive SFP'!AF40+'Evolutive SFP'!AF41+'Evolutive SFP'!AF42+'Evolutive SFP'!AF43+'Evolutive SFP'!AF44)-'Evolutive SFP'!AF10)/1000000 -> 132.1432 | AI3: =(('Evolutive SFP'!AG39+'Evolutive SFP'!AG40+'Evolutive SFP'!AG41+'Evolutive SFP'!AG42+'Evolutive SFP'!AG43+'Evolutive SFP'!AG44)-'Evolutive SFP'!AG10)/1000000 -> 137.10552 | AJ3: =(('Evolutive SFP'!AH39+'Evolutive SFP'!AH40+'Evolutive SFP'!AH41+'Evolutive SFP'!AH42+'Evolutive SFP'!AH43+'Evolutive SFP'!AH44)-'Evolutive SFP'!AH10)/1000000 -> 147.39171 | AK3: =(('Evolutive SFP'!AI39+'Evolutive SFP'!AI40+'Evolutive SFP'!AI41+'Evolutive SFP'!AI42+'Evolutive SFP'!AI43+'Evolutive SFP'!AI44)-'Evolutive SFP'!AI10)/1000000 -> 148.12951 | ... AQ3: =(('Evolutive SFP'!AO39+'Evolutive SFP'!AO40+'Evolutive SFP'!AO41+'Evolutive SFP'!AO42+'Evolutive SFP'!AO43+'Evolutive SFP'!AO44)-'Evolutive SFP'!AO10)/1000000 -> 149.45036
B4: CCA | C4: Min 10% | D4: =D3/(('Evolutive SFP'!C27)/1000000) -> 0.24371857 | E4: =E3/(('Evolutive SFP'!D27)/1000000) -> 0.26757183 | F4: =F3/(('Evolutive SFP'!E27)/1000000) -> 0.22238938 | G4: =G3/(('Evolutive SFP'!F27)/1000000) -> 0.22303537 | H4: =H3/(('Evolutive SFP'!G27)/1000000) -> 0.23122357 | I4: =I3/(('Evolutive SFP'!H27)/1000000) -> 0.21687131 | J4: =J3/(('Evolutive SFP'!I27)/1000000) -> 0.24668384 | K4: =K3/(('Evolutive SFP'!J27)/1000000) -> 0.24227928 | ... AC4: =AC3/(('Evolutive SFP'!AB27)/1000000) -> 0.24711276 | AD4: =AD3/(('Evolutive SFP'!AB27)/1000000) -> 0.24711276 | AE4: =AE3/(('Evolutive SFP'!AC27)/1000000) -> 0.20847017 | AF4: =AF3/(('Evolutive SFP'!AD27)/1000000) -> 0.22333566 | AG4: =AG3/(('Evolutive SFP'!AE27)/1000000) -> 0.22620294 | AH4: =AH3/(('Evolutive SFP'!AF27)/1000000) -> 0.23116069 | AI4: =AI3/(('Evolutive SFP'!AG27)/1000000) -> 0.24366901 | AJ4: =AJ3/(('Evolutive SFP'!AH27)/1000000) -> 0.21054968 | AK4: =AK3/(('Evolutive SFP'!AI27)/1000000) -> 0.23129743 | ... AQ4: =AQ3/(('Evolutive SFP'!AO27)/1000000) -> 0.25449788
B5: CCD | C5: Min 8% | D5: =D3/('Evolutive SFP'!C31/1000000) -> 0.33338937 | E5: =E3/('Evolutive SFP'!D31/1000000) -> 0.3555445 | F5: =F3/('Evolutive SFP'!E31/1000000) -> 0.30192266 | G5: =G3/('Evolutive SFP'!F31/1000000) -> 0.30288257 | H5: =H3/('Evolutive SFP'!G31/1000000) -> 0.3146199 | I5: =I3/('Evolutive SFP'!H31/1000000) -> 0.30404766 | J5: =J3/('Evolutive SFP'!I31/1000000) -> 0.3212732 | K5: =K3/('Evolutive SFP'!J31/1000000) -> 0.31174221 | ... AC5: =AC3/('Evolutive SFP'!AB31/1000000) -> 0.3435424 | AD5: =AD3/('Evolutive SFP'!AB31/1000000) -> 0.3435424 | AE5: =AE3/('Evolutive SFP'!AC31/1000000) -> 0.28888118 | AF5: =AF3/('Evolutive SFP'!AD31/1000000) -> 0.3059714 | AG5: =AG3/('Evolutive SFP'!AE31/1000000) -> 0.30811533 | AH5: =AH3/('Evolutive SFP'!AF31/1000000) -> 0.31493437 | AI5: =AI3/('Evolutive SFP'!AG31/1000000) -> 0.33944329 | AJ5: =AJ3/('Evolutive SFP'!AH31/1000000) -> 0.28366747 | AK5: =AK3/('Evolutive SFP'!AI31/1000000) -> 0.31776296 | ... AQ5: =AQ3/('Evolutive SFP'!AO31/1000000) -> 0.35611529
B6: ICA | C6: Min 8% | D6: =((D3*1000000)-'Evolutive SFP'!C39)/'Evolutive SFP'!C27 -> 0.17698528 | E6: =((E3*1000000)-'Evolutive SFP'!D39)/'Evolutive SFP'!D27 -> 0.19673925 | F6: =((F3*1000000)-'Evolutive SFP'!E39)/'Evolutive SFP'!E27 -> 0.15136911 | G6: =((G3*1000000)-'Evolutive SFP'!F39)/'Evolutive SFP'!F27 -> 0.15325338 | H6: =((H3*1000000)-'Evolutive SFP'!G39)/'Evolutive SFP'!G27 -> 0.16029227 | I6: =((I3*1000000)-'Evolutive SFP'!H39)/'Evolutive SFP'!H27 -> 0.15048316 | J6: =((J3*1000000)-'Evolutive SFP'!I39)/'Evolutive SFP'!I27 -> 0.17208737 | K6: =((K3*1000000)-'Evolutive SFP'!J39)/'Evolutive SFP'!J27 -> 0.16927033 | ... AC6: =((AC3*1000000)-'Evolutive SFP'!AB39)/'Evolutive SFP'!AB27 -> 0.17618246 | AD6: =((AD3*1000000)-'Evolutive SFP'!AB39)/'Evolutive SFP'!AB27 -> 0.17618246 | AE6: =((AE3*1000000)-'Evolutive SFP'!AC39)/'Evolutive SFP'!AC27 -> 0.13678419 | AF6: =((AF3*1000000)-'Evolutive SFP'!AD39)/'Evolutive SFP'!AD27 -> 0.14823787 | AG6: =((AG3*1000000)-'Evolutive SFP'!AE39)/'Evolutive SFP'!AE27 -> 0.15217465 | AH6: =((AH3*1000000)-'Evolutive SFP'!AF39)/'Evolutive SFP'!AF27 -> 0.15753765 | AI6: =((AI3*1000000)-'Evolutive SFP'!AG39)/'Evolutive SFP'!AG27 -> 0.16782494 | AJ6: =((AJ3*1000000)-'Evolutive SFP'!AH39)/'Evolutive SFP'!AH27 -> 0.14893672 | AK6: =((AK3*1000000)-'Evolutive SFP'!AI39)/'Evolutive SFP'!AI27 -> 0.16332549 | ... AQ6: =((AQ3*1000000)-'Evolutive SFP'!AO39)/'Evolutive SFP'!AO27 -> 0.17051233
A7: ASSET QUALITY | B7: A/LNPL30
B8: NPL30 | D8: =('FORM 4'!#REF!+'FORM 4'!#REF!+'FORM 4'!#REF!)/'Evolutive SFP'!C15 -> #REF! | E8: =('FORM 4'!#REF!+'FORM 4'!#REF!+'FORM 4'!#REF!)/'Evolutive SFP'!D15 -> #REF! | F8: =('FORM 4'!#REF!+'FORM 4'!#REF!+'FORM 4'!#REF!)/'Evolutive SFP'!E15 -> #REF! | G8: =('FORM 4'!#REF!+'FORM 4'!#REF!+'FORM 4'!#REF!)/'Evolutive SFP'!F15 -> #REF! | H8: =('FORM 4'!#REF!+'FORM 4'!#REF!+'FORM 4'!#REF!)/'Evolutive SFP'!G15 -> #REF! | I8: =('FORM 4'!#REF!+'FORM 4'!#REF!+'FORM 4'!#REF!)/'Evolutive SFP'!H15 -> #REF! | J8: =('FORM 4'!#REF!+'FORM 4'!#REF!+'FORM 4'!#REF!)/'Evolutive SFP'!#REF! -> #REF! | K8: =('FORM 4'!#REF!+'FORM 4'!#REF!+'FORM 4'!#REF!)/'Evolutive SFP'!I15 -> #REF! | L8: =('FORM 4'!#REF!+'FORM 4'!#REF!+'FORM 4'!#REF!)/'Evolutive SFP'!J15 -> #REF! | AP8: 0.048 | AQ8: 1.048
A9: EARNINGS | B9: ROA | D9: ='Evolutitve SCI'!#REF!/(('Evolutive SFP'!#REF!+'Evolutive SFP'!C27)/2) -> #REF! | E9: ='Evolutitve SCI'!C33/(('Evolutive SFP'!C27+'Evolutive SFP'!D27)/2) -> -0.0047288673 | F9: ='Evolutitve SCI'!D33/(('Evolutive SFP'!D27+'Evolutive SFP'!E27)/2) -> -0.016048062 | G9: ='Evolutitve SCI'!E33/(('Evolutive SFP'!E27+'Evolutive SFP'!F27)/2) -> -0.021531543 | H9: ='Evolutitve SCI'!F33/(('Evolutive SFP'!F27+'Evolutive SFP'!G27)/2) -> -0.026987795 | I9: ='Evolutitve SCI'!G33/(('Evolutive SFP'!G27+'Evolutive SFP'!H27)/2) -> -0.033297782 | J9: ='Evolutitve SCI'!H33/(('Evolutive SFP'!H27+'Evolutive SFP'!I27)/2) -> -0.051417912 | K9: ='Evolutitve SCI'!I33/(('Evolutive SFP'!I27+'Evolutive SFP'!J27)/2) -> -0.062739692 | L9: ='Evolutitve SCI'!J33/(('Evolutive SFP'!J27+'Evolutive SFP'!K27)/2) -> -0.043000646 | ... AC9: ='Evolutitve SCI'!AA33/(('Evolutive SFP'!AA27+'Evolutive SFP'!AB27)/2) -> -0.001125343 | AD9: ='Evolutitve SCI'!AA33/(('Evolutive SFP'!AA27+'Evolutive SFP'!AB27)/2) -> -0.001125343 | AE9: ='Evolutitve SCI'!AB33/(('Evolutive SFP'!AB27+'Evolutive SFP'!AC27)/2) -> -0.0053723638 | AF9: ='Evolutitve SCI'!AC33/(('Evolutive SFP'!AC27+'Evolutive SFP'!AD27)/2) -> -0.011912204 | AG9: ='Evolutitve SCI'!AD33/(('Evolutive SFP'!AD27+'Evolutive SFP'!AE27)/2) -> -0.01600962 | AH9: ='Evolutitve SCI'!AE33/(('Evolutive SFP'!AE27+'Evolutive SFP'!AF27)/2) -> -0.018373829 | AI9: ='Evolutitve SCI'!AF33/(('Evolutive SFP'!AF27+'Evolutive SFP'!AG27)/2) -> -0.022471509 | AJ9: ='Evolutitve SCI'!AG33/(('Evolutive SFP'!AG27+'Evolutive SFP'!AH27)/2) -> -0.014013843 | AK9: ='Evolutitve SCI'!AH33/(('Evolutive SFP'!AH27+'Evolutive SFP'!AI27)/2) -> -0.021943589 | ... AQ9: ='Evolutitve SCI'!AN33/(('Evolutive SFP'!AN27+'Evolutive SFP'!AO27)/2) -> 0.019670838
B10: Cost Income ratio | D10: ='Evolutitve SCI'!#REF!/'Evolutitve SCI'!#REF! -> #REF! | E10: ='Evolutitve SCI'!C23/'Evolutitve SCI'!C19 -> 1.094633 | F10: ='Evolutitve SCI'!D23/'Evolutitve SCI'!D19 -> 1.2221739 | G10: ='Evolutitve SCI'!E23/'Evolutitve SCI'!E19 -> 1.2261038 | H10: ='Evolutitve SCI'!F23/'Evolutitve SCI'!F19 -> 1.2318465 | I10: ='Evolutitve SCI'!G23/'Evolutitve SCI'!G19 -> 1.2505931 | J10: ='Evolutitve SCI'!H23/'Evolutitve SCI'!H19 -> 1.2956106 | K10: ='Evolutitve SCI'!I23/'Evolutitve SCI'!I19 -> 1.3139638 | L10: ='Evolutitve SCI'!J23/'Evolutitve SCI'!J19 -> 1.2222973 | ... AC10: ='Evolutitve SCI'!AA23/'Evolutitve SCI'!AA19 -> 1.0496335 | AD10: ='Evolutitve SCI'!AA23/'Evolutitve SCI'!AA19 -> 1.0496335 | AE10: ='Evolutitve SCI'!AB23/'Evolutitve SCI'!AB19 -> 1.1206002 | AF10: ='Evolutitve SCI'!AC23/'Evolutitve SCI'!AC19 -> 1.170221 | AG10: ='Evolutitve SCI'!AD23/'Evolutitve SCI'!AD19 -> 1.1716129 | AH10: ='Evolutitve SCI'!AE23/'Evolutitve SCI'!AE19 -> 1.1579954 | AI10: ='Evolutitve SCI'!AF23/'Evolutitve SCI'!AF19 -> 1.1612914 | AJ10: ='Evolutitve SCI'!AG23/'Evolutitve SCI'!AG19 -> 1.0892183 | AK10: ='Evolutitve SCI'!AH23/'Evolutitve SCI'!AH19 -> 1.1345851 | ... AQ10: ='Evolutitve SCI'!AN23/'Evolutitve SCI'!AN19 -> 0.86301276
B11: Operating Expense ratio | D11: =('Evolutitve SCI'!#REF!+'Evolutitve SCI'!#REF!)/(('Evolutive SFP'!C27+'Evolutive SFP'!E27)/2) -> #REF! | E11: =('Evolutitve SCI'!C23+'Evolutitve SCI'!C12)/(('Evolutive SFP'!D27+'Evolutive SFP'!F27)/2) -> 0.055522149 | F11: =('Evolutitve SCI'!D23+'Evolutitve SCI'!D12)/(('Evolutive SFP'!E27+'Evolutive SFP'!G27)/2) -> 0.087677448 | G11: =('Evolutitve SCI'!E23+'Evolutitve SCI'!E12)/(('Evolutive SFP'!F27+'Evolutive SFP'!H27)/2) -> 0.11169312 | H11: =('Evolutitve SCI'!F23+'Evolutitve SCI'!F12)/(('Evolutive SFP'!G27+'Evolutive SFP'!I27)/2) -> 0.14662951 | I11: =('Evolutitve SCI'!G23+'Evolutitve SCI'!G12)/(('Evolutive SFP'!H27+'Evolutive SFP'!J27)/2) -> 0.16674601 | J11: =('Evolutitve SCI'!H23+'Evolutitve SCI'!H12)/(('Evolutive SFP'!I27+'Evolutive SFP'!K27)/2) -> 0.19295081 | K11: =('Evolutitve SCI'!I23+'Evolutitve SCI'!I12)/(('Evolutive SFP'!J27+'Evolutive SFP'!L27)/2) -> 0.23812018 | L11: =('Evolutitve SCI'!J23+'Evolutitve SCI'!J12)/(('Evolutive SFP'!K27+'Evolutive SFP'!M27)/2) -> 0.22890876 | ... Z11: =('Evolutitve SCI'!X23+'Evolutitve SCI'!X12)/(('Evolutive SFP'!Y27+'Evolutive SFP'!AA27)/2) -> 0 | AA11: =('Evolutitve SCI'!Y23+'Evolutitve SCI'!Y12)/(('Evolutive SFP'!Z27+'Evolutive SFP'!AB28)/2) -> 0 | AB11: =('Evolutitve SCI'!Z23+'Evolutitve SCI'!Z12)/(('Evolutive SFP'!AA27+'Evolutive SFP'!AC28)/2) -> 0.31471271 | AC11: =('Evolutitve SCI'!AA23+'Evolutitve SCI'!AA12)/(('Evolutive SFP'!AB27+'Evolutive SFP'!AD28)/2) -> 0.034778225 | AD11: =('Evolutitve SCI'!AA23+'Evolutitve SCI'!AA12)/(('Evolutive SFP'!AB27+'Evolutive SFP'!AD28)/2) -> 0.034778225 | AE11: =('Evolutitve SCI'!AB23+'Evolutitve SCI'!AB12)/(('Evolutive SFP'!AC27+'Evolutive SFP'!AE28)/2) -> 0.071888314 | AF11: =('Evolutitve SCI'!AC23+'Evolutitve SCI'!AC12)/(('Evolutive SFP'!AD27+'Evolutive SFP'!AF28)/2) -> 0.11931478 | AG11: =('Evolutitve SCI'!AD23+'Evolutitve SCI'!AD12)/(('Evolutive SFP'!AE27+'Evolutive SFP'!AG28)/2) -> 0.158497 | AH11: =('Evolutitve SCI'!AE23+'Evolutitve SCI'!AE12)/(('Evolutive SFP'!AF27+'Evolutive SFP'!AH28)/2) -> 0.17113607 | AI11: =('Evolutitve SCI'!AF23+'Evolutitve SCI'!AF12)/(('Evolutive SFP'!AG27+'Evolutive SFP'!AI28)/2) -> 0.22198597 | AJ11: =('Evolutitve SCI'!AG23+'Evolutitve SCI'!AG12)/(('Evolutive SFP'!AH27+'Evolutive SFP'!AJ28)/2) -> 0.2287109 | AK11: =('Evolutitve SCI'!AH23+'Evolutitve SCI'!AH12)/(('Evolutive SFP'!AI27+'Evolutive SFP'!AK28)/2) -> 0.27991865 | ... AQ11: =('Evolutitve SCI'!AN23+'Evolutitve SCI'!AN12)/(('Evolutive SFP'!AO27+'Evolutive SFP'!AQ28)/2) -> 0.27000353
A12: LIQUIDITY | B12: MIN LIQ ratio | C12: Min 15% | D12: =('Evolutive SFP'!C4)/('Evolutive SFP'!C28+'Evolutive SFP'!C29+'Evolutive SFP'!C32+'Evolutive SFP'!C33+'Evolutive SFP'!C34+'Evolutive SFP'!C35+'Evolutive SFP'!C36) -> 0.66711125 | E12: =('Evolutive SFP'!D4)/('Evolutive SFP'!D28+'Evolutive SFP'!D29+'Evolutive SFP'!D32+'Evolutive SFP'!D33+'Evolutive SFP'!D34+'Evolutive SFP'!D35+'Evolutive SFP'!D36) -> 0.65647431 | F12: =('Evolutive SFP'!E4)/('Evolutive SFP'!E28+'Evolutive SFP'!E29+'Evolutive SFP'!E32+'Evolutive SFP'!E33+'Evolutive SFP'!E34+'Evolutive SFP'!E35+'Evolutive SFP'!E36) -> 0.62443451 | G12: =('Evolutive SFP'!F4)/('Evolutive SFP'!F28+'Evolutive SFP'!F29+'Evolutive SFP'!F32+'Evolutive SFP'!F33+'Evolutive SFP'!F34+'Evolutive SFP'!F35+'Evolutive SFP'!F36) -> 0.6530101 | H12: =('Evolutive SFP'!G4)/('Evolutive SFP'!G28+'Evolutive SFP'!G29+'Evolutive SFP'!G32+'Evolutive SFP'!G33+'Evolutive SFP'!G34+'Evolutive SFP'!G35+'Evolutive SFP'!G36) -> 0.65388236 | I12: =('Evolutive SFP'!H4)/('Evolutive SFP'!H28+'Evolutive SFP'!H29+'Evolutive SFP'!H32+'Evolutive SFP'!H33+'Evolutive SFP'!H34+'Evolutive SFP'!H35+'Evolutive SFP'!H36) -> 0.6651014 | J12: =('Evolutive SFP'!I4)/('Evolutive SFP'!I28+'Evolutive SFP'!I29+'Evolutive SFP'!I32+'Evolutive SFP'!I33+'Evolutive SFP'!I34+'Evolutive SFP'!I35+'Evolutive SFP'!I36) -> 0.60743405 | K12: =('Evolutive SFP'!J4)/('Evolutive SFP'!J28+'Evolutive SFP'!J29+'Evolutive SFP'!J32+'Evolutive SFP'!J33+'Evolutive SFP'!J34+'Evolutive SFP'!J35+'Evolutive SFP'!J36) -> 0.60897671 | ... AC12: =('Evolutive SFP'!AB4)/('Evolutive SFP'!AB28+'Evolutive SFP'!AB29+'Evolutive SFP'!AB32+'Evolutive SFP'!AB33+'Evolutive SFP'!AB34+'Evolutive SFP'!AB35+'Evolutive SFP'!AB36) -> 0.44599817 | AD12: =('Evolutive SFP'!AB4)/('Evolutive SFP'!AB28+'Evolutive SFP'!AB29+'Evolutive SFP'!AB32+'Evolutive SFP'!AB33+'Evolutive SFP'!AB34+'Evolutive SFP'!AB35+'Evolutive SFP'!AB36) -> 0.44599817 | AE12: =('Evolutive SFP'!AC4)/('Evolutive SFP'!AC28+'Evolutive SFP'!AC29+'Evolutive SFP'!AC32+'Evolutive SFP'!AC33+'Evolutive SFP'!AC34+'Evolutive SFP'!AC35+'Evolutive SFP'!AC36) -> 0.4464412 | AF12: =('Evolutive SFP'!AD4)/('Evolutive SFP'!AD28+'Evolutive SFP'!AD29+'Evolutive SFP'!AD32+'Evolutive SFP'!AD33+'Evolutive SFP'!AD34+'Evolutive SFP'!AD35+'Evolutive SFP'!AD36) -> 0.4385879 | AG12: =('Evolutive SFP'!AE4)/('Evolutive SFP'!AE28+'Evolutive SFP'!AE29+'Evolutive SFP'!AE32+'Evolutive SFP'!AE33+'Evolutive SFP'!AE34+'Evolutive SFP'!AE35+'Evolutive SFP'!AE36) -> 0.45500038 | AH12: =('Evolutive SFP'!AF4)/('Evolutive SFP'!AF28+'Evolutive SFP'!AF29+'Evolutive SFP'!AF32+'Evolutive SFP'!AF33+'Evolutive SFP'!AF34+'Evolutive SFP'!AF35+'Evolutive SFP'!AF36) -> 0.4393051 | AI12: =('Evolutive SFP'!AG4)/('Evolutive SFP'!AG28+'Evolutive SFP'!AG29+'Evolutive SFP'!AG32+'Evolutive SFP'!AG33+'Evolutive SFP'!AG34+'Evolutive SFP'!AG35+'Evolutive SFP'!AG36) -> 0.49312998 | AJ12: =('Evolutive SFP'!AH4)/('Evolutive SFP'!AH28+'Evolutive SFP'!AH29+'Evolutive SFP'!AH32+'Evolutive SFP'!AH33+'Evolutive SFP'!AH34+'Evolutive SFP'!AH35+'Evolutive SFP'!AH36) -> 0.73160217 | AK12: =('Evolutive SFP'!AI4)/('Evolutive SFP'!AI28+'Evolutive SFP'!AI29+'Evolutive SFP'!AI32+'Evolutive SFP'!AI33+'Evolutive SFP'!AI34+'Evolutive SFP'!AI35+'Evolutive SFP'!AI36) -> 0.67712832 | ... AQ12: =('Evolutive SFP'!AO4)/('Evolutive SFP'!AO28+'Evolutive SFP'!AO29+'Evolutive SFP'!AO32+'Evolutive SFP'!AO33+'Evolutive SFP'!AO34+'Evolutive SFP'!AO35+'Evolutive SFP'!AO36) -> 0.62062854
B13: T/LIQ ratio | D13: ='Evolutive SFP'!C4/('Evolutive SFP'!C31+'Evolutive SFP'!C36) -> 0.4195777 | E13: ='Evolutive SFP'!D4/('Evolutive SFP'!D31+'Evolutive SFP'!D36) -> 0.40080983 | F13: ='Evolutive SFP'!E4/('Evolutive SFP'!E31+'Evolutive SFP'!E36) -> 0.41098467 | G13: ='Evolutive SFP'!F4/('Evolutive SFP'!F31+'Evolutive SFP'!F36) -> 0.41937016 | H13: ='Evolutive SFP'!G4/('Evolutive SFP'!G31+'Evolutive SFP'!G36) -> 0.41228467 | I13: ='Evolutive SFP'!H4/('Evolutive SFP'!H31+'Evolutive SFP'!H36) -> 0.44209005 | J13: ='Evolutive SFP'!I4/('Evolutive SFP'!I31+'Evolutive SFP'!I36) -> 0.37341614 | K13: ='Evolutive SFP'!J4/('Evolutive SFP'!J31+'Evolutive SFP'!J36) -> 0.37533517 | ... AC13: ='Evolutive SFP'!AB4/('Evolutive SFP'!AB31+'Evolutive SFP'!AB36) -> 0.27131159 | AD13: ='Evolutive SFP'!AB4/('Evolutive SFP'!AB31+'Evolutive SFP'!AB36) -> 0.27131159 | AE13: ='Evolutive SFP'!AC4/('Evolutive SFP'!AC31+'Evolutive SFP'!AC36) -> 0.28870654 | AF13: ='Evolutive SFP'!AD4/('Evolutive SFP'!AD31+'Evolutive SFP'!AD36) -> 0.26879511 | AG13: ='Evolutive SFP'!AE4/('Evolutive SFP'!AE31+'Evolutive SFP'!AE36) -> 0.28124452 | AH13: ='Evolutive SFP'!AF4/('Evolutive SFP'!AF31+'Evolutive SFP'!AF36) -> 0.27090117 | AI13: ='Evolutive SFP'!AG4/('Evolutive SFP'!AG31+'Evolutive SFP'!AG36) -> 0.29790764 | AJ13: ='Evolutive SFP'!AH4/('Evolutive SFP'!AH31+'Evolutive SFP'!AH36) -> 0.50794183 | AK13: ='Evolutive SFP'!AI4/('Evolutive SFP'!AI31+'Evolutive SFP'!AI36) -> 0.44462196 | ... AQ13: ='Evolutive SFP'!AO4/('Evolutive SFP'!AO31+'Evolutive SFP'!AO36) -> 0.37312001
