Workbook

Sheet Sheet2
D17: =30329098+16329321+2788735 -> 49447154

Sheet statement of deposit

Sheet STATEMENT OF FINANCIAL POSITION
B1: FORM 6 SASRA2/006
B2: STATEMENT OF FINANCIAL POSITION
B3: NAME OF SACCO SOCIETY: YETU
B4: FINANCIAL YEAR : 2017
B5: START DATE: 1st January 2017
B6: END DATE: 31st December 2017
C7: 2010 | D7: 2011 Audited | E7: 2012 audited | F7: 2013 AUDITED | G7: 2014 AUDITED | H7: AUDITED 2015 | I7: AUDITED 2016 | J7: 42736 | K7: 42767 | L7: 42795 | M7: 42826 | N7: 42856 | O7: 42887 | P7: 42917 | Q7: 42948 | R7: 42979 | S7: 43009 | T7: 43040 | U7: 43070 | V7: AUDITED 2017 | W7: AUDITED 2019 | X7: Dcember 2020 | Y7: AUDITED 2020 | Z7: 44197 | AA7: 44228 | AB7: 44256 | AC7: 44287 | AD7: 44317 | AE7: 44348 | AF7: 44378 | AG7: 44409 | AH7: 44440 | AI7: 44470 | AJ7: 44501 | AK7: 44531 | AL7: Audited 2021 | AM7: 44562 | AN7: 44593 | AO7: 44621 | AP7: 44652 | AQ7: 44682 | AR7: 44713 | AS7: 44743 | AT7: 44774 | AU7: 44805 | AV7: 44835 | AW7: 44866 | AX7: 44896 | AY7: Audited 2022 | AZ7: 44927 | BA7: 44958 | BB7: 44986 | BC7: 45017 | BD7: 45047 | BE7: 45078 | BF7: 45108
A9: Ref No | B9: ASSETS
A10: 1 | B10: Cash & Cash Equivalent | C10: =SUM(C11:C12) -> 169242912 | D10: =SUM(D11:D12) -> 257607037 | E10: =SUM(E11:E12) -> 266034639 | F10: =SUM(F11:F12) -> 396472718 | G10: =SUM(G11:G12) -> 407827391 | H10: =SUM(H11:H12) -> 624424540 | I10: =SUM(I11:I12) -> 420746946 | J10: =SUM(J11:J12) -> 7.2882087e+08 | ... BF10: =SUM(BF11:BF12) -> 1.1457232e+09
A11: 1.1 | B11: Cash in hand(both local and foreign notes and coins) | C11: 5659875 | D11: =257607037-179690522 -> 77916515 | E11: 15117143 | F11: ='[1]10,11,12,13'!$G$43 -> 11530858 | G11: =15905344+1100000+38820+641399+1424491 -> 19110054 | H11: =19214131+1300000+68799+807651+4505344 -> 25895925 | I11: =31664084+4550000+31779+677410+4358010 -> 41281283 | J11: 27605410 | K11: 45114693 | L11: 35947494 | M11: 29188907 | N11: 49471932 | O11: 36007322 | P11: 38435553 | Q11: 29323247 | R11: 40994679 | S11: 42150848 | T11: 55282901 | U11: 45283542 | V11: =40309430+6350000+24439+612009+5722240 -> 53018118 | W11: 41378132 | X11: 37200001 | Y11: =30730467+6450000+206308+515714+5969837+1245573+357487 -> 45475386 | Z11: 28426642 | AA11: 36369510 | AB11: 43235335 | AC11: 42456784 | AD11: 41511498 | AE11: 47226217 | AF11: 36157295 | AG11: 38964562 | AH11: 44352302 | AI11: 48985175 | AJ11: 44484659 | AK11: 4.1337802e+08 | AL11: 64478697 | AM11: 47013157 | AN11: 39791215 | AO11: 42336935 | AP11: 39488722 | AQ11: 40859612 | AR11: 42016946 | AS11: 54794824 | AT11: 35184439 | AU11: 46653739 | AV11: 46813083 | AW11: 53790313 | AX11: 46306289 | AY11: 38940535 | AZ11: 54834000 | BA11: 50877124 | BB11: 56270558 | BC11: 45060785 | BD11: 35975675 | BE11: 43436919 | BF11: 52624586
A12: 1.2 | B12: Cash at bank:(placement with financial institutions) | C12: =169242912-5659875 -> 163583037 | D12: =179690522 -> 179690522 | E12: =266034639-E11 -> 250917496 | F12: ='[1]10,11,12,13'!$G$48-'[1]10,11,12,13'!$G$43 -> 384941860 | G12: =205741791+1064890+181910656 -> 388717337 | H12: =11945236+110843+127304+3146057+295099840+6600000+30462654+2539604+2155811+500000+1217444+1057790+210467402+32101630+997000 -> 598528615 | I12: =979604+111028+127516+279762+340000000+7800000+16909887+7733190-140320+500000+20000+1057206+4087790 -> 379465663 | J12: 7.0121546e+08 | K12: 5.9891297e+08 | L12: 5.4016807e+08 | M12: 5.2916761e+08 | N12: 4.4529108e+08 | O12: 4.3855114e+08 | P12: 4.1590804e+08 | Q12: 3.7217425e+08 | R12: 3.696272e+08 | S12: 1.4966014e+09 | T12: 1.1404416e+09 | U12: 1.0269239e+09 | V12: =9885789+110588+127076+351783+420000000+9000000+12648236+15693241+688304+500000+17410+471011+87790 -> 469581228 | W12: =1066133866-W11 -> 1024755734 | X12: =1259116815.56-70000000 -> 1.1891168e+09 | Y12: =384765963+69494+91717698+185967+110431794+593670514 -> 1180841430 | Z12: 1.1024555e+09 | AA12: 1.0061992e+09 | AB12: 999194890 | AC12: 9.9903538e+08 | AD12: 9.6885439e+08 | AE12: 9.3234648e+08 | AF12: 9.5523646e+08 | AG12: 9.2205699e+08 | AH12: 8.8342735e+08 | AI12: 1.4701645e+09 | AJ12: 1.3411901e+09 | AL12: =271087875+59894+5993809+95527+40425932+188551320+80600000+671459286 -> 1258273643 | AM12: 1.2576145e+09 | AN12: 1.1504264e+09 | AO12: 1.1152005e+09 | AP12: 1.1145403e+09 | AQ12: 1.1278092e+09 | AR12: 1.1139143e+09 | AS12: 1.8707173e+09 | AT12: 1.7752339e+09 | AU12: 1.6212936e+09 | AV12: 1.5731022e+09 | AW12: 1.5381152e+09 | AX12: 1.4559655e+09 | AY12: =1502271759-38940535 -> 1463331224 | AZ12: 1.3651628e+09 | BA12: 1.2053548e+09 | BB12: 1.0921819e+09 | BC12: 1.1214988e+09 | BD12: 1.116658e+09 | BE12: 1.0878421e+09 | BF12: 1.0930986e+09
BF13: 0
A14: 2 | B14: Prepayments & Sundry Receivables | C14: 46579272 | D14: 47499560 | E14: 71142033 | F14: ='[1]5,'!$E$16 -> 72147099 | G14: 75848761 | H14: =56260+3000000+48374+200000+868781+3000+50000+17000+54062881+487494+462668+796000+45000+20000+23438541+2617124+496518+454518+4415+215227+112330+174253+474723+47621 -> 88152728 | I14: =56260+3000000+104553+200000+905659+3000+50000+17000+55234231+14110500+583502+796000+612480+90000+20000+32430901+2490887+496518+42236+2859306+31279+2618516+815007+6242272+487494+130000+1500960+21940 -> 125950501 | J14: 1.3487634e+08 | K14: 1.3039381e+08 | L14: 1.3186059e+08 | M14: 1.3896669e+08 | N14: 1.5144308e+08 | O14: 1.6100822e+08 | P14: 1.7848629e+08 | Q14: 1.8087116e+08 | R14: 1.9173963e+08 | S14: 86004695 | T14: 1.082659e+08 | U14: 1.2278335e+08 | V14: =56260+88358+200000+991501+3000+50000+17000+60725920+1113106+796000+612480+90000+20000+39066692+2422490+496518+29899+4037229+46400+4894469+4207200+487494+130000+750000+1349331+102000 -> 122783347 | W14: 145701460 | X14: 1.6785226e+08 | Y14: =56260+50000+200000+1526864+3000+50000+17000+596316+824000+118000+20000+5745+92297+13318+2014260+578000+341400+1884611+178151+631060+45600+114000+14996+26000-(3079957)+113914696+43800355+1529858 -> 165565830 | Z14: 1.611827e+08 | AA14: 1.7951242e+08 | AB14: 1.8644156e+08 | AC14: 1.9360442e+08 | AD14: 2.037857e+08 | AE14: 2.0615418e+08 | AF14: 2.0436892e+08 | AG14: 2.1421149e+08 | AH14: 2.2805852e+08 | AI14: 1.5373286e+08 | AJ14: 1.73035e+08 | AL14: 168997681 | AM14: 1.7236174e+08 | AN14: 2.0818255e+08 | AO14: 2.1313869e+08 | AP14: 2.1869522e+08 | AQ14: 230946024 | AR14: 2.4862466e+08 | AS14: 1.990429e+08 | AT14: 2.3048805e+08 | AU14: 2.5086998e+08 | AV14: 2.6569739e+08 | AW14: 2.7886857e+08 | AX14: 2.876492e+08 | AY14: 288102791 | AZ14: 2.7572855e+08 | BA14: 2.9291718e+08 | BB14: 3.1376555e+08 | BC14: 3.2639609e+08 | BD14: 3.3909827e+08 | BE14: 3.536472e+08 | BF14: 3.6628387e+08
AY15: 0
A16: 3 | B16: Financial Investments | C16: =SUM(C17:C21) -> 14091580 | D16: =SUM(D17:D21) -> 15191580 | E16: =SUM(E17:E21) -> 15191580 | F16: =SUM('[1]10,11,12,13'!$G$125:$G$130) -> 15985700 | G16: =SUM(G17:G21) -> 26085700 | H16: =SUM(H17:H21) -> 27282077 | I16: =SUM(I17:I21) -> 411782430 | J16: =SUM(J17:J21) -> 31082077 | K16: =SUM(K17:K21) -> 31082077 | L16: =SUM(L17:L21) -> 31082077 | M16: =SUM(M17:M21) -> 31082077 | N16: =SUM(N17:N21) -> 31082077 | ... BF16: =SUM(BF17:BF21) -> 143294140
A17: 3.1 | B17: Government Securities - Treasury Bills/bonds, | F17: 0 | J17: 0 | K17: 0 | L17: 0 | X17: 70000000 | Y17: =70000000 -> 70000000 | Z17: 70000000 | AA17: 70000000 | AB17: 70000000 | AC17: 70000000 | AD17: 70000000 | AE17: 70000000 | AF17: 70000000 | AG17: 70000000 | AH17: 70000000 | AI17: 70000000 | AJ17: 70000000 | AL17: 70000000 | AM17: 70000000 | AN17: 70000000 | AO17: 70000000 | AP17: 70000000 | AQ17: 70000000 | AR17: 70000000 | AS17: 70000000 | AT17: 40000000 | AU17: 40000000 | AV17: 40000000 | AW17: 0 | AX17: 0 | AY17: 0 | AZ17: 0 | BA17: 0 | BB17: 0 | BC17: 0 | BD17: 0 | BE17: 0 | BF17: 0
A18: 3.2 | B18: Other Securities - Commercial papers/Bonds | F18: 0 | J18: 0 | K18: 0 | L18: 0 | Z18: 0 | AA18: 0 | AB18: 0 | AC18: 0 | AD18: 0 | AE18: 0 | AF18: 0 | AG18: 0 | AM18: 0 | AN18: 0 | AO18: 0 | AP18: 0 | AQ18: 0 | AR18: 0 | AS18: 0 | AT18: 0 | AU18: 0 | AV18: 0 | AW18: 0 | AX18: 0 | AY18: 0 | AZ18: 0 | BA18: 0 | BB18: 0 | BC18: 0 | BD18: 0 | BE18: 0 | BF18: 0
A19: 3.3a | B19: Balances in NACCOS (E.g Jungu Kuu, ESS, Savings,Money Market,Coop FD, CFP) | F19: 0 | I19: =346954860+32748493+997000 -> 380700353 | J19: 0 | K19: 0 | L19: 0 | V19: =495029531+33408391+1000000+20170124 -> 549608046 | W19: =12398904+2575560+1000000+12333571+9000 -> 28317035 | Y19: =12398904+2575560+1000000+100000+12333571+9000 -> 28417035 | Z19: 0 | AA19: 0 | AB19: 0 | AC19: 0 | AD19: 0 | AE19: 0 | AF19: 0 | AG19: 0 | AM19: 0 | AN19: 0 | AO19: 0 | AP19: 0 | AQ19: 0 | AR19: 0 | AS19: 0 | AT19: 0 | AU19: 0 | AV19: 0 | AW19: 0 | AX19: 0 | AY19: 0 | AZ19: 0 | BA19: 0 | BB19: 0 | BC19: 0 | BD19: 0 | BE19: 0 | BF19: 0
B20: Equity Investments in NACCOs(Shares in- CIC, KUSCCO, COOP BANK,CAK, KERUSSU) | AL20: =12398904+2575560+1000000+20333571+9000 -> 36317035 | AY20: 137404140 | BF20: 0
A21: 3.3b | B21: Equity Investments in companies - shares/stocks | C21: 14091580 | D21: 15191580 | E21: 15191580 | F21: =SUM('[1]10,11,12,13'!$G$125:$G$130) -> 15985700 | G21: 26085700 | H21: =10332420+2575560+3265097+9000+1000000+100000+10000000 -> 27282077 | I21: =10332420+2575560+7065097+9000+1000000+100000+10000000 -> 31082077 | J21: 31082077 | K21: 31082077 | L21: 31082077 | M21: 31082077 | N21: 31082077 | O21: 31082077 | P21: 31082077 | Q21: 31082077 | R21: 31082077 | S21: 31082077 | T21: 51082077 | U21: 33417035 | V21: =12398904+2575560+1000000+100000+10000000+7333571+9000 -> 33417035 | W21: =100000+10000000 -> 10100000 | X21: 38417035 | Y21: 10000000 | Z21: 38417035 | AA21: 38417035 | AB21: 38417035 | AC21: 38417035 | AD21: 38417035 | AE21: 38417035 | AF21: 48917035 | AG21: 48917035 | AH21: 48917035 | AI21: 46417035 | AJ21: 46417035 | AL21: =100000+10000000 -> 10100000 | AM21: 46417035 | AN21: 58617035 | AO21: 58617035 | AP21: 58617035 | AQ21: 58617035 | AR21: 58617035 | AS21: 58617035 | AT21: 58617035 | AU21: 58617035 | AV21: 58617035 | AW21: 58617035 | AX21: 137404140 | AY21: 0 | AZ21: 137404140 | BA21: 137404140 | BB21: 137404140 | BC21: 137404140 | BD21: 143294140 | BE21: 143294140 | BF21: 143294140
A23: 4 | B23: Net Loan Portfolio | C23: =C24-C25 -> 502161933 | D23: =D24-D25 -> 701336906 | E23: =E24-E25 -> 842727981 | F23: =F24-F25 -> 1018650165 | G23: =G24-G25 -> 1128533399 | H23: =H24-H25 -> 1189398328 | I23: =I24-I25 -> 1390743016 | J23: =J24-J25 -> 1.4342734e+09 | ... BF23: =BF24-BF25 -> 3.7911369e+09
B24: Gross Loan Portfolio | C24: 502161933 | D24: 701336906 | E24: 866580456 | F24: =SUM('[1]10,11,12,13'!$G$83:$G$103) -> 1050502640 | G24: 1169889815 | H24: =971478121+16079464+29061764-2680000+28074187+9490022+49046+2321440+10203+131055567+4574407+73311+11986739+23688653+19598761+11937779+494722+1239178+1505137+1000 -> 1260039501 | I24: =944396801+19556130+35445402+-30000+27290321+172222+11846083+87635+1018525+10203+370493220+4439227+58806+13773291+27239013+12910863+20515212+114722+925659+574033+2214 -> 1490839582 | J24: 1.537245e+09 | K24: 1.5641423e+09 | L24: 1.5932334e+09 | M24: 1.6206928e+09 | N24: 1.6860856e+09 | O24: 1.726473e+09 | P24: 1.765986e+09 | Q24: 1.7962765e+09 | R24: 1.8285024e+09 | S24: 1.4289648e+09 | T24: 1.6339078e+09 | U24: 1.7208272e+09 | V24: =11853049+32617396+597725135+1044797338+33834328 -> 1720827246 | W24: 2700721660 | X24: 2.9836566e+09 | Y24: =2700721660+1831425144-(1548490178) -> 2983656626 | Z24: 3.0212551e+09 | AA24: 3.0695181e+09 | AB24: 3.1303044e+09 | AC24: 3.1805279e+09 | AD24: 3.2399479e+09 | AE24: 3.2950827e+09 | AF24: 3.3209628e+09 | AG24: 3.3497253e+09 | AH24: 3.3692725e+09 | AI24: 3.1778765e+09 | AJ24: 3.3136588e+09 | AL24: 3379491104 | AM24: 3.3663871e+09 | AN24: 3.3998942e+09 | AO24: 3.462765e+09 | AP24: 3.5105662e+09 | AQ24: 3.5436692e+09 | AR24: 3.5968934e+09 | AS24: 3.3836114e+09 | AT24: 3.467788e+09 | AU24: 3.5419276e+09 | AV24: 3.587463e+09 | AW24: 3.6754916e+09 | AX24: 3.7482133e+09 | AY24: 3748213331 | AZ24: 3.7453111e+09 | BA24: 3.8234964e+09 | BB24: 4.0186352e+09 | BC24: 4.0561304e+09 | BD24: 4.1114597e+09 | BE24: 4.1978306e+09 | BF24: 4.2438236e+09
B25: Allowance for Loan Loss | E25: 23852475 | F25: =-'[1]10,11,12,13'!$G$105 -> 31852475 | G25: 41356416 | H25: 70641173 | I25: 100096566 | J25: 1.0297157e+08 | K25: 1.0584657e+08 | L25: 1.0872157e+08 | M25: 1.1159657e+08 | N25: 1.1447157e+08 | O25: 1.1734657e+08 | P25: 1.2022157e+08 | Q25: 1.2309657e+08 | R25: 1.2597157e+08 | S25: 1.2884657e+08 | T25: 1.3172157e+08 | U25: 1.3459657e+08 | V25: 134596566 | W25: 331778022 | X25: 3.7287802e+08 | Y25: 372878022 | Z25: 3.7737802e+08 | AA25: 3.8187802e+08 | AB25: 3.8637802e+08 | AC25: 3.9087802e+08 | AD25: 3.9537802e+08 | AE25: 3.9987802e+08 | AF25: 4.0437802e+08 | AG25: 4.0887802e+08 | AH25: 4.1337802e+08 | AI25: 4.1787802e+08 | AJ25: 4.2237802e+08 | AL25: =23485219+20504695+86912138+42948825+187329149+20697996 -> 381878022 | AM25: 3.8637802e+08 | AN25: 3.9087802e+08 | AO25: 3.8187802e+08 | AP25: 3.8187802e+08 | AQ25: 3.8187802e+08 | AR25: 3.8187802e+08 | AS25: 4.1550538e+08 | AT25: 4.316035e+08 | AU25: 4.3551467e+08 | AV25: 4.4992735e+08 | AW25: 4.5295642e+08 | AX25: 4.359408e+08 | AY25: 435940797 | AZ25: 4.359408e+08 | BA25: 4.359408e+08 | BB25: 4.4795997e+08 | BC25: 4.7331125e+08 | BD25: 4.7116508e+08 | BE25: 4.6823846e+08 | BF25: 4.5268676e+08
A27: 5 | B27: Accounts Receivables | C27: =SUM(C28:C30) -> 0 | D27: =SUM(D28:D30) -> 0 | E27: =SUM(E28:E30) -> 0 | F27: =SUM(F28:F30) -> 0 | G27: =SUM(G28:G30) -> 0 | H27: =SUM(H28:H30) -> 0 | I27: =SUM(I28:I30) -> 0 | J27: =SUM(J28:J30) -> 0 | ... BF27: =SUM(BF28:BF30) -> 0
A28: 5.1 | B28: Tax Recoverable | J28: 0 | K28: 0 | L28: 0 | Z28: 0 | AA28: 0 | AB28: 0 | AC28: 0 | AD28: 0 | AE28: 0 | AF28: 0 | AG28: 0 | AH28: 0 | AI28: 0 | AJ28: 0 | AK28: 0 | AL28: 0 | AM28: 0 | AN28: 0 | AO28: 0 | AP28: 0 | AQ28: 0 | AR28: 0 | AS28: 0 | AT28: 0 | AU28: 0 | AV28: 0 | AW28: 0 | AX28: 0 | AY28: 0 | AZ28: 0 | BA28: 0 | BB28: 0 | BC28: 0 | BD28: 0 | BE28: 0 | BF28: 0
A29: 5.2 | B29: Deferred Tax Assets | J29: 0 | K29: 0 | L29: 0 | Z29: 0 | AA29: 0 | AB29: 0 | AC29: 0 | AD29: 0 | AE29: 0 | AF29: 0 | AG29: 0 | AH29: 0 | AI29: 0 | AJ29: 0 | AK29: 0 | AL29: 0 | AM29: 0 | AN29: 0 | AO29: 0 | AP29: 0 | AQ29: 0 | AR29: 0 | AS29: 0 | AT29: 0 | AU29: 0 | AV29: 0 | AW29: 0 | AX29: 0 | AY29: 0 | AZ29: 0 | BA29: 0 | BB29: 0 | BC29: 0 | BD29: 0 | BE29: 0 | BF29: 0
A30: 5.3 | B30: Retirement Benefit Assets | J30: 0 | K30: 0 | L30: 0 | Z30: 0 | AA30: 0 | AB30: 0 | AC30: 0 | AD30: 0 | AE30: 0 | AF30: 0 | AG30: 0 | AH30: 0 | AI30: 0 | AJ30: 0 | AK30: 0 | AL30: 0 | AM30: 0 | AN30: 0 | AO30: 0 | AP30: 0 | AQ30: 0 | AR30: 0 | AS30: 0 | AT30: 0 | AU30: 0 | AV30: 0 | AW30: 0 | AX30: 0 | AY30: 0 | AZ30: 0 | BA30: 0 | BB30: 0 | BC30: 0 | BD30: 0 | BE30: 0 | BF30: 0
A32: 6 | B32: Property & Equipment & Other assets | C32: =SUM(C33:C37) -> 154877010 | D32: =SUM(D33:D37) -> 163611477 | E32: =SUM(E33:E37) -> 40224658 | F32: =SUM(F33:F37) -> 56850072 | G32: =SUM(G33:G37) -> 61006144 | H32: =SUM(H33:H37) -> 66390514 | I32: =SUM(I33:I37) -> 66106031 | J32: =SUM(J33:J37) -> 64982708 | ... BF32: =SUM(BF33:BF37) -> 1.330682e+08
A33: 6.1 | B33: Investment Properties | J33: 0 | K33: 0 | L33: 0 | Z33: 0 | AA33: 0 | AB33: 0 | AC33: 0 | AD33: 0 | AE33: 0 | AF33: 0 | AG33: 0 | AH33: 0 | AI33: 0 | AJ33: 0 | AM33: 0 | AN33: 0 | AO33: 0 | AP33: 0 | AQ33: 0 | AR33: 0 | AS33: 0 | AT33: 0 | AU33: 0 | AV33: 0 | AW33: 0 | AX33: 0 | AY33: 0 | AZ33: 0 | BA33: 0 | BB33: 0 | BC33: 0 | BD33: 0 | BE33: 0 | BF33: 0
A34: 6.2 | B34: Property & Equipment | C34: 152497884 | D34: 161391712 | E34: 37777814 | F34: 43577028 | G34: =48999115 -> 48999115 | H34: =550003+11888666+1427675+531789+379759+12845142+2480271+4706389+6270301+5172805+5532802 -> 51785602 | I34: =550003+11557867+1427675+813196+253299+11981094+4914703+5641159+3872961+7125211+4119604 -> 52256772 | J34: 51142952 | K34: 50372952 | L34: 57553590 | M34: 56640190 | N34: 57428420 | O34: 56657966 | P34: 55507966 | Q34: 54357966 | R34: 53207966 | S34: 52059766 | T34: 51009766 | U34: 53877677 | V34: =550003+11209775+1427675+1218764+168950+15244790+5082215+6867394+2711073+4987648+4409391 -> 53877678 | W34: 66081765 | X34: 62605321 | Y34: =62605319 -> 62605319 | Z34: 62752548 | AA34: 64668208 | AB34: 65943318 | AC34: 64693318 | AD34: 65141918 | AE34: 72433922 | AF34: 74437722 | AG34: 73861572 | AH34: 72611572 | AI34: 74473498 | AJ34: 73223498 | AL34: 79835394 | AM34: 75525877 | AN34: 75357577 | AO34: 79503660 | AP34: 79303660 | AQ34: 78864420 | AR34: 78016170 | AS34: 78753588 | AT34: 77503588 | AU34: 79023576 | AV34: 81145390 | AW34: 83543968 | AX34: 93512669 | AY34: 87413971 | AZ34: 92396669 | BA34: 91292769 | BB34: 90067769 | BC34: 88857269 | BD34: 88227764 | BE34: 95003332 | BF34: 94336757
A35: 6.3 | B35: Prepaid Lease rentals | J35: 0 | K35: 0 | L35: 0 | Z35: 0 | AA35: 0 | AB35: 0 | AC35: 0 | AD35: 0 | AE35: 0 | AF35: 0 | AG35: 0 | AH35: 0 | AI35: 0 | AJ35: 0 | AM35: 0 | AN35: 0 | AO35: 0 | AP35: 0 | AQ35: 0 | AR35: 0 | AS35: 0 | AT35: 0 | AU35: 0 | AV35: 0 | AW35: 0 | AX35: 0 | AZ35: 0 | BA35: 0 | BB35: 0 | BC35: 0 | BD35: 0 | BE35: 0 | BF35: 0
A36: 6.4 | B36: Intangible Assets | F36: ='[1]5,'!$E$21 -> 10500000 | G36: 10500000 | H36: 10500000 | I36: 10500000 | J36: 10500000 | K36: 10500000 | L36: 10500000 | M36: 10500000 | N36: 10500000 | O36: 10500000 | P36: 10500000 | Q36: 10500000 | R36: 10500000 | S36: 10500000 | T36: 10500000 | U36: 10500000 | V36: 10500000 | W36: 10500000 | X36: 10500000 | Y36: 10500000 | Z36: 10500000 | AA36: 10500000 | AB36: 10500000 | AC36: 10500000 | AD36: 10500000 | AE36: 10500000 | AF36: 10500000 | AG36: 15500000 | AH36: 15500000 | AI36: 15500000 | AJ36: 18840800 | AM36: 18771201 | AN36: 20771201 | AO36: 20771201 | AP36: 20771201 | AQ36: 20771201 | AR36: 20771201 | AS36: 20771201 | AT36: 26771201 | AU36: 26771201 | AV36: 26771201 | AW36: 26771201 | AX36: 28487112 | AY36: =11085811+23500000 -> 34585811 | AZ36: 28487112 | BA36: 31371464 | BB36: 33371464 | BC36: 33371464 | BD36: 33371464 | BE36: 33371464 | BF36: 33371464
A37: 6.5 | B37: Other Assets | C37: 2379126 | D37: 2219765 | E37: 2446844 | F37: =SUM('[1]10,11,12,13'!$G$110:$G$112) -> 2773044 | G37: 1507029 | H37: =3975033+89483+40396 -> 4104912 | I37: =3254493+63067+31699 -> 3349259 | J37: 3339755.7 | K37: 3442543.9 | L37: 3546236.3 | M37: 3523469.8 | N37: 3219292.9 | O37: 3545652.3 | P37: 3362454.4 | Q37: 3281327.4 | R37: 3712309.2 | S37: 3485724.8 | T37: 3491608.7 | U37: 3459012 | V37: =3416988+42024 -> 3459012 | W37: 5795087 | X37: 4960619.8 | Y37: =4694032+184683+81905 -> 4960620 | Z37: 5708255.1 | AA37: 5590625.8 | AB37: 5655718.7 | AC37: 5640373.3 | AD37: 5491151.5 | AE37: 5904890 | AF37: 5147500.8 | AG37: 5459773.5 | AH37: 5246111.4 | AI37: 5155908.9 | AJ37: 5689713.8 | AL37: =6161616+15500000 -> 21661616 | AM37: 6050806.1 | AN37: 6026427 | AO37: 5241792 | AP37: 5538856.7 | AQ37: 5374485.8 | AR37: 4816756.2 | AS37: 5453062.8 | AT37: 7395633 | AU37: 6899271.7 | AV37: 5976955.4 | AW37: 5207044.6 | AX37: 5497155.2 | AY37: 5497154 | AZ37: 6103437.8 | BA37: 4251815.1 | BB37: 4952074.2 | BC37: 5600971.8 | BD37: 5857515.8 | BE37: 5792215.2 | BF37: 5359980.9
B39: Total Assets | C39: =C10+C14+C16+C23+C27+C32 -> 886952707 | D39: =D10+D14+D16+D23+D27+D32 -> 1185246560 | E39: =E10+E14+E16+E23+E27+E32 -> 1235320891 | F39: =F10+F14+F16+F23+F27+F32 -> 1560105754 | G39: =G10+G14+G16+G23+G27+G32 -> 1699301395 | H39: =H10+H14+H16+H23+H27+H32 -> 1995648187 | I39: =I10+I14+I16+I23+I27+I32 -> 2415328924 | J39: =J10+J14+J16+J23+J27+J32 -> 2.3940354e+09 | ... BF39: =BF10+BF14+BF16+BF23+BF27+BF32 -> 5.5795063e+09
G40: =1699301395-G39 -> 0
B42: LIABILITIES
A43: 7 | B43: Savings Deposits - Withdrawable deposits - FOSA) | C43: =559229530-314641029 -> 244588501 | D43: =745419886-D44-D45 -> 330041524 | E43: =881752998-E44-E45 -> 375911745 | F43: ='[1]10,11,12,13'!$G$171-'[1]10,11,12,13'!$G$163-'[1]10,11,12,13'!$G$162 -> 412332952 | G43: =1097902733-G44-G45 -> 380508604 | H43: =17123169+257444328+2542189+20643827+14990455+103497918+64027614+2792952+5016+1331499+1948791+6773804+12347+25240538 -> 518374447 | I43: =17077340+359581397+4351414+21185880+14656346+127426754+3338792+5012+1208901+8439349+8491365+5920+25783228 -> 591551698 | J43: 5.3449424e+08 | K43: 5.3915638e+08 | L43: 4.9327734e+08 | M43: 4.9157957e+08 | N43: 4.8216283e+08 | O43: 4.7359464e+08 | P43: 4.7170944e+08 | Q43: 4.357921e+08 | R43: 4.0520479e+08 | S43: 1.0194839e+09 | T43: 8.527019e+08 | U43: 7.5913658e+08 | V43: =735216946 -> 735216946 | W43: =2347338824-(W44+W45) -> 1164138485 | X43: 8.6261593e+08 | Y43: =2600095208-(Y44+Y45) -> 1303353781 | Z43: 9.0877863e+08 | AA43: 8.4894259e+08 | AB43: 8.5413354e+08 | AC43: 8.3161113e+08 | AD43: 8.1110231e+08 | AE43: 7.8163848e+08 | AF43: 7.7539969e+08 | AG43: 7.2738991e+08 | AH43: 697691752 | AI43: 9.6607065e+08 | AJ43: 9.0680536e+08 | AL43: =17433011+369886504+28125593+23428792+14302573+265494831+555456347+5298339+1651829+6418340+22141214+29286616+10061936+74776466+624622 -> 1424387013 | AM43: 9.8181976e+08 | AN43: 8.9565987e+08 | AO43: 8.78877e+08 | AP43: 8.1876818e+08 | AQ43: 8.3374643e+08 | AR43: 8.0121564e+08 | AS43: 1.2103264e+09 | AT43: 1.1330193e+09 | AU43: 1.0449535e+09 | AV43: 9.9378425e+08 | AW43: 9.6368993e+08 | AX43: 9.2683409e+08 | AY43: 903796942 | AZ43: 1.0848922e+09 | BA43: 9.6368356e+08 | BB43: 9.6927827e+08 | BC43: 9.2796462e+08 | BD43: 9.3759838e+08 | BE43: 9.3675096e+08 | BF43: 9.4000987e+08
A44: 8 | B44: Short Term Deposits (e.g Fixed deposits, special savings) | C44: 54809992 | D44: 71496906 | E44: 70123169 | F44: ='[1]10,11,12,13'!$G$163 -> 128086820 | G44: 129187648 | H44: 138180559 | I44: =136545631 -> 136545631 | J44: 1.384246e+08 | K44: 1.3535966e+08 | L44: 1.3547914e+08 | M44: 1.3457832e+08 | N44: 1.2616683e+08 | O44: 1.2440166e+08 | P44: 1.2383756e+08 | Q44: 1.238467e+08 | R44: 1.3256759e+08 | S44: 1.3952065e+08 | T44: 1.4208416e+08 | U44: 1.4873617e+08 | V44: =148736165 -> 148736165 | W44: 267351145 | X44: 2.9243802e+08 | Y44: 292438021 | Z44: 3.0364147e+08 | AA44: 3.0543566e+08 | AB44: 3.1392218e+08 | AC44: 3.1371406e+08 | AD44: 3.1706284e+08 | AE44: 3.1728967e+08 | AF44: 3.0674438e+08 | AG44: 3.1696244e+08 | AH44: 3.1466149e+08 | AI44: 3.043008e+08 | AJ44: 3.1717381e+08 | AL44: =322814962 -> 322814962 | AM44: 3.3210957e+08 | AN44: 3.3760897e+08 | AO44: 3.4792479e+08 | AP44: 3.869918e+08 | AQ44: 3.7294935e+08 | AR44: 3.711988e+08 | AS44: 3.9741418e+08 | AT44: 3.9463205e+08 | AU44: 3.9756644e+08 | AV44: 3.9625292e+08 | AW44: 4.0455244e+08 | AX44: 4.0285861e+08 | AY44: 402858607 | AZ44: 3.1618299e+08 | BA44: 3.1219422e+08 | BB44: 3.1759302e+08 | BC44: 3.462979e+08 | BD44: 3.2424635e+08 | BE44: 3.1740326e+08 | BF44: 3.1814777e+08
A45: 9 | B45: Non withdrawable deposits (BOSA member deposits) | C45: 259831037 | D45: 343881456 | E45: 435718084 | F45: ='[1]10,11,12,13'!$G$162 -> 533687314 | G45: 588206481 | H45: 645106995 | I45: =705964567+127592317 -> 833556884 | J45: 8.4011294e+08 | K45: 8.4807822e+08 | L45: 8.5622319e+08 | M45: 8.706492e+08 | N45: 8.8252153e+08 | O45: 8.9403489e+08 | P45: 9.0175372e+08 | Q45: 9.0676538e+08 | R45: 9.1362438e+08 | S45: 9.3350164e+08 | T45: 8.9533632e+08 | U45: 9.0823093e+08 | V45: =17194763+476548275+5621617+22083185+14849831+157784164+173013983+4143685+6239+3052308+9402350+14230986+5862+34213314 -> 932150562 | W45: 915849194 | X45: 1.4450413e+09 | Y45: 1004303406 | Z45: 1.4627379e+09 | AA45: 1.4778964e+09 | AB45: 1.5012699e+09 | AC45: 1.5186985e+09 | AD45: 1.5411626e+09 | AE45: 1.5764766e+09 | AF45: 1.5977068e+09 | AG45: 1.6120456e+09 | AH45: 1.621443e+09 | AI45: 1.6289946e+09 | AJ45: 1.6430303e+09 | AL45: 1102313070 | AM45: 1.6740585e+09 | AN45: 1.6890618e+09 | AO45: 1.7101521e+09 | AP45: 1.7352145e+09 | AQ45: 1.7618692e+09 | AR45: 1.8077338e+09 | AS45: 1.824624e+09 | AT45: 1.8370985e+09 | AU45: 1.849297e+09 | AV45: 1.8627261e+09 | AW45: 1.8817101e+09 | AX45: 1.9087583e+09 | AY45: 1931795498 | AZ45: 1.9493737e+09 | BA45: 1.988218e+09 | BB45: 2.0448334e+09 | BC45: 2.0924216e+09 | BD45: 2.1234277e+09 | BE45: 2.1783698e+09 | BF45: 2.2010512e+09
B46: Total Deposit liabilities | C46: =SUM(C43:C45) -> 559229530 | D46: =SUM(D43:D45) -> 745419886 | E46: =SUM(E43:E45) -> 881752998 | F46: =SUM(F43:F45) -> 1074107086 | G46: =SUM(G43:G45) -> 1097902733 | H46: =SUM(H43:H45) -> 1301662001 | I46: =SUM(I43:I45) -> 1561654213 | J46: =SUM(J43:J45) -> 1.5130318e+09 | ... BF46: =SUM(BF43:BF45) -> 3.4592088e+09
...

Sheet STATEMENT OF COMPREHENSIVE INCO
A1: FORM 7 SASRA/007
A2: STATEMENT OF COMPREHENSIVE INCOME
A3: NAME OF SACCO SOCIETY: YETU
A4: FINANCIAL YEAR 2011
A5: START DATE: 1st January
A6: END DATE: 31st December
G7: 2014 AUDITED
A8: Ref No. | C8: 40513 | D8: 40878 | E8: Audited 2012 | F8: AUDITED 2013 | H8: AUDITED 2015 | I8: AUDITED 2016 | J8: 42736 | K8: 42767 | L8: 42795 | M8: 42826 | N8: 42856 | O8: 42887 | P8: 42917 | Q8: 42948 | R8: 42979 | S8: 43009 | T8: 43040 | U8: 43070 | V8: AUDITED 2017 | W8: AUDITED 2019 | X8: 44166 | Y8: AUDITED 2020 | Z8: 44197 | AA8: 44228 | AB8: 44256 | AC8: 44287 | AD8: 44317 | AE8: 44348 | AF8: 44378 | AG8: 44409 | AH8: 44440 | AI8: 44470 | AJ8: 44501 | AK8: 44531 | AL8: AUDITED 2021 | AM8: 44562 | AN8: 44593 | AO8: 44621 | AP8: 44652 | AQ8: 44682 | AR8: 44713 | AS8: 44743 | AT8: 44774 | AU8: 44805 | AV8: 44835 | AW8: 44866 | AX8: 44896 | AY8: Audited 2022 | AZ8: 44927 | BA8: 44958 | BB8: 44986 | BC8: 45017 | BD8: 45047 | BE8: 45078 | BF8: 45108
D9: KShs
A10: 1 | B10: Financial Income | C10: =C11+C15 -> 81774220 | D10: =D11+D15 -> 1.7090549e+08 | E10: =E11+E15 -> 235675793 | F10: =F11+F15 -> 288037618 | G10: =G11+G15 -> 277638373 | H10: =H11+H15 -> 314967423 | I10: =I11+I15 -> 386913271 | J10: =J11+J15 -> 25367152 | ... BF10: =BF11+BF15 -> 4.1967583e+08
A11: 2 | B11: Financial Income from Loans Portfolio | C11: =SUM(C12:C13) -> 73871195 | D11: =SUM(D12:D13) -> 1.2777296e+08 | E11: =SUM(E12:E13) -> 171863513 | F11: =SUM(F12:F13) -> 213223483 | G11: =SUM(G12:G13) -> 201218528 | H11: =SUM(H12:H13) -> 199339025 | I11: =SUM(I12:I13) -> 265160914 | J11: =SUM(J12:J13) -> 22258926 | ... BF11: =SUM(BF12:BF13) -> 3.6381577e+08
A12: 2.1 | B12: Interest on Loan Portfolio | C12: 67225127 | D12: 82427924 | E12: =135798607+3563922 -> 139362529 | F12: 176582685 | G12: 185123085 | H12: =6430246+192908779 -> 199339025 | I12: =15547269+208483419 -> 224030688 | J12: 16403062 | K12: 32799726 | L12: 49532688 | M12: 66592721 | N12: 84208039 | O12: 1.0219755e+08 | P12: 1.2075812e+08 | Q12: 1.3992829e+08 | R12: 1.6025645e+08 | S12: 1.8084914e+08 | T12: 2.0003346e+08 | U12: 2.1870221e+08 | V12: =19085479+206555811 -> 225641290 | W12: 325832925 | X12: 3.7559706e+08 | Y12: =373570484 -> 373570484 | Z12: 33549968 | AA12: 67275548 | AB12: 1.0160622e+08 | AC12: 1.3647068e+08 | AD12: 1.7227046e+08 | AE12: 2.0871353e+08 | AF12: 2.4608875e+08 | AG12: 2.8396699e+08 | AH12: 3.2230828e+08 | AI12: 3.6070991e+08 | AJ12: 3.9920015e+08 | AK12: 4.3924825e+08 | AL12: 452871508 | AM12: 38683722 | AN12: 76843586 | AO12: 1.1569307e+08 | AP12: 1.5506282e+08 | AQ12: 1.9385812e+08 | AR12: 2.349502e+08 | AS12: 2.7708656e+08 | AT12: 3.1683554e+08 | AU12: 3.5752545e+08 | AV12: 3.9867479e+08 | AW12: 4.4211605e+08 | AX12: 4.8531681e+08 | AY12: 485316812 | AZ12: 42709547 | BA12: 85887962 | BB12: 1.3022523e+08 | BC12: 1.7564908e+08 | BD12: 2.2208486e+08 | BE12: 2.6905477e+08 | BF12: 3.163379e+08
A13: 2.2 | B13: Fees & Commission on Loan Portfolio | C13: =8230741-1584673 -> 6646068 | D13: 45345034 | E13: 32500984 | F13: 36640798 | G13: 16095443 | I13: =14238976+26891250 -> 41130226 | J13: 5855863.9 | K13: 9811623.6 | L13: 13111476 | M13: 16309635 | N13: 21197470 | O13: 24781487 | P13: 28415873 | Q13: 31795778 | R13: 35155169 | S13: 37736977 | T13: 66037662 | U13: 76208014 | V13: =46587556 -> 46587556 | W13: 0 | X13: 85530988 | Y13: =88161102+51433393 -> 139594495 | Z13: 7724126.3 | AA13: 13198364 | AB13: 19476688 | AC13: 23987935 | AD13: 30987550 | AE13: 36788398 | AF13: 42165178 | AG13: 46371403 | AH13: 50084111 | AI13: 53304954 | AJ13: 73235728 | AK13: 88036892 | AM13: 5613530.4 | AN13: 10721646 | AO13: 16723439 | AP13: 22419742 | AQ13: 27511641 | AR13: 32096278 | AS13: 49283927 | AT13: 59761934 | AU13: 69107854 | AV13: 75171913 | AW13: 82767837 | AX13: 84678042 | AY13: =79346054+60670454 -> 140016508 | AZ13: 7216026.7 | BA13: 14761485 | BB13: 24569142 | BC13: 29220971 | BD13: 36236050 | BE13: 43188758 | BF13: 47477869
A15: 3 | B15: Financial Income from Investments in: | C15: =SUM(C16:C19) -> 7903025 | D15: =SUM(D16:D19) -> 43132528 | E15: =SUM(E16:E19) -> 63812280 | F15: =SUM(F16:F19) -> 74814135 | G15: =SUM(G16:G19) -> 76419845 | H15: =SUM(H16:H19) -> 115628398 | I15: =SUM(I16:I19) -> 121752357 | J15: =SUM(J16:J19) -> 3108225.9 | ... BF15: =SUM(BF16:BF19) -> 55860066
A16: 3.1 | B16: Government Securities | J16: 0 | K16: 0 | L16: 0 | W16: 0 | X16: 1212386.4 | Y16: 0 | Z16: 363934.58 | AA16: 727869.16 | AB16: 1091803.7 | AC16: 1455738.3 | AD16: 1819672.9 | AE16: 2183607.5 | AF16: 2451306.3 | AG16: 2804849.6 | AH16: 3158393 | AI16: 3511936.3 | AJ16: 3756359.4 | AK16: 4131862.4 | AM16: 375503.01 | AN16: 751006.02 | AO16: 1126509 | AP16: 1502012 | AQ16: 1877515.1 | AR16: 2253018.1 | AS16: 2628521.1 | AT16: 2857399.1 | AU16: 3086277.1 | AV16: 3315155.1 | AW16: 3315155.1 | AX16: 3525586.2 | AZ16: 0 | BA16: 0 | BB16: 0 | BC16: 0 | BD16: 0 | BE16: 0 | BF16: 0
A17: 3.2 | B17: Deposit with Banks and Other Financial Inst. | D17: 744599.53 | E17: 7264605 | G17: 13488763 | H17: 19215771 | I17: 32843403 | J17: 0 | K17: 0 | L17: 0 | N17: 163742.5 | O17: 163742.5 | P17: 328303.69 | Q17: 328303.69 | R17: 328303.69 | S17: 328303.69 | T17: 493687.69 | U17: 659898.59 | V17: =46159306 -> 46159306 | W17: 0 | X17: 82503.87 | Y17: 0 | Z17: 91764.57 | AA17: 127776.76 | AB17: 134020.4 | AC17: 172163.92 | AD17: 182578.18 | AE17: 195696.2 | AF17: 218699.52 | AG17: 266179.16 | AH17: 278307.03 | AI17: 356913.33 | AJ17: 371285.66 | AK17: 375928.39 | AM17: 20724.91 | AN17: 48507.73 | AO17: 56757.2 | AP17: 62224.62 | AQ17: 77353.83 | AR17: 77353.83 | AS17: 116192.7 | AT17: 121345.73 | AU17: 132692.55 | AV17: 146172.62 | AW17: 163935.52 | AX17: 169397.19 | AY17: 127876850 | AZ17: 25234.62 | BA17: 34439.77 | BB17: 53118.63 | BC17: 78102.09 | BD17: 110870.12 | BE17: 146247.96 | BF17: 186246.12
A18: 3.3 | B18: Other Investments - dividend & Interest incomes from investments | C18: 7486550 | E18: 3609778 | F18: 17727545 | G18: 10161679 | H18: 12882628 | I18: 18850066 | J18: 0 | K18: 0 | L18: 0 | V18: =8989071 -> 8989071 | W18: 97520095 | Y18: =13010358+76138677 -> 89149035 | Z18: 0 | AA18: 0 | AB18: 0 | AC18: 0 | AD18: 0 | AE18: 0 | AF18: 0 | AK18: 0 | AL18: =19029527+69970286 -> 88999813 | AM18: 0 | AN18: 0 | AO18: 0 | AP18: 0 | AQ18: 0 | AR18: 0 | AS18: 0 | AT18: 0 | AU18: 0 | AV18: 0 | AW18: 0 | AX18: 0 | AY18: 13408029 | AZ18: 0 | BA18: 0 | BB18: 0 | BC18: 0 | BD18: 0 | BE18: 0 | BF18: 0
A19: 3.4 | B19: Other Operating Income- Salary processing fees, transaction fees, membership fees | C19: =453968+1528560-1566053 -> 416475 | D19: 42387929 | E19: 52937897 | F19: 57086590 | G19: =44053130+1269644+3387710+1558378+596150+1904391 -> 52769403 | H19: =46729689+1480900+1607200+30074574+664995+2972641 -> 83529999 | I19: =61215815+550+3642865+1243224+3956434 -> 70058888 | J19: 3108225.9 | K19: 6014421.8 | L19: 8833672.7 | M19: 14393783 | N19: 17650987 | O19: 20698206 | P19: 23425816 | Q19: 26349223 | R19: 28958712 | S19: 42259158 | T19: 47645473 | U19: 51767352 | V19: =67205558+2187071+914040+3971935 -> 74278604 | W19: 158497457 | X19: 63770255 | Y19: =1034316+1144556+6946985 -> 9125857 | Z19: 5942192.2 | AA19: 10187361 | AB19: 15592233 | AC19: 21043387 | AD19: 25707769 | AE19: 31737731 | AF19: 37547299 | AG19: 41775214 | AH19: 45403948 | AI19: 57791629 | AJ19: 62857856 | AK19: 67114482 | AL19: 152868396 | AM19: 5612614.7 | AN19: 10546316 | AO19: 15950694 | AP19: 22923189 | AQ19: 28574406 | AR19: 34828428 | AS19: 51177168 | AT19: 56335365 | AU19: 61503713 | AV19: 66672242 | AW19: 72218418 | AX19: 77874794 | AY19: =1813087+20494968+228244 -> 22536299 | AZ19: 13541874 | BA19: 20075887 | BB19: 28836918 | BC19: 35444531 | BD19: 42857139 | BE19: 49279005 | BF19: 55673819
A21: 4 | B21: Financial Expense | C21: =SUM(C22:C28) -> 35625225 | D21: =SUM(D22:D28) -> 22039304 | E21: =SUM(E22:E28) -> 70050995 | F21: =SUM(F22:F28) -> 100541517 | G21: =G22+G23+G24+G25+G27+G28 -> 84023090 | H21: =H22+H23+H24+H25+H27+H28 -> 84894530 | I21: =I22+I23+I24+I25+I27+I28 -> 120804092 | J21: =J22+J23+J24+J25+J27+J28 -> 7692621.7 | K21: =K22+K23+K24+K25+K27+K28 -> 19009377 | L21: =L22+L23+L24+L25+L27+L28 -> 27746256 | M21: =M22+M23+M24+M25+M27+M28 -> 37506436 | N21: =N22+N23+N24+N25+N27+N28 -> 49227970 | ... BF21: =BF22+BF23+BF24+BF25+BF27+BF28 -> 2.3118282e+08
A22: 4.2 | B22: Interest Expense on Deposits | D22: 7377984.3 | E22: 48000000 | F22: 83304527 | G22: =16018598+55000000 -> 71018598 | H22: 16756380 | I22: =55275000+45225000+17621204 -> 118121204 | J22: 897209.45 | K22: 2750108.5 | L22: 3387572.1 | M22: 5043210.3 | N22: 8644024.2 | O22: 9414776.4 | P22: 10175311 | Q22: 10962672 | R22: 11842524 | S22: 13173822 | T22: 16612631 | U22: 17936889 | V22: =115000000+17936889 -> 132936889 | W22: 194453667 | X22: 33991846 | Y22: =195000000+9743073+24248773 -> 228991846 | Z22: 3117295.6 | AA22: 6048847.9 | AB22: 9271751.8 | AC22: 12458993 | AD22: 15821837 | AE22: 19059848 | AF22: 22241994 | AG22: 25311159 | AH22: 28370013 | AI22: 31595677 | AJ22: 35004173 | AK22: 38473794 | AL22: =240000000+11425946+27047848 -> 278473794 | AM22: 3552743.8 | AN22: 6808642.2 | AO22: 10312784 | AP22: 13916662 | AQ22: 17879735 | AR22: 21589950 | AS22: 25724638 | AT22: 29885633 | AU22: 33838772 | AV22: 37649128 | AW22: 41152795 | AX22: 44849529 | AY22: 303188965 | AZ22: 3552527 | BA22: 6470536.1 | BB22: 8843769 | BC22: 11212169 | BD22: 14415602 | BE22: 17084780 | BF22: 15685763
A23: 4.3 | B23: Cost of External Borrowings | D23: 12361109 | E23: =30538668-8487673 -> 22050995 | F23: 15150271 | G23: =3333058+4256301 -> 7589359 | H23: =11846+1510782 -> 1522628 | J23: 0 | K23: 0 | L23: 0 | S23: 355068 | T23: 355068 | U23: 355068 | V23: 355068 | W23: 0 | X23: 0 | Y23: 0 | Z23: 5583.33 | AA23: 10474.66 | AB23: 15365.99 | AC23: 20257.33 | AD23: 24455.33 | AE23: 28653.33 | AF23: 32851.33 | AG23: 36355.33 | AH23: 39857.33 | AI23: 43359.33 | AJ23: 46166.33 | AK23: 48971.33 | AM23: 2805 | AN23: 4913 | AO23: 7019 | AP23: 9125 | AQ23: 10532 | AR23: 11938 | AS23: 13344 | AT23: 14048 | AU23: 14752 | AV23: 15456 | AW23: 15456 | AX23: 15456 | AY23: 15456 | AZ23: 0 | BA23: 0 | BB23: 0 | BC23: 0 | BD23: 0 | BE23: 0 | BF23: 0
A24: 4.4 | B24: Dividend Expenses (on member shares) | C24: 35000000 | G24: 0 | H24: 60000000 | J24: 6666666.7 | K24: 16000000 | L24: 24000000 | M24: 32000000 | N24: 40000000 | O24: 48000000 | P24: 56000000 | Q24: 64000000 | R24: 72000000 | S24: 80000000 | T24: 88000000 | U24: 115000000 | W24: 0 | X24: 0 | Y24: 0 | Z24: 20000000 | AA24: 40000000 | AB24: 60000000 | AC24: 80000000 | AD24: 100000000 | AE24: 120000000 | AF24: 140000000 | AG24: 160000000 | AH24: 180000000 | AI24: 200000000 | AJ24: 220000000 | AK24: 240000000 | AM24: 24166667 | AN24: 48333333 | AO24: 72500000 | AP24: 96666667 | AQ24: 1.2083333e+08 | AR24: 145000000 | AS24: 1.6916667e+08 | AT24: 1.9333333e+08 | AU24: 2.175e+08 | AV24: 2.4166667e+08 | AW24: 2.6583333e+08 | AX24: 290000000 | AY24: 0 | AZ24: 28333333 | BA24: 56666667 | BB24: 85000000 | BC24: 85000000 | BD24: 1.1333333e+08 | BE24: 170000000 | BF24: 1.9833333e+08
A25: 4.5 | B25: Other Financial Expense | C25: =1625+174000+15200+434400 -> 625225 | D25: 2300209.9 | F25: 2086719 | G25: =3264000+1922358+33275+179800+15700 -> 5415133 | H25: =3847800+2072222+179800+15700+500000 -> 6615522 | I25: =626+230137+1348669+1103456 -> 2682888 | J25: 128745.5 | K25: 259268.5 | L25: 358683.5 | M25: 463225.5 | N25: 583946 | O25: 694169.5 | P25: 720077 | Q25: 902091 | R25: 1010667.5 | S25: 1110163.5 | T25: 1389210.9 | U25: 1358744.9 | V25: 1358745 | W25: 5937775 | X25: 1565302.9 | Y25: =1565303+3000000+27060+92811 -> 4685174 | Z25: 160557.2 | AA25: 285923.2 | AB25: 418633.2 | AC25: 528252.2 | AD25: 657352.2 | AE25: 805672.2 | AF25: 927266.2 | AG25: 1029628.3 | AH25: 1144884.3 | AI25: 1212294.7 | AJ25: 1357722.7 | AK25: 1482289.7 | AL25: 5200083 | AM25: 378132 | AN25: 1681388.4 | AO25: 2936443.5 | AP25: 4377361.6 | AQ25: 6027924.4 | AR25: 7752690.2 | AS25: 9694547.6 | AT25: 11527856 | AU25: 13596393 | AV25: 15607971 | AW25: 17680359 | AX25: 21361091 | AY25: =27216458-15456 -> 27201002 | AZ25: 3362334 | BA25: 7591433.3 | BB25: 12103740 | BC25: 16393707 | BD25: 21493670 | BE25: 14110595 | BF25: 17163721
AF26: 0 | AG26: 0 | BF26: 0
A27: 4.6 | B27: Fees & Commission Expense | J27: 0 | K27: 0 | L27: 0 | W27: 0 | X27: 0 | Y27: 0 | Z27: 0 | AA27: 0 | AB27: 0 | AC27: 0 | AD27: 0 | AE27: 0 | AF27: 0 | AG27: 0 | AM27: 0 | AN27: 0 | AO27: 0 | AP27: 0 | AQ27: 0 | AR27: 0 | AS27: 0 | AT27: 0 | AU27: 0 | AV27: 0 | AW27: 0 | AX27: 0 | AY27: 0 | AZ27: 0 | BA27: 0 | BB27: 0 | BC27: 0 | BD27: 0 | BE27: 0 | BF27: 0
A28: 4.7 | B28: Other Expense | J28: 0 | K28: 0 | L28: 0 | W28: 0 | X28: 0 | Y28: 0 | Z28: 0 | AA28: 0 | AB28: 0 | AC28: 0 | AD28: 0 | AE28: 0 | AM28: 0 | AN28: 0 | AO28: 0 | AP28: 0 | AQ28: 0 | AR28: 0 | AS28: 0 | AT28: 0 | AU28: 0 | AV28: 0 | AW28: 0 | AX28: 0 | AY28: 0 | AZ28: 0 | BA28: 0 | BB28: 0 | BC28: 0 | BD28: 0 | BE28: 0 | BF28: 0
A30: 5 | B30: Net Financial Income/(Loss) | C30: =C10-C21 -> 46148995 | D30: =D10-D21 -> 1.4886618e+08 | E30: =E10-E21 -> 165624798 | F30: =F10-F21 -> 187496101 | G30: =G10-G21 -> 193615283 | H30: =H10-H21 -> 230072893 | I30: =I10-I21 -> 266109179 | J30: =J10-J21 -> 17674530 | ... BF30: =BF10-BF21 -> 1.8849302e+08
A32: 6 | B32: Allowance for Loan Loss | C32: =C33-C34 -> 0 | D32: =D33-D34 -> 5000000 | E32: =E33-E34 -> 5000005 | F32: =F33-F34 -> 8000000 | G32: =G33-G34 -> 9600000 | H32: =H33-H34 -> 30000000 | I32: =I33-I34 -> 30000000 | J32: =J33-J34 -> 2875000 | ... BF32: =BF33-BF34 -> 16745961
A33: 6.1 | B33: Provision for Loan Losses | D33: 5000000 | E33: 5000005 | F33: 8000000 | G33: 9600000 | H33: 30000000 | I33: =30000000 -> 30000000 | J33: 2875000 | K33: 5750000 | L33: 8625000 | M33: 11500000 | N33: 14375000 | O33: 17250000 | P33: 20125000 | Q33: 23000000 | R33: 25875000 | S33: 28750000 | T33: 31625000 | U33: 34500000 | V33: 34500000 | W33: 162681456 | X33: 41100000 | Y33: 41100000 | Z33: 4500000 | AA33: 9000000 | AB33: 13500000 | AC33: 18000000 | AD33: 22500000 | AE33: 27000000 | AF33: 31500000 | AG33: 36000000 | AH33: 40500000 | AI33: 45000000 | AJ33: 49500000 | AK33: 9000000 | AL33: 9000000 | AM33: 4500000 | AN33: 9000000 | AO33: 0 | AP33: 0 | AQ33: 0 | AR33: 0 | AS33: 33627357 | AT33: 49725477 | AU33: 53636645 | AV33: 68049329 | AW33: 71078402 | AX33: 54062775 | AY33: 54062775 | AZ33: 0 | BA33: 0 | BB33: 12019173 | BC33: 37370458 | BD33: 35224281 | BE33: 32297662 | BF33: 16745961
A34: 6.2 | B34: Value of Loans Recovered | J34: 0 | K34: 0 | L34: 0 | W34: 0 | X34: 0 | Y34: 0 | Z34: 0 | AA34: 0 | AB34: 0 | AC34: 0 | AD34: 0 | AE34: 0 | AF34: 0 | AK34: 0 | AM34: 0 | AN34: 0 | AO34: 0 | AP34: 0 | AQ34: 0 | AR34: 0 | AS34: 0 | AT34: 0 | AU34: 0 | AV34: 0 | AW34: 0 | AX34: 0 | AY34: 0 | AZ34: 0 | BA34: 0 | BB34: 0 | BC34: 0 | BD34: 0 | BE34: 0 | BF34: 0
A36: 7 | B36: Operating Expenses | C36: =SUM(C37:C41) -> 20053569 | D36: =SUM(D37:D41) -> 73581334 | E36: =SUM(E37:E41) -> 69196044 | F36: =SUM(F37:F41) -> 89943298 | G36: =SUM(G37:G41) -> 87367063 | H36: =SUM(H37:H41) -> 117610973 | I36: =SUM(I37:I41) -> 121174021 | J36: =SUM(J37:J41) -> 10629822 | ... BF36: =SUM(BF37:BF41) -> 1.7969144e+08
A37: 7.1 | B37: Personnel Expenses | C37: 10339275 | D37: 31404308 | E37: =14225499+465552+3748614+3180843+2606460+24926+72200+2499536+8249440+752300 -> 35825370 | F37: 45213017 | G37: =16094500+5060307+7088000+3368390+3508807+21997+86000+3223360+11520935+956200 -> 50928496 | H37: =18596000+7340665+8126553+5110312+3029147+37597+98000+3685200+13037510+1113800 -> 60174784 | I37: =10805300+4030919+4488000+3348152+1823424+14190+54120+2157430+8963283+594000+8840700+3298025+3672000+2739397+1491893+11610+44280+1765170+7333595+486000 -> 65961488 | J37: 4983196.3 | K37: 10320309 | L37: 15964636 | M37: 22598575 | N37: 29645863 | O37: 35038781 | P37: 39536167 | Q37: 45850174 | R37: 51929566 | S37: 57575807 | T37: 63321819 | U37: 68657692 | V37: =21177693+8235272+8426921+5027392+3764578+38998+102000+4227385+16586453+1071000 -> 68657692 | W37: 86231438 | X37: 84062797 | Y37: =30866036+7905037+11896847+4010956+1012905+4213271+109200+5608421+6212044+2228080+10000000 -> 84062797 | Z37: 6221490 | AA37: 13740036 | AB37: 22146365 | AC37: 29916078 | AD37: 37970786 | AE37: 47700473 | AF37: 60693892 | AG37: 69579804 | AH37: 78682762 | AI37: 87840492 | AJ37: 96406947 | AK37: 1.0566562e+08 | AL37: 105665615 | AM37: 8651302.8 | AN37: 18195477 | AO37: 27784578 | AP37: 36966794 | AQ37: 49242399 | AR37: 59047292 | AS37: 73110560 | AT37: 81896346 | AU37: 90908105 | AV37: 1.0004573e+08 | AW37: 1.1376377e+08 | AX37: 1.2406294e+08 | AY37: 124062936 | AZ37: 9675331.1 | BA37: 20888827 | BB37: 31581158 | BC37: 43969214 | BD37: 57777877 | BE37: 72083996 | BF37: 87508424
A38: 7.2 | B38: Governance Expenses | C38: 4706687 | D38: 5602590 | E38: =981260+2199092+2303397+158045 -> 5641794 | F38: 8566934 | G38: =991618+5142864+2655313+225609 -> 9015404 | H38: =1349230+7879712+1361956 -> 10590898 | I38: =848190+5080974+460609+693974+4157160+376862 -> 11617769 | J38: 388566 | K38: 1232043 | L38: 3266709 | M38: 3797773 | N38: 4231758 | O38: 4786180 | P38: 5260811 | Q38: 5941943 | R38: 7999904 | S38: 8909164 | T38: 9423622 | U38: 9953610 | V38: =1692952+7357620+903038 -> 9953610 | W38: 22543894 | X38: 12570566 | Y38: =4870072+5071010+1372195+514509+742781 -> 12570567 | Z38: 1551122 | AA38: 2638653 | AB38: 4810788.5 | AC38: 6813027.5 | AD38: 7714846.5 | AE38: 9303104 | AF38: 12251193 | AG38: 13235598 | AH38: 17483564 | AI38: 18838686 | AJ38: 20736476 | AK38: 23427238 | AL38: 23427238 | AM38: 1173003 | AN38: 2868536.5 | AO38: 7252869.5 | AP38: 8673135.5 | AQ38: 7710403.5 | AR38: 12751854 | AS38: 15864776 | AT38: 17871261 | AU38: 23974333 | AV38: 26676236 | AW38: 29869905 | AX38: 33995451 | AY38: 33995451 | AZ38: 2500708 | BA38: 4701879.5 | BB38: 6186601.2 | BC38: 11740599 | BD38: 13815424 | BE38: 16607622 | BF38: 20305216
A39: 7.3 | B39: Marketing Expenses | C39: 897213 | D39: 1120228 | E39: 1661825 | F39: 2477039 | G39: 1284059 | H39: 3960517 | I39: =1143975+935979 -> 2079954 | J39: 9990 | K39: 53390 | L39: 188506 | M39: 203886 | N39: 383406 | O39: 576934 | P39: 698184 | Q39: 987950 | R39: 1050410 | S39: 1135835 | T39: 1147415 | U39: 1195765 | V39: 1195765 | W39: 3666270 | X39: 3278342.6 | Y39: 3278343 | Z39: 844120 | AA39: 983900 | AB39: 1368760 | AC39: 2024420 | AD39: 2143700 | AE39: 2628900 | AF39: 3372718 | AG39: 3437248 | AH39: 4833483 | AI39: 5652088 | AJ39: 7465808 | AK39: 8159982 | AL39: 8159982 | AM39: 900770 | AN39: 1140610 | AO39: 2721740 | AP39: 2759640 | AQ39: 4087900 | AR39: 4820246 | AS39: 6769435.6 | AT39: 7942391.6 | AU39: 8533696.8 | AV39: 8962004.8 | AW39: 12064575 | AX39: 13383312 | AY39: 13383312 | AZ39: 653380 | BA39: 2713463.2 | BB39: 3578741.2 | BC39: 4602231.2 | BD39: 5572996.2 | BE39: 7473586.2 | BF39: 9032959.2
A40: 7.4 | B40: Depreciation and Amortization Charges | C40: 471735 | D40: 18116378 | E40: 7563029 | F40: 8638883 | G40: 6668543 | H40: 9567411 | I40: =5561905+4550650 -> 10112555 | J40: 1150000 | K40: 2300000 | L40: 3450000 | M40: 4600000 | N40: 5750000 | O40: 6900000 | P40: 8050000 | Q40: 9200000 | R40: 10350000 | S40: 11500000 | T40: 12650000 | U40: 10750235 | V40: =10750235 -> 10750235 | W40: 12996272 | X40: 12490225 | Y40: 12490225 | Z40: 1250000 | AA40: 2500000 | AB40: 3750000 | AC40: 5000000 | AD40: 6250000 | AE40: 7500000 | AF40: 8750000 | AG40: 10000000 | AH40: 11250000 | AI40: 12500000 | AJ40: 13750000 | AK40: 10387317 | AL40: 10387317 | AM40: 1250000 | AN40: 2500000 | AO40: 3750000 | AP40: 5000000 | AQ40: 6250000 | AR40: 7500000 | AS40: 8750000 | AT40: 10000000 | AU40: 11250000 | AV40: 12500000 | AW40: 13750000 | AX40: 12590197 | AY40: 12590195 | AZ40: 1375000 | BA40: 2750000 | BB40: 4125000 | BC40: 5500000 | BD40: 6250000 | BE40: 8250000 | BF40: 9625000
A41: 7.5 | B41: Administrative Expenses | C41: =5007607-471735-897213 -> 3638659 | D41: 17337830 | E41: =2984687+300+174000+15200+222626+2277907+499188+876407+12450+2991090+2235883+2388618+3366484+451604+7582 -> 18504026 | F41: 25047425 | G41: =1801732+659600+1926087+42710+1198027+2526895+1827958+4561274+4071050+755408+16220+83600 -> 19470561 | H41: =2315865+641030+3005316+108770+3567027+3503613+2124107+5469196+9220032+825017+99483+169640+2268267 -> 33317363 | I41: =1245026+419052+2182752+82500+98890+1901892+198303+257059+1175650+988847+3120863+2466091+516846+30963+2519494+67012+1018657+342861+1785888+67500+80910+1556094+162248+210321+961895+809056+2553434+2017711+422874+25334+2061404+54828 -> 31402255 | J41: 4098069.6 | K41: 6665494.2 | L41: 9135500.1 | M41: 11207052 | N41: 13608142 | O41: 16075294 | P41: 17242126 | Q41: 21519667 | R41: 24051642 | S41: 27088154 | T41: 29834150 | U41: 32427745 | V41: =2541381+660844+13195+4274880+1900+179800+3895074+267650+380716+2716623+1428162+5727566+4052693+938463+109291+4720738+480000+38770 -> 32427746 | W41: 36589147 | X41: 39828415 | Y41: =4239832+489065+4345920+475240+214600+3117509+3303553+349200+619047+2432558+617436+5772004+4368425+1527056+88677+3740267+965800+135166 -> 36801355 | Z41: 2972622.2 | AA41: 6691705.1 | AB41: 10903960 | AC41: 14313250 | AD41: 17910977 | AE41: 22137471 | AF41: 27262372 | AG41: 31295275 | AH41: 35160516 | AI41: 40147022 | AJ41: 43789528 | AK41: 52538013 | AL41: =48869190+5000000 -> 53869190 | AM41: 4894729.3 | AN41: 9041522.2 | AO41: 16858678 | AP41: 24859921 | AQ41: 26137463 | AR41: 32039925 | AS41: 37432050 | AT41: 42613043 | AU41: 48857117 | AV41: 55688931 | AW41: 66810715 | AX41: 77126527 | AY41: 85416047 | AZ41: 6647544.1 | BA41: 13513914 | BB41: 19271924 | BC41: 26660290 | BD41: 34691325 | BE41: 43338272 | BF41: 53219837
A43: 8 | B43: Net Operating Income | C43: =C30-C32-C36 -> 26095426 | D43: =D30-D32-D36 -> 70284849 | E43: =E30-E32-E36 -> 91428749 | F43: =F30-F32-F36 -> 89552803 | G43: =G30-G32-G36 -> 96648220 | H43: =H30-H32-H36 -> 82461920 | I43: =I30-I32-I36 -> 114935158 | J43: =J30-J32-J36 -> 4169708.5 | ... BF43: =BF30-BF32-BF36 -> -7944380.2
A45: 9 | B45: Net Non- Operating Income/ (Expense) | C45: =C46-C47 -> 0 | D45: =D46-D47 -> 8965033.6 | E45: =E46-E47 -> 357268 | F45: =F46-F47 -> 226400 | G45: =G46-G47 -> 0 | H45: =H46-H47 -> 0 | I45: =I46-I47 -> 0 | J45: =J46-J47 -> 13876644 | ... BF45: =BF46-BF47 -> 77514973
A46: 9.1 | B46: Non- Operating Income | D46: 8965033.6 | E46: 357268 | F46: 226400 | J46: 13876644 | K46: 14779521 | L46: 17496061 | M46: 21872603 | N46: 27563400 | O46: 30887255 | P46: 41103698 | Q46: 43719586 | R46: 45805242 | S46: 48480030 | T46: 49273454 | U46: 54318353 | W46: 0 | X46: 0 | Y46: 0 | Z46: 10649958 | AA46: 13425119 | AB46: 18133372 | AC46: 47868107 | AD46: 48309135 | AE46: 54554495 | AF46: 65052753 | AG46: 67861651 | AH46: 70183559 | AI46: 85633841 | AJ46: 88644611 | AK46: 95832303 | AM46: 2922694 | AN46: 13413414 | AO46: 14088308 | AP46: 35283685 | AQ46: 41696675 | AR46: 62190820 | AS46: 67779114 | AT46: 77518348 | AU46: 78547565 | AV46: 1.0008567e+08 | AW46: 1.0663928e+08 | AX46: 1.375899e+08 | AY46: 0 | AZ46: 8956248 | BA46: 15358225 | BB46: 16491277 | BC46: 28037143 | BD46: 35077007 | BE46: 68115767 | BF46: 77514973
A47: 9.2 | B47: Non- Operating Expense | J47: 0 | K47: 0 | L47: 0 | W47: 0 | X47: 0 | Y47: 0 | Z47: 0 | AA47: 0 | AB47: 0 | AC47: 0 | AD47: 0 | AE47: 0 | AF47: 0 | AG47: 0 | AH47: 0 | AI47: 0 | AJ47: 0 | AK47: 0 | AM47: 0 | AN47: 0 | AO47: 0 | AP47: 0 | AQ47: 0 | AR47: 0 | AS47: 0 | AT47: 0 | AU47: 0 | AV47: 0 | AW47: 0 | AX47: 0 | AY47: 0 | AZ47: 0 | BA47: 0 | BB47: 0 | BC47: 0 | BD47: 0 | BE47: 0 | BF47: 0
...

Sheet FINANCIALS
C1: YETU SACCO
C2: Year | D2: Audited 2010 | E2: Audited 2011 | F2: Audited 2012 | G2: AUDITED 2013 | H2: 2014 AUDITED | I2: AUDITED 2015 | J2: AUDITED 2016 | K2: 42736 | L2: 42767 | M2: 42795 | N2: 42826 | O2: 42856 | P2: 42887 | Q2: 42917 | R2: 42948 | S2: 42979 | T2: 43009 | U2: 43040 | V2: 43070 | W2: Audited 2017 | X2: Dcember 2020 | Y2: Audited 2020 | Z2: 44197 | AA2: 44228 | AB2: 44256 | AC2: 44287 | AD2: 44317 | AE2: 44348 | AF2: 44378 | AG2: 44409 | AH2: 44440 | AI2: 44470 | AJ2: 44501 | AK2: 44531 | AL2: AUDITED 2021 | AM2: 44562 | AN2: 44593 | AO2: 44621 | AP2: 44652 | AQ2: 44682 | AR2: 44713 | AS2: 44743 | AT2: 44774 | AU2: 44805 | AV2: 44835 | AW2: 44866 | AX2: 44896 | AY2: Audited 2022 | AZ2: 44927 | BA2: 44958 | BB2: 44986 | BC2: 45017 | BD2: 45047 | BE2: 45078 | BF2: 45108
B3: 1 | C3: Membership
B4: 2 | C4: Total Assets | D4: ='STATEMENT OF FINANCIAL POSITION'!C39 -> 886952707 | E4: ='STATEMENT OF FINANCIAL POSITION'!D39 -> 1185246560 | F4: ='STATEMENT OF FINANCIAL POSITION'!E39 -> 1235320891 | G4: ='STATEMENT OF FINANCIAL POSITION'!F39 -> 1560105754 | H4: ='STATEMENT OF FINANCIAL POSITION'!G39 -> 1699301395 | I4: ='STATEMENT OF FINANCIAL POSITION'!H39 -> 1995648187 | J4: ='STATEMENT OF FINANCIAL POSITION'!I39 -> 2415328924 | K4: ='STATEMENT OF FINANCIAL POSITION'!J39 -> 2.3940354e+09 | ... W4: ='STATEMENT OF FINANCIAL POSITION'!V39 -> 2882475144 | X4: ='STATEMENT OF FINANCIAL POSITION'!X39 -> 4.1914307e+09 | Y4: ='STATEMENT OF FINANCIAL POSITION'!Y39 -> 4189144224 | Z4: ='STATEMENT OF FINANCIAL POSITION'!Z39 -> 4.1233197e+09 | AA4: ='STATEMENT OF FINANCIAL POSITION'!AA39 -> 4.0988971e+09 | AB4: ='STATEMENT OF FINANCIAL POSITION'!AB39 -> 4.1633143e+09 | AC4: ='STATEMENT OF FINANCIAL POSITION'!AC39 -> 4.2139972e+09 | AD4: ='STATEMENT OF FINANCIAL POSITION'!AD39 -> 4.2482716e+09 | AE4: ='STATEMENT OF FINANCIAL POSITION'!AE39 -> 4.2781875e+09 | ... BF4: ='STATEMENT OF FINANCIAL POSITION'!BF39 -> 5.5795063e+09
B5: 3 | C5: Total Deposits | D5: ='STATEMENT OF FINANCIAL POSITION'!C46 -> 559229530 | E5: ='STATEMENT OF FINANCIAL POSITION'!D46 -> 745419886 | F5: ='STATEMENT OF FINANCIAL POSITION'!E46 -> 881752998 | G5: ='STATEMENT OF FINANCIAL POSITION'!F46 -> 1074107086 | H5: ='STATEMENT OF FINANCIAL POSITION'!G46 -> 1097902733 | I5: ='STATEMENT OF FINANCIAL POSITION'!H46 -> 1301662001 | J5: ='STATEMENT OF FINANCIAL POSITION'!I46 -> 1561654213 | K5: ='STATEMENT OF FINANCIAL POSITION'!J46 -> 1.5130318e+09 | ... W5: ='STATEMENT OF FINANCIAL POSITION'!V46 -> 1816103673 | X5: ='STATEMENT OF FINANCIAL POSITION'!X46 -> 2.6000952e+09 | Y5: ='STATEMENT OF FINANCIAL POSITION'!Y46 -> 2600095208 | Z5: ='STATEMENT OF FINANCIAL POSITION'!Z46 -> 2.675158e+09 | AA5: ='STATEMENT OF FINANCIAL POSITION'!AA46 -> 2.6322747e+09 | AB5: ='STATEMENT OF FINANCIAL POSITION'!AB46 -> 2.6693256e+09 | AC5: ='STATEMENT OF FINANCIAL POSITION'!AC46 -> 2664023686 | AD5: ='STATEMENT OF FINANCIAL POSITION'!AD46 -> 2.6693278e+09 | AE5: ='STATEMENT OF FINANCIAL POSITION'!AE46 -> 2.6754047e+09 | ... BF5: ='STATEMENT OF FINANCIAL POSITION'!BF46 -> 3.4592088e+09
B6: 3.1 | C6: Deposits-Members(BOSA) | D6: ='STATEMENT OF FINANCIAL POSITION'!C45 -> 259831037 | E6: ='STATEMENT OF FINANCIAL POSITION'!D45 -> 343881456 | F6: ='STATEMENT OF FINANCIAL POSITION'!E45 -> 435718084 | G6: ='STATEMENT OF FINANCIAL POSITION'!F45 -> 533687314 | H6: ='STATEMENT OF FINANCIAL POSITION'!G45 -> 588206481 | I6: ='STATEMENT OF FINANCIAL POSITION'!H45 -> 645106995 | J6: ='STATEMENT OF FINANCIAL POSITION'!I45 -> 833556884 | K6: ='STATEMENT OF FINANCIAL POSITION'!J45 -> 8.4011294e+08 | ... W6: ='STATEMENT OF FINANCIAL POSITION'!V45 -> 932150562 | X6: ='STATEMENT OF FINANCIAL POSITION'!X45 -> 1.4450413e+09 | Y6: ='STATEMENT OF FINANCIAL POSITION'!Y45 -> 1004303406 | Z6: ='STATEMENT OF FINANCIAL POSITION'!Z45 -> 1.4627379e+09 | AA6: ='STATEMENT OF FINANCIAL POSITION'!AA45 -> 1.4778964e+09 | AB6: ='STATEMENT OF FINANCIAL POSITION'!AB45 -> 1.5012699e+09 | AC6: ='STATEMENT OF FINANCIAL POSITION'!AC45 -> 1.5186985e+09 | AD6: ='STATEMENT OF FINANCIAL POSITION'!AD45 -> 1.5411626e+09 | AE6: ='STATEMENT OF FINANCIAL POSITION'!AE45 -> 1.5764766e+09 | ... BF6: ='STATEMENT OF FINANCIAL POSITION'!BF45 -> 2.2010512e+09
B7: 3.2 | C7: Deposits-Customers(FOSA) | D7: ='STATEMENT OF FINANCIAL POSITION'!C43 -> 244588501 | E7: ='STATEMENT OF FINANCIAL POSITION'!D44 -> 71496906 | F7: ='STATEMENT OF FINANCIAL POSITION'!E43+'STATEMENT OF FINANCIAL POSITION'!E44 -> 446034914 | G7: ='STATEMENT OF FINANCIAL POSITION'!F43+'STATEMENT OF FINANCIAL POSITION'!F44 -> 540419772 | H7: ='STATEMENT OF FINANCIAL POSITION'!G43+'STATEMENT OF FINANCIAL POSITION'!G44 -> 509696252 | I7: ='STATEMENT OF FINANCIAL POSITION'!H43+'STATEMENT OF FINANCIAL POSITION'!H44 -> 656555006 | J7: ='STATEMENT OF FINANCIAL POSITION'!I43+'STATEMENT OF FINANCIAL POSITION'!I44 -> 728097329 | K7: ='STATEMENT OF FINANCIAL POSITION'!J43+'STATEMENT OF FINANCIAL POSITION'!J44 -> 6.7291884e+08 | L7: ='STATEMENT OF FINANCIAL POSITION'!K43+'STATEMENT OF FINANCIAL POSITION'!K44 -> 6.7451603e+08 | M7: ='STATEMENT OF FINANCIAL POSITION'!L43+'STATEMENT OF FINANCIAL POSITION'!L44 -> 6.2875647e+08 | ... W7: ='STATEMENT OF FINANCIAL POSITION'!V43+'STATEMENT OF FINANCIAL POSITION'!V44 -> 883953111 | X7: ='STATEMENT OF FINANCIAL POSITION'!X43+'STATEMENT OF FINANCIAL POSITION'!X44 -> 1.155054e+09 | Y7: ='STATEMENT OF FINANCIAL POSITION'!Y43+'STATEMENT OF FINANCIAL POSITION'!Y44 -> 1595791802 | Z7: ='STATEMENT OF FINANCIAL POSITION'!Z43+'STATEMENT OF FINANCIAL POSITION'!Z44 -> 1.2124201e+09 | AA7: ='STATEMENT OF FINANCIAL POSITION'!AA43+'STATEMENT OF FINANCIAL POSITION'!AA44 -> 1154378248 | AB7: ='STATEMENT OF FINANCIAL POSITION'!AB43+'STATEMENT OF FINANCIAL POSITION'!AB44 -> 1.1680557e+09 | AC7: ='STATEMENT OF FINANCIAL POSITION'!AC43+'STATEMENT OF FINANCIAL POSITION'!AC44 -> 1.1453252e+09 | AD7: ='STATEMENT OF FINANCIAL POSITION'!AD43+'STATEMENT OF FINANCIAL POSITION'!AD44 -> 1.1281652e+09 | AE7: ='STATEMENT OF FINANCIAL POSITION'!AE43+'STATEMENT OF FINANCIAL POSITION'!AE44 -> 1.0989281e+09 | ... BF7: ='STATEMENT OF FINANCIAL POSITION'!BF43+'STATEMENT OF FINANCIAL POSITION'!BF44 -> 1.2581576e+09
B8: 4 | C8: External Borrowing | D8: ='STATEMENT OF FINANCIAL POSITION'!C54 -> 10587743 | E8: ='STATEMENT OF FINANCIAL POSITION'!D54 -> 39797135 | F8: ='STATEMENT OF FINANCIAL POSITION'!E54 -> 3000000 | G8: ='STATEMENT OF FINANCIAL POSITION'!F54 -> 0 | H8: ='STATEMENT OF FINANCIAL POSITION'!G54 -> 0 | I8: ='STATEMENT OF FINANCIAL POSITION'!H54 -> 0 | J8: ='STATEMENT OF FINANCIAL POSITION'!I54 -> 0 | K8: ='STATEMENT OF FINANCIAL POSITION'!J54 -> 0 | ... W8: ='STATEMENT OF FINANCIAL POSITION'!V54 -> 0 | X8: ='STATEMENT OF FINANCIAL POSITION'!X54 -> 6711068.7 | Y8: ='STATEMENT OF FINANCIAL POSITION'!Y54 -> 0 | Z8: ='STATEMENT OF FINANCIAL POSITION'!Z54 -> 5869715 | AA8: ='STATEMENT OF FINANCIAL POSITION'!AA54 -> 5874606.3 | AB8: ='STATEMENT OF FINANCIAL POSITION'!AB54 -> 5879497.7 | AC8: ='STATEMENT OF FINANCIAL POSITION'!AC54 -> 5037452 | AD8: ='STATEMENT OF FINANCIAL POSITION'!AD54 -> 5041650 | AE8: ='STATEMENT OF FINANCIAL POSITION'!AE54 -> 5045848 | ... BF8: ='STATEMENT OF FINANCIAL POSITION'!BF54 -> 0
B10: 5 | C10: Share capital and Reserves
B11: 5.1 | C11: Core Capital | D11: =D14-D23 -> 188947973 | E11: =E14-E23 -> 239362202 | F11: =F14-F23 -> 221733455 | G11: =G14-G23 -> 317987309 | H11: =H14-H23 -> 400606236 | I11: =I14-I23 -> 482819469 | J11: =J14-J23 -> 544401880 | K11: =K14-K23 -> 5.6152946e+08 | ... BF11: =BF14-BF23 -> 1.4169528e+09
B12: 5.2 | C12: Institutional Capital | D12: =D11-D15 -> 61559893 | E12: =E11-E15 -> 106281551 | F12: =F11-F15 -> 188250897 | G12: =G11-G15 -> 275786629 | H12: =H11-H15 -> 358340851 | I12: =I11-I15 -> 438454448 | J12: =J11-J15 -> 494753405 | K12: =K11-K15 -> 5.114579e+08 | ... BF12: =BF11-BF15 -> 1.1792989e+09
B14: 5.3 | C14: Total Capital | D14: =SUM(D15:D21) -> 203039553 | E14: =SUM(E15:E21) -> 254553782 | F14: =SUM(F15:F21) -> 236925035 | G14: =SUM(G15:G21) -> 333973009 | H14: =SUM(H15:H21) -> 426691936 | I14: =SUM(I15:I21) -> 510101546 | J14: =SUM(J15:J21) -> 575483957 | K14: =SUM(K15:K21) -> 5.9261154e+08 | ... BF14: =SUM(BF15:BF21) -> 1.560247e+09
B15: 5.3.1 | C15: Members Share Capital | D15: ='STATEMENT OF FINANCIAL POSITION'!C58 -> 127388080 | E15: ='STATEMENT OF FINANCIAL POSITION'!D58 -> 133080651 | F15: ='STATEMENT OF FINANCIAL POSITION'!E58 -> 33482558 | G15: ='STATEMENT OF FINANCIAL POSITION'!F58 -> 42200680 | H15: ='STATEMENT OF FINANCIAL POSITION'!G58 -> 42265385 | I15: ='STATEMENT OF FINANCIAL POSITION'!H58 -> 44365021 | J15: ='STATEMENT OF FINANCIAL POSITION'!I58 -> 49648475 | K15: ='STATEMENT OF FINANCIAL POSITION'!J58 -> 50071559 | ... W15: ='STATEMENT OF FINANCIAL POSITION'!V58 -> 113780340 | X15: ='STATEMENT OF FINANCIAL POSITION'!X58 -> 1.4578701e+08 | Y15: ='STATEMENT OF FINANCIAL POSITION'!Y58 -> 145787006 | Z15: ='STATEMENT OF FINANCIAL POSITION'!Z58 -> 1.4691082e+08 | AA15: ='STATEMENT OF FINANCIAL POSITION'!AA58 -> 1.4806064e+08 | AB15: ='STATEMENT OF FINANCIAL POSITION'!AB58 -> 1.4936251e+08 | AC15: ='STATEMENT OF FINANCIAL POSITION'!AC58 -> 1.5043828e+08 | AD15: ='STATEMENT OF FINANCIAL POSITION'!AD58 -> 1.5143916e+08 | AE15: ='STATEMENT OF FINANCIAL POSITION'!AE58 -> 1.5285222e+08 | ... BF15: ='STATEMENT OF FINANCIAL POSITION'!BF58 -> 2.3765395e+08
B16: 5.3.3 | C16: Retained Earnings | D16: ='STATEMENT OF FINANCIAL POSITION'!C61 -> 48170884 | E16: ='STATEMENT OF FINANCIAL POSITION'!D61 -> 84159745 | F16: ='STATEMENT OF FINANCIAL POSITION'!E61 -> 145851655 | G16: ='STATEMENT OF FINANCIAL POSITION'!F61 -> 212095859 | H16: ='STATEMENT OF FINANCIAL POSITION'!G61 -> 284016397 | I16: ='STATEMENT OF FINANCIAL POSITION'!H61 -> 348834010 | J16: ='STATEMENT OF FINANCIAL POSITION'!I61 -> 386711956 | K16: ='STATEMENT OF FINANCIAL POSITION'!J61 -> 4.540086e+08 | ... W16: ='STATEMENT OF FINANCIAL POSITION'!V61 -> 407228249 | X16: ='STATEMENT OF FINANCIAL POSITION'!X61 -> 6.5504807e+08 | Y16: ='STATEMENT OF FINANCIAL POSITION'!Y61 -> 618677813 | Z16: ='STATEMENT OF FINANCIAL POSITION'!Z61 -> 6.3512853e+08 | AA16: ='STATEMENT OF FINANCIAL POSITION'!AA61 -> 6.3922187e+08 | AB16: ='STATEMENT OF FINANCIAL POSITION'!AB61 -> 6.4477809e+08 | AC16: ='STATEMENT OF FINANCIAL POSITION'!AC61 -> 6.7560311e+08 | AD16: ='STATEMENT OF FINANCIAL POSITION'!AD61 -> 6.8071258e+08 | AE16: ='STATEMENT OF FINANCIAL POSITION'!AE61 -> 6.8918871e+08 | ... BF16: ='STATEMENT OF FINANCIAL POSITION'!BF61 -> 8.2046693e+08
B17: 5.3.5 | C17: Statutory Reserves | D17: ='STATEMENT OF FINANCIAL POSITION'!C66 -> 22297880 | E17: ='STATEMENT OF FINANCIAL POSITION'!D66 -> 31912074 | F17: ='STATEMENT OF FINANCIAL POSITION'!E66 -> 48489144 | G17: ='STATEMENT OF FINANCIAL POSITION'!F66 -> 66444985 | H17: ='STATEMENT OF FINANCIAL POSITION'!G66 -> 86652629 | I17: ='STATEMENT OF FINANCIAL POSITION'!H66 -> 103145013 | J17: ='STATEMENT OF FINANCIAL POSITION'!I66 -> 126132045 | K17: ='STATEMENT OF FINANCIAL POSITION'!J66 -> 1.2613205e+08 | ... W17: ='STATEMENT OF FINANCIAL POSITION'!V66 -> 148036060 | X17: ='STATEMENT OF FINANCIAL POSITION'!X66 -> 1.8040062e+08 | Y17: ='STATEMENT OF FINANCIAL POSITION'!Y66 -> 215052536 | Z17: ='STATEMENT OF FINANCIAL POSITION'!Z66 -> 2.1505254e+08 | AA17: ='STATEMENT OF FINANCIAL POSITION'!AA66 -> 2.1505254e+08 | AB17: ='STATEMENT OF FINANCIAL POSITION'!AB66 -> 2.1505254e+08 | AC17: ='STATEMENT OF FINANCIAL POSITION'!AC66 -> 2.1505254e+08 | AD17: ='STATEMENT OF FINANCIAL POSITION'!AD66 -> 2.1505254e+08 | AE17: ='STATEMENT OF FINANCIAL POSITION'!AE66 -> 2.1505254e+08 | ... BF17: ='STATEMENT OF FINANCIAL POSITION'!BF66 -> 2.7415492e+08
